File: Amostra BRI com poli_01.txt
#Acq. time (s)=	2
#Accumulations=	3
#Range (nm)=	520...900
#Windows=	24
#Auto scanning=	On
#Autofocus=	Off
#AutoExposure=	Off
#Spike filter=	Multiple accum.
#Delay time (s)=	0
#Binning=	1
#Readout mode=	Signal
#DeNoise=	Off
#ICS correction=	Off
#Dark correction=	Off
#Inst. Process=	Off
#Detector temperature (°C)=	-59.98
#Instrument=	LabRAM HR Evol
#Detector=	Syncerity OE
#Objective=	x50_VIS
#Grating=	600 (500nm)
#ND Filter=	25%
#Laser=	514nm_Edge
#Hole=	199.981
#Range=	Auto
#StageXY=	Marzhauser
#StageZ=	Marzhauser
#X (µm)=	7717.2
#Y (µm)=	10350.4
#Z (µm)=	12.5
#Full time(mm:ss)=	2:55
#Project=
#Sample=
#Site=
#Title=	Amostra BRI com poli
#Remark=
#Date=	22.02.2024 11:11
#Acquired=	22.02.2024 11:11:05
520.013	30.2453
520.274	35.6756
520.536	34.4134
520.797	33.4732
521.059	34.5334
521.32	36.9076
521.582	33.2384
521.843	34.7934
522.105	33.049
522.366	36.9491
522.628	36.8765
522.889	34.9228
523.15	36.8393
523.412	37.3239
523.673	33.8867
523.935	38.8426
524.196	38.7206
524.457	31.7932
524.719	35.274
524.98	37.1966
525.241	37.3333
525.503	36.1601
525.764	36.4627
526.025	38.4206
526.286	37.0552
526.548	34.6721
526.809	39.2472
527.07	32.8974
527.331	41.9548
527.593	35.9873
527.854	34
528.115	39.4145
528.376	33.7102
528.637	32.5996
528.898	39.4699
529.16	39.8787
529.421	41.1405
529.682	38.5036
529.943	39.4366
530.204	39.3644
530.465	36.9552
530.726	35.7527
530.987	39.3584
531.248	40.1501
531.509	38.1764
531.77	42.5437
532.031	39.4919
532.292	39.9177
532.553	41.6391
532.814	43.7078
533.075	41.912
533.336	44.8126
533.597	44.6057
533.858	44.2626
534.119	45.1218
534.38	44.2416
534.641	45.3826
534.901	42.7157
535.162	50.3501
535.423	47.4904
535.684	46.0954
535.945	46.6659
536.205	51.6481
536.466	48.499
536.727	49.997
536.988	49.4493
537.248	50.7219
537.509	51.9052
537.77	47.1749
537.987	52.5558
538.249	53.0087
538.51	54.0122
538.771	50.1576
539.032	55.7203
539.293	48.2903
539.554	56.041
539.815	50.2961
540.076	54.5881
540.337	51.0097
540.598	52.4148
540.859	51.816
541.12	60.3266
541.381	57.7972
541.642	59.0651
541.903	57.7126
542.164	57.784
542.425	61.7451
542.686	57.1493
542.947	61.9624
543.208	57.4073
543.469	56.0002
543.73	58.4541
543.991	63.658
544.252	71.0386
544.513	63.2205
544.773	56.7477
545.034	62.3492
545.295	69.3542
545.556	58.9481
545.817	71.4392
546.077	67.4408
546.338	68.934
546.599	69.6055
546.86	70.5955
547.12	74.7184
547.381	72.8828
547.642	65.1379
547.903	74.8258
548.163	73.0154
548.424	74.156
548.685	72.1997
548.945	75.8344
549.206	77.9012
549.467	77.6336
549.727	82.5471
549.988	81.0386
550.248	86.5906
550.509	86.5414
550.769	94.6424
551.03	93.0828
551.291	111.324
551.551	120.58
551.812	159.721
552.072	226.351
552.332	532.478
552.593	11595.8
552.853	4456.39
553.114	341.394
553.374	175.349
553.635	137.479
553.895	113.925
554.155	101.419
554.416	101.39
554.676	93.5303
554.937	89.8332
555.197	85.859
555.457	89.9924
555.686	81.1066
555.947	88.0088
556.207	80.1788
556.468	87.7309
556.729	89.6112
556.99	94.8595
557.25	87.9209
557.511	82.6471
557.772	83.518
558.032	86.563
558.293	91.771
558.554	80.8835
558.814	86.6079
559.075	84.4292
559.336	85.6614
559.596	83.0732
559.857	87.9075
560.117	82.978
560.378	81.3835
560.638	85.5677
560.899	77.6438
561.159	88.2458
561.42	83.841
561.68	85.488
561.941	87.1286
562.201	91.0534
562.462	85.3275
562.722	80.0231
562.983	84.2123
563.243	85.1366
563.504	84.6674
563.764	88.1058
564.024	85.3707
564.285	83.9619
564.545	88.7805
564.805	85.3301
565.066	82.7558
565.326	84.2795
565.586	88.2051
565.847	83.6275
566.107	85.5127
566.367	92.8105
566.627	87.4303
566.888	83.4334
567.148	83.8699
567.408	88.1414
567.668	89.3762
567.928	92.7415
568.189	90.3799
568.449	91.4974
568.709	88.0061
568.969	85.9263
569.229	84.7322
569.489	86.8015
569.749	88.1441
570.009	89.7745
570.269	84.5444
570.53	86.1652
570.79	83.8785
571.05	85.8249
571.31	91.4158
571.57	84.8926
571.83	87.9432
572.09	85.1148
572.349	92.3508
572.609	85.5123
572.869	87.0058
573.129	89.6971
573.368	88.6105
573.629	89.3727
573.889	85.7799
574.15	91.5038
574.41	91.3068
574.67	96.8391
574.931	87.226
575.191	94.5944
575.451	104.549
575.711	97.9783
575.972	95.0461
576.232	97.3262
576.492	98.7261
576.752	94.1866
577.013	94.2825
577.273	101.015
577.533	92.9275
577.793	88.6056
578.053	87.5834
578.313	93.8356
578.574	90.3756
578.834	89.1212
579.094	97.4147
579.354	88.7192
579.614	96.2962
579.874	102.053
580.134	98.2504
580.394	100.413
580.654	99.8156
580.914	109.266
581.174	102.107
581.434	104.771
581.694	108.661
581.954	105.617
582.214	112.235
582.474	115.503
582.734	117.187
582.994	120.52
583.254	124.73
583.514	131.21
583.773	130.799
584.033	129.449
584.293	132.9
584.553	142.335
584.813	147.944
585.073	144.854
585.332	143.206
585.592	149.035
585.852	152.969
586.112	156.53
586.371	158.528
586.631	171.199
586.891	174.199
587.151	186.29
587.41	198.224
587.67	199.482
587.93	203.186
588.189	201.207
588.449	204.595
588.709	194.646
588.968	197.243
589.228	209.424
589.487	223.551
589.747	218.335
590.006	202.071
590.266	201.729
590.525	193.945
590.785	184.998
591.036	177.04
591.296	165.16
591.556	159.222
591.816	144.253
592.076	136.59
592.336	140.936
592.596	136.215
592.856	133.47
593.116	131.513
593.376	134.664
593.635	118.547
593.895	131.799
594.155	122.344
594.415	127.932
594.675	124.924
594.935	120.877
595.194	122.503
595.454	128.976
595.714	131.604
595.974	132.087
596.233	127.317
596.493	137.592
596.753	144.109
597.012	116.112
597.272	105.898
597.532	98.5705
597.791	102.175
598.051	95.4337
598.311	96.085
598.57	96.9269
598.83	87.9874
599.089	93.783
599.349	92.6236
599.609	88.1431
599.868	93.0175
600.128	94.2733
600.387	89.9251
600.647	91.0935
600.906	86.4351
601.166	85.6074
601.425	89.5241
601.685	89.1832
601.944	86.7737
602.203	90.8372
602.463	84.6371
602.722	87.1758
602.982	87.171
603.241	89.53
603.5	85.0097
603.76	86.1178
604.019	95.0995
604.278	90.139
604.538	88.9481
604.797	97.4405
605.056	94.3195
605.315	89.9439
605.575	90.1782
605.834	93.5349
606.093	95.115
606.352	94.5183
606.611	92.2215
606.871	91.805
607.13	96.6059
607.389	92.8442
607.648	91.0639
607.907	94.8897
608.166	95.563
608.425	89.5239
608.664	88.4948
608.924	95.7474
609.183	95.7606
609.443	86.9635
609.702	91.4084
609.962	106.063
610.221	89.8831
610.481	85.9934
610.74	98.5897
611	98.6756
611.259	97.8431
611.518	91.1915
611.778	94.4932
612.037	97.39
612.297	95.5554
612.556	98.0671
612.815	86.6627
613.075	92.6595
613.334	92.5368
613.594	94.944
613.853	97.8835
614.112	99.5638
614.371	100.169
614.631	91.3587
614.89	103.079
615.149	101.155
615.408	90.9821
615.668	100.778
615.927	101.024
616.186	97.0039
616.445	92.9199
616.704	102.995
616.964	103.081
617.223	98.7349
617.482	96.9333
617.741	96.9531
618	93.5823
618.259	87.1653
618.518	94.9065
618.777	101.488
619.036	90.0475
619.295	93.3594
619.554	98.8567
619.813	93.4205
620.072	89.7033
620.331	94.3182
620.59	99.5332
620.849	100.929
621.108	100.044
621.367	95.9784
621.626	96.2996
621.885	97.0893
622.144	90.3751
622.403	97.9471
622.661	96.7463
622.92	92.5735
623.179	98.2878
623.438	100.192
623.697	96.3008
623.956	95.8353
624.214	93.7261
624.473	99.2304
624.732	103.087
624.99	104.562
625.249	99.3073
625.508	99.2331
625.767	100.729
626.025	98.7328
626.249	97.5305
626.508	99.8809
626.767	103.503
627.026	97.9952
627.285	99.0301
627.544	94.4854
627.803	91.5954
628.062	104.021
628.321	106.055
628.58	101.693
628.839	99.7155
629.098	99.3035
629.357	102.079
629.616	99.3097
629.875	92.5268
630.134	104.952
630.393	100.241
630.652	96.9788
630.911	92.6494
631.17	95.9031
631.429	94.3816
631.688	96.1571
631.947	107.227
632.206	93.4649
632.464	99.8395
632.723	104.907
632.982	101.766
633.241	102.317
633.5	103.527
633.758	102.52
634.017	106.237
634.276	105.538
634.535	101.319
634.793	102.802
635.052	95.985
635.311	97.3166
635.57	100.144
635.828	101.488
636.087	100.191
636.345	102.755
636.604	97.7519
636.863	100.819
637.121	101.376
637.38	102.372
637.638	105.127
637.897	102.6
638.156	104.477
638.414	98.9846
638.673	101.484
638.931	102.454
639.19	96.1314
639.448	107.745
639.706	109.168
639.965	105.402
640.223	96.5148
640.482	102.956
640.74	105.158
640.999	99.8779
641.257	91.5141
641.515	104.893
641.774	102.007
642.032	101.131
642.29	94.2524
642.549	101.267
642.807	93.4914
643.065	100.936
643.323	95.6428
643.582	102.947
643.84	90.0015
644.053	91.4615
644.312	101.448
644.57	100.324
644.829	98.5689
645.088	95.5408
645.346	101.762
645.605	100.705
645.864	92.5058
646.122	99.7267
646.381	95.1519
646.639	97.4146
646.898	93.1435
647.157	96.4709
647.415	90.7299
647.674	94.1681
647.932	92.9491
648.191	100.752
648.449	107.519
648.708	99.1304
648.966	98.5164
649.225	86.0628
649.483	92.2416
649.742	98.5067
650	102.395
650.258	95.4557
650.517	92.937
650.775	95.4884
651.034	90.0503
651.292	94.3417
651.55	96.1912
651.809	94.382
652.067	101.309
652.325	90.8435
652.583	85.2436
652.842	95.8489
653.1	91.9358
653.358	94.2839
653.616	89.5982
653.875	90.8555
654.133	95.3013
654.391	98.3341
654.649	93.7071
654.907	93.7042
655.165	94.531
655.424	92.0194
655.682	99.5071
655.94	93.8133
656.198	92.966
656.456	92.0147
656.714	102.896
656.972	93.724
657.23	98.5703
657.488	95.6838
657.746	96.7364
658.004	104.114
658.262	96.9144
658.52	99.7107
658.778	96.1634
659.036	99.1708
659.294	101.029
659.552	99.6592
659.809	98.3472
660.067	97.3077
660.325	92.7474
660.583	97.3353
660.841	97.5938
661.099	96.3792
661.356	96.921
661.583	95.0636
661.842	100.419
662.1	99.2292
662.358	92.9483
662.616	96.5276
662.875	92.819
663.133	97.7877
663.391	95.3102
663.649	101.269
663.907	90.9935
664.166	93.4856
664.424	94.8611
664.682	96.4121
664.94	88.5048
665.198	93.8267
665.456	88.2857
665.714	95.3916
665.972	90.2896
666.23	88.2482
666.488	95.7191
666.746	92.1731
667.004	96.4787
667.262	93.6705
667.52	90.2045
667.778	91.6814
668.036	88.6127
668.294	86.5375
668.552	92.9449
668.81	99.0835
669.068	91.2798
669.326	89.7575
669.584	92.2187
669.842	93.3859
670.099	87.471
670.357	99.7771
670.615	92.1033
670.873	93.5057
671.131	85.0059
671.388	91.427
671.646	96.7721
671.904	96.1546
672.162	88.2643
672.419	84.1901
672.677	88.8826
672.935	90.1848
673.192	89.5513
673.45	89.0912
673.708	96.56
673.965	89.9196
674.223	98.0379
674.481	93.8657
674.738	90.0563
674.996	80.7413
675.253	87.7444
675.511	95.6386
675.768	94.5578
676.026	86.3693
676.283	91.6756
676.541	85.1118
676.798	91.2719
677.056	87.2225
677.313	85.6572
677.571	92.2624
677.828	91.0226
678.085	83.6223
678.343	90.2859
678.6	95.7278
678.857	81.3
679.083	81.3887
679.341	87.0833
679.599	90.568
679.857	84.4485
680.114	88.9905
680.372	96.1191
680.63	91.4542
680.888	81.957
681.146	84.4521
681.403	89.8889
681.661	95.1872
681.919	89.1632
682.176	89.0208
682.434	93.9516
682.692	88.6209
682.949	81.3084
683.207	93.0715
683.465	86.5937
683.722	90.9625
683.98	91.6923
684.237	88.3596
684.495	95.0402
684.753	81.8497
685.01	88.1616
685.268	86.0319
685.525	85.4697
685.783	76.164
686.04	79.7502
686.298	87.6932
686.555	84.1114
686.813	79.7701
687.07	87.3437
687.327	86.8669
687.585	89.6647
687.842	87.6315
688.1	87.7353
688.357	88.5441
688.614	84.3875
688.872	78.8703
689.129	79.1662
689.386	82.8452
689.643	85.729
689.901	81.3044
690.158	87.5499
690.415	82.7398
690.672	77.6818
690.93	81.8128
691.187	85.3479
691.444	82.8272
691.701	80.2799
691.958	88.285
692.216	83.3425
692.473	78.2598
692.73	81.0013
692.987	86.1988
693.244	78.3603
693.501	77.6804
693.758	81.248
694.015	85.5494
694.272	83.4603
694.529	79.1939
694.786	84.0732
695.043	81.7048
695.3	83.0002
695.557	80.9897
695.814	78.7462
696.071	79.4486
696.328	80.833
696.585	76.257
696.81	77.2604
697.068	83.8236
697.325	82.3246
697.582	79.4597
697.84	81.584
698.097	79.1077
698.354	77.3993
698.612	80.692
698.869	79.5488
699.126	82.6814
699.384	78.0303
699.641	76.4511
699.898	80.3487
700.155	74.5306
700.413	72.9483
700.67	76.8551
700.927	80.1174
701.184	78.0959
701.441	77.7024
701.698	75.2676
701.956	80.4827
702.213	79.7287
702.47	78.7231
702.727	79.5083
702.984	79.8057
703.241	83.2154
703.498	79.9187
703.755	80.7285
704.012	76.4247
704.269	74.7874
704.526	73.8105
704.783	86.2277
705.04	79.779
705.297	73.2947
705.554	78.7685
705.811	79.9741
706.068	71.6648
706.324	78.8292
706.581	77.3143
706.838	78.4952
707.095	75.4654
707.352	76.1016
707.609	82.2448
707.865	73.0952
708.122	71.2
708.379	75.2325
708.636	75.746
708.892	74.0357
709.149	72.2703
709.406	78.7528
709.662	81.1734
709.919	74.57
710.176	78.4948
710.432	73.3596
710.689	78.9833
710.946	69.7023
711.202	76.9005
711.459	75.5903
711.715	76.5857
711.972	75.7367
712.228	77.6006
712.485	78.395
712.741	74.8072
712.998	74.6596
713.254	75.5703
713.511	78.1978
713.767	83.2037
714.024	78.579
714.231	79.0059
714.488	74.3705
714.745	75.8833
715.002	83.2271
715.259	79.8303
715.516	77.0433
715.773	78.4808
716.029	79.5477
716.286	76.1459
716.543	80.9588
716.8	75.9529
717.057	81.5223
717.314	77.5115
717.57	77.4661
717.827	80.0733
718.084	79.3786
718.341	76.361
718.597	75.1101
718.854	83.6823
719.111	83.2752
719.367	80.4429
719.624	82.2984
719.881	84.4138
720.137	77.4518
720.394	81.4232
720.65	86.6958
720.907	83.298
721.164	85.5948
721.42	84.6091
721.677	88.8144
721.933	83.4577
722.19	80.7319
722.446	85.4182
722.703	90.0335
722.959	91.5363
723.216	84.1591
723.472	88.5097
723.728	91.3908
723.985	94.9766
724.241	88.5536
724.498	95.8501
724.754	101.685
725.01	90.3746
725.267	96.0107
725.523	101.382
725.779	104.611
726.036	96.6097
726.292	113.467
726.548	105.791
726.804	97.3742
727.06	106.723
727.317	100.561
727.573	111.195
727.829	105.087
728.085	113.273
728.341	113.153
728.597	110.418
728.854	112.276
729.11	122.917
729.366	118.989
729.622	112.613
729.878	117.93
730.134	124.775
730.39	128.773
730.646	131.675
730.902	124.896
731.158	135.432
731.414	131.703
731.622	132.899
731.878	134.796
732.135	138.496
732.391	141.961
732.648	151.02
732.904	148.003
733.161	156.945
733.417	161.275
733.673	169.121
733.93	174.323
734.186	185.581
734.443	201.372
734.699	214.332
734.955	223.726
735.211	250.389
735.468	250.375
735.724	275.022
735.98	304.258
736.237	324.198
736.493	364.062
736.749	387.984
737.005	430.267
737.261	458.631
737.518	496.627
737.774	518.539
738.03	544.505
738.286	552.21
738.542	548.119
738.798	538.318
739.054	515.115
739.31	471.77
739.566	449.156
739.822	417.243
740.078	384.831
740.334	351.896
740.59	335.073
740.846	292.255
741.102	285.061
741.358	268.434
741.614	250.017
741.87	231.321
742.126	224.934
742.382	211.658
742.638	203.111
742.893	194.334
743.149	184.705
743.405	173.54
743.661	170.738
743.917	174.483
744.172	160.734
744.428	153.743
744.684	151.381
744.94	150.29
745.195	139.997
745.451	139.632
745.707	140.357
745.962	133.075
746.218	128.454
746.474	136.056
746.729	132.994
746.985	130.655
747.241	121.946
747.496	128.404
747.752	126.074
748.007	121.009
748.263	121.034
748.518	118.877
748.774	120.717
749.029	120.289
749.275	111.324
749.531	121.459
749.787	123.527
750.043	114.004
750.299	111.063
750.555	113.014
750.811	112.126
751.067	97.5874
751.323	105.606
751.579	106.712
751.835	112.813
752.09	109.487
752.346	113.604
752.602	106.016
752.858	108.728
753.114	99.0988
753.37	113.732
753.625	104.197
753.881	105.051
754.137	105.033
754.393	104.967
754.648	99.5346
754.904	102.137
755.16	107.889
755.415	108.733
755.671	102.308
755.927	105.871
756.182	99.234
756.438	105.007
756.693	104.063
756.949	108.692
757.205	102.344
757.46	101.075
757.716	103.678
757.971	105.1
758.227	100.463
758.482	98.9554
758.738	98.728
758.993	102.947
759.248	100.924
759.504	97.7926
759.759	96.8392
760.015	98.0224
760.27	100.05
760.525	95.4431
760.781	98.8928
761.036	94.5349
761.291	100.865
761.547	91.1421
761.802	93.2411
762.057	97.1764
762.313	98.9468
762.568	95.1822
762.823	94
763.078	95.5922
763.333	94.5062
763.589	87.7395
763.844	87.9858
764.099	89.8496
764.354	93.5655
764.609	90.0981
764.864	92.3127
765.119	95.0841
765.374	98.3929
765.629	87.4328
765.884	95.8897
766.139	95.3234
766.394	94.8065
766.649	92.2508
766.882	88.2803
767.137	96.7078
767.393	94.9215
767.648	84.655
767.904	85.0282
768.159	91.6881
768.415	88.9895
768.67	86.5458
768.926	81.1911
769.181	78.606
769.436	83.5551
769.692	78.1655
769.947	84.2327
770.203	76.7671
770.458	77.4244
770.713	82.9636
770.968	78.9745
771.224	76.0959
771.479	77.333
771.734	73.7196
771.99	79.8568
772.245	72.1468
772.5	74.9278
772.755	68.7078
773.01	69.0146
773.265	72.6476
773.521	71.2734
773.776	70.1766
774.031	65.2103
774.286	71.2056
774.541	69.2557
774.796	73.8053
775.051	71.7541
775.306	62.7734
775.561	63.7704
775.816	64.3976
776.071	67.2056
776.326	65.4241
776.581	65.1123
776.836	67.572
777.091	62.9975
777.346	63.2635
777.601	62.105
777.856	65.2847
778.111	66.3171
778.365	60.8351
778.62	59.4983
778.875	62.4863
779.13	62.0665
779.385	61.2744
779.639	57.7926
779.894	60.2046
780.149	60.497
780.404	59.3832
780.658	62.4414
780.913	64.6763
781.168	59.8605
781.422	60.8258
781.677	60.4508
781.932	58.7708
782.186	58.1099
782.441	57.6213
782.695	60.5841
782.95	59.7511
783.204	57.9681
783.459	56.1021
783.714	58.1599
783.968	57.3677
784.211	53.0312
784.466	53.2261
784.721	55.9777
784.976	57.6439
785.231	45.1192
785.486	55.2943
785.741	53.8954
785.996	57.3337
786.251	52.4716
786.506	58.4822
786.761	51.4166
787.016	54.3206
787.271	48.9431
787.526	52.8572
787.78	53.2681
788.035	50.3794
788.29	48.742
788.545	55.8326
788.8	52.0486
789.054	48.4106
789.309	53.3646
789.564	53.0849
789.819	56.7714
790.073	53.4849
790.328	56.3476
790.583	50.9986
790.837	49.4544
791.092	51.4701
791.347	47.8117
791.601	48.1477
791.856	49.6762
792.11	49.6839
792.365	52.3648
792.619	47.2561
792.874	52.3531
793.128	51.3902
793.383	50.7611
793.638	54.5338
793.892	50.8808
794.146	52.9059
794.401	48.7637
794.655	50.6598
794.91	47.6609
795.164	52.3299
795.418	52.0286
795.673	46.8859
795.927	51.136
796.181	48.1288
796.436	45.9671
796.69	54.5654
796.944	53.6852
797.199	49.5212
797.453	47.6627
797.707	50.7884
797.961	49.0792
798.216	49.905
798.47	51.3161
798.724	52.0093
798.978	51.5307
799.232	45.7417
799.486	49.5577
799.74	46.6151
799.994	45.9069
800.248	48.7409
800.503	49.4026
800.757	53.9738
801.011	46.0566
801.265	42.6739
801.508	46.233
801.762	47.5729
802.017	46.9401
802.271	47.7856
802.526	46.9271
802.78	47.152
803.035	43.0977
803.289	48.7685
803.544	43.7404
803.798	44.1008
804.052	44.5471
804.307	51.7136
804.561	44.6955
804.816	42.7074
805.07	38.125
805.324	41.6019
805.579	43.2443
805.833	46.0688
806.087	42.7737
806.341	48.7447
806.596	49.8612
806.85	41.5101
807.104	47.3915
807.358	41.5552
807.613	46.2997
807.867	35.9472
808.121	43.9181
808.375	40.8626
808.629	47.0624
808.883	40.2557
809.138	46.1804
809.392	45.2913
809.646	39.5652
809.9	40.3687
810.154	45.6753
810.408	43.7272
810.662	38.1231
810.916	41.8739
811.17	40.7973
811.424	43.2702
811.678	41.3178
811.932	45.4891
812.185	44.218
812.439	44.8561
812.693	39.6581
812.947	42.475
813.201	44.6001
813.455	40.218
813.709	41.2218
813.962	43.2084
814.216	45.499
814.47	40.4931
814.724	39.2853
814.977	42.4213
815.231	38.2239
815.485	37.8942
815.739	41.9432
815.992	41.6107
816.246	40.5988
816.499	36.3576
816.753	39.7929
817.007	40.7596
817.26	40.7317
817.514	38.7433
817.767	38.687
818.021	40.9791
818.274	37.8246
818.528	38.0685
818.781	36.3357
819.01	38.3026
819.264	41.8062
819.518	36.3788
819.772	38.2337
820.026	37.503
820.28	38.6892
820.534	32.8672
820.788	37.7777
821.042	36.1931
821.296	39.4469
821.549	34.6988
821.803	35.9243
822.057	33.8285
822.311	32.6562
822.565	38.0749
822.819	40.181
823.073	37.4861
823.326	35.2582
823.58	36.1424
823.834	36.7518
824.088	34.0406
824.341	32.6961
824.595	38.6826
824.849	39.7231
825.103	33.662
825.356	38.1589
825.61	35.9829
825.864	33.0735
826.117	33.4087
826.371	39.3699
826.624	39.0401
826.878	34.1716
827.131	36.614
827.385	33.5526
827.638	35.1412
827.892	34.1987
828.146	34.7162
828.399	33.3324
828.652	36.8372
828.906	37.6328
829.159	34.0466
829.413	33.3752
829.666	34.6705
829.919	34.6433
830.173	34.752
830.426	36.1687
830.68	36.0069
830.933	35.4602
831.186	30.1698
831.439	34.033
831.693	28.4879
831.946	34.7499
832.199	35.1469
832.452	34.2498
832.706	31.273
832.959	28.6614
833.212	34.8748
833.465	33.7148
833.718	33.9773
833.971	32.5056
834.224	36.5666
834.477	34.8968
834.73	33.6121
834.984	29.2095
835.237	34.663
835.49	35.0192
835.743	33.9009
835.996	29.209
836.201	34.9365
836.454	35.8897
836.708	31.9792
836.961	34.8418
837.215	35.4956
837.468	32.9955
837.722	33.7415
837.975	28.2893
838.229	37.4873
838.482	35.5676
838.735	35.9544
838.989	30.0839
839.242	36.7687
839.496	34.3173
839.749	33.1293
840.002	32.6475
840.256	26.3106
840.509	29.9375
840.762	35.7747
841.015	31.5741
841.269	25.5949
841.522	33.0229
841.775	32.1688
842.028	34.3094
842.281	30.8084
842.535	35.6169
842.788	29.2
843.041	29.218
843.294	31.0699
843.547	33.9445
843.8	34.1507
844.053	26.7086
844.306	34.7062
844.559	31.788
844.812	36.459
845.065	30.7266
845.318	32.6591
845.571	32.1412
845.824	30.9259
846.077	32.3815
846.33	34.1723
846.583	33.408
846.836	32.8006
847.089	34.4227
847.342	33.3049
847.595	35.082
847.847	36.2409
848.1	32.1254
848.353	33.6646
848.606	26.4207
848.859	32.2783
849.111	30.6973
849.364	35.3375
849.617	30.788
849.869	32.0655
850.122	30.5024
850.375	33.284
850.627	32.9194
850.88	31.384
851.133	29.9132
851.385	32.3893
851.638	29.0748
851.89	32.4539
852.143	32.9354
852.395	29.6644
852.648	34.0773
852.9	30.1407
853.153	34.1347
853.405	28.0663
853.645	25.9149
853.898	32.8866
854.151	32.2198
854.404	34.8031
854.657	32.9433
854.91	37.4136
855.163	27.1158
855.416	30.3626
855.669	30.4921
855.922	34.6916
856.175	26.3801
856.427	29.4662
856.68	30.3564
856.933	28.5963
857.186	32.7992
857.439	27.846
857.692	32.4034
857.944	30.8177
858.197	29.2073
858.45	29.5623
858.703	30.5531
858.955	27.2914
859.208	28.8584
859.461	28.2945
859.713	33.3476
859.966	31.4056
860.219	33.4634
860.471	33.3012
860.724	27.5005
860.976	28.8743
861.229	28.5254
861.481	31.9978
861.734	27.9417
861.986	29.8453
862.239	24.3255
862.491	32.2449
862.744	31.1028
862.996	35.7735
863.249	33.6319
863.501	29.5717
863.754	30.5926
864.006	28.8428
864.258	30.4698
864.511	31.6736
864.763	33.1778
865.015	27.6696
865.268	30.4128
865.52	29.6581
865.772	28.5507
866.024	27.4427
866.276	27.2175
866.529	28.9771
866.781	29.8049
867.033	32.858
867.285	27.709
867.537	30.8318
867.789	32.972
868.042	31.0173
868.294	34.5572
868.546	30.821
868.798	30.75
869.05	31.9657
869.302	33.5009
869.554	30.0305
869.806	33.1769
870.058	32.7288
870.31	25.9451
870.562	32.2083
870.782	27.4399
871.034	26.4318
871.287	32.5825
871.539	30.0934
871.792	33.1019
872.044	30.1787
872.297	30.0755
872.549	30.8599
872.801	29.3879
873.054	34.283
873.306	29.2018
873.558	29.7245
873.811	31.7407
874.063	33.6629
874.315	30.5396
874.568	31.26
874.82	28.7696
875.072	29.9937
875.324	29.6762
875.577	27.6284
875.829	28.9689
876.081	30.2233
876.333	25.4812
876.585	29.3263
876.838	34.165
877.09	30.4494
877.342	27.5145
877.594	23.9995
877.846	32.4624
878.098	27.2372
878.35	26.68
878.602	28.0448
878.854	34.6019
879.106	31.8297
879.358	33.9875
879.61	30.9669
879.862	29.4923
880.114	29.037
880.366	26.661
880.618	28.0593
880.87	27.0998
881.121	32.0719
881.373	30.5063
881.625	28.7283
881.877	32.1905
882.129	27.7108
882.38	26.6985
882.632	32.2671
882.884	27.5283
883.136	30.1544
883.387	28.5122
883.639	30.9738
883.891	28.5432
884.142	28.9179
884.394	28.4904
884.646	29.6448
884.897	27.5867
885.149	29.1802
885.4	32.3878
885.652	33.0728
885.903	27.9428
886.155	31.5133
886.406	29.2199
886.658	28.8399
886.909	29.5707
887.161	29.2126
887.412	29.5586
887.664	29.535
887.915	29.0874
888.138	29.0074
888.39	33.6205
888.642	26.9651
888.894	30.2765
889.146	33.8854
889.398	33.206
889.65	29.0976
889.902	28.9828
890.154	30.7704
890.406	28.9871
890.657	31.1296
890.909	28.6287
891.161	30.3274
891.413	27.8127
891.665	30.2463
891.916	30.0226
892.168	33.9072
892.42	24.9869
892.671	27.5059
892.923	28.3052
893.175	26.4183
893.426	26.3514
893.678	28.5812
893.93	31.364
894.181	28.6725
894.433	28.7513
894.684	29.6292
894.936	30.8588
895.188	27.7552
895.439	25.5988
895.69	29.185
895.942	30.3675
896.193	28.8174
896.445	24.5099
896.696	31.1824
896.948	28.7303
897.199	26.904
897.451	26.575
897.702	34.1908
897.953	28.1027
898.204	25.7496
898.456	31.1348
898.707	32
898.958	26.1463
899.21	22.7003
899.461	28.1094
899.712	30.5131
899.963	33.3333