File: Amostra branca_01.txt
#Acq. time (s)=	2
#Accumulations=	3
#Range (nm)=	520...900
#Windows=	24
#Auto scanning=	On
#Autofocus=	Off
#AutoExposure=	Off
#Spike filter=	Multiple accum.
#Delay time (s)=	0
#Binning=	1
#Readout mode=	Signal
#DeNoise=	Off
#ICS correction=	Off
#Dark correction=	Off
#Inst. Process=	Off
#Detector temperature (°C)=	-59.98
#Instrument=	LabRAM HR Evol
#Detector=	Syncerity OE
#Objective=	x50_VIS
#Grating=	600 (500nm)
#ND Filter=	25%
#Laser=	514nm_Edge
#Hole=	199.981
#Range=	Auto
#StageXY=	Marzhauser
#StageZ=	Marzhauser
#X (µm)=	-1795.9
#Y (µm)=	1818.9
#Z (µm)=	13.8
#Full time(mm:ss)=	2:44
#Project=
#Sample=
#Site=
#Title=	Amostra branca
#Remark=
#Date=	22.02.2024 10:55
#Acquired=	22.02.2024 10:55:42
520.013	39.8306
520.274	40.6574
520.536	37.1616
520.797	40.0124
521.059	43.8569
521.32	36.396
521.582	38.4279
521.843	41.7685
522.105	45.3908
522.366	39.4361
522.628	42.1323
522.889	42.3767
523.15	42.0064
523.412	40.312
523.673	44.0726
523.935	42.2495
524.196	41.8681
524.457	40.7683
524.719	38.8269
524.98	39.1189
525.241	38.6441
525.503	42.1531
525.764	42.9092
526.025	42.1279
526.286	39.8377
526.548	43.2651
526.809	43.7277
527.07	42.1528
527.331	42.9578
527.593	44.9104
527.854	43.094
528.115	45.7841
528.376	45.0435
528.637	43.8078
528.898	42.6627
529.16	44.3174
529.421	44.2008
529.682	42.6331
529.943	41.6906
530.204	46.758
530.465	47.3923
530.726	46.1257
530.987	44.2692
531.248	47.8274
531.509	45.0702
531.77	39.3627
532.031	42.0101
532.292	46.3744
532.553	45.9186
532.814	46.367
533.075	46.6641
533.336	49.726
533.597	45.8037
533.858	42.7189
534.119	49.3586
534.38	50.579
534.641	50.566
534.901	51.2067
535.162	51.7854
535.423	51.0264
535.684	50.4337
535.945	52.902
536.205	56.3022
536.466	52.7082
536.727	50.1854
536.988	56.9072
537.248	55.2689
537.509	56.1636
537.77	57.6006
537.987	55.0525
538.249	54.2499
538.51	57.1288
538.771	50.6058
539.032	61.5989
539.293	56.8598
539.554	56.001
539.815	57.3291
540.076	63.2492
540.337	59.9528
540.598	58.7884
540.859	61.4613
541.12	58.9986
541.381	62.7926
541.642	63.5879
541.903	61.0048
542.164	61.7002
542.425	57.2289
542.686	65.0157
542.947	59.4599
543.208	60.9546
543.469	67.7455
543.73	69.7132
543.991	67.8804
544.252	66.2379
544.513	63.8841
544.773	63.8677
545.034	70.888
545.295	68.9729
545.556	66.2446
545.817	74.362
546.077	74.2103
546.338	76.9972
546.599	72.821
546.86	74.1919
547.12	79.2323
547.381	79.5719
547.642	81.5872
547.903	76.4872
548.163	78.6628
548.424	78.1529
548.685	74.2974
548.945	80.6096
549.206	91.9548
549.467	87.739
549.727	93.2993
549.988	92.6671
550.248	105.294
550.509	102.558
550.769	116.526
551.03	108.424
551.291	117.202
551.551	132.513
551.812	156.738
552.072	214.325
552.332	492.144
552.593	10719.4
552.853	4499.16
553.114	326.034
553.374	176.256
553.635	137.803
553.895	121.943
554.155	116.524
554.416	102.588
554.676	105.453
554.937	110.075
555.197	105.212
555.457	109.884
555.686	108.859
555.947	106.167
556.207	114.424
556.468	106.924
556.729	116.696
556.99	115.32
557.25	115.039
557.511	109.101
557.772	117.371
558.032	119.839
558.293	108.358
558.554	115.062
558.814	118.395
559.075	110.876
559.336	117.393
559.596	120.647
559.857	126.781
560.117	126.302
560.378	126.82
560.638	117.697
560.899	115.954
561.159	141.216
561.42	137.556
561.68	140.541
561.941	132.667
562.201	148.48
562.462	139.957
562.722	147.675
562.983	145.315
563.243	149.079
563.504	144.865
563.764	142.371
564.024	149.51
564.285	149.979
564.545	155.537
564.805	155.196
565.066	163.194
565.326	162.329
565.586	173.346
565.847	169.045
566.107	170.232
566.367	172.44
566.627	175.128
566.888	175.363
567.148	185.099
567.408	185.371
567.668	186.691
567.928	187.211
568.189	191.817
568.449	187.516
568.709	195.045
568.969	200.227
569.229	200.083
569.489	203.087
569.749	206.253
570.009	204.567
570.269	211.714
570.53	216.114
570.79	226.901
571.05	233.23
571.31	239.819
571.57	249.069
571.83	256.373
572.09	267.643
572.349	282.006
572.609	300.134
572.869	302.824
573.129	331.166
573.368	348.138
573.629	361.92
573.889	386.849
574.15	413.025
574.41	436.621
574.67	467.002
574.931	494.938
575.191	531.047
575.451	546.355
575.711	570.6
575.972	584.986
576.232	562.214
576.492	543.536
576.752	537.671
577.013	501.129
577.273	492.525
577.533	456.721
577.793	429.749
578.053	424.529
578.313	414.056
578.574	402.926
578.834	393.79
579.094	405.605
579.354	402.179
579.614	396.704
579.874	401.179
580.134	398.218
580.394	404.77
580.654	399.801
580.914	412.993
581.174	400.654
581.434	410.623
581.694	413.65
581.954	412.151
582.214	427.465
582.474	433.943
582.734	440.246
582.994	441.058
583.254	453.221
583.514	453.571
583.773	461.835
584.033	469.601
584.293	480.091
584.553	473.815
584.813	495.195
585.073	507.509
585.332	520.506
585.592	519.762
585.852	540.066
586.112	541.465
586.371	542.677
586.631	552.177
586.891	566.824
587.151	554.669
587.41	562.127
587.67	577.842
587.93	588.596
588.189	579.679
588.449	589.377
588.709	589.696
588.968	605.152
589.228	603.313
589.487	613.766
589.747	625.999
590.006	610.148
590.266	617.884
590.525	608.017
590.785	599.49
591.036	594.923
591.296	581.012
591.556	573.981
591.816	578.297
592.076	564.185
592.336	558.187
592.596	565.543
592.856	563.31
593.116	573.174
593.376	580.804
593.635	587.744
593.895	565.512
594.155	567.382
594.415	574.9
594.675	580.27
594.935	593.413
595.194	581.813
595.454	588.637
595.714	589.98
595.974	604.807
596.233	626.825
596.493	639.4
596.753	665.578
597.012	645.138
597.272	618.155
597.532	621.426
597.791	628.995
598.051	634.01
598.311	630.402
598.57	615.799
598.83	633.595
599.089	629.618
599.349	623.286
599.609	627.986
599.868	624.863
600.128	623.63
600.387	626.315
600.647	628.007
600.906	629.567
601.166	608.448
601.425	608.481
601.685	621.699
601.944	615.979
602.203	615.977
602.463	633.076
602.722	636.063
602.982	636.43
603.241	642.938
603.5	644.623
603.76	650.548
604.019	651.489
604.278	648.824
604.538	642.176
604.797	675.621
605.056	648.226
605.315	659.916
605.575	652.01
605.834	653.794
606.093	650.994
606.352	649.001
606.611	663.004
606.871	653.847
607.13	646.64
607.389	651.439
607.648	663.017
607.907	654.35
608.166	662.718
608.425	661.228
608.664	659.053
608.924	665.042
609.183	665.256
609.443	670.002
609.702	688.351
609.962	684.375
610.221	691.788
610.481	696.144
610.74	674.866
611	691.398
611.259	707.48
611.518	701.516
611.778	706.369
612.037	701.683
612.297	718.499
612.556	704.284
612.815	711.292
613.075	706.917
613.334	715.624
613.594	729.575
613.853	737.738
614.112	729.342
614.371	739.514
614.631	752.909
614.89	763.581
615.149	748.171
615.408	754.856
615.668	759.7
615.927	772.135
616.186	790.063
616.445	789.165
616.704	791.18
616.964	820.748
617.223	792.679
617.482	813.982
617.741	802.491
618	823.255
618.259	818.679
618.518	824.975
618.777	845.656
619.036	833.386
619.295	823.42
619.554	849.112
619.813	841.078
620.072	850.049
620.331	832.759
620.59	828.955
620.849	842.293
621.108	841.496
621.367	849.897
621.626	855.432
621.885	846.799
622.144	847.941
622.403	857.435
622.661	844.223
622.92	862.503
623.179	856.306
623.438	856.877
623.697	857.625
623.956	855.904
624.214	867.011
624.473	866.59
624.732	860.959
624.99	861.92
625.249	873.228
625.508	880.387
625.767	874.029
626.025	861.948
626.249	867.573
626.508	886.807
626.767	889.046
627.026	892.354
627.285	881.91
627.544	894.565
627.803	873.131
628.062	897.288
628.321	894.28
628.58	894.201
628.839	888.374
629.098	893.811
629.357	917.002
629.616	906.758
629.875	904.377
630.134	904.94
630.393	908.056
630.652	902.915
630.911	931.37
631.17	931.62
631.429	941.227
631.688	924.539
631.947	927.134
632.206	960.231
632.464	933.615
632.723	945.879
632.982	956.342
633.241	978.068
633.5	979.169
633.758	979.099
634.017	966.597
634.276	979.095
634.535	998.922
634.793	1013.28
635.052	1008.78
635.311	1024.66
635.57	1042.86
635.828	1051.18
636.087	1074.07
636.345	1087.78
636.604	1124.05
636.863	1141.84
637.121	1178.23
637.38	1215.91
637.638	1253.37
637.897	1296.41
638.156	1277.93
638.414	1256.68
638.673	1275.52
638.931	1257.64
639.19	1225.72
639.448	1221.28
639.706	1191.65
639.965	1169.73
640.223	1162.59
640.482	1127.88
640.74	1137.06
640.999	1125.06
641.257	1135.08
641.515	1127.75
641.774	1115.54
642.032	1134.2
642.29	1102.04
642.549	1123.61
642.807	1100.95
643.065	1117.7
643.323	1128.48
643.582	1114.19
643.84	1132.48
644.053	1152.81
644.312	1130.8
644.57	1144.83
644.829	1146.89
645.088	1147.12
645.346	1148.77
645.605	1151.53
645.864	1146.16
646.122	1168.77
646.381	1164.15
646.639	1144.81
646.898	1184.54
647.157	1168.69
647.415	1151.47
647.674	1157.68
647.932	1190.05
648.191	1178.12
648.449	1179.86
648.708	1206.4
648.966	1185.48
649.225	1207.35
649.483	1197.51
649.742	1208.86
650	1196.94
650.258	1215.83
650.517	1223.84
650.775	1231.42
651.034	1238.39
651.292	1227.01
651.55	1244.35
651.809	1262.09
652.067	1258.69
652.325	1273.29
652.583	1267.18
652.842	1282.99
653.1	1268.12
653.358	1282.24
653.616	1290.74
653.875	1307.6
654.133	1297.2
654.391	1309.14
654.649	1309.84
654.907	1331.18
655.165	1339.84
655.424	1332.17
655.682	1368.22
655.94	1378.16
656.198	1363.26
656.456	1400.76
656.714	1408.5
656.972	1405.74
657.23	1402.45
657.488	1419.96
657.746	1441.04
658.004	1434.19
658.262	1403.43
658.52	1446.54
658.778	1454.09
659.036	1449.62
659.294	1438.91
659.552	1481.34
659.809	1464.8
660.067	1445.09
660.325	1463.16
660.583	1464.7
660.841	1443.22
661.099	1455.06
661.356	1450.93
661.583	1431.69
661.842	1448.5
662.1	1436.07
662.358	1468.02
662.616	1476.36
662.875	1457.58
663.133	1460.81
663.391	1458.63
663.649	1473.44
663.907	1468.75
664.166	1458.99
664.424	1443.87
664.682	1461.79
664.94	1455.73
665.198	1454.16
665.456	1441.4
665.714	1455.59
665.972	1422.22
666.23	1432.78
666.488	1447.15
666.746	1428.76
667.004	1454.01
667.262	1448.46
667.52	1430.3
667.778	1445.77
668.036	1443.63
668.294	1432.76
668.552	1424.73
668.81	1450.98
669.068	1431.72
669.326	1429.54
669.584	1412.31
669.842	1426.92
670.099	1442.12
670.357	1453.15
670.615	1437.23
670.873	1418.19
671.131	1440.84
671.388	1435.49
671.646	1435.15
671.904	1427.53
672.162	1415.77
672.419	1440.28
672.677	1446.67
672.935	1445.78
673.192	1459.98
673.45	1448.5
673.708	1451.81
673.965	1453.06
674.223	1453.56
674.481	1459.53
674.738	1470.81
674.996	1474.55
675.253	1493.04
675.511	1467.94
675.768	1483.36
676.026	1485.4
676.283	1496.75
676.541	1495.04
676.798	1487.52
677.056	1505.13
677.313	1483.82
677.571	1510.23
677.828	1486.9
678.085	1497.75
678.343	1480.74
678.6	1476.81
678.857	1515.54
679.083	1479.54
679.341	1480.24
679.599	1479.14
679.857	1496.65
680.114	1463.75
680.372	1486.85
680.63	1492.84
680.888	1509.07
681.146	1500.19
681.403	1487.89
681.661	1505.6
681.919	1514.21
682.176	1511.36
682.434	1504.36
682.692	1521.51
682.949	1520.13
683.207	1520.19
683.465	1536.74
683.722	1513.41
683.98	1526.69
684.237	1504.4
684.495	1511.8
684.753	1475.84
685.01	1499.75
685.268	1486.79
685.525	1487.12
685.783	1504.12
686.04	1470.16
686.298	1483.1
686.555	1495.18
686.813	1483.08
687.07	1469.9
687.327	1502.56
687.585	1461.45
687.842	1447.74
688.1	1444.88
688.357	1482.9
688.614	1455.78
688.872	1453.53
689.129	1450.18
689.386	1476.05
689.643	1467.83
689.901	1442.65
690.158	1446.38
690.415	1444.08
690.672	1457.83
690.93	1448.41
691.187	1439.8
691.444	1437.14
691.701	1437.64
691.958	1433.05
692.216	1418.7
692.473	1407.87
692.73	1417.59
692.987	1404.42
693.244	1400.74
693.501	1395.11
693.758	1379.13
694.015	1394.62
694.272	1379.49
694.529	1414.88
694.786	1378.07
695.043	1370.39
695.3	1359.37
695.557	1395.46
695.814	1374.89
696.071	1365.05
696.328	1368.81
696.585	1369.84
696.81	1358.34
697.068	1352.59
697.325	1333.52
697.582	1343.09
697.84	1330.39
698.097	1350.48
698.354	1332.26
698.612	1330.36
698.869	1321.34
699.126	1316.13
699.384	1308.6
699.641	1309.54
699.898	1296.42
700.155	1294.64
700.413	1299.21
700.67	1293.65
700.927	1287.17
701.184	1293.97
701.441	1308.24
701.698	1270.11
701.956	1299.86
702.213	1305.59
702.47	1293.3
702.727	1279.83
702.984	1298.76
703.241	1286.46
703.498	1281.91
703.755	1266.7
704.012	1290.5
704.269	1260.6
704.526	1267.42
704.783	1278.51
705.04	1248.18
705.297	1246.06
705.554	1255.52
705.811	1266.73
706.068	1241.16
706.324	1223.55
706.581	1224.75
706.838	1227.17
707.095	1226.52
707.352	1222.23
707.609	1229.83
707.865	1209.21
708.122	1201.46
708.379	1195.28
708.636	1208.33
708.892	1203.62
709.149	1186.18
709.406	1174.67
709.662	1184.38
709.919	1195.76
710.176	1193.58
710.432	1166.03
710.689	1180.43
710.946	1161.74
711.202	1175.86
711.459	1173.12
711.715	1165.79
711.972	1152.76
712.228	1127.37
712.485	1140.8
712.741	1150.29
712.998	1138.26
713.254	1124.11
713.511	1117.33
713.767	1135.79
714.024	1113.32
714.231	1097.76
714.488	1104.08
714.745	1075.18
715.002	1099.53
715.259	1088.34
715.516	1087.27
715.773	1082.16
716.029	1062.04
716.286	1073.75
716.543	1069.97
716.8	1076.18
717.057	1066.42
717.314	1042.9
717.57	1033.25
717.827	1056.37
718.084	1037.59
718.341	1048.41
718.597	1051.28
718.854	1036.84
719.111	1047.26
719.367	1040.03
719.624	1031.44
719.881	1015.04
720.137	1002.13
720.394	1028.95
720.65	1000.76
720.907	996.625
721.164	1007.05
721.42	996.988
721.677	1014.84
721.933	990.212
722.19	979.108
722.446	981.383
722.703	968.27
722.959	975.214
723.216	946.511
723.472	968.977
723.728	971.523
723.985	966.463
724.241	948.979
724.498	954.616
724.754	946.613
725.01	965.307
725.267	959.055
725.523	947.828
725.779	970.917
726.036	969.938
726.292	933.864
726.548	938.846
726.804	942.227
727.06	933.539
727.317	927.78
727.573	940.75
727.829	931.695
728.085	925.108
728.341	925.149
728.597	934.306
728.854	902.853
729.11	895.133
729.366	901.033
729.622	916.327
729.878	897.936
730.134	895.428
730.39	867.482
730.646	908.527
730.902	891.176
731.158	892.287
731.414	875.338
731.622	903.974
731.878	883.37
732.135	884.999
732.391	918.547
732.648	917.189
732.904	903.849
733.161	902.007
733.417	903.489
733.673	918.871
733.93	899.496
734.186	916.905
734.443	942.677
734.699	956.304
734.955	979.549
735.211	996.054
735.468	1010.73
735.724	1040.29
735.98	1059.13
736.237	1109.71
736.493	1145.56
736.749	1180.73
737.005	1225.54
737.261	1284.65
737.518	1317.33
737.774	1348.07
738.03	1373.71
738.286	1393.89
738.542	1403.98
738.798	1363.16
739.054	1345.26
739.31	1302.86
739.566	1260.26
739.822	1200.33
740.078	1169.8
740.334	1131.19
740.59	1091.7
740.846	1060.01
741.102	1021.9
741.358	994.438
741.614	978.63
741.87	945.031
742.126	917.716
742.382	900.43
742.638	869.421
742.893	872.213
743.149	852.667
743.405	842.581
743.661	851.487
743.917	819.622
744.172	820.322
744.428	820.862
744.684	795.809
744.94	773.219
745.195	776.654
745.451	777.808
745.707	767.74
745.962	770.792
746.218	748.572
746.474	740.727
746.729	750.315
746.985	742.456
747.241	728.62
747.496	738.546
747.752	732.12
748.007	716.859
748.263	733.856
748.518	716.707
748.774	701.999
749.029	708.892
749.275	689.355
749.531	690.567
749.787	700.068
750.043	688.053
750.299	687.009
750.555	673.471
750.811	671.89
751.067	688.177
751.323	697.796
751.579	683.963
751.835	665.259
752.09	665.545
752.346	658.16
752.602	688.453
752.858	645.215
753.114	648.21
753.37	656.151
753.625	628.645
753.881	622.243
754.137	654.805
754.393	618.594
754.648	639.471
754.904	621.916
755.16	626.514
755.415	615.223
755.671	635.761
755.927	623.098
756.182	621.747
756.438	606.411
756.693	594.487
756.949	607.106
757.205	604.966
757.46	609.199
757.716	584.423
757.971	594.303
758.227	587.179
758.482	598.73
758.738	574.932
758.993	593.871
759.248	583.777
759.504	574.349
759.759	582.097
760.015	573.695
760.27	566.913
760.525	554.363
760.781	556.48
761.036	555.447
761.291	551.165
761.547	530.852
761.802	545.951
762.057	542.862
762.313	544.127
762.568	532.208
762.823	544.798
763.078	532.924
763.333	532.449
763.589	538.021
763.844	512.143
764.099	534.932
764.354	520.029
764.609	520.417
764.864	510.394
765.119	520.881
765.374	507.424
765.629	503.417
765.884	510.162
766.139	503.44
766.394	504.864
766.649	503.96
766.882	500.544
767.137	492.669
767.393	479.974
767.648	472.832
767.904	502.977
768.159	482.261
768.415	464.115
768.67	468.961
768.926	464.156
769.181	471.601
769.436	458.178
769.692	469.152
769.947	462.373
770.203	462.016
770.458	451.19
770.713	439.237
770.968	438.176
771.224	440.254
771.479	431.188
771.734	437.042
771.99	440.4
772.245	417.825
772.5	417.966
772.755	425.71
773.01	424.809
773.265	414.906
773.521	411.128
773.776	416.879
774.031	420.396
774.286	407.712
774.541	404.246
774.796	412.435
775.051	403.435
775.306	397.924
775.561	392.456
775.816	385.297
776.071	376.532
776.326	389.572
776.581	382.884
776.836	375.269
777.091	373.333
777.346	370.421
777.601	384.526
777.856	371.561
778.111	373.084
778.365	358.036
778.62	352.095
778.875	368.287
779.13	365.732
779.385	360.041
779.639	363.247
779.894	359.603
780.149	345.935
780.404	354.886
780.658	347.851
780.913	343.114
781.168	343.059
781.422	339.819
781.677	337.701
781.932	335.261
782.186	334.19
782.441	336.802
782.695	338.943
782.95	328.269
783.204	328.636
783.459	333.685
783.714	324.672
783.968	317.398
784.211	336.106
784.466	325.515
784.721	332.271
784.976	328.054
785.231	324.926
785.486	305.627
785.741	320.387
785.996	316.37
786.251	303.269
786.506	306.634
786.761	294.814
787.016	299.033
787.271	296.218
787.526	291.814
787.78	282.347
788.035	290.103
788.29	285.536
788.545	284.17
788.8	282.07
789.054	271.333
789.309	275.254
789.564	263.297
789.819	266.356
790.073	269.045
790.328	269.966
790.583	265.221
790.837	262.581
791.092	260.56
791.347	266.396
791.601	259.867
791.856	257.242
792.11	259.589
792.365	254.313
792.619	253.597
792.874	246.138
793.128	257.144
793.383	246.623
793.638	253.679
793.892	241.05
794.146	241.688
794.401	232.679
794.655	238.388
794.91	239.423
795.164	242.283
795.418	234.288
795.673	230.491
795.927	232.526
796.181	234.45
796.436	232.765
796.69	221.543
796.944	220.244
797.199	227.909
797.453	220.918
797.707	226.9
797.961	234.141
798.216	224.513
798.47	223.357
798.724	220.29
798.978	215.601
799.232	211.999
799.486	214.085
799.74	210.034
799.994	201.361
800.248	205.997
800.503	200.544
800.757	205.964
801.011	205.667
801.265	196.911
801.508	205.503
801.762	190.82
802.017	197.702
802.271	190.877
802.526	194.706
802.78	184.09
803.035	194.887
803.289	189.622
803.544	181.18
803.798	189.107
804.052	187.467
804.307	188.167
804.561	172.325
804.816	177.543
805.07	175.227
805.324	175.051
805.579	176.087
805.833	178.946
806.087	175.552
806.341	173.059
806.596	173.656
806.85	172.613
807.104	178.053
807.358	163.953
807.613	168.334
807.867	166.625
808.121	163.841
808.375	173.982
808.629	166.814
808.883	166.008
809.138	160.051
809.392	166.931
809.646	172.426
809.9	172.119
810.154	155.723
810.408	156.302
810.662	157.338
810.916	161.633
811.17	163.16
811.424	165.865
811.678	151.504
811.932	157.632
812.185	157.757
812.439	152.102
812.693	154.306
812.947	152.603
813.201	145.35
813.455	153.92
813.709	147.064
813.962	154.986
814.216	141.162
814.47	145.651
814.724	153.41
814.977	145.308
815.231	138.247
815.485	146.134
815.739	141.137
815.992	136.548
816.246	136.867
816.499	140.741
816.753	139.948
817.007	133.666
817.26	134.45
817.514	137.893
817.767	135.875
818.021	128.998
818.274	136.492
818.528	126.697
818.781	137.682
819.01	132.439
819.264	129.529
819.518	130.88
819.772	122.683
820.026	116.692
820.28	131.08
820.534	125.63
820.788	127.945
821.042	115.248
821.296	127.73
821.549	131.991
821.803	120.274
822.057	124.489
822.311	124.392
822.565	120.383
822.819	113.836
823.073	122.09
823.326	116.721
823.58	117.198
823.834	122.838
824.088	114.54
824.341	118.039
824.595	112.977
824.849	105.921
825.103	112.199
825.356	110.4
825.61	116.115
825.864	113.027
826.117	113.85
826.371	114.721
826.624	108.749
826.878	109.313
827.131	108.988
827.385	108.038
827.638	105.222
827.892	105.635
828.146	113.119
828.399	113.162
828.652	110.847
828.906	107.752
829.159	101.262
829.413	100.578
829.666	104.037
829.919	106.936
830.173	101.285
830.426	100.057
830.68	103.795
830.933	106.027
831.186	97.081
831.439	97.8807
831.693	98.8102
831.946	99.5818
832.199	104.898
832.452	96.6067
832.706	102.3
832.959	98.1925
833.212	97.7206
833.465	103.349
833.718	101.339
833.971	93.3886
834.224	101.434
834.477	92.0717
834.73	100.136
834.984	98.8679
835.237	94.9812
835.49	95.0115
835.743	87.0989
835.996	97.6709
836.201	90.8067
836.454	88.1825
836.708	95.115
836.961	96.9335
837.215	95.9226
837.468	93.543
837.722	93.8146
837.975	84.6345
838.229	79.347
838.482	91.849
838.735	90.0979
838.989	88.9039
839.242	82.769
839.496	92.7218
839.749	87.4946
840.002	91.4131
840.256	84.6497
840.509	82.6938
840.762	84.8883
841.015	85.5859
841.269	82.204
841.522	87.9155
841.775	84.7994
842.028	83.4276
842.281	80.7094
842.535	82.4639
842.788	88.2723
843.041	84.3919
843.294	80.328
843.547	80.7698
843.8	81.2649
844.053	77.6051
844.306	83.4795
844.559	85.9623
844.812	79.9852
845.065	78.1667
845.318	81.8937
845.571	83.0103
845.824	79.3853
846.077	73.4306
846.33	77.6517
846.583	78.1678
846.836	81.4303
847.089	76.7437
847.342	83.3571
847.595	79.5703
847.847	77.7406
848.1	77.3073
848.353	74.0994
848.606	82.8013
848.859	74.6447
849.111	72.9736
849.364	73.5235
849.617	78.2745
849.869	78.4249
850.122	71.8315
850.375	73.9548
850.627	72.9174
850.88	82.241
851.133	73.2145
851.385	76.1078
851.638	72.1432
851.89	72.5077
852.143	71.2324
852.395	78.0639
852.648	77.7182
852.9	70.8191
853.153	67.9814
853.405	72.3259
853.645	72.951
853.898	74.0557
854.151	74.8538
854.404	66.5747
854.657	64.1843
854.91	72.8464
855.163	65.234
855.416	73.4865
855.669	68.425
855.922	68.7548
856.175	74.5178
856.427	65.2912
856.68	70.2569
856.933	68.899
857.186	69.0467
857.439	63.2938
857.692	65.6917
857.944	65.4583
858.197	69.3879
858.45	63.8949
858.703	70.5717
858.955	62.3284
859.208	68.2157
859.461	70.5256
859.713	64.1701
859.966	64.1778
860.219	67.2554
860.471	66.3733
860.724	65.3988
860.976	69.4456
861.229	60.9803
861.481	70.6811
861.734	66.5325
861.986	70.1154
862.239	62.7521
862.491	59.2008
862.744	59.6685
862.996	63.8433
863.249	63.9447
863.501	66.4407
863.754	64.1352
864.006	66.8347
864.258	65.5695
864.511	59.8671
864.763	62.4574
865.015	63.7186
865.268	64.8612
865.52	58.7921
865.772	61.0695
866.024	63.9
866.276	62.6296
866.529	64.3786
866.781	65.412
867.033	60.8407
867.285	60.1341
867.537	62.168
867.789	55.2756
868.042	65.9886
868.294	59.0867
868.546	64.5207
868.798	57.883
869.05	61.4938
869.302	56.1682
869.554	62.8084
869.806	57.9855
870.058	61.9383
870.31	60.1254
870.562	60.2606
870.782	65.9949
871.034	57.5306
871.287	54.3938
871.539	63.4305
871.792	62.7215
872.044	57.2057
872.297	56.7123
872.549	57.8016
872.801	58.8446
873.054	60.4376
873.306	51.2565
873.558	62.182
873.811	58.3668
874.063	57.2958
874.315	59.1079
874.568	54.402
874.82	60.9113
875.072	57.0993
875.324	56.8004
875.577	58.7165
875.829	51.2978
876.081	48.4661
876.333	52.2729
876.585	58.5457
876.838	57.1611
877.09	55.1377
877.342	61.5356
877.594	55.7547
877.846	50.7547
878.098	56.5182
878.35	54.7592
878.602	62.0837
878.854	51.9388
879.106	59.2066
879.358	58.0586
879.61	55.662
879.862	51.8978
880.114	57.2913
880.366	53.4429
880.618	55.9201
880.87	52.3323
881.121	51.2271
881.373	55.2282
881.625	48.9498
881.877	51.5764
882.129	49.7809
882.38	54.0152
882.632	46.3409
882.884	52.7708
883.136	55.9477
883.387	54.7555
883.639	49.2601
883.891	52.4372
884.142	50.9744
884.394	51.9752
884.646	48.7046
884.897	50.4209
885.149	51.5529
885.4	49.9857
885.652	53.8057
885.903	48.8348
886.155	54.4273
886.406	49.9062
886.658	45.5693
886.909	54.2382
887.161	48.2987
887.412	46.7467
887.664	48.8188
887.915	47.3524
888.138	49.9525
888.39	51.7681
888.642	48.6651
888.894	47.491
889.146	49.3163
889.398	48.7862
889.65	49.0657
889.902	43.7713
890.154	50.0912
890.406	48.0401
890.657	50.4945
890.909	51.478
891.161	48.9174
891.413	48.0485
891.665	46.3451
891.916	52.5784
892.168	44.827
892.42	46.1775
892.671	50.2138
892.923	46.7164
893.175	45.4068
893.426	48.3272
893.678	44.0965
893.93	50.2533
894.181	42.6093
894.433	45.2542
894.684	45.16
894.936	49.5995
895.188	43.569
895.439	49.8304
895.69	48.0918
895.942	45.8854
896.193	43.2017
896.445	45.5919
896.696	47.8687
896.948	46.2592
897.199	43.8684
897.451	43.819
897.702	47.4614
897.953	41.9762
898.204	46.9064
898.456	44.2526
898.707	47.8572
898.958	38.992
899.21	40.7047
899.461	45.0425
899.712	42.8727
899.963	45.3333