File: LT_191023_M2_01.txt
#Acq. time (s)=	5
#Accumulations=	2
#Range (nm)=	520...900
#Windows=	8
#Auto scanning=	Off
#Autofocus=	Off
#AutoExposure=	Off
#Spike filter=	Multiple accum.
#Delay time (s)=	0
#Binning=	1
#Readout mode=	Signal
#DeNoise=	Off
#ICS correction=	On
#Dark correction=	Off
#Inst. Process=	Off
#Detector temperature (°C)=	-59.98
#Instrument=	LabRAM HR Evol
#Detector=	Syncerity OE
#Objective=	x50_VIS
#Grating=	600 (500nm)
#ND Filter=	10%
#Laser=	514nm_Edge
#Hole=	199.981
#Range=	Auto
#StageXY=	Marzhauser
#StageZ=	Marzhauser
#X (µm)=	-10816.9
#Y (µm)=	7181.2
#Z (µm)=	-8.4
#Full time(mm:ss)=	2:05
#Project=
#Sample=
#Site=
#Title=	LT_191023_M2
#Remark=
#Date=	27.10.2023 13:31
#Acquired=	27.10.2023 13:31:10
520.044	21.6206
520.306	32.1035
520.569	33.761
520.831	26.7676
521.093	37.5754
521.355	37.5356
521.617	28.456
521.88	28.3595
522.142	37.2387
522.404	35.6536
522.666	33.9895
522.928	35.805
523.19	31.9941
523.453	31.7748
523.715	40.4536
523.977	33.4553
524.239	37.2107
524.501	28.512
524.763	35.7401
525.025	33.8397
525.287	24.8615
525.549	42.6192
525.811	30.1993
526.073	28.6157
526.335	25.2095
526.597	39.7832
526.859	34.3435
527.121	28.8323
527.383	39.5997
527.645	39.5163
527.907	25.1349
528.169	30.635
528.431	39.891
528.693	29.2033
528.955	31.1363
529.217	34.758
529.479	41.9031
529.741	34.4231
530.003	43.397
530.264	36.1165
530.526	32.5981
530.788	25.5302
531.05	40.4256
531.312	38.7053
531.574	35.1818
531.835	48.241
532.097	37.2227
532.359	33.5593
532.621	33.7089
532.883	45.0144
533.144	37.493
533.406	41.2124
533.668	39.3348
533.93	39.212
534.191	37.2067
534.453	37.0195
534.715	44.457
534.976	37.1361
535.238	35.4011
535.5	41.0212
535.761	44.8994
536.023	41.3275
536.285	39.4399
536.546	39.2993
536.808	41.1306
537.069	40.8997
537.331	51.7786
537.593	44.2048
537.854	45.939
538.116	42.1484
538.377	42.2337
538.639	42.2731
538.9	36.8124
539.162	51.536
539.423	38.573
539.685	44.0551
539.946	45.827
540.208	47.5787
540.469	45.7895
540.731	47.7573
540.992	47.7805
541.254	47.9157
541.515	47.9883
541.776	55.3846
542.038	46.2626
542.299	53.5038
542.56	36.7464
542.822	55.0114
543.083	51.2249
543.344	49.3599
543.606	44.0083
543.867	47.6177
544.128	51.3192
544.39	58.7559
544.651	55.1492
544.912	58.8288
545.174	60.6124
545.435	60.4821
545.696	51.1105
545.957	45.5611
546.218	61.7101
546.48	65.1727
546.741	65.1517
547.002	63.4534
547.263	65.2648
547.524	52.5594
547.785	68.9683
548.047	74.435
548.308	69.0295
548.569	72.5259
548.83	79.7386
549.091	72.4122
549.352	70.2869
549.613	73.7637
549.874	84.2582
550.135	82.3832
550.396	90.9502
550.657	96.2908
550.918	94.3994
551.179	101.333
551.44	104.643
551.701	129.558
551.962	195.045
552.223	613.887
552.484	15094.4
552.745	657.805
553.006	186.224
553.267	143.795
553.528	110.329
553.788	106.54
554.049	104.811
554.31	99.5309
554.571	104.74
554.832	99.271
555.093	95.5243
555.353	98.7957
555.614	100.089
555.875	92.8141
556.136	104.961
556.396	109.962
556.657	111.803
556.918	106.441
557.179	117.055
557.439	117.401
557.7	112.426
557.961	114.545
558.221	118.438
558.482	116.681
558.743	123.639
559.003	125.442
559.264	124.929
559.525	115.498
559.785	127.422
560.046	121.427
560.306	131.147
560.567	125.018
560.827	126.053
561.088	130.595
561.348	131.947
561.609	140.282
561.869	138.695
562.13	130.323
562.39	148.968
562.651	161.243
562.911	156.434
563.172	156.753
563.432	156.833
563.692	168.626
563.953	161.41
564.213	179.99
564.474	157.452
564.734	175.152
564.994	162.377
565.255	186.778
565.515	182.23
565.775	176.459
566.035	174.159
566.296	166.857
566.556	189.051
566.816	194.925
567.076	183.556
567.337	208.086
567.597	200.209
567.857	203.78
568.117	191.154
568.377	213.792
568.637	209.555
568.898	227.145
569.158	210.68
569.418	220.296
569.678	232.803
569.938	223.796
570.198	234.687
570.458	238.569
570.718	250.533
570.978	263.995
571.238	265.997
571.498	287.386
571.758	276.369
572.018	292.988
572.278	315.937
572.538	329.611
572.798	353.055
573.058	376.002
573.312	398.906
573.573	400.527
573.834	435.674
574.095	471.264
574.356	482.616
574.617	530.042
574.878	579.432
575.139	576.394
575.4	578.148
575.661	626.841
575.922	621.491
576.183	572.913
576.444	576.553
576.705	557.575
576.965	532.054
577.226	501.134
577.487	494.811
577.748	480.552
578.009	470.682
578.27	427.857
578.531	440.408
578.791	429.747
579.052	418.979
579.313	410.869
579.574	403.989
579.835	411.489
580.095	408.318
580.356	406.928
580.617	394.226
580.878	413.984
581.138	399.198
581.399	412.111
581.66	416.647
581.92	432.454
582.181	432.62
582.442	435.066
582.703	438.052
582.963	451.944
583.224	443.01
583.484	452.205
583.745	450.326
584.006	472.79
584.266	483.981
584.527	472.671
584.787	490.788
585.048	501.308
585.308	489.528
585.569	498.169
585.83	509.677
586.09	510.292
586.351	527.052
586.611	508.506
586.872	542.127
587.132	523.188
587.392	530.594
587.653	536.104
587.913	535.622
588.174	556.441
588.434	538.347
588.695	556.225
588.955	549.301
589.215	555.191
589.476	556.543
589.736	559.204
589.996	563.626
590.257	558.235
590.517	549.933
590.777	558.217
591.038	551.472
591.298	546.384
591.558	532.504
591.818	526.564
592.079	520.865
592.339	524.705
592.599	517.699
592.859	536.712
593.12	520.018
593.38	521.611
593.64	539.354
593.9	548.478
594.16	535.623
594.42	505.292
594.68	543.243
594.941	543.245
595.201	538.982
595.461	535.338
595.721	543.942
595.981	537.107
596.241	562.92
596.501	588.815
596.761	539.794
597.021	552.666
597.281	544.487
597.541	533.182
597.801	574.105
598.061	552.348
598.321	562.185
598.581	564.627
598.841	564.934
599.101	585.289
599.361	594.833
599.62	568.569
599.88	584.072
600.14	573.853
600.4	596.711
600.66	581.109
600.92	576.622
601.18	588.864
601.439	585.938
601.699	593.355
601.959	566.201
602.219	605.705
602.478	580.948
602.738	586.278
602.998	581.042
603.258	601.069
603.517	575.013
603.777	590.636
604.037	568.658
604.296	590.966
604.556	604.31
604.816	602.442
605.075	600.748
605.335	613.394
605.594	625.785
605.854	606.142
606.114	591.352
606.373	612.628
606.633	604.782
606.892	596.144
607.152	582.817
607.411	590.588
607.671	599.393
607.93	608.615
608.19	596.757
608.449	614.226
608.709	621.333
608.968	617.357
609.228	611.839
609.487	630.872
609.746	625.803
610.006	618.04
610.265	624.404
610.524	629.616
610.784	654.64
611.043	630.439
611.302	644.038
611.562	600.816
611.821	641.098
612.08	664.518
612.339	645.624
612.599	630.288
612.858	648.336
613.117	632.705
613.376	650.642
613.635	658.138
613.895	668.218
614.154	669.861
614.413	666.892
614.672	684.732
614.931	692.067
615.19	697.546
615.449	709.979
615.709	702.702
615.968	718.439
616.227	727.009
616.486	721.73
616.745	707.305
617.004	711.258
617.263	708.342
617.522	717.998
617.781	711.565
618.04	726.213
618.299	729.865
618.557	729.116
618.816	731.787
619.075	725.94
619.334	726.7
619.593	735.535
619.852	745.954
620.111	755.482
620.37	733.291
620.628	732.331
620.887	742.474
621.146	747.921
621.373	732.788
621.633	752.933
621.893	747.858
622.153	759.793
622.413	758.094
622.673	716.62
622.932	752.399
623.192	763.015
623.452	736.906
623.712	744.773
623.972	770.226
624.232	765.535
624.492	762.244
624.751	760.042
625.011	773.667
625.271	775.332
625.531	761.763
625.791	776.141
626.05	779.358
626.31	786.837
626.57	769.564
626.83	805.19
627.089	799.635
627.349	785.903
627.609	806.448
627.868	817.903
628.128	795.473
628.388	813.702
628.647	808.361
628.907	807.17
629.167	821.809
629.426	812.313
629.686	845.729
629.945	831.615
630.205	822.859
630.465	843.205
630.724	843.467
630.984	841.724
631.243	859.504
631.503	849.394
631.762	864.431
632.022	857.532
632.281	863.891
632.541	877.945
632.8	877.446
633.06	890.053
633.319	892.041
633.579	919.575
633.838	916.305
634.097	941.767
634.357	933.547
634.616	963.797
634.876	981.958
635.135	1026.24
635.394	1044.18
635.654	1032.08
635.913	1087.93
636.172	1105.16
636.431	1145.09
636.691	1154.27
636.95	1205.88
637.209	1240.22
637.469	1252.78
637.728	1270.88
637.987	1261.43
638.246	1291.22
638.505	1280.16
638.765	1292.24
639.024	1280.18
639.283	1308.67
639.542	1290.3
639.801	1261.87
640.06	1244.25
640.319	1226.28
640.578	1181.74
640.838	1189.46
641.097	1152.58
641.356	1160.83
641.615	1167.17
641.874	1150.67
642.133	1157.95
642.392	1179.99
642.651	1138.85
642.91	1138.75
643.169	1142.24
643.428	1140.36
643.687	1158.97
643.946	1164.22
644.205	1174.69
644.463	1194.41
644.722	1185.02
644.981	1192.62
645.24	1186.88
645.499	1167.22
645.758	1181.76
646.017	1176.97
646.275	1199.29
646.534	1185.02
646.793	1228.61
647.052	1186.28
647.31	1245.38
647.569	1232.55
647.828	1229.26
648.087	1220.43
648.345	1236.18
648.604	1262
648.863	1265.42
649.121	1242.35
649.38	1266.61
649.639	1267.86
649.897	1272.18
650.156	1274.04
650.415	1292.82
650.673	1309.7
650.932	1331.19
651.19	1304.18
651.449	1347.79
651.707	1383.76
651.966	1360.87
652.224	1371.49
652.483	1342.88
652.741	1370.32
653	1379.4
653.258	1395.09
653.517	1413.97
653.775	1434.51
654.034	1421.07
654.292	1479.55
654.55	1441.23
654.809	1447.19
655.067	1444.54
655.326	1475.44
655.584	1497.34
655.842	1502.11
656.1	1537.4
656.359	1564.8
656.617	1567
656.875	1578.88
657.134	1604.62
657.392	1614.49
657.65	1609.14
657.908	1592.07
658.166	1630.68
658.425	1650.75
658.683	1620.4
658.941	1681.75
659.199	1676.86
659.457	1661.99
659.715	1683.35
659.973	1677.55
660.231	1688.91
660.49	1671.28
660.748	1664.53
661.006	1684.09
661.264	1668.52
661.522	1677.98
661.78	1642.19
662.038	1713.24
662.296	1667.19
662.554	1678.21
662.811	1657.4
663.069	1643.04
663.327	1634.3
663.585	1664.38
663.843	1654.88
664.101	1661.23
664.359	1669.17
664.617	1678.17
664.874	1656.8
665.132	1662.44
665.39	1660.63
665.648	1647.16
665.906	1667.84
666.163	1670.22
666.421	1661.46
666.679	1661.88
666.937	1660.3
667.194	1658.33
667.452	1669.17
667.71	1678.09
667.967	1664.91
668.225	1678.86
668.482	1652.7
668.74	1675.7
668.987	1649.69
669.245	1691.84
669.504	1694.58
669.763	1632.88
670.022	1680.64
670.281	1701.76
670.539	1666.32
670.798	1696.63
671.057	1693.88
671.316	1681.35
671.575	1690.62
671.833	1665.73
672.092	1663.76
672.351	1696.52
672.609	1729.01
672.868	1694.28
673.127	1708.46
673.385	1671.81
673.644	1709.29
673.903	1702.41
674.161	1723.66
674.42	1733.31
674.678	1742.8
674.937	1766.84
675.195	1746.86
675.454	1753.79
675.713	1735.92
675.971	1774.47
676.23	1800.49
676.488	1765.08
676.747	1772.87
677.005	1776.95
677.263	1809.37
677.522	1811.1
677.78	1792.33
678.039	1797.35
678.297	1810.04
678.556	1817.67
678.814	1780.95
679.072	1844.61
679.331	1833.05
679.589	1802.1
679.847	1819.29
680.106	1836.81
680.364	1840.76
680.622	1820.44
680.881	1814.89
681.139	1839.12
681.397	1828.87
681.656	1821.78
681.914	1842.2
682.172	1823.93
682.43	1838.91
682.688	1852.81
682.947	1831.9
683.205	1855.88
683.463	1868.92
683.721	1841.86
683.979	1830.16
684.237	1851.76
684.495	1866.02
684.754	1831.94
685.012	1837.54
685.27	1841.68
685.528	1803.66
685.786	1811.01
686.044	1818.51
686.302	1796.92
686.56	1806.78
686.818	1819.85
687.076	1848.19
687.334	1818.38
687.592	1818.75
687.85	1812.08
688.108	1799.55
688.366	1811.19
688.623	1797.13
688.881	1827.71
689.139	1842.9
689.397	1817.02
689.655	1791.11
689.913	1794.52
690.171	1811.32
690.428	1771.39
690.686	1791.95
690.944	1778.14
691.202	1811.84
691.459	1813.44
691.717	1765.56
691.975	1778.84
692.233	1796.46
692.49	1776.51
692.748	1775.05
693.006	1774.86
693.263	1745.26
693.521	1745.77
693.779	1758.06
694.036	1768.79
694.294	1761.33
694.552	1758.35
694.809	1754.49
695.067	1773.32
695.324	1765.32
695.582	1788.47
695.839	1719.72
696.097	1748.18
696.354	1772.24
696.612	1721.63
696.869	1753.45
697.127	1748.31
697.384	1720.61
697.642	1730.67
697.899	1734.32
698.156	1712.53
698.414	1735.7
698.671	1714.71
698.928	1727.5
699.186	1731.98
699.443	1713.78
699.7	1706.4
699.958	1711.43
700.215	1741.24
700.472	1726.98
700.73	1721.11
700.987	1719.52
701.244	1714.58
701.501	1702.93
701.758	1664.84
702.016	1669.31
702.273	1689
702.53	1692.67
702.787	1700.88
703.044	1669.45
703.301	1680.53
703.558	1710.21
703.816	1654.51
704.073	1694.89
704.33	1709.09
704.587	1731.22
704.844	1697.14
705.101	1669.8
705.358	1686.24
705.615	1673.11
705.872	1691.65
706.129	1641.61
706.386	1650.19
706.643	1681.97
706.899	1672.31
707.156	1634.8
707.413	1666.66
707.67	1644.64
707.927	1660.35
708.184	1665.73
708.441	1650.2
708.697	1659.14
708.954	1664.83
709.211	1635.93
709.468	1614.07
709.725	1602.41
709.981	1660.38
710.238	1641.47
710.495	1659.8
710.751	1644.03
711.008	1635.45
711.265	1656.06
711.521	1628.97
711.778	1637.5
712.035	1645.41
712.291	1627.93
712.548	1646.99
712.804	1638.11
713.061	1651.14
713.317	1607.95
713.574	1609.89
713.831	1603.02
714.087	1600.05
714.343	1589.06
714.6	1604.85
714.856	1580.67
715.113	1570.47
715.369	1581.9
715.626	1559.6
715.882	1574.19
716.138	1569.65
716.395	1570.6
716.639	1561.53
716.897	1535.45
717.155	1528.32
717.412	1543.34
717.67	1537.14
717.927	1538.55
718.185	1509.58
718.443	1526.64
718.7	1531.44
718.958	1523.88
719.215	1527.33
719.473	1519.33
719.73	1524.44
719.988	1512.55
720.245	1509.03
720.503	1527.98
720.76	1523.3
721.018	1485.53
721.275	1465.84
721.532	1482.14
721.79	1439.07
722.047	1440.95
722.305	1484.69
722.562	1453.38
722.819	1444.02
723.077	1453.68
723.334	1448.08
723.591	1408.61
723.849	1443.91
724.106	1420.39
724.363	1434.3
724.621	1466.38
724.878	1404.25
725.135	1438.41
725.392	1426.67
725.65	1393.92
725.907	1414.77
726.164	1436.67
726.421	1405.35
726.678	1396.58
726.935	1397.53
727.193	1412.27
727.45	1381.98
727.707	1379.46
727.964	1362.12
728.221	1388.9
728.478	1351.07
728.735	1375.11
728.992	1361.81
729.249	1360.99
729.506	1341.82
729.763	1341.16
730.02	1330.6
730.277	1332.11
730.534	1344.88
730.791	1321.8
731.048	1334.78
731.305	1302.72
731.562	1352.4
731.819	1325.62
732.076	1321.69
732.333	1288.54
732.589	1304.2
732.846	1288.69
733.103	1281.05
733.36	1301.78
733.617	1278.22
733.873	1287.28
734.13	1287.68
734.387	1289.59
734.644	1251.48
734.901	1291.86
735.157	1260.46
735.414	1290.05
735.671	1262.44
735.927	1239.81
736.184	1254.05
736.441	1264.5
736.697	1287.55
736.954	1253.65
737.211	1258.16
737.467	1235.54
737.724	1288.83
737.98	1273.51
738.237	1240.28
738.493	1263.68
738.75	1231.96
739.006	1214.04
739.263	1240.91
739.519	1231.95
739.776	1250.14
740.032	1220.84
740.289	1220.43
740.545	1193.58
740.802	1218.26
741.058	1173.95
741.314	1169.91
741.571	1172.63
741.827	1176.85
742.083	1164.47
742.34	1178.44
742.596	1152.45
742.852	1097.29
743.109	1151.4
743.365	1154.49
743.621	1143.16
743.878	1119.6
744.134	1138.21
744.39	1146.47
744.646	1130.82
744.902	1120.42
745.159	1118.34
745.415	1092.85
745.671	1126.46
745.927	1103.78
746.183	1080.74
746.439	1061.63
746.695	1091.49
746.951	1094.2
747.207	1083.8
747.463	1051.58
747.719	1077.96
747.975	1065.63
748.231	1032.25
748.487	1065.41
748.743	1047.34
748.999	1015.73
749.255	1046.66
749.511	1035.88
749.767	1036.89
750.023	1028.48
750.279	1039.85
750.535	1024.09
750.791	1023.14
751.046	1014.92
751.302	991.629
751.558	994.685
751.814	998.533
752.07	1022.68
752.325	1013.63
752.581	968.828
752.837	974.178
753.092	1002.13
753.348	996.294
753.604	968.585
753.859	967.537
754.115	983.556
754.371	979.623
754.626	968.951
754.882	959.771
755.138	963.476
755.393	937.537
755.649	943.189
755.904	960.509
756.16	950.704
756.415	938.668
756.671	943.347
756.926	942.843
757.182	936.451
757.437	925.808
757.693	919.446
757.948	913.592
758.203	893.417
758.459	921.957
758.714	910.121
758.97	893.264
759.225	907.912
759.48	899.071
759.736	876.496
759.991	891.535
760.246	876.465
760.501	870.8
760.757	881.954
761.012	875.119
761.267	876.729
761.522	875.153
761.777	890.148
762.033	852.942
762.288	839.618
762.543	871.733
762.798	850.569
763.053	860.586
763.308	833.948
763.563	842.95
763.78	822.95
764.037	835.896
764.293	810.121
764.55	831.058
764.806	820.401
765.062	799.275
765.319	783.959
765.575	824.044
765.831	797.912
766.088	795.841
766.344	801.571
766.6	796.641
766.857	786.864
767.113	804.622
767.369	811.558
767.625	775.178
767.882	802.961
768.138	794.376
768.394	760.975
768.65	793.04
768.906	745.055
769.163	758.205
769.419	776.043
769.675	732.94
769.931	742.395
770.187	731.413
770.443	718.281
770.699	744.393
770.955	738.203
771.211	751.269
771.467	742.762
771.723	692.628
771.979	724.3
772.235	700.057
772.491	724.522
772.747	725.386
773.003	691.908
773.259	710.391
773.515	667.243
773.771	678.796
774.027	699.326
774.283	707.592
774.539	686.78
774.795	670.047
775.05	695.438
775.306	678.72
775.562	683.935
775.818	674.861
776.074	645.061
776.329	684.73
776.585	675.868
776.841	669.976
777.097	672.657
777.352	647.931
777.608	644.244
777.864	659.973
778.12	657.43
778.375	638.065
778.631	633.619
778.886	613.943
779.142	629.769
779.398	644.951
779.653	626.641
779.909	631.461
780.164	631.853
780.42	621.055
780.675	623.859
780.931	629.361
781.187	601.957
781.442	630.7
781.698	620.559
781.953	588.696
782.208	596.029
782.464	600.523
782.719	574.097
782.975	601.018
783.23	591.271
783.485	594.917
783.741	572.551
783.996	563.97
784.252	591.603
784.507	567.53
784.762	581.982
785.017	565.548
785.273	577.996
785.528	552.93
785.783	567.133
786.038	555.531
786.294	549.817
786.549	548.105
786.804	556.916
787.059	554.486
787.314	564.956
787.57	524.579
787.825	523.542
788.08	528.212
788.335	517.656
788.59	526.324
788.845	539.034
789.1	538.156
789.355	518.442
789.61	528.677
789.865	529.947
790.12	517.889
790.375	503.698
790.63	514.252
790.885	529.172
791.14	515.016
791.395	491.831
791.65	507.029
791.905	502.042
792.16	485.951
792.414	507.252
792.669	479.892
792.924	491.279
793.179	464.591
793.434	488.645
793.689	516.04
793.943	490.69
794.198	477.574
794.453	480.606
794.708	465.102
794.962	474.787
795.217	481.516
795.472	469.276
795.726	463.837
795.981	471.031
796.236	473.621
796.49	466.903
796.745	455.639
796.999	445.922
797.254	469.866
797.508	450.186
797.763	429.933
798.018	471.316
798.272	434.965
798.526	442.075
798.781	429
799.035	431.831
799.29	450.048
799.544	442.247
799.799	413.174
800.053	409.054
800.307	431.33
800.562	434.59
800.816	433.544
801.07	399.712
801.325	409.394
801.579	425.663
801.833	380.593
802.088	409.606
802.342	381.795
802.596	426.088
802.85	381.044
803.105	426.001
803.359	389.405
803.613	396.641
803.867	395.565
804.121	383.156
804.375	390.452
804.63	373.339
804.884	398.157
805.138	381.055
805.392	372.464
805.646	392.496
805.9	380.18
806.154	395.49
806.408	374.043
806.662	374.146
806.916	366.051
807.17	363.647
807.424	377.521
807.678	356.805
807.931	387.307
808.185	360.766
808.439	360.034
808.693	340.226
808.947	344.296
809.201	345.944
809.454	347.547
809.708	356.358
809.962	380.736
810.216	347.24
810.469	336.762
810.678	347.928
810.933	337.12
811.188	344.472
811.443	352.088
811.699	352.808
811.954	344.296
812.209	311.699
812.464	340.325
812.719	334.023
812.974	345.743
813.229	325.591
813.484	330.696
813.739	319.537
813.994	327.635
814.249	344.752
814.504	325.461
814.759	343.536
815.014	327.294
815.268	327.652
815.523	337.683
815.778	323.236
816.033	310.985
816.288	297.726
816.543	317.295
816.798	310.45
817.052	308.953
817.307	306.753
817.562	300.363
817.817	298.717
818.071	306.006
818.326	304.137
818.581	307.105
818.836	285.896
819.09	308.526
819.345	281.975
819.6	326.959
819.854	308.524
820.109	276.888
820.364	289.299
820.618	305.02
820.873	302.921
821.127	301.263
821.382	284.085
821.637	279.492
821.891	267.456
822.146	278.028
822.4	268.286
822.655	276.852
822.909	277.486
823.164	277.66
823.418	264.847
823.672	275.265
823.927	265.148
824.181	257.75
824.436	275.842
824.69	263.614
824.944	268.831
825.199	271.728
825.453	261.982
825.707	282.857
825.962	254.763
826.216	252.309
826.47	249.578
826.725	224.101
826.979	270.263
827.233	250.228
827.487	253.125
827.741	247.685
827.996	238.164
828.25	233.761
828.504	231.003
828.758	246.955
829.012	244.632
829.266	224.079
829.52	242.313
829.774	232.237
830.029	250.878
830.283	240.837
830.537	253.954
830.791	230.52
831.045	246.485
831.299	218.155
831.553	218.362
831.807	239.291
832.061	229.022
832.315	229.174
832.568	232.208
832.822	232.375
833.076	224.724
833.33	206.756
833.584	217.387
833.838	212.32
834.092	220.438
834.345	209.93
834.599	223.426
834.853	228.867
835.107	213.131
835.36	234.104
835.614	218.528
835.868	223.849
836.122	232.301
836.375	213.809
836.629	205.582
836.883	197.686
837.136	216.383
837.39	216.226
837.643	195.292
837.897	213.967
838.151	203.154
838.404	197.762
838.658	194.955
838.911	189.762
839.165	187.265
839.418	198.061
839.672	205.898
839.925	203.467
840.179	206.372
840.432	177.283
840.686	206.456
840.939	204.082
841.192	183.113
841.446	185.922
841.699	191.451
841.952	178.308
842.206	201.925
842.459	196.621
842.712	204.692
842.966	162.144
843.219	175.568
843.472	194.38
843.725	186.7
843.979	184.108
844.232	186.685
844.485	189.538
844.738	187.031
844.991	197.793
845.244	189.88
845.497	173.922
845.75	166.118
846.004	176.934
846.257	179.745
846.51	171.77
846.763	193.502
847.016	179.881
847.269	177.308
847.522	185.384
847.775	164.077
848.028	158.794
848.281	158.977
848.534	183.357
848.786	183.672
849.039	167.62
849.292	176.017
849.545	162.483
849.798	168.256
850.051	168.228
850.303	168.271
850.556	168.388
850.809	152.256
851.062	168.597
851.314	176.834
851.567	163.702
851.82	150.159
852.073	158.476
852.325	147.804
852.578	158.191
852.831	150.376
853.083	157.903
853.336	164.233
853.588	150.146
853.841	150.284
854.093	153.714
854.346	141.978
854.598	147.886
854.851	146.7
855.103	151.206
855.356	150.066
855.608	152.758
855.861	154.879
856.113	139.879
856.366	151.482
856.618	150.07
856.87	148.772
857.123	145.489
857.352	133.041
857.606	138.618
857.859	135.815
858.113	138.724
858.367	144.295
858.621	152.486
858.875	155.192
859.128	141.409
859.382	149.66
859.636	146.957
859.889	124.763
860.143	130.44
860.397	149.761
860.65	138.872
860.904	133.287
861.158	130.531
861.411	147.363
861.665	130.736
861.918	144.501
862.172	130.404
862.425	122.142
862.679	138.695
862.932	127.632
863.186	136.302
863.439	124.946
863.693	133.296
863.946	133.497
864.2	133.517
864.453	116.938
864.707	139.108
864.96	130.639
865.213	130.732
865.467	127.969
865.72	128.079
865.973	114.294
866.227	122.747
866.48	131.087
866.733	125.529
866.987	131.13
867.24	131.379
867.493	125.73
867.746	114.671
867.999	139.945
868.253	114.807
868.506	126.116
868.759	117.914
869.012	137.673
869.265	120.914
869.518	118.132
869.771	112.468
870.025	123.763
870.278	126.606
870.531	107.114
870.784	132.703
871.037	121.466
871.29	121.431
871.543	121.614
871.796	135.918
872.049	116.105
872.302	113.365
872.555	127.49
872.808	113.332
873.06	121.867
873.313	116.32
873.566	107.785
873.819	136.306
874.072	99.1684
874.325	119.03
874.578	119.285
874.83	93.7153
875.083	107.888
875.336	119.215
875.589	110.795
875.841	113.61
876.094	116.462
876.347	122.266
876.6	110.877
876.852	93.907
877.105	116.754
877.358	114.008
877.61	108.288
877.863	114.006
878.115	105.541
878.368	88.5824
878.621	103.039
878.873	108.761
879.126	108.693
879.378	106.105
879.631	114.882
879.883	106.259
880.136	120.675
880.388	106.487
880.641	109.561
880.893	95.2617
881.145	95.2669
881.398	98.3462
881.65	110.047
881.902	101.439
882.155	89.8949
882.407	101.481
882.659	78.3464
882.912	104.672
883.164	101.851
883.416	113.627
883.669	93.2639
883.921	105.058
884.173	108.068
884.425	111.13
884.677	105.291
884.93	120.069
885.182	105.371
885.434	96.5312
885.686	93.6838
885.938	93.6926
886.19	87.9343
886.442	105.518
886.694	96.8098
886.946	108.583
887.198	91.1946
887.45	91.2838
887.702	82.4777
887.954	82.5928
888.206	91.5137
888.458	100.542
888.71	103.462
888.962	82.8542
889.214	85.8501
889.466	91.8528
889.718	77.0884
889.969	80.179
890.221	92.159
890.473	86.3029
890.725	101.511
890.977	92.6182
891.228	98.662
891.48	98.7816
891.732	95.8468
891.983	93.1374
892.235	96.2154
892.487	90.4091
892.738	96.6462
892.99	96.8579
893.242	75.6883
893.493	84.7895
893.745	90.9718
893.996	88.0657
894.248	94.2652
894.5	91.2201
894.751	82.2841
895.003	91.6371
895.254	85.7663
895.505	88.9209
895.757	85.9479
896.008	89.1107
896.26	92.3098
896.511	92.3965
896.763	83.1577
897.014	74.1266
897.265	86.5384
897.517	83.3716
897.768	83.4815
898.019	80.6104
898.27	86.6365
898.522	68.1579
898.773	77.7439
899.024	99.5325
899.275	71.5633
899.527	74.5909
899.778	81.0493
899.979	90.5458