File: LT_191023_M1_centro_01.txt
#Acq. time (s)=	5
#Accumulations=	2
#Range (nm)=	520...900
#Windows=	8
#Auto scanning=	Off
#Autofocus=	Off
#AutoExposure=	Off
#Spike filter=	Multiple accum.
#Delay time (s)=	0
#Binning=	1
#Readout mode=	Signal
#DeNoise=	Off
#ICS correction=	On
#Dark correction=	Off
#Inst. Process=	Off
#Detector temperature (°C)=	-59.98
#Instrument=	LabRAM HR Evol
#Detector=	Syncerity OE
#Objective=	x50_VIS
#Grating=	600 (500nm)
#ND Filter=	10%
#Laser=	514nm_Edge
#Hole=	199.981
#Range=	Auto
#StageXY=	Marzhauser
#StageZ=	Marzhauser
#X (µm)=	-1976
#Y (µm)=	7193.7
#Z (µm)=	-4.7
#Full time(mm:ss)=	1:47
#Project=
#Sample=
#Site=
#Title=	LT_191023_M1_centro
#Remark=
#Date=	27.10.2023 13:25
#Acquired=	27.10.2023 13:25:25
520.044	23.4223
520.306	33.8871
520.569	35.5379
520.831	32.1211
521.093	26.8396
521.355	37.5356
521.617	35.57
521.88	28.3595
522.142	31.9189
522.404	32.0882
522.666	30.4116
522.928	26.8538
523.19	31.9941
523.453	37.0706
523.715	24.6239
523.977	33.4553
524.239	33.6668
524.501	33.858
524.763	21.4441
525.025	35.6207
525.287	37.2923
525.549	23.0854
525.811	30.1993
526.073	30.4042
526.335	25.2095
526.597	34.3582
526.859	32.5359
527.121	37.8424
527.383	30.5998
527.645	35.9239
527.907	32.3163
528.169	27.0309
528.431	39.891
528.693	38.3293
528.955	38.4625
529.217	32.9286
529.479	36.4375
529.741	34.4231
530.003	36.1642
530.264	37.9224
530.526	32.5981
530.788	38.2953
531.05	34.9131
531.312	40.5484
531.574	37.0334
531.835	31.5422
532.097	31.6393
532.359	46.6102
532.621	33.7089
532.883	39.3876
533.144	41.2423
533.406	37.4658
533.668	35.5887
533.93	39.212
534.191	48.3687
534.453	40.7215
534.715	48.1617
534.976	48.2769
535.238	42.854
535.5	37.292
535.761	50.5118
536.023	50.7201
536.285	48.8304
536.546	54.2705
536.808	50.4785
537.069	53.9132
537.331	59.1755
537.593	66.3072
537.854	88.2028
538.116	86.1294
538.377	91.8123
538.639	95.5739
538.9	119.64
539.162	138.043
539.423	104.698
539.685	104.631
539.946	67.8239
540.208	71.368
540.469	64.1053
540.731	69.7992
540.992	51.456
541.254	57.1303
541.515	59.0626
541.776	49.8461
542.038	46.2626
542.299	59.0387
542.56	60.6315
542.822	53.1777
543.083	51.2249
543.344	62.1569
543.606	60.5114
543.867	56.7749
544.128	76.9788
544.39	62.4282
544.651	64.3407
544.912	62.5056
545.174	66.1227
545.435	62.3149
545.696	52.9358
545.957	61.9631
546.218	67.1551
546.48	65.1727
546.741	63.3419
547.002	87.0218
547.263	72.5165
547.524	76.1205
547.785	79.858
548.047	78.0659
548.308	79.9289
548.569	72.5259
548.83	81.5508
549.091	74.2225
549.352	77.4958
549.613	80.9602
549.874	77.0873
550.135	94.9198
550.396	92.7336
550.657	94.5076
550.918	83.7126
551.179	104.888
551.44	117.058
551.701	133.107
551.962	191.499
552.223	500.336
552.484	12725
552.745	906.704
553.006	189.771
553.267	136.694
553.528	113.888
553.788	104.764
554.049	94.1527
554.31	94.1988
554.571	97.6388
554.832	97.4983
555.093	111.445
555.353	93.503
555.614	101.845
555.875	94.5653
556.136	101.462
556.396	97.7444
556.657	94.3339
556.918	104.696
557.179	108.32
557.439	101.631
557.7	112.426
557.961	103.972
558.221	107.832
558.482	107.842
558.743	127.171
559.003	114.841
559.264	121.41
559.525	113.748
559.785	113.458
560.046	114.488
560.306	119.067
560.567	121.593
560.827	117.536
561.088	110.242
561.348	130.255
561.609	128.451
561.869	130.238
562.13	120.168
562.39	133.733
562.651	132.389
562.911	141.131
563.172	156.753
563.432	151.719
563.692	148.186
563.953	141.021
564.213	152.822
564.474	152.373
564.734	154.942
564.994	159.029
565.255	150.09
565.515	168.977
565.775	156.669
566.035	146.228
566.296	150.498
566.556	162.975
566.816	155.94
567.076	164.064
567.337	162.567
567.597	170.91
567.857	164.655
568.117	173.176
568.377	177.912
568.637	166.763
568.898	177.81
569.158	188.805
569.418	195.024
569.678	202.209
569.938	192.04
570.198	196.15
570.458	208.298
570.718	218.236
570.978	224.36
571.238	225.588
571.498	231.927
571.758	252.004
572.018	259.372
572.278	264.335
572.538	290.847
572.798	313.997
573.058	323.437
573.312	360.252
573.573	383.517
573.834	389.326
574.095	411.004
574.356	442.398
574.617	479.195
574.878	477.993
575.139	515.076
575.4	507.791
575.661	498.727
575.922	481.351
576.183	469.576
576.444	453.656
576.705	448.484
576.965	412.644
577.226	415.096
577.487	390.72
577.748	372.089
578.009	381.959
578.27	357.298
578.531	364.011
578.791	337.232
579.052	341.721
579.313	335.494
579.574	345.227
579.835	338.27
580.095	345.612
580.356	345.889
580.617	346.397
580.878	335.819
581.138	352.914
581.399	368.731
581.66	355.886
581.92	347.12
582.181	367.51
582.442	364.241
582.703	372.995
582.963	392.744
583.224	379.517
583.484	387.398
583.745	384.355
584.006	391.373
584.266	407.114
584.527	403.327
584.787	420.273
585.048	426.884
585.308	419.596
585.569	411.652
585.83	424.731
586.09	416.878
586.351	451.759
586.611	448.435
586.872	452.704
587.132	451.844
587.392	466.195
587.653	480.114
587.913	461.502
588.174	464.167
588.434	470.007
588.695	463.057
588.955	475.783
589.215	469.564
589.476	489.208
589.736	467.374
589.996	472.19
590.257	462.926
590.517	445.378
590.777	449.562
591.038	452.559
591.298	442.246
591.558	435.194
591.818	441.503
592.079	423.709
592.339	412.75
592.599	419.282
592.859	451.755
593.12	417.631
593.38	430.195
593.64	437.386
593.9	442.537
594.16	439.211
594.42	425.087
594.68	440.468
594.941	454.035
595.201	459.33
595.461	434.381
595.721	448.42
595.981	462.841
596.241	467.779
596.501	472.896
596.761	463.433
597.021	471.082
597.281	456.37
597.541	466.206
597.801	467.692
598.061	469.693
598.321	478.12
598.581	458.267
598.841	472.968
599.101	480.069
599.361	478.768
599.62	470.95
599.88	474.393
600.14	468.073
600.4	488.218
600.66	464.623
600.92	474.788
601.18	480.354
601.439	481.448
601.699	460.18
601.959	497.889
602.219	460.178
602.478	463.453
602.738	473.182
602.998	487.66
603.258	466.636
603.517	475.739
603.777	481.259
604.037	488.892
604.296	462.495
604.556	486.02
604.816	478.864
605.075	466.675
605.335	472.636
605.594	490.026
605.854	499.937
606.114	492.794
606.373	498.651
606.633	489.524
606.892	482.347
607.152	496.234
607.411	491.297
607.671	492.634
607.93	504.611
608.19	485.345
608.449	504.406
608.709	502.68
608.968	506.615
609.228	506.262
609.487	511.311
609.746	501.151
610.006	532.837
610.265	519.068
610.524	506.733
610.784	522.952
611.043	534.228
611.302	536.487
611.562	536.443
611.821	525.222
612.08	531.363
612.339	527.782
612.599	542.922
612.858	562.307
613.117	544.449
613.376	550.257
613.635	560.59
613.895	559.925
614.154	541.042
614.413	570.046
614.672	558.565
614.931	557.566
615.19	555.838
615.449	578.231
615.709	584.57
615.968	584.719
616.227	577.074
616.486	578.7
616.745	598.532
617.004	586.708
617.263	575.045
617.522	571.963
617.781	590.096
618.04	587.349
618.299	574.493
618.557	597.416
618.816	599.454
619.075	607.205
619.334	613.991
619.593	604.305
619.852	603.433
620.111	604.51
620.37	586.758
620.628	608.765
620.887	601.488
621.146	611.222
621.373	608.308
621.633	600.707
621.893	612.097
622.153	619.307
622.413	609.746
622.673	628.062
622.932	614.013
623.192	623.651
623.452	641.896
623.712	644.159
623.972	624.944
624.232	640.245
624.492	611.861
624.751	635.276
625.011	612.771
625.271	629.602
625.531	642.382
625.791	656.997
626.05	628.697
626.31	650.98
626.57	641.681
626.83	653.864
627.089	634.738
627.349	670.727
627.609	667.716
627.868	648.914
628.128	664.957
628.388	664.224
628.647	676.82
628.907	686.881
629.167	674.536
629.426	678.613
629.686	703.279
629.945	679.395
630.205	705.467
630.465	694.667
630.724	692.848
630.984	719.088
631.243	731.635
631.503	710.604
631.762	719.065
632.022	726.797
632.281	731.155
632.541	753.948
632.8	731.39
633.06	785.016
633.319	781.64
633.579	779.375
633.838	819.272
634.097	817.3
634.357	809.147
634.616	844.701
634.876	892.689
635.135	873.189
635.394	907.603
635.654	934.152
635.913	982.323
636.172	1014.98
636.431	1044.99
636.691	1113.68
636.95	1097.15
637.209	1123.88
637.469	1120.15
637.728	1129.55
637.987	1110.19
638.246	1102.69
638.505	1055.86
638.765	1065.93
639.024	1035.3
639.283	1039.08
639.542	994.47
639.801	976.968
640.06	969.447
640.319	962.497
640.578	958.932
640.838	948.297
641.097	958.488
641.356	976.799
641.615	976.638
641.874	933.154
642.133	956.803
642.392	966.834
642.651	963.893
642.91	968.316
643.169	962.339
643.428	966.168
643.687	981.661
643.946	970.727
644.205	981.604
644.463	966.954
644.722	990.935
644.981	998.526
645.24	1020.87
645.499	1007.71
645.758	1008
646.017	1008.22
646.275	993.634
646.534	1020.68
646.793	1010.14
647.052	1037.05
647.31	1034.58
647.569	1032.88
647.828	1046.87
648.087	1053.32
648.345	1063.59
648.604	1064.78
648.863	1049.14
649.121	1092.84
649.38	1089.35
649.639	1096.09
649.897	1091.05
650.156	1105.81
650.415	1139.53
650.673	1116.47
650.932	1159.42
651.19	1121.71
651.449	1145.89
651.707	1145.07
651.966	1184.44
652.224	1185.4
652.483	1160.89
652.741	1181.64
653	1216.8
653.258	1224.88
653.517	1234.4
653.775	1234.79
654.034	1253.89
654.292	1250.44
654.55	1238.39
654.809	1281.07
655.067	1251.22
655.326	1290.75
655.584	1279.2
655.842	1313.82
656.1	1319.58
656.359	1335.67
656.617	1346.61
656.875	1384.94
657.134	1388.21
657.392	1391.4
657.65	1384.09
657.908	1401.66
658.166	1408.17
658.425	1417.21
658.683	1423.83
658.941	1433.9
659.199	1441.27
659.457	1422.73
659.715	1449.58
659.973	1416.6
660.231	1425.88
660.49	1412.44
660.748	1434.94
661.006	1425.16
661.264	1450.43
661.522	1403.25
661.78	1421.61
662.038	1388.71
662.296	1407.87
662.554	1389.08
662.811	1391.8
663.069	1374.24
663.327	1387.44
663.585	1389.76
663.843	1392.63
664.101	1386.72
664.359	1401.55
664.617	1367.81
664.874	1383.19
665.132	1391.36
665.39	1405.31
665.648	1402.66
665.906	1399.55
666.163	1410.63
666.421	1406.68
666.679	1400.56
666.937	1403.02
667.194	1397.45
667.452	1421.99
667.71	1419.16
667.967	1413.23
668.225	1412.19
668.482	1419.31
668.74	1435.82
668.987	1419.52
669.245	1460.14
669.504	1437.57
669.763	1420.12
670.022	1433.05
670.281	1421.99
670.539	1430.53
670.798	1450.65
671.057	1454.3
671.316	1415.82
671.575	1419.15
671.833	1420.43
672.092	1444.79
672.351	1453.41
672.609	1462.12
672.868	1447.61
673.127	1468.86
673.385	1441.9
673.644	1461.1
673.903	1461.73
674.161	1461.59
674.42	1475.07
674.678	1438.59
674.937	1463.6
675.195	1495.55
675.454	1501.18
675.713	1515.96
675.971	1520.97
676.23	1504.9
676.488	1537.29
676.747	1567.43
677.005	1545.94
677.263	1555.68
677.522	1551.62
677.78	1535.53
678.039	1570.7
678.297	1539.7
678.556	1553.62
678.814	1555.69
679.072	1552.14
679.331	1540.9
679.589	1561.05
679.847	1562.84
680.106	1536.62
680.364	1546.36
680.622	1529.92
680.881	1572.9
681.139	1568.2
681.397	1571.31
681.656	1554.85
681.914	1561.98
682.172	1547.96
682.43	1597.88
682.688	1575.67
682.947	1541.29
683.205	1569.96
683.463	1573.06
683.721	1573.52
683.979	1578.55
684.237	1534.94
684.495	1575.08
684.754	1586.57
685.012	1566.48
685.27	1573.78
685.528	1562.05
685.786	1548.24
686.044	1540.84
686.302	1548.63
686.56	1550.17
686.818	1549.5
687.076	1566.44
687.334	1519.33
687.592	1543.95
687.85	1525.24
688.108	1563.23
688.366	1515.25
688.623	1542.93
688.881	1525.36
689.139	1516.58
689.397	1536.67
689.655	1543.77
689.913	1515.7
690.171	1519.74
690.428	1532.12
690.686	1519.43
690.944	1523.22
691.202	1492.79
691.459	1532.91
691.717	1511.06
691.975	1506.39
692.233	1536.49
692.49	1507.7
692.748	1527.1
693.006	1484.91
693.263	1495.94
693.521	1497.14
693.779	1451.71
694.036	1472.03
694.294	1516.59
694.552	1501.97
694.809	1493.77
695.067	1477.94
695.324	1481.46
695.582	1482.89
695.839	1476.96
696.097	1503.82
696.354	1483.16
696.612	1490.2
696.869	1498.62
697.127	1485.19
697.384	1473.25
697.642	1460.46
697.899	1476.53
698.156	1471.5
698.414	1463.67
698.671	1459.05
698.928	1477.09
699.186	1473.51
699.443	1444.17
699.7	1464.68
699.958	1474.04
700.215	1440.72
700.472	1441.54
700.73	1457.6
700.987	1443.21
701.244	1439.28
701.501	1440.18
701.758	1449.46
702.016	1406.66
702.273	1432.19
702.53	1451.17
702.787	1448.49
703.044	1444.15
703.301	1431.81
703.558	1434.19
703.816	1430
704.073	1409.63
704.33	1432.21
704.587	1449.19
704.844	1424.34
705.101	1434.3
705.358	1396.01
705.615	1422.48
705.872	1443.84
706.129	1411.46
706.386	1435.09
706.643	1394.42
706.899	1406.75
707.156	1413.54
707.413	1412.02
707.67	1424.13
707.927	1382.47
708.184	1393.28
708.441	1417.75
708.697	1397.96
708.954	1378.54
709.211	1363.86
709.468	1392.56
709.725	1387.99
709.981	1378.45
710.238	1360.17
710.495	1382.39
710.751	1390.75
711.008	1354.92
711.265	1381.71
711.521	1386.02
711.778	1377.56
712.035	1384.5
712.291	1372.18
712.548	1384.67
712.804	1378.89
713.061	1347.88
713.317	1366.54
713.574	1356.06
713.831	1352.01
714.087	1354.79
714.343	1350.02
714.6	1356.47
714.856	1326.19
715.113	1339.43
715.369	1335.83
715.626	1321.66
715.882	1326.28
716.138	1317.84
716.395	1308.52
716.639	1295.17
716.897	1315.23
717.155	1304.21
717.412	1303.07
717.67	1280.54
717.927	1307.33
718.185	1302.72
718.443	1267.05
718.7	1256.82
718.958	1286
719.215	1276.29
719.473	1285.4
719.73	1282.43
719.988	1257.12
720.245	1241.84
720.503	1292.81
720.76	1253.44
721.018	1289.73
721.275	1209.1
721.532	1239.77
721.79	1249.65
722.047	1232.91
722.305	1231.49
722.562	1257.46
722.819	1231.13
723.077	1205.61
723.334	1233.12
723.591	1163.97
723.849	1217.41
724.106	1190.75
724.363	1205.38
724.621	1217.66
724.878	1181.23
725.135	1174.64
725.392	1181.72
725.65	1174.65
725.907	1177.01
726.164	1183.91
726.421	1176.82
726.678	1159.65
726.935	1155.57
727.193	1162.73
727.45	1167.21
727.707	1137.52
727.964	1150.5
728.221	1165.28
728.478	1128.15
728.735	1147.28
728.992	1121.89
729.249	1112.29
729.506	1093.99
729.763	1133.45
730.02	1136.38
730.277	1145.37
730.534	1109.18
730.791	1106.37
731.048	1096.52
731.305	1110.24
731.562	1089.48
731.819	1100.01
732.076	1077.81
732.333	1045.71
732.589	1097.39
732.846	1099.96
733.103	1072.24
733.36	1104.11
733.617	1053.65
733.873	1071.08
734.13	1066.93
734.387	1081.5
734.644	1067.23
734.901	1091.69
735.157	1071.46
735.414	1072.67
735.671	1070.73
735.927	1072.04
736.184	1052.15
736.441	1065.81
736.697	1061.83
736.954	1060.34
737.211	1036.38
737.467	1056.39
737.724	1061.73
737.98	1053.45
738.237	1057.22
738.493	1019.73
738.75	1053.33
739.006	1032.71
739.263	1024.18
739.519	1003.97
739.776	1000.96
740.032	1025.17
740.289	1013.48
740.545	984.032
740.802	989.923
741.058	963.861
741.314	947
741.571	983.585
741.827	987.588
742.083	952.356
742.34	981.795
742.596	971.309
742.852	934.625
743.109	942.837
743.365	928.459
743.621	941.176
743.878	976.249
744.134	950.186
744.39	961.372
744.646	945.462
744.902	924.816
745.159	904.157
745.415	917.192
745.671	927.672
745.927	896.281
746.183	913.588
746.439	910.378
746.695	938.65
746.951	899.577
747.207	886.351
747.463	892.909
747.719	880.788
747.975	872.661
748.231	865.249
748.487	846.572
748.743	854.297
748.999	865.465
749.255	834.151
749.511	842.288
749.767	866.242
750.023	850.56
750.279	871.856
750.535	854.375
750.791	830.126
751.046	853.52
751.302	843.103
751.558	832.793
751.814	833.329
752.07	833.405
752.325	815.024
752.581	834.638
752.837	829.527
753.092	808.499
753.348	848.256
753.604	817.521
753.859	789.735
754.115	800.811
754.371	815.856
754.626	788.577
754.882	786.624
755.138	794.419
755.393	780.282
755.649	802.235
755.904	784.641
756.16	803.285
756.415	765.677
756.671	788.132
756.926	763.326
757.182	743.119
757.437	736.713
757.693	766.457
757.948	770.938
758.203	746.034
758.459	760.691
758.714	759.416
758.97	747.888
759.225	749.866
759.48	729.747
759.736	735.141
759.991	730.119
760.246	730.678
760.501	732.784
760.757	718.776
761.012	710.814
761.267	718.667
761.522	714.535
761.777	707.689
762.033	715.607
762.288	720.042
762.543	712.382
762.798	708.757
763.053	692.915
763.308	705.853
763.563	691.524
763.78	660.878
764.037	704.991
764.293	660.39
764.55	680.962
764.806	690.78
765.062	683.737
765.319	669.929
765.575	663.681
765.831	672.344
766.088	652.59
766.344	648.587
766.6	657.748
766.857	660.518
767.113	634.722
767.369	639.944
767.625	664.209
767.882	654.623
768.138	668.439
768.394	623.352
768.65	624.377
768.906	621.422
769.163	601.672
769.419	629.003
769.675	647.867
769.931	624.399
770.187	619.646
770.443	601.313
770.699	609.049
770.955	592.548
771.211	597.035
771.467	596.536
771.723	587.735
771.979	610.815
772.235	606.269
772.491	578.273
772.747	605.891
773.003	567.027
773.259	570.005
773.515	570.713
773.771	592.249
774.027	575.115
774.283	576.304
774.539	567.192
774.795	579.222
775.05	563.219
775.306	563.303
775.562	547.493
775.818	565.845
776.074	563.562
776.329	563.077
776.585	557.417
776.841	546.1
777.097	541.62
777.352	562.124
777.608	542.429
777.864	527.979
778.12	523.477
778.375	532.015
778.631	516.806
778.886	532.321
779.142	537.26
779.398	509.547
779.653	496.314
779.909	529.497
780.164	513.38
780.42	518.446
780.675	503.054
780.931	502.765
781.187	525.806
781.442	494.382
781.698	504.09
781.953	482.986
782.208	491.815
782.464	490.671
782.719	495.228
782.975	492.577
783.23	491.805
783.485	476.673
783.741	472.494
783.996	461.936
784.252	476.259
784.507	487.254
784.762	456.603
785.017	473.787
785.273	489.795
785.528	477.702
785.783	457.851
786.038	470.501
786.294	451.229
786.549	466.553
786.804	448.574
787.059	468.741
787.314	446.62
787.57	461.4
787.825	458.339
788.08	430.253
788.335	459.925
788.59	456.919
788.845	446.297
789.1	435.558
789.355	421.356
789.61	439.269
789.865	424.737
790.12	426.037
790.375	423.342
790.63	437.703
790.885	411.141
791.14	416.354
791.395	416.772
791.65	433.747
791.905	396.871
792.16	412.262
792.414	409.397
792.669	415.906
792.924	385.002
793.179	388.165
793.434	397.781
793.689	384.501
793.943	403.502
794.198	390.188
794.453	391.002
794.708	373.305
794.962	378.602
795.217	391.36
795.472	368.422
795.726	375.193
795.981	363.603
796.236	386.756
796.49	375.598
796.745	374.498
796.999	381.326
797.254	363.363
797.508	372.712
797.763	383.794
798.018	357.695
798.272	346.283
798.526	359.582
798.781	358.916
799.035	359.505
799.29	358.332
799.544	350.379
799.799	346.809
800.053	353.371
800.307	354.077
800.562	331.321
800.816	349.424
801.07	347.857
801.325	340.078
801.579	343.137
801.833	330.572
802.088	335.528
802.342	335.979
802.596	321.205
802.85	308.777
803.105	344.753
803.359	310.204
803.613	337.145
803.867	335.899
804.121	318.928
804.375	323.898
804.63	322.227
804.884	333.651
805.138	307.518
805.392	318.936
805.646	316.782
805.9	298.899
806.154	305.396
806.408	296.642
806.662	308.485
806.916	302.769
807.17	307.98
807.424	291.86
807.678	287.612
807.931	298.341
808.185	297.417
808.439	292.088
808.693	282.576
808.947	282.491
809.201	290.418
809.454	283.812
809.708	292.537
809.962	290.774
810.216	293.719
810.469	282.737
810.678	282.981
810.933	276.671
811.188	274.647
811.443	282.137
811.699	287.387
811.954	267.005
812.209	253.109
812.464	255.831
812.719	268.159
812.974	263.424
813.229	261.889
813.484	266.919
813.739	260.363
813.994	284.9
814.249	261.536
814.504	251.817
814.759	286.28
815.014	265.18
815.268	246.337
815.523	280.205
815.778	260.983
816.033	251.18
816.288	242.502
816.543	252.394
816.798	223.813
817.052	248.611
817.307	248.784
817.562	261.607
817.817	247.717
818.071	225.861
818.326	255.475
818.581	241.297
818.836	239.468
819.09	259.554
819.345	225.58
819.6	258.125
819.854	246.819
820.109	237.333
820.364	229.956
820.618	223.185
820.873	230.915
821.127	226.57
821.382	241.722
821.637	232.078
821.891	232.462
822.146	237.952
822.4	205.603
822.655	239.1
822.909	224.511
823.164	232.225
823.418	216.923
823.672	237.385
823.927	214.644
824.181	199.63
824.436	222.698
824.69	197.71
824.944	225.716
825.199	215.859
825.453	208.568
825.707	224.247
825.962	201.263
826.216	221.726
826.47	203.737
826.725	211.368
826.979	201.422
827.233	217.035
827.487	212.216
827.741	211.937
827.996	209.994
828.25	202.935
828.504	195.069
828.758	203.223
829.012	200.855
829.266	190.596
829.52	203.646
829.774	193.531
830.029	186.219
830.283	191.633
830.537	196.944
830.791	202.029
831.045	191.998
831.299	199.976
831.553	192.366
831.807	184.67
832.061	171.766
832.315	190.11
832.568	185.245
832.822	185.378
833.076	198.593
833.33	198.904
833.584	185.958
833.838	175.623
834.092	196.819
834.345	188.937
834.599	191.883
834.853	181.515
835.107	181.556
835.36	176.235
835.614	189.566
835.868	181.712
836.122	168.946
836.375	174.215
836.629	173.954
836.883	171.328
837.136	166.245
837.39	171.399
837.643	166.262
837.897	163.777
838.151	168.855
838.404	181.941
838.658	168.609
838.911	187.126
839.165	160.89
839.418	158.449
839.672	158.383
839.925	158.546
840.179	164.039
840.432	174.637
840.686	166.753
840.939	159.025
841.192	172.497
841.446	146.081
841.699	164.861
841.952	154.356
842.206	162.071
842.459	154.108
842.712	162.159
842.966	183.408
843.219	140.986
843.472	151.776
843.725	146.693
843.979	149.421
844.232	157.348
844.485	157.503
844.738	152.297
844.991	138.99
845.244	139.067
845.497	155.192
845.75	150.042
846.004	158.168
846.257	142.186
846.51	147.615
846.763	150.501
847.016	134.239
847.269	147.756
847.522	147.77
847.775	134.489
848.028	145.337
848.281	123.948
848.534	153.697
848.786	145.857
849.039	148.695
849.292	146.229
849.545	148.943
849.798	132.976
850.051	143.808
850.303	143.845
850.556	135.796
850.809	119.629
851.062	144.123
851.314	130.585
851.567	133.69
851.82	139.238
852.073	136.618
852.325	120.455
852.578	130.989
852.831	134.761
853.083	134.643
853.336	141.783
853.588	122.353
853.841	130.765
854.093	125.506
854.346	131.7
854.598	129.136
854.851	129.053
855.103	131.786
855.356	122.125
855.608	123.973
855.861	125.318
856.113	124.823
856.366	120.363
856.618	131.472
856.87	125.308
857.123	122.063
857.352	105.324
857.606	116.439
857.859	121.957
858.113	108.205
858.367	144.295
858.621	127.533
858.875	110.851
859.128	113.681
859.382	113.631
859.636	113.684
859.889	105.355
860.143	124.889
860.397	124.801
860.65	108.32
860.904	105.519
861.158	113.867
861.411	122.339
861.665	108.483
861.918	113.933
862.172	119.306
862.425	113.814
862.679	110.956
862.932	110.984
863.186	122.394
863.439	111.063
863.693	111.08
863.946	105.685
864.2	100.138
864.453	108.586
864.707	108.504
864.96	111.182
865.213	119.606
865.467	108.495
865.72	100.236
865.973	97.5677
866.227	106.009
866.48	119.931
866.733	108.792
866.987	92.07
867.24	114.607
867.493	117.348
867.746	114.671
867.999	83.967
868.253	100.806
868.506	78.4721
868.759	106.684
869.012	103.957
869.265	106.854
869.518	92.8176
869.771	101.221
870.025	104.073
870.278	106.912
870.531	95.8385
870.784	107.292
871.037	107.342
871.29	104.487
871.543	98.9879
871.796	113.265
872.049	104.778
872.302	107.697
872.555	110.492
872.808	116.165
873.06	96.36
873.313	102.134
873.566	96.4392
873.819	93.7105
874.072	90.6683
874.325	104.86
874.578	102.244
874.83	96.5552
875.083	107.888
875.336	96.5076
875.589	96.5908
875.841	93.7286
876.094	96.5781
876.347	93.8317
876.6	99.5046
876.852	99.5983
877.105	102.516
877.358	94.0563
877.61	99.7391
877.863	88.355
878.115	88.4263
878.368	85.7249
878.621	88.7282
878.873	88.7259
879.126	88.6709
879.378	100.37
879.631	100.522
879.883	97.6436
880.136	89.0696
880.388	89.2189
880.641	92.2616
880.893	89.4882
881.145	86.6063
881.398	80.991
881.65	78.1916
881.902	92.7444
882.155	92.7947
882.407	89.8828
882.659	87.0516
882.912	78.504
883.164	90.2109
883.416	93.2327
883.669	90.3494
883.921	93.3853
884.173	87.6224
884.425	93.5833
884.677	81.8931
884.93	99.569
885.182	93.6634
885.434	87.7557
885.686	96.6115
885.938	90.7647
886.19	52.7606
886.442	82.0698
886.694	96.8098
886.946	82.1706
887.198	70.6023
887.45	88.3392
887.702	85.4234
887.954	88.4923
888.206	88.5616
888.458	85.7566
888.71	88.6813
888.962	73.9769
889.214	76.969
889.466	65.1858
889.718	74.1235
889.969	74.2398
890.221	83.2404
890.473	80.3509
890.725	77.626
890.977	83.6552
891.228	77.7337
891.48	86.8081
891.732	83.8659
891.983	72.1064
892.235	81.1818
892.487	81.3682
892.738	99.6664
892.99	81.7239
893.242	66.6057
893.493	75.7049
893.745	87.9394
893.996	75.9187
894.248	72.9795
894.5	76.0167
894.751	79.2365
895.003	76.3642
895.254	79.6402
895.505	82.7884
895.757	76.7392
896.008	76.8196
896.26	70.7708
896.511	83.1569
896.763	70.838
897.014	74.1266
897.265	80.357
897.517	71.0203
897.768	74.2058
898.019	80.6104
898.27	71.1657
898.522	74.3541
898.773	80.8537
899.024	77.7598
899.275	65.3404
899.527	65.267
899.778	62.3456
899.979	81.179