File: LT_191023_M3_borda_01.txt
#Acq. time (s)=	5
#Accumulations=	2
#Range (nm)=	520...900
#Windows=	8
#Auto scanning=	Off
#Autofocus=	Off
#AutoExposure=	Off
#Spike filter=	Multiple accum.
#Delay time (s)=	0
#Binning=	1
#Readout mode=	Signal
#DeNoise=	Off
#ICS correction=	On
#Dark correction=	Off
#Inst. Process=	Off
#Detector temperature (°C)=	-59.98
#Instrument=	LabRAM HR Evol
#Detector=	Syncerity OE
#Objective=	x50_VIS
#Grating=	600 (500nm)
#ND Filter=	10%
#Laser=	514nm_Edge
#Hole=	199.981
#Range=	Auto
#StageXY=	Marzhauser
#StageZ=	Marzhauser
#X (µm)=	-19144.6
#Y (µm)=	7183.9
#Z (µm)=	-16.2
#Full time(mm:ss)=	2:05
#Project=
#Sample=
#Site=
#Title=	LT_191023_M3_borda
#Remark=
#Date=	27.10.2023 13:35
#Acquired=	27.10.2023 13:35:17
520.044	39.6377
520.306	44.5882
520.569	42.6454
520.831	39.2592
521.093	48.3113
521.355	48.2601
521.617	35.57
521.88	38.9943
522.142	42.5585
522.404	41.0016
522.666	46.5119
522.928	41.1758
523.19	40.8814
523.453	37.0706
523.715	42.2124
523.977	45.7809
524.239	35.4387
524.501	51.6781
524.763	41.1012
525.025	49.869
525.287	31.9648
525.549	40.8434
525.811	40.8579
526.073	44.712
526.335	46.8176
526.597	52.4414
526.859	50.6114
527.121	43.2484
527.383	43.1997
527.645	44.9049
527.907	41.2931
528.169	41.4474
528.431	43.5175
528.693	41.9798
528.955	43.9571
529.217	51.2223
529.479	45.5468
529.741	39.8583
530.003	43.397
530.264	50.5631
530.526	41.6531
530.788	41.9425
531.05	53.2883
531.312	46.0777
531.574	48.1435
531.835	48.241
532.097	46.5284
532.359	52.2034
532.621	50.5634
532.883	46.89
533.144	52.4902
533.406	48.7056
533.668	48.7003
533.93	61.6188
534.191	48.3687
534.453	51.8273
534.715	51.8665
534.976	57.561
535.238	52.17
535.5	65.261
535.761	61.7366
536.023	52.5987
536.285	58.2209
536.546	56.1419
536.808	54.2177
537.069	48.336
537.331	59.1755
537.593	60.7816
537.854	56.9643
538.116	53.1437
538.377	55.0874
538.639	58.8147
538.9	53.378
539.162	62.5795
539.423	67.9619
539.685	60.5758
539.946	75.1562
540.208	75.0279
540.469	60.4421
540.731	62.4519
540.992	79.0217
541.254	62.659
541.515	59.0626
541.776	59.0769
542.038	62.9172
542.299	55.3488
542.56	56.9569
542.822	73.3486
543.083	67.6901
543.344	69.4695
543.606	73.3472
543.867	76.9209
544.128	64.149
544.39	75.2811
544.651	66.179
544.912	77.2128
545.174	73.4696
545.435	76.9772
545.696	73.0149
545.957	85.6549
546.218	72.6001
546.48	79.6555
546.741	83.2494
547.002	77.957
547.263	88.8327
547.524	92.4321
547.785	87.1178
548.047	92.5898
548.308	85.3786
548.569	81.5916
548.83	83.3631
549.091	103.187
549.352	99.1226
549.613	98.9514
549.874	91.4292
550.135	103.875
550.396	98.0836
550.657	99.8571
550.918	106.867
551.179	113.777
551.44	115.284
551.701	152.63
551.962	200.364
552.223	519.852
552.484	12195.3
552.745	819.589
553.006	189.771
553.267	150.896
553.528	131.683
553.788	120.746
554.049	122.576
554.31	122.636
554.571	124.268
554.832	116.998
555.093	116.752
555.353	135.844
555.614	129.941
555.875	136.594
556.136	132.951
556.396	144.871
556.657	129.272
556.918	127.38
557.179	132.779
557.439	124.41
557.7	128.236
557.961	130.405
558.221	121.973
558.482	106.074
558.743	120.106
559.003	120.142
559.264	116.132
559.525	127.748
559.785	134.404
560.046	133.57
560.306	120.793
560.567	123.305
560.827	131.163
561.088	127.203
561.348	135.33
561.609	141.973
561.869	150.535
562.13	132.015
562.39	147.275
562.651	144.27
562.911	154.734
563.172	156.753
563.432	172.175
563.692	163.516
563.953	164.808
564.213	169.802
564.474	172.689
564.734	161.678
564.994	165.725
565.255	168.434
565.515	160.694
565.775	173.16
566.035	167.587
566.296	165.221
566.556	177.643
566.816	162.437
567.076	177.059
567.337	165.819
567.597	179.048
567.857	187.478
568.117	191.114
568.377	190.565
568.637	193.719
568.898	195.374
569.158	198.436
569.418	193.322
569.678	203.685
569.938	208.25
570.198	205.93
570.458	208.697
570.718	223.521
570.978	212.718
571.238	229.888
571.498	239.102
571.758	242.827
572.018	252.831
572.278	258.981
572.538	277.504
572.798	288.637
573.058	305.558
573.312	327.783
573.573	320.113
573.834	349.157
574.095	378.557
574.356	391.352
574.617	411.399
574.878	405.756
575.139	438.428
575.4	409.904
575.661	430.095
575.922	453.932
576.183	437.663
576.444	417.242
576.705	384.848
576.965	388.46
577.226	368.303
577.487	362.057
577.748	343.467
578.009	341.357
578.27	351.293
578.531	346.035
578.791	334.247
579.052	325.378
579.313	326.626
579.574	317.315
579.835	323.626
580.095	349.986
580.356	341.529
580.617	334.802
580.878	353.189
581.138	351.467
581.399	341.257
581.66	357.333
581.92	364.476
582.181	338.572
582.442	339.669
582.703	354.2
582.963	353.758
583.224	343.441
583.484	380.198
583.745	358.54
584.006	379.946
584.266	377.221
584.527	375.023
584.787	399.118
585.048	372.119
585.308	402.812
585.569	378.162
585.83	394.095
586.09	398.753
586.351	415.507
586.611	413.51
586.872	420.567
587.132	430.861
587.392	422.795
587.653	438.122
587.913	450.314
588.174	426.418
588.434	430.956
588.695	433.855
588.955	450.815
589.215	457.135
589.476	436.989
589.736	445.445
589.996	438.072
590.257	424.803
590.517	457.598
590.777	448.203
591.038	434.944
591.298	450.361
591.558	428.436
591.818	444.204
592.079	445.299
592.339	441.076
592.599	461.076
592.859	493.559
593.12	468.824
593.38	474.559
593.64	458.853
593.9	451.924
594.16	464.653
594.42	447.811
594.68	453.815
594.941	456.698
595.201	450.037
595.461	460.949
595.721	482.914
595.981	464.167
596.241	466.457
596.501	495.289
596.761	495.031
597.021	469.766
597.281	452.424
597.541	445.194
597.801	476.888
598.061	473.629
598.321	440.028
598.581	466.145
598.841	461.144
599.101	465.601
599.361	448.433
599.62	478.865
599.88	450.608
600.14	477.329
600.4	460.433
600.66	487.126
600.92	470.82
601.18	483.001
601.439	472.189
601.699	477.321
601.959	468.988
602.219	470.667
602.478	480.425
602.738	470.582
602.998	486.363
603.258	479.563
603.517	483.475
603.777	474.825
604.037	479.886
604.296	475.343
604.556	483.448
604.816	477.577
605.075	507.928
605.335	468.762
605.594	490.026
605.854	479.215
606.114	483.716
606.373	475.337
606.633	518.015
606.892	483.64
607.152	484.604
607.411	478.402
607.671	505.497
607.93	477.647
608.19	486.626
608.449	485.251
608.709	511.611
608.968	502.796
609.228	513.894
609.487	506.224
609.746	527.862
610.006	509.946
610.265	500.031
610.524	518.134
610.784	501.426
611.043	494.983
611.302	509.916
611.562	511.198
611.821	507.589
612.08	522.57
612.339	540.318
612.599	520.456
612.858	533.631
613.117	532.019
613.376	524.231
613.635	553.181
613.895	527.929
614.154	544.722
614.413	522.236
614.672	551.215
614.931	560.011
615.19	554.616
615.449	558.712
615.709	558.995
615.968	547.034
616.227	554.037
616.486	550.492
616.745	563.532
617.004	559.727
617.263	550.711
617.522	565.292
617.781	574.792
618.04	572.719
618.299	555.332
618.557	560.426
618.816	562.013
619.075	563.929
619.334	580.395
619.593	583.758
619.852	574.912
620.111	568.133
620.37	577.034
620.628	573.915
620.887	590.054
621.146	589.936
621.373	584.821
621.633	573.774
621.893	596.882
622.153	587.698
622.413	596.897
622.673	572.131
622.932	595.407
623.192	583.004
623.452	571.218
623.712	564.362
623.972	582.282
624.232	570.128
624.492	583.162
624.751	590.635
625.011	584.244
625.271	581.784
625.531	558.247
625.791	600.261
626.05	600.377
626.31	583.052
626.57	598.675
626.83	600.787
627.089	599.726
627.349	605.235
627.609	621.472
627.868	599.345
628.128	609.825
628.388	610.277
628.647	610.487
628.907	611.56
629.167	608.206
629.426	624.683
629.686	603.451
629.945	629.028
630.205	641.741
630.465	627.657
630.724	645.988
630.984	618.75
631.243	643.794
631.503	651.758
631.762	653.594
632.022	648.135
632.281	649.301
632.541	663.164
632.8	662.787
633.06	673.345
633.319	680.071
633.579	685.541
633.838	684.748
634.097	691.731
634.357	714.471
634.616	725.604
634.876	717.457
635.135	747.661
635.394	772.124
635.654	773.509
635.913	775.518
636.172	825.842
636.431	823.893
636.691	870.094
636.95	864.323
637.209	890.105
637.469	911.906
637.728	914.812
637.987	903.058
638.246	903.2
638.505	908.15
638.765	888.822
639.024	882.245
639.283	880.816
639.542	852.559
639.801	842.703
640.06	847.312
640.319	848.044
640.578	838.793
640.838	831.533
641.097	829.817
641.356	789.497
641.615	818.764
641.874	801.556
642.133	824.155
642.392	805.876
642.651	811.756
642.91	800.054
643.169	819.289
643.428	829.845
643.687	818.411
643.946	803.174
644.205	811.172
644.463	816.036
644.722	818.411
644.981	847.561
645.24	830.064
645.499	844.971
645.758	829.93
646.017	847.03
646.275	848.594
646.534	849.843
646.793	870.625
647.052	852.131
647.31	843.228
647.569	852.639
647.828	865.554
648.087	853.872
648.345	859.719
648.604	895.577
648.863	881.278
649.121	893.848
649.38	880.933
649.639	909.294
649.897	892.778
650.156	899.009
650.415	907.975
650.673	906.057
650.932	920.021
651.19	917.76
651.449	947.214
651.707	918.205
651.966	921.951
652.224	924.007
652.483	936.896
652.741	915.341
653	957.287
653.258	945.863
653.517	958.061
653.775	964.212
654.034	990.248
654.292	972.091
654.55	978.97
654.809	1003.13
655.067	992.056
655.326	1009.46
655.584	1025.05
655.842	1015.51
656.1	1016.12
656.359	1040.03
656.617	1062.95
656.875	1044.5
657.134	1066.23
657.392	1052.01
657.65	1061.84
657.908	1094.88
658.166	1088.18
658.425	1097.67
658.683	1085.94
658.941	1095.63
659.199	1096.94
659.457	1094.82
659.715	1081.31
659.973	1088.54
660.231	1084.05
660.49	1095.01
660.748	1118.19
661.006	1097.26
661.264	1093.65
661.522	1091.53
661.78	1117.66
662.038	1066.3
662.296	1061.42
662.554	1084.24
662.811	1096.92
663.069	1067.93
663.327	1055.16
663.585	1075.6
663.843	1082.93
664.101	1074.05
664.359	1090.75
664.617	1083.4
664.874	1064.6
665.132	1079.66
665.39	1091.63
665.648	1087.57
665.906	1094.73
666.163	1083.26
666.421	1087.58
666.679	1088.44
666.937	1094.41
667.194	1083.23
667.452	1078.34
667.71	1080.92
667.967	1088.39
668.225	1085.76
668.482	1104.64
668.74	1099.22
668.987	1096.67
669.245	1115.71
669.504	1096.98
669.763	1085.79
670.022	1096.29
670.281	1081.22
670.539	1133.69
670.798	1091.14
671.057	1123.3
671.316	1110.41
671.575	1104.72
671.833	1110.14
672.092	1105.33
672.351	1090.84
672.609	1113.6
672.868	1125.69
673.127	1125.08
673.385	1140.2
673.644	1104.91
673.903	1124.56
674.161	1122.87
674.42	1123.86
674.678	1118.9
674.937	1129.42
675.195	1128.87
675.454	1141.35
675.713	1164.86
675.971	1128.83
676.23	1176.13
676.488	1153.49
676.747	1149.24
677.005	1159.2
677.263	1152.09
677.522	1157.67
677.78	1159.81
678.039	1194.37
678.297	1179.59
678.556	1174.46
678.814	1189.77
679.072	1206.86
679.331	1160.16
679.589	1168.42
679.847	1188.69
680.106	1155.62
680.364	1174.44
680.622	1161.02
680.881	1191.15
681.139	1191
681.397	1159.01
681.656	1178.86
681.914	1182.12
682.172	1153.7
682.43	1170.87
682.688	1187.46
682.947	1178.02
683.205	1163.43
683.463	1206.36
683.721	1176.75
683.979	1169.3
684.237	1184.66
684.495	1174.25
684.754	1205.92
685.012	1160.94
685.27	1192.41
685.528	1175.48
685.786	1159.34
686.044	1172.72
686.302	1189.88
686.56	1175.77
686.818	1128.73
687.076	1158.54
687.334	1165.73
687.592	1146.42
687.85	1147.33
688.108	1180.53
688.366	1164.94
688.623	1165.31
688.881	1166.52
689.139	1152.6
689.397	1152.77
689.655	1142.37
689.913	1144.64
690.171	1166.29
690.428	1149.09
690.686	1138.52
690.944	1111.34
691.202	1136.76
691.459	1144.39
691.717	1134.62
691.975	1133.24
692.233	1143.88
692.49	1123.07
692.748	1126.97
693.006	1159.79
693.263	1137.94
693.521	1109.78
693.779	1135.75
694.036	1119.77
694.294	1144.65
694.552	1120.6
694.809	1120.86
695.067	1141.9
695.324	1146.18
695.582	1120.48
695.839	1097.79
696.097	1130.29
696.354	1127.2
696.612	1109.54
696.869	1123.42
697.127	1120.96
697.384	1120.2
697.642	1143.21
697.899	1127.69
698.156	1105
698.414	1117.85
698.671	1116.32
698.928	1111.95
699.186	1122.26
699.443	1101.64
699.7	1068.43
699.958	1083.17
700.215	1108.16
700.472	1092.17
700.73	1091.54
700.987	1096.44
701.244	1064.87
701.501	1067.49
701.758	1074.73
702.016	1072.58
702.273	1095.27
702.53	1059.29
702.787	1100.63
703.044	1106.74
703.301	1095.04
703.558	1056.6
703.816	1093.79
704.073	1108.84
704.33	1075.27
704.587	1074.63
704.844	1109.06
705.101	1079.93
705.358	1097.91
705.615	1077.02
705.872	1069.3
706.129	1056.61
706.386	1064.09
706.643	1054.37
706.899	1079.39
707.156	1073.05
707.413	1077.08
707.67	1064.65
707.927	1058.67
708.184	1050.71
708.441	1059.86
708.697	1057.39
708.954	993.38
709.211	1022.6
709.468	1041.82
709.725	1028.31
709.981	1008.71
710.238	1031.42
710.495	1045.79
710.751	1025.92
711.008	1024.34
711.265	1035.93
711.521	1045.99
711.778	1040.58
712.035	1040.83
712.291	1025.41
712.548	1025.92
712.804	1025.84
713.061	1019.99
713.317	1025.19
713.574	1002.82
713.831	1029.21
714.087	1018.57
714.343	1016.26
714.6	1019.82
714.856	993.415
715.113	1001.31
715.369	1002.42
715.626	992.742
715.882	994.351
716.138	999.919
716.395	991.903
716.639	1000.7
716.897	995.904
717.155	983.364
717.412	970.869
717.67	966.235
717.927	986.342
718.185	957.953
718.443	977.789
718.7	962.405
718.958	984.944
719.215	974.307
719.473	950.673
719.73	960.574
719.988	967.88
720.245	963.37
720.503	931.882
720.76	952.062
721.018	956.248
721.275	951.09
721.532	954.252
721.79	931.836
722.047	936.811
722.305	939.921
722.562	929.65
722.819	938.739
723.077	922.847
723.334	907.462
723.591	916.753
723.849	887.965
724.106	908.222
724.363	920.849
724.621	915.838
724.878	893.375
725.135	927.755
725.392	875.543
725.65	874.461
725.907	859.573
726.164	878.765
726.421	911.509
726.678	870.068
726.935	910.972
727.193	858.776
727.45	893.752
727.707	886.223
727.964	885.312
728.221	885.072
728.478	867.389
728.735	862.494
728.992	879.247
729.249	840.368
729.506	854.384
729.763	873.47
730.02	836.102
730.277	834.128
730.534	844.365
730.791	858.965
731.048	855.483
731.305	861.97
731.562	815.358
731.819	864.594
732.076	832.537
732.333	809.9
732.589	823.04
732.846	822.507
733.103	807.004
733.36	820.316
733.617	823.425
733.873	830.868
734.13	823.546
734.387	812.538
734.644	819.204
734.901	794.992
735.157	807.149
735.414	819.776
735.671	806.596
735.927	828.91
736.184	780.585
736.441	787.649
736.697	797.796
736.954	784.597
737.211	813.183
737.467	789.095
737.724	767.907
737.98	783.699
738.237	780.496
738.493	788.557
738.75	785.392
739.006	756.47
739.263	783.36
739.519	778.82
739.776	780.099
740.032	777.03
740.289	768.261
740.545	719.264
740.802	747.406
741.058	723.96
741.314	724.093
741.571	746.217
741.827	738.557
742.083	763.024
742.34	728.153
742.596	727.412
742.852	733.431
743.109	719.985
743.365	735.328
743.621	724.863
743.878	736.846
744.134	733.452
744.39	730.356
744.646	724.184
744.902	701.882
745.159	714.413
745.415	711.292
745.671	708.718
745.927	697.427
746.183	695.998
746.439	695.748
746.695	709.395
746.951	704.957
747.207	674.492
747.463	699.614
747.719	698.01
747.975	692.657
748.231	652.176
748.487	673.802
748.743	652.608
748.999	671.855
749.255	656.334
749.511	663.139
749.767	655.104
750.023	661.064
750.279	625.651
750.535	655.649
750.791	625.497
751.046	658.679
751.302	668.367
751.558	635.898
751.814	621.342
752.07	633.857
752.325	638.484
752.581	635.563
752.837	637.644
753.092	626.698
753.348	623.239
753.604	648.685
753.859	650.457
754.115	619.551
754.371	607.426
754.626	621.619
754.882	603.029
755.138	580.48
755.393	581.093
755.649	607.3
755.904	629.817
756.16	592.686
756.415	600.206
756.671	589.215
756.926	595.877
757.182	601.141
757.437	586.95
757.693	596.807
757.948	600.967
758.203	581.937
758.459	575.082
758.714	587.798
758.97	582.708
759.225	578.981
759.48	587.576
759.736	579.185
759.991	578.141
760.246	561.465
760.501	564.321
760.757	563.784
761.012	550.894
761.267	577.378
761.522	568.8
761.777	557.292
762.033	550.14
762.288	543.25
762.543	554.784
762.798	548.55
763.053	534.971
763.308	545.331
763.563	524.11
763.78	530.276
764.037	552.007
764.293	539.03
764.55	532.446
764.806	540.611
765.062	525.464
765.319	533.726
765.575	520.783
765.831	516.576
766.088	490.238
766.344	508.352
766.6	530.03
766.857	486.192
767.113	519.318
767.369	506.823
767.625	519.466
767.882	509.509
768.138	485.99
768.394	506.777
768.65	497.88
768.906	494.534
769.163	508.731
769.419	483.597
769.675	492.444
769.931	470.348
770.187	491.444
770.443	467.871
770.699	491.86
770.955	471.721
771.211	469.336
771.467	478.558
771.723	471.187
771.979	463.953
772.235	462.239
772.491	467.325
772.747	474.614
773.003	442.146
773.259	454.989
773.515	443.7
773.771	459.884
774.027	467.919
774.283	453.541
774.539	457.854
774.795	428.419
775.05	449.889
775.306	428.937
775.562	409.324
775.818	418.76
776.074	442.179
776.329	439.687
776.585	423.288
776.841	415.246
777.097	422.813
777.352	439.542
777.608	438.858
777.864	445.262
778.12	428.299
778.375	418.896
778.631	394.684
778.886	413.436
779.142	416.288
779.398	425.811
779.653	412.405
779.909	404.278
780.164	423.628
780.42	383.434
780.675	416.507
780.931	423.191
781.187	407.953
781.442	385.327
781.698	393.081
781.953	391.857
782.208	389.43
782.464	399.128
782.719	372.338
782.975	395.165
783.23	386.813
783.485	391.685
783.741	370.583
783.996	374.743
784.252	386.96
784.507	386.443
784.762	372.393
785.017	359.554
785.273	358.432
785.528	362.978
785.783	359.875
786.038	351.458
786.294	369.704
786.549	366.035
786.804	370.644
787.059	362.036
787.314	349.28
787.57	354.187
787.825	372.041
788.08	355.343
788.335	340.614
788.59	339.315
788.845	332.308
789.1	311.666
789.355	359.22
789.61	330.423
789.865	362.39
790.12	347.865
790.375	339.065
790.63	327.787
790.885	340.323
791.14	331.504
791.395	323.937
791.65	336.699
791.905	329.403
792.16	328.615
792.414	327.517
792.669	327.926
792.924	328.856
793.179	311.739
793.434	345.282
793.689	325.814
793.943	326.451
794.198	325.157
794.453	305.47
794.708	326.387
794.962	331.532
795.217	301.204
795.472	312.85
795.726	319.532
795.981	326.416
796.236	310.232
796.49	298.818
796.745	303.759
796.999	293.808
797.254	302.802
797.508	303.614
797.763	291.516
798.018	271.428
798.272	295.608
798.526	313.048
798.781	288.832
799.035	295.687
799.29	268.749
799.544	282.012
799.799	293.289
800.053	263.422
800.307	283.261
800.562	273.232
800.816	269.617
801.07	270.076
801.325	292.424
801.579	260.61
801.833	267.502
802.088	267.987
802.342	259.62
802.596	281.874
802.85	278.118
803.105	283.269
803.359	261.803
803.613	264.428
803.867	251.924
804.121	267.988
804.375	261.78
804.63	260.004
804.884	262.472
805.138	254.036
805.392	263.178
805.646	265.61
805.9	256.847
806.154	250.306
806.408	254.698
806.662	261.322
806.916	265.44
807.17	257.342
807.424	241.122
807.678	248.288
807.931	236.361
808.185	245.404
808.439	261.201
808.693	247.313
808.947	244.25
809.201	238.265
809.454	244.625
809.708	227.92
809.962	232.327
810.216	227.945
810.469	229.078
810.678	238.91
810.933	244.121
811.188	230.424
811.443	221.512
811.699	233.648
811.954	222.504
812.209	222.642
812.464	239.401
812.719	230.523
812.974	216.384
813.229	231.217
813.484	214.953
813.739	215.392
813.994	220.798
814.249	221.117
814.504	209.055
814.759	224.252
815.014	224.567
815.268	212.854
815.523	217.937
815.778	205.913
816.033	215.297
816.288	213.69
816.543	211.53
816.798	206.967
817.052	200.337
817.307	193.231
817.562	210.739
817.817	218.573
818.071	191.861
818.326	214.113
818.581	202.3
818.836	202.815
819.09	205.684
819.345	198.608
819.6	206.5
819.854	190.05
820.109	210.138
820.364	202.757
820.618	200.867
820.873	193.671
821.127	196.693
821.382	181.914
821.637	194.646
821.891	194.968
822.146	192.866
822.4	198.081
822.655	216.448
822.909	196.763
823.164	171.644
823.418	186.654
823.672	191.928
823.927	202.018
824.181	184.468
824.436	202.453
824.69	195.176
824.944	177.53
825.199	190.464
825.453	190.764
825.707	188.572
825.962	175.786
826.216	188.594
826.47	178.27
826.725	170.623
826.979	188.674
827.233	183.841
827.487	168.75
827.741	168.528
827.996	181.824
828.25	164.403
828.504	161.702
828.758	185.216
829.012	180.255
829.266	180.293
829.52	170.135
829.774	165.146
830.029	155.182
830.283	170.916
830.537	181.395
830.791	170.948
831.045	173.836
831.299	163.616
831.553	166.371
831.807	176.867
832.061	153.549
832.315	174.484
832.568	159.154
832.822	154.046
833.076	159.397
833.33	157.03
833.584	141.433
833.838	146.789
834.092	157.455
834.345	160.072
834.599	160.341
834.853	134.163
835.107	147.35
835.36	168.344
835.614	147.44
835.868	163.278
836.122	147.828
836.375	147.819
836.629	150.233
836.883	142.334
837.136	145.135
837.39	145.03
837.643	155.706
837.897	132.079
838.151	145.11
838.404	155.573
838.658	142.264
838.911	147.592
839.165	147.702
839.418	147.886
839.672	134.626
839.925	137.406
840.179	145.519
840.432	150.823
840.686	148.225
840.939	140.472
841.192	153.921
841.446	146.081
841.699	132.952
841.952	146.372
842.206	122.218
842.459	135.509
842.712	148.867
842.966	146.195
843.219	143.646
843.472	125.149
843.725	141.359
843.979	133.412
844.232	141.347
844.485	125.468
844.738	146.953
844.991	141.662
845.244	131.044
845.497	144.489
845.75	128.608
846.004	128.679
846.257	123.407
846.51	120.776
846.763	120.939
847.016	107.391
847.269	123.578
847.522	134.336
847.775	134.489
848.028	134.571
848.281	129.337
848.534	121.34
848.786	126.95
849.039	135.177
849.292	124.566
849.545	119.154
849.798	130.263
850.051	130.241
850.303	124.846
850.556	119.501
850.809	125.067
851.062	122.369
851.314	111.542
851.567	109.135
851.82	106.476
852.073	112.026
852.325	123.066
852.578	117.312
852.831	116.976
853.083	121.157
853.336	126.146
853.588	124.068
853.841	111.777
854.093	114.826
854.346	100.262
854.598	105.555
854.851	112.459
855.103	113.394
855.356	103.829
855.608	105.823
855.861	113.908
856.113	114.964
856.366	106.675
856.618	106.252
856.87	107.606
857.123	110.533
857.352	116.411
857.606	102.577
857.859	105.326
858.113	119.303
858.367	116.546
858.621	110.899
858.875	105.309
859.128	105.363
859.382	110.86
859.636	108.138
859.889	99.81
860.143	108.237
860.397	116.481
860.65	124.985
860.904	105.519
861.158	99.9812
861.411	105.657
861.665	83.4488
861.918	91.7024
862.172	102.659
862.425	99.934
862.679	102.634
862.932	108.209
863.186	102.922
863.439	108.286
863.693	99.9722
863.946	116.81
864.2	108.483
864.453	103.017
864.707	108.504
864.96	105.623
865.213	114.043
865.467	94.5857
865.72	94.667
865.973	97.5677
866.227	89.2708
866.48	103.196
866.733	97.6334
866.987	108.81
867.24	92.245
867.493	103.378
867.746	103.483
867.999	100.76
868.253	112.007
868.506	89.6824
868.759	101.069
869.012	92.7188
869.265	95.6062
869.518	92.8176
869.771	87.1626
870.025	106.886
870.278	95.6579
870.531	104.295
870.784	98.8215
871.037	96.0431
871.29	98.8391
871.543	101.816
871.796	110.433
872.049	93.4504
872.302	87.8582
872.555	90.6598
872.808	82.1655
873.06	96.36
873.313	79.4378
873.566	90.7663
873.819	105.069
874.072	99.1684
874.325	93.5234
874.578	96.5638
874.83	85.1958
875.083	88.0137
875.336	102.185
875.589	102.273
875.841	88.0481
876.094	90.897
876.347	88.145
876.6	90.9756
876.852	82.5243
877.105	79.7346
877.358	88.3559
877.61	74.0919
877.863	94.0554
878.115	88.4263
878.368	85.7249
878.621	77.2794
878.873	94.4501
879.126	85.8106
879.378	88.899
879.631	89.0337
879.883	86.1561
880.136	83.3232
880.388	89.2189
880.641	89.3784
880.893	80.8281
881.145	72.1719
881.398	80.991
881.65	86.8795
881.902	78.2531
882.155	72.4959
882.407	84.0839
882.659	95.7567
882.912	69.7813
883.164	87.3009
883.416	90.3192
883.669	87.4349
883.921	87.5487
884.173	81.7809
884.425	102.357
884.677	70.1941
884.93	81.998
885.182	79.0285
885.434	81.9053
885.686	81.9734
885.938	81.981
886.19	99.6589
886.442	73.2766
886.694	76.2744
886.946	82.1706
887.198	70.6023
887.45	79.5053
887.702	67.7496
887.954	97.3416
888.206	76.7534
888.458	79.8424
888.71	76.8571
888.962	65.0997
889.214	76.969
889.466	80.0008
889.718	77.0884
889.969	71.2702
890.221	74.3218
890.473	83.3269
890.725	68.6692
890.977	77.6798
891.228	74.7439
891.48	83.8147
891.732	71.8851
891.983	66.0975
892.235	81.1818
892.487	66.3
892.738	87.5857
892.99	87.7775
893.242	72.6608
893.493	69.6486
893.745	66.7127
893.996	69.8452
894.248	66.8979
894.5	69.9354
894.751	76.189
895.003	76.3642
895.254	64.3248
895.505	70.5235
895.757	73.6696
896.008	58.3829
896.26	76.9248
896.511	73.9172
896.763	73.918
897.014	64.8607
897.265	80.357
897.517	64.8446
897.768	58.7462
898.019	83.7108
898.27	77.354
898.522	83.6483
898.773	62.1951
899.024	87.0909
899.275	62.2289
899.527	62.159
899.778	74.8148
899.979	68.6899