File: LT_191023_M4_borda_01.txt
#Acq. time (s)=	5
#Accumulations=	2
#Range (nm)=	520...900
#Windows=	8
#Auto scanning=	Off
#Autofocus=	Off
#AutoExposure=	Off
#Spike filter=	Multiple accum.
#Delay time (s)=	0
#Binning=	1
#Readout mode=	Signal
#DeNoise=	Off
#ICS correction=	On
#Dark correction=	Off
#Inst. Process=	Off
#Detector temperature (°C)=	-59.98
#Instrument=	LabRAM HR Evol
#Detector=	Syncerity OE
#Objective=	x50_VIS
#Grating=	600 (500nm)
#ND Filter=	10%
#Laser=	514nm_Edge
#Hole=	199.981
#Range=	Auto
#StageXY=	Marzhauser
#StageZ=	Marzhauser
#X (µm)=	-6155.8
#Y (µm)=	-10599.5
#Z (µm)=	-17
#Full time(mm:ss)=	2:04
#Project=
#Sample=
#Site=
#Title=	LT_191023_M4_borda
#Remark=
#Date=	27.10.2023 13:39
#Acquired=	27.10.2023 13:39:05
520.044	27.0257
520.306	32.1035
520.569	23.0996
520.831	23.1986
521.093	32.2075
521.355	32.1734
521.617	23.1205
521.88	24.8145
522.142	31.9189
522.404	26.7402
522.666	28.6227
522.928	35.805
523.19	31.9941
523.453	26.479
523.715	29.9005
523.977	35.2161
524.239	31.8949
524.501	30.294
524.763	30.3791
525.025	30.2776
525.287	21.3099
525.549	39.0676
525.811	31.9757
526.073	32.1927
526.335	27.0101
526.597	30.7415
526.859	30.7284
527.121	27.0303
527.383	32.3998
527.645	32.3315
527.907	37.7024
528.169	34.2392
528.431	29.0117
528.693	32.8537
528.955	32.9679
529.217	43.9048
529.479	25.5062
529.741	25.3644
530.003	28.9313
530.264	34.3107
530.526	28.9761
530.788	29.1774
531.05	36.7506
531.312	33.1759
531.574	25.9234
531.835	37.1085
532.097	27.917
532.359	37.2882
532.621	33.7089
532.883	37.512
533.144	35.6184
533.406	33.7193
533.668	37.4617
533.93	29.8758
534.191	35.3463
534.453	31.4666
534.715	38.8998
534.976	42.7065
535.238	46.5804
535.5	46.615
535.761	37.4161
536.023	39.449
536.285	41.318
536.546	41.1707
536.808	41.1306
537.069	33.4634
537.331	36.9847
537.593	38.6792
537.854	36.7512
538.116	40.3159
538.377	36.7249
538.639	38.5972
538.9	38.6531
539.162	42.3332
539.423	40.4098
539.685	40.3839
539.946	42.1608
540.208	34.769
540.469	38.4632
540.731	34.8996
540.992	42.2674
541.254	46.0728
541.515	38.7598
541.776	51.6923
542.038	51.8141
542.299	59.0387
542.56	53.2823
542.822	60.5126
543.083	56.7133
543.344	56.6725
543.606	49.5093
543.867	60.4378
544.128	51.3192
544.39	49.5753
544.651	47.7959
544.912	49.6368
545.174	51.4287
545.435	49.4854
545.696	49.2851
545.957	49.206
546.218	56.2651
546.48	52.5002
546.741	57.9126
547.002	70.7052
547.263	61.639
547.524	57.9966
547.785	65.3384
548.047	54.4646
548.308	63.5798
548.569	50.7681
548.83	54.3672
549.091	63.3607
549.352	66.6824
549.613	71.9646
549.874	59.16
550.135	66.2648
550.396	64.2001
550.657	67.7602
550.918	80.1504
551.179	76.444
551.44	90.4539
551.701	113.585
551.962	166.675
552.223	525.175
552.484	13969.2
552.745	647.138
553.006	157.847
553.267	104.74
553.528	92.5339
553.788	72.8024
554.049	87.0468
554.31	74.6481
554.571	72.7853
554.832	76.226
555.093	74.2967
555.353	77.6252
555.614	80.7739
555.875	85.8092
556.136	75.2222
556.396	82.0355
556.657	83.8524
556.918	66.3076
557.179	75.1249
557.439	84.1084
557.7	84.3197
557.961	81.0626
558.221	81.3157
558.482	90.1626
558.743	77.7157
559.003	81.2723
559.264	84.4593
559.525	85.7487
559.785	92.5115
560.046	81.5296
560.306	103.537
560.567	78.7783
560.827	88.5779
561.088	98.3702
561.348	93.0396
561.609	94.6484
561.869	99.7927
562.13	93.0876
562.39	96.4906
562.651	100.141
562.911	103.723
563.172	98.8225
563.432	105.692
563.692	103.901
563.953	113.836
564.213	106.975
564.474	115.126
564.734	114.522
564.994	105.462
565.255	108.398
565.515	110.995
565.775	117.089
566.035	101.867
566.296	101.423
566.556	130.38
566.816	128.325
567.076	116.956
567.337	126.803
567.597	120.451
567.857	128.789
568.117	137.211
568.377	130.752
568.637	138.614
568.898	131.858
569.158	132.247
569.418	141.768
569.678	137.854
569.938	150.136
570.198	138.295
570.458	154.833
570.718	144.395
570.978	163.471
571.238	158.224
571.498	160.151
571.758	177.13
572.018	185.794
572.278	193.44
572.538	190.066
572.798	205.05
573.058	215.067
573.312	218.007
573.573	252.069
573.834	258.006
574.095	264.217
574.356	296.995
574.617	323.572
574.878	341.204
575.139	358.714
575.4	373.196
575.661	370.614
575.922	383.862
576.183	373.837
576.444	355.035
576.705	319.697
576.965	306.838
577.226	307.926
577.487	295.68
577.748	278.69
578.009	270.68
578.27	256.714
578.531	254.658
578.791	253.67
579.052	252.576
579.313	245.339
579.574	233.579
579.835	257.729
580.095	256.657
580.356	248.517
580.617	246.391
580.878	244.627
581.138	251.668
581.399	248.713
581.66	251.724
581.92	263.233
582.181	258.993
582.442	267.399
582.703	274.686
582.963	280.119
583.224	269.847
583.484	282.268
583.745	291.135
584.006	287.102
584.266	306.047
584.527	291.528
584.787	328.602
585.048	320.163
585.308	297.913
585.569	301.413
585.83	311.934
586.09	312.31
586.351	320.693
586.611	312.927
586.872	314.378
587.132	317.55
587.392	338.796
587.653	340.139
587.913	349.623
588.174	350.921
588.434	337.513
588.695	344.859
588.955	341.232
589.215	354.935
589.476	358.661
589.736	341.279
589.996	368.472
590.257	345.833
590.517	321.812
590.777	340.906
591.038	323.837
591.298	334.051
591.558	339.235
591.818	313.238
592.079	321.155
592.339	316.981
592.599	314.125
592.859	312.857
593.12	326.022
593.38	319.957
593.64	317.977
593.9	321.845
594.16	320.035
594.42	334.188
594.68	312.332
594.941	318.224
595.201	326.576
595.461	333.424
595.721	342.285
595.981	326.243
596.241	338.281
596.501	368.833
596.761	358.108
597.021	339.495
597.281	355.1
597.541	338.82
597.801	331.063
598.061	345.054
598.321	329.693
598.581	326.958
598.841	329.764
599.101	343.282
599.361	358.746
599.62	356.18
599.88	344.893
600.14	334.527
600.4	350.617
600.66	338.87
600.92	339.89
601.18	351.995
601.439	338.601
601.699	348.101
601.959	340.246
602.219	340.873
602.478	364.235
602.738	365.286
602.998	342.4
603.258	337.374
603.517	344.234
603.777	346.146
604.037	346.084
604.296	366.142
604.556	347.157
604.816	360.435
605.075	354.518
605.335	353.832
605.594	363.317
605.854	348.402
606.114	376.079
606.373	380.788
606.633	372.971
606.892	350.445
607.152	367.007
607.411	364.927
607.671	364.009
607.93	363.372
608.19	362.408
608.449	362.661
608.709	367.441
608.968	371.687
609.228	389.236
609.487	361.225
609.746	372.683
610.006	376.419
610.265	365.505
610.524	371.182
610.784	374.803
611.043	373.453
611.302	369.468
611.562	379.928
611.821	399.269
612.08	366.804
612.339	382.36
612.599	379.421
612.858	391.495
613.117	387.827
613.376	395.342
613.635	374.138
613.895	385.179
614.154	402.407
614.413	405.775
614.672	410.349
614.931	397.388
615.19	414.13
615.449	389.147
615.709	414.071
615.968	416.962
616.227	433.093
616.486	401.189
616.745	428.733
617.004	415.099
617.263	426.167
617.522	406.587
617.781	417.56
618.04	423.695
618.299	414.759
618.557	425.333
618.816	430.831
619.075	424.981
619.334	424.952
619.593	436.112
619.852	416.857
620.111	435.171
620.37	429.256
620.628	442.798
620.887	434.358
621.146	423.154
621.373	439.203
621.633	419.207
621.893	411.966
622.153	437.847
622.413	457.893
622.673	422.981
622.932	424.46
623.192	445.963
623.452	429.862
623.712	432.524
623.972	447.377
624.232	442.539
624.492	425.892
624.751	429.24
625.011	435.901
625.271	445.161
625.531	451.373
625.791	457.288
626.05	448.584
626.31	452.856
626.57	444.763
626.83	451.719
627.089	449.512
627.349	444.893
627.609	472.59
627.868	461.901
628.128	460.182
628.388	470.913
628.647	472.2
628.907	465.415
629.167	460.933
629.426	474.13
629.686	463.244
629.945	488
630.205	475.156
630.465	492.521
630.724	496.485
630.984	480.507
631.243	483.68
631.503	494.092
631.762	497.131
632.022	500.781
632.281	502.185
632.541	520.346
632.8	521.157
633.06	529.609
633.319	542.07
633.579	526.575
633.838	540.3
634.097	539.726
634.357	568.054
634.616	543.652
634.876	575.289
635.135	561.571
635.394	570.556
635.654	600.762
635.913	609.414
636.172	631.203
636.431	652.295
636.691	664.915
636.95	682.013
637.209	726.571
637.469	760.653
637.728	778.96
637.987	797.847
638.246	795.78
638.505	800.922
638.765	753.258
639.024	727.005
639.283	718.187
639.542	720.472
639.801	680.057
640.06	692.462
640.319	672.549
640.578	677.15
640.838	648.203
641.097	680.428
641.356	668.623
641.615	667.423
641.874	671.045
642.133	661.064
642.392	669.932
642.651	657.447
642.91	664.36
643.169	663.234
643.428	619.949
643.687	644.35
643.946	684.266
644.205	660.156
644.463	679.131
644.722	670.687
644.981	686.891
645.24	669.441
645.499	661.751
645.758	688.55
646.017	679.355
646.275	668.917
646.534	715.771
646.793	691.092
647.052	695.33
647.31	712.419
647.569	708.014
647.828	714.459
648.087	694.31
648.345	706.544
648.604	699.434
648.863	708.035
649.121	719.596
649.38	730.53
649.639	742.894
649.897	718.081
650.156	760.782
650.415	751.465
650.673	753.616
650.932	731.079
651.19	750.309
651.449	777.531
651.707	767.68
651.966	763.81
652.224	793.85
652.483	783.977
652.741	782.73
653	800.072
653.258	811.201
653.517	815.051
653.775	809.594
654.034	817.705
654.292	836.127
654.55	814.563
654.809	838.073
655.067	844.416
655.326	843.869
655.584	850.329
655.842	854.724
656.1	859.63
656.359	877.427
656.617	881.571
656.875	864.272
657.134	938.493
657.392	920.905
657.65	903.359
657.908	916.101
658.166	952.552
658.425	925.695
658.683	936.115
658.941	943.522
659.199	965.822
659.457	945.282
659.715	955.355
659.973	959.666
660.231	956.266
660.49	952.276
660.748	958.752
661.006	968.855
661.264	972.952
661.522	958.394
661.78	935.075
662.038	955.662
662.296	959.578
662.554	943.862
662.811	935.882
663.069	933.524
663.327	949.956
663.585	932.052
663.843	937.463
664.101	915.279
664.359	940.876
664.617	944.886
664.874	944.465
665.132	929.095
665.39	940.445
665.648	947.632
665.906	942.253
666.163	944.501
666.421	926.238
666.679	935.975
666.937	942.153
667.194	950.473
667.452	923.903
667.71	945.075
667.967	944.448
668.225	941.161
668.482	957.808
668.74	934.597
668.987	918.575
669.245	952.898
669.504	932.959
669.763	953.736
670.022	972.503
670.281	961.315
670.539	937.899
670.798	953.432
671.057	960.425
671.316	946.679
671.575	966.365
671.833	950.798
672.092	941.89
672.351	961.954
672.609	961.838
672.868	967.861
673.127	942.779
673.385	984.151
673.644	978.22
673.903	990.736
674.161	951.949
674.42	988.543
674.678	977.619
674.937	987.079
675.195	982.61
675.454	977.419
675.713	990.334
675.971	1005.7
676.23	996.701
676.488	1012.03
676.747	1033.48
677.005	1035.86
677.263	1024.19
677.522	1006.4
677.78	1019.83
678.039	1017.27
678.297	1012.74
678.556	992.799
678.814	1031.13
679.072	1050.6
679.331	1025.16
679.589	1027.37
679.847	1035.24
680.106	1035.96
680.364	1038.24
680.622	1041.89
680.881	1018.01
681.139	1028.45
681.397	1045.81
681.656	1034.49
681.914	1032.67
682.172	1050.99
682.43	1034.77
682.688	1044.22
682.947	1051.4
683.205	1049.06
683.463	1048.01
683.721	1046.23
683.979	1049.24
684.237	1051.87
684.495	1058.08
684.754	1046.53
685.012	1039.07
685.27	1034.83
685.528	1015.8
685.786	1029.01
686.044	1028.63
686.302	1035.23
686.56	1032.74
686.818	1026.69
687.076	1028.18
687.334	1013.59
687.592	1022.65
687.85	1002.87
688.108	1035.18
688.366	1036.31
688.623	1029.32
688.881	990.753
689.139	1019.77
689.397	1025.15
689.655	1029.18
689.913	1030.38
690.171	1039.38
690.428	1002.18
690.686	1017.51
690.944	1022.85
691.202	1040.62
691.459	1026.88
691.717	1014.8
691.975	1011.33
692.233	1015.48
692.49	1016.82
692.748	1021.61
693.006	1004.15
693.263	998.359
693.521	1000.94
693.779	991.644
694.036	1005.55
694.294	1004.64
694.552	1020.18
694.809	1001.19
695.067	998.493
695.324	988.71
695.582	1010.04
695.839	995.742
696.097	970.971
696.354	1006.39
696.612	980.852
696.869	993.294
697.127	969.833
697.384	1013.41
697.642	998.801
697.899	976.311
698.156	980.634
698.414	979.084
698.671	963.147
698.928	961.928
699.186	1000.75
699.443	973.463
699.7	979.027
699.958	978.275
700.215	946.853
700.472	952.209
700.73	950.415
700.987	972.046
701.244	958.051
701.501	967.451
701.758	960.443
702.016	969.276
702.273	970.16
702.53	963.79
702.787	932.739
703.044	972.658
703.301	949.768
703.558	968.273
703.816	946.696
704.073	960.105
704.33	957.402
704.587	955.349
704.844	970.431
705.101	957.697
705.358	960.674
705.615	958.48
705.872	940.308
706.129	954.58
706.386	960.522
706.643	942.543
706.899	960.347
707.156	941.213
707.413	926.815
707.67	937.167
707.927	942.699
708.184	957.593
708.441	951.686
708.697	954.984
708.954	918.647
709.211	930.373
709.468	911.449
709.725	923.404
709.981	946.314
710.238	917.973
710.495	927.397
710.751	930.65
711.008	920.74
711.265	914.737
711.521	926.919
711.778	929.681
712.035	939.429
712.291	921.724
712.548	923.684
712.804	919.135
713.061	892.676
713.317	907.049
713.574	927.732
713.831	905.243
714.087	903.352
714.343	910.71
714.6	899.85
714.856	892.778
715.113	903.842
715.369	886.808
715.626	901.618
715.882	898.35
716.138	877.505
716.395	884.388
716.639	878.514
716.897	858.876
717.155	885.395
717.412	881.383
717.67	880.293
717.927	859.667
718.185	880.381
718.443	864.064
718.7	857.258
718.958	849.902
719.215	878.616
719.473	862.325
719.73	855.784
719.988	860.198
720.245	830.405
720.503	842.592
720.76	856.225
721.018	864.034
721.275	838.527
721.532	838.777
721.79	800.896
722.047	830.877
722.305	840.174
722.562	834.892
722.819	833.58
723.077	838.017
723.334	819.934
723.591	787.996
723.849	800.455
724.106	803.724
724.363	816.089
724.621	781.118
724.878	810.391
725.135	799.117
725.392	801.279
725.65	805.287
725.907	807.319
726.164	791.02
726.421	789.361
726.678	784.509
726.935	790.655
727.193	795.065
727.45	796.373
727.707	796.665
727.964	758.073
728.221	751.705
728.478	770.112
728.735	768.921
728.992	777.009
729.249	758.381
729.506	762.647
729.763	773.056
730.02	750.701
730.277	760.813
730.534	765.336
730.791	767.231
731.048	753.773
731.305	751.783
731.562	745.431
731.819	727.268
732.076	728.821
732.333	767.791
732.589	732.998
732.846	767.579
733.103	725.175
733.36	738.426
733.617	721.733
733.873	731.955
734.13	731.57
734.387	720.526
734.644	704.402
734.901	716.913
735.157	697.729
735.414	707.536
735.671	729.913
735.927	710.901
736.184	729.399
736.441	711.013
736.697	678.552
736.954	676.573
737.211	688.078
737.467	716.584
737.724	684.161
737.98	707.033
738.237	699.608
738.493	700.624
738.75	700.332
739.006	667.224
739.263	704.032
739.519	678.282
739.776	693.736
740.032	667.849
740.289	670.457
740.545	669.708
740.802	699.186
741.058	674.277
741.314	631.806
741.571	649.564
741.827	663.136
742.083	669.07
742.34	644.08
742.596	663.229
742.852	652.097
743.109	665.7
743.365	649.492
743.621	617.423
743.878	627.896
744.134	651.638
744.39	624.174
744.646	636.534
744.902	637.159
745.159	642.541
745.415	626.34
745.671	662.623
745.927	628.261
746.183	623.949
746.439	628.046
746.695	641.627
746.951	609.809
747.207	621.166
747.463	623.161
747.719	620.294
747.975	588.974
748.231	583.072
748.487	614.773
748.743	586.339
748.999	608.282
749.255	599.953
749.511	577.899
749.767	574.12
750.023	608.989
750.279	580.755
750.535	580.221
750.791	593.569
751.046	594.701
751.302	580.999
751.558	567.349
751.814	578.945
752.07	583.97
752.325	581.109
752.581	579.528
752.837	574.174
753.092	560.185
753.348	562.543
753.604	552.419
753.859	564.52
754.115	558.636
754.371	550.852
754.626	529.196
754.882	547.801
755.138	562.527
755.393	546.647
755.649	548.819
755.904	514.075
756.16	540.036
756.415	541.539
756.671	550.035
756.926	537.044
757.182	534.683
757.437	527.953
757.693	530.158
757.948	515.982
758.203	505.966
758.459	520.313
758.714	515.483
758.97	516.182
759.225	526.399
759.48	504.655
759.736	509.061
759.991	511.291
760.246	508.691
760.501	515.792
760.757	491.686
761.012	498.531
761.267	493.74
761.522	490.983
761.777	491.42
762.033	495.399
762.288	482.029
762.543	490.723
762.798	472.527
763.053	493.999
763.308	475.826
763.563	486.125
763.78	470.482
764.037	479.457
764.293	469.681
764.55	481.888
764.806	463.155
765.062	479.565
765.319	456.122
765.575	492.204
765.831	468.892
766.088	445.671
766.344	441.422
766.6	466.171
766.857	459.004
767.113	464.821
767.369	449.083
767.625	424.579
767.882	435.34
768.138	455.313
768.394	432.299
768.65	434.631
768.906	435.971
769.163	425.573
769.419	428.049
769.675	433.547
769.931	429.376
770.187	425.699
770.443	446.455
770.699	402.731
770.955	418.756
771.211	414.608
771.467	412.092
771.723	407.918
771.979	423.899
772.235	406.971
772.491	421.938
772.747	407.293
773.003	413.457
773.259	414.395
773.515	419.991
773.771	408.975
774.027	403.261
774.283	407.505
774.539	389.517
774.795	390.718
775.05	382.92
775.306	403.098
775.562	409.324
775.818	394.534
776.074	388.424
776.329	389.288
776.585	376.256
776.841	373.372
777.097	379.134
777.352	392.261
777.608	384.44
777.864	366.065
778.12	380.71
778.375	367.639
778.631	369.906
778.886	367.301
779.142	373.592
779.398	388.396
779.653	357.061
779.909	370.29
780.164	364.392
780.42	351.031
780.675	384.052
780.931	345.425
781.187	386.195
781.442	372.604
781.698	342.126
781.953	333.534
782.208	325.439
782.464	362.511
782.719	344.825
782.975	358.405
783.23	349.974
783.485	325.172
783.741	348.348
783.996	343.206
784.252	336.73
784.507	352.839
784.762	336.838
785.017	335.209
785.273	349.049
785.528	323.483
785.783	324.076
786.038	326.894
786.294	335.578
786.549	331.897
786.804	338.331
787.059	322.021
787.314	345.463
787.57	312.067
787.825	318.344
788.08	307.323
788.335	282.883
788.59	312.324
788.845	307.192
789.1	329.088
789.355	302.91
789.61	305.156
789.865	313.682
790.12	299.008
790.375	311.627
790.63	298.345
790.885	314.749
791.14	307.825
791.395	310.11
791.65	299.068
791.905	287.732
792.16	288.783
792.414	275.594
792.669	301.932
792.924	284.741
793.179	285.593
793.434	302.879
793.689	287.364
793.943	296.036
794.198	270.286
794.453	287.142
794.708	285.589
794.962	288.556
795.217	282.763
795.472	261.395
795.726	286.548
795.981	268.57
796.236	281.277
796.49	284.292
796.745	276.712
796.999	270.887
797.254	267.301
797.508	276.393
797.763	251.668
798.018	256.699
798.272	268.158
798.526	262.284
798.781	256.975
799.035	253.142
799.29	255.952
799.544	271.33
799.799	259.037
800.053	259.139
800.307	263.948
800.562	260.324
800.816	250.205
801.07	241.988
801.325	246.936
801.579	243.236
801.833	267.502
802.088	230.948
802.342	268.347
802.596	235.987
802.85	221.181
803.105	245.939
803.359	237.603
803.613	233.578
803.867	236.455
804.121	221.478
804.375	235.159
804.63	215.559
804.884	235.78
805.138	231.753
805.392	234.184
805.646	223.04
805.9	231.324
806.154	218.632
806.408	207.287
806.662	217.775
806.916	211.164
807.17	216.11
807.424	219.077
807.678	222.916
807.931	221.671
808.185	215.078
808.439	205.731
808.693	220.703
808.947	215.303
809.201	208.574
809.454	200.805
809.708	206.763
809.962	196.349
810.216	209.751
810.469	219.687
810.678	213.396
810.933	195.297
811.188	221.114
811.443	202.859
811.699	179.909
811.954	208.451
812.209	215.611
812.464	197.154
812.719	188.182
812.974	204.624
813.229	179.311
813.484	184.245
813.739	208.291
813.994	185.185
814.249	187.83
814.504	175.797
814.759	181.31
815.014	200.677
815.268	176.98
815.523	196.383
815.778	189.153
816.033	191.375
816.288	182.477
816.543	197.107
816.798	192.527
817.052	173.786
817.307	183.569
817.562	176.827
817.817	172.43
818.071	184.575
818.326	197.081
818.581	187.675
818.836	185.71
819.09	188.544
819.345	183.897
819.6	172.084
819.854	187.582
820.109	170.583
820.364	168.14
820.618	161.189
820.873	171.324
821.127	171.795
821.382	166.962
821.637	172.187
821.891	164.973
822.146	155.295
822.4	180.529
822.655	171.145
822.909	189.195
823.164	164.072
823.418	181.61
823.672	156.573
823.927	148.988
824.181	161.725
824.436	161.962
824.69	174.898
824.944	134.415
825.199	159.989
825.453	150.067
825.707	150.348
825.962	157.953
826.216	163.109
826.47	160.443
826.725	147.703
826.979	168.277
827.233	155.754
827.487	140.625
827.741	145.547
827.996	153.654
828.25	154.128
828.504	156.569
828.758	141.485
829.012	154.504
829.266	144.235
829.52	139.201
829.774	162.566
830.029	157.768
830.283	134.661
830.537	158.073
830.791	147.637
831.045	140.107
831.299	150.631
831.553	145.574
831.807	140.453
832.061	158.754
832.315	143.233
832.568	133.063
832.822	122.715
833.076	154.171
833.33	136.092
833.584	136.194
833.838	144.168
834.092	133.837
834.345	144.327
834.599	131.427
834.853	139.425
835.107	142.087
835.36	131.519
835.614	136.909
835.868	134.309
836.122	137.269
836.375	134.621
836.629	144.962
836.883	137.062
837.136	129.302
837.39	147.666
837.643	134.593
837.897	134.72
838.151	121.365
838.404	142.389
838.658	142.264
838.911	126.508
839.165	118.689
839.418	134.682
839.672	134.626
839.925	126.836
840.179	124.352
840.432	124.363
840.686	127.05
840.939	140.472
841.192	122.075
841.446	122.177
841.699	122.316
841.952	114.436
842.206	124.874
842.459	116.91
842.712	135.575
842.966	130.246
843.219	125.026
843.472	122.486
843.725	130.69
843.979	114.734
844.232	125.345
844.485	136.147
844.738	109.547
844.991	114.934
845.244	120.346
845.497	120.408
845.75	112.532
846.004	125.999
846.257	118.041
846.51	101.989
846.763	115.563
847.016	123.5
847.269	112.832
847.522	110.156
847.775	110.281
848.028	113.04
848.281	123.948
848.534	102.464
848.786	126.95
849.039	129.77
849.292	102.902
849.545	116.446
849.798	116.694
850.051	113.961
850.303	105.848
850.556	116.785
850.809	108.754
851.062	87.0179
851.314	106.101
851.567	95.4928
851.82	117.397
852.073	95.6323
852.325	106.7
852.578	106.224
852.831	103.545
853.083	112.558
853.336	109.716
853.588	106.586
853.841	107.776
854.093	118.505
854.346	107.064
854.598	96.6539
854.851	92.4728
855.103	97.6922
855.356	97.9866
855.608	92.3416
855.861	99.3942
856.113	98.5864
856.366	94.8552
856.618	96.4705
856.87	102.574
857.123	95.2852
857.352	105.324
857.606	97.0327
857.859	83.1523
858.113	113.754
858.367	88.797
858.621	83.174
858.875	102.538
859.128	99.8178
859.382	94.2307
859.636	97.0472
859.889	102.583
860.143	97.136
860.397	88.7474
860.65	86.1006
860.904	102.742
861.158	88.8722
861.411	83.4133
861.665	100.139
861.918	88.9235
862.172	91.5604
862.425	91.6062
862.679	94.3124
862.932	91.5618
863.186	89.0137
863.439	102.733
863.693	97.1951
863.946	100.123
864.2	86.23
864.453	94.6643
864.707	75.1181
864.96	100.064
865.213	86.2276
865.467	80.676
865.72	83.5297
865.973	89.2047
866.227	83.6914
866.48	94.8288
866.733	100.423
866.987	89.28
867.24	83.8591
867.493	92.202
867.746	89.499
867.999	78.3692
868.253	89.6054
868.506	95.2876
868.759	95.4541
869.012	84.2898
869.265	78.7345
869.518	90.005
869.771	87.1626
870.025	87.1965
870.278	84.404
870.531	81.7446
870.784	90.3511
871.037	90.3935
871.29	96.0151
871.543	87.675
871.796	76.4538
872.049	87.7868
872.302	90.6924
872.555	79.3274
872.808	79.3322
873.06	99.1941
873.313	73.7637
873.566	76.5841
873.819	82.3516
874.072	82.1681
874.325	82.1872
874.578	76.683
874.83	85.1958
875.083	70.9788
875.336	73.7999
875.589	82.3863
875.841	68.1663
876.094	76.6943
876.347	71.0846
876.6	82.4467
876.852	79.6786
877.105	88.2776
877.358	76.9551
877.61	76.9416
877.863	79.8045
878.115	77.0164
878.368	80.0099
878.621	77.2794
878.873	65.8289
879.126	82.9502
879.378	74.5604
879.631	68.9293
879.883	74.6686
880.136	89.0696
880.388	80.5848
880.641	66.313
880.893	77.9414
881.145	80.8325
881.398	66.5283
881.65	78.1916
881.902	75.3548
882.155	78.2956
882.407	72.4861
882.659	69.6413
882.912	78.504
883.164	75.6608
883.416	81.5786
883.669	78.6914
883.921	72.9572
884.173	73.0187
884.425	81.8854
884.677	64.3446
884.93	73.2125
885.182	76.1015
885.434	81.9053
885.686	73.1905
885.938	73.1974
886.19	73.2786
886.442	67.4145
886.694	76.2744
886.946	79.236
887.198	67.6605
887.45	70.6714
887.702	64.8039
887.954	76.6934
888.206	67.8972
888.458	62.0996
888.71	79.8132
888.962	73.9769
889.214	56.2466
889.466	68.1488
889.718	77.0884
889.969	71.2702
890.221	68.3761
890.473	62.4952
890.725	68.6692
890.977	77.6798
891.228	65.7747
891.48	62.861
891.732	56.909
891.983	72.1064
892.235	75.1683
892.487	60.2727
892.738	66.4443
892.99	72.6434
893.242	63.5782
893.493	48.4512
893.745	66.7127
893.996	66.8085
894.248	54.7346
894.5	57.7727
894.751	67.0463
895.003	54.9822
895.254	58.1986
895.505	70.5235
895.757	64.4609
896.008	67.6012
896.26	64.6168
896.511	70.8373
896.763	55.4385
897.014	55.5949
897.265	71.0851
897.517	67.9324
897.768	64.93
898.019	52.7068
898.27	71.1657
898.522	71.256
898.773	59.0854
899.024	62.2078
899.275	68.4518
899.527	68.375
899.778	56.1111
899.979	71.8122