File: LT_191023_M5_borda_01.txt
#Acq. time (s)=	5
#Accumulations=	2
#Range (nm)=	520...900
#Windows=	8
#Auto scanning=	Off
#Autofocus=	Off
#AutoExposure=	Off
#Spike filter=	Multiple accum.
#Delay time (s)=	0
#Binning=	1
#Readout mode=	Signal
#DeNoise=	Off
#ICS correction=	On
#Dark correction=	Off
#Inst. Process=	Off
#Detector temperature (°C)=	-59.98
#Instrument=	LabRAM HR Evol
#Detector=	Syncerity OE
#Objective=	x50_VIS
#Grating=	600 (500nm)
#ND Filter=	10%
#Laser=	514nm_Edge
#Hole=	199.981
#Range=	Auto
#StageXY=	Marzhauser
#StageZ=	Marzhauser
#X (µm)=	899.8
#Y (µm)=	23679
#Z (µm)=	-15.4
#Full time(mm:ss)=	2:04
#Project=
#Sample=
#Site=
#Title=	LT_191023_M5_borda
#Remark=
#Date=	27.10.2023 13:43
#Acquired=	27.10.2023 13:43:28
520.044	36.0343
520.306	26.7529
520.569	37.3148
520.831	26.7676
521.093	33.9968
521.355	39.323
521.617	28.456
521.88	35.4493
522.142	35.4654
522.404	33.8709
522.666	25.0449
522.928	30.4343
523.19	40.8814
523.453	31.7748
523.715	28.1416
523.977	28.1729
524.239	35.4387
524.501	30.294
524.763	21.4441
525.025	35.6207
525.287	26.6374
525.549	35.516
525.811	33.7522
526.073	39.3466
526.335	36.0135
526.597	32.5499
526.859	39.7661
527.121	30.6343
527.383	32.3998
527.645	39.5163
527.907	34.1117
528.169	34.2392
528.431	30.8249
528.693	40.1546
528.955	25.6417
529.217	31.0992
529.479	32.7937
529.741	34.4231
530.003	36.1642
530.264	37.9224
530.526	39.8421
530.788	40.1189
531.05	38.5881
531.312	35.019
531.574	33.3301
531.835	40.8193
532.097	42.8061
532.359	42.8814
532.621	43.0725
532.883	41.2632
533.144	37.493
533.406	39.3391
533.668	43.081
533.93	37.3447
534.191	53.9497
534.453	46.2744
534.715	53.7188
534.976	55.7041
535.238	65.2125
535.5	61.5318
535.761	48.641
536.023	45.0846
536.285	43.1961
536.546	50.5277
536.808	43.0002
537.069	46.4769
537.331	49.9294
537.593	47.8886
537.854	44.1014
538.116	38.4833
538.377	45.9061
538.639	38.5972
538.9	55.2187
539.162	46.0143
539.423	55.1043
539.685	42.2195
539.946	42.1608
540.208	51.2386
540.469	45.7895
540.731	47.7573
540.992	44.1051
541.254	51.6015
541.515	51.6798
541.776	48
542.038	57.3657
542.299	40.5891
542.56	53.2823
542.822	55.0114
543.083	47.566
543.344	54.8443
543.606	51.343
543.867	62.2693
544.128	58.6505
544.39	58.7559
544.651	64.3407
544.912	47.7984
545.174	58.7757
545.435	51.3182
545.696	52.9358
545.957	60.1407
546.218	61.7101
546.48	65.1727
546.741	61.5321
547.002	65.2664
547.263	74.3294
547.524	72.4958
547.785	72.5982
548.047	74.435
548.308	72.6627
548.569	63.4602
548.83	57.9917
549.091	74.2225
549.352	73.8914
549.613	70.1655
549.874	75.2946
550.135	87.7561
550.396	87.3835
550.657	96.2908
550.918	97.9616
551.179	94.2217
551.44	108.19
551.701	131.332
551.962	191.499
552.223	574.854
552.484	14058.1
552.745	648.916
553.006	182.676
553.267	145.57
553.528	121.006
553.788	101.213
554.049	103.035
554.31	111.972
554.571	95.8635
554.832	99.271
555.093	106.138
555.353	107.617
555.614	96.5775
555.875	115.58
556.136	120.705
556.396	118.69
556.657	118.791
556.918	122.146
557.179	117.055
557.439	115.649
557.7	121.21
557.961	118.069
558.221	127.277
558.482	134.36
558.743	132.47
559.003	118.375
559.264	126.689
559.525	132.998
559.785	139.64
560.046	111.019
560.306	143.226
560.567	135.293
560.827	131.163
561.088	150.947
561.348	152.247
561.609	157.184
561.869	150.535
562.13	159.095
562.39	152.354
562.651	156.151
562.911	163.236
563.172	175.495
563.432	172.175
563.692	185.659
563.953	185.197
564.213	193.574
564.474	189.62
564.734	180.204
564.994	200.879
565.255	173.437
565.515	192.17
565.775	184.704
566.035	210.305
566.296	184.851
566.556	208.608
566.816	191.676
567.076	193.303
567.337	214.589
567.597	213.23
567.857	202.15
568.117	205.8
568.377	226.61
568.637	227.898
568.898	230.659
569.158	245.945
569.418	237.949
569.678	241.458
569.938	247.61
570.198	257.826
570.458	261.422
570.718	267.298
570.978	267.036
571.238	282.983
571.498	294.549
571.758	296.093
572.018	311.36
572.278	336.664
572.538	353.606
572.798	372.139
573.058	376.078
573.312	397.36
573.573	442.281
573.834	449.579
574.095	486.716
574.356	541.396
574.617	604.002
574.878	616.319
575.139	660.707
575.4	665.329
575.661	683.272
575.922	709.84
576.183	692.966
576.444	635.725
576.705	596.969
576.965	569.842
577.226	556.983
577.487	537.051
577.748	513.693
578.009	476.697
578.27	468.391
578.531	456.886
578.791	452.129
579.052	424.922
579.313	430.082
579.574	427.494
579.835	437.847
580.095	434.566
580.356	433.088
580.617	429.011
580.878	442.934
581.138	428.125
581.399	456.937
581.66	455.707
581.92	441.132
582.181	473.132
582.442	475.537
582.703	477.086
582.963	467.827
583.224	486.301
583.484	488.209
583.745	477.575
584.006	512.785
584.266	496.792
584.527	523.618
584.787	526.046
585.048	532.201
585.308	534.285
585.569	548.404
585.83	561.202
586.09	543.754
586.351	557.727
586.611	576.959
586.872	578.455
587.132	569.352
587.392	583.794
587.653	585.096
587.913	588.764
588.174	595.588
588.434	582.977
588.695	595.16
588.955	607.56
589.215	607.672
589.476	589.523
589.736	609.917
589.996	607.297
590.257	581.381
590.517	583.879
590.777	579.948
591.038	578.571
591.298	582.899
591.558	585.214
591.818	573.819
592.079	573.492
592.339	573.264
592.599	575.67
592.859	579.864
593.12	575.253
593.38	571.352
593.64	570.212
593.9	584.685
594.16	578.473
594.42	573.466
594.68	576.612
594.941	607.156
595.201	592.084
595.461	605.742
595.721	616.909
595.981	607.395
596.241	638.241
596.501	636.236
596.761	622.738
597.021	644.777
597.281	654.963
597.541	646.122
597.801	652.929
598.061	654.684
598.321	659.385
598.581	644.725
598.841	652.959
599.101	626.062
599.361	643.633
599.62	658.274
599.88	648.822
600.14	639.965
600.4	644.342
600.66	619.497
600.92	673.167
601.18	652.382
601.439	667.943
601.699	628.956
601.959	651.591
602.219	666.013
602.478	667.111
602.738	633.076
602.998	660.157
603.258	663.115
603.517	644.633
603.777	653.688
604.037	675.443
604.296	656.487
604.556	664.741
604.816	688.689
605.075	667.784
605.335	648.261
605.594	664.573
605.854	670.901
606.114	651.006
606.373	677.388
606.633	690.255
606.892	681.492
607.152	666.815
607.411	675.695
607.671	673.995
607.93	680.519
608.19	681.276
608.449	665.305
608.709	674.918
608.968	688.64
609.228	704.696
609.487	702.099
609.746	730.103
610.006	710.873
610.265	720.857
610.524	710.693
610.784	724.282
611.043	719.055
611.302	704.772
611.562	734.611
611.821	716.67
612.08	744.913
612.339	681.979
612.599	736.376
612.858	730.625
613.117	708.53
613.376	738.633
613.635	753.216
613.895	760.514
614.154	764.329
614.413	783.353
614.672	785.176
614.931	758.094
615.19	781.838
615.449	794.152
615.709	789.17
615.968	787.73
616.227	797.569
616.486	800.797
616.745	792.506
617.004	774.527
617.263	785.633
617.522	805.645
617.781	815.353
618.04	806.706
618.299	821.316
618.557	807.747
618.816	822.821
619.075	826.697
619.334	821.792
619.593	823.682
619.852	830.627
620.111	831.331
620.37	824.922
620.628	828.868
620.887	826.63
621.146	828.864
621.373	847.873
621.633	837.242
621.893	863.723
622.153	832.377
622.413	845.701
622.673	852.953
622.932	827.987
623.192	840.826
623.452	806.426
623.712	851.169
623.972	840.562
624.232	862.089
624.492	828.825
624.751	832.154
625.011	853.544
625.271	851.613
625.531	857.268
625.791	841.954
626.05	857.52
626.31	864.955
626.57	865.759
626.83	879.724
627.089	871.918
627.349	902.207
627.609	878.633
627.868	891.131
628.128	893.36
628.388	893.499
628.647	902.801
628.907	901.602
629.167	905.002
629.426	934.778
629.686	907.42
629.945	911.083
630.205	934.661
630.465	932.551
630.724	933.838
630.984	932.028
631.243	940.673
631.503	932.668
631.762	977.617
632.022	987.159
632.281	980.036
632.541	973.157
632.8	998.054
633.06	999.513
633.319	1001.34
633.579	996.85
633.838	991.286
634.097	1047.51
634.357	1054.64
634.616	1068.56
634.876	1056.9
635.135	1082.4
635.394	1093.75
635.654	1133.31
635.913	1161.63
636.172	1207.42
636.431	1256.19
636.691	1290.33
636.95	1384.89
637.209	1437.78
637.469	1445.68
637.728	1499.85
637.987	1527.75
638.246	1519.22
638.505	1498.99
638.765	1471.53
639.024	1397.16
639.283	1379.62
639.542	1355.8
639.801	1335.01
640.06	1318.4
640.319	1294.96
640.578	1273.48
640.838	1277.85
641.097	1265.99
641.356	1252.31
641.615	1268.43
641.874	1284.45
642.133	1257.98
642.392	1258.3
642.651	1260.56
642.91	1255.99
643.169	1262.53
643.428	1261.54
643.687	1259.51
643.946	1291.78
644.205	1286.87
644.463	1295.74
644.722	1274.52
644.981	1292.91
645.24	1308.7
645.499	1281.47
645.758	1305.87
646.017	1317.6
646.275	1299.95
646.534	1312.61
646.793	1279.44
647.052	1331.18
647.31	1323.22
647.569	1325.37
647.828	1330.71
648.087	1375.68
648.345	1348.37
648.604	1336.36
648.863	1339.67
649.121	1377.88
649.38	1405.2
649.639	1400.98
649.897	1376.14
650.156	1426.2
650.415	1432.18
650.673	1396.66
650.932	1418.14
651.19	1453.39
651.449	1430.49
651.707	1466.55
651.966	1508.26
652.224	1462.92
652.483	1497.96
652.741	1509.4
653	1522.61
653.258	1520.06
653.517	1560.21
653.775	1536.51
654.034	1551.82
654.292	1584.47
654.55	1556.53
654.809	1611.19
655.067	1616.61
655.326	1604.94
655.584	1678.42
655.842	1647.04
656.1	1663.22
656.359	1696.78
656.617	1719.91
656.875	1708.52
657.134	1710.19
657.392	1739.25
657.65	1724.31
657.908	1748.63
658.166	1759.94
658.425	1802.56
658.683	1829.73
658.941	1822.16
659.199	1828.24
659.457	1805.12
659.715	1841.33
659.973	1816.02
660.231	1845.44
660.49	1841.71
660.748	1815.46
661.006	1824.16
661.264	1796.63
661.522	1793.16
661.78	1815.27
662.038	1813.33
662.296	1785.82
662.554	1821.73
662.811	1804.84
663.069	1768.07
663.327	1790.54
663.585	1798.57
663.843	1783.84
664.101	1754.18
664.359	1797.3
664.617	1774
664.874	1767.6
665.132	1784.94
665.39	1776.57
665.648	1788.06
665.906	1786.05
666.163	1787
666.421	1797.65
666.679	1798.07
666.937	1781.33
667.194	1793.82
667.452	1784.08
667.71	1787.54
667.967	1781.09
668.225	1784.68
668.482	1799.94
668.74	1800.52
668.987	1769.46
669.245	1821.26
669.504	1806.37
669.763	1794.28
670.022	1835.9
670.281	1838.49
670.539	1827.38
670.798	1831.18
671.057	1836.79
671.316	1824.09
671.575	1801.72
671.833	1804.1
672.092	1848.16
672.351	1812.83
672.609	1814.83
672.868	1833.29
673.127	1820.97
673.385	1858.03
673.644	1828.71
673.903	1843.5
674.161	1845.89
674.42	1836.6
674.678	1854.18
674.937	1863.8
675.195	1903.42
675.454	1899.16
675.713	1902.18
675.971	1885.18
676.23	1914.58
676.488	1909.65
676.747	1910.53
677.005	1954.64
677.263	1923.64
677.522	1920.35
677.78	1923.89
678.039	1933.34
678.297	1923.04
678.556	1934.9
678.814	1956.51
679.072	1970.26
679.331	1971.22
679.589	1994.73
679.847	1970.63
680.106	1965.91
680.364	1973.81
680.622	1958.38
680.881	1974.47
681.139	1941.23
681.397	2009.57
681.656	1999.39
681.914	1976.08
682.172	2002.38
682.43	1970.85
682.688	1979.44
682.947	1991.74
683.205	1997.28
683.463	1967.89
683.721	1991.18
683.979	1954.4
684.237	2002.32
684.495	2007.31
684.754	1985.04
685.012	1958.36
685.27	1964.59
685.528	1989.59
685.786	1973.93
686.044	1957.34
686.302	1964.2
686.56	1969.78
686.818	1934.51
687.076	1944.91
687.334	1952.68
687.592	1932.03
687.85	1927.23
688.108	1923.98
688.366	1946.09
688.623	1902.78
688.881	1954.31
689.139	1908.8
689.397	1932.09
689.655	1932.6
689.913	1943.37
690.171	1914.1
690.428	1937.19
690.686	1912.96
690.944	1908.76
691.202	1921.71
691.459	1921.43
691.717	1908.71
691.975	1900.75
692.233	1936.52
692.49	1884.89
692.748	1892.11
693.006	1896.38
693.263	1885.91
693.521	1867.42
693.779	1881.88
694.036	1885.14
694.294	1867.14
694.552	1903.63
694.809	1876.3
695.067	1860
695.324	1874.59
695.582	1898.91
695.839	1816.4
696.097	1879.51
696.354	1882.26
696.612	1882.76
696.869	1870.56
697.127	1839.64
697.384	1880.8
697.642	1822.57
697.899	1844.02
698.156	1833.6
698.414	1862.35
698.671	1843.64
698.928	1854.36
699.186	1839.13
699.443	1825.38
699.7	1821.19
699.958	1845.03
700.215	1856.14
700.472	1814.05
700.73	1843.5
700.987	1821.9
701.244	1804.88
701.501	1805.18
701.758	1848.36
702.016	1798.99
702.273	1783.38
702.53	1798.05
702.787	1818.29
703.044	1817.83
703.301	1819.2
703.558	1779.77
703.816	1811.55
704.073	1809.21
704.33	1808.06
704.587	1825.98
704.844	1812.29
705.101	1758.4
705.358	1808.86
705.615	1806.32
705.872	1819.51
706.129	1794.66
706.386	1808.38
706.643	1777.82
706.899	1787.92
707.156	1784.98
707.413	1764.16
707.67	1785.9
707.927	1798.13
708.184	1741.6
708.441	1750.32
708.697	1756.94
708.954	1785.55
709.211	1774.28
709.468	1743.29
709.725	1715.39
709.981	1751.66
710.238	1739.87
710.495	1735.24
710.751	1752.09
711.008	1736.72
711.265	1717.18
711.521	1756.58
711.778	1742.86
712.035	1708.83
712.291	1738.83
712.548	1746.65
712.804	1714.03
713.061	1722.22
713.317	1717.32
713.574	1728.74
713.831	1704.1
714.087	1710.53
714.343	1705.45
714.6	1688.71
714.856	1698.01
715.113	1690
715.369	1678.88
715.626	1683.97
715.882	1679.5
716.138	1660.79
716.395	1676.11
716.639	1655.61
716.897	1682.27
717.155	1671.6
717.412	1672.05
717.67	1661.14
717.927	1636.93
718.185	1611.77
718.443	1628
718.7	1622.98
718.958	1611.84
719.215	1618.05
719.473	1607.68
719.73	1591.81
719.988	1615.22
720.245	1585.55
720.503	1607.21
720.76	1591.39
721.018	1562.59
721.275	1572.08
721.532	1557
721.79	1578.91
722.047	1562.2
722.305	1535.84
722.562	1560.94
722.819	1572.26
723.077	1548.79
723.334	1538.18
723.591	1525.78
723.849	1528.84
724.106	1521.01
724.363	1510.61
724.621	1527.26
724.878	1515.75
725.135	1496.88
725.392	1494.42
725.65	1455.26
725.907	1480.08
726.164	1481.2
726.421	1457.89
726.678	1471.61
726.935	1451.74
727.193	1489.25
727.45	1452.68
727.707	1454.31
727.964	1482.66
728.221	1476.47
728.478	1440.24
728.735	1445.63
728.992	1443.6
729.249	1422.48
729.506	1422.6
729.763	1437.44
730.02	1380.19
730.277	1420.65
730.534	1404.5
730.791	1416.32
731.048	1365.43
731.305	1405.93
731.562	1391.56
731.819	1388.67
732.076	1400.18
732.333	1361.53
732.589	1366.11
732.846	1359.11
733.103	1355.82
733.36	1379.43
733.617	1351.66
733.873	1391.84
734.13	1362.67
734.387	1361.78
734.644	1370.54
734.901	1324.51
735.157	1352.83
735.414	1321.3
735.671	1343.38
735.927	1335.07
736.184	1288.18
736.441	1332.62
736.697	1367.04
736.954	1304.82
737.211	1316.45
737.467	1296.67
737.724	1301.61
737.98	1296.23
738.237	1315.49
738.493	1276.44
738.75	1304.26
739.006	1294.78
739.263	1287.66
739.519	1261.69
739.776	1292.61
740.032	1243.53
740.289	1262.95
740.545	1240.31
740.802	1256.55
741.058	1249.19
741.314	1243.74
741.571	1247.96
741.827	1209.58
742.083	1231.37
742.34	1239.71
742.596	1205.22
742.852	1187.19
743.109	1212.83
743.365	1188.83
743.621	1227.68
743.878	1186.98
744.134	1149.7
744.39	1201
744.646	1191.17
744.902	1177.95
745.159	1175.83
745.415	1196.52
745.671	1165.35
745.927	1174.39
746.183	1145.59
746.439	1136.53
746.695	1143.39
746.951	1124.47
747.207	1092.45
747.463	1156.89
747.719	1122.57
747.975	1123.23
748.231	1124.39
748.487	1107.17
748.743	1096.32
748.999	1111.09
749.255	1105.94
749.511	1105.23
749.767	1074.49
750.023	1079.11
750.279	1081.85
750.535	1077.76
750.791	1078.29
751.046	1054.18
751.302	1076.09
751.558	1090.94
751.814	1087.71
752.07	1053.49
752.325	1057.77
752.581	1051.41
752.837	1047.98
753.092	1042.03
753.348	1045.15
753.604	1032.27
753.859	1043.1
754.115	1011.78
754.371	1054.06
754.626	1015.16
754.882	1043.36
755.138	1029.3
755.393	1009.42
755.649	995.672
755.904	990.572
756.16	1009.37
756.415	979.284
756.671	991.57
756.926	986.591
757.182	956.086
757.437	960.602
757.693	973.977
757.948	956.084
758.203	937.48
758.459	976.727
758.714	948.181
758.97	911.015
759.225	956.345
759.48	937.944
759.736	939.67
759.991	948.963
760.246	927.468
760.501	954.308
760.757	921.454
761.012	913.283
761.267	920.94
761.522	915.9
761.777	912.504
762.033	899.735
762.288	909.063
762.543	913.44
762.798	891.632
763.053	897.341
763.308	872.909
763.563	903.239
763.78	878.023
764.037	870.593
764.293	843.219
764.55	889.517
764.806	856.757
765.062	842.009
765.319	856.812
765.575	843.097
765.831	878.974
766.088	854.733
766.344	841.41
766.6	820.588
766.857	806.056
767.113	844.693
767.369	835.616
767.625	836.292
767.882	820.697
768.138	815.366
768.394	809.548
768.65	799.527
768.906	803.619
769.163	798.968
769.419	789.113
769.675	803.289
769.931	811.227
770.187	797.158
770.443	767.704
770.699	795.559
770.955	792.823
771.211	774.487
771.467	774.334
771.723	770.882
771.979	779.374
772.235	785.471
772.491	749.738
772.747	792.707
773.003	747.598
773.259	756.059
773.515	773.934
773.771	746.675
774.027	762.283
774.283	739.988
774.539	743.158
774.795	718.03
775.05	716.044
775.306	720.063
775.562	715.022
775.818	697.356
776.074	705.752
776.329	722.963
776.585	696.771
776.841	697.892
777.097	697.118
777.352	677.701
777.608	710.951
777.864	677.572
778.12	682.106
778.375	691.09
778.631	674.326
778.886	693.792
779.142	661.791
779.398	660.986
779.653	680.201
779.909	695.86
780.164	664.163
780.42	664.259
780.675	663.527
780.931	656.488
781.187	643.659
781.442	656.146
781.698	646.036
781.953	643.374
782.208	669.161
782.464	637.141
782.719	618.118
782.975	632.263
783.23	628.111
783.485	628.174
783.741	633.698
783.996	584.377
784.252	610.207
784.507	588.066
784.762	625.022
785.017	599.256
785.273	609.898
785.528	613.113
785.783	619.889
786.038	587.654
786.294	616.174
786.549	584.14
786.804	596.831
787.059	581.163
787.314	568.773
787.57	580.1
787.825	540.801
788.08	551.261
788.335	565.766
788.59	561.027
788.845	569.947
789.1	538.156
789.355	555.335
789.61	559.776
789.865	537.74
790.12	564.792
790.375	535.057
790.63	539.769
790.885	540.975
791.14	538.694
791.395	497.756
791.65	536.738
791.905	515.933
792.16	513.834
792.414	519.235
792.669	531.88
792.924	507.32
793.179	496.771
793.434	520.952
793.689	507.945
793.943	504.884
794.198	512.122
794.453	468.388
794.708	499.78
794.962	495.252
795.217	510.202
795.472	493.974
795.726	488.575
795.981	489.624
796.236	498.439
796.49	460.678
796.745	468.122
796.999	487.597
797.254	486.572
797.508	479.5
797.763	444.614
798.018	465.004
798.272	466.638
798.526	458.996
798.781	460.857
799.035	431.831
799.29	458.58
799.544	455.065
799.799	451.708
800.053	428.329
800.307	457.081
800.562	460.407
800.816	429.231
801.07	453.727
801.325	444.051
801.579	438.694
801.833	432.788
802.088	446.645
802.342	410.157
802.596	415.163
802.85	424.842
803.105	421.609
803.359	429.005
803.613	431.898
803.867	419.873
804.121	400.875
804.375	377.141
804.63	422.229
804.884	409.278
805.138	389.968
805.392	374.694
805.646	402.517
805.9	400.923
806.154	396.477
806.408	405.28
806.662	394.997
806.916	379.721
807.17	388.49
807.424	376.63
807.678	374.364
807.931	375.679
808.185	377.536
808.439	374.242
808.693	377.68
808.947	376.477
809.201	356.105
809.454	355.592
809.708	367.283
809.962	357.942
810.216	365.613
810.469	362.329
810.678	347.928
810.933	360.37
811.188	342.145
811.443	347.425
811.699	345.799
811.954	365.375
812.209	363.258
812.464	354.408
812.719	359.898
812.974	352.799
813.229	339.747
813.484	325.972
813.739	343.206
813.994	315.764
814.249	339.997
814.504	320.71
814.759	341.15
815.014	341.629
815.268	342.002
815.523	313.734
815.778	323.236
816.033	320.553
816.288	316.934
816.543	338.928
816.798	329.703
817.052	321.022
817.307	314
817.562	302.786
817.817	298.717
818.071	313.292
818.326	309.003
818.581	314.417
818.836	324.992
819.09	313.423
819.345	301.59
819.6	297.459
819.854	296.183
820.109	331.277
820.364	289.299
820.618	305.02
820.873	273.125
821.127	291.304
821.382	279.101
821.637	276.997
821.891	284.953
822.146	295.561
822.4	270.794
822.655	286.92
822.909	282.531
823.164	297.854
823.418	277.459
823.672	290.418
823.927	295.451
824.181	288.073
824.436	293.557
824.69	283.892
824.944	271.367
825.199	269.189
825.453	277.243
825.707	282.857
825.962	254.763
826.216	252.309
826.47	257.219
826.725	247.021
826.979	267.713
827.233	275.762
827.487	271.022
827.741	255.346
827.996	248.407
828.25	254.311
828.504	264.37
828.758	254.672
829.012	270.382
829.266	249.835
829.52	265.513
829.774	247.719
830.029	250.878
830.283	230.478
830.537	248.771
830.791	233.11
831.045	249.079
831.299	238.932
831.553	233.959
831.807	223.685
832.061	244.637
832.315	229.174
832.568	213.944
832.822	229.764
833.076	229.95
833.33	225.076
833.584	227.864
833.838	230.669
834.092	225.686
834.345	212.554
834.599	236.569
834.853	220.975
835.107	199.974
835.36	226.213
835.614	213.262
835.868	244.917
836.122	229.661
836.375	224.368
836.629	216.125
836.883	208.229
837.136	213.744
837.39	218.863
837.643	213.766
837.897	208.684
838.151	205.792
838.404	232.041
838.658	208.127
838.911	205.575
839.165	187.265
839.418	221.829
839.672	213.817
839.925	216.679
840.179	195.789
840.432	209.036
840.686	201.162
840.939	204.082
841.192	214.958
841.446	217.794
841.699	191.451
841.952	215.566
842.206	193.954
842.459	209.906
842.712	217.984
842.966	202.015
843.219	180.888
843.472	194.38
843.725	184.033
843.979	197.45
844.232	186.685
844.485	181.529
844.738	181.687
844.991	203.139
845.244	179.182
845.497	176.598
845.75	187.553
846.004	190.338
846.257	193.159
846.51	174.454
846.763	185.439
847.016	177.196
847.269	188.054
847.522	177.324
847.775	174.836
848.028	172.251
848.281	177.839
848.534	186.054
848.786	170.167
849.039	170.323
849.292	173.309
849.545	167.899
849.798	170.97
850.051	160.088
850.303	157.415
850.556	176.535
850.809	182.163
851.062	171.316
851.314	157.79
851.567	166.43
851.82	147.428
852.073	163.941
852.325	145.137
852.578	151.037
852.831	152.146
853.083	146.043
853.336	158.42
853.588	149.323
853.841	149.637
854.093	153.342
854.346	153.4
854.598	161.396
854.851	158.988
855.103	168.324
855.356	153.763
855.608	148.79
855.861	146.661
856.113	151.271
856.366	143.934
856.618	151.369
856.87	155.518
857.123	156.277
857.352	146.9
857.606	155.252
857.859	144.131
858.113	149.822
858.367	144.295
858.621	163.575
858.875	141.336
859.128	138.636
859.382	130.26
859.636	149.73
859.889	144.17
860.143	127.664
860.397	146.988
860.65	161.092
860.904	141.618
861.158	130.531
861.411	130.681
861.665	150.208
861.918	133.385
862.172	138.728
862.425	149.901
862.679	127.599
862.932	130.406
863.186	144.647
863.439	133.275
863.693	130.519
863.946	127.935
864.2	155.77
864.453	139.212
864.707	147.454
864.96	125.08
865.213	122.388
865.467	122.405
865.72	122.51
865.973	125.444
866.227	128.327
866.48	105.985
866.733	125.529
866.987	139.5
867.24	117.403
867.493	136.906
867.746	120.264
867.999	131.548
868.253	120.407
868.506	134.524
868.759	115.106
869.012	120.815
869.265	126.538
869.518	137.82
869.771	112.468
870.025	129.388
870.278	126.606
870.531	124.026
870.784	112.939
871.037	127.116
871.29	121.431
871.543	121.614
871.796	133.086
872.049	118.937
872.302	133.204
872.555	99.1592
872.808	124.665
873.06	119.033
873.313	119.157
873.566	104.949
873.819	122.108
874.072	104.835
874.325	99.1915
874.578	122.125
874.83	127.794
875.083	102.209
875.336	102.185
875.589	113.636
875.841	124.971
876.094	99.4186
876.347	108.049
876.6	119.406
876.852	102.444
877.105	99.6682
877.358	116.858
877.61	94.0397
877.863	102.606
878.115	119.803
878.368	100.012
878.621	105.901
878.873	111.623
879.126	117.274
879.378	100.37
879.631	112.01
879.883	120.619
880.136	91.9428
880.388	115.121
880.641	103.794
880.893	106.809
881.145	101.041
881.398	115.701
881.65	110.047
881.902	113.032
882.155	95.6946
882.407	107.279
882.659	104.462
882.912	98.8568
883.164	116.401
883.416	107.8
883.669	99.0929
883.921	105.058
884.173	110.988
884.425	105.281
884.677	102.366
884.93	99.569
885.182	102.444
885.434	93.6061
885.686	102.467
885.938	114.188
886.19	111.383
886.442	102.587
886.694	93.8762
886.946	99.7786
887.198	100.02
887.45	108.952
887.702	114.88
887.954	85.5426
888.206	97.4178
888.458	94.628
888.71	115.286
888.962	106.527
889.214	85.8501
889.466	97.7787
889.718	88.9482
889.969	95.027
890.221	86.2133
890.473	101.183
890.725	83.5973
890.977	86.6428
891.228	101.652
891.48	98.7816
891.732	77.8755
891.983	93.1374
892.235	93.2087
892.487	90.4091
892.738	84.5655
892.99	96.8579
893.242	93.8535
893.493	93.8741
893.745	81.8747
893.996	97.176
894.248	88.1836
894.5	91.2201
894.751	94.4743
895.003	97.7462
895.254	85.7663
895.505	104.252
895.757	92.087
896.008	73.7468
896.26	92.3098
896.511	76.9971
896.763	80.0778
897.014	83.3924
897.265	86.5384
897.517	86.4594
897.768	77.2977
898.019	93.012
898.27	95.919
898.522	96.0407
898.773	74.6341
899.024	74.6494
899.275	99.5663
899.527	77.6988
899.778	96.6357
899.979	84.3013