File: M10_140224.txt
#Acq. time (s)=	2
#Accumulations=	3
#Range (nm)=	520...900
#Windows=	24
#Auto scanning=	On
#Autofocus=	Off
#AutoExposure=	Off
#Spike filter=	Multiple accum.
#Delay time (s)=	0
#Binning=	1
#Readout mode=	Signal
#DeNoise=	Off
#ICS correction=	Off
#Dark correction=	Off
#Inst. Process=	Off
#Detector temperature (°C)=	-59.98
#Instrument=	LabRAM HR Evol
#Detector=	Syncerity OE
#Objective=	x50_VIS
#Grating=	600 (500nm)
#ND Filter=	10%
#Laser=	514nm_Edge
#Hole=	199.981
#Range=	Auto
#StageXY=	Marzhauser
#StageZ=	Marzhauser
#X (µm)=	-19405.3
#Y (µm)=	1755.7
#Z (µm)=	-56.8
#Full time(mm:ss)=	3:04
#Project=
#Sample=
#Site=
#Title=	D
#Remark=
#Date=	20.02.2024 11:22
#Acquired=	20.02.2024 11:22:37
520.013	30.3932
520.274	31.5879
520.536	26.9169
520.797	30.2448
521.059	25.6176
521.32	29.3593
521.582	31.4609
521.843	32.7735
522.105	30.8361
522.366	28.0908
522.628	28.0204
522.889	32.2913
523.15	29.2012
523.412	32.8039
523.673	33.0829
523.935	33.2029
524.196	29.6422
524.457	32.6339
524.719	33.3601
524.98	32.8298
525.241	30.339
525.503	30.9184
525.764	33.7706
526.025	27.4695
526.286	28.4827
526.548	29.82
526.809	33.5742
527.07	30.4015
527.331	30.9966
527.593	30.5664
527.854	34.561
528.115	30.8168
528.376	34.1935
528.637	32.5237
528.898	25.4748
529.16	30.8822
529.421	32.0347
529.682	32.4938
529.943	33.6564
530.204	31.7517
530.465	32.4426
530.726	34.2756
530.987	29.7897
531.248	31.4401
531.509	28.9369
531.77	26.5929
532.031	29.4793
532.292	27.9312
532.553	29.9884
532.814	33.2461
533.075	35.6353
533.336	27.9318
533.597	32.5063
533.858	30.1647
534.119	34.2898
534.38	33.0412
534.641	34.9056
534.901	35.8466
535.162	35.1296
535.423	32.2244
535.684	33.1935
535.945	31.6385
536.205	34.9418
536.466	35.0508
536.727	34.9558
536.988	33.9933
537.248	30.7124
537.509	36.3859
537.77	39.3631
537.987	33.5386
538.249	33.7599
538.51	35.0671
538.771	35.9455
539.032	37.4428
539.293	36.6247
539.554	32.0078
539.815	31.5547
540.076	31.9821
540.337	31.8711
540.598	40.0108
540.859	34.5782
541.12	35.3762
541.381	39.4177
541.642	38.6251
541.903	33.2074
542.164	36.3504
542.425	32.8521
542.686	33.8943
542.947	35.733
543.208	34.2403
543.469	35.2306
543.73	37.7662
543.991	31.433
544.252	36.5052
544.513	34.1253
544.773	37.6216
545.034	38.3942
545.295	39.6115
545.556	38.9333
545.817	39.3653
546.077	36.3401
546.338	35.0469
546.599	40.7374
546.86	43.7376
547.12	39.2659
547.381	37.5574
547.642	44.6301
547.903	38.9381
548.163	37.3951
548.424	38.1778
548.685	39.7309
548.945	38.7752
549.206	42.6617
549.467	40.8532
549.727	44.4928
549.988	41.2836
550.248	40.0944
550.509	46.3018
550.769	44.6132
551.03	43.4216
551.291	49.7519
551.551	55.6169
551.812	63.9912
552.072	88.4215
552.332	201.129
552.593	4454.23
552.853	1072.61
553.114	115.884
553.374	75.9349
553.635	58.9947
553.895	52.6951
554.155	49.7991
554.416	51.8429
554.676	47.5905
554.937	47.3349
555.197	44.6476
555.457	45.656
555.686	43.8906
555.947	41.2838
556.207	43.2493
556.468	46.6269
556.729	43.0809
556.99	43.1741
557.25	47.4048
557.511	45.1428
557.772	45.0745
558.032	47.7372
558.293	47.2541
558.554	47.5021
558.814	43.3668
559.075	46.9641
559.336	47.7381
559.596	54.1431
559.857	49.5168
560.117	46.962
560.378	46.6557
560.638	53.7514
560.899	46.7973
561.159	46.0262
561.42	50.4613
561.68	43.8287
561.941	51.9815
562.201	51.0612
562.462	50.2025
562.722	53.9624
562.983	51.6222
563.243	49.8132
563.504	50.1845
563.764	48.3323
564.024	56.7634
564.285	51.9549
564.545	50.0243
564.805	56.8286
565.066	50.9875
565.326	56.6593
565.586	53.8108
565.847	62.9065
566.107	56.1667
566.367	55.2987
566.627	51.5123
566.888	58.8965
567.148	54.1863
567.408	58.4554
567.668	59.8371
567.928	62.0099
568.189	56.5469
568.449	58.5857
568.709	59.9691
568.969	64.5246
569.229	61.5254
569.489	57.8334
569.749	63.0809
570.009	61.8316
570.269	60.4107
570.53	64.7944
570.79	68.6257
571.05	61.1542
571.31	70.3715
571.57	69.3964
571.83	69.3742
572.09	71.3069
572.349	78.5017
572.609	79.4445
572.869	91.2344
573.129	85.5484
573.368	89.5497
573.629	92.2611
573.889	100.06
574.15	103.786
574.41	111.406
574.67	108.812
574.931	119.661
575.191	120.963
575.451	121.865
575.711	119.575
575.972	122.336
576.232	125.642
576.492	112.179
576.752	116.104
577.013	112.174
577.273	109.873
577.533	104.031
577.793	102.445
578.053	98.4366
578.313	93.0295
578.574	97.4096
578.834	93.9758
579.094	98.0967
579.354	89.9716
579.614	95.4299
579.874	101.178
580.134	93.0856
580.394	93.4932
580.654	96.7361
580.914	97.8349
581.174	102.748
581.434	98.0249
581.694	100.082
581.954	101.432
582.214	103.308
582.474	108.871
582.734	103.578
582.994	109.244
583.254	108.553
583.514	111.011
583.773	112.437
584.033	119.659
584.293	118.527
584.553	120.889
584.813	123.528
585.073	125.014
585.332	120.84
585.592	130.528
585.852	127.733
586.112	131.431
586.371	127.655
586.631	126.138
586.891	133.417
587.151	132.301
587.41	130.43
587.67	136.194
587.93	140.447
588.189	137.282
588.449	141.478
588.709	136.206
588.968	140.157
589.228	146.972
589.487	154.647
589.747	151.964
590.006	148.5
590.266	141.122
590.525	148.44
590.785	144.638
591.036	139.111
591.296	138.903
591.556	138.225
591.816	136.46
592.076	126.92
592.336	127.681
592.596	133.621
592.856	130.85
593.116	134.604
593.376	130.561
593.635	129.539
593.895	131.851
594.155	126.186
594.415	129.296
594.675	128.45
594.935	137.558
595.194	133.621
595.454	134.213
595.714	141.697
595.974	132.473
596.233	138.929
596.493	148.113
596.753	148.779
597.012	134.022
597.272	133.923
597.532	135.755
597.791	133.323
598.051	127.913
598.311	124.979
598.57	137.741
598.83	139.109
599.089	133.95
599.349	133.82
599.609	128.303
599.868	132.232
600.128	129.969
600.387	139.955
600.647	136.828
600.906	127.135
601.166	130.841
601.425	134.463
601.685	137.327
601.944	126.085
602.203	132.391
602.463	132.43
602.722	134.809
602.982	128.698
603.241	135.888
603.5	139.006
603.76	140.138
604.019	135.517
604.278	130.576
604.538	136.601
604.797	136.063
605.056	137.449
605.315	133.757
605.575	138.328
605.834	136.704
606.093	136.263
606.352	137.653
606.611	141.765
606.871	133.13
607.13	135.402
607.389	139.012
607.648	139.118
607.907	135.447
608.166	136.996
608.425	135.395
608.664	144.659
608.924	134.855
609.183	131.895
609.443	147.193
609.702	150.661
609.962	142.715
610.221	143.748
610.481	148.776
610.74	142.517
611	154.618
611.259	151.031
611.518	146.815
611.778	148.546
612.037	146.668
612.297	147.861
612.556	153.083
612.815	139.907
613.075	145.822
613.334	151.829
613.594	157.363
613.853	150.197
614.112	149.629
614.371	151.256
614.631	152.05
614.89	153.931
615.149	158.465
615.408	157.799
615.668	167.794
615.927	166.173
616.186	168.356
616.445	161.587
616.704	163.481
616.964	167.789
617.223	157.674
617.482	160.725
617.741	166.206
618	168.212
618.259	177.688
618.518	168.856
618.777	175.945
619.036	185.359
619.295	172.783
619.554	181.418
619.813	178.323
620.072	174.684
620.331	178.346
620.59	174.25
620.849	177.706
621.108	176.051
621.367	182.032
621.626	174.046
621.885	172.872
622.144	182.551
622.403	175.072
622.661	178.744
622.92	181.913
623.179	181.457
623.438	182.797
623.697	183.3
623.956	181.563
624.214	185.04
624.473	183.8
624.732	180.061
624.99	181.233
625.249	182.442
625.508	177.116
625.767	185.559
626.025	185.732
626.249	183.496
626.508	191.816
626.767	191.135
627.026	189.901
627.285	188.667
627.544	184.598
627.803	179.87
628.062	190.267
628.321	198.206
628.58	194.098
628.839	185.188
629.098	195.821
629.357	198.474
629.616	190.637
629.875	196.872
630.134	200.977
630.393	198.242
630.652	201.296
630.911	195.091
631.17	199.198
631.429	200.866
631.688	201.202
631.947	204.183
632.206	202.54
632.464	203.353
632.723	211.97
632.982	208.616
633.241	207.853
633.5	216.941
633.758	209.633
634.017	204.586
634.276	225.856
634.535	226.642
634.793	216.16
635.052	229.736
635.311	237.108
635.57	236.037
635.828	237.633
636.087	246.055
636.345	253.688
636.604	265.868
636.863	271.566
637.121	284.903
637.38	290.542
637.638	296.984
637.897	282.037
638.156	294.721
638.414	290.52
638.673	278.21
638.931	285.189
639.19	264.476
639.448	264.244
639.706	258.481
639.965	266.071
640.223	259.192
640.482	269.044
640.74	242.138
640.999	252.8
641.257	261.385
641.515	250.655
641.774	244.107
642.032	254.927
642.29	260.286
642.549	254.684
642.807	245.79
643.065	248.065
643.323	256.078
643.582	254.257
643.84	265.167
644.053	261.578
644.312	259.955
644.57	263.395
644.829	258.686
645.088	267.53
645.346	264.175
645.605	271.177
645.864	260.926
646.122	261.964
646.381	263.618
646.639	271.528
646.898	271.785
647.157	268.645
647.415	263.012
647.674	273.658
647.932	274.097
648.191	284.308
648.449	277.38
648.708	265.48
648.966	274.187
649.225	277.591
649.483	273.819
649.742	290.924
650	281.138
650.258	285.957
650.517	273.856
650.775	285.793
651.034	294.053
651.292	275.511
651.55	288.458
651.809	295.266
652.067	299.29
652.325	301.622
652.583	309.138
652.842	305.252
653.1	296.836
653.358	306.926
653.616	302.14
653.875	318.009
654.133	311.431
654.391	308.072
654.649	309.444
654.907	320.805
655.165	321.071
655.424	327.517
655.682	328.667
655.94	333.389
656.198	327.833
656.456	337.819
656.714	340.812
656.972	331.87
657.23	341.461
657.488	347.706
657.746	335.475
658.004	351.369
658.262	346.134
658.52	361.781
658.778	355.146
659.036	360.896
659.294	348.271
659.552	348.985
659.809	353.464
660.067	363.738
660.325	345.614
660.583	357.499
660.841	352.448
661.099	354.173
661.356	355.804
661.583	345.356
661.842	346.825
662.1	346.078
662.358	357.089
662.616	360.949
662.875	352.148
663.133	362.235
663.391	353.871
663.649	363.638
663.907	343.854
664.166	342.427
664.424	354.413
664.682	342.096
664.94	353.227
665.198	354.606
665.456	362.691
665.714	361.229
665.972	357.262
666.23	361.714
666.488	360.783
666.746	354.355
667.004	354.804
667.262	343.983
667.52	360.6
667.778	345.977
668.036	353.613
668.294	358.725
668.552	349.92
668.81	348.01
669.068	360.974
669.326	372.491
669.584	343.06
669.842	346.866
670.099	349.531
670.357	346.437
670.615	353.526
670.873	345.249
671.131	358.241
671.388	353.212
671.646	357.931
671.904	342.176
672.162	363.805
672.419	361.393
672.677	357.126
672.935	368.415
673.192	354.621
673.45	364.665
673.708	353.668
673.965	364.504
674.223	364.59
674.481	370.302
674.738	367.697
674.996	366.34
675.253	363.145
675.511	369.241
675.768	378.253
676.026	379.578
676.283	379.486
676.541	376.713
676.798	372.445
677.056	380.248
677.313	373.33
677.571	385.607
677.828	371.014
678.085	379.416
678.343	376.058
678.6	376.341
678.857	367.794
679.083	373.896
679.341	373.287
679.599	378.596
679.857	386.6
680.114	375.301
680.372	370.292
680.63	378.518
680.888	371.108
681.146	389.882
681.403	390.225
681.661	383.758
681.919	377.068
682.176	388.961
682.434	390.377
682.692	381.575
682.949	384.283
683.207	394.075
683.465	390.427
683.722	388.736
683.98	395.967
684.237	374.152
684.495	389.641
684.753	386.221
685.01	387.763
685.268	375.671
685.525	383.646
685.783	377.121
686.04	381.115
686.298	386.316
686.555	376.12
686.813	380.316
687.07	372.389
687.327	386.136
687.585	372.682
687.842	380.891
688.1	369.716
688.357	367.915
688.614	369.514
688.872	380.688
689.129	366.635
689.386	372.659
689.643	360.78
689.901	357.47
690.158	367.666
690.415	370.868
690.672	374.828
690.93	356.259
691.187	360.482
691.444	375.406
691.701	362.25
691.958	366.641
692.216	361.237
692.473	361.259
692.73	364.673
692.987	351.453
693.244	357.104
693.501	358.705
693.758	355.849
694.015	350.934
694.272	352.82
694.529	348.365
694.786	359.46
695.043	356.557
695.3	354.561
695.557	348.64
695.814	353.294
696.071	359.091
696.328	344.384
696.585	345.735
696.81	338.335
697.068	352.472
697.325	346.635
697.582	345.878
697.84	344.679
698.097	341.025
698.354	342.871
698.612	340.974
698.869	351.266
699.126	351.111
699.384	327.35
699.641	343.228
699.898	338.977
700.155	330.448
700.413	335.256
700.67	332.395
700.927	343.442
701.184	340.244
701.441	329.558
701.698	324.367
701.956	344.056
702.213	327.922
702.47	329.514
702.727	323.276
702.984	338.599
703.241	338.19
703.498	328.616
703.755	328.808
704.012	327.493
704.269	332.953
704.526	326.352
704.783	335.52
705.04	330.868
705.297	327.622
705.554	324.47
705.811	330.496
706.068	323.821
706.324	314.529
706.581	322.594
706.838	318.863
707.095	317.296
707.352	314.775
707.609	319.953
707.865	322.509
708.122	305.742
708.379	296.138
708.636	314.865
708.892	305.501
709.149	308.849
709.406	313.425
709.662	306.532
709.919	306.166
710.176	309.938
710.432	304.682
710.689	307.762
710.946	302.521
711.202	298.652
711.459	305.335
711.715	305.73
711.972	297.76
712.228	300.553
712.485	295.347
712.741	297.986
712.998	299.065
713.254	296.178
713.511	281.749
713.767	294.443
714.024	280.665
714.231	283.242
714.488	282.262
714.745	280.688
715.002	282.749
715.259	286.04
715.516	277.038
715.773	282.57
716.029	275.382
716.286	274.118
716.543	275.884
716.8	273.324
717.057	271.598
717.314	266.643
717.57	270.724
717.827	279.637
718.084	276.273
718.341	270.591
718.597	274.188
718.854	270.653
719.111	273.688
719.367	264.718
719.624	267.816
719.881	264.798
720.137	266.226
720.394	266.649
720.65	258.04
720.907	257.558
721.164	265.007
721.42	259.105
721.677	262.772
721.933	252.021
722.19	258.251
722.446	261.803
722.703	254.001
722.959	251.472
723.216	254.609
723.472	254.043
723.728	254.588
723.985	249.511
724.241	255.375
724.498	260.493
724.754	244.008
725.01	250.325
725.267	254.154
725.523	248.575
725.779	241.147
726.036	249.013
726.292	248.214
726.548	249.629
726.804	248.262
727.06	249.32
727.317	241.214
727.573	247.632
727.829	238.671
728.085	235.331
728.341	238.944
728.597	237.387
728.854	233.813
729.11	244.571
729.366	237.348
729.622	229.549
729.878	238.249
730.134	248.845
730.39	234.949
730.646	222.093
730.902	234.354
731.158	231.449
731.414	232.811
731.622	223.653
731.878	236.228
732.135	230.732
732.391	231.968
732.648	229.827
732.904	228.83
733.161	235.489
733.417	232.406
733.673	241.644
733.93	241.185
734.186	235.119
734.443	239.12
734.699	236.837
734.955	243.011
735.211	250.388
735.468	247.69
735.724	267.829
735.98	275.684
736.237	271.477
736.493	272.338
736.749	283.91
737.005	290.576
737.261	294.416
737.518	292.901
737.774	313.345
738.03	318.216
738.286	328.675
738.542	322.8
738.798	310.464
739.054	310.488
739.31	296.659
739.566	286.082
739.822	279.752
740.078	281.037
740.334	264.796
740.59	261.018
740.846	250.703
741.102	247.692
741.358	233.84
741.614	238.83
741.87	232.612
742.126	228.729
742.382	227.425
742.638	220.532
742.893	217.884
743.149	217.369
743.405	217.531
743.661	205.71
743.917	209.444
744.172	207.732
744.428	202.866
744.684	198.509
744.94	199.074
745.195	203.118
745.451	197.122
745.707	192.919
745.962	196.725
746.218	195.472
746.474	187.199
746.729	190.005
746.985	189.922
747.241	188.15
747.496	187.37
747.752	185.605
748.007	185.261
748.263	193.325
748.518	182.58
748.774	182.585
749.029	178.419
749.275	187.686
749.531	177.988
749.787	187.783
750.043	177.459
750.299	182.838
750.555	173.921
750.811	177.118
751.067	174.762
751.323	174.842
751.579	178.121
751.835	184.615
752.09	179.759
752.346	172.277
752.602	175.584
752.858	176.937
753.114	180.948
753.37	167.407
753.625	173.056
753.881	163.643
754.137	174.507
754.393	166.654
754.648	164.436
754.904	171.422
755.16	168.708
755.415	169.044
755.671	167.563
755.927	162.733
756.182	161.515
756.438	159.44
756.693	147.414
756.949	164.024
757.205	151.652
757.46	155.983
757.716	161.73
757.971	159.346
758.227	165.471
758.482	155.808
758.738	155.149
758.993	153.904
759.248	149.165
759.504	153.572
759.759	150.118
760.015	146.942
760.27	154.991
760.525	154.007
760.781	155.087
761.036	141.662
761.291	151.39
761.547	142.233
761.802	151.097
762.057	143.849
762.313	140.675
762.568	147.91
762.823	144.855
763.078	141.812
763.333	139.585
763.589	140.686
763.844	142.214
764.099	131.017
764.354	137.325
764.609	140.942
764.864	142.313
765.119	136.788
765.374	134.993
765.629	136.87
765.884	136.991
766.139	132.346
766.394	132.296
766.649	129.792
766.882	135.383
767.137	131.405
767.393	125.574
767.648	136.519
767.904	133.324
768.159	132.57
768.415	128.501
768.67	126.573
768.926	128.236
769.181	117.294
769.436	125.002
769.692	128.612
769.947	126.103
770.203	122.061
770.458	126.94
770.713	115.375
770.968	120.584
771.224	113.913
771.479	120.09
771.734	123.407
771.99	122.647
772.245	111.765
772.5	122.667
772.755	111.357
773.01	115.074
773.265	111.385
773.521	112.172
773.776	108.556
774.031	106.135
774.286	111.405
774.541	109.087
774.796	108.289
775.051	108.07
775.306	108.808
775.561	107.927
775.816	110.548
776.071	114.075
776.326	103.834
776.581	107.036
776.836	103.97
777.091	104.257
777.346	106.14
777.601	97.1187
777.856	104.657
778.111	105.122
778.365	97.6095
778.62	97.9375
778.875	101.146
779.13	95.9922
779.385	100.631
779.639	100.884
779.894	99.0016
780.149	95.9767
780.404	92.0647
780.658	100.946
780.913	96.36
781.168	90.1241
781.422	99.325
781.677	97.1441
781.932	100.029
782.186	95.6691
782.441	92.7785
782.695	88.6372
782.95	89.4316
783.204	88.0533
783.459	92.7528
783.714	84.6228
783.968	83.0763
784.211	94.8738
784.466	94.4092
784.721	92.8819
784.976	87.4762
785.231	87.8598
785.486	75.2389
785.741	83.8856
785.996	85.6002
786.251	86.3595
786.506	77.3324
786.761	77.5595
787.016	80.7009
787.271	86.8847
787.526	82.3151
787.78	84.2243
788.035	84.7054
788.29	83.9422
788.545	79.8765
788.8	82.9384
789.054	78.38
789.309	80.5192
789.564	80.0247
789.819	74.0688
790.073	79.3224
790.328	83.571
790.583	81.7897
790.837	72.565
791.092	72.6773
791.347	74.4972
791.601	76.2494
791.856	80.8439
792.11	77.2455
792.365	75.8078
792.619	76.275
792.874	74.4036
793.128	71.3709
793.383	74.4611
793.638	72.514
793.892	77.702
794.146	74.7776
794.401	75.089
794.655	76.9197
794.91	75.5507
795.164	68.477
795.418	77.33
795.673	70.8825
795.927	71.6995
796.181	75.6689
796.436	70.3417
796.69	71.4657
796.944	74.4161
797.199	70.7622
797.453	68.6626
797.707	69.0146
797.961	68.9837
798.216	65.9756
798.47	69.8671
798.724	69.204
798.978	70.8969
799.232	70.8846
799.486	63.9231
799.74	66.0509
799.994	60.4013
800.248	67.4181
800.503	63.7125
800.757	66.0618
801.011	64.7377
801.265	67.7531
801.508	68.5026
801.762	62.2765
802.017	59.4064
802.271	65.4411
802.526	67.952
802.78	58.763
803.035	69.5346
803.289	55.959
803.544	59.986
803.798	61.1738
804.052	60.3411
804.307	63.4792
804.561	61.4452
804.816	61.5797
805.07	64.3076
805.324	65.9579
805.579	59.4707
805.833	60.7756
806.087	60.7241
806.341	63.0854
806.596	57.2075
806.85	57.9322
807.104	57.132
807.358	54.273
807.613	55.7467
807.867	64.2013
808.121	59.04
808.375	55.4529
808.629	58.8941
808.883	57.6966
809.138	60.4883
809.392	54.8872
809.646	59.5131
809.9	61.1533
810.154	58.9202
810.408	51.6267
810.662	60.2756
810.916	58.1301
811.17	54.8381
811.424	48.4248
811.678	56.9175
811.932	52.7688
812.185	53.2275
812.439	51.5949
812.693	55.3508
812.947	51.4511
813.201	56.4658
813.455	57.5243
813.709	53.4803
813.962	52.6517
814.216	51.6611
814.47	51.893
814.724	52.0771
814.977	49.2823
815.231	48.1585
815.485	51.9105
815.739	51.8497
815.992	46.3307
816.246	49.6453
816.499	51.3288
816.753	49.9736
817.007	48.7837
817.26	46.4929
817.514	56.3566
817.767	51.2759
818.021	49.074
818.274	48.8074
818.528	52.8598
818.781	48.0942
819.01	47.3512
819.264	51.0668
819.518	51.4483
819.772	46.088
820.026	44.2535
820.28	51.075
820.534	48.6815
820.788	48.5867
821.042	42.16
821.296	49.566
821.549	48.3074
821.803	47.2208
822.057	46.2491
822.311	46.004
822.565	47.9651
822.819	46.1673
823.073	42.407
823.326	49.5464
823.58	41.4931
823.834	44.6818
824.088	47.1311
824.341	45.3554
824.595	43.7184
824.849	46.1911
825.103	44.9973
825.356	45.9006
825.61	46.7105
825.864	44.756
826.117	48.413
826.371	44.614
826.624	43.4524
826.878	43.7777
827.131	46.3924
827.385	40.2742
827.638	40.5659
827.892	39.6976
828.146	43.3135
828.399	46.8217
828.652	43.0794
828.906	44.6659
829.159	46.9447
829.413	40.9457
829.666	41.0195
829.919	40.7896
830.173	46.3682
830.426	41.9088
830.68	41.5561
830.933	44.9615
831.186	41.3055
831.439	37.8797
831.693	42.5055
831.946	44.9621
832.199	43.2923
832.452	38.1322
832.706	38.034
832.959	41.1863
833.212	40.2089
833.465	40.7838
833.718	42.5054
833.971	46.6084
834.224	39.9405
834.477	46.0587
834.73	41.7872
834.984	44.1505
835.237	38.8825
835.49	39.7331
835.743	41.6943
835.996	36.1998
836.201	38.0325
836.454	38.1043
836.708	37.0334
836.961	39.881
837.215	33.9208
837.468	39.8678
837.722	43.0237
837.975	40.5462
838.229	36.8179
838.482	39.3351
838.735	40.8961
838.989	39.3075
839.242	30.9349
839.496	40.923
839.749	39.2704
840.002	39.7493
840.256	39.0048
840.509	41.0141
840.762	38.6773
841.015	39.0432
841.269	36.9041
841.522	39.4904
841.775	40.0299
842.028	35.1206
842.281	38.7709
842.535	37.7931
842.788	38.5584
843.041	38.3297
843.294	37.6114
843.547	37.8129
843.8	37.7471
844.053	40.143
844.306	36.3772
844.559	39.2628
844.812	35.855
845.065	38.2829
845.318	39.0908
845.571	36.7969
845.824	36.0182
846.077	40.4266
846.33	37.4989
846.583	34.2837
846.836	35.0877
847.089	40.4206
847.342	36.7422
847.595	34.4061
847.847	36.9681
848.1	38.2198
848.353	35.1534
848.606	35.4333
848.859	35.0625
849.111	40.7868
849.364	39.9535
849.617	34.465
849.869	36.5526
850.122	41.0255
850.375	36.7741
850.627	32.4225
850.88	33.2704
851.133	37.7757
851.385	37.4994
851.638	34.0281
851.89	37.2341
852.143	33.8273
852.395	37.1138
852.648	40.3371
852.9	38.4789
853.153	40.2677
853.405	31.1894
853.645	35.0004
853.898	37.092
854.151	36.0286
854.404	31.9485
854.657	35.4628
854.91	36.5064
855.163	35.933
855.416	32.7217
855.669	34.3144
855.922	34.9837
856.175	33.0409
856.427	34.0243
856.68	33.7712
856.933	35.9523
857.186	31.3042
857.439	30.705
857.692	35.5111
857.944	34.4126
858.197	33.2696
858.45	34.3248
858.703	37.0772
858.955	31.5449
859.208	33.5099
859.461	33.5645
859.713	34.9111
859.966	27.8088
860.219	31.5445
860.471	33.588
860.724	33.7985
860.976	30.1339
861.229	36.2544
861.481	40.1911
861.734	36.3888
861.986	30.7886
862.239	36.9008
862.491	38.4635
862.744	31.8457
862.996	34.9984
863.249	32.4853
863.501	36.0301
863.754	30.2922
864.006	31.9196
864.258	40.1281
864.511	37.8694
864.763	33.002
865.015	30.3479
865.268	34.2922
865.52	31.0292
865.772	29.702
866.024	35.8321
866.276	33.6421
866.529	29.4882
866.781	30.9761
867.033	37.1054
867.285	33.8074
867.537	30.0904
867.789	30.4695
868.042	34.5411
868.294	36.5381
868.546	31.0606
868.798	32.6044
869.05	36.6886
869.302	28.6356
869.554	28.0854
869.806	29.2279
870.058	35.8812
870.31	34.4258
870.562	33.3944
870.782	31.9951
871.034	37.2662
871.287	33.5516
871.539	31.0719
871.792	31.6548
872.044	33.6802
872.297	34.2425
872.549	25.6714
872.801	30.3747
873.054	35.0501
873.306	31.2024
873.558	33.2394
873.811	36.7447
874.063	31.1013
874.315	30.1254
874.568	27.3508
874.82	32.264
875.072	29.9859
875.324	26.7416
875.577	29.935
875.829	30.4603
876.081	35.3343
876.333	31.2171
876.585	33.9153
876.838	34.3954
877.09	29.3818
877.342	25.0878
877.594	36.5811
877.846	32.4091
878.098	25.3435
878.35	28.5207
878.602	39.2966
878.854	37.3956
879.106	31.2402
879.358	31.5632
879.61	30.0285
879.862	29.129
880.114	33.5919
880.366	31.149
880.618	29.2859
880.87	30.083
881.121	31.2628
881.373	31.2184
881.625	33.9103
881.877	28.1933
882.129	30.982
882.38	32.8433
882.632	32.694
882.884	29.5279
883.136	29.8021
883.387	32.3908
883.639	26.7828
883.891	26.3155
884.142	28.2524
884.394	30.6532
884.646	29.96
884.897	29.3352
885.149	33.9082
885.4	30.9993
885.652	31.2273
885.903	30.7636
886.155	34.1802
886.406	32.3852
886.658	29.5636
886.909	30.5306
887.161	30.7785
887.412	27.3191
887.664	30.2707
887.915	32.9405
888.138	33.5785
888.39	28.6072
888.642	33.0937
888.894	32.8859
889.146	33.5873
889.398	26.4929
889.65	26.1654
889.902	28.0957
890.154	30.2219
890.406	24.3953
890.657	30.7099
890.909	29.4026
891.161	26.4208
891.413	31.4409
891.665	32.6741
891.916	30.883
892.168	29.8163
892.42	28.4912
892.671	29.2432
892.923	32.1911
893.175	30.0415
893.426	28.8945
893.678	27.6515
893.93	27.2528
894.181	28.8005
894.433	31.2035
894.684	29.7005
894.936	30.0516
895.188	29.4632
895.439	29.503
895.69	29.7401
895.942	32.2952
896.193	31.9084
896.445	27.6565
896.696	33.0961
896.948	27.0334
897.199	27.5039
897.451	29.3729
897.702	30.2323
897.953	27.7151
898.204	32.3425
898.456	28.6932
898.707	30.2958
898.958	27.4569
899.21	29.4927
899.461	26.3759
899.712	28.0874
899.963	35.3333