File: M1_270224_01.txt
#Acq. time (s)=	3
#Accumulations=	2
#Range (nm)=	520...900
#Windows=	8
#Auto scanning=	Off
#Autofocus=	Off
#AutoExposure=	Off
#Spike filter=	Multiple accum.
#Delay time (s)=	0
#Binning=	1
#Readout mode=	Signal
#DeNoise=	Off
#ICS correction=	Off
#Dark correction=	Off
#Inst. Process=	Off
#Detector temperature (°C)=	-59.98
#Instrument=	LabRAM HR Evol
#Detector=	Syncerity OE
#Objective=	x50_VIS
#Grating=	600 (500nm)
#ND Filter=	10%
#Laser=	514nm_Edge
#Hole=	199.981
#Range=	Auto
#StageXY=	Marzhauser
#StageZ=	Marzhauser
#X (µm)=	0
#Y (µm)=	0
#Z (µm)=	0
#Full time(mm:ss)=	1:14
#Project=
#Sample=
#Site=
#Title=	M1_270224
#Remark=
#Date=	06.03.2024 10:10
#Acquired=	06.03.2024 10:10:46
520.044	22
520.306	26
520.569	22
520.831	28
521.093	24
521.355	30
521.617	28
521.88	26
522.142	26
522.404	22
522.666	32
522.928	24
523.19	28
523.453	22
523.715	32
523.977	18
524.239	28
524.501	20
524.763	28
525.025	26
525.287	20
525.549	22
525.811	24
526.073	22
526.335	20
526.597	24
526.859	24
527.121	28
527.383	22
527.645	38
527.907	24
528.169	36
528.431	18
528.693	16
528.955	26
529.217	28
529.479	26
529.741	22
530.003	20
530.264	30
530.526	32
530.788	16
531.05	26
531.312	20
531.574	26
531.835	26
532.097	26
532.359	26
532.621	30
532.883	28
533.144	28
533.406	26
533.668	28
533.93	28
534.191	26
534.453	24
534.715	34
534.976	38
535.238	28
535.5	36
535.761	24
536.023	40
536.285	30
536.546	32
536.808	28
537.069	24
537.331	38
537.593	30
537.854	30
538.116	30
538.377	28
538.639	22
538.9	30
539.162	32
539.423	30
539.685	20
539.946	34
540.208	24
540.469	30
540.731	22
540.992	30
541.254	18
541.515	26
541.776	38
542.038	18
542.299	34
542.56	36
542.822	30
543.083	30
543.344	26
543.606	30
543.867	44
544.128	28
544.39	34
544.651	32
544.912	36
545.174	30
545.435	32
545.696	36
545.957	36
546.218	36
546.48	32
546.741	40
547.002	36
547.263	38
547.524	32
547.785	40
548.047	24
548.308	40
548.569	38
548.83	36
549.091	36
549.352	44
549.613	48
549.874	44
550.135	36
550.396	46
550.657	48
550.918	44
551.179	48
551.44	58
551.701	78
551.962	94
552.223	180
552.484	1618
552.745	14336
553.006	318
553.267	118
553.528	82
553.788	70
554.049	64
554.31	42
554.571	38
554.832	48
555.093	48
555.353	38
555.614	48
555.875	46
556.136	40
556.396	48
556.657	52
556.918	48
557.179	50
557.439	48
557.7	48
557.961	48
558.221	54
558.482	50
558.743	50
559.003	56
559.264	56
559.525	44
559.785	44
560.046	54
560.306	48
560.567	60
560.827	50
561.088	58
561.348	56
561.609	58
561.869	56
562.13	60
562.39	60
562.651	46
562.911	58
563.172	56
563.432	72
563.692	58
563.953	52
564.213	62
564.474	66
564.734	72
564.994	74
565.255	70
565.515	60
565.775	62
566.035	66
566.296	72
566.556	62
566.816	68
567.076	70
567.337	66
567.597	74
567.857	74
568.117	62.01
568.377	81.9553
568.637	75.789
568.898	81.3655
569.158	79.4749
569.418	88.4045
569.678	80.2081
569.938	75.8261
570.198	80.4937
570.458	82.1399
570.718	84.0083
570.978	88.8237
571.238	96.7759
571.498	87.7289
571.758	100.795
572.018	101.366
572.278	106.142
572.538	103.455
572.798	114.188
573.058	130.703
573.312	128
573.573	138
573.834	142
574.095	162
574.356	170
574.617	188
574.878	192
575.139	190
575.4	198
575.661	202
575.922	198
576.183	186
576.444	200
576.705	170
576.965	162
577.226	164
577.487	144
577.748	164
578.009	140
578.27	140
578.531	130
578.791	136
579.052	134
579.313	144
579.574	130
579.835	154
580.095	158
580.356	142
580.617	140
580.878	146
581.138	160
581.399	148
581.66	146
581.92	158
582.181	166
582.442	164
582.703	162
582.963	158
583.224	160
583.484	174
583.745	172
584.006	180
584.266	196
584.527	190
584.787	194
585.048	194
585.308	206
585.569	192
585.83	210
586.09	202
586.351	216
586.611	216
586.872	212
587.132	222
587.392	222
587.653	232
587.913	212
588.174	220
588.434	214
588.695	250
588.955	244
589.215	260
589.476	246
589.736	248
589.996	242
590.257	244
590.517	242
590.777	230
591.038	240
591.298	238
591.558	212
591.818	206
592.079	206
592.339	226
592.599	214
592.859	218
593.12	204
593.38	220
593.64	214
593.9	208
594.16	198
594.42	218
594.68	224
594.941	214
595.201	208
595.461	236
595.721	224
595.981	216
596.241	214
596.501	240
596.761	242
597.021	228
597.281	208
597.541	216
597.801	206
598.061	200
598.321	212
598.581	206
598.841	206
599.101	218
599.361	208
599.62	204
599.88	212
600.14	226
600.4	200
600.66	202
600.92	220
601.18	216
601.439	226
601.699	216
601.959	224
602.219	212
602.478	218
602.738	210
602.998	228
603.258	228
603.517	230
603.777	228
604.037	226
604.296	224
604.556	222
604.816	230
605.075	232
605.335	232
605.594	226
605.854	236
606.114	242
606.373	234
606.633	228
606.892	238
607.152	230
607.411	224
607.671	224
607.93	232
608.19	222
608.449	226
608.709	236
608.968	244
609.228	250
609.487	230
609.746	240
610.006	240
610.265	240
610.524	242
610.784	246
611.043	248
611.302	252
611.562	240
611.821	236
612.08	238
612.339	246
612.599	246
612.858	256
613.117	256
613.376	256
613.635	262
613.895	256
614.154	282
614.413	268
614.672	282
614.931	270
615.19	280
615.449	278
615.709	288
615.968	274
616.227	277.84
616.486	288.681
616.745	288.518
617.004	273.044
617.263	293.586
617.522	287.003
617.781	294.77
618.04	298.019
618.299	289.73
618.557	294.353
618.816	303.942
619.075	307.04
619.334	302.334
619.593	297.072
619.852	298.87
620.111	304.928
620.37	315.323
620.628	299.351
620.887	310.048
621.146	308.58
621.373	296
621.633	310
621.893	316
622.153	314
622.413	318
622.673	292
622.932	328
623.192	328
623.452	318
623.712	342
623.972	324
624.232	310
624.492	324
624.751	330
625.011	322
625.271	330
625.531	334
625.791	328
626.05	334
626.31	340
626.57	310
626.83	340
627.089	346
627.349	340
627.609	342
627.868	346
628.128	338
628.388	330
628.647	342
628.907	338
629.167	346
629.426	356
629.686	326
629.945	352
630.205	362
630.465	374
630.724	374
630.984	374
631.243	364
631.503	362
631.762	384
632.022	388
632.281	376
632.541	382
632.8	410
633.06	408
633.319	406
633.579	412
633.838	440
634.097	396
634.357	410
634.616	428
634.876	450
635.135	454
635.394	454
635.654	494
635.913	486
636.172	544
636.431	544
636.691	568
636.95	584
637.209	614
637.469	608
637.728	598
637.987	626
638.246	582
638.505	578
638.765	556
639.024	568
639.283	554
639.542	524
639.801	532
640.06	528
640.319	534
640.578	510
640.838	496
641.097	518
641.356	518
641.615	538
641.874	502
642.133	514
642.392	506
642.651	516
642.91	518
643.169	504
643.428	512
643.687	506
643.946	550
644.205	516
644.463	524
644.722	534
644.981	538
645.24	518
645.499	526
645.758	548
646.017	552
646.275	530
646.534	530
646.793	538
647.052	552
647.31	544
647.569	530
647.828	548
648.087	562
648.345	564
648.604	558
648.863	554
649.121	562
649.38	574
649.639	592
649.897	564
650.156	594
650.415	596
650.673	584
650.932	588
651.19	610
651.449	588
651.707	590
651.966	630
652.224	624
652.483	626
652.741	632
653	602
653.258	586
653.517	678
653.775	650
654.034	656
654.292	686
654.55	690
654.809	684
655.067	674
655.326	654
655.584	694
655.842	708
656.1	690
656.359	708
656.617	732
656.875	772
657.134	752
657.392	778
657.65	746
657.908	756
658.166	760
658.425	780
658.683	756
658.941	784
659.199	758
659.457	788
659.715	782
659.973	754
660.231	780
660.49	774
660.748	756
661.006	774
661.264	770
661.522	742
661.78	744
662.038	760
662.296	780
662.554	772
662.811	764
663.069	768
663.327	764
663.585	786
663.843	749.315
664.101	769.459
664.359	734.735
664.617	777.873
664.874	772.975
665.132	747.166
665.39	772.661
665.648	755.149
665.906	780.314
666.163	762.591
666.421	763.793
666.679	774.88
666.937	768.98
667.194	770.309
667.452	785.07
667.71	769.562
667.967	790.071
668.225	779.964
668.482	762.666
668.74	773.257
668.987	780
669.245	756
669.504	758
669.763	770
670.022	784
670.281	800
670.539	772
670.798	758
671.057	804
671.316	814
671.575	738
671.833	774
672.092	818
672.351	796
672.609	800
672.868	794
673.127	780
673.385	806
673.644	812
673.903	816
674.161	818
674.42	814
674.678	828
674.937	826
675.195	824
675.454	822
675.713	850
675.971	846
676.23	836
676.488	822
676.747	842
677.005	810
677.263	856
677.522	830
677.78	800
678.039	890
678.297	868
678.556	848
678.814	832
679.072	828
679.331	832
679.589	840
679.847	854
680.106	856
680.364	864
680.622	838
680.881	872
681.139	898
681.397	836
681.656	854
681.914	852
682.172	878
682.43	864
682.688	848
682.947	896
683.205	868
683.463	870
683.721	880
683.979	874
684.237	876
684.495	854
684.754	884
685.012	874
685.27	866
685.528	830
685.786	830
686.044	886
686.302	848
686.56	840
686.818	850
687.076	828
687.334	862
687.592	826
687.85	852
688.108	834
688.366	842
688.623	818
688.881	834
689.139	844
689.397	824
689.655	844
689.913	828
690.171	854
690.428	846
690.686	834
690.944	844
691.202	822
691.459	846
691.717	812
691.975	822
692.233	832
692.49	824
692.748	812
693.006	802
693.263	798
693.521	822
693.779	830
694.036	816
694.294	790
694.552	812
694.809	824
695.067	808
695.324	810
695.582	800
695.839	794
696.097	794
696.354	778
696.612	788
696.869	786
697.127	792
697.384	760
697.642	778
697.899	788
698.156	764
698.414	742
698.671	768
698.928	758
699.186	766
699.443	760
699.7	756
699.958	754
700.215	780
700.472	782
700.73	734
700.987	740
701.244	738
701.501	756
701.758	774
702.016	748
702.273	756
702.53	752
702.787	746
703.044	750
703.301	768
703.558	756
703.816	756
704.073	752
704.33	752
704.587	736
704.844	732
705.101	716
705.358	748
705.615	736
705.872	740
706.129	722
706.386	712
706.643	716
706.899	728
707.156	718
707.413	748
707.67	694
707.927	704
708.184	728
708.441	702
708.697	670
708.954	704
709.211	682
709.468	656
709.725	718
709.981	696
710.238	668
710.495	672
710.751	694
711.008	682
711.265	682.03
711.521	686.596
711.778	665.41
712.035	671.117
712.291	682.266
712.548	688.164
712.804	655.491
713.061	685.29
713.317	653.734
713.574	655.289
713.831	650.369
714.087	639.152
714.343	651.318
714.6	635.154
714.856	644.33
715.113	629.037
715.369	631.277
715.626	632.026
715.882	625.865
716.138	651.595
716.395	631.414
716.639	634
716.897	632
717.155	618
717.412	614
717.67	622
717.927	622
718.185	614
718.443	604
718.7	602
718.958	636
719.215	598
719.473	600
719.73	596
719.988	610
720.245	592
720.503	592
720.76	552
721.018	598
721.275	590
721.532	558
721.79	540
722.047	556
722.305	564
722.562	534
722.819	570
723.077	522
723.334	548
723.591	536
723.849	536
724.106	530
724.363	546
724.621	538
724.878	544
725.135	542
725.392	526
725.65	546
725.907	522
726.164	550
726.421	532
726.678	520
726.935	516
727.193	504
727.45	506
727.707	496
727.964	502
728.221	498
728.478	528
728.735	486
728.992	518
729.249	482
729.506	486
729.763	478
730.02	494
730.277	482
730.534	494
730.791	490
731.048	490
731.305	458
731.562	458
731.819	470
732.076	450
732.333	452
732.589	428
732.846	438
733.103	478
733.36	464
733.617	444
733.873	462
734.13	460
734.387	460
734.644	458
734.901	442
735.157	444
735.414	458
735.671	452
735.927	442
736.184	446
736.441	452
736.697	454
736.954	464
737.211	470
737.467	476
737.724	444
737.98	466
738.237	458
738.493	474
738.75	466
739.006	442
739.263	446
739.519	452
739.776	448
740.032	424
740.289	450
740.545	434
740.802	424
741.058	430
741.314	424
741.571	432
741.827	390
742.083	418
742.34	390
742.596	398
742.852	418
743.109	410
743.365	402
743.621	386
743.878	410
744.134	404
744.39	402
744.646	404
744.902	380
745.159	402
745.415	382
745.671	370
745.927	382
746.183	378
746.439	390
746.695	360
746.951	362
747.207	386
747.463	384
747.719	386
747.975	360
748.231	366
748.487	372
748.743	366
748.999	362
749.255	382
749.511	382
749.767	372
750.023	368
750.279	346
750.535	380
750.791	356
751.046	354
751.302	348
751.558	338
751.814	344
752.07	338
752.325	338
752.581	334
752.837	344
753.092	348
753.348	344
753.604	354
753.859	322
754.115	336
754.371	320
754.626	324
754.882	318
755.138	348
755.393	326
755.649	316
755.904	312
756.16	322
756.415	326
756.671	308
756.926	330
757.182	304
757.437	306
757.693	298
757.948	304
758.203	316
758.459	316
758.714	313.912
758.97	304.304
759.225	264.315
759.48	297.967
759.736	288.955
759.991	288.553
760.246	281.517
760.501	295.749
760.757	298.51
761.012	294.119
761.267	277.993
761.522	278.64
761.777	289.532
762.033	275.927
762.288	284.817
762.543	274.958
762.798	276.493
763.053	273.865
763.308	283.853
763.563	270.268
763.78	260
764.037	278
764.293	268
764.55	276
764.806	238
765.062	276
765.319	282
765.575	256
765.831	256
766.088	262
766.344	258
766.6	258
766.857	262
767.113	256
767.369	254
767.625	250
767.882	264
768.138	254
768.394	250
768.65	260
768.906	244
769.163	236
769.419	220
769.675	244
769.931	244
770.187	236
770.443	234
770.699	232
770.955	240
771.211	238
771.467	220
771.723	222
771.979	220
772.235	226
772.491	222
772.747	228
773.003	222
773.259	206
773.515	220
773.771	212
774.027	198
774.283	216
774.539	206
774.795	222
775.05	216
775.306	190
775.562	208
775.818	206
776.074	202
776.329	212
776.585	190
776.841	200
777.097	194
777.352	200
777.608	192
777.864	192
778.12	184
778.375	194
778.631	192
778.886	176
779.142	186
779.398	186
779.653	182
779.909	190
780.164	174
780.42	188
780.675	184
780.931	190
781.187	174
781.442	180
781.698	184
781.953	180
782.208	164
782.464	168
782.719	184
782.975	174
783.23	168
783.485	158
783.741	170
783.996	168
784.252	176
784.507	168
784.762	150
785.017	150
785.273	180
785.528	158
785.783	152
786.038	152
786.294	162
786.549	154
786.804	156
787.059	152
787.314	162
787.57	154
787.825	144
788.08	152
788.335	148
788.59	158
788.845	144
789.1	156
789.355	146
789.61	158
789.865	144
790.12	122
790.375	146
790.63	132
790.885	142
791.14	134
791.395	136
791.65	140
791.905	136
792.16	132
792.414	146
792.669	140
792.924	132
793.179	122
793.434	124
793.689	130
793.943	128
794.198	126
794.453	124
794.708	122
794.962	118
795.217	132
795.472	108
795.726	130
795.981	120
796.236	126
796.49	122
796.745	128
796.999	124
797.254	120
797.508	116
797.763	114
798.018	118
798.272	118
798.526	126
798.781	104
799.035	126
799.29	120
799.544	110
799.799	100
800.053	126
800.307	102
800.562	114
800.816	102
801.07	94
801.325	118
801.579	114
801.833	104
802.088	98
802.342	116
802.596	114
802.85	108
803.105	102
803.359	110
803.613	98
803.867	100
804.121	104
804.375	100
804.63	112
804.884	98
805.138	88
805.392	96
805.646	103.669
805.9	89.8704
806.154	94.3276
806.408	90.784
806.662	93.8409
806.916	93.1731
807.17	95.1937
807.424	91.8931
807.678	92.0782
807.931	93.3566
808.185	94.439
808.439	86.5695
808.693	85.4133
808.947	88.9504
809.201	96.822
809.454	84.3017
809.708	91.6294
809.962	81.0536
810.216	98.614
810.469	83.1236
810.678	86
810.933	78
811.188	82
811.443	90
811.699	86
811.954	88
812.209	78
812.464	88
812.719	80
812.974	80
813.229	80
813.484	80
813.739	70
813.994	82
814.249	86
814.504	68
814.759	78
815.014	80
815.268	74
815.523	80
815.778	78
816.033	90
816.288	74
816.543	80
816.798	78
817.052	80
817.307	68
817.562	64
817.817	72
818.071	76
818.326	72
818.581	68
818.836	68
819.09	88
819.345	72
819.6	72
819.854	72
820.109	64
820.364	82
820.618	72
820.873	80
821.127	68
821.382	72
821.637	66
821.891	70
822.146	64
822.4	80
822.655	68
822.909	74
823.164	72
823.418	52
823.672	58
823.927	78
824.181	68
824.436	56
824.69	64
824.944	72
825.199	72
825.453	66
825.707	72
825.962	62
826.216	66
826.47	74
826.725	68
826.979	66
827.233	68
827.487	64
827.741	74
827.996	62
828.25	60
828.504	64
828.758	58
829.012	58
829.266	64
829.52	76
829.774	58
830.029	62
830.283	56
830.537	66
830.791	64
831.045	64
831.299	64
831.553	60
831.807	62
832.061	60
832.315	66
832.568	58
832.822	56
833.076	54
833.33	56
833.584	54
833.838	66
834.092	50
834.345	64
834.599	52
834.853	52
835.107	60
835.36	58
835.614	58
835.868	52
836.122	60
836.375	62
836.629	52
836.883	54
837.136	54
837.39	50
837.643	58
837.897	58
838.151	66
838.404	52
838.658	64
838.911	48
839.165	58
839.418	58
839.672	52
839.925	46
840.179	52
840.432	62
840.686	54
840.939	60
841.192	52
841.446	50
841.699	54
841.952	58
842.206	48
842.459	60
842.712	48
842.966	54
843.219	48
843.472	52
843.725	46
843.979	46
844.232	46
844.485	48
844.738	48
844.991	52
845.244	56
845.497	46
845.75	54
846.004	48
846.257	52
846.51	58
846.763	46
847.016	52
847.269	50
847.522	48
847.775	40
848.028	52
848.281	40
848.534	52
848.786	38
849.039	52
849.292	38
849.545	50
849.798	44
850.051	42
850.303	32
850.556	42
850.809	52
851.062	46
851.314	44
851.567	42
851.82	44
852.073	44
852.325	49.9412
852.578	32.4416
852.831	41.0447
853.083	32.6702
853.336	40.3421
853.588	40.9637
853.841	39.8997
854.093	39.1774
854.346	40.76
854.598	47.5892
854.851	46.99
855.103	41.153
855.356	38.4133
855.608	41.7642
855.861	44.292
856.113	44.5625
856.366	43.8589
856.618	37.302
856.87	38.7389
857.123	42.1497
857.352	50
857.606	36
857.859	36
858.113	44
858.367	40
858.621	40
858.875	36
859.128	38
859.382	44
859.636	46
859.889	40
860.143	36
860.397	42
860.65	42
860.904	36
861.158	40
861.411	40
861.665	48
861.918	38
862.172	38
862.425	42
862.679	38
862.932	42
863.186	24
863.439	36
863.693	50
863.946	38
864.2	32
864.453	38
864.707	44
864.96	40
865.213	30
865.467	32
865.72	40
865.973	46
866.227	28
866.48	36
866.733	40
866.987	46
867.24	46
867.493	34
867.746	40
867.999	34
868.253	36
868.506	38
868.759	36
869.012	40
869.265	36
869.518	26
869.771	34
870.025	46
870.278	36
870.531	24
870.784	28
871.037	34
871.29	36
871.543	42
871.796	34
872.049	28
872.302	32
872.555	42
872.808	36
873.06	40
873.313	32
873.566	38
873.819	36
874.072	32
874.325	40
874.578	40
874.83	34
875.083	34
875.336	28
875.589	30
875.841	38
876.094	34
876.347	34
876.6	36
876.852	42
877.105	26
877.358	34
877.61	42
877.863	42
878.115	38
878.368	32
878.621	36
878.873	42
879.126	40
879.378	38
879.631	22
879.883	38
880.136	36
880.388	30
880.641	42
880.893	32
881.145	42
881.398	16
881.65	30
881.902	34
882.155	30
882.407	34
882.659	32
882.912	32
883.164	40
883.416	36
883.669	34
883.921	32
884.173	42
884.425	42
884.677	34
884.93	40
885.182	42
885.434	32
885.686	34
885.938	38
886.19	42
886.442	36
886.694	34
886.946	38
887.198	34
887.45	22
887.702	32
887.954	30
888.206	28
888.458	38
888.71	34
888.962	36
889.214	24
889.466	32
889.718	38
889.969	30
890.221	28
890.473	32
890.725	42
890.977	36
891.228	36
891.48	20
891.732	30
891.983	32
892.235	32
892.487	28
892.738	30
892.99	32
893.242	24
893.493	26
893.745	32
893.996	34
894.248	30
894.5	32
894.751	26
895.003	36
895.254	32
895.505	20
895.757	28
896.008	32
896.26	34
896.511	28
896.763	24
897.014	34
897.265	38
897.517	34
897.768	24
898.019	32
898.27	30
898.522	30
898.773	26
899.024	28
899.275	36
899.527	32
899.778	24
899.979	26