File: M1_controle_01.txt
#Acq. time (s)=	5
#Accumulations=	3
#Range (nm)=	520...900
#Windows=	24
#Auto scanning=	On
#Autofocus=	Off
#AutoExposure=	Off
#Spike filter=	Multiple accum.
#Delay time (s)=	0
#Binning=	1
#Readout mode=	Signal
#DeNoise=	Off
#ICS correction=	Off
#Dark correction=	Off
#Inst. Process=	Off
#Detector temperature (°C)=	-59.98
#Instrument=	LabRAM HR Evol
#Detector=	Syncerity OE
#Objective=	x50_VIS
#Grating=	600 (500nm)
#ND Filter=	10%
#Laser=	514nm_Edge
#Hole=	199.981
#Range=	Auto
#StageXY=	Marzhauser
#StageZ=	Marzhauser
#X (µm)=	-24277.9
#Y (µm)=	-158.8
#Z (µm)=	1.6
#Full time(mm:ss)=	5:25
#Project=
#Sample=
#Site=
#Title=	M1_controle
#Remark=
#Date=	19.02.2024 14:03
#Acquired=	19.02.2024 14:03:39
520.013	36.1398
520.274	30.4393
520.536	31.0062
520.797	35.2464
521.059	33.0427
521.32	34.525
521.582	31.7216
521.843	28.5689
522.105	31.6246
522.366	33.1512
522.628	29.4665
522.889	32.668
523.15	30.9984
523.412	31.7104
523.673	31.3471
523.935	36.7746
524.196	36.1769
524.457	35.4483
524.719	42.3752
524.98	32.9837
525.241	37.9786
525.503	31.8695
525.764	34.4404
526.025	30.125
526.286	36.2058
526.548	33.4873
526.809	38.6179
527.07	33.2554
527.331	38.1617
527.593	34.1112
527.854	34.9153
528.115	32.5664
528.376	33.7102
528.637	32.9888
528.898	34.2736
529.16	35.6412
529.421	35.0125
529.682	34.1521
529.943	35.88
530.204	37.5813
530.465	37.7289
530.726	38.8666
530.987	32.9637
531.248	35.5208
531.509	34.4935
531.77	35.0906
532.031	34.8096
532.292	38.1359
532.553	37.4293
532.814	34.0355
533.075	35.9589
533.336	37.3128
533.597	38.8083
533.858	39.367
534.119	40.7505
534.38	47.3478
534.641	50.6726
534.901	53.8338
535.162	59.839
535.423	52.35
535.684	49.7771
535.945	48.7573
536.205	38.6995
536.466	44.4094
536.727	38.9888
536.988	41.784
537.248	45.1971
537.509	36.38
537.77	42.2628
537.987	40.9046
538.249	39.7041
538.51	34.1709
538.771	40.3322
539.032	38.3402
539.293	41.4445
539.554	42.2126
539.815	41.6127
540.076	41.2361
540.337	44.5863
540.598	44.6562
540.859	41.2087
541.12	44.2297
541.381	39.938
541.642	42.0328
541.903	45.9125
542.164	40.4915
542.425	41.8004
542.686	44.3807
542.947	42.7236
543.208	42.926
543.469	45.3621
543.73	41.65
543.991	47.658
544.252	47.6796
544.513	46.3524
544.773	42.8234
545.034	50.4842
545.295	49.9868
545.556	48.2763
545.817	44.6782
546.077	47.3223
546.338	52.1854
546.599	49.3074
546.86	50.5437
547.12	52.487
547.381	47.423
547.642	53.3824
547.903	52.0256
548.163	51.6881
548.424	51.0583
548.685	47.6275
548.945	58.5736
549.206	57.9736
549.467	57.0315
549.727	59.9
549.988	60.7217
550.248	58.4692
550.509	65.3555
550.769	74.3097
551.03	81.897
551.291	83.7519
551.551	90.76
551.812	123.863
552.072	174.604
552.332	426.418
552.593	10423.5
552.853	2759.68
553.114	254.139
553.374	133.989
553.635	99.1242
553.895	89.0631
554.155	80.6571
554.416	76.0192
554.676	69.0053
554.937	74.3808
555.197	68.7661
555.457	69.9633
555.686	73.033
555.947	74.8778
556.207	75.1026
556.468	67.2204
556.729	77.4789
556.99	71.69
557.25	70.6856
557.511	70.6916
557.772	78.4457
558.032	74.6576
558.293	77.4119
558.554	70.1471
558.814	78.8336
559.075	83.327
559.336	78.5871
559.596	73.2906
559.857	82.6714
560.117	79.503
560.378	79.0904
560.638	78.8911
560.899	89.5913
561.159	85.3151
561.42	86.4109
561.68	95.9124
561.941	95.2306
562.201	92.5291
562.462	88.5527
562.722	96.4701
562.983	98.6277
563.243	97.266
563.504	101.825
563.764	105.58
564.024	108.713
564.285	104.998
564.545	102.987
564.805	106.035
565.066	105.003
565.326	106.218
565.586	114.867
565.847	117.788
566.107	120.215
566.367	118.598
566.627	119.414
566.888	123.709
567.148	120.337
567.408	120.637
567.668	132.531
567.928	130.392
568.189	128.863
568.449	128.446
568.709	141.319
568.969	133.614
569.229	137.39
569.489	136.391
569.749	140.294
570.009	148.465
570.269	153.935
570.53	155.754
570.79	167.768
571.05	164.434
571.31	169.912
571.57	169.704
571.83	182.782
572.09	186.875
572.349	194.739
572.609	211.155
572.869	221.203
573.129	227.873
573.368	249.2
573.629	258.495
573.889	279.528
574.15	305.016
574.41	316.45
574.67	342.81
574.931	363.89
575.191	392.291
575.451	419.888
575.711	423.1
575.972	420.459
576.232	414.088
576.492	403.371
576.752	387.614
577.013	369.457
577.273	359.852
577.533	320.64
577.793	315.29
578.053	304.487
578.313	300.338
578.574	294.413
578.834	286.88
579.094	284.409
579.354	275.33
579.614	287.524
579.874	301.069
580.134	280.342
580.394	286.995
580.654	291.937
580.914	298.556
581.174	291.046
581.434	288.875
581.694	299.861
581.954	307.136
582.214	307.22
582.474	320.05
582.734	316.329
582.994	320.685
583.254	326.508
583.514	336.647
583.773	326.323
584.033	355.331
584.293	356.111
584.553	361.356
584.813	371.612
585.073	379.687
585.332	382.336
585.592	386.035
585.852	382.789
586.112	384.544
586.371	408.696
586.631	401.401
586.891	404.838
587.151	407.068
587.41	413.363
587.67	409.287
587.93	414.428
588.189	427.86
588.449	431.861
588.709	443.94
588.968	448.689
589.228	465.289
589.487	462.985
589.747	465.859
590.006	462.578
590.266	457.94
590.525	450.924
590.785	447.704
591.036	447.873
591.296	438.679
591.556	427.249
591.816	401.716
592.076	419.331
592.336	417.895
592.596	413.044
592.856	404.486
593.116	403.793
593.376	411.077
593.635	412.752
593.895	417.263
594.155	410.379
594.415	409.082
594.675	424.545
594.935	409.651
595.194	410.15
595.454	420.24
595.714	430.416
595.974	429.253
596.233	453.727
596.493	463.614
596.753	465.203
597.012	446.009
597.272	436.213
597.532	432.882
597.791	435.061
598.051	431.357
598.311	439.8
598.57	434.604
598.83	443.715
599.089	448.51
599.349	437.38
599.609	426.771
599.868	443.864
600.128	443.837
600.387	436.527
600.647	442.129
600.906	443.775
601.166	442.491
601.425	451.171
601.685	438.5
601.944	450.276
602.203	447.86
602.463	441.978
602.722	450.857
602.982	442.136
603.241	459.397
603.5	463.321
603.76	463.105
604.019	464.282
604.278	465.413
604.538	458.418
604.797	455.988
605.056	462.432
605.315	456.977
605.575	457.357
605.834	467.296
606.093	463.508
606.352	449.058
606.611	456.513
606.871	467.376
607.13	463.119
607.389	472.491
607.648	463.969
607.907	462.65
608.166	475.404
608.425	479.531
608.664	476.153
608.924	473.229
609.183	480.459
609.443	462.386
609.702	491.204
609.962	486.566
610.221	493.53
610.481	505.103
610.74	503.059
611	490.59
611.259	508.642
611.518	498.362
611.778	510.812
612.037	501.621
612.297	501.954
612.556	504.269
612.815	519.101
613.075	509.083
613.334	524.83
613.594	516.892
613.853	512.181
614.112	514.184
614.371	524.565
614.631	523.683
614.89	543.596
615.149	544.378
615.408	546.734
615.668	556.957
615.927	572.164
616.186	551.242
616.445	564.425
616.704	566.281
616.964	573.852
617.223	571.184
617.482	579.16
617.741	583.767
618	597.668
618.259	578.268
618.518	588.475
618.777	597.391
619.036	603.54
619.295	612.246
619.554	612.334
619.813	619.952
620.072	619.321
620.331	604.083
620.59	619.348
620.849	631.776
621.108	625.367
621.367	628.959
621.626	644.52
621.885	610.327
622.144	634.835
622.403	637.149
622.661	635.212
622.92	631.399
623.179	635.406
623.438	635.833
623.697	631.888
623.956	641.582
624.214	636.362
624.473	638.656
624.732	645.081
624.99	655.758
625.249	658.753
625.508	659.746
625.767	661.452
626.025	645.566
626.249	649.45
626.508	660.868
626.767	657.828
627.026	665.297
627.285	653.511
627.544	695.288
627.803	684.258
628.062	680.234
628.321	678.842
628.58	692.304
628.839	681.029
629.098	691.219
629.357	685.901
629.616	702.66
629.875	685.542
630.134	711.669
630.393	699.214
630.652	709.432
630.911	714.466
631.17	727.637
631.429	733.025
631.688	728.317
631.947	728.926
632.206	741.24
632.464	734.504
632.723	755.899
632.982	765.906
633.241	761.909
633.5	765.023
633.758	774.221
634.017	789.137
634.276	786.676
634.535	790.019
634.793	802.107
635.052	812.4
635.311	818.94
635.57	827.449
635.828	871.187
636.087	862.31
636.345	896.78
636.604	946.144
636.863	974.132
637.121	1022.39
637.38	1076.19
637.638	1111.54
637.897	1103.17
638.156	1133.79
638.414	1122.1
638.673	1102.29
638.931	1087.96
639.19	1049.16
639.448	1035.48
639.706	991.731
639.965	989.946
640.223	986.382
640.482	975.149
640.74	962.886
640.999	949.888
641.257	947.932
641.515	937.487
641.774	944.204
642.032	936.893
642.29	927.079
642.549	942.383
642.807	943.267
643.065	920.763
643.323	933.887
643.582	941.584
643.84	931.207
644.053	963.215
644.312	953.575
644.57	974.141
644.829	965.293
645.088	963.159
645.346	971.089
645.605	947.145
645.864	974.877
646.122	985.133
646.381	969.59
646.639	993.084
646.898	987.177
647.157	1007.25
647.415	1002.71
647.674	997.914
647.932	1011.88
648.191	1012.69
648.449	1036.3
648.708	1019.53
648.966	1030.33
649.225	1050.36
649.483	1052.32
649.742	1042.77
650	1040.05
650.258	1078.62
650.517	1056.88
650.775	1061.28
651.034	1075.77
651.292	1084.74
651.55	1094.64
651.809	1112.43
652.067	1095.64
652.325	1132.49
652.583	1125.88
652.842	1121.37
653.1	1137.6
653.358	1157
653.616	1150.57
653.875	1166.57
654.133	1163.75
654.391	1171.93
654.649	1183.62
654.907	1179.31
655.165	1216.65
655.424	1223.05
655.682	1233.83
655.94	1217.92
656.198	1255.57
656.456	1284.95
656.714	1269.04
656.972	1284
657.23	1275.3
657.488	1317.39
657.746	1318.14
658.004	1327.23
658.262	1341.66
658.52	1332.16
658.778	1336.56
659.036	1379.19
659.294	1358.14
659.552	1339.73
659.809	1349.44
660.067	1338.45
660.325	1362.8
660.583	1379.4
660.841	1349.43
661.099	1361.14
661.356	1354.67
661.583	1338
661.842	1343.78
662.1	1334.36
662.358	1361.31
662.616	1343.64
662.875	1345.19
663.133	1342.37
663.391	1355.41
663.649	1344.19
663.907	1370.04
664.166	1343.31
664.424	1373.14
664.682	1363.57
664.94	1329.27
665.198	1370.44
665.456	1355.63
665.714	1330.75
665.972	1361.46
666.23	1353.47
666.488	1347.5
666.746	1352.79
667.004	1349.6
667.262	1336.66
667.52	1341.75
667.778	1325.46
668.036	1342.15
668.294	1337.19
668.552	1342.97
668.81	1361.7
669.068	1350.59
669.326	1360.19
669.584	1350.69
669.842	1347.29
670.099	1345.16
670.357	1336.62
670.615	1336.18
670.873	1343.91
671.131	1347.82
671.388	1336.54
671.646	1330.21
671.904	1341.36
672.162	1346.78
672.419	1361.69
672.677	1357.59
672.935	1366.79
673.192	1363.87
673.45	1365.76
673.708	1360.94
673.965	1377.34
674.223	1404.56
674.481	1389.99
674.738	1395.2
674.996	1391.75
675.253	1417.91
675.511	1413.56
675.768	1411.56
676.026	1431.5
676.283	1418.75
676.541	1427
676.798	1432.89
677.056	1431.22
677.313	1425.82
677.571	1439.29
677.828	1423.05
678.085	1435.74
678.343	1413.1
678.6	1435.88
678.857	1431.18
679.083	1418.12
679.341	1425.11
679.599	1406.98
679.857	1444.72
680.114	1405.89
680.372	1440.81
680.63	1444.99
680.888	1448.85
681.146	1443.26
681.403	1470.96
681.661	1458.46
681.919	1456.19
682.176	1468.61
682.434	1474.49
682.692	1501.33
682.949	1476.89
683.207	1481.68
683.465	1467.28
683.722	1485.22
683.98	1474.93
684.237	1476.34
684.495	1470.75
684.753	1461.45
685.01	1440.57
685.268	1466.38
685.525	1453.33
685.783	1443.88
686.04	1457.91
686.298	1452.55
686.555	1438.49
686.813	1436.51
687.07	1433.67
687.327	1407.83
687.585	1429.39
687.842	1407.23
688.1	1396.83
688.357	1414.01
688.614	1420.97
688.872	1406.92
689.129	1412.03
689.386	1415.31
689.643	1406.81
689.901	1425.23
690.158	1421.07
690.415	1423.02
690.672	1414.91
690.93	1395.8
691.187	1367.69
691.444	1414.26
691.701	1397.89
691.958	1387.77
692.216	1373
692.473	1376.93
692.73	1385.87
692.987	1362.19
693.244	1375.41
693.501	1371.01
693.758	1359.01
694.015	1361.84
694.272	1360.3
694.529	1362.13
694.786	1353.14
695.043	1340.88
695.3	1365.77
695.557	1358.54
695.814	1348.31
696.071	1342.33
696.328	1323.16
696.585	1330.14
696.81	1325.47
697.068	1327.93
697.325	1311.54
697.582	1319.04
697.84	1312.2
698.097	1312.64
698.354	1296.53
698.612	1275.78
698.869	1291.88
699.126	1277.66
699.384	1279.79
699.641	1258.83
699.898	1253.49
700.155	1268.87
700.413	1276.01
700.67	1258.35
700.927	1258.03
701.184	1276.79
701.441	1276.07
701.698	1239.61
701.956	1248.11
702.213	1285.94
702.47	1275.85
702.727	1275.55
702.984	1261.54
703.241	1262.71
703.498	1240.61
703.755	1264.31
704.012	1252.94
704.269	1255.79
704.526	1243.7
704.783	1233.62
705.04	1223.21
705.297	1235.35
705.554	1253.08
705.811	1207.52
706.068	1219.52
706.324	1219.83
706.581	1204.77
706.838	1197.54
707.095	1184.25
707.352	1214.57
707.609	1194.53
707.865	1199.56
708.122	1175.49
708.379	1179.74
708.636	1165.51
708.892	1183.66
709.149	1175.67
709.406	1178.19
709.662	1153.26
709.919	1158.25
710.176	1152.14
710.432	1168.37
710.689	1144.93
710.946	1134.64
711.202	1150.07
711.459	1153.06
711.715	1121.88
711.972	1134.72
712.228	1128.58
712.485	1102.09
712.741	1113.41
712.998	1126.32
713.254	1121.69
713.511	1088.68
713.767	1088.51
714.024	1081.01
714.231	1077.96
714.488	1065.65
714.745	1043.48
715.002	1054.95
715.259	1047.32
715.516	1055.06
715.773	1044.01
716.029	1039.25
716.286	1046.12
716.543	1022.72
716.8	1026.07
717.057	1046.71
717.314	1018.97
717.57	1023.13
717.827	1019.07
718.084	1012.59
718.341	1011.56
718.597	1013.53
718.854	1001.44
719.111	1014.14
719.367	1008.11
719.624	993.9
719.881	977.851
720.137	973.195
720.394	990.634
720.65	974.046
720.907	947.582
721.164	966.256
721.42	969.625
721.677	959.074
721.933	960.078
722.19	958.798
722.446	946.509
722.703	932.576
722.959	950.236
723.216	933.017
723.472	938.854
723.728	926.589
723.985	917.185
724.241	931.435
724.498	918.447
724.754	908.336
725.01	918.803
725.267	907.5
725.523	905.675
725.779	907.54
726.036	883.681
726.292	899.215
726.548	902.488
726.804	889.129
727.06	860.316
727.317	889.604
727.573	868.911
727.829	887.118
728.085	860.233
728.341	874.372
728.597	846.172
728.854	843.412
729.11	856.366
729.366	844.284
729.622	843.74
729.878	849.859
730.134	836.228
730.39	823.786
730.646	782.283
730.902	830.785
731.158	817.642
731.414	812.486
731.622	814.658
731.878	797.088
732.135	791.92
732.391	805.747
732.648	801.297
732.904	808.761
733.161	789.899
733.417	809.763
733.673	806.273
733.93	805.59
734.186	800.693
734.443	810.322
734.699	822.525
734.955	810.688
735.211	839.728
735.468	829.005
735.724	862.198
735.98	851.427
736.237	869.638
736.493	876.552
736.749	903.774
737.005	912.187
737.261	930.72
737.518	931.636
737.774	960.308
738.03	967.941
738.286	958.001
738.542	964.855
738.798	962.836
739.054	960.625
739.31	933.077
739.566	912.967
739.822	874.732
740.078	861.789
740.334	864.319
740.59	846.887
740.846	818.912
741.102	791.892
741.358	781.621
741.614	782.63
741.87	768.533
742.126	753.116
742.382	741.333
742.638	745.763
742.893	740.073
743.149	728.316
743.405	711.625
743.661	722.89
743.917	701.515
744.172	698.917
744.428	687.56
744.684	683.489
744.94	693.72
745.195	689.704
745.451	658.963
745.707	682.438
745.962	675.223
746.218	667.828
746.474	664.365
746.729	651.988
746.985	674.109
747.241	655.383
747.496	641.965
747.752	630.187
748.007	638.47
748.263	641.425
748.518	650.968
748.774	644.66
749.029	622.093
749.275	632.656
749.531	618.348
749.787	622.559
750.043	615.693
750.299	604.757
750.555	606.215
750.811	623.273
751.067	595.149
751.323	616.114
751.579	601.595
751.835	600.406
752.09	596.41
752.346	583.071
752.602	584.653
752.858	599.366
753.114	552.875
753.37	574.387
753.625	587.169
753.881	585.393
754.137	571.889
754.393	562.878
754.648	550.394
754.904	550.193
755.16	571.521
755.415	560.791
755.671	550.551
755.927	546.582
756.182	543.664
756.438	546.96
756.693	537.131
756.949	519.018
757.205	546.228
757.46	523.207
757.716	531.898
757.971	524.628
758.227	514.145
758.482	529.312
758.738	513.606
758.993	514.029
759.248	511.974
759.504	505.19
759.759	497.308
760.015	490.976
760.27	501.031
760.525	498.791
760.781	488.467
761.036	492.323
761.291	493.259
761.547	491.278
761.802	484.245
762.057	474.823
762.313	483.746
762.568	469.475
762.823	477.115
763.078	466.141
763.333	461.692
763.589	455.127
763.844	463.333
764.099	459.264
764.354	450.847
764.609	459.472
764.864	447.875
765.119	454.299
765.374	435.997
765.629	446.763
765.884	452.431
766.139	436.557
766.394	435.022
766.649	430.289
766.882	432.724
767.137	432.181
767.393	432.47
767.648	432.865
767.904	423.805
768.159	423.549
768.415	425.954
768.67	431.479
768.926	413.395
769.181	407.755
769.436	410.99
769.692	408.057
769.947	397.75
770.203	400.099
770.458	402.987
770.713	386.326
770.968	387.321
771.224	397.077
771.479	383.296
771.734	377.02
771.99	378.807
772.245	374.357
772.5	362.881
772.755	377.911
773.01	364.289
773.265	361.135
773.521	365.387
773.776	360.85
774.031	358.708
774.286	363.799
774.541	344.237
774.796	349.894
775.051	350.701
775.306	344.486
775.561	345.813
775.816	337.41
776.071	334.515
776.326	339.777
776.581	337.797
776.836	327.564
777.091	324.032
777.346	318.665
777.601	325.619
777.856	317.418
778.111	328.168
778.365	317.098
778.62	319.053
778.875	314.4
779.13	304.082
779.385	315.418
779.639	304.602
779.894	315.018
780.149	305.116
780.404	298.496
780.658	295.934
780.913	293.986
781.168	293.826
781.422	291.854
781.677	294.174
781.932	291.57
782.186	285.423
782.441	282.168
782.695	279.148
782.95	269.335
783.204	284.669
783.459	274.486
783.714	276.869
783.968	263.79
784.211	274.734
784.466	273.589
784.721	268.471
784.976	270.379
785.231	266.307
785.486	267.382
785.741	263.939
785.996	267.982
786.251	255.852
786.506	250.74
786.761	248.668
787.016	257.542
787.271	253.892
787.526	253.393
787.78	248.518
788.035	242.272
788.29	239.126
788.545	242.606
788.8	240.066
789.054	233.523
789.309	235.597
789.564	232.951
789.819	228.864
790.073	241.915
790.328	224.807
790.583	223.386
790.837	231.603
791.092	229.454
791.347	223.546
791.601	224.141
791.856	227.004
792.11	220.718
792.365	213.271
792.619	217.269
792.874	220.534
793.128	213.587
793.383	211.589
793.638	209.803
793.892	217.364
794.146	207.639
794.401	208.9
794.655	204.049
794.91	208.732
795.164	191.114
795.418	193.887
795.673	196.802
795.927	201.567
796.181	202.559
796.436	194.337
796.69	196.924
796.944	195.523
797.199	193.172
797.453	187.861
797.707	196.526
797.961	189.703
798.216	183.455
798.47	187.63
798.724	186.138
798.978	185.817
799.232	181.069
799.486	176.911
799.74	180.123
799.994	172.64
800.248	179.046
800.503	183.536
800.757	179.84
801.011	168.992
801.265	164.752
801.508	174.472
801.762	175.97
802.017	167.012
802.271	164.11
802.526	173.776
802.78	160.892
803.035	166.635
803.289	163.082
803.544	162.133
803.798	157.742
804.052	156.305
804.307	157.291
804.561	162.983
804.816	163.456
805.07	149.798
805.324	150.885
805.579	159.553
805.833	153.382
806.087	145.183
806.341	150.473
806.596	150.233
806.85	146.17
807.104	145.383
807.358	150.523
807.613	143.521
807.867	151.651
808.121	145.493
808.375	142.303
808.629	139.956
808.883	153.004
809.138	141.209
809.392	145.614
809.646	138.946
809.9	146.091
810.154	140.797
810.408	137.875
810.662	137.298
810.916	133.358
811.17	142.493
811.424	137.788
811.678	133.347
811.932	135.063
812.185	132.849
812.439	129.956
812.693	128.384
812.947	125.95
813.201	130.831
813.455	133.722
813.709	127.722
813.962	129.398
814.216	124.419
814.47	127.421
814.724	128.275
814.977	131.308
815.231	120.797
815.485	124.892
815.739	123.068
815.992	118.044
816.246	121.049
816.499	116.015
816.753	117.918
817.007	112.935
817.26	119.743
817.514	119.582
817.767	115.675
818.021	117.999
818.274	111.199
818.528	118.334
818.781	111.362
819.01	114.227
819.264	113.024
819.518	113.48
819.772	109.074
820.026	115.555
820.28	112.101
820.534	112.198
820.788	113.941
821.042	104.98
821.296	101.745
821.549	107.497
821.803	109.028
822.057	103.648
822.311	107.662
822.565	103.544
822.819	103.825
823.073	102.917
823.326	107.986
823.58	101.765
823.834	98.2777
824.088	103.625
824.341	97.7735
824.595	100.802
824.849	102.777
825.103	100.838
825.356	103.064
825.61	98.6537
825.864	96.7474
826.117	92.6402
826.371	98.7288
826.624	96.1661
826.878	98.6705
827.131	98.4545
827.385	93.0109
827.638	90.0335
827.892	92.828
828.146	94.0343
828.399	88.9446
828.652	91.0099
828.906	93.3074
829.159	92.8891
829.413	93.6374
829.666	86.8061
829.919	91.614
830.173	87.1653
830.426	89.1774
830.68	90.9247
830.933	84.9484
831.186	92.6428
831.439	82.4997
831.693	86.5153
831.946	86.7688
832.199	85.2018
832.452	81.1548
832.706	88.3028
832.959	89.5664
833.212	85.564
833.465	89.8486
833.718	91.2578
833.971	88.7313
834.224	87.2933
834.477	87.9316
834.73	84.9382
834.984	90.6915
835.237	80.0353
835.49	84.0048
835.743	82.1339
835.996	81.0418
836.201	85.8702
836.454	83.0169
836.708	74.033
836.961	79.872
837.215	83.1432
837.468	84.0284
837.722	78.9315
837.975	75.2032
838.229	75.7009
838.482	84.7897
838.735	78.5293
838.989	75.3047
839.242	78.262
839.496	71.8418
839.749	77.5253
840.002	79.5524
840.256	83.1457
840.509	73.6335
840.762	77.6576
841.015	76.1297
841.269	77.1233
841.522	76.6338
841.775	76.2053
842.028	77.4765
842.281	76.8379
842.535	73.6618
842.788	77.9736
843.041	72.9635
843.294	74.7444
843.547	71.8828
843.8	76.3253
844.053	73.8216
844.306	70.9404
844.559	65.8971
844.812	74.6254
845.065	72.0279
845.318	69.6878
845.571	72.2701
845.824	69.7163
846.077	70.9158
846.33	67.9595
846.583	66.7237
846.836	73.6843
847.089	66.4492
847.342	62.8413
847.595	66.6025
847.847	65.3747
848.1	67.7732
848.353	67.6626
848.606	69.5898
848.859	73.05
849.111	66.3355
849.364	64.051
849.617	64.4834
849.869	73.6537
850.122	67.8448
850.375	62.714
850.627	63.1803
850.88	62.7517
851.133	59.6476
851.385	60.525
851.638	69.5312
851.89	66.7194
852.143	64.4488
852.395	62.4917
852.648	64.8853
852.9	66.8011
853.153	63.2214
853.405	62.3025
853.645	62.219
853.898	56.1586
854.151	64.8704
854.404	56.9028
854.657	55.2245
854.91	64.0434
855.163	54.3132
855.416	63.463
855.669	58.3312
855.922	60.5031
856.175	56.8334
856.427	61.6479
856.68	56.4198
856.933	59.7861
857.186	55.7213
857.439	63.3897
857.692	55.0264
857.944	56.9873
858.197	61.1167
858.45	61.3663
858.703	61.2353
858.955	59.7495
859.208	54.0644
859.461	46.8367
859.713	51.6962
859.966	52.8946
860.219	58.3109
860.471	52.838
860.724	63.2038
860.976	55.8271
861.229	58.5043
861.481	55.7766
861.734	56.9439
861.986	51.4606
862.239	56.9482
862.491	58.0275
862.744	55.0716
862.996	52.6323
863.249	55.8881
863.501	59.4904
863.754	52.7212
864.006	58.4478
864.258	54.1274
864.511	59.2914
864.763	54.3764
865.015	51.2797
865.268	50.6259
865.52	61.5025
865.772	53.9718
866.024	48.6879
866.276	53.4697
866.529	55.9496
866.781	51.7479
867.033	49.9343
867.285	52.3747
867.537	54.3298
867.789	45.7639
868.042	49.3813
868.294	50.7996
868.546	47.9873
868.798	49.2958
869.05	44.0917
869.302	51.1414
869.554	50.5598
869.806	51.896
870.058	51.0574
870.31	50.8978
870.562	50.5458
870.782	52.2262
871.034	47.4476
871.287	46.3046
871.539	44.7
871.792	47.1398
872.044	49.5245
872.297	48.7505
872.549	49.9023
872.801	46.7275
873.054	45.7747
873.306	47.7194
873.558	53.4804
873.811	48.7058
874.063	45.8768
874.315	48.7412
874.568	37.5422
874.82	47.7374
875.072	48.9569
875.324	46.3812
875.577	47.0842
875.829	45.899
876.081	48.3281
876.333	45.3855
876.585	44.5068
876.838	50.457
877.09	45.8617
877.342	46.9569
877.594	47.0209
877.846	48.4508
878.098	40.4758
878.35	50.0451
878.602	47.9435
878.854	45.125
879.106	49.0328
879.358	42.4111
879.61	44.4352
879.862	54.5296
880.114	44.4351
880.366	49.9603
880.618	47.3419
880.87	40.3869
881.121	43.4378
881.373	43.2506
881.625	41.9825
881.877	46.2359
882.129	40.809
882.38	40.6291
882.632	44.3504
882.884	47.8386
883.136	42.451
883.387	41.8487
883.639	45.7531
883.891	41.7319
884.142	45.4845
884.394	45.4056
884.646	44.3067
884.897	42.883
885.149	39.9377
885.4	41.3244
885.652	51.7105
885.903	41.0844
886.155	39.5407
886.406	43.2054
886.658	44.2145
886.909	41.3732
887.161	39.6495
887.412	44.2795
887.664	41.0983
887.915	39.8243
888.138	43.3731
888.39	37.3576
888.642	41.4605
888.894	38.4457
889.146	42.271
889.398	42.6968
889.65	46.913
889.902	37.6024
890.154	42.1763
890.406	46.9724
890.657	45.1549
890.909	38.7858
891.161	37.7133
891.413	38.4148
891.665	42.7382
891.916	37.283
892.168	38.8157
892.42	44.4935
892.671	37.1184
892.923	39.0235
893.175	37.6398
893.426	44.7364
893.678	35.6567
893.93	38.7718
894.181	35.4497
894.433	40.2089
894.684	36.7166
894.936	36.4552
895.188	38.4219
895.439	40.212
895.69	40.4265
895.942	36.9659
896.193	39.8432
896.445	32.8161
896.696	37.6155
896.948	34.1128
897.199	37.2032
897.451	40.4982
897.702	38.7584
897.953	32.9277
898.204	39.5837
898.456	42.0095
898.707	35.0896
898.958	29.272
899.21	40.5497
899.461	41.055
899.712	33.8174
899.963	41.3333