File: M2_140224_01.txt
#Acq. time (s)=	2
#Accumulations=	3
#Range (nm)=	520...900
#Windows=	24
#Auto scanning=	On
#Autofocus=	Off
#AutoExposure=	Off
#Spike filter=	Multiple accum.
#Delay time (s)=	0
#Binning=	1
#Readout mode=	Signal
#DeNoise=	Off
#ICS correction=	Off
#Dark correction=	Off
#Inst. Process=	Off
#Detector temperature (°C)=	-59.98
#Instrument=	LabRAM HR Evol
#Detector=	Syncerity OE
#Objective=	x50_VIS
#Grating=	600 (500nm)
#ND Filter=	10%
#Laser=	514nm_Edge
#Hole=	199.981
#Range=	Auto
#StageXY=	Marzhauser
#StageZ=	Marzhauser
#X (µm)=	-14749.4
#Y (µm)=	814.2
#Z (µm)=	-65.4
#Full time(mm:ss)=	3:03
#Project=
#Sample=
#Site=
#Title=	M2_140224
#Remark=
#Date=	19.02.2024 14:11
#Acquired=	19.02.2024 14:11:29
520.013	26.6867
520.274	31.0695
520.536	25.2517
520.797	27.1934
521.059	29.9487
521.32	26.6181
521.582	25.777
521.843	25.4451
522.105	31.8823
522.366	29.0951
522.628	28.953
522.889	26.0338
523.15	29.0183
523.412	29.48
523.673	23.5731
523.935	27.4552
524.196	29.3803
524.457	26.6667
524.719	27.0687
524.98	28.6962
525.241	28.8572
525.503	29.3333
525.764	30
526.025	28.5019
526.286	29.197
526.548	27.497
526.809	23.0331
527.07	27.5266
527.331	30.7635
527.593	26.5003
527.854	25.2168
528.115	27.8844
528.376	29.5245
528.637	27.5524
528.898	31.3063
529.16	29.0004
529.421	27.8134
529.682	26.8879
529.943	27.6625
530.204	28.7879
530.465	23.8863
530.726	24.9281
530.987	28.3086
531.248	29.0929
531.509	24.907
531.77	25.4709
532.031	31.779
532.292	27.6932
532.553	27.4437
532.814	25.1035
533.075	28.9
533.336	27.1006
533.597	29.1551
533.858	26.69
534.119	30.395
534.38	27.5461
534.641	29.2833
534.901	29.5424
535.162	37.2649
535.423	30.2786
535.684	27.7046
535.945	30.6523
536.205	25.7684
536.466	30.3049
536.727	25.2807
536.988	31.4029
537.248	27.3657
537.509	30.811
537.77	25.5652
537.987	30.3168
538.249	35.1743
538.51	30.3816
538.771	27.4847
539.032	24.9892
539.293	32.7049
539.554	24.5615
539.815	27.2488
540.076	34.3267
540.337	30.5803
540.598	26.8958
540.859	23.4802
541.12	31.7261
541.381	30.898
541.642	29.3379
541.903	31.4261
542.164	34.1843
542.425	31.4073
542.686	27.394
542.947	26.4942
543.208	34.2326
543.469	28.59
543.73	22.297
543.991	27.6642
544.252	31.7051
544.513	31.7986
544.773	29.3878
545.034	30.2522
545.295	36.1006
545.556	31.8852
545.817	26.0946
546.077	27.3845
546.338	31.0307
546.599	30.6646
546.86	34.0205
547.12	31.9113
547.381	32.5164
547.642	29.7393
547.903	32.1274
548.163	35.116
548.424	32.4689
548.685	28.6798
548.945	33.0831
549.206	36.09
549.467	34.7267
549.727	29.2186
549.988	35.6146
550.248	37.3422
550.509	38.484
550.769	40.4564
551.03	40.1545
551.291	45.9179
551.551	44.3374
551.812	55.7899
552.072	77.6085
552.332	181.665
552.593	4314.88
552.853	814.203
553.114	97.7291
553.374	60.2328
553.635	48.4949
553.895	39.8543
554.155	39.9825
554.416	39.7676
554.676	39.4066
554.937	38.981
555.197	39.5803
555.457	37.7387
555.686	36.999
555.947	40.9602
556.207	42.8455
556.468	46.6449
556.729	38.1751
556.99	39.7585
557.25	43.7043
557.511	39.3333
557.772	35.7652
558.032	39.8785
558.293	47.6871
558.554	38.725
558.814	38.3079
559.075	43.1337
559.336	38.4982
559.596	41.4132
559.857	36.9703
560.117	43.2855
560.378	41.1597
560.638	45.0338
560.899	46.5112
561.159	40.2035
561.42	46.287
561.68	45.2519
561.941	43.7813
562.201	52.3492
562.462	46.6978
562.722	43.6966
562.983	47.1208
563.243	45.6791
563.504	43.9839
563.764	45.7846
564.024	51.7617
564.285	47.4276
564.545	45.258
564.805	48.4147
565.066	49.3252
565.326	50.2232
565.586	42.5617
565.847	47.469
566.107	49.2707
566.367	48.1751
566.627	50.6039
566.888	55.0769
567.148	57.9185
567.408	56.1345
567.668	53.0118
567.928	55.3115
568.189	54.5222
568.449	54.1674
568.709	55.7581
568.969	52.6499
569.229	54.7173
569.489	57.7664
569.749	56.5227
570.009	64.5097
570.269	58.2888
570.53	59.2064
570.79	68.4385
571.05	66.1923
571.31	63.6735
571.57	65.8966
571.83	67.5576
572.09	70.8643
572.349	71.5708
572.609	72.8643
572.869	75.426
573.129	80.8093
573.368	82.2777
573.629	87.0655
573.889	93.7909
574.15	95.7519
574.41	102.752
574.67	102.106
574.931	121.378
575.191	122.994
575.451	125.224
575.711	128.217
575.972	127.717
576.232	125.57
576.492	127.963
576.752	117.343
577.013	117.421
577.273	110.819
577.533	101.448
577.793	104.042
578.053	96.5395
578.313	101.41
578.574	94.2378
578.834	95.8088
579.094	93.1285
579.354	94.9631
579.614	92.2138
579.874	91.9274
580.134	88.8747
580.394	93.0355
580.654	93.7452
580.914	96.2403
581.174	96.7148
581.434	92.6037
581.694	100.517
581.954	98.7911
582.214	105.916
582.474	101.048
582.734	105.142
582.994	103.022
583.254	110.766
583.514	110.198
583.773	109.88
584.033	112.343
584.293	111.299
584.553	115.112
584.813	122.886
585.073	126.189
585.332	119.939
585.592	126.158
585.852	125.443
586.112	126.122
586.371	126.038
586.631	140.348
586.891	129.035
587.151	133.848
587.41	132.631
587.67	137.521
587.93	137.501
588.189	136.602
588.449	137.675
588.709	143.108
588.968	142.802
589.228	149.032
589.487	148.67
589.747	149.188
590.006	148.036
590.266	150.506
590.525	142.129
590.785	155.477
591.036	147.061
591.296	133.109
591.556	137.137
591.816	132.235
592.076	131.857
592.336	138.028
592.596	123.192
592.856	119.666
593.116	133.224
593.376	126.749
593.635	131.843
593.895	128.22
594.155	121.206
594.415	130.519
594.675	134.335
594.935	138.972
595.194	133.172
595.454	134.826
595.714	133.782
595.974	147.573
596.233	131.454
596.493	148.925
596.753	149.94
597.012	139.683
597.272	135.81
597.532	137.697
597.791	130.916
598.051	135.984
598.311	134.789
598.57	145.969
598.83	136.99
599.089	138.406
599.349	128.347
599.609	145.636
599.868	132.605
600.128	125.982
600.387	139.235
600.647	138.86
600.906	132.164
601.166	135.246
601.425	134.469
601.685	141.303
601.944	137.258
602.203	144.464
602.463	137.993
602.722	136.315
602.982	134.685
603.241	145.288
603.5	138.301
603.76	137.782
604.019	139.08
604.278	143.116
604.538	142.335
604.797	141.64
605.056	137.795
605.315	140.639
605.575	146.019
605.834	141.654
606.093	140.777
606.352	150.773
606.611	151.594
606.871	141.176
607.13	147.484
607.389	144.386
607.648	147.812
607.907	145.783
608.166	141.811
608.425	146.042
608.664	146.819
608.924	149.622
609.183	150.962
609.443	152.079
609.702	151.244
609.962	148.81
610.221	153.82
610.481	160.543
610.74	161.574
611	153.261
611.259	155.64
611.518	155.662
611.778	152.712
612.037	144.959
612.297	166.381
612.556	159.572
612.815	151.745
613.075	156.818
613.334	158.232
613.594	157.645
613.853	163.958
614.112	160.813
614.371	163.638
614.631	169.958
614.89	153.343
615.149	159.511
615.408	171.886
615.668	166.797
615.927	162.717
616.186	170.895
616.445	174.713
616.704	156.104
616.964	170.878
617.223	178.621
617.482	169.64
617.741	170.921
618	173.582
618.259	170.74
618.518	182.599
618.777	175.555
619.036	180.002
619.295	192.929
619.554	187.763
619.813	178.311
620.072	187.766
620.331	192.19
620.59	182.684
620.849	172.515
621.108	191.332
621.367	190.217
621.626	187.662
621.885	186.469
622.144	186.095
622.403	188.525
622.661	185.524
622.92	188.557
623.179	191.087
623.438	185.03
623.697	187.271
623.956	190.037
624.214	195.94
624.473	187.097
624.732	192.414
624.99	195.839
625.249	197.784
625.508	198.339
625.767	199.547
626.025	197.83
626.249	191.044
626.508	189.653
626.767	199.671
627.026	199.6
627.285	198.751
627.544	188.484
627.803	205.668
628.062	194.063
628.321	200.141
628.58	214.7
628.839	197.984
629.098	201.431
629.357	207.466
629.616	210.589
629.875	201.899
630.134	208.749
630.393	207.073
630.652	204.444
630.911	204.644
631.17	207.687
631.429	215.802
631.688	222.792
631.947	215.364
632.206	218.45
632.464	223.899
632.723	220.661
632.982	204.196
633.241	211.49
633.5	221.959
633.758	218.554
634.017	227.182
634.276	234.968
634.535	230.087
634.793	223.87
635.052	237.952
635.311	249.498
635.57	241.455
635.828	249.946
636.087	250.449
636.345	248.375
636.604	265.506
636.863	279.277
637.121	306.367
637.38	309.247
637.638	323.403
637.897	320.712
638.156	321.329
638.414	324.963
638.673	323.628
638.931	313.303
639.19	294.945
639.448	297.923
639.706	282.89
639.965	289.841
640.223	285.512
640.482	279.193
640.74	276.998
640.999	278.269
641.257	267.821
641.515	280.414
641.774	264.558
642.032	268.079
642.29	263.126
642.549	281.582
642.807	260.055
643.065	271.65
643.323	272.301
643.582	280.001
643.84	267.327
644.053	266.725
644.312	274.611
644.57	283.305
644.829	282.518
645.088	275.128
645.346	279.075
645.605	281.318
645.864	281.182
646.122	281.946
646.381	284.504
646.639	280.674
646.898	281.517
647.157	283.342
647.415	296.203
647.674	292.58
647.932	286.916
648.191	290.742
648.449	292.656
648.708	291.011
648.966	300.649
649.225	299.644
649.483	298.701
649.742	302.745
650	305.173
650.258	307.912
650.517	308.303
650.775	303.786
651.034	314.398
651.292	310.458
651.55	304.225
651.809	316.915
652.067	311.096
652.325	323.465
652.583	327.736
652.842	320.341
653.1	326.924
653.358	321.439
653.616	337.681
653.875	327.297
654.133	321.532
654.391	320.74
654.649	343.065
654.907	336.134
655.165	340.492
655.424	348.769
655.682	342.497
655.94	342.936
656.198	361.125
656.456	364.912
656.714	351.373
656.972	364.034
657.23	370.108
657.488	369.761
657.746	371.862
658.004	365.088
658.262	375.194
658.52	379.221
658.778	375.495
659.036	387.273
659.294	394.687
659.552	377.444
659.809	378.901
660.067	378.877
660.325	388.653
660.583	383.166
660.841	382.886
661.099	386.984
661.356	399.753
661.583	395.226
661.842	393.091
662.1	391.078
662.358	386.238
662.616	390.743
662.875	382.867
663.133	378.601
663.391	391.713
663.649	381.952
663.907	398.274
664.166	380.56
664.424	383.054
664.682	398.043
664.94	384.666
665.198	379.644
665.456	387.396
665.714	368.947
665.972	389.472
666.23	383.359
666.488	377.372
666.746	388.094
667.004	390.421
667.262	370.297
667.52	391.169
667.778	384.315
668.036	377.657
668.294	376.026
668.552	376.708
668.81	386.259
669.068	377.529
669.326	376.898
669.584	387.982
669.842	379.336
670.099	376.977
670.357	385.136
670.615	384.703
670.873	385.223
671.131	389.54
671.388	382.634
671.646	367.941
671.904	392.547
672.162	384.877
672.419	390.164
672.677	386.441
672.935	391.022
673.192	400.115
673.45	392.728
673.708	390.482
673.965	377.585
674.223	398.841
674.481	404.781
674.738	389.998
674.996	395.917
675.253	399.047
675.511	398.799
675.768	406.901
676.026	407.8
676.283	397.857
676.541	403.105
676.798	409.868
677.056	398.989
677.313	419.896
677.571	407.148
677.828	399.388
678.085	409.409
678.343	414.463
678.6	403.887
678.857	407.652
679.083	402.099
679.341	410.271
679.599	399.734
679.857	408.033
680.114	400.544
680.372	408.822
680.63	414.42
680.888	413.701
681.146	410.373
681.403	420.049
681.661	413.195
681.919	422.864
682.176	425.224
682.434	431.129
682.692	409.111
682.949	412.917
683.207	414.82
683.465	418.132
683.722	412.935
683.98	420.413
684.237	423.688
684.495	416.631
684.753	413.444
685.01	415.238
685.268	419.225
685.525	410.352
685.783	410.869
686.04	399.59
686.298	410.038
686.555	421.541
686.813	420.091
687.07	424.474
687.327	413.481
687.585	411.867
687.842	412.419
688.1	388.6
688.357	420.547
688.614	399.99
688.872	411.36
689.129	413.619
689.386	407.501
689.643	396.529
689.901	404.661
690.158	400.993
690.415	403.037
690.672	415.784
690.93	395.979
691.187	409.784
691.444	411.282
691.701	397.987
691.958	399.141
692.216	392.919
692.473	400.756
692.73	392.642
692.987	408.041
693.244	391.896
693.501	387.11
693.758	391.259
694.015	385.693
694.272	391.311
694.529	394.214
694.786	387.291
695.043	389.166
695.3	384.089
695.557	382.985
695.814	384.863
696.071	381.417
696.328	387.076
696.585	382.319
696.81	377.337
697.068	370.647
697.325	383.105
697.582	383.637
697.84	369.024
698.097	378.696
698.354	370.989
698.612	381.885
698.869	374.231
699.126	368.634
699.384	361.625
699.641	369.954
699.898	367.023
700.155	363.453
700.413	368.75
700.67	367.376
700.927	359.505
701.184	363.312
701.441	374.94
701.698	361.356
701.956	366.948
702.213	360.944
702.47	370.649
702.727	369.212
702.984	363.512
703.241	361.485
703.498	362.49
703.755	369.082
704.012	372.929
704.269	358.977
704.526	361.683
704.783	363.446
705.04	358.611
705.297	351.695
705.554	350.553
705.811	358.482
706.068	351.211
706.324	350.642
706.581	353.294
706.838	351.086
707.095	350.961
707.352	347.845
707.609	349.161
707.865	347.495
708.122	346.616
708.379	349.588
708.636	347.048
708.892	335.464
709.149	346.796
709.406	334.335
709.662	345.562
709.919	342.284
710.176	335.341
710.432	342.578
710.689	342.109
710.946	343.394
711.202	339.853
711.459	337.724
711.715	345.392
711.972	333.395
712.228	332.414
712.485	325.095
712.741	319.673
712.998	338.229
713.254	322.35
713.511	328.81
713.767	320.495
714.024	329.936
714.231	318.475
714.488	319.484
714.745	316.735
715.002	320.029
715.259	316.413
715.516	307.782
715.773	318.311
716.029	309.17
716.286	313.75
716.543	310.134
716.8	309.775
717.057	310.478
717.314	298.955
717.57	305.287
717.827	302.688
718.084	312.259
718.341	299.242
718.597	308.597
718.854	303.61
719.111	296.275
719.367	304.907
719.624	306.772
719.881	300.116
720.137	294.582
720.394	299.092
720.65	295.539
720.907	299.283
721.164	292.717
721.42	296.966
721.677	297.626
721.933	287.11
722.19	294.759
722.446	281.919
722.703	284.282
722.959	291.908
723.216	284.644
723.472	290.849
723.728	283.271
723.985	293.297
724.241	285.596
724.498	288.231
724.754	282.836
725.01	279.513
725.267	285.336
725.523	279.828
725.779	293.862
726.036	281.002
726.292	278.127
726.548	298.07
726.804	284.779
727.06	286.703
727.317	284.061
727.573	273.157
727.829	282.401
728.085	273.886
728.341	281.629
728.597	278.885
728.854	283.657
729.11	259.938
729.366	274.185
729.622	274.221
729.878	268.128
730.134	260.999
730.39	281.68
730.646	262.588
730.902	278.097
731.158	275.51
731.414	258.343
731.622	264.088
731.878	275.455
732.135	271.848
732.391	286.77
732.648	275.355
732.904	276.357
733.161	280.117
733.417	290.346
733.673	278.722
733.93	288.414
734.186	289.339
734.443	302.406
734.699	300.957
734.955	313.1
735.211	325.653
735.468	324.506
735.724	335.668
735.98	354.227
736.237	368.344
736.493	381.471
736.749	390.809
737.005	407.479
737.261	437.752
737.518	448.286
737.774	463.056
738.03	480.348
738.286	475.374
738.542	469.692
738.798	473.801
739.054	457.513
739.31	440.124
739.566	432.023
739.822	405.114
740.078	404.252
740.334	383.805
740.59	359.386
740.846	347.565
741.102	341.759
741.358	329.369
741.614	315.111
741.87	297.515
742.126	300.618
742.382	296.416
742.638	285.332
742.893	280.637
743.149	273.486
743.405	267.347
743.661	268.333
743.917	257.722
744.172	251.081
744.428	257.449
744.684	254.975
744.94	244.242
745.195	244.014
745.451	239.662
745.707	240.571
745.962	230.805
746.218	237.943
746.474	230.74
746.729	232.621
746.985	235.933
747.241	222.736
747.496	228.757
747.752	228.837
748.007	227.146
748.263	221.813
748.518	216.983
748.774	220.677
749.029	223.307
749.275	228.526
749.531	212.478
749.787	218.583
750.043	224.068
750.299	217.486
750.555	214.01
750.811	219.758
751.067	215.846
751.323	203.371
751.579	215.287
751.835	213.894
752.09	210.741
752.346	211.636
752.602	214.424
752.858	212.771
753.114	207.931
753.37	202.175
753.625	201.269
753.881	199.596
754.137	193.215
754.393	199.192
754.648	197.7
754.904	200.667
755.16	192.819
755.415	185.114
755.671	197.629
755.927	190.854
756.182	193.922
756.438	198.8
756.693	193.779
756.949	183.093
757.205	190.767
757.46	188.416
757.716	183.591
757.971	182.857
758.227	179.007
758.482	186.369
758.738	190.25
758.993	177
759.248	182.488
759.504	180.015
759.759	171.677
760.015	176.124
760.27	183.117
760.525	174.251
760.781	170.443
761.036	167.671
761.291	173.993
761.547	179.816
761.802	172.437
762.057	172.561
762.313	169.455
762.568	169.411
762.823	172.409
763.078	170.351
763.333	168.277
763.589	164.057
763.844	164.87
764.099	161.115
764.354	167.095
764.609	171.216
764.864	158.727
765.119	156.933
765.374	162.499
765.629	164.005
765.884	159.051
766.139	158.6
766.394	161.347
766.649	167.648
766.882	161.164
767.137	154.559
767.393	162.734
767.648	161.753
767.904	147.672
768.159	153.21
768.415	153.13
768.67	146.823
768.926	165.078
769.181	150.116
769.436	147.627
769.692	147.741
769.947	150.176
770.203	145.01
770.458	143.619
770.713	133.217
770.968	140.552
771.224	141.66
771.479	140.613
771.734	132.441
771.99	135.082
772.245	131.981
772.5	135.546
772.755	137.407
773.01	137.784
773.265	133.07
773.521	135.628
773.776	130.404
774.031	130.3
774.286	123.616
774.541	131.436
774.796	121.785
775.051	128.98
775.306	131.528
775.561	119.772
775.816	125.917
776.071	121.446
776.326	128.297
776.581	128.51
776.836	122.978
777.091	122.092
777.346	121.888
777.601	114.661
777.856	116.381
778.111	113.93
778.365	119.172
778.62	120.553
778.875	114.626
779.13	115.134
779.385	112.816
779.639	112.648
779.894	112.989
780.149	117.771
780.404	111.583
780.658	108.131
780.913	106.45
781.168	113.02
781.422	112.879
781.677	111.72
781.932	103.954
782.186	110.536
782.441	106.538
782.695	98.4181
782.95	104.839
783.204	110.166
783.459	95.6885
783.714	104.653
783.968	100.75
784.211	103.667
784.466	97.4355
784.721	92.348
784.976	101.928
785.231	110.007
785.486	93.6325
785.741	97.6711
785.996	97.9269
786.251	93.1316
786.506	102.586
786.761	96.5554
787.016	99.7828
787.271	93.6676
787.526	93.2781
787.78	90.2459
788.035	92.8482
788.29	95.6177
788.545	89.2634
788.8	91.1846
789.054	94.1772
789.309	94.0172
789.564	85.014
789.819	87.0991
790.073	92.329
790.328	87.7251
790.583	86.8409
790.837	92.6773
791.092	95.5399
791.347	90.5062
791.601	79.0572
791.856	84.0999
792.11	88.1757
792.365	80.7502
792.619	84.2804
792.874	86.6212
793.128	82.9922
793.383	89.3186
793.638	84.1785
793.892	82.4498
794.146	81.6969
794.401	84.0747
794.655	78.5632
794.91	79.4811
795.164	86.5728
795.418	82.4718
795.673	73.7181
795.927	80.2718
796.181	80.2487
796.436	78.5441
796.69	78.2569
796.944	79.55
797.199	76.8842
797.453	79.3104
797.707	77.3917
797.961	79.935
798.216	78.0223
798.47	72.8259
798.724	75.2845
798.978	73.2707
799.232	75.3211
799.486	69.7621
799.74	76.5395
799.994	72.5261
800.248	77.3197
800.503	76.2368
800.757	73.8743
801.011	73.7505
801.265	66.8001
801.508	77.9868
801.762	68.3924
802.017	67.0108
802.271	66.1378
802.526	66.6444
802.78	69.1926
803.035	66.7675
803.289	70.2298
803.544	72.6674
803.798	69.3803
804.052	67.4224
804.307	66.8734
804.561	69.4905
804.816	64.5923
805.07	67.53
805.324	71.2927
805.579	62.0114
805.833	60.8932
806.087	68.6291
806.341	70.4809
806.596	60.9874
806.85	61.6216
807.104	71.1017
807.358	67.7604
807.613	66.2025
807.867	69.6964
808.121	62.1166
808.375	61.8903
808.629	66.9814
808.883	59.7311
809.138	61.6774
809.392	60.9116
809.646	60.604
809.9	62.3458
810.154	61.4266
810.408	56.9042
810.662	58.3875
810.916	59.9402
811.17	63.9858
811.424	63.5672
811.678	58.9814
811.932	55.4855
812.185	60.4515
812.439	58.8472
812.693	62.1534
812.947	59.918
813.201	53.8841
813.455	54.7694
813.709	53.7835
813.962	59.8022
814.216	57.5527
814.47	56.3302
814.724	59.0774
814.977	55.5101
815.231	57.8484
815.485	55.2751
815.739	59.6183
815.992	53.2199
816.246	57.0362
816.499	53.3288
816.753	56.609
817.007	55.1561
817.26	55.6564
817.514	53.8393
817.767	54.9838
818.021	56.4466
818.274	58.808
818.528	54.079
818.781	56.7122
819.01	50.1625
819.264	53.7
819.518	52.2052
819.772	58.9843
820.026	53.9669
820.28	48.6802
820.534	50.6212
820.788	54.6426
821.042	48.659
821.296	46.7962
821.549	50.0119
821.803	48.9297
822.057	49.063
822.311	52.0759
822.565	47.9902
822.819	48.9731
823.073	49.4537
823.326	46.7938
823.58	49.2425
823.834	49.6049
824.088	53.0557
824.341	47.0774
824.595	48.4379
824.849	48.2255
825.103	47.9573
825.356	49.3044
825.61	46.0134
825.864	46.5689
826.117	46.748
826.371	42.2494
826.624	50.0605
826.878	44.2271
827.131	44.7038
827.385	46.336
827.638	46.2165
827.892	46.8635
828.146	45.7953
828.399	46.6922
828.652	48.6473
828.906	46.0659
829.159	44.7886
829.413	44.5716
829.666	43.8472
829.919	44.3785
830.173	40.5077
830.426	43.2627
830.68	45.3378
830.933	46.2589
831.186	47.5422
831.439	41.4384
831.693	39.2724
831.946	43.9754
832.199	40.8242
832.452	45.4607
832.706	44.8457
832.959	41.4158
833.212	38.4497
833.465	44.7801
833.718	44.672
833.971	41.3838
834.224	46.7455
834.477	43.9995
834.73	41.1474
834.984	41.7158
835.237	39.3451
835.49	47.4443
835.743	40.7772
835.996	42.9274
836.201	37.093
836.454	42.9743
836.708	44.0549
836.961	40.4628
837.215	35.8127
837.468	38.0684
837.722	44.2298
837.975	40.0936
838.229	39.0108
838.482	39.3066
838.735	45.4452
838.989	41.904
839.242	39.0348
839.496	46.043
839.749	33.2457
840.002	40.0006
840.256	40.3292
840.509	41.1156
840.762	38.6696
841.015	43.4119
841.269	37.6906
841.522	40.9084
841.775	39.6265
842.028	39.309
842.281	45.735
842.535	41.9933
842.788	39.4711
843.041	37.3329
843.294	38.3308
843.547	39.457
843.8	39.9739
844.053	40.6304
844.306	43.9988
844.559	36.7449
844.812	41.5147
845.065	36.3301
845.318	37.7739
845.571	39.3325
845.824	39.5933
846.077	36.8954
846.33	38.6288
846.583	42.1583
846.836	37.5355
847.089	41.0658
847.342	39.6898
847.595	37.4243
847.847	34.216
848.1	37.3378
848.353	34.9736
848.606	40.1993
848.859	33.5081
849.111	37.2189
849.364	40.7593
849.617	36.2893
849.869	39.9199
850.122	40.1045
850.375	36.7338
850.627	36.5949
850.88	35.2773
851.133	39.1299
851.385	35.3237
851.638	34.5358
851.89	37.2762
852.143	32.9143
852.395	36.1033
852.648	34.4017
852.9	40.335
853.153	33.7705
853.405	40.6872
853.645	38.1499
853.898	35.9534
854.151	31.2213
854.404	40.512
854.657	34.7524
854.91	33.382
855.163	32.2588
855.416	34.9801
855.669	38.5154
855.922	34.7526
856.175	37.4698
856.427	37.1912
856.68	39.0609
856.933	36.7473
857.186	33.9034
857.439	35.9506
857.692	37.325
857.944	33.2731
858.197	36.4579
858.45	31.0034
858.703	32.2127
858.955	31.4276
859.208	33.2647
859.461	35.9101
859.713	32.86
859.966	30.0918
860.219	34.328
860.471	32.4039
860.724	36.3345
860.976	29.6437
861.229	37.75
861.481	34.9213
861.734	35.0181
861.986	35.8887
862.239	40.3862
862.491	35.4167
862.744	36.9422
862.996	31.6396
863.249	36.161
863.501	29.458
863.754	28.2253
864.006	32.6726
864.258	36.2144
864.511	37.9415
864.763	29.7776
865.015	32.1692
865.268	34.1331
865.52	33.9098
865.772	33.2376
866.024	33.1273
866.276	35.4077
866.529	33.8077
866.781	34.0678
867.033	35.34
867.285	31.6293
867.537	30.4266
867.789	32.4108
868.042	36.2679
868.294	33.5627
868.546	35.8878
868.798	33.0265
869.05	36.3328
869.302	30.9304
869.554	31.9013
869.806	34.5348
870.058	37.1048
870.31	32.2604
870.562	31.6985
870.782	29.1643
871.034	34.0495
871.287	32.0415
871.539	34.9383
871.792	29.6417
872.044	36.4643
872.297	30.9901
872.549	33.2896
872.801	31.2591
873.054	38.7955
873.306	34.857
873.558	34.8952
873.811	30.5738
874.063	31.94
874.315	34.5214
874.568	29.2921
874.82	35.8492
875.072	32.0906
875.324	34.3487
875.577	30.2982
875.829	32.0956
876.081	30.7239
876.333	34.0894
876.585	28.2442
876.838	33.4183
877.09	29.2158
877.342	30.0817
877.594	31.4922
877.846	34.7414
878.098	35.472
878.35	29.1988
878.602	31.9038
878.854	30.7162
879.106	36.001
879.358	25.3966
879.61	31.1923
879.862	30.2317
880.114	32.9249
880.366	26.0452
880.618	37.6328
880.87	30.0536
881.121	34.6096
881.373	29.0002
881.625	29.482
881.877	30.5772
882.129	31.1117
882.38	30.1569
882.632	29.2283
882.884	32.8536
883.136	28.6545
883.387	32.9101
883.639	29.9121
883.891	32.4992
884.142	30.561
884.394	25.2128
884.646	32.3115
884.897	28.0818
885.149	28.3214
885.4	28.4306
885.652	31.1032
885.903	31.8647
886.155	30.1723
886.406	30.4838
886.658	32.343
886.909	29.2314
887.161	33.3562
887.412	33.3315
887.664	27.7188
887.915	31.1834
888.138	30.0415
888.39	29.9063
888.642	27.5079
888.894	30.4914
889.146	26.8457
889.398	33.1915
889.65	31.822
889.902	27.9013
890.154	33.3742
890.406	27.8436
890.657	33.987
890.909	28.9049
891.161	28.5234
891.413	26.7318
891.665	31.1212
891.916	26.4203
892.168	34.1418
892.42	27.6477
892.671	26.4485
892.923	26.0602
893.175	34.7817
893.426	28.8162
893.678	29.7257
893.93	28.9995
894.181	29.2951
894.433	28.2825
894.684	30.8642
894.936	33.7724
895.188	30.9668
895.439	28.3478
895.69	25.1314
895.942	32.5752
896.193	32.205
896.445	27.8029
896.696	26.3845
896.948	32.4357
897.199	32.9938
897.451	29.1127
897.702	31.9222
897.953	28.9238
898.204	25.3316
898.456	25.9185
898.707	24.6355
898.958	29.7654
899.21	31.1783
899.461	27.6368
899.712	27.2022
899.963	30.6667