File: M2_270224_01.txt
#Acq. time (s)=	3
#Accumulations=	2
#Range (nm)=	520...900
#Windows=	8
#Auto scanning=	Off
#Autofocus=	Off
#AutoExposure=	Off
#Spike filter=	Multiple accum.
#Delay time (s)=	0
#Binning=	1
#Readout mode=	Signal
#DeNoise=	Off
#ICS correction=	Off
#Dark correction=	Off
#Inst. Process=	Off
#Detector temperature (°C)=	-59.98
#Instrument=	LabRAM HR Evol
#Detector=	Syncerity OE
#Objective=	x50_VIS
#Grating=	600 (500nm)
#ND Filter=	10%
#Laser=	514nm_Edge
#Hole=	199.981
#Range=	Auto
#StageXY=	Marzhauser
#StageZ=	Marzhauser
#X (µm)=	0
#Y (µm)=	0
#Z (µm)=	0
#Full time(mm:ss)=	1:32
#Project=
#Sample=
#Site=
#Title=	M2_270224
#Remark=
#Date=	06.03.2024 10:13
#Acquired=	06.03.2024 10:13:36
520.044	30
520.306	20
520.569	28
520.831	26
521.093	28
521.355	28
521.617	20
521.88	30
522.142	30
522.404	26
522.666	24
522.928	12
523.19	20
523.453	30
523.715	30
523.977	22
524.239	26
524.501	30
524.763	22
525.025	24
525.287	18
525.549	32
525.811	28
526.073	22
526.335	32
526.597	26
526.859	32
527.121	28
527.383	22
527.645	34
527.907	26
528.169	20
528.431	20
528.693	30
528.955	30
529.217	28
529.479	20
529.741	28
530.003	36
530.264	24
530.526	28
530.788	20
531.05	32
531.312	30
531.574	24
531.835	26
532.097	28
532.359	26
532.621	30
532.883	24
533.144	30
533.406	22
533.668	28
533.93	28
534.191	20
534.453	32
534.715	34
534.976	34
535.238	26
535.5	36
535.761	34
536.023	30
536.285	26
536.546	32
536.808	26
537.069	34
537.331	28
537.593	30
537.854	24
538.116	40
538.377	26
538.639	24
538.9	30
539.162	26
539.423	24
539.685	26
539.946	36
540.208	30
540.469	34
540.731	28
540.992	30
541.254	30
541.515	32
541.776	24
542.038	24
542.299	34
542.56	32
542.822	28
543.083	26
543.344	34
543.606	28
543.867	36
544.128	24
544.39	38
544.651	34
544.912	32
545.174	24
545.435	34
545.696	38
545.957	34
546.218	30
546.48	32
546.741	36
547.002	28
547.263	38
547.524	30
547.785	34
548.047	34
548.308	42
548.569	30
548.83	40
549.091	32
549.352	34
549.613	36
549.874	38
550.135	46
550.396	30
550.657	40
550.918	36
551.179	52
551.44	54
551.701	60
551.962	80
552.223	154
552.484	1756
552.745	11774
553.006	290
553.267	112
553.528	74
553.788	58
554.049	40
554.31	36
554.571	48
554.832	48
555.093	46
555.353	38
555.614	34
555.875	36
556.136	38
556.396	32
556.657	40
556.918	38
557.179	48
557.439	36
557.7	38
557.961	32
558.221	34
558.482	36
558.743	30
559.003	40
559.264	34
559.525	34
559.785	38
560.046	40
560.306	44
560.567	46
560.827	42
561.088	42
561.348	48
561.609	30
561.869	34
562.13	40
562.39	44
562.651	42
562.911	42
563.172	40
563.432	52
563.692	50
563.953	46
564.213	46
564.474	40
564.734	50
564.994	52
565.255	44
565.515	46
565.775	52
566.035	52
566.296	36
566.556	50
566.816	48
567.076	52
567.337	50
567.597	48
567.857	56
568.117	57.96
568.377	57.7394
568.637	48.7365
568.898	59.2467
569.158	52.4819
569.418	60.2989
569.678	53.494
569.938	52.8121
570.198	59.8912
570.458	56.95
570.718	59.6578
570.978	66.9308
571.238	58.4423
571.498	56.9532
571.758	60.3582
572.018	66.8361
572.278	70.1067
572.538	66.7635
572.798	63.9979
573.058	82.5686
573.312	78
573.573	72
573.834	86
574.095	104
574.356	100
574.617	106
574.878	98
575.139	120
575.4	112
575.661	120
575.922	122
576.183	114
576.444	102
576.705	116
576.965	108
577.226	106
577.487	100
577.748	92
578.009	90
578.27	88
578.531	88
578.791	92
579.052	88
579.313	94
579.574	90
579.835	94
580.095	96
580.356	86
580.617	86
580.878	90
581.138	100
581.399	98
581.66	94
581.92	102
582.181	106
582.442	110
582.703	96
582.963	112
583.224	120
583.484	114
583.745	114
584.006	118
584.266	138
584.527	126
584.787	122
585.048	136
585.308	132
585.569	140
585.83	136
586.09	134
586.351	132
586.611	148
586.872	152
587.132	120
587.392	154
587.653	148
587.913	136
588.174	156
588.434	160
588.695	162
588.955	164
589.215	170
589.476	170
589.736	180
589.996	180
590.257	152
590.517	168
590.777	164
591.038	170
591.298	158
591.558	140
591.818	134
592.079	138
592.339	158
592.599	140
592.859	126
593.12	150
593.38	128
593.64	142
593.9	146
594.16	142
594.42	146
594.68	146
594.941	134
595.201	138
595.461	150
595.721	154
595.981	142
596.241	142
596.501	170
596.761	172
597.021	152
597.281	146
597.541	152
597.801	156
598.061	150
598.321	136
598.581	138
598.841	126
599.101	130
599.361	138
599.62	140
599.88	140
600.14	144
600.4	144
600.66	120
600.92	152
601.18	128
601.439	124
601.699	132
601.959	150
602.219	138
602.478	152
602.738	144
602.998	142
603.258	138
603.517	146
603.777	144
604.037	136
604.296	134
604.556	154
604.816	140
605.075	128
605.335	136
605.594	140
605.854	130
606.114	146
606.373	140
606.633	142
606.892	152
607.152	152
607.411	142
607.671	148
607.93	144
608.19	138
608.449	140
608.709	140
608.968	146
609.228	154
609.487	142
609.746	158
610.006	154
610.265	146
610.524	150
610.784	156
611.043	162
611.302	158
611.562	156
611.821	152
612.08	162
612.339	154
612.599	158
612.858	150
613.117	164
613.376	156
613.635	158
613.895	156
614.154	162
614.413	152
614.672	172
614.931	162
615.19	168
615.449	180
615.709	170
615.968	172
616.227	177.476
616.486	169.397
616.745	163.511
617.004	168.556
617.263	176.563
617.522	170.585
617.781	182.636
618.04	183.588
618.299	180.672
618.557	181.989
618.816	170.506
619.075	165.514
619.334	172.876
619.593	186.88
619.852	178.505
620.111	177.227
620.37	165.695
620.628	174.13
620.887	181.525
621.146	183.024
621.373	170
621.633	174
621.893	176
622.153	198
622.413	180
622.673	178
622.932	178
623.192	194
623.452	182
623.712	172
623.972	188
624.232	172
624.492	182
624.751	164
625.011	170
625.271	184
625.531	176
625.791	180
626.05	200
626.31	184
626.57	200
626.83	192
627.089	186
627.349	190
627.609	192
627.868	182
628.128	194
628.388	204
628.647	200
628.907	204
629.167	196
629.426	204
629.686	206
629.945	214
630.205	204
630.465	184
630.724	204
630.984	202
631.243	196
631.503	196
631.762	200
632.022	218
632.281	210
632.541	198
632.8	208
633.06	214
633.319	210
633.579	226
633.838	226
634.097	208
634.357	206
634.616	216
634.876	244
635.135	236
635.394	246
635.654	240
635.913	240
636.172	256
636.431	258
636.691	262
636.95	282
637.209	288
637.469	310
637.728	314
637.987	296
638.246	294
638.505	282
638.765	294
639.024	282
639.283	272
639.542	260
639.801	260
640.06	272
640.319	252
640.578	250
640.838	260
641.097	246
641.356	240
641.615	252
641.874	264
642.133	262
642.392	234
642.651	262
642.91	252
643.169	252
643.428	236
643.687	264
643.946	264
644.205	272
644.463	262
644.722	258
644.981	272
645.24	264
645.499	268
645.758	256
646.017	266
646.275	270
646.534	262
646.793	276
647.052	278
647.31	274
647.569	268
647.828	280
648.087	264
648.345	270
648.604	280
648.863	282
649.121	280
649.38	280
649.639	284
649.897	276
650.156	280
650.415	288
650.673	286
650.932	268
651.19	288
651.449	282
651.707	294
651.966	280
652.224	296
652.483	294
652.741	318
653	298
653.258	306
653.517	296
653.775	302
654.034	298
654.292	316
654.55	330
654.809	302
655.067	334
655.326	314
655.584	334
655.842	318
656.1	330
656.359	330
656.617	342
656.875	346
657.134	332
657.392	342
657.65	330
657.908	350
658.166	336
658.425	336
658.683	354
658.941	348
659.199	338
659.457	362
659.715	366
659.973	344
660.231	336
660.49	342
660.748	346
661.006	366
661.264	348
661.522	330
661.78	358
662.038	364
662.296	318
662.554	356
662.811	354
663.069	342
663.327	334
663.585	334
663.843	359.99
664.101	346.048
664.359	347.801
664.617	352.533
664.874	322.215
665.132	341.374
665.39	344.43
665.648	344.859
665.906	352.111
666.163	345.077
666.421	362.504
666.679	341.446
666.937	353.334
667.194	344.874
667.452	341.591
667.71	343.339
667.967	339.47
668.225	342.338
668.482	349.711
668.74	347.048
668.987	366
669.245	374
669.504	360
669.763	320
670.022	358
670.281	332
670.539	344
670.798	340
671.057	356
671.316	348
671.575	356
671.833	350
672.092	348
672.351	348
672.609	376
672.868	362
673.127	356
673.385	342
673.644	368
673.903	348
674.161	354
674.42	354
674.678	366
674.937	366
675.195	362
675.454	364
675.713	376
675.971	380
676.23	376
676.488	346
676.747	400
677.005	396
677.263	372
677.522	362
677.78	386
678.039	386
678.297	370
678.556	350
678.814	372
679.072	380
679.331	380
679.589	360
679.847	378
680.106	372
680.364	358
680.622	380
680.881	378
681.139	378
681.397	376
681.656	372
681.914	350
682.172	376
682.43	400
682.688	392
682.947	376
683.205	386
683.463	376
683.721	394
683.979	356
684.237	376
684.495	374
684.754	352
685.012	366
685.27	388
685.528	370
685.786	374
686.044	366
686.302	372
686.56	362
686.818	374
687.076	372
687.334	354
687.592	370
687.85	388
688.108	376
688.366	368
688.623	364
688.881	376
689.139	378
689.397	368
689.655	348
689.913	364
690.171	356
690.428	362
690.686	350
690.944	358
691.202	368
691.459	364
691.717	338
691.975	344
692.233	344
692.49	346
692.748	378
693.006	344
693.263	352
693.521	364
693.779	352
694.036	352
694.294	358
694.552	362
694.809	360
695.067	366
695.324	356
695.582	330
695.839	342
696.097	340
696.354	346
696.612	368
696.869	352
697.127	352
697.384	334
697.642	324
697.899	326
698.156	336
698.414	338
698.671	342
698.928	326
699.186	338
699.443	334
699.7	344
699.958	324
700.215	342
700.472	338
700.73	304
700.987	342
701.244	338
701.501	326
701.758	328
702.016	320
702.273	332
702.53	328
702.787	330
703.044	328
703.301	322
703.558	328
703.816	304
704.073	334
704.33	334
704.587	326
704.844	306
705.101	314
705.358	336
705.615	308
705.872	316
706.129	316
706.386	320
706.643	314
706.899	308
707.156	300
707.413	314
707.67	310
707.927	320
708.184	298
708.441	310
708.697	316
708.954	298
709.211	274
709.468	272
709.725	324
709.981	300
710.238	318
710.495	296
710.751	308
711.008	312
711.265	294.119
711.521	304.145
711.778	305.718
712.035	321.064
712.291	296.479
712.548	291.506
712.804	295.445
713.061	289.551
713.317	295.758
713.574	288.759
713.831	283.015
714.087	283.194
714.343	283.652
714.6	280.075
714.856	278.845
715.113	281.369
715.369	267.485
715.626	279.851
715.882	270.835
716.138	269.832
716.395	282.972
716.639	276
716.897	270
717.155	266
717.412	256
717.67	264
717.927	272
718.185	246
718.443	258
718.7	270
718.958	264
719.215	266
719.473	260
719.73	262
719.988	268
720.245	254
720.503	260
720.76	254
721.018	260
721.275	236
721.532	246
721.79	264
722.047	232
722.305	254
722.562	230
722.819	240
723.077	240
723.334	244
723.591	254
723.849	238
724.106	246
724.363	234
724.621	236
724.878	232
725.135	240
725.392	252
725.65	250
725.907	230
726.164	236
726.421	236
726.678	220
726.935	224
727.193	240
727.45	242
727.707	226
727.964	228
728.221	220
728.478	252
728.735	228
728.992	224
729.249	216
729.506	240
729.763	204
730.02	214
730.277	218
730.534	212
730.791	210
731.048	238
731.305	218
731.562	212
731.819	220
732.076	216
732.333	214
732.589	196
732.846	218
733.103	200
733.36	214
733.617	202
733.873	214
734.13	222
734.387	220
734.644	202
734.901	210
735.157	222
735.414	224
735.671	224
735.927	218
736.184	224
736.441	222
736.697	224
736.954	222
737.211	242
737.467	218
737.724	230
737.98	234
738.237	238
738.493	240
738.75	248
739.006	238
739.263	214
739.519	218
739.776	224
740.032	216
740.289	222
740.545	206
740.802	190
741.058	220
741.314	198
741.571	180
741.827	198
742.083	198
742.34	168
742.596	186
742.852	184
743.109	192
743.365	204
743.621	190
743.878	196
744.134	160
744.39	186
744.646	184
744.902	182
745.159	182
745.415	188
745.671	168
745.927	174
746.183	188
746.439	182
746.695	156
746.951	162
747.207	174
747.463	182
747.719	174
747.975	168
748.231	176
748.487	176
748.743	174
748.999	158
749.255	166
749.511	170
749.767	168
750.023	174
750.279	168
750.535	178
750.791	166
751.046	170
751.302	168
751.558	172
751.814	176
752.07	166
752.325	168
752.581	162
752.837	156
753.092	162
753.348	154
753.604	148
753.859	144
754.115	154
754.371	154
754.626	144
754.882	150
755.138	168
755.393	154
755.649	146
755.904	160
756.16	142
756.415	158
756.671	134
756.926	146
757.182	152
757.437	150
757.693	148
757.948	126
758.203	144
758.459	142
758.714	145.912
758.97	146.436
759.225	143.94
759.48	136.552
759.736	134.291
759.991	135.502
760.246	127.396
760.501	136.775
760.757	136.825
761.012	132.709
761.267	132.554
761.522	126.071
761.777	137.486
762.033	136.829
762.288	135.765
762.543	125.407
762.798	133.404
763.053	132.11
763.308	133.542
763.563	132.774
763.78	112
764.037	126
764.293	134
764.55	122
764.806	116
765.062	132
765.319	108
765.575	114
765.831	114
766.088	116
766.344	118
766.6	130
766.857	110
767.113	118
767.369	116
767.625	102
767.882	120
768.138	112
768.394	122
768.65	108
768.906	118
769.163	110
769.419	118
769.675	118
769.931	118
770.187	118
770.443	114
770.699	122
770.955	106
771.211	118
771.467	114
771.723	92
771.979	106
772.235	106
772.491	104
772.747	96
773.003	100
773.259	106
773.515	102
773.771	90
774.027	112
774.283	108
774.539	96
774.795	102
775.05	98
775.306	102
775.562	108
775.818	108
776.074	90
776.329	94
776.585	94
776.841	110
777.097	86
777.352	100
777.608	98
777.864	100
778.12	86
778.375	94
778.631	86
778.886	100
779.142	94
779.398	90
779.653	90
779.909	86
780.164	100
780.42	100
780.675	96
780.931	88
781.187	88
781.442	92
781.698	78
781.953	80
782.208	102
782.464	86
782.719	86
782.975	100
783.23	88
783.485	100
783.741	82
783.996	74
784.252	88
784.507	82
784.762	86
785.017	84
785.273	88
785.528	84
785.783	88
786.038	88
786.294	82
786.549	74
786.804	86
787.059	84
787.314	74
787.57	70
787.825	72
788.08	76
788.335	66
788.59	80
788.845	74
789.1	82
789.355	82
789.61	72
789.865	72
790.12	70
790.375	72
790.63	68
790.885	74
791.14	64
791.395	80
791.65	82
791.905	80
792.16	78
792.414	72
792.669	68
792.924	70
793.179	76
793.434	64
793.689	68
793.943	76
794.198	76
794.453	74
794.708	78
794.962	68
795.217	68
795.472	62
795.726	60
795.981	66
796.236	68
796.49	62
796.745	66
796.999	70
797.254	62
797.508	70
797.763	58
798.018	66
798.272	46
798.526	72
798.781	60
799.035	70
799.29	50
799.544	64
799.799	54
800.053	50
800.307	60
800.562	66
800.816	64
801.07	52
801.325	62
801.579	54
801.833	60
802.088	66
802.342	56
802.596	58
802.85	62
803.105	58
803.359	52
803.613	54
803.867	58
804.121	60
804.375	50
804.63	54
804.884	50
805.138	64
805.392	58
805.646	61.5495
805.9	44.7963
806.154	47.0968
806.408	60.6543
806.662	49.8574
806.916	47.8997
807.17	50.299
807.424	55.5098
807.678	54.1852
807.931	53.1185
808.185	56.7328
808.439	50.5067
808.693	59.0072
808.947	49.0286
809.201	48.0077
809.454	45.3801
809.708	59.6138
809.962	51.0017
810.216	53.6776
810.469	46.3745
810.678	50
810.933	44
811.188	54
811.443	44
811.699	54
811.954	48
812.209	54
812.464	48
812.719	46
812.974	44
813.229	52
813.484	52
813.739	40
813.994	46
814.249	46
814.504	52
814.759	54
815.014	48
815.268	40
815.523	46
815.778	44
816.033	46
816.288	46
816.543	52
816.798	48
817.052	42
817.307	42
817.562	30
817.817	54
818.071	42
818.326	40
818.581	42
818.836	46
819.09	48
819.345	42
819.6	42
819.854	46
820.109	40
820.364	42
820.618	44
820.873	48
821.127	46
821.382	30
821.637	38
821.891	44
822.146	46
822.4	44
822.655	40
822.909	44
823.164	50
823.418	40
823.672	44
823.927	40
824.181	46
824.436	44
824.69	42
824.944	46
825.199	48
825.453	38
825.707	36
825.962	48
826.216	30
826.47	44
826.725	32
826.979	44
827.233	42
827.487	36
827.741	42
827.996	30
828.25	36
828.504	46
828.758	36
829.012	40
829.266	30
829.52	40
829.774	48
830.029	36
830.283	30
830.537	44
830.791	46
831.045	34
831.299	40
831.553	38
831.807	44
832.061	48
832.315	40
832.568	44
832.822	42
833.076	40
833.33	42
833.584	32
833.838	48
834.092	36
834.345	38
834.599	32
834.853	46
835.107	34
835.36	38
835.614	40
835.868	30
836.122	42
836.375	36
836.629	38
836.883	32
837.136	38
837.39	44
837.643	34
837.897	36
838.151	36
838.404	42
838.658	38
838.911	36
839.165	38
839.418	44
839.672	34
839.925	34
840.179	42
840.432	36
840.686	40
840.939	32
841.192	30
841.446	42
841.699	40
841.952	30
842.206	42
842.459	32
842.712	38
842.966	36
843.219	36
843.472	32
843.725	42
843.979	24
844.232	36
844.485	26
844.738	36
844.991	40
845.244	34
845.497	32
845.75	36
846.004	38
846.257	26
846.51	26
846.763	34
847.016	40
847.269	40
847.522	26
847.775	42
848.028	38
848.281	30
848.534	38
848.786	34
849.039	40
849.292	36
849.545	30
849.798	28
850.051	36
850.303	32
850.556	28
850.809	32
851.062	28
851.314	38
851.567	28
851.82	34
852.073	34
852.325	33.9903
852.578	31.6712
852.831	31.5641
853.083	26.62
853.336	33.0262
853.588	28.0563
853.841	27.1503
854.093	34.9421
854.346	33.7287
854.598	31.6554
854.851	30.2561
855.103	30.1694
855.356	30.87
855.608	29.373
855.861	26.5839
856.113	28.9945
856.366	34.5311
856.618	29.219
856.87	26.9753
857.123	26.8058
857.352	36
857.606	32
857.859	26
858.113	34
858.367	28
858.621	34
858.875	32
859.128	28
859.382	28
859.636	32
859.889	34
860.143	28
860.397	28
860.65	34
860.904	28
861.158	30
861.411	20
861.665	24
861.918	28
862.172	34
862.425	26
862.679	34
862.932	26
863.186	34
863.439	22
863.693	28
863.946	26
864.2	28
864.453	26
864.707	30
864.96	34
865.213	28
865.467	24
865.72	20
865.973	34
866.227	30
866.48	36
866.733	24
866.987	30
867.24	32
867.493	30
867.746	28
867.999	26
868.253	32
868.506	32
868.759	32
869.012	28
869.265	24
869.518	32
869.771	38
870.025	24
870.278	32
870.531	26
870.784	28
871.037	30
871.29	24
871.543	28
871.796	32
872.049	32
872.302	22
872.555	30
872.808	26
873.06	32
873.313	24
873.566	26
873.819	34
874.072	32
874.325	26
874.578	30
874.83	30
875.083	36
875.336	22
875.589	30
875.841	34
876.094	32
876.347	30
876.6	22
876.852	28
877.105	32
877.358	30
877.61	26
877.863	26
878.115	30
878.368	34
878.621	26
878.873	32
879.126	24
879.378	34
879.631	30
879.883	22
880.136	34
880.388	30
880.641	30
880.893	24
881.145	26
881.398	32
881.65	32
881.902	28
882.155	30
882.407	42
882.659	28
882.912	26
883.164	32
883.416	40
883.669	32
883.921	28
884.173	20
884.425	26
884.677	32
884.93	30
885.182	24
885.434	32
885.686	30
885.938	32
886.19	24
886.442	28
886.694	34
886.946	22
887.198	22
887.45	20
887.702	26
887.954	28
888.206	30
888.458	26
888.71	34
888.962	26
889.214	30
889.466	20
889.718	26
889.969	30
890.221	18
890.473	22
890.725	26
890.977	36
891.228	26
891.48	22
891.732	22
891.983	28
892.235	32
892.487	26
892.738	26
892.99	24
893.242	24
893.493	30
893.745	30
893.996	24
894.248	22
894.5	34
894.751	20
895.003	22
895.254	32
895.505	30
895.757	26
896.008	26
896.26	30
896.511	26
896.763	28
897.014	18
897.265	22
897.517	26
897.768	24
898.019	22
898.27	22
898.522	28
898.773	28
899.024	22
899.275	18
899.527	28
899.778	18
899.979	24