File: M3_140224_01.txt
#Acq. time (s)=	2
#Accumulations=	3
#Range (nm)=	520...900
#Windows=	24
#Auto scanning=	On
#Autofocus=	Off
#AutoExposure=	Off
#Spike filter=	Multiple accum.
#Delay time (s)=	0
#Binning=	1
#Readout mode=	Signal
#DeNoise=	Off
#ICS correction=	Off
#Dark correction=	Off
#Inst. Process=	Off
#Detector temperature (°C)=	-59.98
#Instrument=	LabRAM HR Evol
#Detector=	Syncerity OE
#Objective=	x50_VIS
#Grating=	600 (500nm)
#ND Filter=	10%
#Laser=	514nm_Edge
#Hole=	199.981
#Range=	Auto
#StageXY=	Marzhauser
#StageZ=	Marzhauser
#X (µm)=	-5866
#Y (µm)=	817.4
#Z (µm)=	-25.2
#Full time(mm:ss)=	3:03
#Project=
#Sample=
#Site=
#Title=	M3_140224
#Remark=
#Date=	19.02.2024 14:16
#Acquired=	19.02.2024 14:16:38
520.013	26.0636
520.274	31.6663
520.536	23.2673
520.797	25.7677
521.059	27.327
521.32	23.0626
521.582	29.0405
521.843	25.0868
522.105	26.8866
522.366	29.8531
522.628	25.7529
522.889	26.4282
523.15	26.9172
523.412	31.402
523.673	25.749
523.935	28.2356
524.196	26.058
524.457	27.4451
524.719	25.8483
524.98	26.8407
525.241	26.285
525.503	28.3636
525.764	27.0092
526.025	27.0805
526.286	30.5072
526.548	25.497
526.809	25.8732
527.07	26.8225
527.331	29.8512
527.593	24.8118
527.854	28.7832
528.115	27.6746
528.376	27.4266
528.637	25.6912
528.898	27.7745
529.16	26.5995
529.421	27.4426
529.682	25.799
529.943	25.2383
530.204	28.5424
530.465	32.0816
530.726	25.7452
530.987	30.0799
531.248	25.3019
531.509	30.1181
531.77	31.1894
532.031	30.5929
532.292	31.139
532.553	30.7087
532.814	28.1839
533.075	27.5058
533.336	29.6413
533.597	28.6624
533.858	27.2316
534.119	26.6869
534.38	30.5274
534.641	34.0706
534.901	33.4826
535.162	32.6044
535.423	31.319
535.684	36.7847
535.945	25.3471
536.205	30.65
536.466	27.6404
536.727	31.3337
536.988	29.123
537.248	33.6187
537.509	29.2771
537.77	27.8913
537.987	27.6456
538.249	32.4834
538.51	30.9279
538.771	25.9764
539.032	27.853
539.293	24.4684
539.554	27.6711
539.815	31.3087
540.076	28.6514
540.337	30.2919
540.598	28.9486
540.859	28.9898
541.12	29.7376
541.381	32.7908
541.642	27.5751
541.903	29.8584
542.164	25.7131
542.425	30.7778
542.686	31.7514
542.947	31.3865
543.208	33.0818
543.469	26.7559
543.73	31.6676
543.991	32.0503
544.252	32.866
544.513	33.5538
544.773	34.0584
545.034	27.3681
545.295	30.8908
545.556	29.4914
545.817	31.1114
546.077	31.9765
546.338	33.387
546.599	35.3023
546.86	32.8227
547.12	31.669
547.381	31.6312
547.642	35.1076
547.903	33.7208
548.163	33.4893
548.424	36.408
548.685	31.8396
548.945	32.7613
549.206	29.4478
549.467	33.4273
549.727	34.21
549.988	36.7291
550.248	37.6278
550.509	35.8927
550.769	36.1269
551.03	37.8198
551.291	45.8709
551.551	50.4711
551.812	62.8092
552.072	82.1285
552.332	172.25
552.593	3602.48
552.853	1190.25
553.114	105.667
553.374	63.8705
553.635	55.1598
553.895	44.0966
554.155	42.176
554.416	38.9044
554.676	39.5487
554.937	39.3563
555.197	39.487
555.457	39.5235
555.686	37.9394
555.947	34.2478
556.207	39.8856
556.468	42.2924
556.729	38.2644
556.99	38.1418
557.25	39.8681
557.511	38.9555
557.772	39.2746
558.032	43.3089
558.293	33.3207
558.554	40.8916
558.814	36.5589
559.075	39.5194
559.336	40.8581
559.596	39.8388
559.857	39.4812
560.117	42.1745
560.378	36.5128
560.638	42.5163
560.899	34.5379
561.159	43.2285
561.42	41.9547
561.68	46.3551
561.941	44.1599
562.201	42.3949
562.462	45.7625
562.722	43.9014
562.983	43.1893
563.243	46.1607
563.504	42.6828
563.764	41.864
564.024	49.3165
564.285	48.8251
564.545	48.7189
564.805	44.3055
565.066	46.749
565.326	48.9746
565.586	50.683
565.847	48.1616
566.107	47.5665
566.367	49.2065
566.627	49.7517
566.888	54.1948
567.148	48.1447
567.408	51.6591
567.668	49.5395
567.928	55.6684
568.189	51.6062
568.449	58.2625
568.709	55.1192
568.969	55.2393
569.229	56.0959
569.489	62.5077
569.749	59.5334
570.009	66.1716
570.269	69.6218
570.53	64.2488
570.79	66.0624
571.05	64.4392
571.31	66.3464
571.57	64.0682
571.83	63.2092
572.09	69.5312
572.349	75.5351
572.609	75.118
572.869	75.437
573.129	74.6288
573.368	87.1059
573.629	90.4325
573.889	86.8739
574.15	96.9877
574.41	110.498
574.67	113.931
574.931	115.916
575.191	111.695
575.451	121.971
575.711	119.024
575.972	114.758
576.232	107.623
576.492	113.81
576.752	106.189
577.013	103.429
577.273	97.7493
577.533	98.581
577.793	95.2418
578.053	89.6585
578.313	83.2007
578.574	94.2154
578.834	90.0593
579.094	90.5535
579.354	91.6505
579.614	92.4355
579.874	91.6928
580.134	96.8713
580.394	86.4516
580.654	89.1312
580.914	93.3546
581.174	96.9307
581.434	87.8728
581.694	93.6218
581.954	98.1268
582.214	101.374
582.474	105.641
582.734	102.389
582.994	106.905
583.254	111.296
583.514	107.508
583.773	112.208
584.033	110.128
584.293	109.602
584.553	112.947
584.813	118.855
585.073	119.9
585.332	120.838
585.592	124.032
585.852	118.86
586.112	121.425
586.371	119.555
586.631	127.324
586.891	126.078
587.151	135.605
587.41	132.861
587.67	132.189
587.93	135.903
588.189	132.904
588.449	140.68
588.709	135.631
588.968	141.974
589.228	154.032
589.487	143.349
589.747	138.795
590.006	146.926
590.266	145.64
590.525	139.984
590.785	140.294
591.036	142.91
591.296	133.769
591.556	129.251
591.816	130.787
592.076	123.609
592.336	121.513
592.596	130.111
592.856	127.245
593.116	129.276
593.376	139.115
593.635	135.804
593.895	128.346
594.155	121.986
594.415	133.647
594.675	127.911
594.935	131.685
595.194	143.788
595.454	134.62
595.714	138.482
595.974	135.688
596.233	143.838
596.493	137.932
596.753	158.641
597.012	140.061
597.272	142.692
597.532	136.32
597.791	135.953
598.051	131.744
598.311	139.623
598.57	137.213
598.83	131.982
599.089	139.741
599.349	138.12
599.609	125.03
599.868	127.893
600.128	132.678
600.387	137.968
600.647	127.062
600.906	137.337
601.166	135.921
601.425	125.899
601.685	126.028
601.944	138.032
602.203	132.795
602.463	132.069
602.722	136.93
602.982	137.528
603.241	137.425
603.5	140.988
603.76	140.276
604.019	135.475
604.278	142.079
604.538	144.88
604.797	137.874
605.056	139.47
605.315	137.916
605.575	141.653
605.834	140.335
606.093	141.053
606.352	142.4
606.611	145.88
606.871	143.473
607.13	144.934
607.389	140.547
607.648	139.185
607.907	137.646
608.166	139.656
608.425	145.778
608.664	146.028
608.924	143.762
609.183	143.685
609.443	152.657
609.702	152.247
609.962	152.744
610.221	151.59
610.481	158.564
610.74	147.018
611	149.509
611.259	147.738
611.518	144.847
611.778	152.603
612.037	149.719
612.297	149.775
612.556	149.32
612.815	148.312
613.075	160.966
613.334	152.521
613.594	162.435
613.853	161.58
614.112	161.042
614.371	164.43
614.631	158.379
614.89	159.138
615.149	169.445
615.408	165.31
615.668	169.315
615.927	169.031
616.186	178.177
616.445	174.664
616.704	167.625
616.964	170.099
617.223	166.193
617.482	181.369
617.741	177.478
618	174.729
618.259	173.995
618.518	174.592
618.777	183.901
619.036	184.738
619.295	173.231
619.554	182.076
619.813	176.24
620.072	185.902
620.331	177.287
620.59	183.348
620.849	178.846
621.108	185.76
621.367	189.841
621.626	185.508
621.885	188.031
622.144	181.994
622.403	187.223
622.661	184.166
622.92	191.493
623.179	185.448
623.438	190.359
623.697	182.409
623.956	188.797
624.214	196.02
624.473	187.592
624.732	187.229
624.99	194.572
625.249	189.564
625.508	196.298
625.767	198.919
626.025	200.244
626.249	193.997
626.508	185.774
626.767	187.264
627.026	199.546
627.285	194.745
627.544	194.488
627.803	192.482
628.062	205.143
628.321	203.764
628.58	212.729
628.839	199.419
629.098	197.124
629.357	203.484
629.616	205.827
629.875	201.084
630.134	202.87
630.393	202.815
630.652	205.067
630.911	207.834
631.17	207.306
631.429	212.946
631.688	206.953
631.947	212.394
632.206	206.873
632.464	213.312
632.723	211.931
632.982	224.527
633.241	219.02
633.5	222.774
633.758	213.922
634.017	222.244
634.276	229.022
634.535	228.873
634.793	231.419
635.052	232.268
635.311	241.109
635.57	248.638
635.828	255.689
636.087	255.913
636.345	269.966
636.604	282.313
636.863	278.346
637.121	301.559
637.38	298.167
637.638	294.111
637.897	308.082
638.156	298.897
638.414	296.401
638.673	287.668
638.931	286.667
639.19	287.284
639.448	279.281
639.706	275.823
639.965	270.353
640.223	270.631
640.482	275.609
640.74	267.47
640.999	264.752
641.257	258.344
641.515	261.098
641.774	249.467
642.032	265.304
642.29	262.017
642.549	244.45
642.807	268.913
643.065	258.767
643.323	258.513
643.582	259.846
643.84	263.076
644.053	265.985
644.312	281.826
644.57	272.866
644.829	263.854
645.088	268.95
645.346	270.405
645.605	278.505
645.864	267.393
646.122	270.807
646.381	271.203
646.639	276.004
646.898	267.135
647.157	278.798
647.415	282.499
647.674	281.116
647.932	276.917
648.191	275.682
648.449	280.612
648.708	281.765
648.966	288.491
649.225	282.151
649.483	286.305
649.742	291.435
650	296.983
650.258	296.859
650.517	310.396
650.775	296.112
651.034	294.146
651.292	297.869
651.55	296.607
651.809	311.16
652.067	299.129
652.325	302.744
652.583	305.194
652.842	312.523
653.1	302.837
653.358	306.933
653.616	311.602
653.875	324.694
654.133	314.814
654.391	327.446
654.649	327.487
654.907	329.879
655.165	332.276
655.424	338.838
655.682	332.59
655.94	350.625
656.198	342.742
656.456	341.083
656.714	352.906
656.972	358.675
657.23	356.79
657.488	352.202
657.746	363.401
658.004	363.641
658.262	348.845
658.52	369.657
658.778	351.366
659.036	370.845
659.294	372.441
659.552	370.211
659.809	367.493
660.067	372.255
660.325	365.467
660.583	357.24
660.841	368.825
661.099	359.054
661.356	362.04
661.583	362.567
661.842	354.734
662.1	364.077
662.358	367.004
662.616	367.495
662.875	356.135
663.133	353.092
663.391	368.386
663.649	371.485
663.907	354.693
664.166	371.648
664.424	369.975
664.682	353.492
664.94	374.284
665.198	366.911
665.456	375.213
665.714	356.255
665.972	373.935
666.23	357.402
666.488	376.42
666.746	355.948
667.004	350.329
667.262	364.548
667.52	367.949
667.778	355.069
668.036	374.473
668.294	362.645
668.552	359.502
668.81	362.498
669.068	358.143
669.326	365.707
669.584	363.518
669.842	360.322
670.099	360.133
670.357	357.597
670.615	354.733
670.873	364.19
671.131	370.546
671.388	380.108
671.646	365.598
671.904	362.296
672.162	370.149
672.419	356.173
672.677	365.683
672.935	361.481
673.192	367.106
673.45	368.31
673.708	382.221
673.965	372.514
674.223	375.532
674.481	376.494
674.738	372.832
674.996	372.619
675.253	387.63
675.511	380.942
675.768	378.579
676.026	379.587
676.283	375.52
676.541	379.346
676.798	385.6
677.056	373.937
677.313	385.599
677.571	392.624
677.828	376.145
678.085	384.098
678.343	375.963
678.6	388.354
678.857	381.198
679.083	378.285
679.341	387.072
679.599	388.712
679.857	397.107
680.114	368.121
680.372	389.152
680.63	378.618
680.888	381.024
681.146	382.211
681.403	393.796
681.661	398.982
681.919	394.921
682.176	391.026
682.434	395.408
682.692	387.416
682.949	399.64
683.207	388.97
683.465	387.069
683.722	407.662
683.98	387.688
684.237	396.697
684.495	396.6
684.753	375.992
685.01	390.082
685.268	398.931
685.525	395.132
685.783	386.212
686.04	370.242
686.298	384.291
686.555	394.632
686.813	380.028
687.07	387.843
687.327	382.682
687.585	389.28
687.842	375.174
688.1	385.737
688.357	388.74
688.614	383.824
688.872	382.264
689.129	379.054
689.386	375.376
689.643	380.181
689.901	371.488
690.158	368.65
690.415	382.462
690.672	373.026
690.93	375.263
691.187	381.733
691.444	368.178
691.701	372.205
691.958	381.742
692.216	372.348
692.473	376.633
692.73	364.691
692.987	368.541
693.244	370.817
693.501	365.88
693.758	370.257
694.015	373.838
694.272	371.652
694.529	371.133
694.786	348.28
695.043	371.783
695.3	364.959
695.557	364.782
695.814	349.998
696.071	367.712
696.328	359.986
696.585	355.667
696.81	358.705
697.068	360.236
697.325	351.586
697.582	357.48
697.84	350.547
698.097	351.147
698.354	348.21
698.612	349.513
698.869	338.799
699.126	335.06
699.384	351.579
699.641	343.744
699.898	346.971
700.155	350.46
700.413	335.024
700.67	333.967
700.927	334.607
701.184	347.167
701.441	340.967
701.698	340.013
701.956	335.404
702.213	332.626
702.47	350.716
702.727	339.149
702.984	340.857
703.241	339.879
703.498	342.012
703.755	332.479
704.012	339.737
704.269	342.437
704.526	341.931
704.783	326.558
705.04	334.844
705.297	332.058
705.554	318.349
705.811	330.782
706.068	329.892
706.324	325.452
706.581	332.218
706.838	323.984
707.095	332.553
707.352	322.28
707.609	319.404
707.865	332.344
708.122	316.244
708.379	318.743
708.636	316.896
708.892	308.109
709.149	318.154
709.406	307.062
709.662	319.813
709.919	314.154
710.176	323.334
710.432	318.34
710.689	300.158
710.946	307.544
711.202	314.258
711.459	314.297
711.715	303.487
711.972	306.933
712.228	299.9
712.485	299.217
712.741	297.819
712.998	305.244
713.254	290.092
713.511	290.897
713.767	298.9
714.024	296.315
714.231	297.667
714.488	295.437
714.745	288.064
715.002	290.77
715.259	302.103
715.516	285.236
715.773	281.523
716.029	285.021
716.286	279.125
716.543	286.288
716.8	278.494
717.057	284.701
717.314	291.31
717.57	285.498
717.827	278.107
718.084	287.083
718.341	286.482
718.597	271.832
718.854	274.781
719.111	278.662
719.367	279.075
719.624	277.152
719.881	271.724
720.137	275.156
720.394	273.422
720.65	261.932
720.907	268.693
721.164	269.037
721.42	264.528
721.677	263.583
721.933	263.323
722.19	262.296
722.446	257.748
722.703	259.063
722.959	259.671
723.216	257.645
723.472	253.622
723.728	250.848
723.985	262.578
724.241	254.196
724.498	249.377
724.754	251.983
725.01	261.655
725.267	254.347
725.523	251.946
725.779	249.766
726.036	246.659
726.292	249.639
726.548	248.142
726.804	253.046
727.06	258.219
727.317	246.917
727.573	252.147
727.829	257.834
728.085	247.549
728.341	240.667
728.597	243.196
728.854	251.982
729.11	254.494
729.366	242.522
729.622	232.585
729.878	238.251
730.134	244.658
730.39	240.383
730.646	230.977
730.902	252.007
731.158	238.976
731.414	230.985
731.622	245.662
731.878	235.47
732.135	238.539
732.391	243.089
732.648	239.239
732.904	236.97
733.161	254.861
733.417	251.935
733.673	253.454
733.93	249.061
734.186	244.06
734.443	270.432
734.699	250.558
734.955	247.102
735.211	262.554
735.468	270.988
735.724	280.702
735.98	283.196
736.237	286.763
736.493	311.075
736.749	311.003
737.005	324.091
737.261	340.405
737.518	342.104
737.774	353.288
738.03	361.036
738.286	364.884
738.542	362.8
738.798	363.054
739.054	344.213
739.31	332.469
739.566	320.436
739.822	310.765
740.078	300.692
740.334	292.943
740.59	282.239
740.846	271.922
741.102	265.245
741.358	258.919
741.614	263.152
741.87	244.52
742.126	245.348
742.382	237.109
742.638	244.161
742.893	236.838
743.149	230.648
743.405	220.033
743.661	216.777
743.917	224.618
744.172	217.663
744.428	209.46
744.684	218.772
744.94	206.789
745.195	214.877
745.451	205.905
745.707	198.502
745.962	204.848
746.218	205.933
746.474	208.068
746.729	203.501
746.985	203.605
747.241	196.727
747.496	200.033
747.752	199.482
748.007	190.898
748.263	186.519
748.518	195.029
748.774	196.833
749.029	194.967
749.275	187.567
749.531	190.739
749.787	177.209
750.043	191.917
750.299	191.895
750.555	193.891
750.811	190.72
751.067	179.704
751.323	171.243
751.579	179.886
751.835	185.719
752.09	176.729
752.346	181.06
752.602	173.629
752.858	179.012
753.114	185.916
753.37	180.077
753.625	167.273
753.881	178.533
754.137	178.675
754.393	166.703
754.648	174.617
754.904	167.479
755.16	176.055
755.415	165.558
755.671	168.81
755.927	164.093
756.182	167.479
756.438	164.15
756.693	168.517
756.949	159.681
757.205	158.118
757.46	162.628
757.716	163.892
757.971	163.384
758.227	160.157
758.482	159.362
758.738	160.221
758.993	161.724
759.248	154.221
759.504	157.806
759.759	153.76
760.015	153.076
760.27	160.877
760.525	158.075
760.781	144.888
761.036	150.968
761.291	152.354
761.547	154.493
761.802	150.562
762.057	152.091
762.313	144.393
762.568	156.779
762.823	146.898
763.078	146.406
763.333	150.816
763.589	143.993
763.844	153.806
764.099	145.054
764.354	150.653
764.609	142.176
764.864	139.942
765.119	142.252
765.374	138.984
765.629	138.447
765.884	136.979
766.139	134.988
766.394	135.351
766.649	137.638
766.882	140.256
767.137	131.885
767.393	143.541
767.648	135.047
767.904	139.571
768.159	139.332
768.415	121.506
768.67	131.417
768.926	128.969
769.181	117.865
769.436	127.239
769.692	129.826
769.947	128.253
770.203	125.198
770.458	128.076
770.713	120.514
770.968	124.889
771.224	125.121
771.479	112.26
771.734	127.227
771.99	120.689
772.245	127.423
772.5	120.199
772.755	114.898
773.01	123.711
773.265	120.931
773.521	115.25
773.776	117.619
774.031	117.121
774.286	113.05
774.541	111.669
774.796	107.749
775.051	111.469
775.306	114.849
775.561	118.997
775.816	112.389
776.071	113.515
776.326	108.213
776.581	110.898
776.836	102.812
777.091	108.03
777.346	109.146
777.601	102.853
777.856	109.538
778.111	107.745
778.365	101.365
778.62	101.357
778.875	104.479
779.13	108.385
779.385	99.3424
779.639	100.852
779.894	101.837
780.149	99.4976
780.404	100.401
780.658	100.816
780.913	99.5982
781.168	89.904
781.422	100.512
781.677	103.113
781.932	96.9884
782.186	89.387
782.441	91.2439
782.695	96.0959
782.95	91.3221
783.204	91.3494
783.459	98.3714
783.714	94.6607
783.968	81.1928
784.211	91.6638
784.466	92.1801
784.721	91.3446
784.976	85.4047
785.231	92.5775
785.486	94.7235
785.741	89.9746
785.996	85.5893
786.251	88.6507
786.506	86.1551
786.761	84.6056
787.016	92.2826
787.271	87.0788
787.526	84.1586
787.78	84.3952
788.035	79.8298
788.29	85.9926
788.545	83.0444
788.8	84.3292
789.054	79.1613
789.309	81.0672
789.564	80.5454
789.819	86.771
790.073	85.9402
790.328	83.6381
790.583	77.942
790.837	75.4816
791.092	76.3813
791.347	73.9508
791.601	76.1216
791.856	75.8947
792.11	78.0999
792.365	80.1647
792.619	79.3272
792.874	75.1425
793.128	75.3758
793.383	80.8969
793.638	78.6194
793.892	73.5031
794.146	73.9572
794.401	75.1256
794.655	72.1822
794.91	74.9672
795.164	75.8392
795.418	76.4644
795.673	70.759
795.927	72.5509
796.181	72.3867
796.436	76.05
796.69	74.663
796.944	71.3598
797.199	68.6955
797.453	72.591
797.707	68.1023
797.961	74.4188
798.216	69.0781
798.47	71.231
798.724	70.8749
798.978	68.4592
799.232	69.2558
799.486	69.6163
799.74	67.4026
799.994	69.5192
800.248	68.5782
800.503	66.1161
800.757	64.4062
801.011	60.8912
801.265	69.079
801.508	61.7612
801.762	64.1272
802.017	61.402
802.271	62.3443
802.526	65.7666
802.78	66.7523
803.035	66.2432
803.289	63.9571
803.544	63.1553
803.798	61.5931
804.052	63.9736
804.307	61.1719
804.561	64.2528
804.816	62.0053
805.07	62.5032
805.324	60.9286
805.579	59.8798
805.833	60.762
806.087	65.8624
806.341	56.2941
806.596	61.1061
806.85	55.2387
807.104	61.4441
807.358	59.2085
807.613	59.6913
807.867	60.4529
808.121	56.3922
808.375	61.5607
808.629	59.5352
808.883	53.0466
809.138	61.3273
809.392	53.0294
809.646	55.4009
809.9	54.3394
810.154	53.6021
810.408	57.2827
810.662	51.0029
810.916	55.2046
811.17	57.5143
811.424	57.2702
811.678	55.9911
811.932	55.8099
812.185	54.2279
812.439	57.7774
812.693	50.9979
812.947	53.2742
813.201	57.4995
813.455	53.273
813.709	45.8131
813.962	50.6978
814.216	61.167
814.47	50.3825
814.724	49.3532
814.977	55.133
815.231	50.468
815.485	53.4953
815.739	51.9433
815.992	53.0819
816.246	53.0887
816.499	52.9897
816.753	47.5357
817.007	50.5694
817.26	51.3357
817.514	44.5422
817.767	48.8997
818.021	51.3743
818.274	51.7938
818.528	51.037
818.781	47.7087
819.01	47.2922
819.264	49.056
819.518	43.6595
819.772	49.566
820.026	47.9341
820.28	51.4923
820.534	41.6411
820.788	45.751
821.042	49.4719
821.296	45.5699
821.549	49.0485
821.803	47.4847
822.057	45.7959
822.311	45.6594
822.565	44.419
822.819	46.319
823.073	46.0073
823.326	42.1735
823.58	48.1722
823.834	47.4143
824.088	44.683
824.341	45.66
824.595	45.6849
824.849	45.736
825.103	47.9298
825.356	47.0641
825.61	46.7906
825.864	48.751
826.117	43.4973
826.371	45.7947
826.624	41.895
826.878	45.7755
827.131	44.946
827.385	40.9234
827.638	44.6106
827.892	43.2989
828.146	43.3434
828.399	38.997
828.652	44.0365
828.906	37.8279
829.159	43.7587
829.413	41.4758
829.666	45.6714
829.919	46.4876
830.173	41.657
830.426	42.4407
830.68	42.2476
830.933	43.2869
831.186	41.453
831.439	42.4877
831.693	41.4203
831.946	43.272
832.199	42.6186
832.452	41.5821
832.706	43.1127
832.959	38.8149
833.212	43.8876
833.465	44.1344
833.718	44.1247
833.971	38.4991
834.224	35.773
834.477	44.0642
834.73	42.0912
834.984	42.7108
835.237	41.8036
835.49	45.0883
835.743	39.9894
835.996	34.1472
836.201	44.9424
836.454	43.0088
836.708	39.9176
836.961	43.4608
837.215	41.0537
837.468	42.8586
837.722	34.4308
837.975	42.9572
838.229	40.2954
838.482	38.1768
838.735	35.9925
838.989	37.1828
839.242	39.6735
839.496	40.0728
839.749	39.4569
840.002	38.8188
840.256	37.7984
840.509	42.1537
840.762	43.8652
841.015	41.1351
841.269	41.1871
841.522	39.035
841.775	36.8839
842.028	38.7593
842.281	39.1987
842.535	31.2868
842.788	33.6732
843.041	40.1641
843.294	36.3248
843.547	37.3371
843.8	38.7267
844.053	42.1487
844.306	34.7695
844.559	35.7335
844.812	36.5165
845.065	37.2989
845.318	33.7029
845.571	37.3921
845.824	34.4551
846.077	35.9264
846.33	36.5667
846.583	34.0309
846.836	37.0739
847.089	35.5112
847.342	35.4685
847.595	34.4726
847.847	38.0277
848.1	33.4541
848.353	38.6266
848.606	37.0681
848.859	40.6056
849.111	34.1721
849.364	35.1345
849.617	35.585
849.869	31.7207
850.122	31.9595
850.375	36.1461
850.627	30.9961
850.88	36.5532
851.133	35.4419
851.385	31.4602
851.638	34.4249
851.89	34.5625
852.143	33.7376
852.395	35.0521
852.648	31.6309
852.9	37.8601
853.153	35.9757
853.405	35.9196
853.645	37.0268
853.898	34.2835
854.151	35.3548
854.404	38.2214
854.657	33.2729
854.91	35.6888
855.163	32.4478
855.416	38.7413
855.669	28.1581
855.922	34.2605
856.175	34.567
856.427	30.9886
856.68	32.3422
856.933	31.0908
857.186	35.4881
857.439	36.0613
857.692	30.3459
857.944	35.4508
858.197	36.8599
858.45	33.5105
858.703	32.3233
858.955	36.1752
859.208	31.5187
859.461	31.6143
859.713	30.2465
859.966	35.1289
860.219	38.708
860.471	28.2104
860.724	34.6354
860.976	38.3039
861.229	34.5223
861.481	34.2313
861.734	36.0195
861.986	35.7212
862.239	34.7009
862.491	30.0572
862.744	27.7026
862.996	35.0432
863.249	33.09
863.501	31.3603
863.754	31.1408
864.006	38.188
864.258	30.7858
864.511	30.5105
864.763	29.0219
865.015	31.9225
865.268	29.0308
865.52	31.5185
865.772	35.0621
866.024	36.8953
866.276	32.3033
866.529	34.4623
866.781	31.7229
867.033	34.9147
867.285	31.5802
867.537	26.2293
867.789	36.0807
868.042	29.0851
868.294	31.6246
868.546	31.7448
868.798	33.4303
869.05	32.0574
869.302	27.5234
869.554	33.6262
869.806	35.6813
870.058	34.9597
870.31	26.044
870.562	34.8305
870.782	35.004
871.034	33.9847
871.287	32.4475
871.539	29.6013
871.792	34.4822
872.044	34.9195
872.297	31.2173
872.549	31.5517
872.801	33.6532
873.054	34.8729
873.306	21.2928
873.558	31.8054
873.811	31.6012
874.063	30.018
874.315	31.3068
874.568	33.2198
874.82	31.1681
875.072	34.4161
875.324	27.3184
875.577	31.1019
875.829	33.5759
876.081	27.7381
876.333	26.7085
876.585	34.3503
876.838	33.7986
877.09	26.8373
877.342	32.8965
877.594	34.5736
877.846	29.5273
878.098	26.5653
878.35	34.0431
878.602	32.1516
878.854	30.9563
879.106	23.8497
879.358	35.6152
879.61	32.6884
879.862	27.4005
880.114	29.5027
880.366	38.9211
880.618	31.8717
880.87	31.0576
881.121	28.5655
881.373	31.4465
881.625	34.267
881.877	26.2218
882.129	32.704
882.38	31.9955
882.632	28.8853
882.884	28.3192
883.136	27.2026
883.387	34.2139
883.639	30.462
883.891	32.5593
884.142	34.8621
884.394	32.4728
884.646	26.9264
884.897	31.373
885.149	31.4973
885.4	32.6205
885.652	27.2156
885.903	30.6751
886.155	31.5656
886.406	34.2702
886.658	28.7458
886.909	31.2527
887.161	30.2731
887.412	27.7729
887.664	30.6949
887.915	30.1538
888.138	31.4033
888.39	31.1209
888.642	29.8253
888.894	31.3253
889.146	30.1947
889.398	31.0725
889.65	25.3455
889.902	31.0534
890.154	31.7846
890.406	26.0847
890.657	26.1527
890.909	33.1385
891.161	30.0706
891.413	33.403
891.665	26.0354
891.916	30.5997
892.168	29.1106
892.42	26.8339
892.671	27.0858
892.923	29.9006
893.175	32.1045
893.426	24.2334
893.678	28.7391
893.93	28.6209
894.181	29.5054
894.433	25.2882
894.684	30.2959
894.936	30.949
895.188	29.6898
895.439	28.4224
895.69	28.6667
895.942	30.5628
896.193	26.2302
896.445	28.976
896.696	29.5749
896.948	28.187
897.199	28.3814
897.451	26.9588
897.702	31.0685
897.953	25.6043
898.204	25.6723
898.456	31.0903
898.707	27.2244
898.958	32.4934
899.21	27.6023
899.461	28.872
899.712	27.4869
899.963	27.3333