File: M3_270224_01.txt
#Acq. time (s)=	3
#Accumulations=	2
#Range (nm)=	520...900
#Windows=	8
#Auto scanning=	Off
#Autofocus=	Off
#AutoExposure=	Off
#Spike filter=	Multiple accum.
#Delay time (s)=	0
#Binning=	1
#Readout mode=	Signal
#DeNoise=	Off
#ICS correction=	Off
#Dark correction=	Off
#Inst. Process=	Off
#Detector temperature (°C)=	-59.98
#Instrument=	LabRAM HR Evol
#Detector=	Syncerity OE
#Objective=	x50_VIS
#Grating=	600 (500nm)
#ND Filter=	10%
#Laser=	514nm_Edge
#Hole=	199.981
#Range=	Auto
#StageXY=	Marzhauser
#StageZ=	Marzhauser
#X (µm)=	0
#Y (µm)=	0
#Z (µm)=	0
#Full time(mm:ss)=	1:32
#Project=
#Sample=
#Site=
#Title=	M3_270224
#Remark=
#Date=	06.03.2024 10:16
#Acquired=	06.03.2024 10:16:15
520.044	32
520.306	22
520.569	28
520.831	26
521.093	30
521.355	26
521.617	28
521.88	28
522.142	30
522.404	22
522.666	24
522.928	24
523.19	38
523.453	20
523.715	26
523.977	30
524.239	28
524.501	34
524.763	26
525.025	26
525.287	34
525.549	36
525.811	28
526.073	34
526.335	36
526.597	36
526.859	28
527.121	20
527.383	24
527.645	34
527.907	32
528.169	24
528.431	32
528.693	32
528.955	28
529.217	24
529.479	36
529.741	34
530.003	30
530.264	26
530.526	28
530.788	34
531.05	32
531.312	36
531.574	28
531.835	36
532.097	38
532.359	30
532.621	30
532.883	24
533.144	36
533.406	36
533.668	26
533.93	26
534.191	28
534.453	38
534.715	30
534.976	36
535.238	36
535.5	28
535.761	32
536.023	32
536.285	40
536.546	38
536.808	28
537.069	32
537.331	32
537.593	36
537.854	32
538.116	36
538.377	40
538.639	34
538.9	30
539.162	30
539.423	32
539.685	36
539.946	36
540.208	28
540.469	30
540.731	42
540.992	30
541.254	38
541.515	32
541.776	32
542.038	42
542.299	46
542.56	30
542.822	34
543.083	38
543.344	44
543.606	42
543.867	34
544.128	42
544.39	38
544.651	42
544.912	30
545.174	38
545.435	40
545.696	36
545.957	30
546.218	36
546.48	40
546.741	48
547.002	38
547.263	38
547.524	44
547.785	50
548.047	38
548.308	46
548.569	46
548.83	48
549.091	54
549.352	38
549.613	36
549.874	52
550.135	54
550.396	44
550.657	58
550.918	58
551.179	46
551.44	62
551.701	76
551.962	110
552.223	186
552.484	1876
552.745	10274
553.006	286
553.267	116
553.528	80
553.788	70
554.049	66
554.31	64
554.571	58
554.832	50
555.093	50
555.353	58
555.614	56
555.875	58
556.136	50
556.396	60
556.657	52
556.918	54
557.179	50
557.439	70
557.7	64
557.961	60
558.221	54
558.482	60
558.743	62
559.003	68
559.264	58
559.525	58
559.785	72
560.046	60
560.306	62
560.567	56
560.827	74
561.088	72
561.348	64
561.609	60
561.869	66
562.13	62
562.39	74
562.651	72
562.911	74
563.172	70
563.432	82
563.692	70
563.953	78
564.213	74
564.474	86
564.734	84
564.994	76
565.255	92
565.515	80
565.775	94
566.035	84
566.296	78
566.556	86
566.816	98
567.076	94
567.337	96
567.597	92
567.857	102
568.117	84.06
568.377	88.2077
568.637	102.109
568.898	96.8933
569.158	98.547
569.418	103.333
569.678	93.6879
569.938	102.022
570.198	104.967
570.458	103.36
570.718	102.668
570.978	118.645
571.238	113.485
571.498	112.349
571.758	125.947
572.018	125.421
572.278	127.934
572.538	138.893
572.798	135.615
573.058	152.361
573.312	162
573.573	170
573.834	192
574.095	186
574.356	228
574.617	234
574.878	258
575.139	270
575.4	270
575.661	264
575.922	262
576.183	270
576.444	268
576.705	250
576.965	226
577.226	228
577.487	212
577.748	200
578.009	206
578.27	188
578.531	190
578.791	182
579.052	186
579.313	192
579.574	182
579.835	188
580.095	192
580.356	192
580.617	192
580.878	182
581.138	188
581.399	206
581.66	202
581.92	204
582.181	218
582.442	218
582.703	204
582.963	196
583.224	216
583.484	226
583.745	224
584.006	228
584.266	234
584.527	228
584.787	236
585.048	264
585.308	252
585.569	258
585.83	278
586.09	266
586.351	244
586.611	260
586.872	270
587.132	274
587.392	280
587.653	278
587.913	258
588.174	272
588.434	272
588.695	280
588.955	282
589.215	304
589.476	314
589.736	304
589.996	306
590.257	310
590.517	336
590.777	296
591.038	296
591.298	278
591.558	298
591.818	274
592.079	272
592.339	286
592.599	264
592.859	274
593.12	260
593.38	274
593.64	258
593.9	266
594.16	262
594.42	288
594.68	268
594.941	280
595.201	264
595.461	286
595.721	292
595.981	300
596.241	304
596.501	298
596.761	318
597.021	306
597.281	302
597.541	292
597.801	286
598.061	288
598.321	284
598.581	302
598.841	280
599.101	274
599.361	312
599.62	296
599.88	288
600.14	298
600.4	302
600.66	306
600.92	294
601.18	282
601.439	296
601.699	298
601.959	294
602.219	300
602.478	300
602.738	306
602.998	288
603.258	292
603.517	318
603.777	294
604.037	314
604.296	310
604.556	306
604.816	308
605.075	306
605.335	308
605.594	320
605.854	302
606.114	300
606.373	316
606.633	306
606.892	294
607.152	322
607.411	316
607.671	304
607.93	320
608.19	340
608.449	298
608.709	320
608.968	324
609.228	328
609.487	338
609.746	324
610.006	332
610.265	326
610.524	344
610.784	342
611.043	344
611.302	322
611.562	344
611.821	324
612.08	344
612.339	342
612.599	342
612.858	342
613.117	332
613.376	356
613.635	364
613.895	360
614.154	356
614.413	356
614.672	356
614.931	364
615.19	358
615.449	366
615.709	382
615.968	376
616.227	383.139
616.486	357.463
616.745	382.892
617.004	361.723
617.263	376.526
617.522	383.867
617.781	404.339
618.04	382.652
618.299	397.213
618.557	384.063
618.816	386.113
619.075	390.614
619.334	397.432
619.593	401.685
619.852	409.966
620.111	404.223
620.37	392.459
620.628	399.184
620.887	400.975
621.146	409.563
621.373	406
621.633	392
621.893	388
622.153	414
622.413	406
622.673	396
622.932	420
623.192	424
623.452	426
623.712	410
623.972	412
624.232	444
624.492	416
624.751	430
625.011	436
625.271	434
625.531	434
625.791	422
626.05	434
626.31	432
626.57	428
626.83	428
627.089	460
627.349	420
627.609	464
627.868	444
628.128	438
628.388	424
628.647	468
628.907	474
629.167	434
629.426	460
629.686	478
629.945	484
630.205	478
630.465	468
630.724	454
630.984	484
631.243	486
631.503	480
631.762	474
632.022	500
632.281	494
632.541	462
632.8	492
633.06	496
633.319	522
633.579	504
633.838	530
634.097	504
634.357	538
634.616	534
634.876	554
635.135	538
635.394	556
635.654	572
635.913	576
636.172	584
636.431	610
636.691	676
636.95	652
637.209	714
637.469	736
637.728	758
637.987	756
638.246	754
638.505	736
638.765	716
639.024	716
639.283	700
639.542	682
639.801	680
640.06	660
640.319	640
640.578	630
640.838	642
641.097	640
641.356	630
641.615	636
641.874	620
642.133	610
642.392	642
642.651	630
642.91	644
643.169	650
643.428	646
643.687	616
643.946	616
644.205	662
644.463	678
644.722	658
644.981	642
645.24	646
645.499	650
645.758	664
646.017	658
646.275	674
646.534	676
646.793	676
647.052	670
647.31	616
647.569	668
647.828	680
648.087	680
648.345	676
648.604	688
648.863	690
649.121	708
649.38	710
649.639	702
649.897	726
650.156	704
650.415	742
650.673	740
650.932	724
651.19	756
651.449	726
651.707	734
651.966	762
652.224	694
652.483	758
652.741	772
653	752
653.258	780
653.517	782
653.775	748
654.034	808
654.292	792
654.55	788
654.809	812
655.067	806
655.326	836
655.584	838
655.842	818
656.1	812
656.359	840
656.617	874
656.875	880
657.134	856
657.392	892
657.65	912
657.908	890
658.166	896
658.425	884
658.683	916
658.941	920
659.199	918
659.457	896
659.715	928
659.973	930
660.231	906
660.49	956
660.748	916
661.006	910
661.264	932
661.522	916
661.78	926
662.038	934
662.296	920
662.554	904
662.811	920
663.069	936
663.327	936
663.585	920
663.843	916.853
664.101	907.935
664.359	919.525
664.617	917.337
664.874	903.713
665.132	921.954
665.39	922.33
665.648	935.723
665.906	925.153
666.163	897.943
666.421	907.632
666.679	901.401
666.937	901.095
667.194	914.448
667.452	915.13
667.71	908.087
667.967	913.979
668.225	926.517
668.482	917.45
668.74	919.327
668.987	918
669.245	924
669.504	942
669.763	932
670.022	930
670.281	940
670.539	920
670.798	938
671.057	900
671.316	928
671.575	936
671.833	918
672.092	932
672.351	934
672.609	924
672.868	962
673.127	928
673.385	944
673.644	942
673.903	940
674.161	978
674.42	952
674.678	972
674.937	998
675.195	948
675.454	950
675.713	984
675.971	974
676.23	952
676.488	970
676.747	972
677.005	984
677.263	968
677.522	996
677.78	984
678.039	980
678.297	956
678.556	974
678.814	1000
679.072	990
679.331	984
679.589	1006
679.847	1000
680.106	962
680.364	974
680.622	996
680.881	986
681.139	1030
681.397	1030
681.656	984
681.914	1010
682.172	1024
682.43	1030
682.688	1028
682.947	1026
683.205	1002
683.463	1004
683.721	1018
683.979	996
684.237	1052
684.495	966
684.754	994
685.012	992
685.27	1020
685.528	980
685.786	970
686.044	1006
686.302	1006
686.56	992
686.818	1016
687.076	1002
687.334	992
687.592	1004
687.85	1016
688.108	990
688.366	988
688.623	966
688.881	952
689.139	946
689.397	996
689.655	990
689.913	1004
690.171	984
690.428	930
690.686	978
690.944	998
691.202	986
691.459	968
691.717	964
691.975	946
692.233	952
692.49	968
692.748	966
693.006	966
693.263	936
693.521	938
693.779	956
694.036	994
694.294	902
694.552	930
694.809	926
695.067	956
695.324	940
695.582	936
695.839	928
696.097	936
696.354	924
696.612	950
696.869	902
697.127	932
697.384	930
697.642	904
697.899	926
698.156	926
698.414	902
698.671	882
698.928	852
699.186	872
699.443	886
699.7	856
699.958	854
700.215	876
700.472	880
700.73	878
700.987	854
701.244	892
701.501	904
701.758	874
702.016	884
702.273	890
702.53	884
702.787	886
703.044	846
703.301	860
703.558	878
703.816	846
704.073	850
704.33	834
704.587	884
704.844	874
705.101	848
705.358	834
705.615	842
705.872	872
706.129	868
706.386	842
706.643	812
706.899	812
707.156	806
707.413	820
707.67	828
707.927	840
708.184	816
708.441	856
708.697	816
708.954	818
709.211	834
709.468	810
709.725	830
709.981	812
710.238	814
710.495	810
710.751	810
711.008	802
711.265	805.931
711.521	787.826
711.778	785
712.035	798.01
712.291	773.753
712.548	786.726
712.804	778.502
713.061	751.857
713.317	765.196
713.574	775.367
713.831	750.692
714.087	762.449
714.343	753.471
714.6	743.362
714.856	754.537
715.113	741.816
715.369	745.706
715.626	749.087
715.882	735.511
716.138	730.647
716.395	729.884
716.639	722
716.897	744
717.155	696
717.412	704
717.67	694
717.927	708
718.185	714
718.443	684
718.7	720
718.958	684
719.215	670
719.473	690
719.73	706
719.988	696
720.245	652
720.503	686
720.76	674
721.018	668
721.275	650
721.532	666
721.79	634
722.047	658
722.305	672
722.562	660
722.819	676
723.077	654
723.334	614
723.591	652
723.849	650
724.106	628
724.363	628
724.621	628
724.878	604
725.135	596
725.392	642
725.65	614
725.907	626
726.164	624
726.421	630
726.678	612
726.935	614
727.193	596
727.45	598
727.707	600
727.964	612
728.221	602
728.478	586
728.735	570
728.992	572
729.249	584
729.506	578
729.763	538
730.02	572
730.277	566
730.534	566
730.791	570
731.048	554
731.305	554
731.562	540
731.819	552
732.076	546
732.333	534
732.589	536
732.846	518
733.103	570
733.36	528
733.617	506
733.873	530
734.13	536
734.387	544
734.644	540
734.901	554
735.157	544
735.414	540
735.671	530
735.927	534
736.184	554
736.441	528
736.697	538
736.954	546
737.211	548
737.467	576
737.724	554
737.98	576
738.237	564
738.493	570
738.75	572
739.006	542
739.263	556
739.519	542
739.776	522
740.032	512
740.289	534
740.545	486
740.802	494
741.058	512
741.314	504
741.571	498
741.827	496
742.083	500
742.34	492
742.596	494
742.852	480
743.109	478
743.365	478
743.621	474
743.878	462
744.134	480
744.39	454
744.646	450
744.902	464
745.159	452
745.415	430
745.671	450
745.927	450
746.183	444
746.439	430
746.695	426
746.951	460
747.207	446
747.463	430
747.719	438
747.975	434
748.231	424
748.487	420
748.743	418
748.999	440
749.255	406
749.511	440
749.767	432
750.023	410
750.279	426
750.535	422
750.791	438
751.046	436
751.302	416
751.558	408
751.814	390
752.07	402
752.325	410
752.581	414
752.837	398
753.092	388
753.348	396
753.604	396
753.859	386
754.115	366
754.371	376
754.626	380
754.882	378
755.138	368
755.393	352
755.649	404
755.904	386
756.16	376
756.415	362
756.671	376
756.926	376
757.182	374
757.437	366
757.693	360
757.948	380
758.203	370
758.459	330
758.714	344.953
758.97	350.74
759.225	347.414
759.48	353.219
759.736	343.539
759.991	356.368
760.246	357.004
760.501	343.217
760.757	330.112
761.012	344.411
761.267	340.783
761.522	325.044
761.777	335.77
762.033	321.083
762.288	328.67
762.543	323.118
762.798	321.941
763.053	326.061
763.308	319.523
763.563	310.529
763.78	324
764.037	304
764.293	308
764.55	314
764.806	302
765.062	298
765.319	310
765.575	308
765.831	286
766.088	312
766.344	306
766.6	302
766.857	280
767.113	288
767.369	290
767.625	286
767.882	280
768.138	276
768.394	284
768.65	296
768.906	278
769.163	282
769.419	262
769.675	282
769.931	280
770.187	288
770.443	266
770.699	248
770.955	260
771.211	270
771.467	278
771.723	254
771.979	240
772.235	254
772.491	262
772.747	266
773.003	244
773.259	246
773.515	254
773.771	258
774.027	244
774.283	238
774.539	258
774.795	242
775.05	240
775.306	228
775.562	234
775.818	238
776.074	242
776.329	232
776.585	228
776.841	224
777.097	224
777.352	232
777.608	232
777.864	232
778.12	212
778.375	230
778.631	210
778.886	216
779.142	214
779.398	222
779.653	202
779.909	210
780.164	222
780.42	200
780.675	218
780.931	186
781.187	194
781.442	214
781.698	192
781.953	210
782.208	198
782.464	188
782.719	208
782.975	190
783.23	172
783.485	188
783.741	192
783.996	200
784.252	198
784.507	188
784.762	186
785.017	190
785.273	192
785.528	186
785.783	192
786.038	176
786.294	166
786.549	182
786.804	188
787.059	182
787.314	190
787.57	172
787.825	164
788.08	186
788.335	186
788.59	172
788.845	152
789.1	170
789.355	172
789.61	170
789.865	160
790.12	170
790.375	164
790.63	142
790.885	162
791.14	160
791.395	160
791.65	160
791.905	156
792.16	162
792.414	148
792.669	158
792.924	162
793.179	156
793.434	142
793.689	136
793.943	150
794.198	142
794.453	142
794.708	146
794.962	138
795.217	146
795.472	138
795.726	146
795.981	138
796.236	146
796.49	138
796.745	142
796.999	136
797.254	136
797.508	150
797.763	138
798.018	134
798.272	134
798.526	128
798.781	156
799.035	134
799.29	128
799.544	138
799.799	130
800.053	138
800.307	136
800.562	134
800.816	130
801.07	128
801.325	116
801.579	122
801.833	132
802.088	124
802.342	106
802.596	118
802.85	122
803.105	126
803.359	118
803.613	110
803.867	114
804.121	112
804.375	120
804.63	122
804.884	104
805.138	108
805.392	126
805.646	112.083
805.9	111.494
806.154	106.693
806.408	102.644
806.662	109.364
806.916	104.324
807.17	97.701
807.424	110.388
807.678	114.028
807.931	102.153
808.185	96.3671
808.439	95.1952
808.693	105.161
808.947	98.7939
809.201	99.2817
809.454	97.6917
809.708	101.467
809.962	107.424
810.216	87.8706
810.469	89.6551
810.678	102
810.933	98
811.188	106
811.443	106
811.699	98
811.954	96
812.209	88
812.464	98
812.719	88
812.974	88
813.229	92
813.484	92
813.739	98
813.994	90
814.249	80
814.504	104
814.759	96
815.014	76
815.268	84
815.523	102
815.778	94
816.033	86
816.288	92
816.543	88
816.798	86
817.052	92
817.307	80
817.562	86
817.817	94
818.071	88
818.326	68
818.581	82
818.836	86
819.09	94
819.345	84
819.6	78
819.854	88
820.109	86
820.364	82
820.618	66
820.873	86
821.127	84
821.382	78
821.637	72
821.891	80
822.146	90
822.4	80
822.655	76
822.909	82
823.164	80
823.418	78
823.672	78
823.927	74
824.181	88
824.436	78
824.69	68
824.944	72
825.199	68
825.453	80
825.707	66
825.962	74
826.216	72
826.47	74
826.725	76
826.979	66
827.233	70
827.487	66
827.741	66
827.996	76
828.25	64
828.504	76
828.758	70
829.012	72
829.266	66
829.52	66
829.774	64
830.029	70
830.283	66
830.537	64
830.791	74
831.045	74
831.299	56
831.553	60
831.807	66
832.061	64
832.315	58
832.568	54
832.822	70
833.076	74
833.33	74
833.584	58
833.838	60
834.092	72
834.345	66
834.599	64
834.853	54
835.107	62
835.36	70
835.614	64
835.868	46
836.122	66
836.375	62
836.629	68
836.883	70
837.136	68
837.39	58
837.643	60
837.897	56
838.151	56
838.404	64
838.658	68
838.911	50
839.165	56
839.418	74
839.672	60
839.925	50
840.179	56
840.432	66
840.686	58
840.939	68
841.192	54
841.446	60
841.699	70
841.952	62
842.206	58
842.459	56
842.712	54
842.966	62
843.219	56
843.472	40
843.725	60
843.979	58
844.232	66
844.485	52
844.738	48
844.991	58
845.244	60
845.497	44
845.75	54
846.004	56
846.257	60
846.51	34
846.763	50
847.016	52
847.269	44
847.522	52
847.775	52
848.028	52
848.281	52
848.534	54
848.786	42
849.039	48
849.292	44
849.545	48
849.798	40
850.051	48
850.303	60
850.556	52
850.809	48
851.062	44
851.314	50
851.567	54
851.82	46
852.073	40
852.325	50.0013
852.578	50.1096
852.831	65.6794
853.083	37.617
853.336	46.376
853.588	47.96
853.841	49.0501
854.093	40.97
854.346	38.0961
854.598	49.45
854.851	43.2316
855.103	46.3894
855.356	47.2167
855.608	38.5487
855.861	44.1361
856.113	46.0073
856.366	40.5234
856.618	43.503
856.87	48.7868
857.123	41.3458
857.352	54
857.606	38
857.859	42
858.113	46
858.367	56
858.621	44
858.875	40
859.128	36
859.382	40
859.636	54
859.889	46
860.143	38
860.397	46
860.65	40
860.904	52
861.158	40
861.411	44
861.665	44
861.918	44
862.172	38
862.425	46
862.679	48
862.932	46
863.186	44
863.439	40
863.693	50
863.946	40
864.2	46
864.453	40
864.707	40
864.96	38
865.213	46
865.467	42
865.72	42
865.973	48
866.227	44
866.48	42
866.733	36
866.987	38
867.24	42
867.493	42
867.746	36
867.999	42
868.253	50
868.506	40
868.759	42
869.012	42
869.265	46
869.518	40
869.771	36
870.025	38
870.278	48
870.531	44
870.784	34
871.037	38
871.29	42
871.543	40
871.796	34
872.049	44
872.302	40
872.555	42
872.808	40
873.06	32
873.313	46
873.566	34
873.819	50
874.072	36
874.325	38
874.578	44
874.83	46
875.083	36
875.336	36
875.589	42
875.841	40
876.094	42
876.347	30
876.6	42
876.852	40
877.105	42
877.358	40
877.61	30
877.863	42
878.115	42
878.368	32
878.621	32
878.873	34
879.126	36
879.378	36
879.631	36
879.883	46
880.136	42
880.388	34
880.641	40
880.893	44
881.145	36
881.398	38
881.65	32
881.902	42
882.155	38
882.407	36
882.659	28
882.912	24
883.164	38
883.416	38
883.669	30
883.921	30
884.173	34
884.425	40
884.677	38
884.93	32
885.182	40
885.434	50
885.686	42
885.938	34
886.19	36
886.442	40
886.694	34
886.946	34
887.198	38
887.45	44
887.702	44
887.954	30
888.206	34
888.458	38
888.71	28
888.962	34
889.214	26
889.466	26
889.718	40
889.969	44
890.221	26
890.473	36
890.725	32
890.977	38
891.228	30
891.48	24
891.732	28
891.983	34
892.235	34
892.487	34
892.738	30
892.99	30
893.242	32
893.493	32
893.745	28
893.996	34
894.248	36
894.5	28
894.751	24
895.003	30
895.254	34
895.505	38
895.757	22
896.008	30
896.26	32
896.511	40
896.763	28
897.014	24
897.265	32
897.517	26
897.768	28
898.019	28
898.27	36
898.522	32
898.773	34
899.024	16
899.275	34
899.527	34
899.778	32
899.979	26