File: M4_140224_01.txt
#Acq. time (s)=	2
#Accumulations=	3
#Range (nm)=	520...900
#Windows=	24
#Auto scanning=	On
#Autofocus=	Off
#AutoExposure=	Off
#Spike filter=	Multiple accum.
#Delay time (s)=	0
#Binning=	1
#Readout mode=	Signal
#DeNoise=	Off
#ICS correction=	Off
#Dark correction=	Off
#Inst. Process=	Off
#Detector temperature (°C)=	-59.98
#Instrument=	LabRAM HR Evol
#Detector=	Syncerity OE
#Objective=	x50_VIS
#Grating=	600 (500nm)
#ND Filter=	10%
#Laser=	514nm_Edge
#Hole=	199.981
#Range=	Auto
#StageXY=	Marzhauser
#StageZ=	Marzhauser
#X (µm)=	3020.4
#Y (µm)=	819.6
#Z (µm)=	60.3
#Full time(mm:ss)=	3:03
#Project=
#Sample=
#Site=
#Title=	M4_140224
#Remark=
#Date=	19.02.2024 14:21
#Acquired=	19.02.2024 14:21:13
520.013	41.9581
520.274	41.8976
520.536	37.9922
520.797	39.7056
521.059	39.5663
521.32	37.131
521.582	36.9125
521.843	42.2734
522.105	40.6765
522.366	38.9928
522.628	39.9429
522.889	44.9242
523.15	43.0596
523.412	38.1229
523.673	40.6153
523.935	43.6993
524.196	42.2639
524.457	37.5174
524.719	37.6527
524.98	43.4763
525.241	37.005
525.503	40.6698
525.764	42.9215
526.025	40.4537
526.286	38.3012
526.548	36.6039
526.809	39.7137
527.07	42.2591
527.331	38.6671
527.593	37.7664
527.854	42.5563
528.115	40.1254
528.376	40.857
528.637	39.5394
528.898	41.0818
529.16	39.7191
529.421	41.4628
529.682	39.7821
529.943	39.5258
530.204	40.7109
530.465	43.2458
530.726	41.2866
530.987	41.7566
531.248	37.7654
531.509	37.4005
531.77	42.2753
532.031	47.2658
532.292	40.8008
532.553	45.7868
532.814	46.3945
533.075	42.5291
533.336	42.6398
533.597	44.254
533.858	48.5055
534.119	49.987
534.38	63.2388
534.641	71.7712
534.901	78.1683
535.162	78.068
535.423	71.5719
535.684	65.2304
535.945	59.7275
536.205	52.0936
536.466	48.8824
536.727	55.5035
536.988	51.9092
537.248	44.306
537.509	47.526
537.77	47.1584
537.987	49.2754
538.249	52.1855
538.51	48.0316
538.771	53.06
539.032	49.8581
539.293	45.171
539.554	45.0345
539.815	47.285
540.076	44.7682
540.337	44.713
540.598	47.7818
540.859	46.5036
541.12	53.3117
541.381	49.2462
541.642	48.5964
541.903	55.7527
542.164	54.7266
542.425	57.104
542.686	62.4263
542.947	52.7983
543.208	54.8439
543.469	47.6284
543.73	56.6781
543.991	58.7627
544.252	55.1446
544.513	56.059
544.773	64.0751
545.034	58.5468
545.295	55.8055
545.556	64.6711
545.817	59.4163
546.077	62.3147
546.338	55.7142
546.599	62.6008
546.86	63.5785
547.12	62.8825
547.381	65.6622
547.642	60.9707
547.903	63.8021
548.163	65.6572
548.424	70.4098
548.685	71.1359
548.945	65.2601
549.206	62.7461
549.467	67.4407
549.727	71.8187
549.988	75.4446
550.248	67.7061
550.509	73.4103
550.769	80.8142
551.03	82.3275
551.291	79.1506
551.551	92.5296
551.812	101.378
552.072	120.531
552.332	239.932
552.593	5160.45
552.853	874.128
553.114	149.697
553.374	109.34
553.635	97.5804
553.895	99.0529
554.155	92.2825
554.416	94.5157
554.676	89.6464
554.937	92.2999
555.197	92.5492
555.457	92.5012
555.686	96.9074
555.947	94.7591
556.207	95.3286
556.468	89.721
556.729	101.442
556.99	104.56
557.25	95.316
557.511	99.6978
557.772	99.0289
558.032	99.7425
558.293	108.444
558.554	104.747
558.814	113.802
559.075	104.14
559.336	110.283
559.596	112.08
559.857	112.84
560.117	115.98
560.378	117.358
560.638	117.868
560.899	118.175
561.159	121.544
561.42	122.455
561.68	123.062
561.941	136.923
562.201	126.537
562.462	132.584
562.722	134.598
562.983	132.008
563.243	132.343
563.504	136.635
563.764	139.826
564.024	140.956
564.285	140.416
564.545	152.152
564.805	144.937
565.066	150.141
565.326	152.373
565.586	156.79
565.847	158.291
566.107	158.46
566.367	160.476
566.627	164.865
566.888	164.361
567.148	172.585
567.408	175.661
567.668	176.936
567.928	172.401
568.189	170.7
568.449	180.358
568.709	179.386
568.969	183.45
569.229	183.22
569.489	194.622
569.749	201.612
570.009	200.296
570.269	206.778
570.53	206.282
570.79	217.312
571.05	223.714
571.31	231.341
571.57	235.573
571.83	246.446
572.09	269.111
572.349	273.931
572.609	292.709
572.869	298.472
573.129	325.685
573.368	339.858
573.629	373.379
573.889	375.091
574.15	416.849
574.41	448.904
574.67	476.517
574.931	525.286
575.191	557.54
575.451	582.172
575.711	611.687
575.972	598.967
576.232	575.956
576.492	583.53
576.752	545.526
577.013	504.7
577.273	491.958
577.533	455.293
577.793	442.084
578.053	431.811
578.313	409.36
578.574	405.319
578.834	385.046
579.094	373.686
579.354	391.426
579.614	383.473
579.874	383.294
580.134	384.175
580.394	381.024
580.654	382.742
580.914	390.529
581.174	390.919
581.434	382.967
581.694	399.017
581.954	402.636
582.214	404.062
582.474	413.28
582.734	407.612
582.994	418.553
583.254	435.418
583.514	437.343
583.773	434.853
584.033	438.244
584.293	462.161
584.553	457.179
584.813	472.679
585.073	473.993
585.332	489.035
585.592	498.805
585.852	498.659
586.112	502.76
586.371	508.874
586.631	510.889
586.891	517.09
587.151	529.519
587.41	535.513
587.67	532.683
587.93	529.305
588.189	533.733
588.449	535.154
588.709	537.103
588.968	551.565
589.228	559.155
589.487	561.278
589.747	558.855
590.006	556.94
590.266	549.194
590.525	559.277
590.785	542.039
591.036	553.787
591.296	544.94
591.556	531.224
591.816	542.779
592.076	534.883
592.336	538.953
592.596	515.621
592.856	547.743
593.116	539.394
593.376	544.319
593.635	547.79
593.895	542.069
594.155	537.059
594.415	556.277
594.675	554.411
594.935	564.723
595.194	552.729
595.454	569.414
595.714	588.72
595.974	586.475
596.233	578.808
596.493	590.304
596.753	601.052
597.012	623.85
597.272	620.413
597.532	620.836
597.791	631.176
598.051	622.199
598.311	628.832
598.57	606.671
598.83	620.991
599.089	621.554
599.349	631.387
599.609	620.991
599.868	628.03
600.128	623.884
600.387	634.43
600.647	614.798
600.906	632.716
601.166	623.403
601.425	626.342
601.685	632.52
601.944	633.53
602.203	631.019
602.463	636.897
602.722	633.723
602.982	641.193
603.241	647.618
603.5	629.797
603.76	648.06
604.019	653.618
604.278	643.214
604.538	648.155
604.797	652.501
605.056	673.346
605.315	642.817
605.575	647.494
605.834	647.257
606.093	663.011
606.352	649.231
606.611	637.155
606.871	648.095
607.13	648.052
607.389	651.347
607.648	655.097
607.907	646.749
608.166	650.455
608.425	664.757
608.664	659.215
608.924	680.843
609.183	683.132
609.443	686.967
609.702	672.328
609.962	689.427
610.221	698.828
610.481	680.908
610.74	687.122
611	703.032
611.259	703.367
611.518	682.254
611.778	697.805
612.037	708.487
612.297	694.862
612.556	713.254
612.815	702.826
613.075	714.84
613.334	711.876
613.594	730.328
613.853	733.038
614.112	737.896
614.371	743.462
614.631	754.172
614.89	732.104
615.149	746.101
615.408	755.766
615.668	767.945
615.927	760.042
616.186	759.774
616.445	776.546
616.704	766.942
616.964	791.06
617.223	792.866
617.482	788.853
617.741	794.735
618	805.241
618.259	815.267
618.518	814.158
618.777	814.271
619.036	818.927
619.295	806.223
619.554	824.086
619.813	842.96
620.072	832.353
620.331	842.168
620.59	827.664
620.849	844.28
621.108	822.847
621.367	837.896
621.626	847.615
621.885	852.218
622.144	848.204
622.403	855.939
622.661	837.633
622.92	855.689
623.179	838.182
623.438	848.437
623.697	838.982
623.956	856.033
624.214	854.788
624.473	858.421
624.732	854.447
624.99	868.686
625.249	858.285
625.508	867.818
625.767	860.64
626.025	877.325
626.249	865.383
626.508	879.208
626.767	881.095
627.026	895.559
627.285	879.913
627.544	890.081
627.803	874.418
628.062	873.424
628.321	892.091
628.58	896.222
628.839	896.587
629.098	892.595
629.357	896.926
629.616	900.138
629.875	899.099
630.134	908.411
630.393	920.485
630.652	907.905
630.911	935.234
631.17	920.306
631.429	896.447
631.688	907.791
631.947	926.753
632.206	933.444
632.464	947.301
632.723	952.312
632.982	960.607
633.241	948.275
633.5	947.611
633.758	977.758
634.017	977.425
634.276	974.704
634.535	975.648
634.793	1000.77
635.052	985.468
635.311	1011.77
635.57	1027.94
635.828	1034.36
636.087	1029.25
636.345	1054.98
636.604	1091.3
636.863	1130.18
637.121	1161.06
637.38	1226.53
637.638	1263.89
637.897	1288.96
638.156	1287.98
638.414	1294.37
638.673	1267.62
638.931	1250.87
639.19	1225.14
639.448	1205.78
639.706	1183.46
639.965	1161.97
640.223	1155.11
640.482	1142.05
640.74	1148.8
640.999	1129.6
641.257	1130.76
641.515	1096.28
641.774	1122.14
642.032	1126.24
642.29	1092.3
642.549	1112.06
642.807	1120.77
643.065	1115.38
643.323	1103.42
643.582	1118.64
643.84	1128.24
644.053	1127.23
644.312	1147.24
644.57	1124
644.829	1140.39
645.088	1155.67
645.346	1145.45
645.605	1148.22
645.864	1154.87
646.122	1136.99
646.381	1145.51
646.639	1145.08
646.898	1152.06
647.157	1157.27
647.415	1148.54
647.674	1145.93
647.932	1172.3
648.191	1171.03
648.449	1172.3
648.708	1203.38
648.966	1182.43
649.225	1189.13
649.483	1192.51
649.742	1223.38
650	1205.38
650.258	1198.6
650.517	1221.91
650.775	1237.36
651.034	1228.29
651.292	1255.34
651.55	1244.28
651.809	1240.18
652.067	1223.07
652.325	1244.29
652.583	1244.01
652.842	1246.68
653.1	1247.08
653.358	1260.44
653.616	1258.11
653.875	1265.19
654.133	1250.6
654.391	1281.81
654.649	1286.08
654.907	1317.19
655.165	1307.45
655.424	1328.09
655.682	1342.16
655.94	1344.32
656.198	1349.75
656.456	1366.04
656.714	1387.74
656.972	1383.37
657.23	1385.59
657.488	1400.95
657.746	1411.65
658.004	1417.29
658.262	1418.8
658.52	1439.91
658.778	1434.99
659.036	1435.16
659.294	1443.47
659.552	1454.81
659.809	1436.97
660.067	1428.82
660.325	1411.61
660.583	1429.11
660.841	1448.75
661.099	1428.84
661.356	1449.82
661.583	1448.22
661.842	1451.32
662.1	1427.41
662.358	1452.73
662.616	1435.74
662.875	1444.44
663.133	1442.31
663.391	1447.72
663.649	1431.38
663.907	1455.21
664.166	1433.38
664.424	1434.93
664.682	1425.11
664.94	1443.92
665.198	1441.98
665.456	1436.35
665.714	1405.93
665.972	1429.94
666.23	1434.7
666.488	1425.64
666.746	1453.9
667.004	1443.29
667.262	1394.55
667.52	1409.54
667.778	1407.5
668.036	1404.86
668.294	1407.92
668.552	1419.89
668.81	1432.41
669.068	1430.55
669.326	1393.34
669.584	1412.48
669.842	1400.79
670.099	1416.21
670.357	1407.5
670.615	1391.01
670.873	1405.15
671.131	1405.91
671.388	1390.34
671.646	1393.27
671.904	1406.6
672.162	1409.59
672.419	1410.52
672.677	1405.04
672.935	1405.62
673.192	1428.89
673.45	1438.05
673.708	1408.89
673.965	1419.13
674.223	1439.09
674.481	1432.13
674.738	1451.28
674.996	1455.95
675.253	1459.54
675.511	1451.02
675.768	1451.59
676.026	1462.54
676.283	1472.76
676.541	1446.25
676.798	1472.18
677.056	1447.19
677.313	1479.65
677.571	1469.18
677.828	1484.59
678.085	1487.32
678.343	1440.28
678.6	1458.37
678.857	1430.85
679.083	1471.73
679.341	1475.85
679.599	1455.35
679.857	1466.59
680.114	1470.36
680.372	1454.63
680.63	1471.67
680.888	1453.74
681.146	1483.35
681.403	1491.53
681.661	1484.18
681.919	1482.37
682.176	1506.18
682.434	1477.18
682.692	1509.81
682.949	1503.51
683.207	1497.86
683.465	1478.02
683.722	1512.45
683.98	1479.23
684.237	1488.13
684.495	1512.7
684.753	1465.5
685.01	1478.09
685.268	1466.47
685.525	1454.94
685.783	1454.5
686.04	1433.57
686.298	1436.42
686.555	1427.3
686.813	1462.43
687.07	1467.36
687.327	1443.56
687.585	1449.97
687.842	1451.25
688.1	1437.19
688.357	1423.91
688.614	1425.92
688.872	1414.96
689.129	1434.52
689.386	1421.74
689.643	1438.13
689.901	1419.13
690.158	1426.6
690.415	1422.22
690.672	1433.44
690.93	1410.67
691.187	1406.55
691.444	1404.48
691.701	1395.77
691.958	1392.84
692.216	1389.2
692.473	1378.58
692.73	1382.7
692.987	1375.8
693.244	1378.25
693.501	1372.47
693.758	1369
694.015	1370.77
694.272	1368.06
694.529	1361.86
694.786	1363.29
695.043	1352.72
695.3	1340
695.557	1355.13
695.814	1355.86
696.071	1336.09
696.328	1347.05
696.585	1348.7
696.81	1349.72
697.068	1350.34
697.325	1335.81
697.582	1300.03
697.84	1305.84
698.097	1333.17
698.354	1320.56
698.612	1306.2
698.869	1294.06
699.126	1298.24
699.384	1297.53
699.641	1264.28
699.898	1278.02
700.155	1251.62
700.413	1278.12
700.67	1261.47
700.927	1253.49
701.184	1265.88
701.441	1274.03
701.698	1264.88
701.956	1267.76
702.213	1278.8
702.47	1276.74
702.727	1271.3
702.984	1270.27
703.241	1269.06
703.498	1259.3
703.755	1257.56
704.012	1251.98
704.269	1246.63
704.526	1276.06
704.783	1255.18
705.04	1248.61
705.297	1224.12
705.554	1250.68
705.811	1215.41
706.068	1225.52
706.324	1215.92
706.581	1214.68
706.838	1209.61
707.095	1205.97
707.352	1184.28
707.609	1195.45
707.865	1189.93
708.122	1193.01
708.379	1187.83
708.636	1193.14
708.892	1181.84
709.149	1173.31
709.406	1201.98
709.662	1160.79
709.919	1177.23
710.176	1181.57
710.432	1183.19
710.689	1152.97
710.946	1173.32
711.202	1167.33
711.459	1165.32
711.715	1143.37
711.972	1148.28
712.228	1128.32
712.485	1125.36
712.741	1124.18
712.998	1128.84
713.254	1136.94
713.511	1135.09
713.767	1112.75
714.024	1112.79
714.231	1109.14
714.488	1103.62
714.745	1090.67
715.002	1097.5
715.259	1079.21
715.516	1084.97
715.773	1075.63
716.029	1100.98
716.286	1077.43
716.543	1080.28
716.8	1075.32
717.057	1100.31
717.314	1071.41
717.57	1086.35
717.827	1075.05
718.084	1080.2
718.341	1090.54
718.597	1065.92
718.854	1071.36
719.111	1064.95
719.367	1071.46
719.624	1065.48
719.881	1064.53
720.137	1051.37
720.394	1057.41
720.65	1046.92
720.907	1064.03
721.164	1069.98
721.42	1059
721.677	1051.03
721.933	1049.84
722.19	1031.77
722.446	1049.83
722.703	1048.56
722.959	1066.1
723.216	1040.06
723.472	1046.84
723.728	1060.91
723.985	1056.07
724.241	1068.9
724.498	1084.09
724.754	1065.33
725.01	1081.82
725.267	1077.64
725.523	1085.88
725.779	1088.8
726.036	1073.71
726.292	1098.24
726.548	1102.63
726.804	1120.27
727.06	1110.4
727.317	1109.57
727.573	1114.1
727.829	1136.85
728.085	1083.59
728.341	1126.1
728.597	1127.29
728.854	1105.86
729.11	1133.93
729.366	1128.4
729.622	1126.35
729.878	1118.64
730.134	1169.52
730.39	1144.86
730.646	1171.34
730.902	1157.87
731.158	1170.61
731.414	1187.17
731.622	1199.15
731.878	1211.83
732.135	1205.25
732.391	1226.47
732.648	1257.36
732.904	1270.64
733.161	1285.56
733.417	1317.75
733.673	1353.91
733.93	1410.66
734.186	1463.17
734.443	1512.04
734.699	1582.78
734.955	1654.75
735.211	1743.13
735.468	1868.3
735.724	1958.51
735.98	2086.29
736.237	2238.37
736.493	2394.49
736.749	2563.51
737.005	2753.51
737.261	2958.58
737.518	3168.94
737.774	3321.05
738.03	3439.58
738.286	3503.08
738.542	3503.57
738.798	3437.4
739.054	3277.36
739.31	3135.35
739.566	2988.18
739.822	2773.9
740.078	2603
740.334	2417.91
740.59	2265.49
740.846	2121.11
741.102	1994.28
741.358	1872.23
741.614	1801.82
741.87	1718.81
742.126	1635.96
742.382	1563.88
742.638	1519.15
742.893	1436.27
743.149	1416.67
743.405	1350.33
743.661	1320.46
743.917	1280.78
744.172	1255.1
744.428	1221.38
744.684	1174.92
744.94	1170.4
745.195	1145.61
745.451	1133.32
745.707	1103.06
745.962	1111.69
746.218	1066.4
746.474	1063.05
746.729	1053.89
746.985	1039.08
747.241	1029.37
747.496	1025.77
747.752	989.2
748.007	996.685
748.263	994.39
748.518	971.657
748.774	985.593
749.029	972.47
749.275	949.889
749.531	963.879
749.787	943.281
750.043	954.033
750.299	943.327
750.555	912.607
750.811	909.743
751.067	901.615
751.323	919.626
751.579	908.496
751.835	890.23
752.09	899.347
752.346	882.191
752.602	892.667
752.858	882.892
753.114	880.897
753.37	856.361
753.625	860.742
753.881	847.482
754.137	873.656
754.393	849.553
754.648	845.498
754.904	845.618
755.16	847.455
755.415	827.839
755.671	834.221
755.927	826.702
756.182	835.194
756.438	812.602
756.693	831.075
756.949	814.336
757.205	801.644
757.46	790.33
757.716	814.024
757.971	780.028
758.227	802.627
758.482	773.571
758.738	777.334
758.993	785.858
759.248	759.427
759.504	777.187
759.759	765.054
760.015	764.224
760.27	769.865
760.525	766.896
760.781	756.264
761.036	721.048
761.291	734.852
761.547	749.862
761.802	747.137
762.057	745.994
762.313	737.929
762.568	739.351
762.823	731.289
763.078	729.111
763.333	722.168
763.589	721.107
763.844	710.855
764.099	712.188
764.354	703.142
764.609	703.23
764.864	695.61
765.119	705.473
765.374	695.781
765.629	708.525
765.884	701.117
766.139	705.729
766.394	706.857
766.649	692.896
766.882	692.248
767.137	668.859
767.393	660.224
767.648	673.934
767.904	667.115
768.159	660.82
768.415	656.862
768.67	643.464
768.926	635.296
769.181	617.829
769.436	623.194
769.692	619.199
769.947	598.726
770.203	582.451
770.458	589.582
770.713	590.011
770.968	573.375
771.224	578.491
771.479	564.372
771.734	547.385
771.99	562.253
772.245	558.865
772.5	543.604
772.755	531.992
773.01	545.246
773.265	527.368
773.521	526.669
773.776	524.484
774.031	497.063
774.286	519.614
774.541	504.181
774.796	483.619
775.051	488.729
775.306	494.743
775.561	492.319
775.816	481.813
776.071	479.049
776.326	473.594
776.581	469.682
776.836	460.309
777.091	451.192
777.346	457.177
777.601	449.162
777.856	448.566
778.111	437.041
778.365	446.473
778.62	432.65
778.875	426.006
779.13	433.422
779.385	426.071
779.639	429.419
779.894	427.231
780.149	427.442
780.404	428.236
780.658	412.805
780.913	413.643
781.168	398.354
781.422	405.177
781.677	395.273
781.932	385.552
782.186	389.438
782.441	392.158
782.695	376.491
782.95	393.517
783.204	387.076
783.459	374.856
783.714	366.406
783.968	369.872
784.211	361.828
784.466	354.406
784.721	373.791
784.976	360.481
785.231	355.687
785.486	359.105
785.741	360.089
785.996	357.877
786.251	344.331
786.506	353.588
786.761	340.07
787.016	333.293
787.271	344.377
787.526	333.088
787.78	336.027
788.035	334.329
788.29	332.533
788.545	332.469
788.8	329.04
789.054	313.549
789.309	334.711
789.564	329.566
789.819	316.351
790.073	316.717
790.328	315.927
790.583	314.615
790.837	302.559
791.092	311.695
791.347	309.13
791.601	297.392
791.856	311.984
792.11	298.271
792.365	307.464
792.619	300.423
792.874	296.727
793.128	291.779
793.383	293.159
793.638	281.697
793.892	293.998
794.146	298.232
794.401	294.833
794.655	279.796
794.91	288.9
795.164	280.314
795.418	274.799
795.673	281.045
795.927	277.029
796.181	281.918
796.436	276.293
796.69	275.477
796.944	274.062
797.199	272.279
797.453	263.617
797.707	260.828
797.961	267.204
798.216	267.731
798.47	263.557
798.724	259.184
798.978	260.124
799.232	257.681
799.486	251.208
799.74	251.403
799.994	248.511
800.248	247.017
800.503	243.253
800.757	245.826
801.011	235.835
801.265	234.922
801.508	229.754
801.762	231.379
802.017	232.461
802.271	219.492
802.526	223.867
802.78	233.623
803.035	226.613
803.289	215.113
803.544	221.68
803.798	229.552
804.052	220.006
804.307	228.22
804.561	220.197
804.816	220.221
805.07	213.448
805.324	208.368
805.579	205.597
805.833	209.549
806.087	203.377
806.341	190.881
806.596	204.342
806.85	202.43
807.104	196.588
807.358	204.575
807.613	205.344
807.867	198.171
808.121	199.449
808.375	196.991
808.629	201.032
808.883	198.964
809.138	199.936
809.392	200.081
809.646	197.659
809.9	194.106
810.154	180.235
810.408	195.988
810.662	199.275
810.916	187.062
811.17	188.299
811.424	190.271
811.678	188.62
811.932	187.733
812.185	183.055
812.439	192.304
812.693	186.789
812.947	181.781
813.201	182.941
813.455	183.213
813.709	174.041
813.962	179.488
814.216	175.424
814.47	176.404
814.724	164.923
814.977	176.169
815.231	174.835
815.485	170.968
815.739	166.814
815.992	159.157
816.246	158.883
816.499	160.836
816.753	155.113
817.007	162.358
817.26	153.731
817.514	163.432
817.767	156.928
818.021	155.701
818.274	156.017
818.528	154.083
818.781	146.32
819.01	152.57
819.264	142.752
819.518	153.588
819.772	147.657
820.026	138.531
820.28	136.333
820.534	142.325
820.788	136.159
821.042	137.544
821.296	137.58
821.549	134.298
821.803	139.156
822.057	133.903
822.311	141.904
822.565	144.508
822.819	138.329
823.073	139.742
823.326	135.227
823.58	128.667
823.834	131.273
824.088	132.649
824.341	133.698
824.595	127.232
824.849	128.221
825.103	124.347
825.356	123.024
825.61	125.162
825.864	116.782
826.117	123.508
826.371	119.676
826.624	123.83
826.878	121.316
827.131	119.79
827.385	120.718
827.638	121.844
827.892	121.643
828.146	119.603
828.399	114.911
828.652	119.502
828.906	115.753
829.159	117.021
829.413	117.362
829.666	116.245
829.919	115.673
830.173	109.729
830.426	112.392
830.68	116.413
830.933	113.129
831.186	105.749
831.439	107.008
831.693	116.175
831.946	105.485
832.199	107.604
832.452	113.912
832.706	112.137
832.959	110.144
833.212	105.412
833.465	105.084
833.718	104.075
833.971	106.758
834.224	102.837
834.477	113.634
834.73	97.7788
834.984	102.848
835.237	104.168
835.49	107.121
835.743	107.937
835.996	97.2398
836.201	97.093
836.454	103.001
836.708	101.075
836.961	99.9637
837.215	90.7755
837.468	94.9462
837.722	97.5308
837.975	92.6549
838.229	100.271
838.482	98.6427
838.735	101.868
838.989	94.7455
839.242	96.465
839.496	99.7538
839.749	96.4909
840.002	97.2059
840.256	99.073
840.509	97.0746
840.762	90.182
841.015	94.1951
841.269	90.6925
841.522	93.7371
841.775	92.1886
842.028	93.6727
842.281	97.1488
842.535	101.873
842.788	95.9976
843.041	87.7592
843.294	94.659
843.547	86.8668
843.8	97.2532
844.053	88.9886
844.306	82.7329
844.559	90.3541
844.812	90.0269
845.065	83.766
845.318	87.9398
845.571	88.5076
845.824	85.809
846.077	78.8415
846.33	87.4928
846.583	90.7318
846.836	92.3655
847.089	88.2389
847.342	86.0442
847.595	87.151
847.847	83.7406
848.1	90.3551
848.353	85.9427
848.606	84.7612
848.859	79.8122
849.111	85.8953
849.364	86.1753
849.617	76.9895
849.869	81.3175
850.122	86.8889
850.375	80.8328
850.627	77.0666
850.88	82.8542
851.133	82.4775
851.385	86.5813
851.638	80.883
851.89	84.1773
852.143	83.0204
852.395	83.409
852.648	75.6308
852.9	79.2943
853.153	84.9142
853.405	80.1949
853.645	77.3651
853.898	72.4883
854.151	82.0762
854.404	79.0093
854.657	75.1854
854.91	73.7414
855.163	81.611
855.416	74.4821
855.669	70.7144
855.922	74.6484
856.175	75.0223
856.427	71.251
856.68	72.3089
856.933	72.8021
857.186	71.7995
857.439	71.0059
857.692	74.8976
857.944	72.7631
858.197	75.5701
858.45	68.0277
858.703	73.338
858.955	72.6911
859.208	71.4455
859.461	69.4516
859.713	74.5932
859.966	69.4187
860.219	73.5679
860.471	66.9637
860.724	66.0085
860.976	73.8665
861.229	65.3515
861.481	66.5833
861.734	76.7163
861.986	64.9958
862.239	64.6217
862.491	69.1483
862.744	64.5585
862.996	64.2633
863.249	67.76
863.501	70.0289
863.754	70.0017
864.006	69.2763
864.258	66.2047
864.511	70.5461
864.763	64.94
865.015	73.5737
865.268	61.8405
865.52	70.5966
865.772	67.6472
866.024	67.7908
866.276	67.3128
866.529	66.4022
866.781	66.5207
867.033	64.7203
867.285	64.0068
867.537	63.2266
867.789	64.5564
868.042	67.2585
868.294	67.2361
868.546	63.3718
868.798	62.2424
869.05	62.094
869.302	62.8254
869.554	61.5768
869.806	67.0214
870.058	59.8826
870.31	64.5317
870.562	56.6003
870.782	62.0767
871.034	63.3134
871.287	58.6729
871.539	64.7374
871.792	63.7317
872.044	59.275
872.297	62.7869
872.549	63.951
872.801	65.7753
873.054	63.2602
873.306	62.1237
873.558	59.66
873.811	59.0478
874.063	59.7463
874.315	62.4094
874.568	54.7308
874.82	59.7357
875.072	60.3942
875.324	57.6249
875.577	61.5501
875.829	62.7573
876.081	54.7406
876.333	53.7064
876.585	66.624
876.838	59.4065
877.09	60.6311
877.342	54.751
877.594	61.3294
877.846	57.6211
878.098	56.2857
878.35	53.2398
878.602	58.4956
878.854	59.145
879.106	51.8624
879.358	52.6159
879.61	57.1545
879.862	58.2392
880.114	54.2592
880.366	55.3278
880.618	56.8896
880.87	55.7878
881.121	48.7743
881.373	61.3793
881.625	54.9125
881.877	50.4875
882.129	57.4573
882.38	58.3414
882.632	54.2449
882.884	53.848
883.136	55.0272
883.387	53.7486
883.639	53.6843
883.891	52.7949
884.142	53.9604
884.394	58.9451
884.646	56.3769
884.897	53.536
885.149	50.9764
885.4	51.4901
885.652	54.8192
885.903	52.2767
886.155	53.7179
886.406	49.2686
886.658	51.1371
886.909	53.9998
887.161	53.6891
887.412	51.9075
887.664	50.7745
887.915	53.7392
888.138	49.3272
888.39	51.9146
888.642	50.1614
888.894	44.0077
889.146	49.335
889.398	46.021
889.65	50.5766
889.902	54.415
890.154	50.6028
890.406	54.8092
890.657	53.9077
890.909	50.4752
891.161	51.0934
891.413	47.5533
891.665	47.9403
891.916	45.9291
892.168	49.3127
892.42	43.2176
892.671	49.5455
892.923	48.8841
893.175	50.2174
893.426	46.7592
893.678	49.1006
893.93	47.9228
894.181	47.2627
894.433	48.1864
894.684	44.9448
894.936	49.7703
895.188	48.3102
895.439	44.3274
895.69	45.605
895.942	42.6051
896.193	46.7774
896.445	50.1737
896.696	49.4726
896.948	45.6155
897.199	45.4246
897.451	48.6077
897.702	43.9209
897.953	47.9881
898.204	45.4559
898.456	47.793
898.707	42.467
898.958	49.8991
899.21	46.6256
899.461	48.5216
899.712	48.3703
899.963	45.3333