File: M5_140224_01.txt
#Acq. time (s)=	2
#Accumulations=	3
#Range (nm)=	520...900
#Windows=	24
#Auto scanning=	On
#Autofocus=	Off
#AutoExposure=	Off
#Spike filter=	Multiple accum.
#Delay time (s)=	0
#Binning=	1
#Readout mode=	Signal
#DeNoise=	Off
#ICS correction=	Off
#Dark correction=	Off
#Inst. Process=	Off
#Detector temperature (°C)=	-59.98
#Instrument=	LabRAM HR Evol
#Detector=	Syncerity OE
#Objective=	x50_VIS
#Grating=	600 (500nm)
#ND Filter=	10%
#Laser=	514nm_Edge
#Hole=	199.981
#Range=	Auto
#StageXY=	Marzhauser
#StageZ=	Marzhauser
#X (µm)=	14714.6
#Y (µm)=	2789.2
#Z (µm)=	-16.6
#Full time(mm:ss)=	3:04
#Project=
#Sample=
#Site=
#Title=	M5_140224
#Remark=
#Date=	19.02.2024 14:27
#Acquired=	19.02.2024 14:27:01
520.013	29.1796
520.274	29.324
520.536	27.4771
520.797	26.7817
521.059	28.9959
521.32	28.8393
521.582	28.4529
521.843	31.8264
522.105	27.1639
522.366	27.175
522.628	28.7054
522.889	26.8565
523.15	29.79
523.412	28.1467
523.673	28.4263
523.935	30.959
524.196	30.1679
524.457	26.7686
524.719	29.5848
524.98	31.4934
525.241	30.3603
525.503	26.9984
525.764	31.0917
526.025	29.0776
526.286	26.0682
526.548	28.6449
526.809	28.9797
527.07	30.3236
527.331	26.5828
527.593	27.155
527.854	30.4553
528.115	30.9422
528.376	23.4258
528.637	26.6134
528.898	31.4124
529.16	29.1204
529.421	20.9462
529.682	30.812
529.943	29.6876
530.204	28.3722
530.465	31.3234
530.726	30.9432
530.987	29.2784
531.248	24.0789
531.509	30.4065
531.77	26.6324
532.031	29.7605
532.292	26.9164
532.553	27.8018
532.814	32.0679
533.075	32.3119
533.336	34.5975
533.597	36.2447
533.858	31.6374
534.119	34.8335
534.38	37.5232
534.641	44.2202
534.901	50.8009
535.162	54.3887
535.423	53.031
535.684	47.1875
535.945	35.8992
536.205	35.3008
536.466	36.9901
536.727	34.9558
536.988	31.3893
537.248	38.4973
537.509	33.146
537.77	35.2679
537.987	37.2953
538.249	33.4012
538.51	33.0279
538.771	37.0757
539.032	30.4645
539.293	29.1743
539.554	33.9597
539.815	36.1523
540.076	34.2589
540.337	31.0428
540.598	33.8357
540.859	34.3037
541.12	36.0401
541.381	39.5999
541.642	35.4056
541.903	40.3721
542.164	33.2276
542.425	37.6642
542.686	33.8865
542.947	37.5023
543.208	30.6659
543.469	37.7799
543.73	37.9573
543.991	38.4025
544.252	33.9669
544.513	39.6131
544.773	39.0076
545.034	35.6317
545.295	41.5505
545.556	37.7934
545.817	39.8848
546.077	37.7414
546.338	39.5151
546.599	39.0294
546.86	39.7959
547.12	38.1842
547.381	41.0899
547.642	34.571
547.903	39.8956
548.163	46.4567
548.424	37.5157
548.685	35.2132
548.945	34.8712
549.206	41.7303
549.467	41.9509
549.727	46.8641
549.988	44.6225
550.248	39.0863
550.509	39.9651
550.769	49.2295
551.03	48.2045
551.291	49.1432
551.551	50.9424
551.812	59.4209
552.072	84.8726
552.332	188.996
552.593	3888.83
552.853	716.568
553.114	93.8621
553.374	69.1177
553.635	61.4693
553.895	54.0096
554.155	49.6683
554.416	50.3527
554.676	50.7466
554.937	54.5646
555.197	48.0826
555.457	48.271
555.686	45.1509
555.947	48.9724
556.207	48.2171
556.468	51.9822
556.729	52.6883
556.99	55.32
557.25	55.114
557.511	59.7611
557.772	56.6891
558.032	49.4107
558.293	55.7989
558.554	59.0412
558.814	57.9711
559.075	51.0234
559.336	58.6459
559.596	60.6874
559.857	52.1616
560.117	57.1091
560.378	51.3849
560.638	59.8319
560.899	60.8566
561.159	60.3278
561.42	63.9598
561.68	59.6786
561.941	63.203
562.201	64.1624
562.462	63.8966
562.722	63.5619
562.983	70.1223
563.243	70.045
563.504	62.0754
563.764	70.6084
564.024	69.022
564.285	72.0876
564.545	73.1777
564.805	71.3981
565.066	74.4968
565.326	75.1644
565.586	70.8418
565.847	73.4553
566.107	81.9313
566.367	76.2618
566.627	79.3789
566.888	81.5344
567.148	84.1005
567.408	81.7011
567.668	84.4291
567.928	83.8376
568.189	81.3829
568.449	85.3454
568.709	91.0952
568.969	85.7757
569.229	87.4112
569.489	87.2457
569.749	89.5857
570.009	92.0474
570.269	97.668
570.53	102.169
570.79	102.114
571.05	104.897
571.31	106.996
571.57	114.111
571.83	111.008
572.09	114.82
572.349	122.715
572.609	124.02
572.869	135.897
573.129	143.517
573.368	152.285
573.629	153.022
573.889	163.35
574.15	184.583
574.41	197.555
574.67	213.248
574.931	225.915
575.191	232.674
575.451	244.132
575.711	266.21
575.972	271.146
576.232	265.046
576.492	250.853
576.752	240.423
577.013	234.037
577.273	213.858
577.533	214.083
577.793	206.209
578.053	184.578
578.313	182.697
578.574	187.842
578.834	179.496
579.094	178.249
579.354	165.699
579.614	178.131
579.874	170.982
580.134	167.312
580.394	169.91
580.654	169.274
580.914	167.601
581.174	174.788
581.434	175.319
581.694	174.561
581.954	176.461
582.214	184.561
582.474	185.674
582.734	179.654
582.994	188.61
583.254	193.568
583.514	196.08
583.773	195.164
584.033	196.874
584.293	204.069
584.553	207.405
584.813	211.199
585.073	211.488
585.332	220.18
585.592	222.271
585.852	224.038
586.112	222.373
586.371	233.553
586.631	233.634
586.891	232.697
587.151	229.67
587.41	230.423
587.67	228.052
587.93	240.899
588.189	242.085
588.449	243.7
588.709	247.809
588.968	246.048
589.228	262.571
589.487	256.594
589.747	260.223
590.006	245.899
590.266	247.839
590.525	245.457
590.785	261.982
591.036	245.764
591.296	237.098
591.556	248.185
591.816	238.799
592.076	235.706
592.336	227.267
592.596	231.729
592.856	227.09
593.116	223.016
593.376	228.5
593.635	237.077
593.895	224.22
594.155	243.388
594.415	237.661
594.675	237.665
594.935	242.551
595.194	242.971
595.454	252.77
595.714	242.5
595.974	251.542
596.233	252
596.493	256.995
596.753	269.722
597.012	254.299
597.272	266.654
597.532	263.755
597.791	248.079
598.051	260.575
598.311	265.782
598.57	261.389
598.83	263.637
599.089	261.634
599.349	263.11
599.609	259.291
599.868	263.856
600.128	264.621
600.387	270.204
600.647	268.239
600.906	262.282
601.166	271.95
601.425	269.458
601.685	261.786
601.944	272.141
602.203	271.493
602.463	269.086
602.722	272.358
602.982	276.745
603.241	262.752
603.5	273.609
603.76	262.842
604.019	272.625
604.278	277.052
604.538	277.215
604.797	288.181
605.056	276.527
605.315	275.671
605.575	273.171
605.834	267.868
606.093	279.907
606.352	272.696
606.611	278.774
606.871	276.095
607.13	276.679
607.389	289.131
607.648	277.919
607.907	283.408
608.166	291.154
608.425	281.551
608.664	279.539
608.924	292.977
609.183	281.083
609.443	289.647
609.702	288.648
609.962	294.222
610.221	290.444
610.481	290.721
610.74	292.61
611	296.451
611.259	299.704
611.518	294.063
611.778	297.788
612.037	302.838
612.297	301.676
612.556	303.076
612.815	304.151
613.075	296.242
613.334	311.353
613.594	307.05
613.853	320.784
614.112	305.491
614.371	317.219
614.631	323.319
614.89	323.324
615.149	326.335
615.408	319.509
615.668	323.927
615.927	328.618
616.186	331.655
616.445	335.794
616.704	335.734
616.964	342.598
617.223	346.299
617.482	346.185
617.741	340.823
618	349.086
618.259	344.889
618.518	354.026
618.777	368.259
619.036	356.787
619.295	360.286
619.554	353.02
619.813	360.455
620.072	364.16
620.331	361.727
620.59	365.163
620.849	357.043
621.108	370.516
621.367	383.816
621.626	371.172
621.885	378.767
622.144	386.872
622.403	366.842
622.661	378.376
622.92	375.515
623.179	384.491
623.438	375.042
623.697	373.929
623.956	381.45
624.214	388.602
624.473	379.732
624.732	387
624.99	383.233
625.249	388.327
625.508	380.35
625.767	390.981
626.025	393.534
626.249	395.453
626.508	396.953
626.767	399.391
627.026	399.223
627.285	406.346
627.544	396.997
627.803	405.862
628.062	407.543
628.321	408.416
628.58	396.382
628.839	419.821
629.098	408.684
629.357	412.408
629.616	408.735
629.875	422.845
630.134	425.421
630.393	414.42
630.652	415.557
630.911	421.004
631.17	432.623
631.429	439.1
631.688	436.614
631.947	435.34
632.206	445.706
632.464	440.887
632.723	459.408
632.982	446.631
633.241	454.023
633.5	456.365
633.758	446.879
634.017	473.918
634.276	464.918
634.535	467.342
634.793	463.978
635.052	487.153
635.311	498.442
635.57	493.592
635.828	499.897
636.087	519.003
636.345	536.669
636.604	547.184
636.863	566.567
637.121	576.108
637.38	605.377
637.638	644.991
637.897	659.364
638.156	680.326
638.414	675.318
638.673	666.784
638.931	671.425
639.19	629.824
639.448	611.649
639.706	605.635
639.965	599.415
640.223	596.267
640.482	582.78
640.74	586.477
640.999	574.054
641.257	581.946
641.515	563.559
641.774	571.978
642.032	559.553
642.29	574.826
642.549	553.354
642.807	577.946
643.065	564.162
643.323	574.276
643.582	574.32
643.84	576.285
644.053	567.656
644.312	572.632
644.57	568.873
644.829	582.078
645.088	577.478
645.346	591.79
645.605	588.624
645.864	613.696
646.122	577.655
646.381	595.025
646.639	592.003
646.898	597.21
647.157	602.914
647.415	606.78
647.674	594.283
647.932	617.23
648.191	601.434
648.449	603.779
648.708	621.923
648.966	615.864
649.225	616.186
649.483	631.25
649.742	634.201
650	638.976
650.258	634.544
650.517	622.086
650.775	643.634
651.034	652.555
651.292	651.598
651.55	646.514
651.809	652.721
652.067	638.391
652.325	653.93
652.583	662.911
652.842	663.674
653.1	659.689
653.358	679.011
653.616	683.529
653.875	678.452
654.133	703.135
654.391	697.546
654.649	715.685
654.907	722.019
655.165	725.344
655.424	706.871
655.682	725.164
655.94	747.032
656.198	744.456
656.456	745.4
656.714	761.457
656.972	766.235
657.23	788.072
657.488	779.594
657.746	786.938
658.004	797.288
658.262	794.308
658.52	810.04
658.778	800.436
659.036	810.617
659.294	794.417
659.552	808.51
659.809	813.487
660.067	820.67
660.325	804.252
660.583	808.927
660.841	804.809
661.099	807.107
661.356	813.863
661.583	815.645
661.842	810.882
662.1	812.166
662.358	823.985
662.616	809.349
662.875	806.925
663.133	820.377
663.391	816.075
663.649	808.664
663.907	826.817
664.166	811.199
664.424	821.701
664.682	818.289
664.94	818.456
665.198	808.969
665.456	805.241
665.714	821.449
665.972	807.807
666.23	825.881
666.488	814.312
666.746	822.553
667.004	821.337
667.262	803.949
667.52	814.28
667.778	801.121
668.036	806.888
668.294	801.382
668.552	821.659
668.81	815.404
669.068	813.352
669.326	805.582
669.584	836.904
669.842	834.581
670.099	804.429
670.357	821.523
670.615	801.213
670.873	806.743
671.131	801.762
671.388	810.346
671.646	822.653
671.904	812.122
672.162	816.714
672.419	820.41
672.677	808.616
672.935	820.021
673.192	823.271
673.45	828.096
673.708	821.856
673.965	830.689
674.223	832.47
674.481	859.222
674.738	850.608
674.996	860.725
675.253	857.011
675.511	840.723
675.768	851.642
676.026	858.162
676.283	877.376
676.541	869.348
676.798	863.61
677.056	858.253
677.313	860.736
677.571	869.684
677.828	858.671
678.085	858.138
678.343	865.629
678.6	871.829
678.857	863.294
679.083	857.565
679.341	869.994
679.599	871.618
679.857	872.74
680.114	874.029
680.372	874.606
680.63	889.899
680.888	852.846
681.146	868.401
681.403	896.019
681.661	900.401
681.919	890.289
682.176	883.888
682.434	912.237
682.692	886.545
682.949	898.953
683.207	906.693
683.465	890.072
683.722	899.652
683.98	889.641
684.237	902.63
684.495	895.826
684.753	882.459
685.01	901.762
685.268	886.05
685.525	872.177
685.783	878.04
686.04	902.536
686.298	839.699
686.555	868.449
686.813	874.207
687.07	887.805
687.327	877.907
687.585	874.968
687.842	878.864
688.1	885.874
688.357	853.461
688.614	860.792
688.872	861.776
689.129	863.334
689.386	869.375
689.643	850.635
689.901	865.082
690.158	890.97
690.415	872.297
690.672	857.791
690.93	829.044
691.187	863.316
691.444	841.621
691.701	851.071
691.958	847.292
692.216	852.394
692.473	849.416
692.73	847.381
692.987	856.153
693.244	843.529
693.501	827.012
693.758	843.869
694.015	837.242
694.272	828.156
694.529	827.748
694.786	842.475
695.043	819.436
695.3	840.041
695.557	827.602
695.814	830.058
696.071	814.191
696.328	804.403
696.585	812.803
696.81	814.468
697.068	824.476
697.325	812.627
697.582	804.415
697.84	816.543
698.097	804.538
698.354	779.235
698.612	786.218
698.869	798.389
699.126	790.889
699.384	800.43
699.641	776.814
699.898	791.609
700.155	782.22
700.413	786.13
700.67	782.905
700.927	786.167
701.184	794.146
701.441	776.755
701.698	786.957
701.956	779.82
702.213	780.647
702.47	780.25
702.727	788.817
702.984	776.791
703.241	783.945
703.498	802.699
703.755	776.887
704.012	764.497
704.269	779.665
704.526	765.944
704.783	770.193
705.04	777.122
705.297	764.79
705.554	786.367
705.811	756.597
706.068	770.719
706.324	757.335
706.581	749.46
706.838	763.525
707.095	748.139
707.352	729.187
707.609	735.329
707.865	732.255
708.122	733.318
708.379	730.61
708.636	739.475
708.892	744.696
709.149	735.073
709.406	711.324
709.662	731.407
709.919	725.319
710.176	709.083
710.432	726.454
710.689	717.036
710.946	709.904
711.202	738.894
711.459	694.198
711.715	722.171
711.972	703.006
712.228	702.55
712.485	694.784
712.741	695.039
712.998	694.61
713.254	693.275
713.511	697.248
713.767	674.677
714.024	679.149
714.231	683.13
714.488	678.16
714.745	660.826
715.002	663.189
715.259	662.607
715.516	666.439
715.773	655.526
716.029	662.357
716.286	648.197
716.543	648.346
716.8	651.488
717.057	646.561
717.314	643.286
717.57	646.006
717.827	625.918
718.084	633.315
718.341	625.149
718.597	633.687
718.854	628.512
719.111	626.344
719.367	627.648
719.624	626.85
719.881	608.258
720.137	624.265
720.394	618.753
720.65	597.261
720.907	605.949
721.164	605.947
721.42	598.816
721.677	596.639
721.933	593.123
722.19	597.075
722.446	593.088
722.703	595.96
722.959	591.4
723.216	579.987
723.472	590.753
723.728	585.446
723.985	582.736
724.241	579.288
724.498	565.729
724.754	578.756
725.01	558.659
725.267	568.497
725.523	554.873
725.779	573.009
726.036	574.011
726.292	557.816
726.548	554.796
726.804	546.364
727.06	547.483
727.317	556.395
727.573	547.678
727.829	535.712
728.085	541.476
728.341	537.901
728.597	525.48
728.854	516.16
729.11	508.284
729.366	520.355
729.622	530.354
729.878	507.537
730.134	514.891
730.39	514.648
730.646	524.521
730.902	515.111
731.158	512.155
731.414	519.599
731.622	487.215
731.878	520.044
732.135	517.375
732.391	515.124
732.648	494.366
732.904	499.311
733.161	491.764
733.417	497.51
733.673	489.384
733.93	487.605
734.186	481.198
734.443	503.744
734.699	497.507
734.955	503.599
735.211	502.331
735.468	514.571
735.724	517.146
735.98	518.053
736.237	534.384
736.493	532.739
736.749	548.376
737.005	535.154
737.261	541.881
737.518	562.587
737.774	570.744
738.03	577.568
738.286	572.139
738.542	574.759
738.798	563.389
739.054	551.043
739.31	558.972
739.566	543.603
739.822	521.617
740.078	516.244
740.334	509.624
740.59	495.718
740.846	495
741.102	484.429
741.358	495.758
741.614	474.979
741.87	474.68
742.126	464.603
742.382	467.37
742.638	463.276
742.893	464.701
743.149	457.848
743.405	441.5
743.661	449.688
743.917	449.357
744.172	440.318
744.428	433.565
744.684	438.623
744.94	430.294
745.195	424.127
745.451	429.763
745.707	411.067
745.962	422.733
746.218	416.314
746.474	420.455
746.729	422.464
746.985	414.654
747.241	417.791
747.496	417.381
747.752	412.501
748.007	399.084
748.263	406.888
748.518	406.791
748.774	396.937
749.029	406.482
749.275	392.131
749.531	401.8
749.787	387.929
750.043	398.639
750.299	399.26
750.555	394.584
750.811	403.882
751.067	387.451
751.323	394.103
751.579	358.192
751.835	380.881
752.09	367.005
752.346	360.611
752.602	370.148
752.858	358.125
753.114	386.46
753.37	364.7
753.625	371.471
753.881	362.519
754.137	365.055
754.393	352.72
754.648	353.433
754.904	350.272
755.16	345.923
755.415	354.621
755.671	350.765
755.927	345.199
756.182	342.673
756.438	340.364
756.693	339.468
756.949	348.743
757.205	330.764
757.46	337.341
757.716	322.909
757.971	339.807
758.227	322.652
758.482	328.927
758.738	330.573
758.993	322.213
759.248	326.173
759.504	324.271
759.759	323.009
760.015	318.37
760.27	308.014
760.525	322.621
760.781	316.861
761.036	308.984
761.291	306.08
761.547	307.126
761.802	311.42
762.057	304.256
762.313	306.939
762.568	304.985
762.823	310.203
763.078	295.267
763.333	297.528
763.589	308.194
763.844	296.08
764.099	286.415
764.354	298.733
764.609	290.839
764.864	295.117
765.119	294.283
765.374	283.996
765.629	282.534
765.884	283.15
766.139	283.788
766.394	290.743
766.649	288.037
766.882	276.665
767.137	290.439
767.393	270.476
767.648	262.711
767.904	276.407
768.159	270.955
768.415	271.203
768.67	270.547
768.926	268.933
769.181	265.103
769.436	261.381
769.692	252.701
769.947	254.851
770.203	260.149
770.458	249.776
770.713	247.578
770.968	247.178
771.224	257.521
771.479	235.41
771.734	241.498
771.99	249.603
772.245	241.366
772.5	242.457
772.755	238.148
773.01	235.366
773.265	231.271
773.521	231.879
773.776	233.852
774.031	229.982
774.286	225.793
774.541	238.302
774.796	227.174
775.051	231.663
775.306	226.733
775.561	224.741
775.816	224.904
776.071	224.61
776.326	219.908
776.581	219.611
776.836	212.661
777.091	222.527
777.346	219.879
777.601	212.631
777.856	209.961
778.111	205.093
778.365	209.623
778.62	206.406
778.875	204.711
779.13	208.113
779.385	201.758
779.639	197.066
779.894	199.926
780.149	196.897
780.404	197.939
780.658	197.442
780.913	192.481
781.168	186.125
781.422	192.217
781.677	181.711
781.932	191.378
782.186	185.898
782.441	189.05
782.695	183.877
782.95	180.464
783.204	180.133
783.459	188.388
783.714	179.655
783.968	181.693
784.211	179.706
784.466	179.562
784.721	178.563
784.976	164.999
785.231	179.519
785.486	169.834
785.741	173.548
785.996	175.972
786.251	168.667
786.506	172.077
786.761	166.392
787.016	160.639
787.271	163.268
787.526	177.165
787.78	156.408
788.035	160.234
788.29	156.147
788.545	164.213
788.8	157.335
789.054	151.64
789.309	154.293
789.564	154.571
789.819	156.513
790.073	158.631
790.328	152.915
790.583	148.621
790.837	157.775
791.092	150.348
791.347	149.902
791.601	155.079
791.856	147.271
792.11	143.205
792.365	143.94
792.619	146.445
792.874	149.508
793.128	139.143
793.383	137.503
793.638	134.888
793.892	140.076
794.146	140.257
794.401	141.062
794.655	142.889
794.91	141.634
795.164	140.27
795.418	139.968
795.673	135.556
795.927	131.769
796.181	139.591
796.436	133.012
796.69	128.681
796.944	128.321
797.199	130.064
797.453	129.326
797.707	128.795
797.961	129.863
798.216	124.883
798.47	125.204
798.724	126.373
798.978	127.157
799.232	127.874
799.486	126.66
799.74	119.742
799.994	127.772
800.248	131.003
800.503	127.077
800.757	115.721
801.011	112.941
801.265	120.603
801.508	115.495
801.762	121.026
802.017	106.702
802.271	118.373
802.526	118.756
802.78	113.089
803.035	111.325
803.289	114.977
803.544	114.065
803.798	109.498
804.052	113.795
804.307	107.088
804.561	109.555
804.816	108.477
805.07	103.399
805.324	107.017
805.579	109.784
805.833	106.337
806.087	103.521
806.341	106.686
806.596	104.103
806.85	107.153
807.104	104.512
807.358	103.847
807.613	95.0221
807.867	101.312
808.121	101.969
808.375	100.324
808.629	106.737
808.883	98.1948
809.138	99.1919
809.392	95.8919
809.646	97.7814
809.9	94.9167
810.154	100.042
810.408	95.095
810.662	99.3989
810.916	94.5365
811.17	95.2957
811.424	93.2599
811.678	95.1932
811.932	91.2857
812.185	92.2027
812.439	95.2332
812.693	85.9229
812.947	90.8746
813.201	91.493
813.455	94.1504
813.709	91.2746
813.962	92.6524
814.216	91.3286
814.47	90.8946
814.724	93.0744
814.977	93.8862
815.231	88.3228
815.485	85.5156
815.739	89.6805
815.992	88.6516
816.246	86.7109
816.499	82.1947
816.753	87.6841
817.007	85.6478
817.26	82.9748
817.514	82.7696
817.767	84.0501
818.021	84.0445
818.274	85.7984
818.528	78.0073
818.781	80.5258
819.01	82.2444
819.264	79.1795
819.518	80.8735
819.772	78.33
820.026	75.0989
820.28	77.0815
820.534	84.2402
820.788	82.1253
821.042	77.6684
821.296	78.0953
821.549	77.256
821.803	76.6291
822.057	78.1603
822.311	77.9149
822.565	76.9455
822.819	77.6367
823.073	75.3703
823.326	72.2204
823.58	71.523
823.834	69.6858
824.088	69.1193
824.341	71.4413
824.595	75.8039
824.849	73.2595
825.103	67.8797
825.356	71.9972
825.61	74.4535
825.864	71.7359
826.117	74.6303
826.371	70.9901
826.624	70.177
826.878	67.6393
827.131	71.7779
827.385	66.1559
827.638	66.4038
827.892	68.9762
828.146	70.5337
828.399	72.7402
828.652	66.9858
828.906	67.6706
829.159	65.9417
829.413	65.7346
829.666	65.2349
829.919	67.4507
830.173	69.4572
830.426	67.136
830.68	64.4823
830.933	68.5732
831.186	64.006
831.439	61.2335
831.693	66.9317
831.946	64.5535
832.199	59.1664
832.452	67.6902
832.706	62.7559
832.959	66.6312
833.212	67.8778
833.465	62.4301
833.718	62.0964
833.971	61.1974
834.224	63.1514
834.477	63.7714
834.73	58.4361
834.984	68.5517
835.237	60.7097
835.49	63.0611
835.743	62.9814
835.996	63.9237
836.201	65.0015
836.454	54.1684
836.708	56.9106
836.961	64.9189
837.215	58.909
837.468	63.4976
837.722	65.4128
837.975	58.8602
838.229	53.2864
838.482	56.9267
838.735	59.1442
838.989	61.2543
839.242	62.6457
839.496	54.5095
839.749	61.0092
840.002	58.5191
840.256	59.8634
840.509	55.1898
840.762	56.4252
841.015	61.1529
841.269	54.4186
841.522	57.1112
841.775	56.104
842.028	57.9437
842.281	57.4074
842.535	57.9074
842.788	55.8502
843.041	53.4509
843.294	56.5051
843.547	54.2049
843.8	53.4959
844.053	51.5103
844.306	53.4069
844.559	56.3676
844.812	56.5487
845.065	52.363
845.318	59.6583
845.571	49.8563
845.824	58.2579
846.077	53.7318
846.33	55.7588
846.583	52.3521
846.836	56.0475
847.089	48.2905
847.342	50.272
847.595	52.1932
847.847	51.125
848.1	53.0279
848.353	51.7501
848.606	51.379
848.859	51.6079
849.111	49.1818
849.364	50.3177
849.617	51.4964
849.869	51.0576
850.122	47.7826
850.375	48.7071
850.627	47.7213
850.88	52.6127
851.133	50.2846
851.385	49.255
851.638	55.1175
851.89	49.3703
852.143	52.3034
852.395	49.7773
852.648	53.3241
852.9	46.1429
853.153	46.8058
853.405	52.6012
853.645	51.1286
853.898	46.0715
854.151	45.9575
854.404	50.2437
854.657	47.8791
854.91	48.5452
855.163	48.1302
855.416	43.3149
855.669	46.0703
855.922	48.1181
856.175	41.9451
856.427	56.5718
856.68	41.8725
856.933	44.9037
857.186	43.9036
857.439	49.2219
857.692	45.1548
857.944	44.5671
858.197	46.2292
858.45	49.8797
858.703	51.7259
858.955	43.1042
859.208	47.7256
859.461	50.5518
859.713	45.0487
859.966	44.8345
860.219	43.3092
860.471	43.0229
860.724	38.4084
860.976	37.6963
861.229	46.7882
861.481	43.4125
861.734	44.4227
861.986	40.3988
862.239	44.6681
862.491	39.9158
862.744	41.4265
862.996	41.5749
863.249	40.5677
863.501	43.0568
863.754	44.947
864.006	46.2863
864.258	47.6742
864.511	44.7362
864.763	44.2833
865.015	40.7764
865.268	43.1596
865.52	39.8144
865.772	42.2685
866.024	41.5377
866.276	43.5988
866.529	41.7128
866.781	39.378
867.033	41.3983
867.285	43.6744
867.537	46.4485
867.789	37.9026
868.042	40.8777
868.294	45.848
868.546	42.9888
868.798	39.895
869.05	41.2567
869.302	37.9432
869.554	39.725
869.806	38.7841
870.058	40.3211
870.31	41.4236
870.562	39.7491
870.782	43.0604
871.034	35.0674
871.287	44.1425
871.539	40.8934
871.792	45.3154
872.044	40.573
872.297	37.1792
872.549	44.2394
872.801	42.2566
873.054	38.2798
873.306	35.3486
873.558	41.082
873.811	41.0635
874.063	39.6408
874.315	41.5313
874.568	44.8423
874.82	40.599
875.072	39.9016
875.324	37.2631
875.577	33.9106
875.829	38.2455
876.081	43.4125
876.333	41.5361
876.585	40.8376
876.838	35.3712
877.09	40.1023
877.342	42.3085
877.594	39.6363
877.846	38.2693
878.098	37.8041
878.35	39.5808
878.602	39.0895
878.854	38.2265
879.106	38.2825
879.358	37.1179
879.61	39.3024
879.862	43.2519
880.114	38.4735
880.366	44.049
880.618	37.5194
880.87	37.1673
881.121	41.4609
881.373	39.974
881.625	36.7224
881.877	38.1904
882.129	41.6535
882.38	34.7837
882.632	37.4372
882.884	36.5167
883.136	36.9635
883.387	35.4422
883.639	36.2214
883.891	36.5896
884.142	41.1722
884.394	36.1332
884.646	36.9035
884.897	37.6978
885.149	33.1306
885.4	36.5554
885.652	37.4289
885.903	35.1152
886.155	35.0562
886.406	37.8138
886.658	35.4296
886.909	35.249
887.161	39.7055
887.412	34.683
887.664	36.8495
887.915	35.8827
888.138	36.3189
888.39	35.3576
888.642	37.8813
888.894	35.1083
889.146	32.3801
889.398	34.7261
889.65	31.3688
889.902	38.5872
890.154	36.4268
890.406	34.6101
890.657	31.497
890.909	35.1879
891.161	33.2023
891.413	33.7815
891.665	31.9784
891.916	37.4634
892.168	31.8472
892.42	36.0045
892.671	36.1092
892.923	33.8393
893.175	35.0506
893.426	35.1153
893.678	32.6075
893.93	32.2801
894.181	33.1612
894.433	30.7628
894.684	35.4075
894.936	31.3172
895.188	34.8046
895.439	30.4461
895.69	37.2783
895.942	29.7815
896.193	35.613
896.445	33.1055
896.696	35.1244
896.948	35.2257
897.199	33.7767
897.451	31.5144
897.702	31.5242
897.953	31.8734
898.204	35.8792
898.456	35.3598
898.707	31.3671
898.958	35.4115
899.21	34.7762
899.461	32.5818
899.712	29.0817
899.963	32