File: M5_140224_02_01.txt
#Acq. time (s)=	5
#Accumulations=	3
#Range (nm)=	520...900
#Windows=	24
#Auto scanning=	On
#Autofocus=	Off
#AutoExposure=	Off
#Spike filter=	Multiple accum.
#Delay time (s)=	0
#Binning=	1
#Readout mode=	Signal
#DeNoise=	Off
#ICS correction=	Off
#Dark correction=	Off
#Inst. Process=	Off
#Detector temperature (°C)=	-59.98
#Instrument=	LabRAM HR Evol
#Detector=	Syncerity OE
#Objective=	x50_VIS
#Grating=	600 (500nm)
#ND Filter=	10%
#Laser=	514nm_Edge
#Hole=	199.981
#Range=	Auto
#StageXY=	Marzhauser
#StageZ=	Marzhauser
#X (µm)=	14714.6
#Y (µm)=	2789.2
#Z (µm)=	-16.6
#Full time(mm:ss)=	5:28
#Project=
#Sample=
#Site=
#Title=	M5_140224_02
#Remark=
#Date=	19.02.2024 14:30
#Acquired=	19.02.2024 14:30:32
520.013	35.4452
520.274	34.0233
520.536	34.3318
520.797	31.3706
521.059	34.906
521.32	35.3333
521.582	34.4134
521.843	39.7335
522.105	32.4426
522.366	34.9015
522.628	39.9041
522.889	35.485
523.15	34.8496
523.412	32.8617
523.673	37.9487
523.935	36.1248
524.196	39.7361
524.457	37.5006
524.719	39.4742
524.98	37.7032
525.241	39.1636
525.503	37.4413
525.764	38.789
526.025	36.444
526.286	35.7724
526.548	42.09
526.809	39.4194
527.07	41.2929
527.331	35.2878
527.593	36.1112
527.854	39.7374
528.115	42.0905
528.376	34.6713
528.637	38.1163
528.898	36
529.16	35.8845
529.421	38.989
529.682	40.9309
529.943	33.6762
530.204	37.4729
530.465	37.5827
530.726	41.5103
530.987	42.1512
531.248	36.2602
531.509	43.6595
531.77	35.9249
532.031	40.0852
532.292	39.312
532.553	39.0436
532.814	44.0374
533.075	41.3053
533.336	39.2564
533.597	44.0076
533.858	51.323
534.119	58.394
534.38	68.8729
534.641	90.0458
534.901	105.838
535.162	122.263
535.423	112.432
535.684	90.0042
535.945	77.6917
536.205	65.7187
536.466	59.7919
536.727	53.3789
536.988	54.2234
537.248	51.1902
537.509	50.8969
537.77	48.2473
537.987	52.544
538.249	51.4481
538.51	50.4059
538.771	50.4287
539.032	40.3657
539.293	45.5435
539.554	46.3515
539.815	51.6285
540.076	47.2793
540.337	49.9551
540.598	52.825
540.859	50.3197
541.12	54.6922
541.381	49.8874
541.642	52.7704
541.903	54.3058
542.164	54.2517
542.425	55.173
542.686	60.9286
542.947	55.7609
543.208	55.8605
543.469	61.1325
543.73	60.3884
543.991	58.6477
544.252	58.1591
544.513	64.0673
544.773	64.6612
545.034	60.1617
545.295	68.5503
545.556	61.6904
545.817	65.1077
546.077	59.1351
546.338	69.9615
546.599	67.4724
546.86	66.3986
547.12	69.0173
547.381	75.046
547.642	74.8545
547.903	76.2724
548.163	63.4667
548.424	69.0413
548.685	72.3953
548.945	70.5629
549.206	66.4826
549.467	78.5659
549.727	72.799
549.988	71.2978
550.248	74.3057
550.509	82.3019
550.769	85.3528
551.03	82.2795
551.291	95.3355
551.551	106.177
551.812	130.073
552.072	174.562
552.332	449.249
552.593	10388
552.853	1823.27
553.114	219.828
553.374	139.653
553.635	116.02
553.895	96.2079
554.155	93.5528
554.416	90.5559
554.676	93.6811
554.937	88.1327
555.197	89.7648
555.457	94.9156
555.686	95.8713
555.947	96.0347
556.207	87.9212
556.468	93.7853
556.729	96.0764
556.99	95.2068
557.25	97.0522
557.511	97.4274
557.772	106.325
558.032	95.2073
558.293	104.94
558.554	105.134
558.814	105.387
559.075	99.5094
559.336	103.817
559.596	109.192
559.857	115.738
560.117	108.045
560.378	114.082
560.638	116.773
560.899	110.885
561.159	121.626
561.42	121.738
561.68	128.326
561.941	127.451
562.201	127.792
562.462	127.885
562.722	136.632
562.983	128.539
563.243	136.01
563.504	134.585
563.764	133.475
564.024	140.47
564.285	136.369
564.545	143.882
564.805	141.542
565.066	141.772
565.326	157.036
565.586	152.525
565.847	156.959
566.107	152.559
566.367	161.46
566.627	163.156
566.888	162.24
567.148	161.723
567.408	171.547
567.668	178.01
567.928	171.748
568.189	175.819
568.449	184.343
568.709	185.419
568.969	187.711
569.229	189.431
569.489	192.764
569.749	197.313
570.009	196.111
570.269	217.255
570.53	214.562
570.79	224.809
571.05	226.622
571.31	233.197
571.57	244.273
571.83	248.338
572.09	264.057
572.349	271.863
572.609	288.503
572.869	309.238
573.129	329.194
573.368	351.134
573.629	365.427
573.889	394.812
574.15	414.942
574.41	458.798
574.67	493.138
574.931	529.258
575.191	582.259
575.451	597.3
575.711	617.724
575.972	628.517
576.232	612.881
576.492	592.199
576.752	573.688
577.013	540.795
577.273	513.557
577.533	493.088
577.793	463.572
578.053	441.495
578.313	431.97
578.574	409.883
578.834	412.152
579.094	402.769
579.354	392.253
579.614	402.515
579.874	396.514
580.134	394.71
580.394	408.914
580.654	393.791
580.914	406.467
581.174	392.896
581.434	412.304
581.694	406.857
581.954	420.366
582.214	413.8
582.474	429.407
582.734	434.436
582.994	429.99
583.254	441.629
583.514	456.666
583.773	453.575
584.033	466.827
584.293	474.509
584.553	494.75
584.813	499.824
585.073	507.903
585.332	517.962
585.592	515.056
585.852	525.944
586.112	530.597
586.371	534.334
586.631	538.077
586.891	562.075
587.151	562.642
587.41	557.899
587.67	559.91
587.93	559.94
588.189	568.201
588.449	581.14
588.709	585.583
588.968	588.778
589.228	610.089
589.487	609.618
589.747	623.785
590.006	597.624
590.266	602.087
590.525	598.203
590.785	597.577
591.036	585.048
591.296	581.242
591.556	579.847
591.816	557.719
592.076	556.591
592.336	564.848
592.596	566.89
592.856	560.976
593.116	556.064
593.376	558.394
593.635	564.357
593.895	586.449
594.155	562.651
594.415	576.745
594.675	567.238
594.935	560.406
595.194	574.957
595.454	591.019
595.714	597.627
595.974	591.951
596.233	598.7
596.493	597.974
596.753	613.055
597.012	609.689
597.272	616.583
597.532	627.735
597.791	610.512
598.051	621.497
598.311	629.904
598.57	621.532
598.83	627.336
599.089	610.335
599.349	624.162
599.609	629.667
599.868	621.688
600.128	635.823
600.387	632.423
600.647	638.752
600.906	638.45
601.166	639.858
601.425	628.615
601.685	653.724
601.944	628.267
602.203	648.037
602.463	642.37
602.722	635.328
602.982	651.386
603.241	657.898
603.5	654.017
603.76	663.321
604.019	669.581
604.278	670.134
604.538	662.384
604.797	646.722
605.056	684.181
605.315	664.256
605.575	664.199
605.834	664.358
606.093	656.815
606.352	661.51
606.611	665.955
606.871	650.528
607.13	668.683
607.389	670.163
607.648	674.363
607.907	659.629
608.166	668.171
608.425	693.56
608.664	675.642
608.924	688.569
609.183	687.847
609.443	700.102
609.702	693.323
609.962	684.163
610.221	704.68
610.481	696.698
610.74	716.716
611	719.316
611.259	719.807
611.518	706.858
611.778	723.361
612.037	730.073
612.297	736.831
612.556	740.981
612.815	735.192
613.075	735.621
613.334	738.571
613.594	760.56
613.853	771.258
614.112	750.9
614.371	768.221
614.631	779.34
614.89	779.773
615.149	800.151
615.408	801.559
615.668	796.683
615.927	801.495
616.186	812.754
616.445	816.165
616.704	818.957
616.964	828.762
617.223	833.012
617.482	843.232
617.741	851.84
618	858.27
618.259	854.403
618.518	869.919
618.777	888.185
619.036	856.216
619.295	867.226
619.554	892.574
619.813	883.234
620.072	894.683
620.331	914.839
620.59	902.964
620.849	909.655
621.108	904.208
621.367	895.467
621.626	902.013
621.885	934.846
622.144	918.72
622.403	917.672
622.661	920.995
622.92	942.1
623.179	932.807
623.438	935.642
623.697	930.998
623.956	946.273
624.214	932.024
624.473	926.982
624.732	951.984
624.99	947.059
625.249	952.596
625.508	953.576
625.767	951.682
626.025	959.513
626.249	960.541
626.508	984.252
626.767	963.63
627.026	970.481
627.285	987.033
627.544	984.59
627.803	972.928
628.062	1011.62
628.321	1001.91
628.58	993.249
628.839	1003.25
629.098	1021.22
629.357	1012.54
629.616	1013.72
629.875	1031.87
630.134	1029.84
630.393	1055.57
630.652	1046.36
630.911	1045.02
631.17	1050.02
631.429	1053.67
631.688	1072.78
631.947	1050.77
632.206	1078.63
632.464	1080.97
632.723	1110.64
632.982	1100.65
633.241	1105.31
633.5	1143.04
633.758	1133.19
634.017	1141.64
634.276	1148.91
634.535	1168.22
634.793	1182.86
635.052	1192.7
635.311	1222.27
635.57	1252.92
635.828	1248.94
636.087	1251.42
636.345	1308.34
636.604	1342.15
636.863	1411.99
637.121	1490.5
637.38	1548.04
637.638	1622.02
637.897	1697.35
638.156	1732.07
638.414	1743.18
638.673	1715.53
638.931	1668.32
639.19	1595.75
639.448	1553.93
639.706	1554.78
639.965	1518.41
640.223	1480.93
640.482	1461.45
640.74	1435.11
640.999	1447.72
641.257	1441.14
641.515	1435.64
641.774	1410.99
642.032	1428.66
642.29	1398.89
642.549	1415.24
642.807	1422.4
643.065	1408.68
643.323	1405.11
643.582	1412.57
643.84	1424.21
644.053	1406.11
644.312	1427.68
644.57	1438.89
644.829	1440.19
645.088	1473.73
645.346	1450.96
645.605	1456.5
645.864	1453.6
646.122	1454.87
646.381	1468.12
646.639	1474.03
646.898	1482.53
647.157	1489.19
647.415	1488.32
647.674	1520.41
647.932	1513.63
648.191	1513.98
648.449	1510.92
648.708	1541.45
648.966	1554.01
649.225	1554.36
649.483	1577.53
649.742	1580.66
650	1562.24
650.258	1597.69
650.517	1583.72
650.775	1615.69
651.034	1628.47
651.292	1649.81
651.55	1662.06
651.809	1659.33
652.067	1665.34
652.325	1676.26
652.583	1688.83
652.842	1704.88
653.1	1681.29
653.358	1724.81
653.616	1747.77
653.875	1730.28
654.133	1783.58
654.391	1783.04
654.649	1800.61
654.907	1788.91
655.165	1808.83
655.424	1842.62
655.682	1867.47
655.94	1881.06
656.198	1895.61
656.456	1915.03
656.714	1936.64
656.972	1948.21
657.23	1949.7
657.488	1978.55
657.746	1980.79
658.004	2011.1
658.262	2018.77
658.52	2026.74
658.778	2046.85
659.036	2044.02
659.294	2056.08
659.552	2068.7
659.809	2067.79
660.067	2086.6
660.325	2070.12
660.583	2072.92
660.841	2074.55
661.099	2064.11
661.356	2081.37
661.583	2103.22
661.842	2095.02
662.1	2050.41
662.358	2074.3
662.616	2076.14
662.875	2076.53
663.133	2082.04
663.391	2071.85
663.649	2106.7
663.907	2100.27
664.166	2081.45
664.424	2067.45
664.682	2085.48
664.94	2086.68
665.198	2099.48
665.456	2086.52
665.714	2077.04
665.972	2042.49
666.23	2066.01
666.488	2060.78
666.746	2088.46
667.004	2083.95
667.262	2087.74
667.52	2068.87
667.778	2039.77
668.036	2062.7
668.294	2071.05
668.552	2060.26
668.81	2067.64
669.068	2077.29
669.326	2072.98
669.584	2048.54
669.842	2084.23
670.099	2083.44
670.357	2089.07
670.615	2068.68
670.873	2072.37
671.131	2069.91
671.388	2096.43
671.646	2085.2
671.904	2079.02
672.162	2073.3
672.419	2081.84
672.677	2105.56
672.935	2070.81
673.192	2118.35
673.45	2091.33
673.708	2127.67
673.965	2134.94
674.223	2151.77
674.481	2145.54
674.738	2169.78
674.996	2186.42
675.253	2201.81
675.511	2171.91
675.768	2213.28
676.026	2203.13
676.283	2191.98
676.541	2202.63
676.798	2208.24
677.056	2205.36
677.313	2217.6
677.571	2239.04
677.828	2196.81
678.085	2254.01
678.343	2216.61
678.6	2229.14
678.857	2198.46
679.083	2226.28
679.341	2217.06
679.599	2267.83
679.857	2210.23
680.114	2216.56
680.372	2241.86
680.63	2242.14
680.888	2274.8
681.146	2252.12
681.403	2235.14
681.661	2277.51
681.919	2288.1
682.176	2270.9
682.434	2298.95
682.692	2318.05
682.949	2291.58
683.207	2291.98
683.465	2314.04
683.722	2293.88
683.98	2303.36
684.237	2281.13
684.495	2297.14
684.753	2289.1
685.01	2270.77
685.268	2263.58
685.525	2241.2
685.783	2237.65
686.04	2246.87
686.298	2233.93
686.555	2245.29
686.813	2263.63
687.07	2258.52
687.327	2260.29
687.585	2234.66
687.842	2235.66
688.1	2220.23
688.357	2208.34
688.614	2230.78
688.872	2222.47
689.129	2239.61
689.386	2234.09
689.643	2250.91
689.901	2252.4
690.158	2243.37
690.415	2205.46
690.672	2221.6
690.93	2202.09
691.187	2150.07
691.444	2177.76
691.701	2204.53
691.958	2184.79
692.216	2174.51
692.473	2165.81
692.73	2195.12
692.987	2167.18
693.244	2162.23
693.501	2152.14
693.758	2144.22
694.015	2134.99
694.272	2120.2
694.529	2122.28
694.786	2128.91
695.043	2115.77
695.3	2128.89
695.557	2118.12
695.814	2110.12
696.071	2118.27
696.328	2112.46
696.585	2114.72
696.81	2090.13
697.068	2093.47
697.325	2060.97
697.582	2069.91
697.84	2059.46
698.097	2056.94
698.354	2036.45
698.612	2045.12
698.869	2037.39
699.126	2040.92
699.384	2022.39
699.641	2010.02
699.898	2025.65
700.155	1990.88
700.413	2009.44
700.67	2019.79
700.927	2006.83
701.184	2012.34
701.441	1993.74
701.698	2026.79
701.956	1987.33
702.213	1985.53
702.47	2003.55
702.727	2009.06
702.984	1991.86
703.241	1991.43
703.498	1998.27
703.755	1973.1
704.012	1979.69
704.269	1999.21
704.526	1985.87
704.783	1965.77
705.04	1970
705.297	1950.88
705.554	1937.56
705.811	1943
706.068	1936.26
706.324	1929.6
706.581	1935.22
706.838	1869.16
707.095	1902.23
707.352	1883.11
707.609	1902.44
707.865	1888.45
708.122	1890.68
708.379	1876.38
708.636	1862.77
708.892	1844.78
709.149	1849.01
709.406	1840.23
709.662	1857.6
709.919	1842.52
710.176	1855.09
710.432	1820.29
710.689	1835.95
710.946	1823.37
711.202	1828.34
711.459	1781.64
711.715	1799.14
711.972	1771.84
712.228	1773.12
712.485	1761.77
712.741	1773.05
712.998	1763.61
713.254	1762.86
713.511	1746.03
713.767	1729.06
714.024	1708.02
714.231	1705.71
714.488	1708.89
714.745	1691.16
715.002	1667.36
715.259	1687.63
715.516	1689.62
715.773	1651.56
716.029	1668.15
716.286	1647.97
716.543	1650.72
716.8	1635.19
717.057	1616.76
717.314	1613.08
717.57	1615.42
717.827	1637.04
718.084	1588.48
718.341	1600.32
718.597	1628.3
718.854	1614.31
719.111	1590.96
719.367	1577.17
719.624	1604.57
719.881	1577.77
720.137	1582.11
720.394	1563
720.65	1545.51
720.907	1546.31
721.164	1541.07
721.42	1511.29
721.677	1520.85
721.933	1498.6
722.19	1512.37
722.446	1499.73
722.703	1485.69
722.959	1473.13
723.216	1485.13
723.472	1481.47
723.728	1453.63
723.985	1455.27
724.241	1466.09
724.498	1461.42
724.754	1437.77
725.01	1416.1
725.267	1441.95
725.523	1422.13
725.779	1427.15
726.036	1396.78
726.292	1412.46
726.548	1399.93
726.804	1386.08
727.06	1402.22
727.317	1364.39
727.573	1383.52
727.829	1375.33
728.085	1352.92
728.341	1364.37
728.597	1362.79
728.854	1321.14
729.11	1346.31
729.366	1323.29
729.622	1309.63
729.878	1322.77
730.134	1313.49
730.39	1275.47
730.646	1302.7
730.902	1294.28
731.158	1296.26
731.414	1290.95
731.622	1265.94
731.878	1271.02
732.135	1258.88
732.391	1259.62
732.648	1256.07
732.904	1238.38
733.161	1243.21
733.417	1233.77
733.673	1230.05
733.93	1247.94
734.186	1268.31
734.443	1243.26
734.699	1243.23
734.955	1247.88
735.211	1281.97
735.468	1285.46
735.724	1289.49
735.98	1313.53
736.237	1323.15
736.493	1343.69
736.749	1369.46
737.005	1383.83
737.261	1398.51
737.518	1390.67
737.774	1424.81
738.03	1441.23
738.286	1458.92
738.542	1431.05
738.798	1424.64
739.054	1412.04
739.31	1391.61
739.566	1391.71
739.822	1355.22
740.078	1321.84
740.334	1293.08
740.59	1247.55
740.846	1240.3
741.102	1232.78
741.358	1215.71
741.614	1218.36
741.87	1185.74
742.126	1160.24
742.382	1174.83
742.638	1137.76
742.893	1139.42
743.149	1130.87
743.405	1114.57
743.661	1118.89
743.917	1099.68
744.172	1086.77
744.428	1068.67
744.684	1087.78
744.94	1072.83
745.195	1045.94
745.451	1068.72
745.707	1048.89
745.962	1047.25
746.218	1027.71
746.474	1036.54
746.729	1032.91
746.985	1038.18
747.241	1033.99
747.496	1015.38
747.752	1017.89
748.007	1014.32
748.263	995.482
748.518	998.852
748.774	988.142
749.029	1008.47
749.275	1011.83
749.531	992.429
749.787	968.16
750.043	973.48
750.299	943.97
750.555	965.201
750.811	963.06
751.067	944.516
751.323	950.121
751.579	956.185
751.835	943.826
752.09	936.617
752.346	948.532
752.602	901.395
752.858	908.302
753.114	899.279
753.37	926.841
753.625	917.019
753.881	898.867
754.137	879.53
754.393	886.997
754.648	890.893
754.904	872.985
755.16	887.012
755.415	861.306
755.671	854.615
755.927	863.646
756.182	868.952
756.438	856.677
756.693	845.671
756.949	851.52
757.205	828.949
757.46	840.483
757.716	826.612
757.971	829.187
758.227	840.887
758.482	829.277
758.738	802.217
758.993	810.464
759.248	806.974
759.504	810.524
759.759	779.286
760.015	784.943
760.27	793.043
760.525	775.054
760.781	778.306
761.036	755.685
761.291	765.519
761.547	749.621
761.802	755.391
762.057	748.791
762.313	746.28
762.568	747.738
762.823	737.649
763.078	739.855
763.333	738.765
763.589	746.997
763.844	727.779
764.099	739.762
764.354	725.994
764.609	721.49
764.864	704.026
765.119	709.267
765.374	698.363
765.629	707.136
765.884	708.091
766.139	691.771
766.394	696.062
766.649	693.983
766.882	708.033
767.137	684.557
767.393	666.542
767.648	678.729
767.904	658.16
768.159	655.864
768.415	640.887
768.67	654.693
768.926	651.201
769.181	631.518
769.436	632.2
769.692	625.352
769.947	628.1
770.203	620.85
770.458	612.14
770.713	614.591
770.968	608.019
771.224	602.814
771.479	612.717
771.734	598.906
771.99	586.71
772.245	593.953
772.5	585.377
772.755	587.144
773.01	580.043
773.265	582.464
773.521	565.139
773.776	570.688
774.031	562.983
774.286	557.78
774.541	541.78
774.796	546.06
775.051	537.624
775.306	541.938
775.561	541.04
775.816	527.577
776.071	531.272
776.326	520.495
776.581	519.583
776.836	522.393
777.091	509.952
777.346	505.675
777.601	521.658
777.856	505.186
778.111	501.217
778.365	490.009
778.62	493.439
778.875	504.473
779.13	495.396
779.385	489.073
779.639	481.814
779.894	477.297
780.149	456.959
780.404	467.695
780.658	470.709
780.913	462.188
781.168	456.184
781.422	462.658
781.677	447.428
781.932	454.455
782.186	445.318
782.441	435.741
782.695	435.325
782.95	436.668
783.204	430.957
783.459	434.668
783.714	425.607
783.968	427.054
784.211	420.817
784.466	423.186
784.721	418.957
784.976	411.001
785.231	415.155
785.486	402.607
785.741	393.229
785.996	388.404
786.251	402.995
786.506	390.056
786.761	387.262
787.016	394.339
787.271	391.897
787.526	386.797
787.78	389.616
788.035	375.46
788.29	374.919
788.545	369.358
788.8	377.038
789.054	377.976
789.309	361.864
789.564	354.856
789.819	363.789
790.073	365.948
790.328	363.886
790.583	354.606
790.837	357.589
791.092	351.828
791.347	343.793
791.601	346.863
791.856	348.659
792.11	345.5
792.365	341.603
792.619	331.838
792.874	339.71
793.128	332.985
793.383	329.876
793.638	332.033
793.892	323.184
794.146	319.609
794.401	305.988
794.655	318.099
794.91	318.949
795.164	314.676
795.418	304
795.673	306.735
795.927	302.69
796.181	297.066
796.436	297.13
796.69	302.923
796.944	300.438
797.199	295.111
797.453	297.06
797.707	298.405
797.961	290.957
798.216	287.678
798.47	286.882
798.724	288.762
798.978	281.803
799.232	275.026
799.486	282.275
799.74	277.05
799.994	274.994
800.248	280.049
800.503	261.571
800.757	263.686
801.011	274.444
801.265	256.43
801.508	261.742
801.762	259.922
802.017	263.781
802.271	263.124
802.526	259.253
802.78	244.703
803.035	249.213
803.289	256.677
803.544	257.22
803.798	247.946
804.052	242.216
804.307	247.913
804.561	234.313
804.816	227.003
805.07	234.717
805.324	228.755
805.579	232.55
805.833	226.173
806.087	228.913
806.341	231.915
806.596	233.554
806.85	227.263
807.104	237.835
807.358	222.546
807.613	229.247
807.867	234.635
808.121	219.582
808.375	222.428
808.629	218.806
808.883	213.229
809.138	222.223
809.392	211.746
809.646	215.973
809.9	213.119
810.154	212.603
810.408	211.992
810.662	209.22
810.916	214.518
811.17	202.13
811.424	198.23
811.678	192.331
811.932	199.355
812.185	200.375
812.439	200.828
812.693	205.381
812.947	203.247
813.201	195.537
813.455	183.276
813.709	196.614
813.962	193.148
814.216	191.4
814.47	185.616
814.724	186.96
814.977	189.59
815.231	179.214
815.485	183.41
815.739	181.281
815.992	181.347
816.246	178.185
816.499	174.99
816.753	176.52
817.007	179.43
817.26	171.454
817.514	172.579
817.767	176.61
818.021	171.473
818.274	170.935
818.528	177.649
818.781	161.906
819.01	166.575
819.264	166.706
819.518	165.43
819.772	162.817
820.026	169.348
820.28	170.554
820.534	159.786
820.788	157.637
821.042	157.412
821.296	157.458
821.549	160.353
821.803	157.484
822.057	154.986
822.311	154.726
822.565	157.731
822.819	154.567
823.073	152.499
823.326	156.724
823.58	154.537
823.834	149.034
824.088	142.959
824.341	146.767
824.595	151.832
824.849	141.073
825.103	146.467
825.356	143.222
825.61	145.812
825.864	142.882
826.117	145.584
826.371	136.539
826.624	146.812
826.878	134.795
827.131	144.68
827.385	138.704
827.638	139.878
827.892	132.844
828.146	139.476
828.399	132.255
828.652	134.369
828.906	133.841
829.159	125.583
829.413	127.745
829.666	132.101
829.919	134.758
830.173	130.684
830.426	129.919
830.68	126.123
830.933	129.74
831.186	126.721
831.439	127.285
831.693	121.303
831.946	125.345
832.199	117.976
832.452	126.157
832.706	129.209
832.959	125.948
833.212	129.137
833.465	121.46
833.718	117.491
833.971	121.713
834.224	121.307
834.477	117.741
834.73	121.288
834.984	113.861
835.237	124.955
835.49	118.891
835.743	126.57
835.996	106.322
836.201	115.852
836.454	110.241
836.708	114.872
836.961	111.645
837.215	115.391
837.468	115.62
837.722	112.886
837.975	117.564
838.229	121.064
838.482	114.617
838.735	104.303
838.989	101.069
839.242	112.603
839.496	98.4075
839.749	109.066
840.002	104.014
840.256	108.554
840.509	104.446
840.762	103.587
841.015	103.888
841.269	105.75
841.522	104.097
841.775	103.406
842.028	105.466
842.281	98.9177
842.535	102.877
842.788	98.4242
843.041	102.447
843.294	100.732
843.547	97.1833
843.8	96.414
844.053	106.611
844.306	100.963
844.559	101.91
844.812	100.964
845.065	103.913
845.318	93.7571
845.571	96.2245
845.824	94.366
846.077	98.9089
846.33	92.8219
846.583	91.3495
846.836	89.4136
847.089	101.773
847.342	94.902
847.595	91.2978
847.847	91.8886
848.1	90.7631
848.353	95.5518
848.606	95.788
848.859	95.2039
849.111	99.2393
849.364	86.7454
849.617	93.3071
849.869	89.2446
850.122	87.7204
850.375	85.5675
850.627	94.5477
850.88	83.957
851.133	93.9717
851.385	83.587
851.638	82.1754
851.89	85.4865
852.143	86.3904
852.395	89.8296
852.648	84.2696
852.9	89.8738
853.153	88.3435
853.405	83.3592
853.645	79.8191
853.898	80.8526
854.151	85.3224
854.404	80.1642
854.657	79.8723
854.91	80.5032
855.163	79.4116
855.416	78.1821
855.669	83.3975
855.922	85.264
856.175	82.211
856.427	86.2886
856.68	76.944
856.933	79.113
857.186	84.837
857.439	79.5492
857.692	81.8293
857.944	77.8602
858.197	79.1737
858.45	81.3793
858.703	79.182
858.955	77.9366
859.208	70.4795
859.461	64.0912
859.713	68.4185
859.966	82.0605
860.219	72.4736
860.471	74.6299
860.724	74.7482
860.976	71.0275
861.229	77.877
861.481	71.9998
861.734	79.3618
861.986	80.9899
862.239	77.5748
862.491	74.2989
862.744	69.285
862.996	76.527
863.249	69.7102
863.501	72.6683
863.754	78.9027
864.006	73.1669
864.258	71.4863
864.511	69.0686
864.763	70.5428
865.015	72.47
865.268	72.0112
865.52	71.3133
865.772	73.1855
866.024	70.9815
866.276	66.5014
866.529	72.7665
866.781	72.3122
867.033	67.1361
867.285	68.0012
867.537	66.5764
867.789	68.0823
868.042	64.3811
868.294	65.7137
868.546	68.4388
868.798	65.9075
869.05	62.6008
869.302	65.9121
869.554	69.9071
869.806	64.5917
870.058	63.4379
870.31	64.4228
870.562	66.2554
870.782	67.0515
871.034	64.832
871.287	66.2553
871.539	65.8963
871.792	64.4275
872.044	58.595
872.297	56.5629
872.549	67.8855
872.801	62.0743
873.054	67.0003
873.306	56.1712
873.558	63.6129
873.811	63.916
874.063	52.0441
874.315	65.7057
874.568	64.999
874.82	60.8687
875.072	56.0769
875.324	55.7363
875.577	56.1956
875.829	58.92
876.081	65.4656
876.333	62.3601
876.585	58.5426
876.838	56.0007
877.09	62.0612
877.342	59.8964
877.594	59.4746
877.846	59.9105
878.098	61.6999
878.35	61.3306
878.602	56.6909
878.854	54.8462
879.106	56.1695
879.358	57.8913
879.61	61.747
879.862	60.7913
880.114	56.0036
880.366	55.6218
880.618	57.7504
880.87	58.3881
881.121	52.6166
881.373	58.7254
881.625	49.1114
881.877	53.5252
882.129	52.1384
882.38	54.1879
882.632	58.2785
882.884	52.9251
883.136	57.6957
883.387	52.3892
883.639	48.2685
883.891	51.8466
884.142	50.8269
884.394	47.1223
884.646	53.2729
884.897	53.4589
885.149	56.501
885.4	52.5108
885.652	53.2273
885.903	51.7579
886.155	54.6886
886.406	48.7202
886.658	48.0371
886.909	51.3899
887.161	49.1079
887.412	50.5233
887.664	51.1574
887.915	53.8757
888.138	53.6193
888.39	54.1064
888.642	50.6658
888.894	54.369
889.146	52.639
889.398	47.2522
889.65	46.5114
889.902	52.1049
890.154	54.5767
890.406	41.7579
890.657	52.6557
890.909	51.7664
891.161	46.3061
891.413	48.5149
891.665	46.2135
891.916	50.8697
892.168	46.5589
892.42	48.2453
892.671	51.0992
892.923	51.4196
893.175	47.735
893.426	48.1111
893.678	50.8479
893.93	46.2175
894.181	44.1413
894.433	48.3051
894.684	47.8368
894.936	47.9807
895.188	47.3033
895.439	46.5097
895.69	50.5631
895.942	44.9343
896.193	46.8004
896.445	48.4865
896.696	45.8374
896.948	45.4075
897.199	42.8093
897.451	43.3855
897.702	48.2123
897.953	43.6241
898.204	39.5261
898.456	46.5136
898.707	39.4423
898.958	46.1622
899.21	43.7573
899.461	48.0608
899.712	47.0796
899.963	44.6667