File: M5_270224_01.txt
#Acq. time (s)=	3
#Accumulations=	2
#Range (nm)=	520...900
#Windows=	8
#Auto scanning=	Off
#Autofocus=	Off
#AutoExposure=	Off
#Spike filter=	Multiple accum.
#Delay time (s)=	0
#Binning=	1
#Readout mode=	Signal
#DeNoise=	Off
#ICS correction=	Off
#Dark correction=	Off
#Inst. Process=	Off
#Detector temperature (°C)=	-59.98
#Instrument=	LabRAM HR Evol
#Detector=	Syncerity OE
#Objective=	x50_VIS
#Grating=	600 (500nm)
#ND Filter=	10%
#Laser=	514nm_Edge
#Hole=	199.981
#Range=	Auto
#StageXY=	Marzhauser
#StageZ=	Marzhauser
#X (µm)=	0
#Y (µm)=	0
#Z (µm)=	0
#Full time(mm:ss)=	1:32
#Project=
#Sample=
#Site=
#Title=	M5_270224
#Remark=
#Date=	06.03.2024 10:19
#Acquired=	06.03.2024 10:19:02
520.044	24
520.306	28
520.569	26
520.831	26
521.093	26
521.355	28
521.617	26
521.88	18
522.142	22
522.404	30
522.666	28
522.928	18
523.19	16
523.453	26
523.715	30
523.977	26
524.239	22
524.501	24
524.763	24
525.025	26
525.287	22
525.549	22
525.811	30
526.073	30
526.335	24
526.597	28
526.859	24
527.121	24
527.383	18
527.645	26
527.907	28
528.169	30
528.431	20
528.693	24
528.955	30
529.217	24
529.479	30
529.741	26
530.003	28
530.264	30
530.526	32
530.788	20
531.05	24
531.312	24
531.574	26
531.835	32
532.097	28
532.359	34
532.621	32
532.883	36
533.144	28
533.406	34
533.668	28
533.93	28
534.191	20
534.453	32
534.715	44
534.976	36
535.238	30
535.5	30
535.761	30
536.023	42
536.285	36
536.546	32
536.808	36
537.069	30
537.331	34
537.593	28
537.854	28
538.116	28
538.377	32
538.639	28
538.9	24
539.162	34
539.423	34
539.685	26
539.946	32
540.208	28
540.469	34
540.731	32
540.992	28
541.254	26
541.515	36
541.776	36
542.038	30
542.299	28
542.56	36
542.822	30
543.083	30
543.344	26
543.606	38
543.867	36
544.128	38
544.39	26
544.651	34
544.912	28
545.174	36
545.435	36
545.696	28
545.957	44
546.218	40
546.48	36
546.741	34
547.002	42
547.263	42
547.524	32
547.785	34
548.047	40
548.308	40
548.569	32
548.83	28
549.091	42
549.352	44
549.613	42
549.874	34
550.135	44
550.396	50
550.657	60
550.918	50
551.179	50
551.44	66
551.701	84
551.962	88
552.223	164
552.484	1868
552.745	11042
553.006	296
553.267	102
553.528	76
553.788	64
554.049	60
554.31	48
554.571	54
554.832	50
555.093	42
555.353	52
555.614	44
555.875	50
556.136	54
556.396	46
556.657	46
556.918	48
557.179	52
557.439	46
557.7	34
557.961	50
558.221	58
558.482	52
558.743	44
559.003	46
559.264	56
559.525	46
559.785	56
560.046	44
560.306	48
560.567	54
560.827	50
561.088	60
561.348	44
561.609	56
561.869	54
562.13	58
562.39	58
562.651	52
562.911	54
563.172	52
563.432	62
563.692	66
563.953	58
564.213	66
564.474	56
564.734	68
564.994	62
565.255	68
565.515	72
565.775	66
566.035	66
566.296	66
566.556	52
566.816	60
567.076	66
567.337	64
567.597	64
567.857	70
568.117	79.92
568.377	70.0571
568.637	63.7939
568.898	70.7388
569.158	71.2951
569.418	67.2022
569.678	77.054
569.938	75.74
570.198	75.7686
570.458	78.54
570.718	80.6561
570.978	85.1355
571.238	81.9055
571.498	92.4565
571.758	89.2696
572.018	91.3477
572.278	96.1416
572.538	104.119
572.798	101.236
573.058	111.486
573.312	98
573.573	126
573.834	138
574.095	122
574.356	142
574.617	150
574.878	162
575.139	168
575.4	174
575.661	184
575.922	182
576.183	184
576.444	174
576.705	164
576.965	168
577.226	154
577.487	152
577.748	144
578.009	140
578.27	142
578.531	126
578.791	126
579.052	124
579.313	130
579.574	132
579.835	142
580.095	116
580.356	150
580.617	140
580.878	132
581.138	130
581.399	142
581.66	142
581.92	134
582.181	152
582.442	160
582.703	134
582.963	144
583.224	154
583.484	164
583.745	158
584.006	168
584.266	184
584.527	166
584.787	176
585.048	162
585.308	180
585.569	182
585.83	192
586.09	204
586.351	186
586.611	192
586.872	188
587.132	190
587.392	204
587.653	200
587.913	198
588.174	200
588.434	206
588.695	222
588.955	212
589.215	220
589.476	218
589.736	236
589.996	224
590.257	220
590.517	224
590.777	212
591.038	214
591.298	208
591.558	212
591.818	196
592.079	200
592.339	196
592.599	196
592.859	176
593.12	186
593.38	174
593.64	192
593.9	196
594.16	186
594.42	194
594.68	204
594.941	210
595.201	196
595.461	202
595.721	198
595.981	206
596.241	198
596.501	202
596.761	214
597.021	200
597.281	182
597.541	188
597.801	196
598.061	196
598.321	188
598.581	184
598.841	200
599.101	190
599.361	190
599.62	188
599.88	178
600.14	176
600.4	184
600.66	188
600.92	188
601.18	200
601.439	190
601.699	190
601.959	188
602.219	200
602.478	202
602.738	196
602.998	190
603.258	190
603.517	200
603.777	182
604.037	198
604.296	196
604.556	192
604.816	208
605.075	214
605.335	198
605.594	190
605.854	212
606.114	190
606.373	192
606.633	198
606.892	198
607.152	216
607.411	196
607.671	204
607.93	208
608.19	220
608.449	212
608.709	218
608.968	194
609.228	212
609.487	208
609.746	208
610.006	208
610.265	206
610.524	232
610.784	218
611.043	222
611.302	204
611.562	228
611.821	226
612.08	220
612.339	220
612.599	226
612.858	220
613.117	234
613.376	232
613.635	230
613.895	232
614.154	214
614.413	222
614.672	228
614.931	234
615.19	242
615.449	244
615.709	254
615.968	250
616.227	237.824
616.486	242.346
616.745	242.264
617.004	261.505
617.263	250.402
617.522	263.707
617.781	256.486
618.04	252.144
618.299	253.429
618.557	244.294
618.816	257.593
619.075	261.24
619.334	257.87
619.593	263.764
619.852	261.931
620.111	268.484
620.37	267.636
620.628	263.347
620.887	274.634
621.146	271.917
621.373	274
621.633	262
621.893	234
622.153	278
622.413	264
622.673	276
622.932	256
623.192	264
623.452	266
623.712	276
623.972	270
624.232	252
624.492	294
624.751	296
625.011	274
625.271	288
625.531	288
625.791	294
626.05	308
626.31	276
626.57	308
626.83	298
627.089	284
627.349	274
627.609	300
627.868	280
628.128	278
628.388	292
628.647	296
628.907	306
629.167	294
629.426	286
629.686	312
629.945	296
630.205	306
630.465	324
630.724	312
630.984	314
631.243	312
631.503	330
631.762	334
632.022	318
632.281	320
632.541	336
632.8	340
633.06	330
633.319	342
633.579	344
633.838	336
634.097	344
634.357	342
634.616	362
634.876	376
635.135	350
635.394	354
635.654	392
635.913	404
636.172	416
636.431	440
636.691	420
636.95	458
637.209	488
637.469	514
637.728	526
637.987	536
638.246	508
638.505	480
638.765	494
639.024	470
639.283	470
639.542	426
639.801	468
640.06	462
640.319	440
640.578	430
640.838	430
641.097	432
641.356	426
641.615	428
641.874	430
642.133	430
642.392	408
642.651	414
642.91	400
643.169	414
643.428	404
643.687	436
643.946	434
644.205	424
644.463	436
644.722	434
644.981	452
645.24	430
645.499	444
645.758	446
646.017	440
646.275	444
646.534	444
646.793	446
647.052	458
647.31	446
647.569	454
647.828	448
648.087	468
648.345	464
648.604	474
648.863	472
649.121	472
649.38	460
649.639	484
649.897	500
650.156	484
650.415	476
650.673	518
650.932	502
651.19	470
651.449	518
651.707	516
651.966	502
652.224	524
652.483	532
652.741	530
653	526
653.258	512
653.517	526
653.775	508
654.034	528
654.292	550
654.55	540
654.809	538
655.067	572
655.326	546
655.584	562
655.842	606
656.1	558
656.359	584
656.617	606
656.875	594
657.134	608
657.392	614
657.65	614
657.908	606
658.166	638
658.425	618
658.683	640
658.941	592
659.199	634
659.457	636
659.715	606
659.973	638
660.231	612
660.49	630
660.748	612
661.006	610
661.264	630
661.522	622
661.78	630
662.038	638
662.296	630
662.554	630
662.811	640
663.069	626
663.327	628
663.585	624
663.843	626.415
664.101	643.346
664.359	607.148
664.617	623.54
664.874	623.365
665.132	633.104
665.39	620.127
665.648	621.613
665.906	620.116
666.163	612.94
666.421	620.929
666.679	617.95
666.937	621.816
667.194	618.973
667.452	623.53
667.71	619.572
667.967	619.053
668.225	606.116
668.482	635.279
668.74	602.906
668.987	608
669.245	636
669.504	658
669.763	646
670.022	626
670.281	620
670.539	626
670.798	620
671.057	608
671.316	632
671.575	654
671.833	622
672.092	620
672.351	640
672.609	634
672.868	626
673.127	640
673.385	636
673.644	650
673.903	616
674.161	660
674.42	626
674.678	660
674.937	640
675.195	664
675.454	648
675.713	642
675.971	642
676.23	670
676.488	688
676.747	676
677.005	668
677.263	658
677.522	674
677.78	646
678.039	658
678.297	678
678.556	668
678.814	682
679.072	648
679.331	684
679.589	672
679.847	666
680.106	676
680.364	722
680.622	696
680.881	668
681.139	678
681.397	650
681.656	710
681.914	688
682.172	730
682.43	698
682.688	676
682.947	686
683.205	690
683.463	666
683.721	702
683.979	698
684.237	708
684.495	672
684.754	690
685.012	700
685.27	712
685.528	668
685.786	698
686.044	692
686.302	666
686.56	680
686.818	686
687.076	682
687.334	662
687.592	694
687.85	684
688.108	698
688.366	686
688.623	660
688.881	682
689.139	670
689.397	648
689.655	660
689.913	664
690.171	676
690.428	642
690.686	660
690.944	652
691.202	688
691.459	664
691.717	670
691.975	654
692.233	652
692.49	646
692.748	650
693.006	630
693.263	652
693.521	654
693.779	658
694.036	640
694.294	640
694.552	644
694.809	630
695.067	634
695.324	614
695.582	636
695.839	628
696.097	636
696.354	638
696.612	624
696.869	642
697.127	638
697.384	652
697.642	644
697.899	620
698.156	610
698.414	612
698.671	606
698.928	618
699.186	626
699.443	630
699.7	602
699.958	584
700.215	620
700.472	618
700.73	604
700.987	590
701.244	618
701.501	616
701.758	596
702.016	606
702.273	608
702.53	614
702.787	620
703.044	614
703.301	592
703.558	584
703.816	616
704.073	618
704.33	602
704.587	590
704.844	598
705.101	576
705.358	572
705.615	568
705.872	582
706.129	560
706.386	588
706.643	584
706.899	588
707.156	562
707.413	572
707.67	562
707.927	556
708.184	564
708.441	556
708.697	554
708.954	546
709.211	524
709.468	560
709.725	558
709.981	540
710.238	548
710.495	546
710.751	560
711.008	548
711.265	536.168
711.521	548.515
711.778	569.724
712.035	542.579
712.291	532.702
712.548	531.911
712.804	525.898
713.061	524.42
713.317	524.6
713.574	534.792
713.831	522.662
714.087	515.64
714.343	497.964
714.6	518.615
714.856	507.051
715.113	514.151
715.369	513.375
715.626	505.511
715.882	502.168
716.138	494.122
716.395	502.627
716.639	504
716.897	472
717.155	484
717.412	500
717.67	508
717.927	476
718.185	490
718.443	510
718.7	492
718.958	478
719.215	488
719.473	488
719.73	484
719.988	480
720.245	450
720.503	476
720.76	464
721.018	468
721.275	462
721.532	462
721.79	460
722.047	470
722.305	440
722.562	468
722.819	440
723.077	454
723.334	444
723.591	450
723.849	426
724.106	442
724.363	452
724.621	430
724.878	444
725.135	430
725.392	452
725.65	422
725.907	422
726.164	424
726.421	422
726.678	430
726.935	428
727.193	422
727.45	424
727.707	416
727.964	420
728.221	406
728.478	412
728.735	398
728.992	394
729.249	408
729.506	376
729.763	404
730.02	362
730.277	400
730.534	358
730.791	392
731.048	398
731.305	364
731.562	378
731.819	386
732.076	382
732.333	384
732.589	390
732.846	368
733.103	372
733.36	348
733.617	380
733.873	376
734.13	388
734.387	348
734.644	364
734.901	378
735.157	368
735.414	372
735.671	394
735.927	384
736.184	382
736.441	382
736.697	398
736.954	402
737.211	400
737.467	390
737.724	410
737.98	422
738.237	424
738.493	402
738.75	402
739.006	414
739.263	372
739.519	386
739.776	390
740.032	396
740.289	378
740.545	354
740.802	364
741.058	358
741.314	354
741.571	362
741.827	356
742.083	346
742.34	340
742.596	338
742.852	328
743.109	340
743.365	348
743.621	316
743.878	336
744.134	330
744.39	332
744.646	324
744.902	326
745.159	330
745.415	320
745.671	320
745.927	326
746.183	296
746.439	318
746.695	314
746.951	300
747.207	330
747.463	306
747.719	294
747.975	304
748.231	296
748.487	306
748.743	278
748.999	296
749.255	296
749.511	292
749.767	292
750.023	306
750.279	280
750.535	312
750.791	288
751.046	278
751.302	280
751.558	284
751.814	286
752.07	276
752.325	270
752.581	294
752.837	290
753.092	266
753.348	278
753.604	280
753.859	282
754.115	282
754.371	278
754.626	262
754.882	264
755.138	262
755.393	252
755.649	264
755.904	244
756.16	274
756.415	260
756.671	256
756.926	234
757.182	252
757.437	238
757.693	252
757.948	236
758.203	248
758.459	236
758.714	263.118
758.97	252.936
759.225	242.241
759.48	232.601
759.736	239.979
759.991	243.027
760.246	232.778
760.501	238.902
760.757	237.363
761.012	243.708
761.267	241.591
761.522	227.298
761.777	231.203
762.033	233.378
762.288	228.225
762.543	223.565
762.798	220.773
763.053	217.136
763.308	229.575
763.563	223.814
763.78	220
764.037	214
764.293	226
764.55	206
764.806	228
765.062	212
765.319	230
765.575	226
765.831	216
766.088	220
766.344	206
766.6	220
766.857	208
767.113	202
767.369	208
767.625	220
767.882	200
768.138	214
768.394	208
768.65	208
768.906	196
769.163	198
769.419	200
769.675	202
769.931	212
770.187	178
770.443	196
770.699	194
770.955	194
771.211	176
771.467	200
771.723	184
771.979	184
772.235	196
772.491	194
772.747	190
773.003	182
773.259	174
773.515	174
773.771	178
774.027	172
774.283	160
774.539	194
774.795	174
775.05	168
775.306	178
775.562	178
775.818	170
776.074	158
776.329	154
776.585	174
776.841	178
777.097	162
777.352	164
777.608	146
777.864	166
778.12	142
778.375	168
778.631	166
778.886	152
779.142	162
779.398	150
779.653	182
779.909	158
780.164	142
780.42	154
780.675	140
780.931	154
781.187	140
781.442	156
781.698	140
781.953	154
782.208	146
782.464	138
782.719	142
782.975	138
783.23	156
783.485	148
783.741	136
783.996	132
784.252	130
784.507	134
784.762	140
785.017	138
785.273	116
785.528	126
785.783	140
786.038	140
786.294	116
786.549	136
786.804	124
787.059	136
787.314	124
787.57	122
787.825	138
788.08	130
788.335	130
788.59	122
788.845	126
789.1	116
789.355	132
789.61	122
789.865	114
790.12	118
790.375	126
790.63	126
790.885	110
791.14	130
791.395	122
791.65	118
791.905	106
792.16	118
792.414	116
792.669	110
792.924	112
793.179	112
793.434	112
793.689	110
793.943	98
794.198	116
794.453	116
794.708	108
794.962	114
795.217	112
795.472	104
795.726	102
795.981	106
796.236	106
796.49	100
796.745	104
796.999	98
797.254	108
797.508	98
797.763	102
798.018	98
798.272	98
798.526	104
798.781	96
799.035	86
799.29	94
799.544	94
799.799	94
800.053	90
800.307	92
800.562	86
800.816	98
801.07	82
801.325	92
801.579	88
801.833	86
802.088	92
802.342	88
802.596	86
802.85	84
803.105	100
803.359	76
803.613	80
803.867	76
804.121	90
804.375	94
804.63	82
804.884	80
805.138	90
805.392	80
805.646	74.1194
805.9	72.5309
806.154	86.7394
806.408	85.1224
806.662	81.8574
806.916	83.6765
807.17	80
807.424	75.9094
807.678	83.1758
807.931	75.3011
808.185	79.488
808.439	70.7634
808.693	83.2719
808.947	70.5466
809.201	74.0635
809.454	69.2696
809.708	77.9843
809.962	75.0536
810.216	77.9737
810.469	88.545
810.678	76
810.933	72
811.188	86
811.443	72
811.699	78
811.954	74
812.209	78
812.464	72
812.719	76
812.974	62
813.229	70
813.484	76
813.739	68
813.994	66
814.249	76
814.504	62
814.759	74
815.014	68
815.268	72
815.523	74
815.778	66
816.033	74
816.288	62
816.543	74
816.798	64
817.052	72
817.307	64
817.562	64
817.817	68
818.071	60
818.326	74
818.581	60
818.836	66
819.09	72
819.345	76
819.6	62
819.854	68
820.109	54
820.364	66
820.618	64
820.873	68
821.127	54
821.382	62
821.637	54
821.891	56
822.146	62
822.4	60
822.655	66
822.909	56
823.164	54
823.418	60
823.672	62
823.927	58
824.181	66
824.436	58
824.69	62
824.944	54
825.199	66
825.453	48
825.707	60
825.962	36
826.216	48
826.47	48
826.725	58
826.979	52
827.233	56
827.487	64
827.741	50
827.996	58
828.25	50
828.504	58
828.758	60
829.012	58
829.266	56
829.52	60
829.774	50
830.029	44
830.283	50
830.537	52
830.791	44
831.045	48
831.299	56
831.553	48
831.807	58
832.061	50
832.315	64
832.568	50
832.822	62
833.076	56
833.33	52
833.584	52
833.838	48
834.092	48
834.345	48
834.599	48
834.853	54
835.107	48
835.36	48
835.614	54
835.868	46
836.122	56
836.375	44
836.629	54
836.883	54
837.136	50
837.39	56
837.643	48
837.897	48
838.151	54
838.404	52
838.658	42
838.911	46
839.165	44
839.418	48
839.672	52
839.925	52
840.179	40
840.432	46
840.686	40
840.939	44
841.192	52
841.446	48
841.699	44
841.952	44
842.206	42
842.459	44
842.712	42
842.966	50
843.219	42
843.472	38
843.725	48
843.979	42
844.232	44
844.485	38
844.738	50
844.991	50
845.244	48
845.497	48
845.75	46
846.004	46
846.257	42
846.51	34
846.763	42
847.016	46
847.269	50
847.522	48
847.775	48
848.028	46
848.281	44
848.534	46
848.786	40
849.039	38
849.292	46
849.545	50
849.798	38
850.051	44
850.303	32
850.556	34
850.809	42
851.062	42
851.314	46
851.567	30
851.82	40
852.073	40
852.325	43.9712
852.578	36.0004
852.831	39.2024
853.083	37.1035
853.336	45.3183
853.588	42.851
853.841	36.7646
854.093	29.7679
854.346	40.8061
854.598	38.91
854.851	35.2407
855.103	38.6524
855.356	38.9933
855.608	41.6228
855.861	38.8139
856.113	36.6025
856.366	34.78
856.618	35.3729
856.87	38.0464
857.123	40.6248
857.352	40
857.606	32
857.859	48
858.113	34
858.367	36
858.621	40
858.875	40
859.128	38
859.382	46
859.636	26
859.889	36
860.143	32
860.397	36
860.65	36
860.904	34
861.158	34
861.411	38
861.665	46
861.918	28
862.172	40
862.425	36
862.679	42
862.932	42
863.186	44
863.439	38
863.693	36
863.946	38
864.2	38
864.453	40
864.707	32
864.96	44
865.213	36
865.467	40
865.72	40
865.973	32
866.227	26
866.48	28
866.733	38
866.987	34
867.24	34
867.493	34
867.746	46
867.999	40
868.253	36
868.506	40
868.759	32
869.012	26
869.265	32
869.518	34
869.771	42
870.025	48
870.278	38
870.531	28
870.784	32
871.037	36
871.29	28
871.543	40
871.796	36
872.049	42
872.302	32
872.555	36
872.808	34
873.06	34
873.313	36
873.566	26
873.819	28
874.072	38
874.325	40
874.578	34
874.83	34
875.083	34
875.336	36
875.589	34
875.841	34
876.094	26
876.347	38
876.6	36
876.852	34
877.105	34
877.358	32
877.61	36
877.863	36
878.115	34
878.368	36
878.621	40
878.873	36
879.126	30
879.378	40
879.631	38
879.883	36
880.136	32
880.388	38
880.641	40
880.893	42
881.145	28
881.398	32
881.65	30
881.902	32
882.155	36
882.407	26
882.659	32
882.912	38
883.164	34
883.416	24
883.669	34
883.921	34
884.173	34
884.425	24
884.677	34
884.93	36
885.182	42
885.434	26
885.686	36
885.938	38
886.19	30
886.442	28
886.694	32
886.946	30
887.198	40
887.45	36
887.702	26
887.954	26
888.206	36
888.458	28
888.71	32
888.962	26
889.214	42
889.466	38
889.718	24
889.969	30
890.221	30
890.473	24
890.725	36
890.977	30
891.228	32
891.48	40
891.732	26
891.983	26
892.235	18
892.487	34
892.738	30
892.99	26
893.242	30
893.493	28
893.745	40
893.996	30
894.248	28
894.5	30
894.751	32
895.003	30
895.254	16
895.505	30
895.757	32
896.008	36
896.26	20
896.511	22
896.763	38
897.014	28
897.265	30
897.517	30
897.768	32
898.019	32
898.27	26
898.522	28
898.773	28
899.024	34
899.275	26
899.527	24
899.778	28
899.979	22