File: M6_140224_01.txt
#Acq. time (s)=	2
#Accumulations=	3
#Range (nm)=	520...900
#Windows=	24
#Auto scanning=	On
#Autofocus=	Off
#AutoExposure=	Off
#Spike filter=	Multiple accum.
#Delay time (s)=	0
#Binning=	1
#Readout mode=	Signal
#DeNoise=	Off
#ICS correction=	Off
#Dark correction=	Off
#Inst. Process=	Off
#Detector temperature (°C)=	-59.98
#Instrument=	LabRAM HR Evol
#Detector=	Syncerity OE
#Objective=	x50_VIS
#Grating=	600 (500nm)
#ND Filter=	10%
#Laser=	514nm_Edge
#Hole=	199.981
#Range=	Auto
#StageXY=	Marzhauser
#StageZ=	Marzhauser
#X (µm)=	23190.1
#Y (µm)=	2761.6
#Z (µm)=	27.7
#Full time(mm:ss)=	3:04
#Project=
#Sample=
#Site=
#Title=	M6_140224
#Remark=
#Date=	19.02.2024 14:38
#Acquired=	19.02.2024 14:38:56
520.013	28.6948
520.274	23.7175
520.536	25.3955
520.797	28.1151
521.059	25.3333
521.32	22.6977
521.582	30.7616
521.843	29.2974
522.105	25.3908
522.366	24.4612
522.628	27.9627
522.889	24.6519
523.15	23.8377
523.412	25.9019
523.673	27.5224
523.935	24.1136
524.196	24.8856
524.457	30.1968
524.719	27.5483
524.98	27.3504
525.241	22.8359
525.503	27.7444
525.764	27.4965
526.025	24.1648
526.286	25.287
526.548	30.2427
526.809	27.5335
527.07	27.1565
527.331	26.3234
527.593	28.4
527.854	28.2657
528.115	22.3352
528.376	26.0963
528.637	26
528.898	25.3284
529.16	26.9214
529.421	28.4849
529.682	24.4458
529.943	29.1325
530.204	26.356
530.465	25.6646
530.726	26.4783
530.987	29.8144
531.248	23.3119
531.509	28.5978
531.77	28.824
532.031	24.6713
532.292	23.8877
532.553	30.9312
532.814	27.7127
533.075	23.9419
533.336	22.1428
533.597	27.4364
533.858	30.2418
534.119	26.9677
534.38	27.2828
534.641	26.3521
534.901	27.6687
535.162	21.8563
535.423	24.6632
535.684	29.2811
535.945	27.8929
536.205	23.046
536.466	31.1874
536.727	33.3428
536.988	24.267
537.248	24.3311
537.509	28.6396
537.77	29.4575
537.987	26.1537
538.249	20.5921
538.51	29.4711
538.771	28.2246
539.032	28.9002
539.293	23.5999
539.554	30.2744
539.815	28.4157
540.076	25.6376
540.337	25.1614
540.598	28.0558
540.859	31.6584
541.12	24.9592
541.381	25.9801
541.642	26.8552
541.903	30.4218
542.164	27.5958
542.425	29.6879
542.686	26.4181
542.947	27.1419
543.208	23.9856
543.469	29.2869
543.73	27.5102
543.991	26.7304
544.252	22.0678
544.513	24.2957
544.773	24.1573
545.034	23.9109
545.295	26.2169
545.556	29.2834
545.817	31.5159
546.077	22.1692
546.338	30.0631
546.599	33.089
546.86	30.007
547.12	21.2494
547.381	28.1988
547.642	27.4318
547.903	31.333
548.163	25.1964
548.424	31.1045
548.685	28.275
548.945	24.2975
549.206	26.6282
549.467	30.9805
549.727	33.556
549.988	24.9146
550.248	31.8367
550.509	38.327
550.769	30.467
551.03	28.6683
551.291	38.5141
551.551	43.4232
551.812	50.7758
552.072	67.2618
552.332	165.143
552.593	3690.4
552.853	1052.26
553.114	89.7343
553.374	57.5976
553.635	44.0193
553.895	33.4897
554.155	29.4376
554.416	38.4914
554.676	35.2618
554.937	28.2158
555.197	28.1303
555.457	29.7471
555.686	28.0599
555.947	29.1388
556.207	29.9475
556.468	31.6356
556.729	30.3086
556.99	23.1429
557.25	31.2739
557.511	31.146
557.772	26.9678
558.032	23.6616
558.293	29.9687
558.554	30.0264
558.814	30.9261
559.075	25.7953
559.336	30.2
559.596	31.9777
559.857	28.3768
560.117	27.5905
560.378	29.3587
560.638	30.3315
560.899	27.7525
561.159	28.0554
561.42	32.985
561.68	31.5993
561.941	27.9754
562.201	29.9112
562.462	32.3967
562.722	32.791
562.983	27.6978
563.243	32.0347
563.504	32.6955
563.764	30.3315
564.024	26.3665
564.285	31.0905
564.545	33.9203
564.805	31.8428
565.066	30.6457
565.326	30.9338
565.586	34.8415
565.847	33.2799
566.107	31.0168
566.367	31.1538
566.627	32.7972
566.888	28.024
567.148	28.5151
567.408	34.9243
567.668	30.8746
567.928	30.508
568.189	34.0593
568.449	34.5727
568.709	32.8601
568.969	32.5845
569.229	29.3035
569.489	31.783
569.749	33.4935
570.009	30.4938
570.269	35.6164
570.53	34.1007
570.79	35.153
571.05	31.6962
571.31	33.7537
571.57	36.6308
571.83	33.8649
572.09	34.9301
572.349	32.0566
572.609	35.9675
572.869	33.8424
573.129	35.2074
573.368	41.375
573.629	39.0801
573.889	40.0655
574.15	38.4999
574.41	38.2706
574.67	44.0252
574.931	36.7689
575.191	45.2316
575.451	43.6705
575.711	45.9202
575.972	47.7354
576.232	43.3072
576.492	42.266
576.752	39.0314
577.013	37.4584
577.273	41.4252
577.533	44.2718
577.793	39.7467
578.053	40.9481
578.313	39.6131
578.574	39.2295
578.834	36.1464
579.094	37.4981
579.354	41.6899
579.614	42.0943
579.874	45.1496
580.134	41.8786
580.394	42.3016
580.654	41.3282
580.914	43.0209
581.174	44.1629
581.434	42.8446
581.694	47.4559
581.954	44.4828
582.214	48.2018
582.474	44.9746
582.734	50.1362
582.994	52.2815
583.254	50.2249
583.514	50.3909
583.773	50.5618
584.033	53.8104
584.293	51.9221
584.553	56.9275
584.813	54.3702
585.073	52.9748
585.332	56.9458
585.592	56.3678
585.852	56.8843
586.112	57.5618
586.371	58.7029
586.631	60.1209
586.891	64.0598
587.151	60.8581
587.41	65.4172
587.67	62.5527
587.93	62.0606
588.189	68.2826
588.449	70.4892
588.709	63.6278
588.968	67.5569
589.228	77.8823
589.487	79.6908
589.747	75.1319
590.006	73.7244
590.266	70.134
590.525	73.5446
590.785	67.3858
591.036	70.9169
591.296	67.9094
591.556	62.8198
591.816	55.2843
592.076	59.8572
592.336	61.4623
592.596	55.0143
592.856	48.5744
593.116	57.3637
593.376	58.0696
593.635	53.7352
593.895	55.4656
594.155	50.6953
594.415	52.9676
594.675	50.7812
594.935	54.7266
595.194	61.5121
595.454	53.8365
595.714	57.2467
595.974	57.873
596.233	66.0978
596.493	65.9744
596.753	68.9956
597.012	56.9043
597.272	55.6905
597.532	55.6998
597.791	52.1931
598.051	57.3582
598.311	56.8703
598.57	50.3733
598.83	52.3501
599.089	49.3894
599.349	52.2959
599.609	50.1732
599.868	50.3802
600.128	51.0035
600.387	44.636
600.647	45.5558
600.906	51.1677
601.166	49.8186
601.425	48.0506
601.685	49.2701
601.944	51.6806
602.203	43.9108
602.463	51.6198
602.722	45.5752
602.982	52.0905
603.241	52.0571
603.5	50.7507
603.76	49.2578
604.019	51.6371
604.278	51.7167
604.538	50.0504
604.797	53.5332
605.056	50.506
605.315	51.7832
605.575	52.8375
605.834	50.5193
606.093	53.0794
606.352	53.4839
606.611	50.2956
606.871	54.3639
607.13	56.4914
607.389	45.8086
607.648	50.7479
607.907	53.6458
608.166	47.7584
608.425	53.1462
608.664	47.3359
608.924	53.2758
609.183	51.9508
609.443	58.76
609.702	54.1649
609.962	48.5673
610.221	57.0618
610.481	53.4035
610.74	57.3391
611	51.4132
611.259	56.471
611.518	61.4214
611.778	58.4815
612.037	52.5232
612.297	59.4188
612.556	54.6893
612.815	54.6721
613.075	53.3872
613.334	55.1515
613.594	56.6369
613.853	54.9934
614.112	58.1559
614.371	56.6224
614.631	57.6161
614.89	48.6976
615.149	56.9014
615.408	56.8275
615.668	52.7653
615.927	59.944
616.186	54.7024
616.445	59.5906
616.704	57.7805
616.964	53.3305
617.223	60.6307
617.482	56.9987
617.741	49.3507
618	53.495
618.259	61.3813
618.518	66.7414
618.777	56.7942
619.036	62.2715
619.295	62.8793
619.554	65.6941
619.813	57.9931
620.072	61.5181
620.331	62.0539
620.59	53.4011
620.849	58.3789
621.108	62.9084
621.367	56.5513
621.626	60.1694
621.885	60.683
622.144	61.9823
622.403	61.0883
622.661	56.5243
622.92	60.874
623.179	65.5304
623.438	60.9349
623.697	56.2764
623.956	57.0746
624.214	60.0285
624.473	57.8989
624.732	54.3601
624.99	57.0704
625.249	63.9074
625.508	59.6261
625.767	59.368
626.025	56.6726
626.249	61.5168
626.508	64.8747
626.767	55.6402
627.026	56.5009
627.285	59.488
627.544	60.5759
627.803	61.43
628.062	57.7184
628.321	59.8626
628.58	61.478
628.839	54.7244
629.098	60.0259
629.357	64.5316
629.616	58.1986
629.875	59.5357
630.134	57.2492
630.393	60.5944
630.652	61.555
630.911	63.6624
631.17	61.5191
631.429	59.6298
631.688	58.3052
631.947	61.0017
632.206	61.0387
632.464	66.2956
632.723	62.0236
632.982	58.9542
633.241	65.9976
633.5	60.0166
633.758	60.6234
634.017	63.7827
634.276	65.129
634.535	61.8207
634.793	66.6188
635.052	64.364
635.311	72.2653
635.57	64.1829
635.828	65.455
636.087	63.9847
636.345	70.1103
636.604	62.8816
636.863	64.5607
637.121	66.9313
637.38	68.3195
637.638	70.3257
637.897	68.338
638.156	68.9958
638.414	72.119
638.673	76.4674
638.931	65.6859
639.19	75.9213
639.448	66.3827
639.706	67.6483
639.965	61.749
640.223	68.5166
640.482	69.6507
640.74	64.8133
640.999	60.1148
641.257	66.9654
641.515	66.7073
641.774	62.952
642.032	61.0522
642.29	66.4321
642.549	67.3758
642.807	60.6587
643.065	67.2893
643.323	65.8528
643.582	65.0141
643.84	66.6641
644.053	64.4771
644.312	72.7588
644.57	69.2351
644.829	59.0722
645.088	64.1972
645.346	62.2617
645.605	72.494
645.864	66.9303
646.122	59.0157
646.381	72.0191
646.639	67.7771
646.898	57.1421
647.157	69.3326
647.415	62.2449
647.674	64.2121
647.932	61.8028
648.191	68.9291
648.449	61.6864
648.708	64.0505
648.966	58.1643
649.225	66.2713
649.483	67.6412
649.742	63.4688
650	65.0278
650.258	64.8041
650.517	60.584
650.775	61.1221
651.034	64.0183
651.292	54.4105
651.55	66.3166
651.809	71.6062
652.067	67.5269
652.325	59.0947
652.583	72.6651
652.842	65.1174
653.1	66.1963
653.358	66.0496
653.616	67.7868
653.875	66.5634
654.133	66.2013
654.391	62.9353
654.649	66.4981
654.907	66.1208
655.165	69.8239
655.424	70.9583
655.682	63.0647
655.94	71.3676
656.198	67.3799
656.456	72.4199
656.714	61.5739
656.972	68.8508
657.23	63.768
657.488	64.4891
657.746	71.2347
658.004	69.2974
658.262	67.908
658.52	74.0573
658.778	70.1142
659.036	68.7683
659.294	68.4642
659.552	72.8851
659.809	71.2217
660.067	71.0753
660.325	69.4542
660.583	69.3577
660.841	71.8439
661.099	66.7498
661.356	72.6952
661.583	67.0588
661.842	69.6492
662.1	70.5964
662.358	65.2722
662.616	70.7172
662.875	75.4001
663.133	68.9548
663.391	67.7684
663.649	69.7386
663.907	71.6553
664.166	68.2371
664.424	67.6693
664.682	63.2432
664.94	71.0787
665.198	67.1103
665.456	68.0323
665.714	70.9902
665.972	65.6951
666.23	67.0425
666.488	61.4421
666.746	71.1031
667.004	64.623
667.262	65.7789
667.52	58.8775
667.778	72.9244
668.036	66.1883
668.294	61.8531
668.552	69.3739
668.81	72.6312
669.068	61.5346
669.326	66.0888
669.584	66.9653
669.842	61.3981
670.099	67.289
670.357	66.7607
670.615	67.7335
670.873	67.3542
671.131	65.1792
671.388	67.0075
671.646	60.5372
671.904	63.7076
672.162	62.3451
672.419	72.0896
672.677	60.3792
672.935	68.3865
673.192	65.7963
673.45	63.9122
673.708	65.2838
673.965	67.4526
674.223	62.6589
674.481	71.3352
674.738	68.4245
674.996	65.5746
675.253	69.0485
675.511	71.3255
675.768	67.732
676.026	67.6186
676.283	68.7269
676.541	71.4587
676.798	66.9182
677.056	66.4444
677.313	66.9647
677.571	65.3133
677.828	72.9921
678.085	67.0087
678.343	70.9005
678.6	69.1552
678.857	63.7174
679.083	62.2896
679.341	66.5
679.599	69.065
679.857	63.094
680.114	68.0848
680.372	66.4048
680.63	65.7483
680.888	69.1584
681.146	65.9468
681.403	73.5686
681.661	67.2014
681.919	65.6936
682.176	63.7272
682.434	70.9027
682.692	69.3644
682.949	67.6188
683.207	67.9838
683.465	68.2188
683.722	68.6493
683.98	66.0344
684.237	71.8143
684.495	63.01
684.753	69.5174
685.01	63.8571
685.268	69.6486
685.525	63.9521
685.783	61.9134
686.04	61.6554
686.298	60.1962
686.555	54.1045
686.813	64.2899
687.07	68.1046
687.327	66.4436
687.585	64.1589
687.842	67.3295
688.1	63.0417
688.357	67.8498
688.614	67.8887
688.872	59.4003
689.129	70.3108
689.386	64.6947
689.643	64.9211
689.901	63.0828
690.158	59.1813
690.415	60.8662
690.672	67.2404
690.93	58.5308
691.187	61.5232
691.444	67.3048
691.701	64.8837
691.958	60.3045
692.216	61.7262
692.473	67.2377
692.73	60.0866
692.987	68.6563
693.244	60.2597
693.501	65.3473
693.758	62.2243
694.015	62.8323
694.272	62.9424
694.529	63.3323
694.786	63.071
695.043	64.526
695.3	66.8778
695.557	62.5734
695.814	64.3698
696.071	63.3099
696.328	64.2405
696.585	60.4987
696.81	60.1481
697.068	64.2448
697.325	50.1068
697.582	62.5586
697.84	58.6174
698.097	62.7288
698.354	63.3625
698.612	64.9978
698.869	58.5182
699.126	58.3564
699.384	59.2149
699.641	59.131
699.898	59.9793
700.155	63.2677
700.413	57.4696
700.67	60.9687
700.927	55.8042
701.184	56.843
701.441	61.7798
701.698	61.7485
701.956	62.8337
702.213	59.3288
702.47	61.8331
702.727	61.2204
702.984	62.9754
703.241	64.1185
703.498	54.7998
703.755	61.2278
704.012	59.4044
704.269	59.8371
704.526	58.7823
704.783	58.8258
705.04	57.8855
705.297	57.6029
705.554	58.1234
705.811	57.0578
706.068	57.0411
706.324	58.7437
706.581	57.5414
706.838	58.7029
707.095	53.9144
707.352	53.5764
707.609	61.4059
707.865	59.1255
708.122	59.2769
708.379	59.4407
708.636	58.8558
708.892	52.1597
709.149	53.9068
709.406	59.4533
709.662	55.194
709.919	54.256
710.176	58.0692
710.432	56.6273
710.689	55.1047
710.946	59.9333
711.202	59.3881
711.459	59.8385
711.715	54.1699
711.972	54.6188
712.228	55.2188
712.485	60.112
712.741	53.3333
712.998	53.5135
713.254	55.7167
713.511	56.1273
713.767	54.4636
714.024	54.116
714.231	55.3674
714.488	59.0684
714.745	58.7904
715.002	50.65
715.259	55.6426
715.516	58.5211
715.773	51.3748
716.029	51.992
716.286	59.0687
716.543	51.9486
716.8	53.0978
717.057	56.1358
717.314	56.9739
717.57	55.3079
717.827	51.3968
718.084	50.9688
718.341	55.6679
718.597	48.3711
718.854	52.6151
719.111	53.0571
719.367	54.0862
719.624	54.0673
719.881	51.4467
720.137	53.8593
720.394	53.8411
720.65	49.737
720.907	56.0807
721.164	50.7606
721.42	53.1137
721.677	53.8916
721.933	55.9656
722.19	60.0161
722.446	54.1818
722.703	50.9828
722.959	52.8111
723.216	53.7975
723.472	54.8023
723.728	51.4244
723.985	54.4754
724.241	51.0568
724.498	53.6989
724.754	52.7792
725.01	54.3419
725.267	56.8821
725.523	58.0572
725.779	51.9989
726.036	58.8483
726.292	56.8703
726.548	58.1656
726.804	51.7785
727.06	50.1581
727.317	51.6266
727.573	55.013
727.829	57.3225
728.085	54.6597
728.341	53.8343
728.597	53.9297
728.854	57.2086
729.11	51.9964
729.366	59.0706
729.622	51.8688
729.878	55.967
730.134	55.3536
730.39	54.4214
730.646	50.9541
730.902	63.5146
731.158	62.5873
731.414	59.4941
731.622	53.3289
731.878	57.4429
732.135	61.1485
732.391	58.4818
732.648	59.3913
732.904	58.0025
733.161	65.3291
733.417	60.1251
733.673	63.7921
733.93	64.2628
734.186	67.1733
734.443	68.7279
734.699	68.0428
734.955	73.5578
735.211	74.0872
735.468	75.8401
735.724	81.747
735.98	83.6751
736.237	92.5237
736.493	92.7232
736.749	99.9199
737.005	105.502
737.261	101.574
737.518	114.415
737.774	124.523
738.03	116.301
738.286	126.078
738.542	124.559
738.798	119.422
739.054	120.037
739.31	109.556
739.566	112.905
739.822	100.221
740.078	101.074
740.334	95.183
740.59	89.6044
740.846	88.6581
741.102	82.8061
741.358	71.6612
741.614	75.6156
741.87	71.2926
742.126	74.7926
742.382	66.142
742.638	71.8699
742.893	61.3152
743.149	66.3904
743.405	59.328
743.661	62.5015
743.917	60.7503
744.172	61.108
744.428	61.7965
744.684	54.8385
744.94	56.5872
745.195	55.5625
745.451	55.271
745.707	57.6161
745.962	54.4165
746.218	52.167
746.474	54.625
746.729	50.9783
746.985	52.8774
747.241	55.2701
747.496	57.0026
747.752	56.3233
748.007	56.0115
748.263	49.3746
748.518	48.5048
748.774	51.9155
749.029	52.1991
749.275	47.6046
749.531	52.236
749.787	46.7193
750.043	53.3739
750.299	53.8607
750.555	51.316
750.811	47.3892
751.067	52.5545
751.323	47.2597
751.579	48.3092
751.835	48.3947
752.09	47.8221
752.346	45.547
752.602	50.7393
752.858	53.6124
753.114	50.3516
753.37	45.8267
753.625	51.5554
753.881	47.7637
754.137	41.8602
754.393	46.2504
754.648	46.2125
754.904	52.0948
755.16	43.4685
755.415	44.319
755.671	49.0575
755.927	49.0096
756.182	43.9934
756.438	45.2997
756.693	51.732
756.949	43.5351
757.205	43.1471
757.46	47.9398
757.716	48.2605
757.971	47.6972
758.227	43.8244
758.482	47.6199
758.738	48.6144
758.993	43.9746
759.248	46.6693
759.504	47.2175
759.759	45.8767
760.015	45.1376
760.27	46.0159
760.525	47.321
760.781	45.0039
761.036	45.9036
761.291	44.121
761.547	44.0234
761.802	45.8136
762.057	44.3174
762.313	44.6777
762.568	47.2904
762.823	45.1301
763.078	45.5754
763.333	46.7881
763.589	46.6615
763.844	47.8168
764.099	45.6808
764.354	49.5717
764.609	44.2408
764.864	40.99
765.119	43.9344
765.374	46.2763
765.629	41.6938
765.884	43.9389
766.139	43.334
766.394	44.5883
766.649	41.3452
766.882	43.8373
767.137	46.5693
767.393	41.9585
767.648	44.7357
767.904	38.1803
768.159	47.814
768.415	43.0303
768.67	44.6171
768.926	40.244
769.181	44.0414
769.436	45.5728
769.692	41.5376
769.947	40.5057
770.203	40.1073
770.458	41.2123
770.713	41.4313
770.968	41.6051
771.224	39.4685
771.479	39.145
771.734	39.4039
771.99	41.991
772.245	45.4934
772.5	41.2578
772.755	37.8258
773.01	37.4818
773.265	37.1171
773.521	39.2107
773.776	37.3745
774.031	39.4213
774.286	38.9033
774.541	42.2658
774.796	36.2327
775.051	38.9785
775.306	41.4036
775.561	37.3221
775.816	37.9362
776.071	41.1356
776.326	38.3918
776.581	37.0679
776.836	36.5466
777.091	38.3867
777.346	41.5795
777.601	37.3028
777.856	39.7436
778.111	36.7736
778.365	38.8863
778.62	37.428
778.875	35.6277
779.13	35.8845
779.385	39.0743
779.639	35.7941
779.894	37.5656
780.149	37.3623
780.404	36.2613
780.658	35.873
780.913	34.1321
781.168	38.5561
781.422	35.3971
781.677	34.3557
781.932	31.8891
782.186	35.5895
782.441	35.877
782.695	36.8453
782.95	37.218
783.204	33.0107
783.459	32.4237
783.714	40.4492
783.968	34.1584
784.211	36.1701
784.466	36.665
784.721	36.8178
784.976	36.5406
785.231	32.9264
785.486	34.0588
785.741	39.9375
785.996	35.6158
786.251	35.4652
786.506	32.1233
786.761	32.6788
787.016	32.1241
787.271	36.9165
787.526	35.6551
787.78	36.7336
788.035	35.0887
788.29	35.4954
788.545	32.7505
788.8	32.2353
789.054	32.0646
789.309	32.0922
789.564	33.9326
789.819	32.4846
790.073	33.7499
790.328	28.1345
790.583	33.9592
790.837	29.5472
791.092	31.3975
791.347	30.2456
791.601	31.1549
791.856	34.6336
792.11	33.6371
792.365	36.1659
792.619	33.8205
792.874	30.8238
793.128	33.2655
793.383	34.5877
793.638	32.1382
793.892	32.7139
794.146	33.7421
794.401	32.5847
794.655	31.7104
794.91	29.9106
795.164	32.3518
795.418	36.6046
795.673	29.8472
795.927	33.9545
796.181	34.2027
796.436	34.2297
796.69	32.2434
796.944	32.6437
797.199	31.5992
797.453	34.9381
797.707	30.1517
797.961	29.4919
798.216	32.7178
798.47	29.6498
798.724	30.8837
798.978	34.272
799.232	33.582
799.486	31.3777
799.74	33.5469
799.994	32.6962
800.248	32.8207
800.503	27.9799
800.757	34.385
801.011	38.0846
801.265	30.6227
801.508	26.0015
801.762	27.1813
802.017	27.3471
802.271	25.9668
802.526	28.2931
802.78	34.8566
803.035	31.7988
803.289	36.8029
803.544	30.4574
803.798	27.7856
804.052	28.89
804.307	26.88
804.561	26.8459
804.816	36.0033
805.07	30.7036
805.324	23.0655
805.579	32.5066
805.833	29.5358
806.087	25.3879
806.341	28.3142
806.596	30.258
806.85	35.0616
807.104	26.8939
807.358	25.0744
807.613	29.7355
807.867	29.912
808.121	33.4432
808.375	23.9466
808.629	35.3473
808.883	27.5744
809.138	34.0707
809.392	29.188
809.646	29.843
809.9	26.8376
810.154	29.2103
810.408	32.1258
810.662	35.6749
810.916	25.4726
811.17	27.7099
811.424	29.5483
811.678	32.622
811.932	29.84
812.185	28.628
812.439	31.2227
812.693	27.7977
812.947	30.2681
813.201	28.2635
813.455	31.0724
813.709	29.8958
813.962	28.492
814.216	27.2577
814.47	31.3436
814.724	30.8116
814.977	28.5377
815.231	27.8721
815.485	29.635
815.739	30.1873
815.992	29.6567
816.246	33.3383
816.499	31.3831
816.753	28.5097
817.007	29.0413
817.26	27.7749
817.514	29.5463
817.767	32.1907
818.021	26.3722
818.274	31.2874
818.528	28.9062
818.781	31.6319
819.01	30.2449
819.264	29.1534
819.518	28.5573
819.772	25.3611
820.026	28.9016
820.28	31.883
820.534	28.0381
820.788	32.1603
821.042	22.6112
821.296	32.9253
821.549	26.3808
821.803	28.4339
822.057	23.6864
822.311	26.1346
822.565	27.6796
822.819	27.5778
823.073	30.4305
823.326	29.1387
823.58	28.7758
823.834	27.4529
824.088	29.105
824.341	31.8465
824.595	24.733
824.849	25.9406
825.103	29.5896
825.356	30.2232
825.61	27.2917
825.864	23.776
826.117	25.4785
826.371	27.3917
826.624	26.5654
826.878	24.5213
827.131	30.0259
827.385	29.082
827.638	27.3697
827.892	28.1928
828.146	29.3494
828.399	27.9515
828.652	23.3721
828.906	28.1254
829.159	27.3674
829.413	28.1053
829.666	21.6806
829.919	27.5816
830.173	25.8664
830.426	28.0184
830.68	27.3666
830.933	28.469
831.186	28.5276
831.439	25.9825
831.693	24.7004
831.946	26.0522
832.199	32.5606
832.452	24.3361
832.706	26.6409
832.959	27.1605
833.212	28.3855
833.465	25.2011
833.718	30.1829
833.971	26.5642
834.224	26.1746
834.477	23.9211
834.73	28.8106
834.984	26.7744
835.237	25.8318
835.49	23.884
835.743	27.8795
835.996	33.9143
836.201	28.0029
836.454	26.9502
836.708	27.9081
836.961	26.9245
837.215	29.8909
837.468	23.1836
837.722	27.1126
837.975	26.9548
838.229	30.2776
838.482	21.673
838.735	19.3374
838.989	30.0609
839.242	30.7137
839.496	28.6651
839.749	24.619
840.002	26.2812
840.256	27.7581
840.509	23.7952
840.762	25.898
841.015	28.0188
841.269	29.1586
841.522	24.3883
841.775	28.4047
842.028	28.4143
842.281	25.5759
842.535	25.4218
842.788	25.611
843.041	29.5726
843.294	24.1734
843.547	21.5635
843.8	24.3563
844.053	26.6732
844.306	23.4939
844.559	25.5767
844.812	27.8529
845.065	28.0839
845.318	28.7078
845.571	25.2142
845.824	25.5457
846.077	26.7734
846.33	26
846.583	26.2741
846.836	25.5176
847.089	24.1122
847.342	24.6528
847.595	26.1726
847.847	32.2839
848.1	28.3428
848.353	23.606
848.606	28.7174
848.859	27.4797
849.111	28.9316
849.364	26.3949
849.617	28.8126
849.869	25.7815
850.122	28.2761
850.375	25.3902
850.627	27.8059
850.88	26.9273
851.133	25.7124
851.385	25.2214
851.638	26.602
851.89	28.5163
852.143	23.5069
852.395	28.0121
852.648	30.4168
852.9	28.8416
853.153	24.609
853.405	26.5293
853.645	27.2427
853.898	24.6036
854.151	21.399
854.404	22.7447
854.657	29.8084
854.91	27.1853
855.163	25.2204
855.416	31.6152
855.669	28.6069
855.922	23.4741
856.175	25.1887
856.427	25.0944
856.68	27.7899
856.933	29.667
857.186	27.0055
857.439	26.1362
857.692	26.6705
857.944	25.062
858.197	19.9237
858.45	25.9136
858.703	25.874
858.955	24.3762
859.208	22.7733
859.461	27.153
859.713	27.4183
859.966	22.2521
860.219	27.8453
860.471	28.2075
860.724	27.4154
860.976	23.5202
861.229	23.8641
861.481	25.1126
861.734	23.2886
861.986	22.327
862.239	27.7664
862.491	29.5951
862.744	26.6379
862.996	27.1206
863.249	27.0289
863.501	28.6697
863.754	24.572
864.006	26.5223
864.258	27.7906
864.511	26.7619
864.763	23.0563
865.015	22.8639
865.268	27.2656
865.52	22.2148
865.772	22.1734
866.024	25.3891
866.276	27.7425
866.529	28.4562
866.781	26.162
867.033	28.7503
867.285	28.1301
867.537	33.3322
867.789	22.7954
868.042	25.7347
868.294	28.3189
868.546	19.3545
868.798	26.3293
869.05	25.5394
869.302	25.6617
869.554	26.4469
869.806	24.0407
870.058	26.7842
870.31	30.5777
870.562	25.663
870.782	25.1604
871.034	26.3363
871.287	26.884
871.539	25.9596
871.792	26.6032
872.044	26.344
872.297	27.5929
872.549	25.9246
872.801	25.8726
873.054	28.6344
873.306	27.8541
873.558	21.2867
873.811	23.7919
874.063	31.6003
874.315	28.0252
874.568	19.6644
874.82	24.9036
875.072	27.8095
875.324	27.2501
875.577	21.5085
875.829	30.3114
876.081	28.1294
876.333	26.5923
876.585	25.893
876.838	27.2232
877.09	27.5765
877.342	21.1024
877.594	27.0117
877.846	24.8277
878.098	29.0198
878.35	24.7253
878.602	25.1309
878.854	26.6478
879.106	28.4985
879.358	23.6482
879.61	32.6565
879.862	29.3126
880.114	23.4433
880.366	28.1691
880.618	29.3717
880.87	27.7928
881.121	21.9142
881.373	24.6694
881.625	21.9911
881.877	31.7072
882.129	22.8229
882.38	27.3782
882.632	23.4865
882.884	26.2685
883.136	27.5779
883.387	27.6032
883.639	25.9031
883.891	26.8167
884.142	23.4254
884.394	26.898
884.646	28.3324
884.897	26.5344
885.149	23.5892
885.4	26.0276
885.652	27.4389
885.903	24.7313
886.155	26.5434
886.406	27.8835
886.658	23.1378
886.909	19.3231
887.161	28.1691
887.412	26.7467
887.664	24.1247
887.915	24.303
888.138	24.362
888.39	28.9133
888.642	27.3923
888.894	20.9773
889.146	21.8081
889.398	26.3366
889.65	28.7623
889.902	28.0584
890.154	27.5462
890.406	31.2345
890.657	28.9978
890.909	22.3852
891.161	25.9011
891.413	26.743
891.665	23.5417
891.916	23.9922
892.168	27.2494
892.42	25.1251
892.671	29.0216
892.923	28.2213
893.175	26.3414
893.426	26.818
893.678	24.9072
893.93	24.9301
894.181	26.0324
894.433	25.3278
894.684	23.5615
894.936	25.4568
895.188	28.2023
895.439	23.4529
895.69	24.4068
895.942	29.4863
896.193	25.6843
896.445	25.2484
896.696	25.0418
896.948	24.5026
897.199	24.1441
897.451	26.4089
897.702	27.7928
897.953	25.7051
898.204	21.892
898.456	18.9992
898.707	25.4579
898.958	26.6792
899.21	23.057
899.461	21.3206
899.712	24.93
899.963	28.6667