File: M6_270224_01.txt
#Acq. time (s)=	3
#Accumulations=	2
#Range (nm)=	520...900
#Windows=	8
#Auto scanning=	Off
#Autofocus=	Off
#AutoExposure=	Off
#Spike filter=	Multiple accum.
#Delay time (s)=	0
#Binning=	1
#Readout mode=	Signal
#DeNoise=	Off
#ICS correction=	Off
#Dark correction=	Off
#Inst. Process=	Off
#Detector temperature (°C)=	-59.98
#Instrument=	LabRAM HR Evol
#Detector=	Syncerity OE
#Objective=	x50_VIS
#Grating=	600 (500nm)
#ND Filter=	10%
#Laser=	514nm_Edge
#Hole=	199.981
#Range=	Auto
#StageXY=	Marzhauser
#StageZ=	Marzhauser
#X (µm)=	0
#Y (µm)=	0
#Z (µm)=	0
#Full time(mm:ss)=	1:32
#Project=
#Sample=
#Site=
#Title=	M6_270224
#Remark=
#Date=	06.03.2024 10:23
#Acquired=	06.03.2024 10:23:55
520.044	34
520.306	26
520.569	16
520.831	24
521.093	28
521.355	24
521.617	22
521.88	20
522.142	26
522.404	32
522.666	24
522.928	24
523.19	28
523.453	26
523.715	20
523.977	22
524.239	30
524.501	36
524.763	32
525.025	22
525.287	30
525.549	32
525.811	30
526.073	24
526.335	26
526.597	24
526.859	26
527.121	18
527.383	24
527.645	30
527.907	24
528.169	30
528.431	24
528.693	28
528.955	38
529.217	26
529.479	32
529.741	26
530.003	30
530.264	32
530.526	28
530.788	20
531.05	28
531.312	32
531.574	20
531.835	24
532.097	34
532.359	34
532.621	32
532.883	30
533.144	28
533.406	32
533.668	32
533.93	32
534.191	32
534.453	34
534.715	26
534.976	30
535.238	32
535.5	36
535.761	32
536.023	36
536.285	26
536.546	34
536.808	32
537.069	36
537.331	30
537.593	34
537.854	38
538.116	28
538.377	32
538.639	28
538.9	38
539.162	42
539.423	26
539.685	24
539.946	34
540.208	38
540.469	34
540.731	30
540.992	30
541.254	32
541.515	30
541.776	32
542.038	24
542.299	40
542.56	32
542.822	26
543.083	32
543.344	34
543.606	34
543.867	34
544.128	28
544.39	34
544.651	38
544.912	30
545.174	34
545.435	28
545.696	38
545.957	38
546.218	32
546.48	26
546.741	44
547.002	32
547.263	38
547.524	36
547.785	34
548.047	40
548.308	38
548.569	36
548.83	42
549.091	42
549.352	42
549.613	34
549.874	28
550.135	38
550.396	42
550.657	40
550.918	38
551.179	50
551.44	50
551.701	66
551.962	86
552.223	168
552.484	1742
552.745	10162
553.006	258
553.267	96
553.528	66
553.788	66
554.049	46
554.31	54
554.571	46
554.832	52
555.093	44
555.353	38
555.614	40
555.875	46
556.136	30
556.396	40
556.657	44
556.918	44
557.179	46
557.439	44
557.7	40
557.961	42
558.221	40
558.482	42
558.743	38
559.003	42
559.264	38
559.525	40
559.785	34
560.046	54
560.306	48
560.567	44
560.827	50
561.088	52
561.348	46
561.609	48
561.869	46
562.13	48
562.39	46
562.651	50
562.911	46
563.172	52
563.432	48
563.692	44
563.953	54
564.213	54
564.474	60
564.734	52
564.994	44
565.255	48
565.515	46
565.775	48
566.035	56
566.296	46
566.556	46
566.816	60
567.076	60
567.337	50
567.597	48
567.857	52
568.117	62.03
568.377	63.3482
568.637	59.4745
568.898	56.789
569.158	61.95
569.418	61.5555
569.678	59.0711
569.938	59.8729
570.198	58.5676
570.458	60.5099
570.718	63.01
570.978	68.6291
571.238	68.74
571.498	70.8222
571.758	60.6777
572.018	65.3569
572.278	66.3239
572.538	71.5682
572.798	82.7621
573.058	77.4868
573.312	80
573.573	88
573.834	104
574.095	102
574.356	108
574.617	112
574.878	122
575.139	122
575.4	138
575.661	140
575.922	136
576.183	140
576.444	110
576.705	126
576.965	116
577.226	104
577.487	104
577.748	94
578.009	106
578.27	112
578.531	96
578.791	98
579.052	88
579.313	98
579.574	106
579.835	106
580.095	102
580.356	98
580.617	100
580.878	102
581.138	118
581.399	96
581.66	114
581.92	112
582.181	102
582.442	114
582.703	122
582.963	104
583.224	134
583.484	116
583.745	124
584.006	116
584.266	126
584.527	130
584.787	130
585.048	140
585.308	136
585.569	144
585.83	140
586.09	156
586.351	148
586.611	144
586.872	148
587.132	158
587.392	154
587.653	150
587.913	158
588.174	162
588.434	162
588.695	166
588.955	164
589.215	182
589.476	192
589.736	186
589.996	184
590.257	184
590.517	156
590.777	166
591.038	168
591.298	164
591.558	140
591.818	146
592.079	142
592.339	148
592.599	130
592.859	152
593.12	136
593.38	140
593.64	122
593.9	148
594.16	156
594.42	158
594.68	152
594.941	138
595.201	146
595.461	152
595.721	142
595.981	142
596.241	150
596.501	154
596.761	174
597.021	142
597.281	138
597.541	146
597.801	138
598.061	134
598.321	144
598.581	140
598.841	146
599.101	134
599.361	152
599.62	140
599.88	158
600.14	144
600.4	138
600.66	152
600.92	150
601.18	146
601.439	134
601.699	142
601.959	144
602.219	130
602.478	138
602.738	140
602.998	152
603.258	140
603.517	138
603.777	134
604.037	150
604.296	138
604.556	134
604.816	150
605.075	150
605.335	166
605.594	146
605.854	132
606.114	132
606.373	138
606.633	146
606.892	142
607.152	136
607.411	154
607.671	152
607.93	146
608.19	138
608.449	150
608.709	154
608.968	154
609.228	136
609.487	156
609.746	158
610.006	162
610.265	144
610.524	156
610.784	164
611.043	158
611.302	152
611.562	158
611.821	162
612.08	160
612.339	158
612.599	146
612.858	164
613.117	168
613.376	160
613.635	162
613.895	176
614.154	168
614.413	166
614.672	164
614.931	170
615.19	170
615.449	166
615.709	174
615.968	168
616.227	184.554
616.486	177.285
616.745	172.269
617.004	171.622
617.263	175.258
617.522	181.052
617.781	164.783
618.04	180.974
618.299	183.514
618.557	187.285
618.816	191.904
619.075	172.147
619.334	187.278
619.593	184.976
619.852	181.757
620.111	184.441
620.37	192.814
620.628	185.571
620.887	196.092
621.146	172.818
621.373	166
621.633	198
621.893	198
622.153	190
622.413	188
622.673	196
622.932	190
623.192	206
623.452	194
623.712	200
623.972	204
624.232	196
624.492	198
624.751	194
625.011	204
625.271	204
625.531	206
625.791	206
626.05	192
626.31	202
626.57	212
626.83	200
627.089	198
627.349	204
627.609	206
627.868	200
628.128	214
628.388	200
628.647	220
628.907	196
629.167	192
629.426	214
629.686	208
629.945	226
630.205	220
630.465	222
630.724	228
630.984	220
631.243	224
631.503	216
631.762	214
632.022	230
632.281	250
632.541	230
632.8	248
633.06	244
633.319	250
633.579	232
633.838	256
634.097	262
634.357	268
634.616	238
634.876	260
635.135	266
635.394	292
635.654	272
635.913	282
636.172	278
636.431	284
636.691	302
636.95	334
637.209	374
637.469	366
637.728	364
637.987	384
638.246	382
638.505	352
638.765	352
639.024	336
639.283	330
639.542	342
639.801	310
640.06	304
640.319	292
640.578	312
640.838	316
641.097	302
641.356	296
641.615	312
641.874	306
642.133	302
642.392	296
642.651	318
642.91	306
643.169	298
643.428	312
643.687	306
643.946	308
644.205	300
644.463	302
644.722	306
644.981	316
645.24	306
645.499	302
645.758	302
646.017	328
646.275	312
646.534	314
646.793	336
647.052	324
647.31	334
647.569	328
647.828	324
648.087	318
648.345	340
648.604	308
648.863	326
649.121	330
649.38	330
649.639	358
649.897	334
650.156	332
650.415	352
650.673	362
650.932	366
651.19	350
651.449	362
651.707	372
651.966	376
652.224	364
652.483	358
652.741	354
653	370
653.258	370
653.517	372
653.775	384
654.034	394
654.292	376
654.55	402
654.809	396
655.067	410
655.326	390
655.584	402
655.842	416
656.1	416
656.359	416
656.617	436
656.875	412
657.134	424
657.392	430
657.65	466
657.908	428
658.166	442
658.425	438
658.683	460
658.941	458
659.199	466
659.457	474
659.715	454
659.973	474
660.231	454
660.49	438
660.748	454
661.006	446
661.264	436
661.522	438
661.78	452
662.038	422
662.296	450
662.554	452
662.811	460
663.069	454
663.327	464
663.585	444
663.843	448.071
664.101	447.703
664.359	455.465
664.617	447.2
664.874	460.859
665.132	426.026
665.39	455.065
665.648	446.8
665.906	465.375
666.163	447.892
666.421	452.153
666.679	445.305
666.937	442.99
667.194	452.877
667.452	448.101
667.71	475.125
667.967	450.699
668.225	451.055
668.482	445.599
668.74	455.233
668.987	414
669.245	450
669.504	478
669.763	454
670.022	448
670.281	448
670.539	442
670.798	456
671.057	460
671.316	454
671.575	442
671.833	450
672.092	456
672.351	458
672.609	446
672.868	468
673.127	458
673.385	480
673.644	466
673.903	430
674.161	474
674.42	478
674.678	498
674.937	470
675.195	478
675.454	482
675.713	482
675.971	490
676.23	496
676.488	514
676.747	490
677.005	478
677.263	480
677.522	482
677.78	488
678.039	494
678.297	492
678.556	490
678.814	490
679.072	488
679.331	484
679.589	508
679.847	508
680.106	522
680.364	484
680.622	496
680.881	484
681.139	512
681.397	530
681.656	500
681.914	514
682.172	514
682.43	500
682.688	522
682.947	508
683.205	504
683.463	494
683.721	516
683.979	478
684.237	516
684.495	502
684.754	504
685.012	500
685.27	508
685.528	526
685.786	488
686.044	480
686.302	492
686.56	502
686.818	496
687.076	500
687.334	498
687.592	482
687.85	498
688.108	502
688.366	486
688.623	484
688.881	496
689.139	468
689.397	472
689.655	502
689.913	484
690.171	510
690.428	462
690.686	496
690.944	484
691.202	482
691.459	466
691.717	482
691.975	494
692.233	492
692.49	468
692.748	482
693.006	484
693.263	486
693.521	462
693.779	472
694.036	470
694.294	480
694.552	498
694.809	470
695.067	468
695.324	456
695.582	464
695.839	462
696.097	458
696.354	462
696.612	474
696.869	474
697.127	452
697.384	460
697.642	474
697.899	462
698.156	458
698.414	426
698.671	458
698.928	474
699.186	442
699.443	462
699.7	460
699.958	454
700.215	442
700.472	444
700.73	420
700.987	450
701.244	440
701.501	456
701.758	444
702.016	456
702.273	444
702.53	446
702.787	438
703.044	432
703.301	466
703.558	442
703.816	438
704.073	438
704.33	440
704.587	442
704.844	454
705.101	448
705.358	418
705.615	436
705.872	422
706.129	436
706.386	418
706.643	406
706.899	400
707.156	408
707.413	442
707.67	426
707.927	416
708.184	432
708.441	428
708.697	424
708.954	406
709.211	428
709.468	400
709.725	426
709.981	398
710.238	410
710.495	378
710.751	406
711.008	408
711.265	396.168
711.521	403.123
711.778	399.597
712.035	406.085
712.291	415.212
712.548	403.549
712.804	399.024
713.061	384.185
713.317	407.36
713.574	384.82
713.831	391.462
714.087	386.335
714.343	387.077
714.6	379.871
714.856	360.721
715.113	376.387
715.369	384.324
715.626	393.174
715.882	378.696
716.138	375.755
716.395	377.873
716.639	368
716.897	358
717.155	356
717.412	358
717.67	354
717.927	358
718.185	360
718.443	370
718.7	372
718.958	356
719.215	366
719.473	344
719.73	358
719.988	362
720.245	358
720.503	340
720.76	338
721.018	340
721.275	336
721.532	342
721.79	342
722.047	334
722.305	340
722.562	316
722.819	332
723.077	332
723.334	332
723.591	336
723.849	336
724.106	328
724.363	348
724.621	302
724.878	312
725.135	320
725.392	316
725.65	310
725.907	314
726.164	326
726.421	320
726.678	314
726.935	320
727.193	318
727.45	306
727.707	320
727.964	320
728.221	304
728.478	306
728.735	308
728.992	280
729.249	296
729.506	298
729.763	280
730.02	304
730.277	304
730.534	274
730.791	288
731.048	296
731.305	292
731.562	276
731.819	296
732.076	288
732.333	282
732.589	278
732.846	276
733.103	282
733.36	286
733.617	268
733.873	272
734.13	288
734.387	272
734.644	280
734.901	282
735.157	292
735.414	274
735.671	264
735.927	278
736.184	282
736.441	258
736.697	294
736.954	264
737.211	286
737.467	286
737.724	294
737.98	270
738.237	292
738.493	280
738.75	264
739.006	266
739.263	282
739.519	282
739.776	254
740.032	266
740.289	258
740.545	248
740.802	262
741.058	270
741.314	260
741.571	264
741.827	262
742.083	260
742.34	258
742.596	238
742.852	248
743.109	236
743.365	260
743.621	240
743.878	252
744.134	244
744.39	252
744.646	228
744.902	234
745.159	242
745.415	222
745.671	244
745.927	232
746.183	250
746.439	224
746.695	242
746.951	234
747.207	232
747.463	224
747.719	220
747.975	216
748.231	248
748.487	214
748.743	236
748.999	226
749.255	224
749.511	224
749.767	216
750.023	202
750.279	204
750.535	228
750.791	222
751.046	220
751.302	210
751.558	216
751.814	218
752.07	212
752.325	214
752.581	214
752.837	208
753.092	204
753.348	196
753.604	200
753.859	204
754.115	198
754.371	188
754.626	212
754.882	198
755.138	220
755.393	190
755.649	198
755.904	200
756.16	224
756.415	202
756.671	178
756.926	174
757.182	200
757.437	186
757.693	196
757.948	192
758.203	176
758.459	186
758.714	182.116
758.97	196.838
759.225	173.542
759.48	188.438
759.736	183.02
759.991	177.704
760.246	174.663
760.501	185.371
760.757	177.012
761.012	181.118
761.267	181.042
761.522	179.236
761.777	172.658
762.033	175.244
762.288	170.079
762.543	179.935
762.798	170.284
763.053	166.579
763.308	174.311
763.563	171.134
763.78	176
764.037	166
764.293	176
764.55	164
764.806	172
765.062	172
765.319	162
765.575	152
765.831	168
766.088	154
766.344	152
766.6	146
766.857	164
767.113	166
767.369	170
767.625	152
767.882	158
768.138	154
768.394	162
768.65	150
768.906	158
769.163	162
769.419	136
769.675	162
769.931	156
770.187	150
770.443	150
770.699	150
770.955	158
771.211	144
771.467	138
771.723	156
771.979	148
772.235	152
772.491	140
772.747	136
773.003	144
773.259	140
773.515	140
773.771	136
774.027	128
774.283	144
774.539	136
774.795	136
775.05	126
775.306	134
775.562	136
775.818	134
776.074	112
776.329	122
776.585	136
776.841	118
777.097	124
777.352	130
777.608	124
777.864	138
778.12	120
778.375	112
778.631	126
778.886	122
779.142	118
779.398	128
779.653	116
779.909	124
780.164	124
780.42	118
780.675	114
780.931	108
781.187	120
781.442	106
781.698	112
781.953	116
782.208	116
782.464	108
782.719	104
782.975	120
783.23	102
783.485	104
783.741	104
783.996	88
784.252	106
784.507	102
784.762	106
785.017	110
785.273	110
785.528	110
785.783	112
786.038	96
786.294	114
786.549	96
786.804	104
787.059	106
787.314	106
787.57	96
787.825	104
788.08	106
788.335	92
788.59	112
788.845	90
789.1	102
789.355	100
789.61	100
789.865	100
790.12	92
790.375	102
790.63	90
790.885	96
791.14	90
791.395	94
791.65	94
791.905	104
792.16	98
792.414	92
792.669	98
792.924	84
793.179	98
793.434	88
793.689	84
793.943	88
794.198	90
794.453	90
794.708	84
794.962	92
795.217	82
795.472	80
795.726	78
795.981	94
796.236	80
796.49	92
796.745	82
796.999	84
797.254	86
797.508	86
797.763	80
798.018	74
798.272	74
798.526	66
798.781	80
799.035	78
799.29	86
799.544	76
799.799	80
800.053	80
800.307	74
800.562	74
800.816	72
801.07	78
801.325	66
801.579	76
801.833	70
802.088	78
802.342	78
802.596	60
802.85	74
803.105	62
803.359	76
803.613	68
803.867	76
804.121	70
804.375	70
804.63	68
804.884	72
805.138	60
805.392	62
805.646	77.5972
805.9	60.9383
806.154	79.4288
806.408	62.1287
806.662	68.4585
806.916	68.2787
807.17	68.6274
807.424	65.0755
807.678	56.8248
807.931	60.9927
808.185	69.0269
808.439	65.0281
808.693	60.7609
808.947	68.2557
809.201	67.4536
809.454	65.4232
809.708	67.9922
809.962	60.0519
810.216	67.9518
810.469	65.1451
810.678	64
810.933	60
811.188	60
811.443	58
811.699	64
811.954	58
812.209	52
812.464	66
812.719	54
812.974	62
813.229	58
813.484	56
813.739	64
813.994	58
814.249	56
814.504	54
814.759	64
815.014	66
815.268	54
815.523	56
815.778	62
816.033	60
816.288	60
816.543	58
816.798	62
817.052	60
817.307	48
817.562	52
817.817	52
818.071	60
818.326	50
818.581	36
818.836	36
819.09	66
819.345	62
819.6	52
819.854	52
820.109	56
820.364	60
820.618	54
820.873	56
821.127	54
821.382	58
821.637	54
821.891	56
822.146	56
822.4	52
822.655	60
822.909	42
823.164	46
823.418	48
823.672	52
823.927	48
824.181	52
824.436	52
824.69	50
824.944	46
825.199	48
825.453	56
825.707	54
825.962	50
826.216	44
826.47	44
826.725	46
826.979	44
827.233	44
827.487	46
827.741	56
827.996	50
828.25	46
828.504	46
828.758	52
829.012	46
829.266	48
829.52	50
829.774	40
830.029	48
830.283	48
830.537	48
830.791	48
831.045	44
831.299	46
831.553	50
831.807	52
832.061	50
832.315	56
832.568	44
832.822	38
833.076	44
833.33	46
833.584	44
833.838	36
834.092	46
834.345	48
834.599	46
834.853	50
835.107	36
835.36	46
835.614	42
835.868	40
836.122	44
836.375	42
836.629	46
836.883	48
837.136	46
837.39	38
837.643	50
837.897	44
838.151	40
838.404	38
838.658	46
838.911	44
839.165	36
839.418	44
839.672	42
839.925	44
840.179	44
840.432	42
840.686	48
840.939	46
841.192	40
841.446	42
841.699	36
841.952	44
842.206	34
842.459	36
842.712	40
842.966	52
843.219	48
843.472	38
843.725	38
843.979	40
844.232	44
844.485	44
844.738	30
844.991	34
845.244	42
845.497	36
845.75	38
846.004	36
846.257	42
846.51	48
846.763	32
847.016	36
847.269	46
847.522	38
847.775	36
848.028	34
848.281	38
848.534	38
848.786	42
849.039	36
849.292	38
849.545	40
849.798	40
850.051	38
850.303	32
850.556	42
850.809	42
851.062	38
851.314	38
851.567	40
851.82	38
852.073	30
852.325	39.9809
852.578	36.3292
852.831	34.4094
853.083	30.93
853.336	36.6502
853.588	36.1557
853.841	43.9848
854.093	36.8084
854.346	33.4613
854.598	34.7016
854.851	36.0146
855.103	34.0935
855.356	30.6367
855.608	36.5255
855.861	37.478
856.113	37.0525
856.366	32.2078
856.618	30.148
856.87	33.6889
857.123	35.1942
857.352	42
857.606	30
857.859	38
858.113	30
858.367	36
858.621	34
858.875	34
859.128	36
859.382	32
859.636	38
859.889	28
860.143	30
860.397	40
860.65	30
860.904	30
861.158	30
861.411	42
861.665	38
861.918	28
862.172	30
862.425	36
862.679	28
862.932	28
863.186	30
863.439	36
863.693	34
863.946	40
864.2	24
864.453	36
864.707	28
864.96	30
865.213	30
865.467	22
865.72	32
865.973	36
866.227	34
866.48	30
866.733	34
866.987	32
867.24	32
867.493	30
867.746	34
867.999	30
868.253	40
868.506	36
868.759	28
869.012	32
869.265	26
869.518	38
869.771	24
870.025	40
870.278	38
870.531	40
870.784	24
871.037	26
871.29	28
871.543	28
871.796	26
872.049	36
872.302	26
872.555	36
872.808	30
873.06	34
873.313	30
873.566	36
873.819	30
874.072	18
874.325	38
874.578	30
874.83	34
875.083	26
875.336	36
875.589	32
875.841	36
876.094	24
876.347	26
876.6	44
876.852	34
877.105	36
877.358	28
877.61	34
877.863	30
878.115	30
878.368	18
878.621	38
878.873	34
879.126	40
879.378	30
879.631	36
879.883	28
880.136	34
880.388	30
880.641	26
880.893	32
881.145	34
881.398	28
881.65	30
881.902	36
882.155	26
882.407	24
882.659	24
882.912	34
883.164	36
883.416	44
883.669	26
883.921	30
884.173	38
884.425	36
884.677	26
884.93	34
885.182	38
885.434	34
885.686	38
885.938	26
886.19	34
886.442	30
886.694	30
886.946	24
887.198	28
887.45	34
887.702	36
887.954	28
888.206	24
888.458	30
888.71	30
888.962	28
889.214	26
889.466	42
889.718	30
889.969	38
890.221	26
890.473	30
890.725	24
890.977	32
891.228	20
891.48	30
891.732	30
891.983	30
892.235	28
892.487	26
892.738	36
892.99	32
893.242	28
893.493	28
893.745	32
893.996	34
894.248	30
894.5	20
894.751	26
895.003	30
895.254	32
895.505	30
895.757	26
896.008	32
896.26	28
896.511	28
896.763	26
897.014	28
897.265	36
897.517	34
897.768	22
898.019	32
898.27	28
898.522	32
898.773	22
899.024	30
899.275	30
899.527	30
899.778	26
899.979	22