File: M7_140224_01.txt
#Acq. time (s)=	2
#Accumulations=	3
#Range (nm)=	520...900
#Windows=	24
#Auto scanning=	On
#Autofocus=	Off
#AutoExposure=	Off
#Spike filter=	Multiple accum.
#Delay time (s)=	0
#Binning=	1
#Readout mode=	Signal
#DeNoise=	Off
#ICS correction=	Off
#Dark correction=	Off
#Inst. Process=	Off
#Detector temperature (°C)=	-59.98
#Instrument=	LabRAM HR Evol
#Detector=	Syncerity OE
#Objective=	x50_VIS
#Grating=	600 (500nm)
#ND Filter=	25%
#Laser=	514nm_Edge
#Hole=	199.981
#Range=	Auto
#StageXY=	Marzhauser
#StageZ=	Marzhauser
#X (µm)=	-14729.6
#Y (µm)=	7396.1
#Z (µm)=	-433.4
#Full time(mm:ss)=	3:04
#Project=
#Sample=
#Site=
#Title=	M7_140224
#Remark=
#Date=	19.02.2024 14:52
#Acquired=	19.02.2024 14:52:40
520.013	32.7925
520.274	28.6574
520.536	30.2688
520.797	26.2944
521.059	29.9757
521.32	29.9443
521.582	31.4142
521.843	27.4451
522.105	27.7227
522.366	26.6315
522.628	30.3231
522.889	29.3849
523.15	27.9729
523.412	29.7139
523.673	28.1885
523.935	28.0057
524.196	26.3488
524.457	32.6995
524.719	23.3236
524.98	27.1437
525.241	28.4981
525.503	28.3349
525.764	29.4679
526.025	26
526.286	29.7928
526.548	29.4028
526.809	28.022
527.07	26.8764
527.331	31.9996
527.593	28.1783
527.854	28.1818
528.115	24.532
528.376	29.2393
528.637	26.0493
528.898	28.5566
529.16	27.6359
529.421	29.8624
529.682	30.1876
529.943	25.8633
530.204	27.3659
530.465	29.5948
530.726	23.4462
530.987	29.8575
531.248	33.0628
531.509	27.1157
531.77	26.126
532.031	29.4285
532.292	29.4413
532.553	26.9883
532.814	27.6215
533.075	30.7351
533.336	31.0392
533.597	30.9307
533.858	25.7446
534.119	30.1865
534.38	29.575
534.641	31.515
534.901	27.5942
535.162	31.8077
535.423	30.0033
535.684	29.5295
535.945	32.8811
536.205	31.5595
536.466	28.2659
536.727	29.066
536.988	30.8875
537.248	27.9278
537.509	26.809
537.77	30.1502
537.987	26.4789
538.249	34.9843
538.51	28.4876
538.771	32.3835
539.032	27.3014
539.293	32.6806
539.554	26.5168
539.815	26.1975
540.076	34.059
540.337	29.7539
540.598	26.8554
540.859	26.3256
541.12	22.5033
541.381	31.3246
541.642	27.5041
541.903	25.5896
542.164	32.0845
542.425	29.6678
542.686	25.4123
542.947	25.7732
543.208	30.0859
543.469	25.4851
543.73	26.1748
543.991	29.1155
544.252	30.1815
544.513	28.95
544.773	28.4687
545.034	28.4507
545.295	31.5795
545.556	31.2605
545.817	27.2629
546.077	39.1224
546.338	31.2509
546.599	27.548
546.86	24.866
547.12	27.702
547.381	28.1903
547.642	29.7832
547.903	29.5927
548.163	30.5144
548.424	33.5793
548.685	29.7538
548.945	32.5786
549.206	29.5978
549.467	34.9851
549.727	27.3512
549.988	31.9118
550.248	36.8295
550.509	33.4277
550.769	35.0651
551.03	44.9003
551.291	44.2797
551.551	53.803
551.812	65.5834
552.072	106.49
552.332	339.882
552.593	8497.53
552.853	1532.88
553.114	137.359
553.374	75.5802
553.635	52.0074
553.895	51.9881
554.155	36.6312
554.416	36.1134
554.676	37.3833
554.937	34.8494
555.197	30.0513
555.457	30.7683
555.686	29.9725
555.947	28.7906
556.207	36.8579
556.468	35.7521
556.729	33.41
556.99	33.8794
557.25	31.6304
557.511	35.259
557.772	24.9081
558.032	33.5038
558.293	27.2659
558.554	33.8099
558.814	28.6207
559.075	31.358
559.336	32.893
559.596	30.4152
559.857	29.4929
560.117	33.7639
560.378	27.7271
560.638	29.7619
560.899	23.8508
561.159	30.873
561.42	31.4452
561.68	30.289
561.941	33.5538
562.201	28.9739
562.462	29.7791
562.722	31.4008
562.983	36.7235
563.243	33.2109
563.504	31.7675
563.764	31.7138
564.024	36.8972
564.285	33.3122
564.545	30.4174
564.805	36.2454
565.066	29.2926
565.326	33.9207
565.586	33.5553
565.847	32.5639
566.107	28.1372
566.367	30.0565
566.627	32.8844
566.888	34.4445
567.148	33.9945
567.408	36.5739
567.668	34.7601
567.928	36.7708
568.189	32.5456
568.449	35.6168
568.709	36.9869
568.969	36.8029
569.229	36.0226
569.489	37.4315
569.749	33.1543
570.009	35.5956
570.269	33.3551
570.53	38.8247
570.79	36.3085
571.05	38.3706
571.31	31.1937
571.57	37.2185
571.83	38.9081
572.09	36.535
572.349	37.0632
572.609	40.8252
572.869	37.7273
573.129	38.9449
573.368	46.1978
573.629	44.5271
573.889	49.0998
574.15	49.6428
574.41	43.2074
574.67	46.5484
574.931	46.0886
575.191	48.9844
575.451	48.5876
575.711	52.8624
575.972	47.4493
576.232	49.6887
576.492	47.6641
576.752	48.1482
577.013	45.5308
577.273	49.6424
577.533	46.1782
577.793	48.3173
578.053	42.0673
578.313	49.6855
578.574	47.1621
578.834	45.5581
579.094	40.6359
579.354	49.0304
579.614	51.7683
579.874	53.5697
580.134	49.2315
580.394	52.3022
580.654	52.2687
580.914	48.3035
581.174	51.3249
581.434	53.5144
581.694	54.2461
581.954	60.7048
582.214	59.8592
582.474	55.4998
582.734	61.0582
582.994	61.0163
583.254	63.1462
583.514	63.6529
583.773	63.3656
584.033	70.5499
584.293	72.4587
584.553	71.7383
584.813	74.8577
585.073	72.3924
585.332	81.349
585.592	78.5235
585.852	78.4959
586.112	81.7514
586.371	80.058
586.631	81.2858
586.891	79.9517
587.151	82.2465
587.41	79.6
587.67	87.868
587.93	83.1923
588.189	94.2645
588.449	92.6762
588.709	92.9168
588.968	102.703
589.228	107.244
589.487	109.793
589.747	108.994
590.006	101.153
590.266	99.5605
590.525	97.0319
590.785	93.626
591.036	89.0378
591.296	92.7971
591.556	81.2135
591.816	81.8752
592.076	73.7679
592.336	81.5373
592.596	74.4622
592.856	86.8823
593.116	82.114
593.376	72.0359
593.635	75.3424
593.895	72.5299
594.155	71.4638
594.415	72.6279
594.675	77.3234
594.935	78.0073
595.194	79.8801
595.454	73.0331
595.714	77.1531
595.974	74.8869
596.233	78.4705
596.493	89.4473
596.753	86.1631
597.012	73.5731
597.272	72.1728
597.532	65.3849
597.791	68.9752
598.051	68.2141
598.311	65.9002
598.57	63.8637
598.83	66.9391
599.089	63.0176
599.349	57.6496
599.609	63.7751
599.868	59.4776
600.128	60.3056
600.387	58.9255
600.647	60.6095
600.906	63.6821
601.166	63.4505
601.425	62.0974
601.685	54.5377
601.944	59.4483
602.203	62.3601
602.463	60.4977
602.722	56.6536
602.982	58.814
603.241	64.2222
603.5	61.635
603.76	63.0214
604.019	59.1855
604.278	64.3849
604.538	67.8359
604.797	66.2532
605.056	65.6932
605.315	60.8215
605.575	64.7895
605.834	65.2213
606.093	65.3577
606.352	67.3123
606.611	61.4567
606.871	65.0718
607.13	63.61
607.389	61.7561
607.648	69.0897
607.907	68.3965
608.166	69.1731
608.425	67.0489
608.664	66.5853
608.924	63.331
609.183	62.1818
609.443	70.2521
609.702	70.7377
609.962	67.1565
610.221	64.0467
610.481	65.6368
610.74	71.589
611	68.666
611.259	64.2062
611.518	78.5263
611.778	68.3652
612.037	73.3204
612.297	67.0301
612.556	71.1225
612.815	70.4857
613.075	65.8117
613.334	68.0161
613.594	70.2586
613.853	73.9155
614.112	65.4856
614.371	72.1798
614.631	72.7732
614.89	71.0065
615.149	64.7779
615.408	71.4738
615.668	76.7042
615.927	72.3371
616.186	70.2147
616.445	71.6317
616.704	68.7658
616.964	73.152
617.223	75.9393
617.482	70.1573
617.741	71.8993
618	72.4355
618.259	81.7232
618.518	77.8949
618.777	70.4827
619.036	71.7874
619.295	75.2391
619.554	75.2859
619.813	68.0023
620.072	76.9729
620.331	69.5151
620.59	75.5938
620.849	72.586
621.108	72.366
621.367	79.6433
621.626	76.2899
621.885	72.6307
622.144	79.1831
622.403	76.0364
622.661	73.2679
622.92	72.3718
623.179	75.8083
623.438	77.6117
623.697	75.44
623.956	71.8277
624.214	74.9873
624.473	73.9224
624.732	77.9662
624.99	72.5792
625.249	76.7199
625.508	78.4637
625.767	75.0246
626.025	69.2735
626.249	70.0271
626.508	75.4175
626.767	73.5029
627.026	75.2351
627.285	70.4266
627.544	73.8216
627.803	74.4371
628.062	73.2115
628.321	72.2906
628.58	80.016
628.839	74.3333
629.098	76.9457
629.357	79.3125
629.616	79.8468
629.875	79.8698
630.134	73.3932
630.393	73.4524
630.652	74.2194
630.911	78.6645
631.17	72.6099
631.429	85.5508
631.688	83.0277
631.947	78.8353
632.206	75.6634
632.464	77.3645
632.723	73.0414
632.982	78.9103
633.241	77.0318
633.5	80.0296
633.758	85.4596
634.017	73.2271
634.276	77.2271
634.535	80.936
634.793	81.1793
635.052	71.2603
635.311	77.9251
635.57	83.2889
635.828	78.2487
636.087	72.1339
636.345	78.7145
636.604	75.8151
636.863	74.929
637.121	82.5821
637.38	85.0971
637.638	85.8144
637.897	81.5754
638.156	84.1906
638.414	87.9592
638.673	79.4755
638.931	83.0886
639.19	83.6491
639.448	80.3823
639.706	82.1554
639.965	65.7487
640.223	77.816
640.482	79.6914
640.74	78.7676
640.999	79.8233
641.257	81.7618
641.515	78.1917
641.774	75.1938
642.032	70.6775
642.29	81.0114
642.549	83.7487
642.807	72.4141
643.065	72.7173
643.323	78.4817
643.582	77.9981
643.84	78.4984
644.053	77.1359
644.312	76.0212
644.57	78.0658
644.829	76.9001
645.088	78.1205
645.346	78.0241
645.605	84.3161
645.864	79.2385
646.122	76.2654
646.381	77.0283
646.639	74.6164
646.898	69.4028
647.157	72.2481
647.415	77.611
647.674	82.0335
647.932	80.9024
648.191	77.0192
648.449	79.4743
648.708	75.4956
648.966	77.5428
649.225	74.0869
649.483	83.348
649.742	82.6818
650	73.0584
650.258	77.8356
650.517	77.2834
650.775	76.1193
651.034	73.9832
651.292	75.6799
651.55	75.3877
651.809	76.1968
652.067	73.6862
652.325	76.6691
652.583	83.8524
652.842	78.4757
653.1	70.357
653.358	79.7797
653.616	75.5431
653.875	76.5177
654.133	74.5212
654.391	79.7512
654.649	76.6359
654.907	79.55
655.165	76.0768
655.424	74.3708
655.682	74.6363
655.94	72.9919
656.198	77.6364
656.456	79.9328
656.714	76.4362
656.972	72.8128
657.23	83.6882
657.488	83.7613
657.746	74.5176
658.004	77.5183
658.262	82.107
658.52	74.7203
658.778	72.9716
659.036	78.5268
659.294	78.0966
659.552	77.7509
659.809	74.1752
660.067	77.9372
660.325	76.6666
660.583	79.3141
660.841	70.0048
661.099	79.1273
661.356	79.9665
661.583	75.3066
661.842	69.6027
662.1	72.2489
662.358	72.6017
662.616	80.74
662.875	72.3118
663.133	74.0203
663.391	78.1764
663.649	68.4065
663.907	76.6851
664.166	76.1424
664.424	79.0072
664.682	73.9381
664.94	69.6704
665.198	76.9977
665.456	73.5975
665.714	73.5641
665.972	64.3787
666.23	80.8648
666.488	67.8553
666.746	63.7993
667.004	75.3805
667.262	67.435
667.52	78.4806
667.778	76.6842
668.036	75.1352
668.294	74.917
668.552	72.0158
668.81	72.7844
669.068	77.6645
669.326	70.5147
669.584	72.6191
669.842	74.2021
670.099	68.2327
670.357	72.5222
670.615	74.0933
670.873	68.1618
671.131	71.3756
671.388	73.2216
671.646	65.9577
671.904	65.1829
672.162	71.2232
672.419	66.0786
672.677	64.6403
672.935	72.0961
673.192	72.8977
673.45	68.1395
673.708	72.7887
673.965	73.2697
674.223	74.4184
674.481	72.3856
674.738	76.5282
674.996	71.9342
675.253	72.469
675.511	68.4751
675.768	69.7493
676.026	76.2271
676.283	67.6496
676.541	74.5139
676.798	73.1481
677.056	65.5011
677.313	69.1066
677.571	68.4032
677.828	66.7249
678.085	68.4442
678.343	70.2694
678.6	66.7259
678.857	75.4471
679.083	68.5596
679.341	68.7235
679.599	70.1301
679.857	67.3507
680.114	70.4852
680.372	66.2559
680.63	70.3485
680.888	75.8428
681.146	63.395
681.403	66.1778
681.661	74.055
681.919	73.2263
682.176	67.3851
682.434	64.7612
682.692	67.5228
682.949	69.3583
683.207	67.7624
683.465	73.321
683.722	68.0688
683.98	65.6183
684.237	73.3633
684.495	67.6202
684.753	68.2012
685.01	69.5406
685.268	62.8401
685.525	63.1691
685.783	72.713
686.04	68.1087
686.298	64.8417
686.555	68.4982
686.813	62.0159
687.07	70.8174
687.327	67.2843
687.585	70.3549
687.842	63.4881
688.1	69.7973
688.357	62.0354
688.614	59.9701
688.872	61.384
689.129	69.4082
689.386	65.7387
689.643	61.0843
689.901	65.918
690.158	58.2883
690.415	66.6555
690.672	67.7093
690.93	60.6618
691.187	63.1533
691.444	65.9612
691.701	65.2762
691.958	66.7767
692.216	64.5518
692.473	66.2224
692.73	69.3599
692.987	60.4204
693.244	63.4075
693.501	65.435
693.758	60.9341
694.015	64.1657
694.272	65.8478
694.529	66.8031
694.786	64.4515
695.043	60.8039
695.3	67.5174
695.557	62.9625
695.814	68.6829
696.071	60.5636
696.328	64.941
696.585	67.4622
696.81	60.4089
697.068	64.5898
697.325	65.2749
697.582	66.6586
697.84	63.7608
698.097	67.2864
698.354	65.6495
698.612	62.1164
698.869	57.3648
699.126	60.2303
699.384	65.5689
699.641	66.8597
699.898	60.3075
700.155	62.1391
700.413	64.0684
700.67	54.5846
700.927	59.24
701.184	64.5154
701.441	63.2038
701.698	62.8741
701.956	62.9029
702.213	64.2765
702.47	64.5901
702.727	58.7594
702.984	56.8352
703.241	61.1215
703.498	64.0733
703.755	62.5916
704.012	63.2917
704.269	60.9199
704.526	59.8007
704.783	67.6176
705.04	59.9667
705.297	62.5658
705.554	64.4169
705.811	61.6275
706.068	63.1589
706.324	64.3107
706.581	65.0686
706.838	59.1837
707.095	66.0829
707.352	61.6187
707.609	61.6549
707.865	62.6771
708.122	61.0823
708.379	72.4581
708.636	65.1661
708.892	61.8513
709.149	64.5757
709.406	60.3523
709.662	66.6118
709.919	62.4573
710.176	68.4327
710.432	69.3571
710.689	60.7038
710.946	64.6197
711.202	64.6863
711.459	63.6909
711.715	58.7914
711.972	67.5338
712.228	66.5504
712.485	71.0717
712.741	61.5379
712.998	69.3221
713.254	69.0635
713.511	72.963
713.767	64.8965
714.024	67.4733
714.231	67.9013
714.488	68.9075
714.745	73.7987
715.002	69.1469
715.259	71.7198
715.516	72.6125
715.773	67.7269
716.029	67.4739
716.286	69.5311
716.543	67.4558
716.8	68.9968
717.057	76.1322
717.314	75.5563
717.57	77.6986
717.827	71.8182
718.084	74.6787
718.341	73.4945
718.597	76.0237
718.854	72.8876
719.111	76.3514
719.367	74.4978
719.624	76.3975
719.881	73.5238
720.137	79.4739
720.394	75.6126
720.65	76.2771
720.907	79.2269
721.164	84.8014
721.42	85.3365
721.677	86.4936
721.933	82.569
722.19	82.0074
722.446	91.6457
722.703	94.668
722.959	91.7033
723.216	94.8102
723.472	95.7535
723.728	95.57
723.985	94.7496
724.241	107.973
724.498	106.302
724.754	103.918
725.01	106.777
725.267	107.116
725.523	110.935
725.779	109.986
726.036	120.177
726.292	116.518
726.548	122.412
726.804	121.559
727.06	121.419
727.317	123.718
727.573	129.083
727.829	127.515
728.085	124.141
728.341	138.73
728.597	128.958
728.854	136.977
729.11	141.056
729.366	142.764
729.622	148.457
729.878	140.784
730.134	153.066
730.39	156.431
730.646	152.915
730.902	156.214
731.158	164.475
731.414	166.17
731.622	165.36
731.878	177.406
732.135	174.231
732.391	179.347
732.648	193.677
732.904	201.115
733.161	199.109
733.417	222.841
733.673	237.146
733.93	237.053
734.186	258.959
734.443	278.636
734.699	303.435
734.955	317.234
735.211	347.587
735.468	387.696
735.724	407.554
735.98	441.47
736.237	498.571
736.493	540.858
736.749	607.674
737.005	651.487
737.261	704.059
737.518	764.432
737.774	791.423
738.03	828.272
738.286	830.264
738.542	827.741
738.798	806.809
739.054	753.224
739.31	711.985
739.566	658.47
739.822	615.578
740.078	550.233
740.334	513.468
740.59	479.97
740.846	450.438
741.102	401.066
741.358	366.658
741.614	349.309
741.87	327.324
742.126	314.245
742.382	291.5
742.638	275.991
742.893	257.353
743.149	251.554
743.405	239.887
743.661	235.667
743.917	226.269
744.172	217.335
744.428	204.375
744.684	203.189
744.94	194.681
745.195	193.573
745.451	189.816
745.707	180.131
745.962	177.039
746.218	178.617
746.474	172.078
746.729	163.271
746.985	168.036
747.241	162.716
747.496	156.109
747.752	156.723
748.007	157.34
748.263	156.706
748.518	150.337
748.774	150.277
749.029	145.907
749.275	152.315
749.531	141.118
749.787	148.02
750.043	149.123
750.299	149.968
750.555	141.416
750.811	144.523
751.067	141.746
751.323	141.49
751.579	148.979
751.835	133.066
752.09	143.072
752.346	137.091
752.602	133.681
752.858	144.718
753.114	141.168
753.37	140.505
753.625	138.138
753.881	136.768
754.137	134.152
754.393	140.836
754.648	136.425
754.904	132.688
755.16	134.102
755.415	123.956
755.671	129.945
755.927	128.002
756.182	137.887
756.438	130.956
756.693	133.753
756.949	127.692
757.205	131.853
757.46	132.885
757.716	135.936
757.971	125.568
758.227	125.851
758.482	131.891
758.738	114.625
758.993	125.865
759.248	127.906
759.504	127.627
759.759	119.376
760.015	127.87
760.27	125.844
760.525	120.644
760.781	125.91
761.036	123.289
761.291	121.083
761.547	124.419
761.802	115.585
762.057	119.559
762.313	121.543
762.568	115.111
762.823	122.69
763.078	120.304
763.333	123.017
763.589	116.169
763.844	118.831
764.099	119.45
764.354	120.252
764.609	122.713
764.864	117.074
765.119	126.937
765.374	127.791
765.629	123.308
765.884	120.347
766.139	122.346
766.394	113.204
766.649	113.69
766.882	111.471
767.137	112.759
767.393	115.117
767.648	102.056
767.904	112.701
768.159	105.307
768.415	111.743
768.67	109.724
768.926	106.099
769.181	110.021
769.436	103.089
769.692	100.778
769.947	104.859
770.203	99.2109
770.458	99.3873
770.713	98.5611
770.968	106.153
771.224	96.6987
771.479	95.4627
771.734	90.8871
771.99	97.9225
772.245	94.4801
772.5	89.8981
772.755	91.1907
773.01	90.7434
773.265	91.5326
773.521	86.9668
773.776	91.7685
774.031	88.7101
774.286	86.7116
774.541	81.7003
774.796	82.9183
775.051	82.1152
775.306	82.5856
775.561	85.7062
775.816	79.2834
776.071	81.0054
776.326	77.3127
776.581	83.2569
776.836	78.9548
777.091	78.5872
777.346	78.6893
777.601	80.3369
777.856	77.3845
778.111	70.6284
778.365	74.2407
778.62	73.6906
778.875	73.5335
779.13	73.0874
779.385	73.0256
779.639	64.0731
779.894	70.9246
780.149	71.986
780.404	69.9286
780.658	73.4632
780.913	68.1172
781.168	67.7461
781.422	67.2239
781.677	65.5207
781.932	66.264
782.186	69.613
782.441	69.9421
782.695	72.4498
782.95	70.1805
783.204	62.4225
783.459	68
783.714	65.7743
783.968	65.005
784.211	60.1929
784.466	74.1279
784.721	69.0562
784.976	58.298
785.231	61.6486
785.486	63.2012
785.741	68.3952
785.996	60.0096
786.251	58.9188
786.506	65.7129
786.761	63.5316
787.016	61.8639
787.271	62.8987
787.526	61.286
787.78	59.0503
788.035	58.3562
788.29	60.1301
788.545	59.5548
788.8	57.0423
789.054	55.5865
789.309	56.7313
789.564	62.5069
789.819	59.7654
790.073	61.3507
790.328	60.7068
790.583	60.9788
790.837	53.1306
791.092	58.399
791.347	59.419
791.601	51.1334
791.856	55.9435
792.11	62.8318
792.365	60.2326
792.619	58.7854
792.874	60.9663
793.128	60.6677
793.383	56.4358
793.638	53.2027
793.892	56.7646
794.146	57.9967
794.401	57.1692
794.655	55.9308
794.91	60.4659
795.164	59.2277
795.418	55.5654
795.673	55.8477
795.927	54.89
796.181	53.9304
796.436	55.6986
796.69	57.1452
796.944	60.1619
797.199	58.8425
797.453	54.9165
797.707	58.9767
797.961	55.9633
798.216	57.5284
798.47	54.2483
798.724	52.921
798.978	53.9514
799.232	53.4545
799.486	53.4932
799.74	53.1054
799.994	57.882
800.248	53.5934
800.503	49.8815
800.757	55.9075
801.011	52.3294
801.265	53.5155
801.508	49.0139
801.762	53.0703
802.017	55.9168
802.271	55.4411
802.526	46.9442
802.78	52.6636
803.035	51.8247
803.289	44.1069
803.544	49.8504
803.798	56.5106
804.052	45.3649
804.307	46.1766
804.561	48.6268
804.816	50.7119
805.07	42.2392
805.324	45.1159
805.579	50.9069
805.833	48.0738
806.087	50.4829
806.341	46.9872
806.596	47.2419
806.85	50.7499
807.104	43.0878
807.358	48.8127
807.613	50.4976
807.867	45.3936
808.121	41.9081
808.375	49.1589
808.629	50.302
808.883	43.2636
809.138	44.5694
809.392	47.732
809.646	48.3595
809.9	48.4562
810.154	39.5169
810.408	47.8659
810.662	49.9891
810.916	47.2422
811.17	40.577
811.424	48.6559
811.678	44.9853
811.932	44.9446
812.185	49.4885
812.439	49.2945
812.693	45.3044
812.947	47.6976
813.201	49.1119
813.455	48.1278
813.709	49.1968
813.962	46.2996
814.216	44.4591
814.47	44.054
814.724	43.3644
814.977	38.0834
815.231	45.2748
815.485	45.4857
815.739	44.3794
815.992	43.9231
816.246	40.8732
816.499	44.7075
816.753	42.8438
817.007	40.501
817.26	42.1792
817.514	39.6616
817.767	46.28
818.021	41.0021
818.274	40.4269
818.528	40.6529
818.781	42.789
819.01	36.5313
819.264	38.1582
819.518	43.9985
819.772	40.8908
820.026	35.2275
820.28	40.8336
820.534	40.3705
820.788	39.6529
821.042	35.5768
821.296	38.9916
821.549	40.9327
821.803	34.8128
822.057	34.9926
822.311	36.8453
822.565	38.6874
822.819	35.5122
823.073	39.6013
823.326	37.8576
823.58	33.153
823.834	34.1373
824.088	38.6074
824.341	36.2931
824.595	39.2927
824.849	33.432
825.103	38.2687
825.356	37.9296
825.61	36.7302
825.864	39.802
826.117	34.8025
826.371	36.426
826.624	36.5195
826.878	39.7492
827.131	39.1606
827.385	37.5004
827.638	36.0793
827.892	38.5668
828.146	41.7336
828.399	37.2973
828.652	34.6242
828.906	35.4091
829.159	36.4178
829.413	39.0286
829.666	34.358
829.919	36.8307
830.173	40.7442
830.426	37.1733
830.68	35.1296
830.933	32.6531
831.186	37.6408
831.439	36.2017
831.693	33.9128
831.946	37.9446
832.199	33.9737
832.452	36.395
832.706	35.0196
832.959	35.6656
833.212	39.1846
833.465	34.9462
833.718	34.1216
833.971	36.2483
834.224	36.2627
834.477	34.1183
834.73	35.1708
834.984	35.1867
835.237	38.6143
835.49	34.0781
835.743	39.7008
835.996	37.9618
836.201	40.9956
836.454	32.0643
836.708	32.9325
836.961	38.8891
837.215	30.8181
837.468	35.8542
837.722	32.1116
837.975	34.3898
838.229	27.9002
838.482	34.0679
838.735	32.0097
838.989	37.5865
839.242	29.5015
839.496	30.8398
839.749	33.3164
840.002	31.8335
840.256	36.4704
840.509	29.2676
840.762	35.9122
841.015	34.15
841.269	34.1936
841.522	32.6153
841.775	38.2876
842.028	29.8889
842.281	36.4569
842.535	33.8209
842.788	32.9084
843.041	31.1906
843.294	33.4249
843.547	36.5457
843.8	35.6404
844.053	33.6258
844.306	32.4922
844.559	33.8716
844.812	32.232
845.065	29.0193
845.318	31.5898
845.571	32.259
845.824	29.4777
846.077	26.5658
846.33	30.9125
846.583	31.088
846.836	31.0457
847.089	31.5204
847.342	36.205
847.595	36.6736
847.847	30.8846
848.1	32.4344
848.353	32.6184
848.606	32.9954
848.859	29.2013
849.111	33.2757
849.364	35.2362
849.617	32.8947
849.869	29.2347
850.122	36.1559
850.375	35.0407
850.627	33.1715
850.88	30.5999
851.133	33.106
851.385	35.3812
851.638	30.4816
851.89	31.3888
852.143	35.9423
852.395	32.3808
852.648	29.2865
852.9	30.5689
853.153	32.9926
853.405	28.8987
853.645	26.0234
853.898	32.5288
854.151	33.4748
854.404	31.6815
854.657	28.9763
854.91	33.7454
855.163	40.0333
855.416	27.7282
855.669	31.4496
855.922	33.0468
856.175	30.5289
856.427	28.1587
856.68	30.7485
856.933	31.163
857.186	33.3604
857.439	29.9058
857.692	28.2968
857.944	30.5854
858.197	33.1677
858.45	26.5947
858.703	28.0834
858.955	35.2751
859.208	33.5585
859.461	33.5208
859.713	26.1725
859.966	30.5653
860.219	32.0079
860.471	31.798
860.724	31.8594
860.976	34.9398
861.229	30.8998
861.481	32.3039
861.734	30.6135
861.986	31.9125
862.239	29.6291
862.491	29.3797
862.744	31.572
862.996	36.4535
863.249	30.8192
863.501	27.9203
863.754	33.7316
864.006	27.826
864.258	30.1751
864.511	27.7805
864.763	30.921
865.015	33.2648
865.268	31.0696
865.52	31.7287
865.772	30.7752
866.024	30.1883
866.276	27.1315
866.529	28.1476
866.781	35.1923
867.033	31.8852
867.285	32.8917
867.537	30.001
867.789	31.5301
868.042	27.5869
868.294	29.6701
868.546	31.0617
868.798	29.0268
869.05	32.1119
869.302	27.3291
869.554	31.2401
869.806	34.4778
870.058	35.1122
870.31	30.1524
870.562	32.9513
870.782	35.916
871.034	27.7084
871.287	27.4009
871.539	30.2556
871.792	31.2888
872.044	36.8726
872.297	28.6931
872.549	30.0403
872.801	35.984
873.054	34.4245
873.306	28.3441
873.558	33.7026
873.811	28.1152
874.063	29.6496
874.315	27.5962
874.568	33.0397
874.82	30.0594
875.072	30.6741
875.324	28.3778
875.577	32.4379
875.829	29.5149
876.081	29.3705
876.333	32.6054
876.585	34.3193
876.838	33.3398
877.09	27.1273
877.342	31.8654
877.594	31.2113
877.846	28.6989
878.098	32.0378
878.35	30.246
878.602	31.383
878.854	28.4077
879.106	26.3727
879.358	28.4368
879.61	29.1214
879.862	30.1268
880.114	30.5697
880.366	32.3993
880.618	31.6881
880.87	27.2928
881.121	33.5235
881.373	28.201
881.625	25.6791
881.877	29.1073
882.129	33.1253
882.38	28.5355
882.632	31.1944
882.884	27.9268
883.136	28.5215
883.387	30.1677
883.639	28.0844
883.891	28.923
884.142	30.8431
884.394	30.7807
884.646	32.2217
884.897	31.437
885.149	32.1713
885.4	34.3826
885.652	33.5168
885.903	28.5465
886.155	28.1858
886.406	31.076
886.658	29.6296
886.909	31.1808
887.161	27.1123
887.412	29.7735
887.664	31.6929
887.915	31.4351
888.138	27.3558
888.39	30.8558
888.642	29.0915
888.894	30.1587
889.146	29.8807
889.398	32.8916
889.65	27.4143
889.902	31.5056
890.154	31.779
890.406	31.8863
890.657	26.0545
890.909	28.1953
891.161	28.3271
891.413	29.6015
891.665	30.3506
891.916	28.0584
892.168	29.9723
892.42	30.2409
892.671	29.5785
892.923	29.3352
893.175	26.327
893.426	27.5668
893.678	30.1502
893.93	28.1621
894.181	29.276
894.433	29.3052
894.684	30.102
894.936	29.8766
895.188	31.278
895.439	27.0679
895.69	30.2731
895.942	26.2377
896.193	27.8723
896.445	31.9354
896.696	29.6562
896.948	27.628
897.199	27.6465
897.451	29.7224
897.702	29.351
897.953	30.1027
898.204	27.2595
898.456	31.5584
898.707	30.109
898.958	30.5826
899.21	29.3041
899.461	28.9085
899.712	25.4538
899.963	26.6667