File: M7HPHT_270224_01.txt
#Acq. time (s)=	3
#Accumulations=	2
#Range (nm)=	520...900
#Windows=	8
#Auto scanning=	Off
#Autofocus=	Off
#AutoExposure=	Off
#Spike filter=	Multiple accum.
#Delay time (s)=	0
#Binning=	1
#Readout mode=	Signal
#DeNoise=	Off
#ICS correction=	Off
#Dark correction=	Off
#Inst. Process=	Off
#Detector temperature (°C)=	-59.98
#Instrument=	LabRAM HR Evol
#Detector=	Syncerity OE
#Objective=	x50_VIS
#Grating=	600 (500nm)
#ND Filter=	10%
#Laser=	514nm_Edge
#Hole=	199.981
#Range=	Auto
#StageXY=	Marzhauser
#StageZ=	Marzhauser
#X (µm)=	0
#Y (µm)=	0
#Z (µm)=	0
#Full time(mm:ss)=	1:32
#Project=
#Sample=
#Site=
#Title=	M7_270224
#Remark=
#Date=	06.03.2024 10:36
#Acquired=	06.03.2024 10:36:35
520.044	24
520.306	26
520.569	28
520.831	36
521.093	20
521.355	28
521.617	22
521.88	24
522.142	16
522.404	32
522.666	20
522.928	34
523.19	24
523.453	20
523.715	24
523.977	30
524.239	24
524.501	26
524.763	28
525.025	22
525.287	36
525.549	22
525.811	30
526.073	22
526.335	32
526.597	22
526.859	26
527.121	26
527.383	34
527.645	28
527.907	22
528.169	22
528.431	30
528.693	26
528.955	22
529.217	30
529.479	18
529.741	30
530.003	16
530.264	30
530.526	18
530.788	20
531.05	28
531.312	26
531.574	26
531.835	32
532.097	24
532.359	32
532.621	18
532.883	24
533.144	30
533.406	28
533.668	30
533.93	22
534.191	34
534.453	36
534.715	34
534.976	36
535.238	40
535.5	42
535.761	30
536.023	36
536.285	36
536.546	34
536.808	28
537.069	30
537.331	32
537.593	30
537.854	30
538.116	32
538.377	30
538.639	32
538.9	28
539.162	46
539.423	32
539.685	36
539.946	26
540.208	20
540.469	36
540.731	38
540.992	38
541.254	32
541.515	34
541.776	40
542.038	38
542.299	28
542.56	40
542.822	34
543.083	44
543.344	34
543.606	42
543.867	36
544.128	32
544.39	38
544.651	38
544.912	42
545.174	34
545.435	48
545.696	38
545.957	44
546.218	42
546.48	32
546.741	42
547.002	42
547.263	38
547.524	44
547.785	34
548.047	42
548.308	40
548.569	38
548.83	48
549.091	38
549.352	46
549.613	42
549.874	50
550.135	44
550.396	42
550.657	46
550.918	58
551.179	64
551.44	62
551.701	76
551.962	98
552.223	176
552.484	1940
552.745	8382
553.006	234
553.267	104
553.528	62
553.788	64
554.049	62
554.31	76
554.571	40
554.832	54
555.093	50
555.353	62
555.614	58
555.875	54
556.136	58
556.396	60
556.657	64
556.918	56
557.179	54
557.439	54
557.7	58
557.961	58
558.221	62
558.482	68
558.743	66
559.003	62
559.264	58
559.525	60
559.785	62
560.046	64
560.306	72
560.567	78
560.827	72
561.088	70
561.348	68
561.609	68
561.869	72
562.13	86
562.39	70
562.651	88
562.911	68
563.172	76
563.432	82
563.692	82
563.953	68
564.213	84
564.474	88
564.734	88
564.994	100
565.255	88
565.515	98
565.775	86
566.035	98
566.296	102
566.556	98
566.816	90
567.076	92
567.337	86
567.597	92
567.857	106
568.117	105.92
568.377	111.295
568.637	97.6845
568.898	108.9
569.158	106.806
569.418	120.86
569.678	119.373
569.938	123.613
570.198	112.587
570.458	126.53
570.718	119.538
570.978	129.959
571.238	137.625
571.498	131.272
571.758	141.155
572.018	135.77
572.278	161.026
572.538	156.35
572.798	180.189
573.058	173.774
573.312	202
573.573	212
573.834	212
574.095	234
574.356	260
574.617	270
574.878	288
575.139	316
575.4	330
575.661	340
575.922	324
576.183	340
576.444	314
576.705	320
576.965	284
577.226	294
577.487	254
577.748	256
578.009	242
578.27	228
578.531	224
578.791	228
579.052	216
579.313	216
579.574	214
579.835	212
580.095	220
580.356	220
580.617	210
580.878	204
581.138	214
581.399	216
581.66	228
581.92	230
582.181	226
582.442	228
582.703	234
582.963	240
583.224	258
583.484	250
583.745	230
584.006	244
584.266	264
584.527	292
584.787	284
585.048	272
585.308	288
585.569	268
585.83	276
586.09	290
586.351	300
586.611	316
586.872	314
587.132	312
587.392	314
587.653	310
587.913	314
588.174	322
588.434	344
588.695	330
588.955	336
589.215	348
589.476	328
589.736	350
589.996	342
590.257	330
590.517	326
590.777	332
591.038	330
591.298	326
591.558	328
591.818	318
592.079	324
592.339	320
592.599	312
592.859	318
593.12	316
593.38	334
593.64	322
593.9	316
594.16	314
594.42	308
594.68	318
594.941	328
595.201	300
595.461	310
595.721	348
595.981	340
596.241	328
596.501	342
596.761	364
597.021	338
597.281	356
597.541	330
597.801	354
598.061	350
598.321	344
598.581	344
598.841	348
599.101	322
599.361	354
599.62	346
599.88	346
600.14	358
600.4	336
600.66	348
600.92	348
601.18	346
601.439	348
601.699	360
601.959	354
602.219	368
602.478	374
602.738	358
602.998	370
603.258	368
603.517	364
603.777	366
604.037	372
604.296	366
604.556	366
604.816	352
605.075	324
605.335	358
605.594	354
605.854	372
606.114	374
606.373	368
606.633	382
606.892	370
607.152	384
607.411	374
607.671	364
607.93	366
608.19	394
608.449	364
608.709	378
608.968	400
609.228	388
609.487	380
609.746	394
610.006	394
610.265	398
610.524	398
610.784	374
611.043	404
611.302	422
611.562	412
611.821	382
612.08	408
612.339	412
612.599	406
612.858	428
613.117	416
613.376	416
613.635	432
613.895	426
614.154	420
614.413	420
614.672	450
614.931	428
615.19	452
615.449	462
615.709	452
615.968	468
616.227	449.072
616.486	467.552
616.745	450.269
617.004	449.139
617.263	478.405
617.522	476.02
617.781	481.615
618.04	474.543
618.299	481.9
618.557	487.184
618.816	479.847
619.075	466.874
619.334	473.795
619.593	479.647
619.852	491.167
620.111	489.731
620.37	484.891
620.628	494.435
620.887	481.793
621.146	492.416
621.373	490
621.633	498
621.893	492
622.153	478
622.413	512
622.673	496
622.932	484
623.192	490
623.452	506
623.712	508
623.972	478
624.232	502
624.492	502
624.751	522
625.011	522
625.271	518
625.531	526
625.791	546
626.05	538
626.31	528
626.57	532
626.83	532
627.089	540
627.349	560
627.609	542
627.868	544
628.128	546
628.388	534
628.647	558
628.907	560
629.167	568
629.426	574
629.686	568
629.945	568
630.205	598
630.465	600
630.724	588
630.984	588
631.243	612
631.503	596
631.762	610
632.022	610
632.281	598
632.541	622
632.8	600
633.06	602
633.319	652
633.579	668
633.838	668
634.097	628
634.357	634
634.616	642
634.876	678
635.135	682
635.394	670
635.654	722
635.913	734
636.172	726
636.431	766
636.691	790
636.95	858
637.209	892
637.469	954
637.728	964
637.987	1028
638.246	1004
638.505	1032
638.765	974
639.024	910
639.283	934
639.542	894
639.801	862
640.06	856
640.319	838
640.578	836
640.838	842
641.097	832
641.356	850
641.615	792
641.874	824
642.133	780
642.392	824
642.651	820
642.91	794
643.169	796
643.428	782
643.687	820
643.946	830
644.205	820
644.463	826
644.722	838
644.981	832
645.24	846
645.499	828
645.758	844
646.017	868
646.275	846
646.534	856
646.793	844
647.052	868
647.31	876
647.569	850
647.828	878
648.087	844
648.345	902
648.604	900
648.863	912
649.121	864
649.38	870
649.639	902
649.897	934
650.156	960
650.415	910
650.673	950
650.932	940
651.19	966
651.449	946
651.707	996
651.966	990
652.224	950
652.483	990
652.741	1010
653	1008
653.258	998
653.517	1002
653.775	1022
654.034	1044
654.292	1024
654.55	1004
654.809	1050
655.067	1028
655.326	1088
655.584	1106
655.842	1116
656.1	1116
656.359	1108
656.617	1118
656.875	1144
657.134	1158
657.392	1202
657.65	1180
657.908	1174
658.166	1206
658.425	1192
658.683	1210
658.941	1228
659.199	1208
659.457	1188
659.715	1224
659.973	1224
660.231	1228
660.49	1236
660.748	1214
661.006	1240
661.264	1188
661.522	1192
661.78	1242
662.038	1252
662.296	1234
662.554	1238
662.811	1252
663.069	1246
663.327	1250
663.585	1258
663.843	1255.04
664.101	1203.26
664.359	1238.67
664.617	1248.23
664.874	1229.77
665.132	1245.62
665.39	1222.64
665.648	1229.23
665.906	1213.46
666.163	1236.37
666.421	1227.1
666.679	1212.76
666.937	1213
667.194	1242.17
667.452	1242.25
667.71	1222.4
667.967	1222.19
668.225	1247.67
668.482	1208.91
668.74	1236.68
668.987	1232
669.245	1240
669.504	1214
669.763	1248
670.022	1200
670.281	1216
670.539	1230
670.798	1240
671.057	1246
671.316	1228
671.575	1218
671.833	1232
672.092	1264
672.351	1250
672.609	1284
672.868	1236
673.127	1266
673.385	1252
673.644	1290
673.903	1278
674.161	1308
674.42	1280
674.678	1314
674.937	1276
675.195	1322
675.454	1294
675.713	1302
675.971	1340
676.23	1304
676.488	1286
676.747	1324
677.005	1302
677.263	1300
677.522	1348
677.78	1360
678.039	1362
678.297	1338
678.556	1302
678.814	1350
679.072	1330
679.331	1278
679.589	1324
679.847	1306
680.106	1326
680.364	1356
680.622	1340
680.881	1346
681.139	1372
681.397	1370
681.656	1360
681.914	1378
682.172	1374
682.43	1336
682.688	1350
682.947	1396
683.205	1356
683.463	1352
683.721	1362
683.979	1348
684.237	1398
684.495	1356
684.754	1348
685.012	1372
685.27	1408
685.528	1376
685.786	1338
686.044	1358
686.302	1344
686.56	1360
686.818	1362
687.076	1362
687.334	1348
687.592	1334
687.85	1352
688.108	1346
688.366	1306
688.623	1360
688.881	1358
689.139	1328
689.397	1322
689.655	1322
689.913	1344
690.171	1348
690.428	1326
690.686	1314
690.944	1380
691.202	1308
691.459	1320
691.717	1328
691.975	1340
692.233	1302
692.49	1274
692.748	1308
693.006	1316
693.263	1290
693.521	1318
693.779	1278
694.036	1274
694.294	1308
694.552	1274
694.809	1294
695.067	1268
695.324	1272
695.582	1260
695.839	1254
696.097	1274
696.354	1278
696.612	1242
696.869	1262
697.127	1250
697.384	1252
697.642	1268
697.899	1262
698.156	1202
698.414	1212
698.671	1214
698.928	1188
699.186	1176
699.443	1190
699.7	1220
699.958	1192
700.215	1176
700.472	1232
700.73	1202
700.987	1230
701.244	1174
701.501	1186
701.758	1178
702.016	1188
702.273	1204
702.53	1182
702.787	1196
703.044	1232
703.301	1236
703.558	1198
703.816	1206
704.073	1178
704.33	1184
704.587	1200
704.844	1202
705.101	1180
705.358	1180
705.615	1164
705.872	1174
706.129	1134
706.386	1176
706.643	1156
706.899	1128
707.156	1154
707.413	1108
707.67	1128
707.927	1128
708.184	1132
708.441	1114
708.697	1114
708.954	1108
709.211	1074
709.468	1116
709.725	1098
709.981	1152
710.238	1104
710.495	1110
710.751	1098
711.008	1072
711.265	1115.87
711.521	1080.21
711.778	1080.89
712.035	1110.79
712.291	1068.89
712.548	1082.56
712.804	1072.36
713.061	1030.2
713.317	1057.79
713.574	1062.64
713.831	1034.54
714.087	1035.07
714.343	1038.38
714.6	1022.85
714.856	1032.9
715.113	1008.45
715.369	1008.22
715.626	1024.18
715.882	1030
716.138	1014.79
716.395	1010.88
716.639	1010
716.897	1006
717.155	1006
717.412	998
717.67	970
717.927	982
718.185	962
718.443	1010
718.7	962
718.958	972
719.215	972
719.473	978
719.73	968
719.988	974
720.245	936
720.503	948
720.76	932
721.018	920
721.275	950
721.532	914
721.79	918
722.047	944
722.305	880
722.562	898
722.819	904
723.077	930
723.334	866
723.591	876
723.849	880
724.106	906
724.363	856
724.621	874
724.878	854
725.135	868
725.392	866
725.65	836
725.907	836
726.164	838
726.421	836
726.678	864
726.935	830
727.193	830
727.45	840
727.707	838
727.964	842
728.221	840
728.478	776
728.735	822
728.992	844
729.249	798
729.506	802
729.763	774
730.02	768
730.277	792
730.534	780
730.791	746
731.048	772
731.305	752
731.562	754
731.819	760
732.076	752
732.333	756
732.589	758
732.846	752
733.103	752
733.36	748
733.617	724
733.873	742
734.13	758
734.387	724
734.644	750
734.901	754
735.157	756
735.414	768
735.671	744
735.927	778
736.184	766
736.441	774
736.697	784
736.954	806
737.211	780
737.467	806
737.724	826
737.98	828
738.237	832
738.493	828
738.75	792
739.006	812
739.263	814
739.519	776
739.776	796
740.032	770
740.289	756
740.545	746
740.802	776
741.058	714
741.314	690
741.571	726
741.827	730
742.083	730
742.34	700
742.596	674
742.852	666
743.109	708
743.365	678
743.621	662
743.878	648
744.134	632
744.39	670
744.646	628
744.902	682
745.159	644
745.415	644
745.671	638
745.927	620
746.183	630
746.439	632
746.695	614
746.951	600
747.207	626
747.463	608
747.719	612
747.975	636
748.231	620
748.487	578
748.743	630
748.999	594
749.255	582
749.511	580
749.767	572
750.023	600
750.279	614
750.535	588
750.791	558
751.046	550
751.302	544
751.558	560
751.814	550
752.07	566
752.325	572
752.581	554
752.837	576
753.092	520
753.348	528
753.604	526
753.859	536
754.115	562
754.371	548
754.626	540
754.882	546
755.138	522
755.393	536
755.649	540
755.904	534
756.16	526
756.415	500
756.671	484
756.926	524
757.182	500
757.437	518
757.693	472
757.948	506
758.203	484
758.459	488
758.714	464.994
758.97	491.848
759.225	494.044
759.48	492.799
759.736	487.114
759.991	477.695
760.246	476.419
760.501	473.731
760.757	465.616
761.012	454.023
761.267	472.493
761.522	465.921
761.777	457.447
762.033	450.58
762.288	460.581
762.543	457.718
762.798	438.741
763.053	451.396
763.308	430.898
763.563	447.503
763.78	456
764.037	426
764.293	424
764.55	422
764.806	420
765.062	438
765.319	424
765.575	428
765.831	408
766.088	414
766.344	414
766.6	408
766.857	410
767.113	426
767.369	406
767.625	398
767.882	402
768.138	412
768.394	406
768.65	384
768.906	402
769.163	388
769.419	372
769.675	394
769.931	356
770.187	382
770.443	382
770.699	356
770.955	356
771.211	368
771.467	362
771.723	352
771.979	364
772.235	366
772.491	338
772.747	366
773.003	336
773.259	336
773.515	344
773.771	340
774.027	346
774.283	348
774.539	348
774.795	336
775.05	340
775.306	334
775.562	320
775.818	328
776.074	320
776.329	306
776.585	326
776.841	342
777.097	310
777.352	310
777.608	312
777.864	314
778.12	310
778.375	306
778.631	296
778.886	286
779.142	304
779.398	302
779.653	304
779.909	294
780.164	298
780.42	276
780.675	294
780.931	288
781.187	292
781.442	290
781.698	276
781.953	288
782.208	278
782.464	274
782.719	276
782.975	290
783.23	270
783.485	276
783.741	272
783.996	272
784.252	260
784.507	256
784.762	230
785.017	252
785.273	258
785.528	254
785.783	264
786.038	254
786.294	248
786.549	252
786.804	262
787.059	238
787.314	228
787.57	230
787.825	248
788.08	244
788.335	222
788.59	248
788.845	226
789.1	240
789.355	218
789.61	224
789.865	216
790.12	220
790.375	220
790.63	218
790.885	222
791.14	218
791.395	216
791.65	214
791.905	228
792.16	206
792.414	204
792.669	210
792.924	198
793.179	208
793.434	202
793.689	218
793.943	208
794.198	208
794.453	194
794.708	206
794.962	188
795.217	198
795.472	206
795.726	210
795.981	198
796.236	198
796.49	182
796.745	190
796.999	186
797.254	188
797.508	198
797.763	176
798.018	178
798.272	176
798.526	182
798.781	182
799.035	170
799.29	188
799.544	192
799.799	186
800.053	180
800.307	174
800.562	176
800.816	164
801.07	170
801.325	178
801.579	182
801.833	162
802.088	170
802.342	150
802.596	152
802.85	168
803.105	160
803.359	152
803.613	152
803.867	158
804.121	160
804.375	164
804.63	136
804.884	162
805.138	146
805.392	152
805.646	151.588
805.9	140.654
806.154	142.114
806.408	146.058
806.662	141.064
806.916	147.509
807.17	148.657
807.424	142.502
807.678	144.479
807.931	137.161
808.185	141.902
808.439	144.678
808.693	137.188
808.947	139.295
809.201	138.316
809.454	139.423
809.708	131.096
809.962	128.161
810.216	133.263
810.469	126.98
810.678	138
810.933	126
811.188	128
811.443	126
811.699	112
811.954	130
812.209	128
812.464	122
812.719	132
812.974	120
813.229	118
813.484	118
813.739	132
813.994	120
814.249	118
814.504	126
814.759	114
815.014	124
815.268	112
815.523	114
815.778	118
816.033	106
816.288	118
816.543	98
816.798	108
817.052	108
817.307	118
817.562	106
817.817	112
818.071	98
818.326	120
818.581	106
818.836	112
819.09	96
819.345	108
819.6	106
819.854	114
820.109	112
820.364	92
820.618	104
820.873	100
821.127	102
821.382	98
821.637	106
821.891	100
822.146	94
822.4	106
822.655	100
822.909	92
823.164	108
823.418	96
823.672	108
823.927	96
824.181	98
824.436	80
824.69	96
824.944	90
825.199	80
825.453	92
825.707	88
825.962	100
826.216	94
826.47	94
826.725	94
826.979	92
827.233	90
827.487	96
827.741	88
827.996	90
828.25	90
828.504	98
828.758	90
829.012	78
829.266	84
829.52	76
829.774	86
830.029	86
830.283	76
830.537	84
830.791	84
831.045	84
831.299	80
831.553	90
831.807	76
832.061	82
832.315	78
832.568	86
832.822	80
833.076	88
833.33	74
833.584	68
833.838	86
834.092	80
834.345	82
834.599	80
834.853	72
835.107	84
835.36	82
835.614	76
835.868	78
836.122	78
836.375	78
836.629	66
836.883	76
837.136	88
837.39	76
837.643	76
837.897	78
838.151	76
838.404	74
838.658	76
838.911	78
839.165	76
839.418	74
839.672	80
839.925	72
840.179	64
840.432	64
840.686	78
840.939	60
841.192	60
841.446	68
841.699	72
841.952	62
842.206	72
842.459	74
842.712	72
842.966	66
843.219	68
843.472	66
843.725	66
843.979	60
844.232	68
844.485	66
844.738	64
844.991	76
845.244	68
845.497	64
845.75	58
846.004	62
846.257	74
846.51	62
846.763	62
847.016	70
847.269	62
847.522	56
847.775	68
848.028	60
848.281	60
848.534	60
848.786	68
849.039	64
849.292	64
849.545	68
849.798	66
850.051	58
850.303	66
850.556	66
850.809	60
851.062	56
851.314	54
851.567	62
851.82	60
852.073	58
852.325	54.0194
852.578	56.1108
852.831	60.0318
853.083	56
853.336	57.214
853.588	56.1853
853.841	58.3246
854.093	53.2863
854.346	48.0461
854.598	54.2308
854.851	60.7939
855.103	57.6611
855.356	57.58
855.608	53.247
855.861	59.1059
856.113	52.2724
856.366	49.1456
856.618	53.0239
856.87	52.3068
857.123	52.2406
857.352	56
857.606	48
857.859	54
858.113	58
858.367	60
858.621	48
858.875	48
859.128	62
859.382	60
859.636	42
859.889	50
860.143	48
860.397	56
860.65	60
860.904	42
861.158	52
861.411	62
861.665	50
861.918	50
862.172	50
862.425	62
862.679	50
862.932	46
863.186	48
863.439	50
863.693	58
863.946	48
864.2	50
864.453	58
864.707	54
864.96	48
865.213	32
865.467	48
865.72	44
865.973	52
866.227	46
866.48	46
866.733	50
866.987	52
867.24	46
867.493	46
867.746	56
867.999	50
868.253	50
868.506	48
868.759	52
869.012	48
869.265	44
869.518	48
869.771	44
870.025	50
870.278	46
870.531	38
870.784	42
871.037	38
871.29	44
871.543	52
871.796	48
872.049	46
872.302	48
872.555	52
872.808	42
873.06	38
873.313	48
873.566	44
873.819	42
874.072	58
874.325	46
874.578	46
874.83	36
875.083	38
875.336	48
875.589	46
875.841	46
876.094	38
876.347	50
876.6	44
876.852	46
877.105	38
877.358	42
877.61	50
877.863	46
878.115	40
878.368	44
878.621	42
878.873	50
879.126	30
879.378	46
879.631	48
879.883	46
880.136	36
880.388	42
880.641	46
880.893	46
881.145	36
881.398	38
881.65	38
881.902	46
882.155	44
882.407	44
882.659	46
882.912	44
883.164	46
883.416	36
883.669	36
883.921	52
884.173	40
884.425	40
884.677	38
884.93	42
885.182	48
885.434	46
885.686	38
885.938	36
886.19	48
886.442	42
886.694	38
886.946	36
887.198	36
887.45	36
887.702	40
887.954	36
888.206	40
888.458	38
888.71	34
888.962	34
889.214	36
889.466	34
889.718	36
889.969	34
890.221	38
890.473	42
890.725	34
890.977	30
891.228	36
891.48	38
891.732	34
891.983	34
892.235	42
892.487	36
892.738	32
892.99	38
893.242	32
893.493	40
893.745	38
893.996	42
894.248	28
894.5	32
894.751	34
895.003	42
895.254	38
895.505	36
895.757	30
896.008	38
896.26	38
896.511	34
896.763	38
897.014	38
897.265	40
897.517	34
897.768	40
898.019	36
898.27	36
898.522	32
898.773	24
899.024	36
899.275	30
899.527	34
899.778	36
899.979	22