File: M8_140224_01.txt
#Acq. time (s)=	2
#Accumulations=	3
#Range (nm)=	520...900
#Windows=	24
#Auto scanning=	On
#Autofocus=	Off
#AutoExposure=	Off
#Spike filter=	Multiple accum.
#Delay time (s)=	0
#Binning=	1
#Readout mode=	Signal
#DeNoise=	Off
#ICS correction=	Off
#Dark correction=	Off
#Inst. Process=	Off
#Detector temperature (°C)=	-59.98
#Instrument=	LabRAM HR Evol
#Detector=	Syncerity OE
#Objective=	x50_VIS
#Grating=	600 (500nm)
#ND Filter=	25%
#Laser=	514nm_Edge
#Hole=	199.981
#Range=	Auto
#StageXY=	Marzhauser
#StageZ=	Marzhauser
#X (µm)=	-5129.7
#Y (µm)=	8193.4
#Z (µm)=	-417.5
#Full time(mm:ss)=	3:03
#Project=
#Sample=
#Site=
#Title=	M8_140224
#Remark=
#Date=	19.02.2024 14:58
#Acquired=	19.02.2024 14:58:17
520.013	30.6806
520.274	36.0737
520.536	30.756
520.797	31.9076
521.059	34.7423
521.32	31.2353
521.582	28.5787
521.843	29.6487
522.105	35.9397
522.366	28.62
522.628	33.6958
522.889	31.4391
523.15	32.7446
523.412	33.3204
523.673	36.4263
523.935	31.1294
524.196	31.6442
524.457	30.1708
524.719	31.3881
524.98	28.1601
525.241	30.634
525.503	29.6115
525.764	26.5504
526.025	32.8374
526.286	31.2147
526.548	33.4342
526.809	30.7388
527.07	27.7633
527.331	32.3626
527.593	32.9665
527.854	34.1678
528.115	36.3007
528.376	26.5664
528.637	27.5258
528.898	29.8944
529.16	30.798
529.421	32.0605
529.682	31.933
529.943	30.491
530.204	30.7124
530.465	32.2662
530.726	28.8127
530.987	28.2803
531.248	31.2476
531.509	32.1157
531.77	35.7668
532.031	30.1454
532.292	33.3725
532.553	33.8339
532.814	32.9653
533.075	31.5359
533.336	31.1026
533.597	35.5846
533.858	32.8113
534.119	31.8124
534.38	35.0476
534.641	37.5735
534.901	42.6865
535.162	45.3421
535.423	39.2111
535.684	40.9
535.945	33.0933
536.205	30.8971
536.466	33.6144
536.727	35.3777
536.988	35.7125
537.248	37.9597
537.509	35.3825
537.77	36.6679
537.987	38.4568
538.249	35.2385
538.51	33.3094
538.771	34.6382
539.032	33.6574
539.293	34.5139
539.554	37.5298
539.815	35.0659
540.076	35.0873
540.337	41.5982
540.598	34.9603
540.859	34.2335
541.12	29.6403
541.381	36.159
541.642	32.2068
541.903	36.4325
542.164	39.8209
542.425	39.6612
542.686	36.302
542.947	34.658
543.208	39.3467
543.469	42.0296
543.73	39.9497
543.991	40.4969
544.252	39.0789
544.513	40.1729
544.773	34.3238
545.034	38.0276
545.295	40.915
545.556	34.4813
545.817	41.1123
546.077	43.2516
546.338	42.3108
546.599	46.6346
546.86	39.6861
547.12	39.6574
547.381	34.5732
547.642	46.8824
547.903	44.8351
548.163	50.4264
548.424	48.0034
548.685	42.5289
548.945	38.7391
549.206	49.8842
549.467	44.0552
549.727	54.5578
549.988	49.132
550.248	52.3744
550.509	51.9598
550.769	61.9563
551.03	69.8074
551.291	78.8283
551.551	91.7275
551.812	121.392
552.072	193.022
552.332	527.65
552.593	13512.5
552.853	3182.75
553.114	279.491
553.374	136.213
553.635	95.0646
553.895	76.4989
554.155	64.3802
554.416	60.9868
554.676	59.4858
554.937	56.0261
555.197	55.2156
555.457	56.2016
555.686	60.8832
555.947	53.1202
556.207	59.6639
556.468	48.5228
556.729	51.142
556.99	48.7823
557.25	54.9639
557.511	58.3858
557.772	55.8345
558.032	49.0628
558.293	57.3075
558.554	51.2914
558.814	59.1665
559.075	56.1535
559.336	60.4615
559.596	54.86
559.857	64.7977
560.117	62.5621
560.378	55.508
560.638	60.1681
560.899	63.3569
561.159	63.2976
561.42	59.5721
561.68	59.4089
561.941	61.1886
562.201	67.1273
562.462	58.1045
562.722	70.3764
562.983	71.553
563.243	63.6502
563.504	68.7985
563.764	71.0517
564.024	71.5868
564.285	69.6227
564.545	73.8949
564.805	72.7801
565.066	69.7529
565.326	71.4846
565.586	71.6988
565.847	73.5249
566.107	78.0473
566.367	78.2072
566.627	73.5616
566.888	75.4724
567.148	71.6918
567.408	77.3363
567.668	79.9618
567.928	80.79
568.189	77.1108
568.449	86.3505
568.709	83.6425
568.969	84.3887
569.229	82.5653
569.489	88.9442
569.749	89.287
570.009	90.5713
570.269	93.1105
570.53	97.8601
570.79	94.6091
571.05	91.9713
571.31	97.6359
571.57	105.076
571.83	104.648
572.09	113.061
572.349	112.791
572.609	118.746
572.869	124.033
573.129	126.836
573.368	134.863
573.629	143.492
573.889	152.69
574.15	157.908
574.41	172.132
574.67	181.823
574.931	190.754
575.191	201.869
575.451	218.423
575.711	225.313
575.972	223.194
576.232	218.036
576.492	211.006
576.752	200.728
577.013	198.458
577.273	188.966
577.533	178.881
577.793	163.448
578.053	169.483
578.313	170.741
578.574	152.555
578.834	160.178
579.094	162.753
579.354	166.176
579.614	164.144
579.874	171.238
580.134	168.677
580.394	170.474
580.654	170.894
580.914	165.97
581.174	168.331
581.434	181.212
581.694	179.289
581.954	179.165
582.214	182.068
582.474	191.404
582.734	191.602
582.994	197.529
583.254	198.309
583.514	200.531
583.773	209.408
584.033	210.856
584.293	215.581
584.553	227.292
584.813	227.572
585.073	234.377
585.332	234.296
585.592	236.942
585.852	243.579
586.112	245.702
586.371	247.937
586.631	252.763
586.891	250.809
587.151	258.898
587.41	262.294
587.67	265.313
587.93	270.543
588.189	265.983
588.449	278.986
588.709	289.77
588.968	299.84
589.228	321.23
589.487	316.571
589.747	320.864
590.006	303.11
590.266	297.092
590.525	302.777
590.785	289.146
591.036	272.231
591.296	269.694
591.556	279.205
591.816	244.432
592.076	254.22
592.336	244.571
592.596	258.568
592.856	253.278
593.116	247.349
593.376	252.438
593.635	246.579
593.895	253.827
594.155	246.918
594.415	239.018
594.675	253.628
594.935	241.49
595.194	243.324
595.454	244.432
595.714	252.372
595.974	255.809
596.233	267.883
596.493	273.783
596.753	281.035
597.012	255.62
597.272	254.079
597.532	242.84
597.791	258.91
598.051	236.209
598.311	247.937
598.57	248.801
598.83	238.47
599.089	245.929
599.349	238.569
599.609	241.732
599.868	237.695
600.128	240.701
600.387	242.642
600.647	236.279
600.906	240.053
601.166	237.996
601.425	236.178
601.685	235.299
601.944	233.644
602.203	242.258
602.463	238.028
602.722	240.587
602.982	243.679
603.241	242.002
603.5	241.177
603.76	234.062
604.019	249.109
604.278	253.507
604.538	247.457
604.797	246.78
605.056	243.965
605.315	249.079
605.575	237.683
605.834	251.86
606.093	258.198
606.352	252.293
606.611	250.994
606.871	251.21
607.13	256.403
607.389	251.627
607.648	254.431
607.907	249.519
608.166	256.53
608.425	256.699
608.664	245.572
608.924	256.577
609.183	262.422
609.443	254.819
609.702	258.242
609.962	256.899
610.221	272.611
610.481	265.788
610.74	260.337
611	272.463
611.259	271.847
611.518	276.757
611.778	268.715
612.037	260.449
612.297	268.203
612.556	272.16
612.815	274.915
613.075	282.873
613.334	272.72
613.594	266.576
613.853	272.017
614.112	278.022
614.371	284.36
614.631	292.626
614.89	284.907
615.149	292.835
615.408	287.526
615.668	288.179
615.927	290.598
616.186	299.099
616.445	302.466
616.704	301.437
616.964	304.791
617.223	302.133
617.482	297.89
617.741	308.101
618	314.695
618.259	305.853
618.518	313.232
618.777	313.946
619.036	312.674
619.295	312.868
619.554	315.247
619.813	325.052
620.072	313.972
620.331	318.457
620.59	314.062
620.849	327.155
621.108	328.493
621.367	319.238
621.626	327.983
621.885	337.584
622.144	322.584
622.403	325.947
622.661	327.751
622.92	329.516
623.179	331.513
623.438	325.471
623.697	332.174
623.956	339.57
624.214	327.701
624.473	329.952
624.732	326.183
624.99	331.569
625.249	324.51
625.508	339.513
625.767	326.327
626.025	340.608
626.249	329.055
626.508	332.529
626.767	343.674
627.026	353.606
627.285	340.588
627.544	338.144
627.803	320.888
628.062	351.82
628.321	351.707
628.58	347.593
628.839	352.231
629.098	341.658
629.357	343.234
629.616	348.854
629.875	341.244
630.134	343.539
630.393	349.831
630.652	359.566
630.911	359.752
631.17	360.095
631.429	366.131
631.688	365.621
631.947	361.462
632.206	367.464
632.464	368.453
632.723	372.6
632.982	366.133
633.241	381.362
633.5	367.193
633.758	378.64
634.017	394.06
634.276	371.518
634.535	381.969
634.793	385.01
635.052	385.217
635.311	397.84
635.57	400.894
635.828	405.751
636.087	414.655
636.345	419.081
636.604	421.462
636.863	447.862
637.121	460.633
637.38	487.012
637.638	501.259
637.897	490.642
638.156	514.469
638.414	499.057
638.673	505.427
638.931	501.877
639.19	488.39
639.448	492.123
639.706	479.702
639.965	472.248
640.223	464.323
640.482	442.668
640.74	454.426
640.999	445.091
641.257	445.538
641.515	442.924
641.774	439.015
642.032	444.595
642.29	440.128
642.549	454.545
642.807	449.148
643.065	441.356
643.323	447.053
643.582	437.192
643.84	440.725
644.053	447.099
644.312	444.539
644.57	447.007
644.829	434.446
645.088	442.873
645.346	457.877
645.605	441.413
645.864	475.875
646.122	450.613
646.381	450.2
646.639	457.608
646.898	462.263
647.157	465.181
647.415	449.082
647.674	456.645
647.932	466.491
648.191	467.381
648.449	460.194
648.708	467.508
648.966	467.332
649.225	487.719
649.483	480.969
649.742	480.677
650	477.961
650.258	471.955
650.517	486.39
650.775	480.273
651.034	497.183
651.292	500.104
651.55	488.851
651.809	488.88
652.067	480.79
652.325	497.488
652.583	492.663
652.842	500.669
653.1	505.645
653.358	517.225
653.616	520.069
653.875	527.468
654.133	496.807
654.391	529.014
654.649	527.686
654.907	539.284
655.165	521.156
655.424	537.7
655.682	528.83
655.94	547.953
656.198	549.187
656.456	565.344
656.714	570.341
656.972	564.847
657.23	571.328
657.488	564.999
657.746	587.282
658.004	584.553
658.262	574.822
658.52	594.429
658.778	583.016
659.036	607.884
659.294	591.625
659.552	592.666
659.809	594.761
660.067	594.146
660.325	588.879
660.583	586.652
660.841	591.012
661.099	600.485
661.356	588.71
661.583	607.959
661.842	577.25
662.1	590.333
662.358	600.866
662.616	586.894
662.875	584.687
663.133	588.669
663.391	599.742
663.649	583.296
663.907	585.703
664.166	600.255
664.424	596.178
664.682	588.928
664.94	581.099
665.198	597.619
665.456	597.867
665.714	594.574
665.972	586.479
666.23	579.906
666.488	582.911
666.746	582.084
667.004	590.583
667.262	581.875
667.52	602.802
667.778	572.208
668.036	594.03
668.294	597.646
668.552	578.453
668.81	574.799
669.068	608.606
669.326	584.581
669.584	565.175
669.842	571.113
670.099	582.92
670.357	582.349
670.615	584.063
670.873	576.894
671.131	581.273
671.388	576.527
671.646	579.488
671.904	583.324
672.162	586.508
672.419	579.019
672.677	572.583
672.935	597.835
673.192	606.003
673.45	577.792
673.708	590.279
673.965	606.776
674.223	605.171
674.481	599.987
674.738	613.557
674.996	620.556
675.253	606.172
675.511	591.718
675.768	610.359
676.026	617.979
676.283	610.735
676.541	612.815
676.798	590.959
677.056	618.387
677.313	605.039
677.571	607.324
677.828	603.602
678.085	605.174
678.343	609.54
678.6	613.097
678.857	607.988
679.083	603.382
679.341	608.888
679.599	613.851
679.857	617.878
680.114	616.001
680.372	606.384
680.63	618.329
680.888	602.314
681.146	629.327
681.403	603.941
681.661	615.13
681.919	624.345
682.176	626.43
682.434	617.694
682.692	622.36
682.949	620.78
683.207	613.082
683.465	621.002
683.722	626.771
683.98	622.933
684.237	627.017
684.495	627.306
684.753	620.59
685.01	622.879
685.268	615.263
685.525	608.29
685.783	611.75
686.04	607.863
686.298	599.497
686.555	607.914
686.813	625.564
687.07	606.094
687.327	585.814
687.585	593.619
687.842	608.302
688.1	612.157
688.357	595.416
688.614	611.838
688.872	610.266
689.129	603.035
689.386	608.459
689.643	603.224
689.901	603.134
690.158	603.783
690.415	611.792
690.672	601.606
690.93	599.207
691.187	604.711
691.444	581.906
691.701	590.945
691.958	572.123
692.216	591.069
692.473	594.77
692.73	580.448
692.987	589.696
693.244	581.164
693.501	587.94
693.758	585.317
694.015	578.086
694.272	576.31
694.529	571.37
694.786	574.418
695.043	575.016
695.3	584.099
695.557	575.677
695.814	583.296
696.071	566.865
696.328	557.448
696.585	560.734
696.81	568.873
697.068	559.346
697.325	574.886
697.582	563.576
697.84	546.099
698.097	553.235
698.354	542.359
698.612	544.851
698.869	553.685
699.126	546.956
699.384	548.833
699.641	540.979
699.898	537.555
700.155	539.516
700.413	533.375
700.67	533.323
700.927	533.292
701.184	536.169
701.441	540.038
701.698	524.193
701.956	546.044
702.213	541.801
702.47	536.175
702.727	544.572
702.984	549.3
703.241	542.046
703.498	535.053
703.755	540.006
704.012	541.573
704.269	529.681
704.526	537.712
704.783	534.087
705.04	541.048
705.297	515.529
705.554	521.466
705.811	523.846
706.068	523.675
706.324	505.965
706.581	518.751
706.838	501.169
707.095	518.68
707.352	508.17
707.609	506.508
707.865	498.298
708.122	516.733
708.379	511.526
708.636	508.874
708.892	493.011
709.149	493.613
709.406	487.966
709.662	497.546
709.919	492.214
710.176	497.517
710.432	506.786
710.689	499.761
710.946	481.927
711.202	479.015
711.459	486.508
711.715	484.174
711.972	484.152
712.228	480.695
712.485	486.101
712.741	484.738
712.998	471.49
713.254	477.238
713.511	482.122
713.767	462.612
714.024	465.563
714.231	471.638
714.488	475.552
714.745	454.606
715.002	463.501
715.259	449.512
715.516	453.125
715.773	453.039
716.029	447.245
716.286	451.656
716.543	442.495
716.8	446.433
717.057	441.576
717.314	445.751
717.57	444.935
717.827	439.23
718.084	439.811
718.341	441.156
718.597	436.023
718.854	432.213
719.111	440.626
719.367	437.875
719.624	434.434
719.881	432.925
720.137	434.38
720.394	430.271
720.65	434.327
720.907	440.857
721.164	415.98
721.42	421.622
721.677	418.674
721.933	425.216
722.19	413.363
722.446	414.942
722.703	411.531
722.959	433.277
723.216	413.845
723.472	416.322
723.728	415.658
723.985	411.506
724.241	429.402
724.498	412.313
724.754	411.508
725.01	415.852
725.267	420.898
725.523	415.963
725.779	405.523
726.036	416.071
726.292	416.646
726.548	420.716
726.804	406.208
727.06	401.223
727.317	416.388
727.573	412.612
727.829	416.42
728.085	405.482
728.341	413.286
728.597	398.811
728.854	406.408
729.11	401.429
729.366	398.453
729.622	404.699
729.878	398.666
730.134	408.152
730.39	398.879
730.646	407.392
730.902	390.494
731.158	407.815
731.414	400.425
731.622	406.702
731.878	408.833
732.135	408.058
732.391	415.952
732.648	410.237
732.904	417.337
733.161	416.679
733.417	401.357
733.673	418.122
733.93	431.195
734.186	443.773
734.443	433.68
734.699	460.746
734.955	466.817
735.211	485.62
735.468	504.679
735.724	513.761
735.98	530.09
736.237	560.948
736.493	590.269
736.749	621.861
737.005	635.624
737.261	681.024
737.518	704.742
737.774	741.029
738.03	750.817
738.286	774.583
738.542	760.89
738.798	769.142
739.054	753.49
739.31	708.867
739.566	691.872
739.822	666.718
740.078	624.084
740.334	601.714
740.59	569.259
740.846	544.1
741.102	525.021
741.358	497.22
741.614	478.261
741.87	479.157
742.126	465.268
742.382	442.753
742.638	440.508
742.893	420.782
743.149	413.827
743.405	405.25
743.661	398.954
743.917	389.612
744.172	389.287
744.428	375.411
744.684	373.967
744.94	373.251
745.195	361.164
745.451	359.894
745.707	360.756
745.962	355.204
746.218	349.502
746.474	348.602
746.729	345.483
746.985	342.243
747.241	337.163
747.496	340.885
747.752	339.042
748.007	335.198
748.263	328.512
748.518	326.611
748.774	327.798
749.029	310.654
749.275	317.424
749.531	319.051
749.787	316.617
750.043	324.226
750.299	316.183
750.555	312.051
750.811	316.113
751.067	308.34
751.323	308.61
751.579	304.045
751.835	296.931
752.09	306.492
752.346	307.775
752.602	299.952
752.858	299.988
753.114	301.969
753.37	304.659
753.625	302.327
753.881	293.042
754.137	300.442
754.393	287.902
754.648	299.14
754.904	281.334
755.16	299.91
755.415	284.612
755.671	276.309
755.927	285.007
756.182	271.519
756.438	284.371
756.693	283.172
756.949	280.832
757.205	280.642
757.46	276.123
757.716	276.067
757.971	272.957
758.227	265.301
758.482	264.223
758.738	256.804
758.993	261.158
759.248	266.57
759.504	268.022
759.759	269.477
760.015	252.709
760.27	262.372
760.525	256.327
760.781	261.667
761.036	255.408
761.291	250.316
761.547	252.965
761.802	255.461
762.057	248.373
762.313	245.593
762.568	245.197
762.823	251.474
763.078	249.366
763.333	244.539
763.589	240.758
763.844	241.606
764.099	247.486
764.354	247.001
764.609	239.618
764.864	246.469
765.119	231.265
765.374	241.074
765.629	235.918
765.884	230.961
766.139	233.434
766.394	237.715
766.649	239.455
766.882	234.249
767.137	224.64
767.393	230.821
767.648	230.171
767.904	222.575
768.159	226.932
768.415	219.617
768.67	223.421
768.926	215.388
769.181	214.562
769.436	208.177
769.692	218.381
769.947	205.043
770.203	215.318
770.458	210.225
770.713	207.814
770.968	206.913
771.224	193.709
771.479	206.101
771.734	209.184
771.99	203.265
772.245	205.977
772.5	201.842
772.755	193.183
773.01	189.131
773.265	190.722
773.521	199.611
773.776	195.73
774.031	192.114
774.286	182.578
774.541	187.761
774.796	179.332
775.051	182.96
775.306	178.439
775.561	176.718
775.816	180.291
776.071	180.507
776.326	178.001
776.581	179.112
776.836	169.572
777.091	172.961
777.346	173.143
777.601	172.693
777.856	168.324
778.111	171.052
778.365	167.819
778.62	164.9
778.875	161.373
779.13	165.221
779.385	156.13
779.639	157.496
779.894	161.722
780.149	158.482
780.404	157.466
780.658	160.456
780.913	157.679
781.168	156.948
781.422	161.377
781.677	155.923
781.932	152.198
782.186	149.44
782.441	155.066
782.695	144.221
782.95	148.125
783.204	139.307
783.459	137.598
783.714	142.651
783.968	149.787
784.211	149.26
784.466	140.751
784.721	137.76
784.976	131.242
785.231	142.943
785.486	140.91
785.741	134.134
785.996	128.902
786.251	134.133
786.506	133.623
786.761	132.92
787.016	136.54
787.271	130.934
787.526	130.24
787.78	132.422
788.035	131.08
788.29	124.972
788.545	129.987
788.8	128.761
789.054	136.664
789.309	128.136
789.564	131.646
789.819	126.761
790.073	126.557
790.328	125.419
790.583	130.13
790.837	123.195
791.092	125.033
791.347	119.907
791.601	123.784
791.856	118.297
792.11	115.874
792.365	123.355
792.619	123.469
792.874	113.824
793.128	120.576
793.383	115.894
793.638	111.798
793.892	116.292
794.146	110.427
794.401	118.441
794.655	115.146
794.91	110.563
795.164	115.585
795.418	117.15
795.673	106.683
795.927	108.331
796.181	108.504
796.436	108.053
796.69	107.841
796.944	112.731
797.199	107.733
797.453	106.048
797.707	108.411
797.961	102.078
798.216	100.934
798.47	99.7997
798.724	107.205
798.978	102.449
799.232	95.2027
799.486	99.1306
799.74	98.5931
799.994	100.835
800.248	102.637
800.503	96.4804
800.757	99.1274
801.011	99.2614
801.265	98.0074
801.508	91.244
801.762	95.8607
802.017	91.956
802.271	102.101
802.526	80.6209
802.78	96.8446
803.035	95.9675
803.289	85.6913
803.544	85.4445
803.798	96.4908
804.052	88.9298
804.307	89.4881
804.561	92.2746
804.816	90.7013
805.07	89.2204
805.324	76.6838
805.579	87.2705
805.833	85.7125
806.087	89.1832
806.341	89.4268
806.596	88.3875
806.85	85.0632
807.104	87.8491
807.358	74.5685
807.613	88.9888
807.867	85.58
808.121	86.2309
808.375	86.35
808.629	83.9407
808.883	83.6845
809.138	73.987
809.392	79.335
809.646	77.5805
809.9	85.2129
810.154	80.7301
810.408	78.8377
810.662	83.6544
810.916	76.2373
811.17	77.3865
811.424	85.267
811.678	78.9821
811.932	76.474
812.185	80.03
812.439	80.6525
812.693	74.3581
812.947	75.8705
813.201	79.3965
813.455	77.7431
813.709	85.097
813.962	76.894
814.216	70.262
814.47	75.6552
814.724	77.3586
814.977	75.9902
815.231	75.5121
815.485	75.0288
815.739	73.5043
815.992	69.7073
816.246	70.6553
816.499	70.1593
816.753	70.3096
817.007	68.4661
817.26	68.9055
817.514	68.2582
817.767	74.5681
818.021	61.9268
818.274	73.1521
818.528	68.3828
818.781	61.8661
819.01	70.4369
819.264	65.4015
819.518	65.3445
819.772	69.3189
820.026	63.6914
820.28	65.0413
820.534	62.75
820.788	64.974
821.042	61.7587
821.296	60.1048
821.549	59.4427
821.803	69.9144
822.057	65.1622
822.311	67.6564
822.565	59.5541
822.819	60.8558
823.073	58.8181
823.326	59.0296
823.58	61.9758
823.834	65.1219
824.088	61.4428
824.341	61.3334
824.595	62.3273
824.849	57.2788
825.103	61.6604
825.356	58.3914
825.61	59.9292
825.864	61.5958
826.117	58.6078
826.371	56.6631
826.624	57.3036
826.878	62.1979
827.131	58.8529
827.385	58.6326
827.638	57.2979
827.892	55.7714
828.146	60.9302
828.399	53.0153
828.652	56.7083
828.906	54.9119
829.159	58.5716
829.413	55.5036
829.666	60.2906
829.919	59.6478
830.173	60.0862
830.426	54.9785
830.68	55.2049
830.933	54.0768
831.186	57.913
831.439	51.975
831.693	52.6178
831.946	57.9378
832.199	52.2348
832.452	57.7775
832.706	56.3756
832.959	55.2433
833.212	52.7276
833.465	59.3729
833.718	57.1015
833.971	55.7732
834.224	48.8287
834.477	46.5725
834.73	50.9733
834.984	51.0894
835.237	55.8953
835.49	54.0465
835.743	58.839
835.996	56.9188
836.201	51.09
836.454	52.9563
836.708	54.0436
836.961	49.8516
837.215	54.162
837.468	51.728
837.722	48.0292
837.975	45.0809
838.229	50.467
838.482	54.233
838.735	56.5757
838.989	57.1821
839.242	50.2578
839.496	49.6123
839.749	50.8411
840.002	47.1254
840.256	50.5287
840.509	50.3037
840.762	49.0184
841.015	48.911
841.269	51.0055
841.522	49.5086
841.775	47.9623
842.028	48.3585
842.281	45.9237
842.535	54.0147
842.788	48.0851
843.041	46.4607
843.294	46.9125
843.547	46.9183
843.8	48.0272
844.053	46.0082
844.306	47.0473
844.559	51.3437
844.812	50.0922
845.065	46.3276
845.318	50.5619
845.571	49.6604
845.824	42.6762
846.077	44.2177
846.33	47.0094
846.583	48.6249
846.836	46.5368
847.089	46.5303
847.342	47.9498
847.595	46.9171
847.847	40.9866
848.1	41.4788
848.353	47.5847
848.606	47.2012
848.859	47.1182
849.111	40.7533
849.364	46.1786
849.617	48.4389
849.869	45.9404
850.122	42.8981
850.375	47.9009
850.627	46.2087
850.88	50.2939
851.133	45.8257
851.385	45.9025
851.638	44.0166
851.89	42.6549
852.143	44.78
852.395	47.322
852.648	43.8667
852.9	43.4834
853.153	43.3087
853.405	43.4012
853.645	42.424
853.898	44.9422
854.151	43.3577
854.404	48.0685
854.657	45.7612
854.91	45.4207
855.163	44.1243
855.416	47.9121
855.669	42.4531
855.922	40.4172
856.175	42.3753
856.427	43.9084
856.68	39.4828
856.933	40.4216
857.186	40.1033
857.439	40.3785
857.692	41.1764
857.944	43.5452
858.197	43.8956
858.45	44.0456
858.703	42.7426
858.955	40.8302
859.208	46.217
859.461	40.1769
859.713	36.757
859.966	38.8019
860.219	43.5984
860.471	37.1408
860.724	40.5384
860.976	45.41
861.229	48.1897
861.481	45.437
861.734	37.8366
861.986	37.2845
862.239	39.8906
862.491	37.11
862.744	37.0831
862.996	47.5098
863.249	42.287
863.501	44.013
863.754	37.4344
864.006	39.5321
864.258	41.5641
864.511	34.7191
864.763	39.365
865.015	43.6397
865.268	44.6004
865.52	37.2618
865.772	31.9153
866.024	39.261
866.276	39.0797
866.529	39.2288
866.781	39.648
867.033	42.1693
867.285	38.0252
867.537	39.647
867.789	41.9689
868.042	38.6197
868.294	42.3377
868.546	38.6127
868.798	40.0299
869.05	39.058
869.302	38.3706
869.554	34.9621
869.806	39.1233
870.058	40.7359
870.31	38.566
870.562	34.4236
870.782	39.2624
871.034	43.8492
871.287	37.8877
871.539	36.9502
871.792	46.9192
872.044	39.1901
872.297	41.1335
872.549	34.3105
872.801	43.509
873.054	38.729
873.306	35.0229
873.558	36.1846
873.811	40.4688
874.063	38.1665
874.315	36.6569
874.568	41.232
874.82	37.113
875.072	33.006
875.324	32.0151
875.577	35.4392
875.829	38.6263
876.081	36.3252
876.333	35.6087
876.585	41.4946
876.838	36.0985
877.09	40.3914
877.342	37.1484
877.594	39.1891
877.846	37.2038
878.098	35.7048
878.35	36.6514
878.602	41.01
878.854	34.3031
879.106	33.9346
879.358	37.6903
879.61	35.1409
879.862	35.2586
880.114	29.2901
880.366	38.6223
880.618	32.5079
880.87	38.2612
881.121	37.2605
881.373	36.759
881.625	30.147
881.877	36.3824
882.129	33.4969
882.38	35.497
882.632	36.5664
882.884	35.4066
883.136	33.2853
883.387	35.644
883.639	34.1278
883.891	32.0717
884.142	39.0643
884.394	34.1436
884.646	36.203
884.897	31.9855
885.149	32.2434
885.4	32.6509
885.652	36.2992
885.903	32.0988
886.155	36.5141
886.406	33.2753
886.658	35.7599
886.909	35.7451
887.161	32.529
887.412	31.8685
887.664	36.7756
887.915	33.3084
888.138	29.1826
888.39	33.5558
888.642	34.2437
888.894	32.7483
889.146	36.9193
889.398	33.3731
889.65	38.6115
889.902	36.427
890.154	34.8943
890.406	34.1405
890.657	35.356
890.909	37.8219
891.161	28.0131
891.413	30.1439
891.665	29.0688
891.916	34.1118
892.168	32.3611
892.42	37.6434
892.671	29.1871
892.923	31.0244
893.175	32.4531
893.426	32.9107
893.678	31.9707
893.93	30.3533
894.181	28.6093
894.433	32.9887
894.684	33.6328
894.936	31.5964
895.188	31.562
895.439	32.4224
895.69	35.0867
895.942	33.0957
896.193	31.1635
896.445	36.5341
896.696	33.3856
896.948	30.0742
897.199	31.0326
897.451	36.6546
897.702	28.074
897.953	30.5241
898.204	31.9513
898.456	37.9555
898.707	26.2179
898.958	28.6053
899.21	34.8217
899.461	36.3519
899.712	30.0107
899.963	32.6667