File: M9_140224_01.txt
#Acq. time (s)=	2
#Accumulations=	3
#Range (nm)=	520...900
#Windows=	24
#Auto scanning=	On
#Autofocus=	Off
#AutoExposure=	Off
#Spike filter=	Multiple accum.
#Delay time (s)=	0
#Binning=	1
#Readout mode=	Signal
#DeNoise=	Off
#ICS correction=	Off
#Dark correction=	Off
#Inst. Process=	Off
#Detector temperature (°C)=	-59.98
#Instrument=	LabRAM HR Evol
#Detector=	Syncerity OE
#Objective=	x50_VIS
#Grating=	600 (500nm)
#ND Filter=	25%
#Laser=	514nm_Edge
#Hole=	199.981
#Range=	Auto
#StageXY=	Marzhauser
#StageZ=	Marzhauser
#X (µm)=	4822.7
#Y (µm)=	8167.9
#Z (µm)=	-1002.4
#Full time(mm:ss)=	3:03
#Project=
#Sample=
#Site=
#Title=	M9_140224
#Remark=
#Date=	19.02.2024 15:03
#Acquired=	19.02.2024 15:03:07
520.013	33.1157
520.274	34.4261
520.536	33.2479
520.797	37.4437
521.059	36.5236
521.32	37.5307
521.582	30.6434
521.843	36.8423
522.105	34.1555
522.366	34.6106
522.628	33.9802
522.889	37.916
523.15	36.1894
523.412	34.6985
523.673	33.5981
523.935	35.5773
524.196	34.8836
524.457	33.5367
524.719	35.6989
524.98	35.6255
525.241	35.7144
525.503	32.2075
525.764	36.1224
526.025	35.6893
526.286	34.3694
526.548	36.8533
526.809	36.014
527.07	33.8562
527.331	34.1295
527.593	35.0548
527.854	33.0629
528.115	32.4046
528.376	33.0482
528.637	36.7697
528.898	36.8392
529.16	38.6822
529.421	32.4063
529.682	31.7957
529.943	33.4617
530.204	32.6034
530.465	36.6
530.726	31.5249
530.987	33.1445
531.248	33.9618
531.509	33.9382
531.77	34.7827
532.031	34.1934
532.292	33.7241
532.553	37.8621
532.814	33.7578
533.075	36.7173
533.336	34.9158
533.597	37.0009
533.858	41.3094
534.119	47.3066
534.38	48.3828
534.641	55.682
534.901	58.3451
535.162	68.3571
535.423	52.0855
535.684	47.5088
535.945	50.7598
536.205	46.9639
536.466	45.2043
536.727	35.7616
536.988	37.2842
537.248	37.4341
537.509	41.2838
537.77	39.1587
537.987	48.6766
538.249	38.4856
538.51	37.8055
538.771	44.0709
539.032	39.514
539.293	41.8205
539.554	44.3723
539.815	37.7366
540.076	38.0289
540.337	39.841
540.598	44.4445
540.859	40.6132
541.12	46.3031
541.381	38.8742
541.642	39.5877
541.903	42.8302
542.164	42.3002
542.425	38.3753
542.686	42.2502
542.947	43.2939
543.208	36.3665
543.469	42.7101
543.73	44.9811
543.991	47.9522
544.252	43.9948
544.513	45.6518
544.773	41.7348
545.034	46.6474
545.295	45.9444
545.556	44.1622
545.817	44.6566
546.077	46.4964
546.338	45.6941
546.599	48.7779
546.86	49.6997
547.12	46.1717
547.381	49.6943
547.642	46.4745
547.903	47.8903
548.163	47.4394
548.424	50.4014
548.685	52.1439
548.945	53.2708
549.206	47.6753
549.467	55.9027
549.727	50.6776
549.988	55.8469
550.248	57.371
550.509	67.488
550.769	75.3528
551.03	73.2187
551.291	86.1338
551.551	96.4779
551.812	128.388
552.072	200.277
552.332	506.584
552.593	11465.1
552.853	4581.74
553.114	316.122
553.374	154.902
553.635	110.036
553.895	88.4063
554.155	75.9387
554.416	72.6559
554.676	71.1437
554.937	65.0946
555.197	59.1203
555.457	58.4451
555.686	63.9216
555.947	59.9456
556.207	53.0269
556.468	55.3961
556.729	64.7695
556.99	61.5627
557.25	59.3868
557.511	69.0598
557.772	65.2634
558.032	61.1844
558.293	62.3635
558.554	61.6488
558.814	61.5102
559.075	64.297
559.336	66.2467
559.596	69.7193
559.857	68.7604
560.117	66.6836
560.378	71.0729
560.638	76.5913
560.899	76.0045
561.159	61.5926
561.42	74.9589
561.68	73.5397
561.941	71.497
562.201	68.2002
562.462	72.9166
562.722	72.402
562.983	73.3371
563.243	74.4246
563.504	86.4307
563.764	81.7578
564.024	76.934
564.285	81.543
564.545	82.2828
564.805	80.3145
565.066	78.2413
565.326	82.5134
565.586	86.5099
565.847	83.3464
566.107	85.0992
566.367	86.0935
566.627	89.1591
566.888	81.7461
567.148	87.0602
567.408	90.4379
567.668	95.3068
567.928	88.7322
568.189	93.0782
568.449	92.4379
568.709	93.1844
568.969	96.7564
569.229	98.6184
569.489	99.535
569.749	96.5168
570.009	100.488
570.269	104.765
570.53	106.938
570.79	111.257
571.05	101.909
571.31	113.34
571.57	121.965
571.83	122.549
572.09	128.332
572.349	137.674
572.609	143.241
572.869	141.93
573.129	153.696
573.368	162.15
573.629	170.045
573.889	176.446
574.15	198.345
574.41	205.047
574.67	214.264
574.931	228.029
575.191	230.825
575.451	247.252
575.711	251.356
575.972	248.744
576.232	229.202
576.492	236.742
576.752	218.227
577.013	214.703
577.273	205.293
577.533	198.881
577.793	184.356
578.053	186.345
578.313	186.994
578.574	188.311
578.834	181.643
579.094	181.078
579.354	183.59
579.614	185.33
579.874	192.666
580.134	192.034
580.394	182.832
580.654	189.412
580.914	189.032
581.174	191.466
581.434	196.919
581.694	199.676
581.954	206.436
582.214	213.809
582.474	215.746
582.734	217.307
582.994	222.99
583.254	226.822
583.514	228.438
583.773	236.926
584.033	242.154
584.293	245.606
584.553	256.999
584.813	258.439
585.073	260.642
585.332	273.965
585.592	269.828
585.852	273.914
586.112	279.659
586.371	276.678
586.631	278.797
586.891	285.53
587.151	295.022
587.41	293.168
587.67	301.973
587.93	308.128
588.189	311.469
588.449	321.769
588.709	325.617
588.968	329.802
589.228	345.659
589.487	359.138
589.747	349.001
590.006	350.105
590.266	337.598
590.525	338.656
590.785	335.323
591.036	332.002
591.296	319.199
591.556	303.076
591.816	290.573
592.076	293.338
592.336	284.281
592.596	284.91
592.856	290.429
593.116	286.66
593.376	274.449
593.635	280.991
593.895	285.685
594.155	292.358
594.415	282.555
594.675	296.099
594.935	288.466
595.194	291.281
595.454	296.96
595.714	310.956
595.974	322.096
596.233	328.498
596.493	322.934
596.753	347.225
597.012	318.023
597.272	298.095
597.532	291.638
597.791	298.111
598.051	293.6
598.311	284.042
598.57	294.74
598.83	285.936
599.089	280.037
599.349	286.023
599.609	279.481
599.868	273.514
600.128	276.699
600.387	275.606
600.647	280.469
600.906	270.633
601.166	281.973
601.425	289.143
601.685	280.431
601.944	289.192
602.203	279.363
602.463	286.676
602.722	283.407
602.982	282.182
603.241	289.577
603.5	289.577
603.76	293.764
604.019	301.919
604.278	300.828
604.538	293.884
604.797	298.097
605.056	297.546
605.315	309.306
605.575	298.915
605.834	301.154
606.093	297.858
606.352	291.2
606.611	309.451
606.871	307.635
607.13	295.06
607.389	294.348
607.648	303.471
607.907	305.69
608.166	298.459
608.425	315.146
608.664	307.732
608.924	319.289
609.183	311.89
609.443	305.305
609.702	326.907
609.962	309.08
610.221	325.608
610.481	327.077
610.74	312.733
611	308.006
611.259	320.852
611.518	325.312
611.778	321.716
612.037	323.051
612.297	334.029
612.556	327.475
612.815	339.029
613.075	340.365
613.334	335.446
613.594	337.515
613.853	342.749
614.112	340.958
614.371	343.475
614.631	338.974
614.89	339.844
615.149	353.838
615.408	362.441
615.668	352.662
615.927	368.853
616.186	352.21
616.445	352.019
616.704	372.319
616.964	370.01
617.223	360.453
617.482	376.823
617.741	377.245
618	365.699
618.259	384.524
618.518	384.414
618.777	385.375
619.036	398.697
619.295	402.294
619.554	386.15
619.813	397.165
620.072	408.657
620.331	408.041
620.59	401.137
620.849	400.638
621.108	403.982
621.367	391.986
621.626	394.273
621.885	400.261
622.144	400.424
622.403	402.892
622.661	402.288
622.92	402.792
623.179	397.869
623.438	403.541
623.697	400.958
623.956	405.304
624.214	400.714
624.473	405.067
624.732	409.848
624.99	398.501
625.249	400.593
625.508	402.787
625.767	418.803
626.025	404.744
626.249	414.049
626.508	405.533
626.767	418.019
627.026	410.872
627.285	429.094
627.544	407.669
627.803	429.922
628.062	418.824
628.321	421.02
628.58	428.473
628.839	431.387
629.098	430.924
629.357	421.579
629.616	437.685
629.875	436.82
630.134	427.526
630.393	432.144
630.652	434.232
630.911	437.088
631.17	431.798
631.429	457.539
631.688	444.618
631.947	454.911
632.206	458.112
632.464	450.111
632.723	455.682
632.982	471.171
633.241	471.665
633.5	462.32
633.758	478.964
634.017	470.778
634.276	482.309
634.535	488.553
634.793	479.22
635.052	497.585
635.311	511.473
635.57	518.809
635.828	529.456
636.087	547.258
636.345	560.376
636.604	575.573
636.863	615.412
637.121	623.603
637.38	654.224
637.638	648.224
637.897	662.658
638.156	656.147
638.414	639.514
638.673	626.182
638.931	607.445
639.19	584.235
639.448	578.323
639.706	573.372
639.965	554.521
640.223	575.786
640.482	542.287
640.74	555.421
640.999	552.846
641.257	556.396
641.515	562.362
641.774	557.217
642.032	546.883
642.29	558.212
642.549	555.544
642.807	563.967
643.065	554.853
643.323	555.701
643.582	559.757
643.84	552.141
644.053	552.878
644.312	573.008
644.57	579.699
644.829	553.16
645.088	571.622
645.346	575.961
645.605	582.505
645.864	584.261
646.122	579.208
646.381	570.743
646.639	571.766
646.898	580.221
647.157	566.13
647.415	594.816
647.674	581.122
647.932	582.307
648.191	587.419
648.449	588.764
648.708	603.076
648.966	591.797
649.225	607.836
649.483	603.386
649.742	600.499
650	624.682
650.258	612.477
650.517	610.605
650.775	625.723
651.034	609.111
651.292	617.331
651.55	630.229
651.809	623.426
652.067	624.591
652.325	653.086
652.583	653.86
652.842	636.5
653.1	653.081
653.358	650.232
653.616	663.012
653.875	664.12
654.133	663.052
654.391	676.932
654.649	683.832
654.907	679.759
655.165	696.926
655.424	687.295
655.682	716.313
655.94	704.63
656.198	730.62
656.456	719.271
656.714	720.465
656.972	736.153
657.23	743.394
657.488	721.48
657.746	761.718
658.004	748.307
658.262	750.868
658.52	760.554
658.778	763.929
659.036	741.36
659.294	750.292
659.552	758.77
659.809	757.035
660.067	757.148
660.325	759.877
660.583	755.786
660.841	762.222
661.099	733.272
661.356	753.027
661.583	759.712
661.842	761.055
662.1	758.363
662.358	770.105
662.616	741.926
662.875	763.313
663.133	745.397
663.391	747.097
663.649	758.539
663.907	771.188
664.166	747.187
664.424	751.581
664.682	758.605
664.94	769.835
665.198	767.193
665.456	764.55
665.714	761.23
665.972	754.232
666.23	743.643
666.488	757.968
666.746	759.683
667.004	764.889
667.262	753.276
667.52	749.506
667.778	746.871
668.036	738.758
668.294	757.887
668.552	742.43
668.81	764.427
669.068	753.004
669.326	757.475
669.584	744.889
669.842	739.23
670.099	767.222
670.357	751.669
670.615	754.572
670.873	738.731
671.131	722.936
671.388	739.036
671.646	750.44
671.904	748.6
672.162	757.574
672.419	748.842
672.677	763.503
672.935	748.28
673.192	767.84
673.45	752.346
673.708	765.822
673.965	766.418
674.223	767.727
674.481	777.04
674.738	780.071
674.996	781.59
675.253	793.904
675.511	779.471
675.768	789.004
676.026	800.519
676.283	786.018
676.541	787.259
676.798	802.888
677.056	786.262
677.313	795.063
677.571	782.917
677.828	777.334
678.085	788.075
678.343	797.87
678.6	791.159
678.857	797.126
679.083	817.215
679.341	795.994
679.599	810.237
679.857	803.263
680.114	789.099
680.372	779.648
680.63	799.708
680.888	798.986
681.146	821.444
681.403	786.195
681.661	799.862
681.919	804.071
682.176	821.122
682.434	811.99
682.692	814.027
682.949	819.203
683.207	810.584
683.465	803.171
683.722	821.732
683.98	813.904
684.237	814.718
684.495	803.215
684.753	813.436
685.01	803.945
685.268	798.922
685.525	798.073
685.783	796.311
686.04	779.162
686.298	783.954
686.555	802.753
686.813	793.34
687.07	774.789
687.327	778.989
687.585	784.568
687.842	781.994
688.1	776.308
688.357	782.279
688.614	782.22
688.872	767.024
689.129	784.069
689.386	770.716
689.643	781.53
689.901	767.613
690.158	761.685
690.415	777.171
690.672	771.438
690.93	777.249
691.187	767.695
691.444	771.955
691.701	757.579
691.958	764.358
692.216	749.954
692.473	753.438
692.73	757.169
692.987	745.681
693.244	752.343
693.501	753.457
693.758	750.792
694.015	743.46
694.272	731.593
694.529	753.22
694.786	750.712
695.043	738.626
695.3	748.512
695.557	744.277
695.814	742.74
696.071	719.951
696.328	723.168
696.585	722.623
696.81	733.483
697.068	718.259
697.325	715.062
697.582	715.175
697.84	721.845
698.097	713.606
698.354	713.251
698.612	700.11
698.869	705.189
699.126	715.521
699.384	716.645
699.641	696.522
699.898	698.482
700.155	682.424
700.413	692.257
700.67	699.527
700.927	691.735
701.184	700.465
701.441	693.447
701.698	697.55
701.956	699.189
702.213	684.679
702.47	692.92
702.727	702.277
702.984	693.719
703.241	693.351
703.498	695.532
703.755	677.289
704.012	674.542
704.269	684.923
704.526	677.081
704.783	686.112
705.04	684.201
705.297	672.176
705.554	675.953
705.811	670.335
706.068	669.393
706.324	657.88
706.581	658.799
706.838	655.426
707.095	647.452
707.352	647.016
707.609	658.212
707.865	648.035
708.122	646.183
708.379	649.518
708.636	654.274
708.892	634.984
709.149	652.135
709.406	648.486
709.662	636.883
709.919	639.07
710.176	647.843
710.432	626.97
710.689	628.841
710.946	629.959
711.202	638.691
711.459	624.581
711.715	614.521
711.972	607.53
712.228	622.756
712.485	618.182
712.741	616.46
712.998	613.468
713.254	612.831
713.511	603.902
713.767	600.136
714.024	589.296
714.231	608.661
714.488	587.314
714.745	595.391
715.002	592.808
715.259	586.62
715.516	594.106
715.773	575.737
716.029	583.812
716.286	590.47
716.543	589.293
716.8	580.064
717.057	585.64
717.314	585.9
717.57	565.128
717.827	577.862
718.084	569.919
718.341	569.165
718.597	575.594
718.854	553.925
719.111	563.597
719.367	559.236
719.624	565.906
719.881	563.137
720.137	560.868
720.394	559.096
720.65	552.674
720.907	560.484
721.164	545.68
721.42	558.337
721.677	545.192
721.933	558.046
722.19	565.412
722.446	544.776
722.703	544.471
722.959	546
723.216	552.646
723.472	546.746
723.728	548.392
723.985	553.973
724.241	546.269
724.498	553.813
724.754	550.794
725.01	554.645
725.267	558.167
725.523	550.322
725.779	561.051
726.036	572.82
726.292	564.115
726.548	557.876
726.804	536.433
727.06	575.68
727.317	552.473
727.573	547.308
727.829	550.761
728.085	555.415
728.341	554.098
728.597	546.919
728.854	557.353
729.11	554.679
729.366	550.728
729.622	540.841
729.878	568.159
730.134	557.371
730.39	551.756
730.646	568.105
730.902	549.75
731.158	569.622
731.414	560.282
731.622	547.219
731.878	575.525
732.135	571.058
732.391	588.016
732.648	580.412
732.904	605.498
733.161	602.601
733.417	622.721
733.673	632.419
733.93	645.352
734.186	666.419
734.443	671.104
734.699	693.243
734.955	734.429
735.211	755.594
735.468	778.016
735.724	820.07
735.98	856.133
736.237	904.611
736.493	935.849
736.749	1014.64
737.005	1074.62
737.261	1111.86
737.518	1171.33
737.774	1234.93
738.03	1269.47
738.286	1280.85
738.542	1283.5
738.798	1232.3
739.054	1186.3
739.31	1146.37
739.566	1094.53
739.822	1029.12
740.078	971.213
740.334	918.579
740.59	868.714
740.846	822.411
741.102	787.516
741.358	765.597
741.614	732.161
741.87	689.836
742.126	680.499
742.382	659.48
742.638	643.503
742.893	625.959
743.149	599.1
743.405	583.388
743.661	574.849
743.917	572.023
744.172	550.674
744.428	556.25
744.684	530.822
744.94	533.879
745.195	518.16
745.451	511.583
745.707	509.039
745.962	507.418
746.218	481.626
746.474	497.352
746.729	482.307
746.985	477.826
747.241	470.2
747.496	473.295
747.752	473.915
748.007	474.18
748.263	453.093
748.518	452.994
748.774	472.763
749.029	469.362
749.275	458.517
749.531	455.039
749.787	448.034
750.043	456.018
750.299	440.088
750.555	435.066
750.811	439.226
751.067	438.374
751.323	433.266
751.579	415.563
751.835	426.415
752.09	429.551
752.346	417.128
752.602	417.668
752.858	412.73
753.114	424.899
753.37	419.626
753.625	405.953
753.881	414.677
754.137	408.127
754.393	414.914
754.648	412.581
754.904	398.945
755.16	398.601
755.415	391.224
755.671	386.193
755.927	397.86
756.182	384.926
756.438	384.439
756.693	389.194
756.949	385.068
757.205	384.191
757.46	379.156
757.716	383.011
757.971	378.969
758.227	374.068
758.482	377.218
758.738	377.395
758.993	370.871
759.248	375.445
759.504	366.037
759.759	371.179
760.015	361.314
760.27	360.27
760.525	364.25
760.781	352.877
761.036	352.66
761.291	364.928
761.547	347.217
761.802	345.981
762.057	346.845
762.313	348.337
762.568	346.805
762.823	348.778
763.078	347.909
763.333	333.13
763.589	336.256
763.844	335.96
764.099	334.792
764.354	330.118
764.609	331.822
764.864	327.949
765.119	347.666
765.374	327.701
765.629	343.147
765.884	336.46
766.139	331.954
766.394	324.56
766.649	315.404
766.882	327.738
767.137	323.777
767.393	326.885
767.648	311.42
767.904	304.955
768.159	302.985
768.415	301.191
768.67	301.176
768.926	299.458
769.181	290.506
769.436	298.332
769.692	296.318
769.947	283.252
770.203	289.325
770.458	282.61
770.713	274.606
770.968	278.68
771.224	283.986
771.479	268.698
771.734	272.188
771.99	269.775
772.245	269.034
772.5	270.752
772.755	260.645
773.01	267.359
773.265	260.968
773.521	256.912
773.776	256.271
774.031	255.046
774.286	262.884
774.541	254.643
774.796	243.095
775.051	240.532
775.306	236.322
775.561	246.478
775.816	241.912
776.071	237.393
776.326	228.258
776.581	237.489
776.836	233.257
777.091	232.574
777.346	235.566
777.601	228.584
777.856	222.62
778.111	222.744
778.365	216.293
778.62	216.596
778.875	221.193
779.13	213.842
779.385	211.199
779.639	213.593
779.894	218.928
780.149	204.058
780.404	213.534
780.658	207.185
780.913	206.254
781.168	202.312
781.422	199.963
781.677	203.533
781.932	204.594
782.186	197.523
782.441	191.721
782.695	200.584
782.95	195.704
783.204	192.982
783.459	198.574
783.714	187.756
783.968	192.324
784.211	194.806
784.466	197.895
784.721	173.907
784.976	186.291
785.231	175.576
785.486	191.716
785.741	176.199
785.996	182.362
786.251	178.549
786.506	176.879
786.761	182.446
787.016	178.1
787.271	175.102
787.526	165.401
787.78	169.317
788.035	161.933
788.29	172.067
788.545	170.69
788.8	172.825
789.054	159.439
789.309	166.002
789.564	160.324
789.819	166.34
790.073	163.139
790.328	166.564
790.583	150.871
790.837	159.926
791.092	160.526
791.347	157.717
791.601	152.505
791.856	158.913
792.11	148.278
792.365	151.908
792.619	156.734
792.874	157.176
793.128	149.792
793.383	156.334
793.638	149.331
793.892	144.791
794.146	149.944
794.401	146.724
794.655	146.554
794.91	141.902
795.164	146.673
795.418	148.898
795.673	148.776
795.927	142.596
796.181	143.291
796.436	136.54
796.69	144.214
796.944	141.371
797.199	145.104
797.453	141.01
797.707	143.945
797.961	136.13
798.216	138.958
798.47	135.44
798.724	140.676
798.978	129.833
799.232	135.42
799.486	132.383
799.74	130.259
799.994	136.23
800.248	129.496
800.503	128.708
800.757	127.195
801.011	132.504
801.265	117.803
801.508	119.754
801.762	122.732
802.017	122.857
802.271	121.553
802.526	117.238
802.78	116.471
803.035	120.846
803.289	112.218
803.544	113.743
803.798	119.534
804.052	110.349
804.307	118.099
804.561	110.216
804.816	117.381
805.07	114.364
805.324	112.193
805.579	114.626
805.833	116.111
806.087	113.144
806.341	111.698
806.596	113.036
806.85	107.591
807.104	110.753
807.358	106.583
807.613	110.486
807.867	102.965
808.121	103.37
808.375	111.959
808.629	102.294
808.883	103.072
809.138	103.524
809.392	102.348
809.646	98.99
809.9	103.68
810.154	98.9052
810.408	107.56
810.662	105.21
810.916	100.33
811.17	104.298
811.424	101.315
811.678	96.3174
811.932	93.2327
812.185	98.1874
812.439	100.545
812.693	100.62
812.947	99.5781
813.201	100.682
813.455	95.7354
813.709	95.277
813.962	95.1848
814.216	93.584
814.47	93.9967
814.724	96.4336
814.977	94.1427
815.231	92.3608
815.485	95.7851
815.739	95.826
815.992	93.1466
816.246	93.945
816.499	91.9538
816.753	88.3851
817.007	89.5358
817.26	88.8602
817.514	83.1886
817.767	85.6515
818.021	87.3213
818.274	83.3584
818.528	86.9805
818.781	88.6929
819.01	83.7306
819.264	79.1541
819.518	84.6748
819.772	79.9702
820.026	84.2248
820.28	81.6405
820.534	81.8971
820.788	76.7808
821.042	74.5091
821.296	74.6765
821.549	75.5383
821.803	75.1085
822.057	78.6364
822.311	75.328
822.565	79.3855
822.819	79.5405
823.073	76.5716
823.326	78.4478
823.58	74.9992
823.834	76.0943
824.088	73.6783
824.341	75.3033
824.595	74.0864
824.849	75.0646
825.103	73.8713
825.356	68.4529
825.61	74.6678
825.864	73.4372
826.117	68.451
826.371	74.0178
826.624	71.3068
826.878	73.397
827.131	70.6818
827.385	75.1179
827.638	70.3943
827.892	68.6172
828.146	66.1925
828.399	73.4271
828.652	73.5924
828.906	65.0684
829.159	63.373
829.413	67.0359
829.666	72.4121
829.919	66.9234
830.173	69.6208
830.426	59.8269
830.68	73.2478
830.933	67.2723
831.186	65.0499
831.439	61.5589
831.693	65.7467
831.946	64.8894
832.199	63.0639
832.452	71.1202
832.706	66.0766
832.959	64.6917
833.212	58.3147
833.465	60.3019
833.718	55.7759
833.971	67.1194
834.224	64.6252
834.477	64.6254
834.73	62.7135
834.984	62.8669
835.237	60.7317
835.49	64.819
835.743	64.7103
835.996	66.7234
836.201	56.0679
836.454	60.923
836.708	59.1922
836.961	64.8998
837.215	57.7895
837.468	59.3452
837.722	56.6002
837.975	61.0412
838.229	56.6446
838.482	56.4661
838.735	55.8595
838.989	59.9477
839.242	55.264
839.496	57.3814
839.749	58.2328
840.002	56.2275
840.256	61.044
840.509	57.2513
840.762	64.1425
841.015	57.5168
841.269	59.3316
841.522	59.0402
841.775	55.5539
842.028	52.219
842.281	57.0151
842.535	55.6657
842.788	60.5103
843.041	53.4886
843.294	54.8996
843.547	55.265
843.8	51.9593
844.053	52.6007
844.306	54.8632
844.559	60.4883
844.812	56.3778
845.065	57.1768
845.318	48.5248
845.571	58.4924
845.824	54.3647
846.077	53.9808
846.33	57.5471
846.583	53.4059
846.836	49.7739
847.089	52.2598
847.342	56.5972
847.595	53.4399
847.847	55.8145
848.1	53.2856
848.353	52.6266
848.606	56.1806
848.859	52.8799
849.111	51.0898
849.364	57.3788
849.617	50.0224
849.869	53.4272
850.122	51.8856
850.375	53.3366
850.627	47.4063
850.88	48.8372
851.133	53.5719
851.385	48.6206
851.638	50.5788
851.89	49.0491
852.143	49.9226
852.395	46.91
852.648	46.3948
852.9	51.4008
853.153	48.6914
853.405	51.0597
853.645	45.2807
853.898	49.3811
854.151	53.2079
854.404	52.3742
854.657	48.9677
854.91	47.7557
855.163	50.2442
855.416	45.2118
855.669	44.6149
855.922	52.7514
856.175	47.2839
856.427	44.9069
856.68	49.7417
856.933	47.2767
857.186	51.8085
857.439	49.246
857.692	47.6809
857.944	53.5101
858.197	49.6851
858.45	49.5799
858.703	47.271
858.955	49.7554
859.208	43.1226
859.461	48.8639
859.713	44.511
859.966	43.989
860.219	46.4553
860.471	47.9258
860.724	45.1442
860.976	48.4482
861.229	45.1122
861.481	43.846
861.734	41.8462
861.986	47.5676
862.239	46.1091
862.491	52.5003
862.744	48.3231
862.996	47.9486
863.249	43.0167
863.501	47.9935
863.754	43.3614
864.006	41.8017
864.258	44.5445
864.511	38.8606
864.763	46.2231
865.015	44.8163
865.268	44.6728
865.52	43.827
865.772	41.1781
866.024	37.4967
866.276	45.3837
866.529	42.1338
866.781	43.7621
867.033	44.5306
867.285	44.267
867.537	44.6345
867.789	41.7639
868.042	43.4695
868.294	43.1808
868.546	40.5823
868.798	40.9883
869.05	43.7371
869.302	41.8169
869.554	41.2608
869.806	46.7693
870.058	44.4061
870.31	40.34
870.562	41.6218
870.782	40.6504
871.034	40.0426
871.287	43.6262
871.539	43.1882
871.792	42.1235
872.044	40.5031
872.297	37.9556
872.549	39.1797
872.801	41.25
873.054	47.4385
873.306	41.8188
873.558	42.2887
873.811	41.9488
874.063	43.2386
874.315	38.1717
874.568	45.8518
874.82	38.5169
875.072	41.6305
875.324	37.2559
875.577	39.782
875.829	42.2708
876.081	36.2313
876.333	35.0735
876.585	38.0722
876.838	41.0438
877.09	38.8874
877.342	38.8679
877.594	40.7196
877.846	41.0952
878.098	38.1477
878.35	39.5134
878.602	43.9497
878.854	42.066
879.106	39.9146
879.358	41.527
879.61	36.7649
879.862	41.3578
880.114	35.3851
880.366	42.4426
880.618	41.6121
880.87	34.5457
881.121	33.9945
881.373	41.0208
881.625	41.2441
881.877	35.9304
882.129	36.5056
882.38	41.3205
882.632	39.4853
882.884	33.8624
883.136	41.621
883.387	39.0405
883.639	36.3744
883.891	35.6833
884.142	37.1119
884.394	40.4668
884.646	38.2253
884.897	39.9743
885.149	41.2258
885.4	40.2141
885.652	36.9963
885.903	34.0723
886.155	43.0369
886.406	39.055
886.658	36.0014
886.909	36.7393
887.161	34.8476
887.412	34.3362
887.664	36.854
887.915	38.2525
888.138	37.3323
888.39	38.482
888.642	32.9597
888.894	37.0731
889.146	33.0574
889.398	35.2805
889.65	31.7491
889.902	35.7181
890.154	39.174
890.406	33.9589
890.657	32.5091
890.909	37.2999
891.161	32.5986
891.413	35.5009
891.665	38.6358
891.916	35.6962
892.168	33.5386
892.42	35.0792
892.671	36.3461
892.923	34.7026
893.175	32.5559
893.426	34.6856
893.678	35.3234
893.93	36.0033
894.181	37.8279
894.433	33.1694
894.684	32.4905
894.936	31.2067
895.188	33.3242
895.439	36.2316
895.69	31.9199
895.942	33.0573
896.193	33.0115
896.445	30.9487
896.696	36.7769
896.948	31.769
897.199	34.4976
897.451	36.4784
897.702	33.5367
897.953	32.9358
898.204	34.1713
898.456	38.9833
898.707	31.3489
898.958	37.0307
899.21	33.5512
899.461	29.7092
899.712	29.6841
899.963	32