File: MS_091025_04.txt
#Acq. time (s)=	5
#Accumulations=	2
#Range (nm)=	520...900
#Windows=	8
#Auto scanning=	Off
#Autofocus=	Off
#AutoExposure=	Off
#Spike filter=	Multiple accum.
#Delay time (s)=	0
#Binning=	1
#Readout mode=	Signal
#DeNoise=	Off
#ICS correction=	Off
#Dark correction=	Off
#Inst. Process=	Off
#Detector temperature (°C)=	-59.98
#Instrument=	LabRAM HR Evol
#Detector=	Syncerity OE
#Objective=	x50_VIS
#Grating=	600 (500nm)
#ND Filter=	10%
#Laser=	514nm_Edge
#Hole=	199.981
#Range=	Auto
#StageXY=	Marzhauser
#StageZ=	Marzhauser
#X (µm)=	-10802.4
#Y (µm)=	12273.3
#Z (µm)=	-163.4
#Full time(mm:ss)=	2:04
#Project=
#Sample=
#Site=
#Title=	MS_091025
#Remark=
#Date=	13.10.2023 16:39
#Acquired=	13.10.2023 16:39:12
520.044	28
520.306	30
520.569	42
520.831	32
521.093	36
521.355	36
521.617	42
521.88	28
522.142	32
522.404	44
522.666	34
522.928	40
523.19	34
523.453	32
523.715	30
523.977	36
524.239	46
524.501	36
524.763	34
525.025	42
525.287	46
525.549	38
525.811	40
526.073	38
526.335	46
526.597	38
526.859	32
527.121	48
527.383	36
527.645	42
527.907	46
528.169	42
528.431	36
528.693	40
528.955	42
529.217	36
529.479	40
529.741	48
530.003	44
530.264	36
530.526	38
530.788	46
531.05	50
531.312	40
531.574	48
531.835	44
532.097	48
532.359	38
532.621	50
532.883	40
533.144	50
533.406	48
533.668	56
533.93	42
534.191	42
534.453	46
534.715	42
534.976	50
535.238	52
535.5	60
535.761	52
536.023	52
536.285	52
536.546	50
536.808	48
537.069	52
537.331	62
537.593	50
537.854	48
538.116	50
538.377	50
538.639	52
538.9	54
539.162	64
539.423	54
539.685	52
539.946	56
540.208	54
540.469	56
540.731	54
540.992	62
541.254	68
541.515	62
541.776	68
542.038	70
542.299	66
542.56	64
542.822	70
543.083	72
543.344	64
543.606	72
543.867	72
544.128	72
544.39	78
544.651	82
544.912	78
545.174	74
545.435	76
545.696	68
545.957	84
546.218	76
546.48	88
546.741	92
547.002	88
547.263	108
547.524	94
547.785	94
548.047	78
548.308	92
548.569	118
548.83	96
549.091	94
549.352	106
549.613	104
549.874	110
550.135	108
550.396	126
550.657	114
550.918	130
551.179	142
551.44	138
551.701	160
551.962	234
552.223	584
552.484	14428
552.745	718
553.006	242
553.267	190
553.528	172
553.788	160
554.049	158
554.31	158
554.571	144
554.832	160
555.093	170
555.353	166
555.614	166
555.875	174
556.136	162
556.396	166
556.657	194
556.918	168
557.179	186
557.439	186
557.7	204
557.961	192
558.221	196
558.482	204
558.743	214
559.003	184
559.264	202
559.525	196
559.785	226
560.046	212
560.306	222
560.567	228
560.827	226
561.088	238
561.348	244
561.609	262
561.869	254
562.13	268
562.39	258
562.651	286
562.911	266
563.172	290
563.432	290
563.692	284
563.953	296
564.213	298
564.474	312
564.734	298
564.994	342
565.255	330
565.515	324
565.775	352
566.035	346
566.296	342
566.556	364
566.816	352
567.076	364
567.337	370
567.597	384
567.857	384
568.117	390.09
568.377	376.758
568.637	408.522
568.898	422.784
569.158	419.208
569.418	429.479
569.678	439.348
569.938	447.639
570.198	465.675
570.458	478.13
570.718	508.693
570.978	520.261
571.238	538.723
571.498	560.619
571.758	585.514
572.018	627.084
572.278	649.686
572.538	697.148
572.798	730.761
573.058	770.045
573.312	834
573.573	866
573.834	960
574.095	1040
574.356	1084
574.617	1176
574.878	1242
575.139	1334
575.4	1362
575.661	1404
575.922	1464
576.183	1418
576.444	1396
576.705	1358
576.965	1328
577.226	1226
577.487	1210
577.748	1148
578.009	1136
578.27	1054
578.531	1036
578.791	1008
579.052	1002
579.313	962
579.574	980
579.835	966
580.095	942
580.356	968
580.617	952
580.878	970
581.138	988
581.399	988
581.66	982
581.92	970
582.181	1020
582.442	990
582.703	1040
582.963	1032
583.224	1010
583.484	1096
583.745	1060
584.006	1120
584.266	1108
584.527	1152
584.787	1132
585.048	1178
585.308	1168
585.569	1232
585.83	1228
586.09	1252
586.351	1236
586.611	1274
586.872	1284
587.132	1296
587.392	1308
587.653	1342
587.913	1320
588.174	1366
588.434	1368
588.695	1350
588.955	1370
589.215	1350
589.476	1348
589.736	1404
589.996	1370
590.257	1382
590.517	1396
590.777	1392
591.038	1388
591.298	1382
591.558	1324
591.818	1372
592.079	1326
592.339	1378
592.599	1344
592.859	1362
593.12	1356
593.38	1386
593.64	1378
593.9	1378
594.16	1368
594.42	1416
594.68	1408
594.941	1406
595.201	1430
595.461	1432
595.721	1448
595.981	1490
596.241	1512
596.501	1548
596.761	1514
597.021	1540
597.281	1530
597.541	1538
597.801	1550
598.061	1584
598.321	1554
598.581	1612
598.841	1590
599.101	1554
599.361	1576
599.62	1610
599.88	1608
600.14	1572
600.4	1576
600.66	1586
600.92	1586
601.18	1602
601.439	1578
601.699	1628
601.959	1606
602.219	1590
602.478	1646
602.738	1612
602.998	1610
603.258	1658
603.517	1610
603.777	1638
604.037	1614
604.296	1674
604.556	1678
604.816	1680
605.075	1710
605.335	1704
605.594	1674
605.854	1652
606.114	1642
606.373	1700
606.633	1694
606.892	1688
607.152	1712
607.411	1696
607.671	1662
607.93	1726
608.19	1708
608.449	1720
608.709	1730
608.968	1704
609.228	1736
609.487	1764
609.746	1778
610.006	1844
610.265	1836
610.524	1822
610.784	1796
611.043	1882
611.302	1836
611.562	1860
611.821	1818
612.08	1890
612.339	1872
612.599	1908
612.858	1914
613.117	1918
613.376	1930
613.635	1960
613.895	1924
614.154	1940
614.413	1998
614.672	2058
614.931	2020
615.19	2022
615.449	2042
615.709	2108
615.968	2086
616.227	2075.44
616.486	2096.68
616.745	2138.33
617.004	2091.4
617.263	2131.99
617.522	2137.51
617.781	2180.43
618.04	2157.5
618.299	2187.75
618.557	2204.12
618.816	2189.68
619.075	2232.97
619.334	2237.46
619.593	2259.54
619.852	2246.65
620.111	2260.97
620.37	2297.57
620.628	2268.68
620.887	2257.09
621.146	2283.1
621.373	2320
621.633	2328
621.893	2330
622.153	2354
622.413	2294
622.673	2328
622.932	2342
623.192	2316
623.452	2386
623.712	2386
623.972	2384
624.232	2418
624.492	2408
624.751	2426
625.011	2428
625.271	2410
625.531	2458
625.791	2494
626.05	2468
626.31	2466
626.57	2470
626.83	2474
627.089	2464
627.349	2498
627.609	2564
627.868	2556
628.128	2566
628.388	2508
628.647	2604
628.907	2620
629.167	2596
629.426	2546
629.686	2634
629.945	2658
630.205	2638
630.465	2714
630.724	2690
630.984	2764
631.243	2736
631.503	2730
631.762	2818
632.022	2786
632.281	2830
632.541	2872
632.8	2886
633.06	2884
633.319	2924
633.579	2970
633.838	2974
634.097	2898
634.357	2998
634.616	3046
634.876	3038
635.135	3056
635.394	3176
635.654	3232
635.913	3266
636.172	3408
636.431	3470
636.691	3526
636.95	3632
637.209	3794
637.469	3884
637.728	4060
637.987	4210
638.246	4230
638.505	4272
638.765	4296
639.024	4256
639.283	4218
639.542	4154
639.801	4184
640.06	4008
640.319	3944
640.578	3850
640.838	3864
641.097	3798
641.356	3728
641.615	3728
641.874	3720
642.133	3702
642.392	3750
642.651	3724
642.91	3738
643.169	3746
643.428	3732
643.687	3714
643.946	3784
644.205	3730
644.463	3748
644.722	3754
644.981	3844
645.24	3848
645.499	3816
645.758	3804
646.017	3810
646.275	3800
646.534	3878
646.793	3802
647.052	3836
647.31	3900
647.569	3948
647.828	3958
648.087	3964
648.345	4022
648.604	4026
648.863	4020
649.121	4072
649.38	4046
649.639	4048
649.897	4140
650.156	4184
650.415	4132
650.673	4150
650.932	4194
651.19	4260
651.449	4178
651.707	4256
651.966	4336
652.224	4310
652.483	4328
652.741	4392
653	4440
653.258	4460
653.517	4500
653.775	4462
654.034	4496
654.292	4604
654.55	4660
654.809	4668
655.067	4722
655.326	4694
655.584	4814
655.842	4794
656.1	4918
656.359	4966
656.617	4990
656.875	5020
657.134	5056
657.392	5156
657.65	5126
657.908	5224
658.166	5222
658.425	5264
658.683	5274
658.941	5282
659.199	5312
659.457	5296
659.715	5368
659.973	5390
660.231	5360
660.49	5388
660.748	5406
661.006	5410
661.264	5352
661.522	5398
661.78	5412
662.038	5352
662.296	5270
662.554	5408
662.811	5384
663.069	5432
663.327	5484
663.585	5440
663.843	5454.04
664.101	5497.91
664.359	5493.89
664.617	5459.59
664.874	5430.1
665.132	5442.01
665.39	5482.04
665.648	5439.46
665.906	5472.51
666.163	5413.34
666.421	5454.8
666.679	5401.54
666.937	5407.57
667.194	5404.14
667.452	5452.86
667.71	5437.76
667.967	5446.74
668.225	5398.99
668.482	5436.72
668.74	5370.68
668.987	5436
669.245	5400
669.504	5412
669.763	5450
670.022	5416
670.281	5440
670.539	5422
670.798	5392
671.057	5430
671.316	5408
671.575	5402
671.833	5430
672.092	5394
672.351	5452
672.609	5378
672.868	5384
673.127	5470
673.385	5480
673.644	5550
673.903	5490
674.161	5530
674.42	5618
674.678	5602
674.937	5650
675.195	5604
675.454	5656
675.713	5662
675.971	5682
676.23	5666
676.488	5774
676.747	5800
677.005	5674
677.263	5700
677.522	5740
677.78	5766
678.039	5690
678.297	5752
678.556	5718
678.814	5716
679.072	5706
679.331	5724
679.589	5750
679.847	5738
680.106	5738
680.364	5760
680.622	5754
680.881	5774
681.139	5802
681.397	5822
681.656	5814
681.914	5920
682.172	5822
682.43	5952
682.688	5900
682.947	5820
683.205	5894
683.463	5898
683.721	5936
683.979	5850
684.237	5892
684.495	5898
684.754	5810
685.012	5744
685.27	5764
685.528	5798
685.786	5796
686.044	5742
686.302	5754
686.56	5804
686.818	5822
687.076	5760
687.334	5734
687.592	5808
687.85	5742
688.108	5682
688.366	5750
688.623	5682
688.881	5734
689.139	5682
689.397	5660
689.655	5696
689.913	5732
690.171	5646
690.428	5612
690.686	5688
690.944	5670
691.202	5654
691.459	5606
691.717	5646
691.975	5580
692.233	5562
692.49	5516
692.748	5476
693.006	5500
693.263	5522
693.521	5380
693.779	5426
694.036	5438
694.294	5434
694.552	5458
694.809	5410
695.067	5482
695.324	5342
695.582	5420
695.839	5330
696.097	5376
696.354	5372
696.612	5316
696.869	5222
697.127	5384
697.384	5342
697.642	5208
697.899	5196
698.156	5138
698.414	5158
698.671	5116
698.928	5108
699.186	5168
699.443	5054
699.7	5088
699.958	5088
700.215	5058
700.472	4994
700.73	5064
700.987	5018
701.244	5060
701.501	5018
701.758	5076
702.016	5102
702.273	5024
702.53	5052
702.787	5098
703.044	5014
703.301	5034
703.558	5026
703.816	5024
704.073	4988
704.33	4952
704.587	4934
704.844	4880
705.101	4908
705.358	4844
705.615	4964
705.872	4862
706.129	4830
706.386	4794
706.643	4736
706.899	4790
707.156	4686
707.413	4744
707.67	4644
707.927	4676
708.184	4662
708.441	4638
708.697	4672
708.954	4646
709.211	4598
709.468	4630
709.725	4574
709.981	4564
710.238	4528
710.495	4558
710.751	4544
711.008	4512
711.265	4534.37
711.521	4521.89
711.778	4473.27
712.035	4498.65
712.291	4481.88
712.548	4423.09
712.804	4392.11
713.061	4400.3
713.317	4339.66
713.574	4308.71
713.831	4323.25
714.087	4289.95
714.343	4282.07
714.6	4240.84
714.856	4236.73
715.113	4246.24
715.369	4201.21
715.626	4182.3
715.882	4136.5
716.138	4085.27
716.395	4090.37
716.639	4126
716.897	4050
717.155	4060
717.412	4052
717.67	3994
717.927	4012
718.185	3988
718.443	4014
718.7	3986
718.958	3944
719.215	3928
719.473	3934
719.73	3874
719.988	3944
720.245	3878
720.503	3838
720.76	3824
721.018	3798
721.275	3784
721.532	3764
721.79	3700
722.047	3706
722.305	3674
722.562	3656
722.819	3736
723.077	3638
723.334	3602
723.591	3588
723.849	3590
724.106	3580
724.363	3516
724.621	3532
724.878	3520
725.135	3488
725.392	3490
725.65	3474
725.907	3482
726.164	3404
726.421	3400
726.678	3360
726.935	3358
727.193	3322
727.45	3342
727.707	3324
727.964	3196
728.221	3244
728.478	3272
728.735	3234
728.992	3200
729.249	3146
729.506	3118
729.763	3156
730.02	3106
730.277	3082
730.534	3092
730.791	3060
731.048	3048
731.305	3028
731.562	2934
731.819	3026
732.076	3028
732.333	2980
732.589	2930
732.846	2956
733.103	3020
733.36	2954
733.617	2950
733.873	2920
734.13	2920
734.387	2972
734.644	2944
734.901	2910
735.157	2886
735.414	2900
735.671	2904
735.927	2900
736.184	2878
736.441	2918
736.697	2902
736.954	2920
737.211	2948
737.467	2912
737.724	2968
737.98	2914
738.237	2912
738.493	2914
738.75	2902
739.006	2932
739.263	2878
739.519	2834
739.776	2830
740.032	2792
740.289	2774
740.545	2748
740.802	2762
741.058	2716
741.314	2664
741.571	2656
741.827	2662
742.083	2598
742.34	2634
742.596	2564
742.852	2590
743.109	2580
743.365	2508
743.621	2556
743.878	2498
744.134	2514
744.39	2484
744.646	2446
744.902	2438
745.159	2364
745.415	2438
745.671	2434
745.927	2370
746.183	2432
746.439	2384
746.695	2304
746.951	2316
747.207	2294
747.463	2306
747.719	2332
747.975	2286
748.231	2334
748.487	2292
748.743	2272
748.999	2270
749.255	2282
749.511	2290
749.767	2226
750.023	2246
750.279	2208
750.535	2210
750.791	2174
751.046	2196
751.302	2170
751.558	2172
751.814	2140
752.07	2150
752.325	2104
752.581	2120
752.837	2072
753.092	2100
753.348	2014
753.604	2012
753.859	2028
754.115	1994
754.371	1984
754.626	2020
754.882	2042
755.138	2006
755.393	1990
755.649	1896
755.904	1936
756.16	1958
756.415	1954
756.671	1938
756.926	1900
757.182	1934
757.437	1868
757.693	1912
757.948	1836
758.203	1840
758.459	1804
758.714	1801.62
758.97	1846.99
759.225	1833.72
759.48	1831.88
759.736	1773.28
759.991	1769.78
760.246	1776.27
760.501	1774.34
760.757	1748.98
761.012	1758.86
761.267	1716.95
761.522	1726.88
761.777	1715.3
762.033	1719.61
762.288	1661.9
762.543	1667.87
762.798	1664.35
763.053	1663.99
763.308	1649.83
763.563	1614.86
763.78	1638
764.037	1618
764.293	1574
764.55	1594
764.806	1598
765.062	1546
765.319	1548
765.575	1554
765.831	1574
766.088	1570
766.344	1570
766.6	1544
766.857	1560
767.113	1496
767.369	1486
767.625	1450
767.882	1484
768.138	1454
768.394	1454
768.65	1452
768.906	1408
769.163	1366
769.419	1400
769.675	1400
769.931	1404
770.187	1376
770.443	1356
770.699	1336
770.955	1366
771.211	1322
771.467	1318
771.723	1316
771.979	1300
772.235	1298
772.491	1326
772.747	1286
773.003	1260
773.259	1264
773.515	1214
773.771	1246
774.027	1228
774.283	1210
774.539	1188
774.795	1186
775.05	1202
775.306	1214
775.562	1170
775.818	1148
776.074	1166
776.329	1146
776.585	1138
776.841	1136
777.097	1126
777.352	1124
777.608	1112
777.864	1118
778.12	1062
778.375	1064
778.631	1088
778.886	1046
779.142	1068
779.398	1078
779.653	1064
779.909	1068
780.164	1056
780.42	1072
780.675	1010
780.931	1024
781.187	994
781.442	996
781.698	946
781.953	990
782.208	988
782.464	990
782.719	960
782.975	942
783.23	934
783.485	960
783.741	912
783.996	932
784.252	920
784.507	930
784.762	884
785.017	892
785.273	890
785.528	852
785.783	894
786.038	824
786.294	844
786.549	842
786.804	840
787.059	822
787.314	830
787.57	852
787.825	818
788.08	822
788.335	786
788.59	816
788.845	780
789.1	798
789.355	790
789.61	772
789.865	792
790.12	746
790.375	766
790.63	752
790.885	768
791.14	750
791.395	744
791.65	716
791.905	744
792.16	734
792.414	718
792.669	744
792.924	672
793.179	706
793.434	688
793.689	708
793.943	694
794.198	668
794.453	688
794.708	652
794.962	664
795.217	662
795.472	634
795.726	650
795.981	594
796.236	650
796.49	620
796.745	610
796.999	610
797.254	618
797.508	618
797.763	594
798.018	598
798.272	570
798.526	578
798.781	572
799.035	604
799.29	580
799.544	580
799.799	596
800.053	582
800.307	538
800.562	584
800.816	568
801.07	526
801.325	526
801.579	532
801.833	546
802.088	522
802.342	546
802.596	530
802.85	550
803.105	530
803.359	500
803.613	520
803.867	486
804.121	506
804.375	500
804.63	476
804.884	490
805.138	476
805.392	484
805.646	480.084
805.9	454.383
806.154	486.097
806.408	461.766
806.662	466.925
806.916	468.858
807.17	450.002
807.424	450.683
807.678	441.277
807.931	455.385
808.185	441.097
808.439	435.099
808.693	429.059
808.947	439.149
809.201	427.198
809.454	422.198
809.708	421.3
809.962	441.005
810.216	417.952
810.469	404.173
810.678	380
810.933	414
811.188	428
811.443	412
811.699	412
811.954	406
812.209	408
812.464	382
812.719	408
812.974	382
813.229	378
813.484	382
813.739	390
813.994	372
814.249	394
814.504	344
814.759	358
815.014	358
815.268	368
815.523	368
815.778	356
816.033	354
816.288	354
816.543	358
816.798	364
817.052	332
817.307	358
817.562	338
817.817	344
818.071	340
818.326	344
818.581	338
818.836	336
819.09	336
819.345	330
819.6	300
819.854	322
820.109	324
820.364	310
820.618	330
820.873	326
821.127	304
821.382	312
821.637	294
821.891	308
822.146	296
822.4	278
822.655	276
822.909	298
823.164	292
823.418	284
823.672	292
823.927	282
824.181	286
824.436	274
824.69	278
824.944	292
825.199	270
825.453	260
825.707	286
825.962	270
826.216	266
826.47	264
826.725	246
826.979	248
827.233	270
827.487	268
827.741	246
827.996	266
828.25	260
828.504	266
828.758	250
829.012	260
829.266	246
829.52	262
829.774	254
830.029	254
830.283	236
830.537	224
830.791	246
831.045	248
831.299	238
831.553	248
831.807	254
832.061	230
832.315	220
832.568	226
832.822	232
833.076	228
833.33	228
833.584	228
833.838	228
834.092	214
834.345	222
834.599	232
834.853	220
835.107	216
835.36	228
835.614	208
835.868	214
836.122	228
836.375	208
836.629	222
836.883	216
837.136	214
837.39	224
837.643	202
837.897	216
838.151	208
838.404	204
838.658	178
838.911	192
839.165	196
839.418	184
839.672	194
839.925	186
840.179	194
840.432	182
840.686	178
840.939	190
841.192	172
841.446	194
841.699	182
841.952	194
842.206	168
842.459	180
842.712	178
842.966	184
843.219	174
843.472	186
843.725	174
843.979	186
844.232	178
844.485	198
844.738	176
844.991	168
845.244	176
845.497	178
845.75	164
846.004	174
846.257	166
846.51	166
846.763	164
847.016	168
847.269	164
847.522	156
847.775	168
848.028	152
848.281	154
848.534	152
848.786	168
849.039	154
849.292	156
849.545	164
849.798	160
850.051	144
850.303	158
850.556	152
850.809	156
851.062	138
851.314	148
851.567	146
851.82	150
852.073	134
852.325	137.991
852.578	146.11
852.831	137.391
853.083	143.517
853.336	143.146
853.588	139.887
853.841	135.135
854.093	140
854.346	133.17
854.598	127.934
854.851	133.718
855.103	132.22
855.356	141.833
855.608	132.69
855.861	134.752
856.113	132.145
856.366	129.311
856.618	129.45
856.87	123.45
857.123	118.48
857.352	134
857.606	138
857.859	136
858.113	112
858.367	132
858.621	128
858.875	120
859.128	118
859.382	136
859.636	122
859.889	104
860.143	120
860.397	118
860.65	134
860.904	120
861.158	120
861.411	130
861.665	118
861.918	112
862.172	122
862.425	116
862.679	118
862.932	118
863.186	112
863.439	124
863.693	122
863.946	118
864.2	116
864.453	104
864.707	118
864.96	106
865.213	112
865.467	116
865.72	108
865.973	108
866.227	108
866.48	110
866.733	110
866.987	106
867.24	108
867.493	112
867.746	110
867.999	102
868.253	100
868.506	106
868.759	104
869.012	104
869.265	108
869.518	102
869.771	96
870.025	102
870.278	106
870.531	100
870.784	104
871.037	104
871.29	106
871.543	92
871.796	110
872.049	96
872.302	92
872.555	90
872.808	94
873.06	86
873.313	92
873.566	80
873.819	98
874.072	94
874.325	94
874.578	88
874.83	96
875.083	74
875.336	82
875.589	94
875.841	90
876.094	90
876.347	78
876.6	94
876.852	82
877.105	84
877.358	94
877.61	84
877.863	76
878.115	96
878.368	92
878.621	82
878.873	104
879.126	92
879.378	86
879.631	88
879.883	94
880.136	84
880.388	86
880.641	84
880.893	84
881.145	80
881.398	74
881.65	88
881.902	82
882.155	88
882.407	82
882.659	76
882.912	84
883.164	68
883.416	82
883.669	82
883.921	80
884.173	88
884.425	82
884.677	76
884.93	84
885.182	78
885.434	80
885.686	80
885.938	68
886.19	82
886.442	78
886.694	66
886.946	82
887.198	78
887.45	76
887.702	62
887.954	76
888.206	68
888.458	68
888.71	70
888.962	72
889.214	66
889.466	68
889.718	76
889.969	84
890.221	78
890.473	62
890.725	74
890.977	68
891.228	78
891.48	58
891.732	66
891.983	58
892.235	68
892.487	68
892.738	76
892.99	52
893.242	78
893.493	74
893.745	64
893.996	66
894.248	74
894.5	60
894.751	54
895.003	60
895.254	64
895.505	56
895.757	62
896.008	70
896.26	64
896.511	64
896.763	68
897.014	66
897.265	68
897.517	52
897.768	66
898.019	56
898.27	52
898.522	56
898.773	62
899.024	58
899.275	44
899.527	62
899.778	58
899.979	64