File: MS_091025_05.txt
#Acq. time (s)=	5
#Accumulations=	2
#Range (nm)=	520...900
#Windows=	8
#Auto scanning=	Off
#Autofocus=	Off
#AutoExposure=	Off
#Spike filter=	Multiple accum.
#Delay time (s)=	0
#Binning=	1
#Readout mode=	Signal
#DeNoise=	Off
#ICS correction=	Off
#Dark correction=	Off
#Inst. Process=	Off
#Detector temperature (°C)=	-59.98
#Instrument=	LabRAM HR Evol
#Detector=	Syncerity OE
#Objective=	x50_VIS
#Grating=	600 (500nm)
#ND Filter=	10%
#Laser=	514nm_Edge
#Hole=	199.981
#Range=	Auto
#StageXY=	Marzhauser
#StageZ=	Marzhauser
#X (µm)=	15300.7
#Y (µm)=	11699
#Z (µm)=	-41
#Full time(mm:ss)=	2:05
#Project=
#Sample=
#Site=
#Title=	MS_091025
#Remark=
#Date=	13.10.2023 16:42
#Acquired=	13.10.2023 16:42:58
520.044	34
520.306	36
520.569	32
520.831	38
521.093	36
521.355	42
521.617	28
521.88	42
522.142	44
522.404	48
522.666	40
522.928	32
523.19	42
523.453	38
523.715	34
523.977	46
524.239	40
524.501	36
524.763	38
525.025	36
525.287	44
525.549	34
525.811	38
526.073	42
526.335	46
526.597	30
526.859	40
527.121	46
527.383	44
527.645	42
527.907	38
528.169	42
528.431	42
528.693	44
528.955	38
529.217	38
529.479	36
529.741	42
530.003	44
530.264	40
530.526	48
530.788	44
531.05	36
531.312	46
531.574	50
531.835	44
532.097	44
532.359	48
532.621	44
532.883	52
533.144	44
533.406	42
533.668	52
533.93	38
534.191	60
534.453	50
534.715	50
534.976	44
535.238	58
535.5	60
535.761	46
536.023	56
536.285	48
536.546	52
536.808	50
537.069	54
537.331	58
537.593	52
537.854	60
538.116	54
538.377	58
538.639	48
538.9	58
539.162	62
539.423	56
539.685	52
539.946	64
540.208	60
540.469	56
540.731	56
540.992	62
541.254	62
541.515	68
541.776	60
542.038	68
542.299	60
542.56	60
542.822	74
543.083	66
543.344	70
543.606	72
543.867	64
544.128	68
544.39	76
544.651	82
544.912	70
545.174	72
545.435	78
545.696	82
545.957	76
546.218	74
546.48	92
546.741	84
547.002	82
547.263	102
547.524	112
547.785	80
548.047	104
548.308	100
548.569	98
548.83	98
549.091	108
549.352	98
549.613	94
549.874	114
550.135	114
550.396	98
550.657	114
550.918	132
551.179	142
551.44	140
551.701	178
551.962	238
552.223	574
552.484	13646
552.745	688
553.006	242
553.267	170
553.528	162
553.788	168
554.049	154
554.31	158
554.571	158
554.832	156
555.093	152
555.353	172
555.614	160
555.875	164
556.136	170
556.396	180
556.657	184
556.918	158
557.179	184
557.439	190
557.7	170
557.961	180
558.221	206
558.482	194
558.743	200
559.003	208
559.264	214
559.525	210
559.785	180
560.046	220
560.306	208
560.567	202
560.827	242
561.088	234
561.348	228
561.609	238
561.869	242
562.13	258
562.39	250
562.651	274
562.911	268
563.172	266
563.432	274
563.692	264
563.953	284
564.213	292
564.474	310
564.734	310
564.994	318
565.255	304
565.515	336
565.775	342
566.035	312
566.296	330
566.556	326
566.816	358
567.076	326
567.337	362
567.597	376
567.857	360
568.117	372.11
568.377	389.922
568.637	395.58
568.898	398.095
569.158	426.123
569.418	434.521
569.678	446.649
569.938	439.591
570.198	455.279
570.458	472.21
570.718	490.925
570.978	506.542
571.238	526.045
571.498	539.025
571.758	557.926
572.018	601.733
572.278	642.635
572.538	671.811
572.798	707.714
573.058	721.514
573.312	760
573.573	852
573.834	910
574.095	986
574.356	1010
574.617	1142
574.878	1230
575.139	1324
575.4	1410
575.661	1392
575.922	1442
576.183	1386
576.444	1346
576.705	1370
576.965	1244
577.226	1192
577.487	1142
577.748	1074
578.009	1052
578.27	988
578.531	958
578.791	976
579.052	948
579.313	926
579.574	902
579.835	910
580.095	892
580.356	922
580.617	890
580.878	934
581.138	940
581.399	968
581.66	970
581.92	952
582.181	992
582.442	988
582.703	982
582.963	984
583.224	1004
583.484	1040
583.745	1058
584.006	1054
584.266	1120
584.527	1112
584.787	1104
585.048	1144
585.308	1174
585.569	1160
585.83	1174
586.09	1174
586.351	1234
586.611	1228
586.872	1280
587.132	1268
587.392	1242
587.653	1238
587.913	1290
588.174	1272
588.434	1302
588.695	1280
588.955	1324
589.215	1346
589.476	1322
589.736	1300
589.996	1314
590.257	1350
590.517	1336
590.777	1310
591.038	1294
591.298	1278
591.558	1314
591.818	1274
592.079	1306
592.339	1336
592.599	1268
592.859	1312
593.12	1310
593.38	1298
593.64	1318
593.9	1324
594.16	1300
594.42	1334
594.68	1322
594.941	1328
595.201	1340
595.461	1366
595.721	1378
595.981	1394
596.241	1404
596.501	1420
596.761	1440
597.021	1454
597.281	1478
597.541	1494
597.801	1490
598.061	1484
598.321	1546
598.581	1440
598.841	1542
599.101	1520
599.361	1492
599.62	1474
599.88	1510
600.14	1522
600.4	1508
600.66	1508
600.92	1560
601.18	1522
601.439	1562
601.699	1544
601.959	1582
602.219	1540
602.478	1544
602.738	1532
602.998	1512
603.258	1574
603.517	1554
603.777	1542
604.037	1578
604.296	1616
604.556	1596
604.816	1638
605.075	1618
605.335	1610
605.594	1598
605.854	1604
606.114	1606
606.373	1604
606.633	1602
606.892	1596
607.152	1608
607.411	1588
607.671	1608
607.93	1604
608.19	1674
608.449	1652
608.709	1666
608.968	1664
609.228	1668
609.487	1732
609.746	1734
610.006	1758
610.265	1732
610.524	1746
610.784	1742
611.043	1744
611.302	1750
611.562	1760
611.821	1768
612.08	1792
612.339	1770
612.599	1812
612.858	1840
613.117	1822
613.376	1842
613.635	1878
613.895	1850
614.154	1892
614.413	1878
614.672	1938
614.931	1996
615.19	1944
615.449	1986
615.709	1986
615.968	1940
616.227	1991.23
616.486	2071.31
616.745	2007.52
617.004	2046.99
617.263	2053.67
617.522	2075.7
617.781	2104.57
618.04	2091.2
618.299	2134.26
618.557	2114.84
618.816	2135.31
619.075	2132.85
619.334	2174.45
619.593	2180.75
619.852	2182.82
620.111	2211.47
620.37	2201.39
620.628	2220.43
620.887	2225.63
621.146	2190.47
621.373	2210
621.633	2240
621.893	2228
622.153	2224
622.413	2248
622.673	2204
622.932	2298
623.192	2272
623.452	2280
623.712	2276
623.972	2300
624.232	2248
624.492	2272
624.751	2332
625.011	2302
625.271	2334
625.531	2342
625.791	2376
626.05	2368
626.31	2402
626.57	2386
626.83	2410
627.089	2452
627.349	2434
627.609	2440
627.868	2480
628.128	2514
628.388	2458
628.647	2498
628.907	2512
629.167	2530
629.426	2592
629.686	2574
629.945	2570
630.205	2594
630.465	2584
630.724	2616
630.984	2632
631.243	2660
631.503	2630
631.762	2714
632.022	2708
632.281	2762
632.541	2834
632.8	2772
633.06	2868
633.319	2810
633.579	2914
633.838	2892
634.097	2934
634.357	2958
634.616	3000
634.876	3016
635.135	3022
635.394	3120
635.654	3140
635.913	3220
636.172	3356
636.431	3396
636.691	3522
636.95	3690
637.209	3856
637.469	4050
637.728	4236
637.987	4318
638.246	4442
638.505	4506
638.765	4392
639.024	4294
639.283	4180
639.542	4064
639.801	3918
640.06	3932
640.319	3840
640.578	3760
640.838	3786
641.097	3734
641.356	3754
641.615	3736
641.874	3642
642.133	3730
642.392	3732
642.651	3704
642.91	3666
643.169	3798
643.428	3660
643.687	3702
643.946	3694
644.205	3732
644.463	3776
644.722	3732
644.981	3792
645.24	3794
645.499	3788
645.758	3860
646.017	3850
646.275	3886
646.534	3858
646.793	3894
647.052	3866
647.31	3962
647.569	3890
647.828	3928
648.087	3938
648.345	4018
648.604	4002
648.863	4008
649.121	4100
649.38	4084
649.639	4182
649.897	4160
650.156	4248
650.415	4120
650.673	4222
650.932	4298
651.19	4292
651.449	4304
651.707	4304
651.966	4336
652.224	4414
652.483	4424
652.741	4486
653	4494
653.258	4542
653.517	4528
653.775	4540
654.034	4594
654.292	4688
654.55	4634
654.809	4716
655.067	4782
655.326	4836
655.584	4922
655.842	4978
656.1	4968
656.359	5064
656.617	5070
656.875	5132
657.134	5190
657.392	5202
657.65	5266
657.908	5278
658.166	5288
658.425	5412
658.683	5406
658.941	5394
659.199	5362
659.457	5462
659.715	5514
659.973	5438
660.231	5460
660.49	5428
660.748	5558
661.006	5532
661.264	5532
661.522	5548
661.78	5476
662.038	5504
662.296	5508
662.554	5590
662.811	5542
663.069	5568
663.327	5472
663.585	5538
663.843	5576.01
664.101	5518.34
664.359	5526.15
664.617	5494.1
664.874	5555.21
665.132	5534.41
665.39	5522.75
665.648	5514.39
665.906	5527.54
666.163	5570.98
666.421	5581.66
666.679	5546.64
666.937	5527.49
667.194	5543.47
667.452	5511.23
667.71	5561.31
667.967	5555.08
668.225	5571.53
668.482	5553.42
668.74	5503.58
668.987	5530
669.245	5542
669.504	5520
669.763	5564
670.022	5606
670.281	5538
670.539	5484
670.798	5594
671.057	5532
671.316	5566
671.575	5534
671.833	5574
672.092	5600
672.351	5622
672.609	5476
672.868	5680
673.127	5618
673.385	5636
673.644	5700
673.903	5696
674.161	5722
674.42	5802
674.678	5782
674.937	5806
675.195	5760
675.454	5748
675.713	5836
675.971	5840
676.23	5864
676.488	5950
676.747	5870
677.005	5936
677.263	5906
677.522	5834
677.78	5898
678.039	5950
678.297	5870
678.556	5954
678.814	5908
679.072	5888
679.331	5902
679.589	6008
679.847	5898
680.106	5956
680.364	5954
680.622	5994
680.881	6066
681.139	6028
681.397	6060
681.656	6094
681.914	6102
682.172	6080
682.43	6122
682.688	6140
682.947	6074
683.205	6120
683.463	6088
683.721	6036
683.979	6000
684.237	6034
684.495	6070
684.754	6070
685.012	6064
685.27	5940
685.528	6014
685.786	5924
686.044	6004
686.302	5966
686.56	5926
686.818	5916
687.076	6024
687.334	5914
687.592	5972
687.85	5956
688.108	5936
688.366	5952
688.623	5928
688.881	5974
689.139	5912
689.397	5830
689.655	5886
689.913	5884
690.171	5894
690.428	5820
690.686	5918
690.944	5794
691.202	5762
691.459	5778
691.717	5834
691.975	5784
692.233	5758
692.49	5722
692.748	5710
693.006	5672
693.263	5634
693.521	5690
693.779	5630
694.036	5546
694.294	5588
694.552	5630
694.809	5620
695.067	5546
695.324	5566
695.582	5562
695.839	5534
696.097	5550
696.354	5552
696.612	5482
696.869	5504
697.127	5484
697.384	5484
697.642	5400
697.899	5434
698.156	5374
698.414	5378
698.671	5356
698.928	5318
699.186	5274
699.443	5266
699.7	5242
699.958	5220
700.215	5266
700.472	5236
700.73	5230
700.987	5264
701.244	5250
701.501	5280
701.758	5182
702.016	5238
702.273	5256
702.53	5248
702.787	5240
703.044	5236
703.301	5162
703.558	5266
703.816	5190
704.073	5158
704.33	5192
704.587	5118
704.844	5168
705.101	5114
705.358	5118
705.615	5070
705.872	5016
706.129	5014
706.386	5064
706.643	4936
706.899	4930
707.156	4906
707.413	4902
707.67	4868
707.927	4826
708.184	4812
708.441	4816
708.697	4824
708.954	4806
709.211	4810
709.468	4756
709.725	4736
709.981	4784
710.238	4766
710.495	4754
710.751	4756
711.008	4708
711.265	4676.39
711.521	4688.06
711.778	4663.49
712.035	4700.11
712.291	4654.75
712.548	4600.51
712.804	4553.67
713.061	4516.82
713.317	4545.58
713.574	4490.34
713.831	4483.06
714.087	4462.9
714.343	4453.04
714.6	4388.99
714.856	4449.74
715.113	4367.18
715.369	4369.41
715.626	4347.78
715.882	4338.16
716.138	4313.38
716.395	4335.77
716.639	4312
716.897	4206
717.155	4224
717.412	4262
717.67	4222
717.927	4178
718.185	4132
718.443	4172
718.7	4142
718.958	4090
719.215	4106
719.473	4100
719.73	4070
719.988	4026
720.245	4036
720.503	4008
720.76	4022
721.018	3976
721.275	3872
721.532	3852
721.79	3926
722.047	3890
722.305	3856
722.562	3818
722.819	3726
723.077	3802
723.334	3774
723.591	3670
723.849	3692
724.106	3678
724.363	3710
724.621	3634
724.878	3662
725.135	3634
725.392	3606
725.65	3618
725.907	3604
726.164	3552
726.421	3532
726.678	3564
726.935	3458
727.193	3464
727.45	3516
727.707	3420
727.964	3404
728.221	3430
728.478	3340
728.735	3302
728.992	3286
729.249	3270
729.506	3216
729.763	3230
730.02	3188
730.277	3182
730.534	3188
730.791	3162
731.048	3142
731.305	3128
731.562	3100
731.819	3112
732.076	3038
732.333	3086
732.589	3030
732.846	2988
733.103	3014
733.36	3042
733.617	3064
733.873	2968
734.13	2950
734.387	2950
734.644	2936
734.901	2958
735.157	2946
735.414	2954
735.671	2894
735.927	2950
736.184	2896
736.441	2930
736.697	2924
736.954	2886
737.211	2880
737.467	2936
737.724	2900
737.98	2896
738.237	2876
738.493	2934
738.75	2874
739.006	2850
739.263	2836
739.519	2802
739.776	2840
740.032	2884
740.289	2780
740.545	2798
740.802	2794
741.058	2730
741.314	2714
741.571	2718
741.827	2706
742.083	2656
742.34	2694
742.596	2658
742.852	2642
743.109	2608
743.365	2608
743.621	2590
743.878	2614
744.134	2552
744.39	2516
744.646	2558
744.902	2532
745.159	2470
745.415	2476
745.671	2522
745.927	2476
746.183	2462
746.439	2486
746.695	2454
746.951	2458
747.207	2430
747.463	2424
747.719	2424
747.975	2440
748.231	2362
748.487	2366
748.743	2360
748.999	2386
749.255	2358
749.511	2266
749.767	2368
750.023	2304
750.279	2320
750.535	2298
750.791	2256
751.046	2250
751.302	2244
751.558	2230
751.814	2234
752.07	2260
752.325	2186
752.581	2250
752.837	2170
753.092	2168
753.348	2150
753.604	2132
753.859	2118
754.115	2122
754.371	2032
754.626	2088
754.882	2108
755.138	2082
755.393	2072
755.649	2050
755.904	2038
756.16	2056
756.415	1952
756.671	2058
756.926	1978
757.182	1994
757.437	1940
757.693	1958
757.948	1932
758.203	1908
758.459	1922
758.714	1917.88
758.97	1876.64
759.225	1871.95
759.48	1870.65
759.736	1845.9
759.991	1862.77
760.246	1840.73
760.501	1825.42
760.757	1825.38
761.012	1800.99
761.267	1755.81
761.522	1792.39
761.777	1772.23
762.033	1778.76
762.288	1720.48
762.543	1758.25
762.798	1752.81
763.053	1729.76
763.308	1706.66
763.563	1724.27
763.78	1678
764.037	1700
764.293	1672
764.55	1734
764.806	1632
765.062	1616
765.319	1650
765.575	1626
765.831	1572
766.088	1590
766.344	1596
766.6	1572
766.857	1570
767.113	1550
767.369	1538
767.625	1512
767.882	1518
768.138	1512
768.394	1500
768.65	1482
768.906	1480
769.163	1502
769.419	1430
769.675	1450
769.931	1462
770.187	1420
770.443	1412
770.699	1410
770.955	1420
771.211	1426
771.467	1392
771.723	1360
771.979	1372
772.235	1366
772.491	1368
772.747	1370
773.003	1346
773.259	1306
773.515	1292
773.771	1292
774.027	1286
774.283	1270
774.539	1238
774.795	1224
775.05	1230
775.306	1256
775.562	1234
775.818	1218
776.074	1192
776.329	1174
776.585	1200
776.841	1174
777.097	1194
777.352	1168
777.608	1180
777.864	1130
778.12	1154
778.375	1154
778.631	1104
778.886	1146
779.142	1102
779.398	1112
779.653	1094
779.909	1072
780.164	1060
780.42	1064
780.675	1078
780.931	1086
781.187	1012
781.442	996
781.698	1014
781.953	1032
782.208	1010
782.464	1024
782.719	982
782.975	1014
783.23	962
783.485	1002
783.741	958
783.996	980
784.252	958
784.507	974
784.762	938
785.017	904
785.273	942
785.528	912
785.783	890
786.038	886
786.294	908
786.549	886
786.804	886
787.059	892
787.314	870
787.57	894
787.825	858
788.08	842
788.335	836
788.59	838
788.845	854
789.1	826
789.355	804
789.61	838
789.865	806
790.12	774
790.375	784
790.63	788
790.885	776
791.14	792
791.395	768
791.65	768
791.905	756
792.16	760
792.414	768
792.669	742
792.924	708
793.179	734
793.434	744
793.689	688
793.943	706
794.198	692
794.453	704
794.708	646
794.962	688
795.217	684
795.472	664
795.726	662
795.981	680
796.236	646
796.49	630
796.745	642
796.999	644
797.254	666
797.508	626
797.763	638
798.018	632
798.272	644
798.526	618
798.781	632
799.035	612
799.29	582
799.544	604
799.799	610
800.053	570
800.307	574
800.562	574
800.816	570
801.07	588
801.325	584
801.579	560
801.833	556
802.088	544
802.342	532
802.596	552
802.85	546
803.105	520
803.359	546
803.613	516
803.867	510
804.121	504
804.375	492
804.63	498
804.884	532
805.138	522
805.392	504
805.646	503.126
805.9	491.006
806.154	502.576
806.408	479.38
806.662	478.124
806.916	491.305
807.17	471.463
807.424	479.984
807.678	475.01
807.931	463.832
808.185	460.661
808.439	459.487
808.693	463.026
808.947	462.549
809.201	444.324
809.454	465.772
809.708	445.857
809.962	446.062
810.216	440.607
810.469	442.339
810.678	438
810.933	420
811.188	404
811.443	430
811.699	430
811.954	402
812.209	404
812.464	410
812.719	422
812.974	406
813.229	412
813.484	402
813.739	388
813.994	396
814.249	380
814.504	382
814.759	372
815.014	372
815.268	396
815.523	366
815.778	376
816.033	378
816.288	372
816.543	362
816.798	374
817.052	376
817.307	358
817.562	358
817.817	352
818.071	368
818.326	330
818.581	334
818.836	328
819.09	352
819.345	310
819.6	326
819.854	326
820.109	344
820.364	324
820.618	322
820.873	350
821.127	320
821.382	344
821.637	316
821.891	318
822.146	306
822.4	316
822.655	328
822.909	298
823.164	328
823.418	298
823.672	308
823.927	308
824.181	284
824.436	288
824.69	280
824.944	290
825.199	282
825.453	290
825.707	280
825.962	276
826.216	282
826.47	282
826.725	258
826.979	264
827.233	248
827.487	274
827.741	268
827.996	280
828.25	280
828.504	274
828.758	256
829.012	256
829.266	258
829.52	268
829.774	252
830.029	264
830.283	268
830.537	246
830.791	258
831.045	252
831.299	234
831.553	254
831.807	250
832.061	262
832.315	234
832.568	226
832.822	238
833.076	232
833.33	222
833.584	230
833.838	238
834.092	236
834.345	226
834.599	218
834.853	230
835.107	224
835.36	228
835.614	240
835.868	212
836.122	222
836.375	216
836.629	220
836.883	198
837.136	192
837.39	226
837.643	218
837.897	204
838.151	202
838.404	222
838.658	204
838.911	192
839.165	198
839.418	206
839.672	202
839.925	200
840.179	198
840.432	186
840.686	202
840.939	202
841.192	186
841.446	182
841.699	190
841.952	194
842.206	190
842.459	196
842.712	192
842.966	206
843.219	178
843.472	190
843.725	190
843.979	182
844.232	182
844.485	192
844.738	196
844.991	180
845.244	190
845.497	178
845.75	168
846.004	178
846.257	184
846.51	172
846.763	178
847.016	168
847.269	170
847.522	160
847.775	164
848.028	164
848.281	170
848.534	160
848.786	156
849.039	154
849.292	164
849.545	160
849.798	160
850.051	154
850.303	142
850.556	158
850.809	154
851.062	158
851.314	150
851.567	152
851.82	166
852.073	152
852.325	163.928
852.578	147.671
852.831	138.798
853.083	142.601
853.336	144.394
853.588	143.222
853.841	144.155
854.093	144.731
854.346	140.096
854.598	144.793
854.851	146.503
855.103	144.025
855.356	139.173
855.608	140.697
855.861	136.474
856.113	135.205
856.366	129.237
856.618	138.148
856.87	132.645
857.123	126.155
857.352	136
857.606	136
857.859	136
858.113	132
858.367	124
858.621	138
858.875	138
859.128	126
859.382	138
859.636	132
859.889	130
860.143	134
860.397	120
860.65	126
860.904	138
861.158	128
861.411	116
861.665	126
861.918	112
862.172	126
862.425	126
862.679	120
862.932	124
863.186	116
863.439	124
863.693	116
863.946	112
864.2	120
864.453	102
864.707	110
864.96	116
865.213	116
865.467	114
865.72	120
865.973	118
866.227	118
866.48	110
866.733	116
866.987	108
867.24	108
867.493	104
867.746	120
867.999	114
868.253	108
868.506	122
868.759	106
869.012	110
869.265	106
869.518	108
869.771	98
870.025	100
870.278	94
870.531	90
870.784	100
871.037	108
871.29	114
871.543	108
871.796	92
872.049	102
872.302	102
872.555	96
872.808	90
873.06	94
873.313	106
873.566	94
873.819	96
874.072	94
874.325	90
874.578	86
874.83	94
875.083	90
875.336	94
875.589	102
875.841	100
876.094	92
876.347	92
876.6	100
876.852	94
877.105	92
877.358	94
877.61	100
877.863	86
878.115	92
878.368	86
878.621	86
878.873	78
879.126	90
879.378	104
879.631	76
879.883	84
880.136	96
880.388	90
880.641	84
880.893	86
881.145	92
881.398	94
881.65	78
881.902	90
882.155	80
882.407	86
882.659	72
882.912	86
883.164	72
883.416	84
883.669	82
883.921	90
884.173	80
884.425	82
884.677	78
884.93	86
885.182	80
885.434	84
885.686	80
885.938	80
886.19	74
886.442	76
886.694	74
886.946	78
887.198	72
887.45	88
887.702	66
887.954	70
888.206	76
888.458	84
888.71	74
888.962	84
889.214	76
889.466	68
889.718	82
889.969	64
890.221	76
890.473	58
890.725	78
890.977	78
891.228	60
891.48	70
891.732	82
891.983	70
892.235	68
892.487	74
892.738	70
892.99	70
893.242	48
893.493	70
893.745	64
893.996	66
894.248	70
894.5	64
894.751	66
895.003	58
895.254	70
895.505	64
895.757	56
896.008	68
896.26	66
896.511	66
896.763	60
897.014	66
897.265	62
897.517	58
897.768	64
898.019	62
898.27	58
898.522	58
898.773	54
899.024	68
899.275	56
899.527	54
899.778	62
899.979	64