File: MS_091025_02.txt
#Acq. time (s)=	5
#Accumulations=	2
#Range (nm)=	520...900
#Windows=	8
#Auto scanning=	Off
#Autofocus=	Off
#AutoExposure=	Off
#Spike filter=	Multiple accum.
#Delay time (s)=	0
#Binning=	1
#Readout mode=	Signal
#DeNoise=	Off
#ICS correction=	Off
#Dark correction=	Off
#Inst. Process=	Off
#Detector temperature (°C)=	-59.98
#Instrument=	LabRAM HR Evol
#Detector=	Syncerity OE
#Objective=	x50_VIS
#Grating=	600 (500nm)
#ND Filter=	10%
#Laser=	514nm_Edge
#Hole=	199.981
#Range=	Auto
#StageXY=	Marzhauser
#StageZ=	Marzhauser
#X (µm)=	-19137.9
#Y (µm)=	7454.1
#Z (µm)=	-71.5
#Full time(mm:ss)=	2:04
#Project=
#Sample=
#Site=
#Title=	MS_091025
#Remark=
#Date=	13.10.2023 16:33
#Acquired=	13.10.2023 16:33:22
520.044	34
520.306	40
520.569	40
520.831	28
521.093	44
521.355	36
521.617	46
521.88	42
522.142	40
522.404	44
522.666	36
522.928	48
523.19	46
523.453	48
523.715	42
523.977	44
524.239	48
524.501	32
524.763	52
525.025	46
525.287	44
525.549	46
525.811	50
526.073	44
526.335	40
526.597	48
526.859	50
527.121	48
527.383	48
527.645	50
527.907	54
528.169	44
528.431	48
528.693	52
528.955	44
529.217	38
529.479	40
529.741	48
530.003	46
530.264	48
530.526	56
530.788	52
531.05	46
531.312	50
531.574	50
531.835	60
532.097	48
532.359	50
532.621	62
532.883	48
533.144	54
533.406	56
533.668	56
533.93	62
534.191	68
534.453	60
534.715	52
534.976	56
535.238	60
535.5	50
535.761	54
536.023	58
536.285	62
536.546	58
536.808	58
537.069	64
537.331	68
537.593	60
537.854	62
538.116	70
538.377	62
538.639	66
538.9	72
539.162	76
539.423	58
539.685	78
539.946	70
540.208	70
540.469	72
540.731	66
540.992	68
541.254	64
541.515	80
541.776	82
542.038	74
542.299	74
542.56	84
542.822	88
543.083	76
543.344	80
543.606	90
543.867	76
544.128	82
544.39	82
544.651	100
544.912	92
545.174	98
545.435	96
545.696	104
545.957	98
546.218	100
546.48	102
546.741	92
547.002	118
547.263	110
547.524	130
547.785	116
548.047	124
548.308	124
548.569	130
548.83	128
549.091	138
549.352	142
549.613	134
549.874	140
550.135	148
550.396	154
550.657	138
550.918	164
551.179	170
551.44	172
551.701	202
551.962	252
552.223	550
552.484	12268
552.745	776
553.006	280
553.267	218
553.528	186
553.788	204
554.049	182
554.31	184
554.571	208
554.832	210
555.093	210
555.353	208
555.614	210
555.875	210
556.136	208
556.396	230
556.657	218
556.918	236
557.179	234
557.439	242
557.7	244
557.961	248
558.221	268
558.482	284
558.743	256
559.003	250
559.264	252
559.525	276
559.785	276
560.046	292
560.306	282
560.567	302
560.827	298
561.088	316
561.348	310
561.609	320
561.869	340
562.13	330
562.39	342
562.651	358
562.911	360
563.172	354
563.432	368
563.692	382
563.953	378
564.213	406
564.474	404
564.734	406
564.994	392
565.255	446
565.515	420
565.775	440
566.035	452
566.296	432
566.556	462
566.816	444
567.076	482
567.337	474
567.597	498
567.857	486
568.117	508.04
568.377	514.888
568.637	520.313
568.898	548.347
569.158	555.77
569.418	597.698
569.678	585.618
569.938	601.141
570.198	622.803
570.458	642.35
570.718	652.949
570.978	700.021
571.238	734.745
571.498	770.759
571.758	801.565
572.018	835.208
572.278	872.957
572.538	942.472
572.798	997.724
573.058	1034.65
573.312	1140
573.573	1230
573.834	1312
574.095	1402
574.356	1512
574.617	1624
574.878	1744
575.139	1834
575.4	1910
575.661	1960
575.922	1978
576.183	1930
576.444	1872
576.705	1758
576.965	1638
577.226	1574
577.487	1528
577.748	1472
578.009	1404
578.27	1318
578.531	1338
578.791	1316
579.052	1304
579.313	1242
579.574	1250
579.835	1242
580.095	1264
580.356	1268
580.617	1244
580.878	1306
581.138	1296
581.399	1294
581.66	1290
581.92	1326
582.181	1294
582.442	1322
582.703	1354
582.963	1400
583.224	1384
583.484	1412
583.745	1470
584.006	1470
584.266	1488
584.527	1486
584.787	1540
585.048	1540
585.308	1606
585.569	1604
585.83	1656
586.09	1664
586.351	1664
586.611	1692
586.872	1660
587.132	1716
587.392	1730
587.653	1742
587.913	1748
588.174	1690
588.434	1748
588.695	1800
588.955	1780
589.215	1776
589.476	1810
589.736	1790
589.996	1788
590.257	1800
590.517	1790
590.777	1802
591.038	1812
591.298	1760
591.558	1730
591.818	1752
592.079	1778
592.339	1788
592.599	1770
592.859	1780
593.12	1738
593.38	1776
593.64	1732
593.9	1834
594.16	1812
594.42	1808
594.68	1836
594.941	1900
595.201	1840
595.461	1866
595.721	1894
595.981	1948
596.241	2010
596.501	1996
596.761	2038
597.021	2030
597.281	2022
597.541	2052
597.801	2080
598.061	2056
598.321	2058
598.581	2040
598.841	2132
599.101	2092
599.361	2092
599.62	2102
599.88	2048
600.14	2158
600.4	2104
600.66	2076
600.92	2086
601.18	2094
601.439	2164
601.699	2092
601.959	2106
602.219	2150
602.478	2162
602.738	2140
602.998	2164
603.258	2146
603.517	2190
603.777	2164
604.037	2188
604.296	2210
604.556	2204
604.816	2212
605.075	2178
605.335	2234
605.594	2242
605.854	2178
606.114	2228
606.373	2214
606.633	2238
606.892	2258
607.152	2230
607.411	2224
607.671	2236
607.93	2198
608.19	2262
608.449	2270
608.709	2280
608.968	2304
609.228	2322
609.487	2254
609.746	2340
610.006	2344
610.265	2360
610.524	2362
610.784	2392
611.043	2402
611.302	2352
611.562	2434
611.821	2438
612.08	2482
612.339	2474
612.599	2456
612.858	2518
613.117	2532
613.376	2522
613.635	2566
613.895	2584
614.154	2596
614.413	2594
614.672	2594
614.931	2642
615.19	2658
615.449	2720
615.709	2716
615.968	2724
616.227	2779.23
616.486	2723.89
616.745	2745.75
617.004	2814.57
617.263	2795.72
617.522	2842.84
617.781	2837.41
618.04	2878.59
618.299	2873.04
618.557	2890.28
618.816	2915.9
619.075	2961.38
619.334	2935.83
619.593	2958.14
619.852	2942.85
620.111	3004.7
620.37	2950.88
620.628	2989.22
620.887	3006.08
621.146	3012.09
621.373	2996
621.633	2988
621.893	3016
622.153	3050
622.413	3046
622.673	3052
622.932	3084
623.192	3084
623.452	3012
623.712	3066
623.972	3104
624.232	3136
624.492	3144
624.751	3148
625.011	3170
625.271	3142
625.531	3212
625.791	3124
626.05	3234
626.31	3256
626.57	3262
626.83	3212
627.089	3236
627.349	3304
627.609	3352
627.868	3298
628.128	3368
628.388	3338
628.647	3350
628.907	3340
629.167	3402
629.426	3438
629.686	3414
629.945	3432
630.205	3436
630.465	3454
630.724	3440
630.984	3500
631.243	3518
631.503	3546
631.762	3590
632.022	3644
632.281	3598
632.541	3676
632.8	3722
633.06	3788
633.319	3752
633.579	3826
633.838	3846
634.097	3846
634.357	3886
634.616	3930
634.876	4012
635.135	4040
635.394	4166
635.654	4268
635.913	4302
636.172	4526
636.431	4558
636.691	4760
636.95	5064
637.209	5252
637.469	5320
637.728	5532
637.987	5620
638.246	5524
638.505	5464
638.765	5444
639.024	5284
639.283	5200
639.542	5112
639.801	4996
640.06	4828
640.319	4860
640.578	4840
640.838	4790
641.097	4742
641.356	4726
641.615	4762
641.874	4658
642.133	4714
642.392	4646
642.651	4724
642.91	4664
643.169	4738
643.428	4760
643.687	4776
643.946	4764
644.205	4822
644.463	4830
644.722	4810
644.981	4926
645.24	4870
645.499	4932
645.758	4840
646.017	4914
646.275	4980
646.534	4966
646.793	4856
647.052	4998
647.31	5082
647.569	5048
647.828	5126
648.087	5110
648.345	5146
648.604	5150
648.863	5144
649.121	5202
649.38	5212
649.639	5282
649.897	5248
650.156	5324
650.415	5332
650.673	5390
650.932	5444
651.19	5346
651.449	5390
651.707	5500
651.966	5554
652.224	5598
652.483	5584
652.741	5604
653	5654
653.258	5734
653.517	5726
653.775	5856
654.034	5810
654.292	5880
654.55	5922
654.809	5942
655.067	6038
655.326	6114
655.584	6156
655.842	6162
656.1	6242
656.359	6310
656.617	6298
656.875	6374
657.134	6522
657.392	6562
657.65	6590
657.908	6582
658.166	6668
658.425	6664
658.683	6734
658.941	6728
659.199	6730
659.457	6790
659.715	6818
659.973	6686
660.231	6840
660.49	6680
660.748	6788
661.006	6738
661.264	6778
661.522	6804
661.78	6744
662.038	6684
662.296	6802
662.554	6774
662.811	6862
663.069	6802
663.327	6824
663.585	6804
663.843	6815.48
664.101	6819.47
664.359	6770.54
664.617	6842.94
664.874	6817.54
665.132	6776.33
665.39	6829.5
665.648	6822.02
665.906	6781.05
666.163	6806.79
666.421	6747.77
666.679	6789.58
666.937	6791.86
667.194	6807.07
667.452	6817.64
667.71	6824.78
667.967	6847.84
668.225	6802.09
668.482	6850.07
668.74	6781.2
668.987	6804
669.245	6816
669.504	6840
669.763	6728
670.022	6862
670.281	6824
670.539	6826
670.798	6682
671.057	6792
671.316	6774
671.575	6868
671.833	6776
672.092	6868
672.351	6844
672.609	6860
672.868	6858
673.127	6974
673.385	6926
673.644	6912
673.903	6942
674.161	7036
674.42	7044
674.678	7010
674.937	7136
675.195	7166
675.454	7156
675.713	7136
675.971	7224
676.23	7176
676.488	7206
676.747	7154
677.005	7192
677.263	7214
677.522	7198
677.78	7212
678.039	7178
678.297	7104
678.556	7136
678.814	7142
679.072	7196
679.331	7306
679.589	7198
679.847	7274
680.106	7218
680.364	7212
680.622	7318
680.881	7294
681.139	7296
681.397	7340
681.656	7370
681.914	7426
682.172	7358
682.43	7366
682.688	7450
682.947	7386
683.205	7370
683.463	7394
683.721	7356
683.979	7288
684.237	7380
684.495	7314
684.754	7292
685.012	7340
685.27	7260
685.528	7254
685.786	7354
686.044	7252
686.302	7212
686.56	7234
686.818	7228
687.076	7240
687.334	7180
687.592	7192
687.85	7164
688.108	7246
688.366	7212
688.623	7094
688.881	7130
689.139	7104
689.397	7114
689.655	7124
689.913	7126
690.171	7096
690.428	7074
690.686	7078
690.944	6986
691.202	6934
691.459	7054
691.717	6966
691.975	6914
692.233	6916
692.49	6942
692.748	6900
693.006	6762
693.263	6834
693.521	6764
693.779	6862
694.036	6824
694.294	6674
694.552	6764
694.809	6690
695.067	6738
695.324	6768
695.582	6662
695.839	6672
696.097	6672
696.354	6666
696.612	6614
696.869	6568
697.127	6640
697.384	6494
697.642	6446
697.899	6464
698.156	6510
698.414	6480
698.671	6418
698.928	6380
699.186	6384
699.443	6334
699.7	6364
699.958	6242
700.215	6292
700.472	6294
700.73	6272
700.987	6268
701.244	6290
701.501	6272
701.758	6276
702.016	6292
702.273	6260
702.53	6298
702.787	6240
703.044	6270
703.301	6230
703.558	6240
703.816	6296
704.073	6248
704.33	6154
704.587	6178
704.844	6138
705.101	6068
705.358	6076
705.615	6058
705.872	6042
706.129	5982
706.386	5930
706.643	5966
706.899	5984
707.156	5892
707.413	5878
707.67	5794
707.927	5768
708.184	5762
708.441	5850
708.697	5710
708.954	5774
709.211	5720
709.468	5742
709.725	5702
709.981	5748
710.238	5734
710.495	5642
710.751	5666
711.008	5648
711.265	5622.16
711.521	5642.25
711.778	5528.11
712.035	5620.97
712.291	5504.96
712.548	5448.58
712.804	5439.84
713.061	5424.64
713.317	5398.44
713.574	5333.05
713.831	5379.95
714.087	5314.02
714.343	5270.39
714.6	5277.91
714.856	5261.33
715.113	5229.31
715.369	5198.31
715.626	5178.49
715.882	5156.81
716.138	5097.41
716.395	5121.98
716.639	5078
716.897	5074
717.155	4976
717.412	4936
717.67	4946
717.927	5074
718.185	4994
718.443	4862
718.7	4912
718.958	4934
719.215	4888
719.473	4828
719.73	4886
719.988	4772
720.245	4794
720.503	4646
720.76	4672
721.018	4688
721.275	4684
721.532	4670
721.79	4714
722.047	4674
722.305	4486
722.562	4558
722.819	4510
723.077	4462
723.334	4458
723.591	4484
723.849	4392
724.106	4380
724.363	4394
724.621	4336
724.878	4384
725.135	4306
725.392	4294
725.65	4306
725.907	4304
726.164	4202
726.421	4172
726.678	4124
726.935	4142
727.193	4134
727.45	4060
727.707	4108
727.964	4042
728.221	3996
728.478	4002
728.735	4018
728.992	3868
729.249	3916
729.506	3894
729.763	3886
730.02	3848
730.277	3788
730.534	3804
730.791	3826
731.048	3706
731.305	3710
731.562	3682
731.819	3700
732.076	3680
732.333	3618
732.589	3586
732.846	3608
733.103	3644
733.36	3610
733.617	3570
733.873	3642
734.13	3608
734.387	3512
734.644	3578
734.901	3504
735.157	3508
735.414	3512
735.671	3520
735.927	3462
736.184	3450
736.441	3490
736.697	3472
736.954	3534
737.211	3516
737.467	3470
737.724	3544
737.98	3450
738.237	3554
738.493	3520
738.75	3470
739.006	3442
739.263	3398
739.519	3436
739.776	3288
740.032	3326
740.289	3386
740.545	3320
740.802	3296
741.058	3306
741.314	3230
741.571	3216
741.827	3206
742.083	3226
742.34	3198
742.596	3164
742.852	3110
743.109	3112
743.365	3044
743.621	3076
743.878	3060
744.134	3046
744.39	3006
744.646	2988
744.902	2982
745.159	2964
745.415	3034
745.671	2910
745.927	2984
746.183	2930
746.439	2908
746.695	2890
746.951	2858
747.207	2796
747.463	2850
747.719	2824
747.975	2836
748.231	2852
748.487	2826
748.743	2798
748.999	2772
749.255	2794
749.511	2798
749.767	2708
750.023	2742
750.279	2690
750.535	2686
750.791	2706
751.046	2656
751.302	2638
751.558	2652
751.814	2554
752.07	2606
752.325	2614
752.581	2554
752.837	2542
753.092	2508
753.348	2486
753.604	2514
753.859	2474
754.115	2506
754.371	2444
754.626	2440
754.882	2484
755.138	2422
755.393	2472
755.649	2444
755.904	2398
756.16	2394
756.415	2392
756.671	2380
756.926	2348
757.182	2340
757.437	2308
757.693	2294
757.948	2316
758.203	2322
758.459	2296
758.714	2226.13
758.97	2213.57
759.225	2241.54
759.48	2258.03
759.736	2204.64
759.991	2173.46
760.246	2136.47
760.501	2163.08
760.757	2102.13
761.012	2125.71
761.267	2117.11
761.522	2129.81
761.777	2107.28
762.033	2093.07
762.288	2037.64
762.543	2006.03
762.798	2061.18
763.053	2032.62
763.308	1995.76
763.563	1996.09
763.78	1992
764.037	1988
764.293	1956
764.55	1980
764.806	1878
765.062	1922
765.319	1912
765.575	1884
765.831	1882
766.088	1902
766.344	1866
766.6	1834
766.857	1816
767.113	1832
767.369	1822
767.625	1868
767.882	1786
768.138	1760
768.394	1772
768.65	1824
768.906	1722
769.163	1722
769.419	1720
769.675	1706
769.931	1716
770.187	1678
770.443	1662
770.699	1636
770.955	1632
771.211	1600
771.467	1636
771.723	1584
771.979	1628
772.235	1616
772.491	1544
772.747	1616
773.003	1530
773.259	1580
773.515	1540
773.771	1560
774.027	1546
774.283	1468
774.539	1526
774.795	1484
775.05	1462
775.306	1440
775.562	1430
775.818	1442
776.074	1448
776.329	1404
776.585	1392
776.841	1382
777.097	1380
777.352	1382
777.608	1344
777.864	1318
778.12	1338
778.375	1322
778.631	1318
778.886	1308
779.142	1334
779.398	1312
779.653	1248
779.909	1294
780.164	1260
780.42	1256
780.675	1280
780.931	1264
781.187	1238
781.442	1236
781.698	1208
781.953	1196
782.208	1170
782.464	1188
782.719	1198
782.975	1180
783.23	1156
783.485	1164
783.741	1136
783.996	1138
784.252	1090
784.507	1110
784.762	1132
785.017	1102
785.273	1082
785.528	1052
785.783	1110
786.038	1036
786.294	1080
786.549	1062
786.804	1060
787.059	1036
787.314	1014
787.57	1016
787.825	986
788.08	1020
788.335	982
788.59	984
788.845	998
789.1	996
789.355	966
789.61	964
789.865	976
790.12	974
790.375	940
790.63	922
790.885	894
791.14	922
791.395	902
791.65	924
791.905	916
792.16	914
792.414	874
792.669	858
792.924	890
793.179	816
793.434	860
793.689	874
793.943	842
794.198	818
794.453	826
794.708	788
794.962	802
795.217	826
795.472	794
795.726	802
795.981	780
796.236	778
796.49	760
796.745	760
796.999	744
797.254	762
797.508	754
797.763	726
798.018	728
798.272	740
798.526	740
798.781	740
799.035	730
799.29	712
799.544	676
799.799	692
800.053	674
800.307	678
800.562	688
800.816	690
801.07	688
801.325	670
801.579	662
801.833	668
802.088	670
802.342	670
802.596	646
802.85	632
803.105	648
803.359	614
803.613	610
803.867	614
804.121	628
804.375	626
804.63	592
804.884	582
805.138	560
805.392	602
805.646	564.188
805.9	630.401
806.154	587.526
806.408	549.641
806.662	571.965
806.916	567.654
807.17	569.343
807.424	540.253
807.678	557.733
807.931	545.343
808.185	563.096
808.439	545.11
808.693	528.659
808.947	530.647
809.201	534
809.454	507.023
809.708	512.386
809.962	518.417
810.216	503.818
810.469	502.718
810.678	494
810.933	524
811.188	508
811.443	482
811.699	482
811.954	498
812.209	484
812.464	470
812.719	482
812.974	478
813.229	464
813.484	452
813.739	456
813.994	442
814.249	446
814.504	436
814.759	458
815.014	448
815.268	438
815.523	414
815.778	438
816.033	422
816.288	430
816.543	432
816.798	434
817.052	412
817.307	398
817.562	418
817.817	410
818.071	418
818.326	414
818.581	402
818.836	388
819.09	402
819.345	396
819.6	400
819.854	390
820.109	366
820.364	382
820.618	386
820.873	362
821.127	380
821.382	370
821.637	378
821.891	364
822.146	344
822.4	358
822.655	370
822.909	350
823.164	344
823.418	344
823.672	364
823.927	350
824.181	336
824.436	334
824.69	328
824.944	340
825.199	334
825.453	334
825.707	318
825.962	328
826.216	328
826.47	310
826.725	330
826.979	308
827.233	316
827.487	304
827.741	316
827.996	318
828.25	300
828.504	286
828.758	296
829.012	310
829.266	288
829.52	290
829.774	286
830.029	278
830.283	296
830.537	288
830.791	316
831.045	292
831.299	284
831.553	288
831.807	296
832.061	276
832.315	262
832.568	288
832.822	292
833.076	274
833.33	278
833.584	276
833.838	252
834.092	272
834.345	270
834.599	276
834.853	256
835.107	242
835.36	244
835.614	258
835.868	252
836.122	250
836.375	240
836.629	254
836.883	256
837.136	244
837.39	258
837.643	260
837.897	250
838.151	242
838.404	242
838.658	226
838.911	244
839.165	240
839.418	232
839.672	238
839.925	232
840.179	244
840.432	234
840.686	226
840.939	224
841.192	220
841.446	238
841.699	216
841.952	232
842.206	214
842.459	222
842.712	218
842.966	224
843.219	202
843.472	208
843.725	210
843.979	194
844.232	196
844.485	210
844.738	202
844.991	206
845.244	208
845.497	206
845.75	214
846.004	210
846.257	208
846.51	200
846.763	202
847.016	198
847.269	196
847.522	204
847.775	190
848.028	186
848.281	194
848.534	186
848.786	188
849.039	196
849.292	174
849.545	188
849.798	186
850.051	182
850.303	170
850.556	184
850.809	184
851.062	182
851.314	174
851.567	180
851.82	176
852.073	176
852.325	180.019
852.578	173.891
852.831	177.564
853.083	165.757
853.336	165.196
853.588	179.92
853.841	156.355
854.093	165.315
854.346	164.221
854.598	164.139
854.851	167.221
855.103	164.025
855.356	166.66
855.608	159.827
855.861	154.732
856.113	166.537
856.366	154.639
856.618	150.965
856.87	152.19
857.123	162.121
857.352	154
857.606	146
857.859	160
858.113	152
858.367	152
858.621	148
858.875	148
859.128	152
859.382	142
859.636	142
859.889	154
860.143	152
860.397	146
860.65	148
860.904	144
861.158	142
861.411	148
861.665	132
861.918	144
862.172	134
862.425	148
862.679	160
862.932	128
863.186	138
863.439	152
863.693	144
863.946	130
864.2	138
864.453	130
864.707	124
864.96	136
865.213	132
865.467	132
865.72	120
865.973	128
866.227	132
866.48	126
866.733	132
866.987	134
867.24	126
867.493	122
867.746	122
867.999	130
868.253	124
868.506	112
868.759	120
869.012	114
869.265	132
869.518	126
869.771	118
870.025	130
870.278	122
870.531	114
870.784	114
871.037	112
871.29	120
871.543	120
871.796	114
872.049	116
872.302	108
872.555	122
872.808	120
873.06	116
873.313	120
873.566	116
873.819	110
874.072	108
874.325	106
874.578	112
874.83	102
875.083	116
875.336	118
875.589	96
875.841	104
876.094	118
876.347	112
876.6	98
876.852	114
877.105	108
877.358	102
877.61	98
877.863	110
878.115	92
878.368	94
878.621	118
878.873	112
879.126	98
879.378	102
879.631	114
879.883	110
880.136	94
880.388	102
880.641	102
880.893	86
881.145	100
881.398	92
881.65	98
881.902	76
882.155	100
882.407	92
882.659	84
882.912	94
883.164	98
883.416	92
883.669	88
883.921	98
884.173	94
884.425	88
884.677	84
884.93	88
885.182	90
885.434	92
885.686	94
885.938	86
886.19	80
886.442	86
886.694	92
886.946	102
887.198	72
887.45	80
887.702	78
887.954	92
888.206	78
888.458	84
888.71	78
888.962	76
889.214	82
889.466	84
889.718	86
889.969	80
890.221	82
890.473	76
890.725	82
890.977	72
891.228	76
891.48	80
891.732	76
891.983	82
892.235	78
892.487	80
892.738	76
892.99	74
893.242	74
893.493	72
893.745	70
893.996	66
894.248	76
894.5	76
894.751	68
895.003	78
895.254	72
895.505	74
895.757	70
896.008	80
896.26	64
896.511	76
896.763	70
897.014	70
897.265	68
897.517	72
897.768	78
898.019	62
898.27	64
898.522	70
898.773	58
899.024	52
899.275	72
899.527	66
899.778	72
899.979	68