File: MS_091025_01.txt
#Acq. time (s)=	5
#Accumulations=	2
#Range (nm)=	520...900
#Windows=	8
#Auto scanning=	Off
#Autofocus=	Off
#AutoExposure=	Off
#Spike filter=	Multiple accum.
#Delay time (s)=	0
#Binning=	1
#Readout mode=	Signal
#DeNoise=	Off
#ICS correction=	Off
#Dark correction=	Off
#Inst. Process=	Off
#Detector temperature (°C)=	-59.98
#Instrument=	LabRAM HR Evol
#Detector=	Syncerity OE
#Objective=	x50_VIS
#Grating=	600 (500nm)
#ND Filter=	10%
#Laser=	514nm_Edge
#Hole=	199.981
#Range=	Auto
#StageXY=	Marzhauser
#StageZ=	Marzhauser
#X (µm)=	-24016.1
#Y (µm)=	7454.1
#Z (µm)=	16.8
#Full time(mm:ss)=	1:54
#Project=
#Sample=
#Site=
#Title=	MS_091025
#Remark=
#Date=	13.10.2023 16:29
#Acquired=	13.10.2023 16:29:59
520.044	50
520.306	50
520.569	50
520.831	36
521.093	46
521.355	40
521.617	40
521.88	48
522.142	40
522.404	56
522.666	48
522.928	52
523.19	40
523.453	52
523.715	46
523.977	38
524.239	50
524.501	42
524.763	38
525.025	48
525.287	50
525.549	48
525.811	50
526.073	58
526.335	44
526.597	52
526.859	52
527.121	44
527.383	48
527.645	52
527.907	54
528.169	56
528.431	60
528.693	46
528.955	60
529.217	50
529.479	42
529.741	52
530.003	58
530.264	50
530.526	54
530.788	62
531.05	50
531.312	64
531.574	50
531.835	60
532.097	54
532.359	56
532.621	62
532.883	58
533.144	58
533.406	58
533.668	72
533.93	56
534.191	70
534.453	70
534.715	60
534.976	74
535.238	66
535.5	84
535.761	66
536.023	64
536.285	66
536.546	62
536.808	70
537.069	74
537.331	72
537.593	68
537.854	78
538.116	78
538.377	74
538.639	70
538.9	88
539.162	64
539.423	84
539.685	80
539.946	82
540.208	84
540.469	80
540.731	88
540.992	74
541.254	94
541.515	82
541.776	82
542.038	84
542.299	96
542.56	94
542.822	100
543.083	94
543.344	94
543.606	96
543.867	92
544.128	102
544.39	92
544.651	104
544.912	106
545.174	110
545.435	110
545.696	114
545.957	106
546.218	120
546.48	126
546.741	120
547.002	128
547.263	134
547.524	134
547.785	144
548.047	144
548.308	158
548.569	148
548.83	156
549.091	144
549.352	166
549.613	162
549.874	152
550.135	180
550.396	168
550.657	192
550.918	186
551.179	194
551.44	210
551.701	242
551.962	290
552.223	568
552.484	11958
552.745	992
553.006	320
553.267	256
553.528	246
553.788	232
554.049	228
554.31	236
554.571	228
554.832	236
555.093	240
555.353	242
555.614	232
555.875	268
556.136	256
556.396	272
556.657	278
556.918	268
557.179	288
557.439	286
557.7	276
557.961	294
558.221	330
558.482	296
558.743	290
559.003	312
559.264	314
559.525	326
559.785	320
560.046	352
560.306	332
560.567	356
560.827	360
561.088	382
561.348	360
561.609	380
561.869	400
562.13	418
562.39	422
562.651	432
562.911	410
563.172	440
563.432	438
563.692	448
563.953	458
564.213	476
564.474	450
564.734	478
564.994	466
565.255	520
565.515	518
565.775	542
566.035	538
566.296	542
566.556	558
566.816	566
567.076	590
567.337	578
567.597	588
567.857	586
568.117	622.03
568.377	600.306
568.637	613.783
568.898	636.48
569.158	686.136
569.418	696.051
569.678	714.07
569.938	704.548
570.198	763.116
570.458	762.67
570.718	803.726
570.978	830.747
571.238	863.041
571.498	920.999
571.758	969.64
572.018	1002.21
572.278	1076.59
572.538	1121.54
572.798	1187.71
573.058	1248.24
573.312	1324
573.573	1454
573.834	1558
574.095	1730
574.356	1870
574.617	1946
574.878	2096
575.139	2250
575.4	2292
575.661	2362
575.922	2376
576.183	2204
576.444	2184
576.705	2094
576.965	2012
577.226	1876
577.487	1820
577.748	1698
578.009	1658
578.27	1602
578.531	1586
578.791	1540
579.052	1488
579.313	1474
579.574	1516
579.835	1494
580.095	1502
580.356	1492
580.617	1490
580.878	1550
581.138	1530
581.399	1584
581.66	1516
581.92	1590
582.181	1584
582.442	1608
582.703	1618
582.963	1604
583.224	1670
583.484	1670
583.745	1722
584.006	1764
584.266	1784
584.527	1780
584.787	1834
585.048	1850
585.308	1886
585.569	1876
585.83	1972
586.09	1968
586.351	1970
586.611	2006
586.872	2028
587.132	2040
587.392	2024
587.653	2066
587.913	2102
588.174	2058
588.434	2128
588.695	2046
588.955	2136
589.215	2096
589.476	2136
589.736	2150
589.996	2110
590.257	2142
590.517	2110
590.777	2128
591.038	2144
591.298	2164
591.558	2092
591.818	2126
592.079	2164
592.339	2064
592.599	2102
592.859	2068
593.12	2114
593.38	2112
593.64	2156
593.9	2136
594.16	2144
594.42	2138
594.68	2180
594.941	2186
595.201	2188
595.461	2228
595.721	2276
595.981	2296
596.241	2360
596.501	2338
596.761	2362
597.021	2382
597.281	2446
597.541	2404
597.801	2398
598.061	2432
598.321	2446
598.581	2406
598.841	2424
599.101	2440
599.361	2484
599.62	2502
599.88	2490
600.14	2500
600.4	2430
600.66	2446
600.92	2496
601.18	2560
601.439	2528
601.699	2456
601.959	2526
602.219	2534
602.478	2526
602.738	2508
602.998	2556
603.258	2564
603.517	2574
603.777	2572
604.037	2582
604.296	2620
604.556	2610
604.816	2608
605.075	2642
605.335	2636
605.594	2626
605.854	2652
606.114	2612
606.373	2650
606.633	2580
606.892	2646
607.152	2596
607.411	2624
607.671	2614
607.93	2678
608.19	2672
608.449	2696
608.709	2754
608.968	2744
609.228	2786
609.487	2740
609.746	2796
610.006	2774
610.265	2806
610.524	2814
610.784	2812
611.043	2850
611.302	2860
611.562	2882
611.821	2898
612.08	2898
612.339	2886
612.599	2988
612.858	2984
613.117	2930
613.376	2962
613.635	3028
613.895	3028
614.154	3090
614.413	3060
614.672	3170
614.931	3160
615.19	3174
615.449	3168
615.709	3214
615.968	3184
616.227	3215.4
616.486	3274.99
616.745	3291.29
617.004	3293.58
617.263	3279.1
617.522	3368.67
617.781	3323.46
618.04	3365.56
618.299	3410.36
618.557	3457.32
618.816	3497.92
619.075	3429.54
619.334	3484.9
619.593	3481.08
619.852	3515.64
620.111	3515.73
620.37	3545.55
620.628	3518.72
620.887	3533.52
621.146	3551.02
621.373	3586
621.633	3582
621.893	3512
622.153	3598
622.413	3634
622.673	3598
622.932	3630
623.192	3576
623.452	3566
623.712	3604
623.972	3664
624.232	3670
624.492	3672
624.751	3664
625.011	3682
625.271	3752
625.531	3726
625.791	3710
626.05	3766
626.31	3792
626.57	3862
626.83	3836
627.089	3806
627.349	3826
627.609	3912
627.868	3910
628.128	3962
628.388	3962
628.647	3948
628.907	3990
629.167	4012
629.426	4004
629.686	4038
629.945	4070
630.205	4056
630.465	4120
630.724	4182
630.984	4146
631.243	4184
631.503	4198
631.762	4298
632.022	4256
632.281	4262
632.541	4372
632.8	4350
633.06	4494
633.319	4498
633.579	4462
633.838	4570
634.097	4628
634.357	4680
634.616	4636
634.876	4782
635.135	4802
635.394	4992
635.654	5070
635.913	5172
636.172	5358
636.431	5584
636.691	5836
636.95	6006
637.209	6232
637.469	6568
637.728	6616
637.987	6600
638.246	6710
638.505	6504
638.765	6388
639.024	6250
639.283	6098
639.542	5946
639.801	5836
640.06	5736
640.319	5770
640.578	5646
640.838	5616
641.097	5654
641.356	5648
641.615	5594
641.874	5586
642.133	5568
642.392	5516
642.651	5608
642.91	5588
643.169	5650
643.428	5630
643.687	5628
643.946	5664
644.205	5656
644.463	5648
644.722	5730
644.981	5804
645.24	5764
645.499	5806
645.758	5836
646.017	5826
646.275	5806
646.534	5878
646.793	5926
647.052	5932
647.31	5932
647.569	6026
647.828	5954
648.087	6100
648.345	6050
648.604	6110
648.863	6188
649.121	6172
649.38	6214
649.639	6242
649.897	6366
650.156	6314
650.415	6280
650.673	6356
650.932	6428
651.19	6482
651.449	6458
651.707	6562
651.966	6638
652.224	6664
652.483	6588
652.741	6784
653	6782
653.258	6732
653.517	6856
653.775	6942
654.034	6986
654.292	7096
654.55	7074
654.809	7104
655.067	7202
655.326	7260
655.584	7340
655.842	7484
656.1	7454
656.359	7572
656.617	7596
656.875	7718
657.134	7720
657.392	7768
657.65	7862
657.908	7900
658.166	7978
658.425	7956
658.683	8030
658.941	8086
659.199	8100
659.457	8052
659.715	8108
659.973	8146
660.231	8138
660.49	8100
660.748	8068
661.006	8028
661.264	8126
661.522	8112
661.78	8052
662.038	7996
662.296	8188
662.554	8138
662.811	7940
663.069	8096
663.327	8130
663.585	8072
663.843	8129.11
664.101	8163.83
664.359	8107.27
664.617	8151.94
664.874	8156.69
665.132	8104.57
665.39	8081.68
665.648	8192.47
665.906	8179.59
666.163	8162.61
666.421	8075.16
666.679	8135.54
666.937	8133.79
667.194	8143.37
667.452	8187.6
667.71	8090.52
667.967	8135.41
668.225	8124.26
668.482	8223.12
668.74	8133.76
668.987	8164
669.245	8212
669.504	8142
669.763	8158
670.022	8080
670.281	8066
670.539	8120
670.798	8186
671.057	8088
671.316	8230
671.575	8186
671.833	8184
672.092	8192
672.351	8294
672.609	8208
672.868	8266
673.127	8306
673.385	8326
673.644	8316
673.903	8360
674.161	8396
674.42	8418
674.678	8480
674.937	8552
675.195	8620
675.454	8720
675.713	8576
675.971	8650
676.23	8662
676.488	8660
676.747	8692
677.005	8726
677.263	8694
677.522	8724
677.78	8648
678.039	8758
678.297	8692
678.556	8632
678.814	8734
679.072	8472
679.331	8564
679.589	8740
679.847	8684
680.106	8718
680.364	8742
680.622	8780
680.881	8714
681.139	8804
681.397	8818
681.656	8868
681.914	8832
682.172	8904
682.43	8916
682.688	8816
682.947	8910
683.205	8922
683.463	8802
683.721	8900
683.979	8844
684.237	8850
684.495	8830
684.754	8826
685.012	8764
685.27	8786
685.528	8690
685.786	8672
686.044	8790
686.302	8724
686.56	8706
686.818	8730
687.076	8684
687.334	8666
687.592	8734
687.85	8680
688.108	8576
688.366	8698
688.623	8600
688.881	8556
689.139	8608
689.397	8616
689.655	8562
689.913	8674
690.171	8564
690.428	8512
690.686	8458
690.944	8492
691.202	8530
691.459	8390
691.717	8408
691.975	8444
692.233	8324
692.49	8310
692.748	8302
693.006	8308
693.263	8272
693.521	8244
693.779	8240
694.036	8228
694.294	8232
694.552	8170
694.809	8106
695.067	8118
695.324	8194
695.582	8162
695.839	8096
696.097	8106
696.354	8044
696.612	8022
696.869	8108
697.127	7890
697.384	7974
697.642	7916
697.899	7860
698.156	7812
698.414	7810
698.671	7682
698.928	7708
699.186	7742
699.443	7680
699.7	7688
699.958	7644
700.215	7632
700.472	7724
700.73	7574
700.987	7634
701.244	7622
701.501	7600
701.758	7660
702.016	7616
702.273	7546
702.53	7660
702.787	7684
703.044	7676
703.301	7594
703.558	7636
703.816	7566
704.073	7524
704.33	7492
704.587	7438
704.844	7500
705.101	7402
705.358	7372
705.615	7386
705.872	7274
706.129	7332
706.386	7262
706.643	7156
706.899	7208
707.156	7052
707.413	7096
707.67	7066
707.927	7062
708.184	7120
708.441	7078
708.697	7036
708.954	7056
709.211	7006
709.468	6916
709.725	6904
709.981	6956
710.238	6906
710.495	6938
710.751	6840
711.008	6812
711.265	6834.76
711.521	6840.68
711.778	6769.99
712.035	6826.12
712.291	6765.33
712.548	6682.94
712.804	6663.21
713.061	6617.21
713.317	6576.31
713.574	6564.51
713.831	6479.77
714.087	6450.29
714.343	6448.94
714.6	6451.6
714.856	6394.12
715.113	6396.86
715.369	6326.32
715.626	6328.23
715.882	6221.65
716.138	6291.42
716.395	6281.31
716.639	6180
716.897	6182
717.155	6162
717.412	6122
717.67	6132
717.927	6086
718.185	6030
718.443	6094
718.7	6010
718.958	6036
719.215	5984
719.473	5906
719.73	5876
719.988	5890
720.245	5764
720.503	5796
720.76	5800
721.018	5720
721.275	5610
721.532	5616
721.79	5688
722.047	5580
722.305	5538
722.562	5578
722.819	5596
723.077	5454
723.334	5410
723.591	5394
723.849	5406
724.106	5282
724.363	5268
724.621	5272
724.878	5306
725.135	5266
725.392	5232
725.65	5206
725.907	5200
726.164	5220
726.421	5190
726.678	5146
726.935	5128
727.193	5122
727.45	5002
727.707	4936
727.964	4980
728.221	4940
728.478	4892
728.735	4808
728.992	4884
729.249	4746
729.506	4738
729.763	4670
730.02	4660
730.277	4650
730.534	4640
730.791	4644
731.048	4588
731.305	4528
731.562	4520
731.819	4488
732.076	4494
732.333	4476
732.589	4460
732.846	4390
733.103	4462
733.36	4340
733.617	4372
733.873	4378
734.13	4374
734.387	4296
734.644	4246
734.901	4238
735.157	4314
735.414	4288
735.671	4226
735.927	4182
736.184	4268
736.441	4192
736.697	4236
736.954	4196
737.211	4172
737.467	4158
737.724	4138
737.98	4126
738.237	4100
738.493	4116
738.75	4114
739.006	4040
739.263	4036
739.519	4004
739.776	4074
740.032	4000
740.289	4002
740.545	3990
740.802	3980
741.058	3938
741.314	3928
741.571	3940
741.827	3876
742.083	3858
742.34	3890
742.596	3824
742.852	3804
743.109	3816
743.365	3760
743.621	3734
743.878	3700
744.134	3704
744.39	3708
744.646	3654
744.902	3632
745.159	3660
745.415	3564
745.671	3598
745.927	3578
746.183	3588
746.439	3570
746.695	3558
746.951	3504
747.207	3484
747.463	3524
747.719	3506
747.975	3432
748.231	3490
748.487	3474
748.743	3420
748.999	3390
749.255	3362
749.511	3352
749.767	3362
750.023	3384
750.279	3326
750.535	3336
750.791	3270
751.046	3270
751.302	3284
751.558	3220
751.814	3172
752.07	3194
752.325	3126
752.581	3184
752.837	3138
753.092	3122
753.348	3112
753.604	3104
753.859	3050
754.115	3052
754.371	3044
754.626	2994
754.882	3006
755.138	2984
755.393	2906
755.649	2908
755.904	2926
756.16	2874
756.415	2840
756.671	2886
756.926	2878
757.182	2824
757.437	2836
757.693	2778
757.948	2832
758.203	2798
758.459	2786
758.714	2786.33
758.97	2780.14
759.225	2716.41
759.48	2693.61
759.736	2707.14
759.991	2720.62
760.246	2651.46
760.501	2640.26
760.757	2592.24
761.012	2607.4
761.267	2603.04
761.522	2557.14
761.777	2572.54
762.033	2573.04
762.288	2573.76
762.543	2549.83
762.798	2506.06
763.053	2474.59
763.308	2468.65
763.563	2479.97
763.78	2436
764.037	2414
764.293	2476
764.55	2420
764.806	2362
765.062	2332
765.319	2386
765.575	2324
765.831	2310
766.088	2274
766.344	2322
766.6	2292
766.857	2310
767.113	2274
767.369	2274
767.625	2154
767.882	2220
768.138	2216
768.394	2152
768.65	2138
768.906	2086
769.163	2126
769.419	2094
769.675	2130
769.931	2126
770.187	2082
770.443	2072
770.699	2048
770.955	2044
771.211	2040
771.467	2046
771.723	1936
771.979	1966
772.235	2002
772.491	2004
772.747	1986
773.003	1908
773.259	1924
773.515	1880
773.771	1926
774.027	1820
774.283	1906
774.539	1854
774.795	1850
775.05	1838
775.306	1796
775.562	1788
775.818	1740
776.074	1750
776.329	1746
776.585	1762
776.841	1748
777.097	1726
777.352	1758
777.608	1672
777.864	1724
778.12	1636
778.375	1608
778.631	1658
778.886	1594
779.142	1674
779.398	1630
779.653	1600
779.909	1594
780.164	1602
780.42	1538
780.675	1548
780.931	1550
781.187	1510
781.442	1514
781.698	1464
781.953	1502
782.208	1474
782.464	1468
782.719	1446
782.975	1450
783.23	1418
783.485	1440
783.741	1428
783.996	1394
784.252	1380
784.507	1402
784.762	1362
785.017	1354
785.273	1386
785.528	1350
785.783	1332
786.038	1352
786.294	1326
786.549	1284
786.804	1312
787.059	1292
787.314	1254
787.57	1310
787.825	1242
788.08	1274
788.335	1178
788.59	1222
788.845	1240
789.1	1194
789.355	1170
789.61	1194
789.865	1174
790.12	1134
790.375	1152
790.63	1138
790.885	1138
791.14	1106
791.395	1150
791.65	1092
791.905	1126
792.16	1068
792.414	1086
792.669	1068
792.924	1096
793.179	1044
793.434	1086
793.689	1054
793.943	1056
794.198	1036
794.453	1042
794.708	1022
794.962	1018
795.217	1020
795.472	1026
795.726	996
795.981	1006
796.236	954
796.49	996
796.745	958
796.999	962
797.254	964
797.508	930
797.763	950
798.018	916
798.272	906
798.526	890
798.781	922
799.035	886
799.29	858
799.544	898
799.799	874
800.053	884
800.307	890
800.562	862
800.816	856
801.07	820
801.325	816
801.579	794
801.833	826
802.088	804
802.342	800
802.596	788
802.85	818
803.105	772
803.359	776
803.613	768
803.867	778
804.121	788
804.375	780
804.63	736
804.884	746
805.138	746
805.392	736
805.646	695.217
805.9	759.253
806.154	714.152
806.408	700.258
806.662	715.386
806.916	699.294
807.17	701.49
807.424	682.672
807.678	695.92
807.931	673.734
808.185	685.928
808.439	683.385
808.693	662.271
808.947	673.727
809.201	662.455
809.454	651.886
809.708	659.459
809.962	627.464
810.216	634.581
810.469	635.225
810.678	604
810.933	612
811.188	628
811.443	620
811.699	606
811.954	606
812.209	590
812.464	590
812.719	592
812.974	580
813.229	584
813.484	562
813.739	588
813.994	578
814.249	582
814.504	536
814.759	546
815.014	564
815.268	550
815.523	538
815.778	542
816.033	556
816.288	522
816.543	520
816.798	548
817.052	522
817.307	530
817.562	516
817.817	508
818.071	520
818.326	524
818.581	500
818.836	502
819.09	506
819.345	506
819.6	480
819.854	482
820.109	486
820.364	490
820.618	472
820.873	470
821.127	470
821.382	464
821.637	452
821.891	476
822.146	442
822.4	464
822.655	436
822.909	438
823.164	454
823.418	436
823.672	420
823.927	432
824.181	432
824.436	414
824.69	436
824.944	410
825.199	412
825.453	396
825.707	414
825.962	416
826.216	392
826.47	404
826.725	410
826.979	384
827.233	410
827.487	392
827.741	410
827.996	384
828.25	404
828.504	382
828.758	392
829.012	370
829.266	372
829.52	394
829.774	362
830.029	374
830.283	366
830.537	374
830.791	366
831.045	374
831.299	348
831.553	342
831.807	356
832.061	362
832.315	330
832.568	348
832.822	362
833.076	332
833.33	332
833.584	326
833.838	326
834.092	340
834.345	334
834.599	336
834.853	332
835.107	312
835.36	332
835.614	324
835.868	322
836.122	332
836.375	334
836.629	308
836.883	300
837.136	310
837.39	306
837.643	316
837.897	298
838.151	296
838.404	304
838.658	306
838.911	288
839.165	304
839.418	308
839.672	286
839.925	280
840.179	280
840.432	272
840.686	288
840.939	280
841.192	288
841.446	262
841.699	280
841.952	286
842.206	272
842.459	270
842.712	278
842.966	254
843.219	268
843.472	250
843.725	276
843.979	276
844.232	252
844.485	260
844.738	264
844.991	260
845.244	258
845.497	252
845.75	260
846.004	248
846.257	260
846.51	254
846.763	242
847.016	242
847.269	258
847.522	244
847.775	226
848.028	232
848.281	244
848.534	222
848.786	228
849.039	248
849.292	232
849.545	224
849.798	216
850.051	222
850.303	220
850.556	226
850.809	230
851.062	242
851.314	224
851.567	212
851.82	214
852.073	222
852.325	208.032
852.578	223.011
852.831	210.178
853.083	225.02
853.336	205.436
853.588	211.927
853.841	217.931
854.093	202.246
854.346	198.998
854.598	204.095
854.851	213.951
855.103	211.838
855.356	202.66
855.608	193.779
855.861	196.786
856.113	192.337
856.366	196.863
856.618	189.48
856.87	186.86
857.123	199.251
857.352	198
857.606	186
857.859	198
858.113	192
858.367	182
858.621	180
858.875	184
859.128	176
859.382	164
859.636	196
859.889	180
860.143	182
860.397	192
860.65	186
860.904	178
861.158	170
861.411	182
861.665	180
861.918	184
862.172	166
862.425	182
862.679	174
862.932	176
863.186	160
863.439	180
863.693	176
863.946	152
864.2	158
864.453	160
864.707	158
864.96	164
865.213	170
865.467	162
865.72	158
865.973	162
866.227	152
866.48	168
866.733	164
866.987	160
867.24	158
867.493	152
867.746	156
867.999	164
868.253	158
868.506	144
868.759	156
869.012	160
869.265	160
869.518	160
869.771	144
870.025	140
870.278	138
870.531	156
870.784	152
871.037	144
871.29	146
871.543	146
871.796	148
872.049	140
872.302	148
872.555	140
872.808	124
873.06	142
873.313	132
873.566	136
873.819	132
874.072	138
874.325	130
874.578	136
874.83	132
875.083	130
875.336	136
875.589	132
875.841	120
876.094	132
876.347	136
876.6	122
876.852	142
877.105	128
877.358	130
877.61	118
877.863	134
878.115	140
878.368	126
878.621	116
878.873	112
879.126	122
879.378	120
879.631	134
879.883	120
880.136	120
880.388	116
880.641	116
880.893	102
881.145	114
881.398	124
881.65	128
881.902	122
882.155	108
882.407	126
882.659	126
882.912	108
883.164	110
883.416	116
883.669	116
883.921	104
884.173	112
884.425	112
884.677	110
884.93	100
885.182	110
885.434	112
885.686	106
885.938	106
886.19	94
886.442	106
886.694	104
886.946	106
887.198	108
887.45	106
887.702	106
887.954	110
888.206	94
888.458	94
888.71	110
888.962	108
889.214	102
889.466	100
889.718	104
889.969	110
890.221	94
890.473	100
890.725	96
890.977	96
891.228	92
891.48	92
891.732	92
891.983	92
892.235	96
892.487	100
892.738	94
892.99	88
893.242	86
893.493	90
893.745	86
893.996	88
894.248	94
894.5	86
894.751	80
895.003	92
895.254	90
895.505	86
895.757	84
896.008	94
896.26	94
896.511	80
896.763	92
897.014	90
897.265	86
897.517	72
897.768	78
898.019	100
898.27	72
898.522	86
898.773	84
899.024	74
899.275	68
899.527	92
899.778	84
899.979	78