File: MS_091025_03.txt
#Acq. time (s)=	5
#Accumulations=	2
#Range (nm)=	520...900
#Windows=	8
#Auto scanning=	Off
#Autofocus=	Off
#AutoExposure=	Off
#Spike filter=	Multiple accum.
#Delay time (s)=	0
#Binning=	1
#Readout mode=	Signal
#DeNoise=	Off
#ICS correction=	Off
#Dark correction=	Off
#Inst. Process=	Off
#Detector temperature (°C)=	-59.98
#Instrument=	LabRAM HR Evol
#Detector=	Syncerity OE
#Objective=	x50_VIS
#Grating=	600 (500nm)
#ND Filter=	10%
#Laser=	514nm_Edge
#Hole=	199.981
#Range=	Auto
#StageXY=	Marzhauser
#StageZ=	Marzhauser
#X (µm)=	-19162.1
#Y (µm)=	12273.3
#Z (µm)=	-106.8
#Full time(mm:ss)=	2:04
#Project=
#Sample=
#Site=
#Title=	MS_091025
#Remark=
#Date=	13.10.2023 16:36
#Acquired=	13.10.2023 16:36:24
520.044	40
520.306	42
520.569	44
520.831	38
521.093	44
521.355	50
521.617	48
521.88	40
522.142	46
522.404	48
522.666	40
522.928	36
523.19	50
523.453	50
523.715	34
523.977	38
524.239	52
524.501	38
524.763	44
525.025	50
525.287	56
525.549	42
525.811	52
526.073	40
526.335	50
526.597	48
526.859	60
527.121	52
527.383	52
527.645	56
527.907	54
528.169	50
528.431	54
528.693	58
528.955	64
529.217	38
529.479	58
529.741	50
530.003	52
530.264	48
530.526	62
530.788	52
531.05	48
531.312	60
531.574	58
531.835	58
532.097	52
532.359	64
532.621	72
532.883	58
533.144	52
533.406	54
533.668	68
533.93	54
534.191	76
534.453	72
534.715	74
534.976	68
535.238	72
535.5	70
535.761	68
536.023	74
536.285	70
536.546	58
536.808	60
537.069	60
537.331	82
537.593	74
537.854	78
538.116	80
538.377	72
538.639	72
538.9	80
539.162	78
539.423	72
539.685	76
539.946	84
540.208	86
540.469	76
540.731	84
540.992	86
541.254	78
541.515	96
541.776	92
542.038	86
542.299	76
542.56	92
542.822	82
543.083	104
543.344	108
543.606	104
543.867	106
544.128	102
544.39	106
544.651	106
544.912	102
545.174	106
545.435	108
545.696	122
545.957	112
546.218	112
546.48	116
546.741	128
547.002	122
547.263	144
547.524	146
547.785	134
548.047	134
548.308	146
548.569	146
548.83	132
549.091	154
549.352	160
549.613	152
549.874	154
550.135	160
550.396	176
550.657	162
550.918	194
551.179	202
551.44	186
551.701	212
551.962	292
552.223	592
552.484	12544
552.745	928
553.006	312
553.267	252
553.528	232
553.788	218
554.049	230
554.31	234
554.571	234
554.832	232
555.093	226
555.353	246
555.614	262
555.875	248
556.136	262
556.396	268
556.657	256
556.918	264
557.179	260
557.439	292
557.7	288
557.961	290
558.221	318
558.482	300
558.743	310
559.003	310
559.264	300
559.525	322
559.785	322
560.046	314
560.306	324
560.567	358
560.827	340
561.088	372
561.348	374
561.609	390
561.869	372
562.13	394
562.39	402
562.651	386
562.911	402
563.172	438
563.432	436
563.692	434
563.953	468
564.213	468
564.474	464
564.734	472
564.994	482
565.255	482
565.515	484
565.775	506
566.035	514
566.296	528
566.556	554
566.816	572
567.076	540
567.337	552
567.597	566
567.857	568
568.117	604.12
568.377	618.493
568.637	610.525
568.898	644.923
569.158	651.489
569.418	670.994
569.678	687.23
569.938	717.376
570.198	700.151
570.458	742.82
570.718	768.855
570.978	808.855
571.238	857.077
571.498	886.514
571.758	924.692
572.018	983.213
572.278	1031.8
572.538	1092.49
572.798	1151.81
573.058	1180.56
573.312	1298
573.573	1414
573.834	1486
574.095	1610
574.356	1740
574.617	1878
574.878	2020
575.139	2138
575.4	2200
575.661	2326
575.922	2232
576.183	2214
576.444	2248
576.705	2098
576.965	2016
577.226	1858
577.487	1770
577.748	1770
578.009	1670
578.27	1594
578.531	1532
578.791	1532
579.052	1488
579.313	1496
579.574	1482
579.835	1516
580.095	1476
580.356	1500
580.617	1534
580.878	1482
581.138	1476
581.399	1526
581.66	1596
581.92	1506
582.181	1568
582.442	1576
582.703	1608
582.963	1640
583.224	1642
583.484	1648
583.745	1648
584.006	1712
584.266	1772
584.527	1762
584.787	1802
585.048	1804
585.308	1818
585.569	1918
585.83	1876
586.09	1888
586.351	1958
586.611	1986
586.872	2060
587.132	2028
587.392	2032
587.653	2064
587.913	2010
588.174	2064
588.434	2040
588.695	2044
588.955	2076
589.215	2096
589.476	2172
589.736	2096
589.996	2102
590.257	2128
590.517	2090
590.777	2108
591.038	2140
591.298	2058
591.558	2136
591.818	2086
592.079	2124
592.339	2068
592.599	2096
592.859	2086
593.12	2132
593.38	2084
593.64	2108
593.9	2148
594.16	2092
594.42	2118
594.68	2178
594.941	2202
595.201	2238
595.461	2234
595.721	2256
595.981	2314
596.241	2320
596.501	2358
596.761	2404
597.021	2380
597.281	2458
597.541	2366
597.801	2422
598.061	2372
598.321	2432
598.581	2424
598.841	2414
599.101	2480
599.361	2436
599.62	2394
599.88	2484
600.14	2452
600.4	2478
600.66	2506
600.92	2460
601.18	2472
601.439	2464
601.699	2438
601.959	2476
602.219	2526
602.478	2518
602.738	2566
602.998	2520
603.258	2480
603.517	2586
603.777	2546
604.037	2562
604.296	2606
604.556	2584
604.816	2586
605.075	2630
605.335	2602
605.594	2620
605.854	2604
606.114	2624
606.373	2654
606.633	2632
606.892	2630
607.152	2620
607.411	2610
607.671	2588
607.93	2692
608.19	2698
608.449	2696
608.709	2690
608.968	2706
609.228	2744
609.487	2744
609.746	2744
610.006	2736
610.265	2800
610.524	2792
610.784	2866
611.043	2846
611.302	2818
611.562	2810
611.821	2880
612.08	2878
612.339	2926
612.599	2990
612.858	2862
613.117	2956
613.376	2988
613.635	3008
613.895	3002
614.154	3072
614.413	3100
614.672	3110
614.931	3154
615.19	3204
615.449	3162
615.709	3218
615.968	3186
616.227	3266.72
616.486	3243.39
616.745	3288.75
617.004	3298.11
617.263	3272.72
617.522	3278.53
617.781	3350.46
618.04	3388.86
618.299	3410.14
618.557	3425.92
618.816	3471.88
619.075	3466.15
619.334	3453.72
619.593	3460.79
619.852	3442.57
620.111	3512.62
620.37	3499.98
620.628	3531.39
620.887	3577.55
621.146	3520.83
621.373	3556
621.633	3500
621.893	3552
622.153	3610
622.413	3552
622.673	3622
622.932	3610
623.192	3618
623.452	3636
623.712	3602
623.972	3694
624.232	3676
624.492	3626
624.751	3680
625.011	3680
625.271	3766
625.531	3780
625.791	3802
626.05	3774
626.31	3734
626.57	3864
626.83	3856
627.089	3830
627.349	3880
627.609	3882
627.868	3942
628.128	3972
628.388	3986
628.647	3990
628.907	4044
629.167	3980
629.426	4046
629.686	4068
629.945	4110
630.205	4182
630.465	4108
630.724	4154
630.984	4188
631.243	4204
631.503	4150
631.762	4310
632.022	4328
632.281	4278
632.541	4332
632.8	4360
633.06	4456
633.319	4364
633.579	4460
633.838	4558
634.097	4502
634.357	4606
634.616	4714
634.876	4762
635.135	4848
635.394	4824
635.654	5018
635.913	5102
636.172	5256
636.431	5412
636.691	5618
636.95	5804
637.209	5954
637.469	6330
637.728	6452
637.987	6538
638.246	6602
638.505	6602
638.765	6510
639.024	6272
639.283	6202
639.542	6136
639.801	5960
640.06	5890
640.319	5848
640.578	5706
640.838	5614
641.097	5648
641.356	5676
641.615	5560
641.874	5616
642.133	5634
642.392	5616
642.651	5570
642.91	5602
643.169	5576
643.428	5594
643.687	5638
643.946	5626
644.205	5672
644.463	5648
644.722	5752
644.981	5754
645.24	5844
645.499	5802
645.758	5830
646.017	5858
646.275	5910
646.534	5832
646.793	5898
647.052	5952
647.31	5910
647.569	5970
647.828	6102
648.087	5960
648.345	6056
648.604	6106
648.863	6110
649.121	6154
649.38	6130
649.639	6194
649.897	6336
650.156	6344
650.415	6344
650.673	6414
650.932	6376
651.19	6462
651.449	6424
651.707	6400
651.966	6546
652.224	6532
652.483	6646
652.741	6692
653	6796
653.258	6682
653.517	6802
653.775	6906
654.034	6902
654.292	6984
654.55	7028
654.809	7008
655.067	7196
655.326	7220
655.584	7270
655.842	7350
656.1	7436
656.359	7558
656.617	7650
656.875	7642
657.134	7808
657.392	7808
657.65	7880
657.908	7888
658.166	7934
658.425	7916
658.683	8018
658.941	8004
659.199	8054
659.457	8142
659.715	8052
659.973	7920
660.231	8028
660.49	8136
660.748	8088
661.006	8128
661.264	8122
661.522	8146
661.78	8078
662.038	8152
662.296	8150
662.554	8040
662.811	8080
663.069	8120
663.327	8192
663.585	8084
663.843	8057.29
664.101	8108.66
664.359	8065.37
664.617	8090.02
664.874	8180.07
665.132	8163.83
665.39	8177.8
665.648	8102.2
665.906	8084.7
666.163	8135.75
666.421	8057.08
666.679	8116.42
666.937	8083.6
667.194	8101.98
667.452	8113.47
667.71	8133.08
667.967	8144.14
668.225	8146.29
668.482	8089.69
668.74	8091.01
668.987	8100
669.245	8104
669.504	8130
669.763	8158
670.022	8064
670.281	8118
670.539	8110
670.798	8106
671.057	8144
671.316	8200
671.575	8162
671.833	8112
672.092	8246
672.351	8068
672.609	8192
672.868	8192
673.127	8226
673.385	8350
673.644	8266
673.903	8362
674.161	8368
674.42	8304
674.678	8408
674.937	8500
675.195	8560
675.454	8568
675.713	8530
675.971	8556
676.23	8566
676.488	8586
676.747	8546
677.005	8630
677.263	8544
677.522	8548
677.78	8582
678.039	8690
678.297	8516
678.556	8612
678.814	8570
679.072	8546
679.331	8548
679.589	8570
679.847	8658
680.106	8624
680.364	8684
680.622	8754
680.881	8632
681.139	8704
681.397	8690
681.656	8740
681.914	8840
682.172	8808
682.43	8778
682.688	8796
682.947	8896
683.205	8832
683.463	8858
683.721	8844
683.979	8846
684.237	8742
684.495	8734
684.754	8770
685.012	8670
685.27	8780
685.528	8724
685.786	8630
686.044	8620
686.302	8530
686.56	8588
686.818	8520
687.076	8592
687.334	8688
687.592	8656
687.85	8608
688.108	8584
688.366	8538
688.623	8552
688.881	8568
689.139	8516
689.397	8442
689.655	8442
689.913	8518
690.171	8538
690.428	8436
690.686	8410
690.944	8412
691.202	8400
691.459	8360
691.717	8328
691.975	8322
692.233	8288
692.49	8260
692.748	8178
693.006	8186
693.263	8190
693.521	8170
693.779	8238
694.036	8134
694.294	8132
694.552	8156
694.809	8104
695.067	8016
695.324	8052
695.582	8092
695.839	7896
696.097	8080
696.354	7970
696.612	7962
696.869	7968
697.127	7812
697.384	7802
697.642	7792
697.899	7744
698.156	7860
698.414	7768
698.671	7698
698.928	7750
699.186	7720
699.443	7640
699.7	7630
699.958	7588
700.215	7536
700.472	7602
700.73	7558
700.987	7448
701.244	7540
701.501	7576
701.758	7520
702.016	7568
702.273	7544
702.53	7572
702.787	7414
703.044	7596
703.301	7514
703.558	7586
703.816	7504
704.073	7466
704.33	7434
704.587	7472
704.844	7408
705.101	7348
705.358	7306
705.615	7296
705.872	7326
706.129	7160
706.386	7152
706.643	7102
706.899	7108
707.156	7096
707.413	6996
707.67	7070
707.927	6944
708.184	6950
708.441	6876
708.697	6936
708.954	7002
709.211	6960
709.468	6840
709.725	6848
709.981	6914
710.238	6896
710.495	6870
710.751	6840
711.008	6802
711.265	6831.83
711.521	6737.39
711.778	6725.48
712.035	6593.04
712.291	6629.73
712.548	6688.29
712.804	6632.71
713.061	6506.58
713.317	6471.73
713.574	6480.82
713.831	6415.83
714.087	6381.49
714.343	6381.69
714.6	6301.43
714.856	6338.73
715.113	6253.71
715.369	6250.93
715.626	6269.96
715.882	6164.96
716.138	6132.9
716.395	6147.3
716.639	6052
716.897	6074
717.155	6084
717.412	5990
717.67	5928
717.927	6010
718.185	5920
718.443	5912
718.7	5918
718.958	5952
719.215	5864
719.473	5828
719.73	5784
719.988	5746
720.245	5696
720.503	5662
720.76	5574
721.018	5664
721.275	5608
721.532	5562
721.79	5560
722.047	5560
722.305	5440
722.562	5346
722.819	5462
723.077	5388
723.334	5322
723.591	5378
723.849	5258
724.106	5294
724.363	5304
724.621	5288
724.878	5260
725.135	5152
725.392	5258
725.65	5186
725.907	5178
726.164	5100
726.421	5016
726.678	5082
726.935	5038
727.193	4966
727.45	5004
727.707	4920
727.964	4860
728.221	4870
728.478	4812
728.735	4820
728.992	4756
729.249	4724
729.506	4718
729.763	4582
730.02	4706
730.277	4522
730.534	4596
730.791	4580
731.048	4520
731.305	4478
731.562	4416
731.819	4406
732.076	4410
732.333	4388
732.589	4444
732.846	4422
733.103	4392
733.36	4410
733.617	4376
733.873	4382
734.13	4322
734.387	4342
734.644	4350
734.901	4334
735.157	4288
735.414	4328
735.671	4242
735.927	4302
736.184	4214
736.441	4256
736.697	4250
736.954	4272
737.211	4286
737.467	4254
737.724	4314
737.98	4316
738.237	4298
738.493	4266
738.75	4228
739.006	4266
739.263	4228
739.519	4176
739.776	4154
740.032	4164
740.289	4112
740.545	4050
740.802	3926
741.058	3968
741.314	3966
741.571	3896
741.827	3938
742.083	3876
742.34	3868
742.596	3890
742.852	3802
743.109	3772
743.365	3736
743.621	3742
743.878	3662
744.134	3690
744.39	3742
744.646	3650
744.902	3650
745.159	3594
745.415	3666
745.671	3568
745.927	3604
746.183	3582
746.439	3520
746.695	3482
746.951	3586
747.207	3468
747.463	3382
747.719	3468
747.975	3460
748.231	3460
748.487	3380
748.743	3468
748.999	3370
749.255	3332
749.511	3382
749.767	3390
750.023	3268
750.279	3302
750.535	3320
750.791	3274
751.046	3286
751.302	3294
751.558	3188
751.814	3196
752.07	3156
752.325	3134
752.581	3126
752.837	3128
753.092	3036
753.348	3062
753.604	3042
753.859	3064
754.115	2986
754.371	3040
754.626	2980
754.882	2982
755.138	2996
755.393	2902
755.649	2890
755.904	2892
756.16	2878
756.415	2858
756.671	2882
756.926	2844
757.182	2854
757.437	2816
757.693	2788
757.948	2714
758.203	2784
758.459	2778
758.714	2721.23
758.97	2727.56
759.225	2731.92
759.48	2662.11
759.736	2607.26
759.991	2647.02
760.246	2612.93
760.501	2637.1
760.757	2564.73
761.012	2589.15
761.267	2592.79
761.522	2581.6
761.777	2556.47
762.033	2549.55
762.288	2525.36
762.543	2500.79
762.798	2471.89
763.053	2499.61
763.308	2423.49
763.563	2466.16
763.78	2390
764.037	2400
764.293	2392
764.55	2394
764.806	2352
765.062	2372
765.319	2386
765.575	2352
765.831	2360
766.088	2302
766.344	2260
766.6	2248
766.857	2282
767.113	2272
767.369	2234
767.625	2166
767.882	2184
768.138	2214
768.394	2180
768.65	2128
768.906	2146
769.163	2148
769.419	2078
769.675	2118
769.931	2084
770.187	2076
770.443	2088
770.699	2018
770.955	1994
771.211	2022
771.467	2018
771.723	1976
771.979	2004
772.235	1978
772.491	1940
772.747	1940
773.003	1876
773.259	1886
773.515	1860
773.771	1802
774.027	1826
774.283	1820
774.539	1806
774.795	1764
775.05	1800
775.306	1732
775.562	1778
775.818	1728
776.074	1754
776.329	1730
776.585	1732
776.841	1700
777.097	1684
777.352	1668
777.608	1626
777.864	1682
778.12	1644
778.375	1692
778.631	1586
778.886	1602
779.142	1616
779.398	1562
779.653	1526
779.909	1540
780.164	1580
780.42	1536
780.675	1534
780.931	1528
781.187	1516
781.442	1478
781.698	1522
781.953	1464
782.208	1458
782.464	1460
782.719	1444
782.975	1418
783.23	1412
783.485	1414
783.741	1376
783.996	1430
784.252	1368
784.507	1344
784.762	1334
785.017	1350
785.273	1340
785.528	1316
785.783	1306
786.038	1324
786.294	1268
786.549	1254
786.804	1226
787.059	1238
787.314	1236
787.57	1274
787.825	1222
788.08	1228
788.335	1214
788.59	1182
788.845	1200
789.1	1202
789.355	1168
789.61	1146
789.865	1156
790.12	1136
790.375	1166
790.63	1130
790.885	1132
791.14	1142
791.395	1120
791.65	1114
791.905	1094
792.16	1102
792.414	1088
792.669	1080
792.924	1064
793.179	1048
793.434	1062
793.689	1032
793.943	1066
794.198	1008
794.453	1012
794.708	1000
794.962	1012
795.217	1004
795.472	966
795.726	996
795.981	970
796.236	966
796.49	938
796.745	930
796.999	930
797.254	940
797.508	930
797.763	914
798.018	956
798.272	874
798.526	886
798.781	902
799.035	868
799.29	864
799.544	866
799.799	878
800.053	822
800.307	850
800.562	838
800.816	818
801.07	832
801.325	796
801.579	790
801.833	808
802.088	790
802.342	796
802.596	762
802.85	776
803.105	754
803.359	768
803.613	758
803.867	750
804.121	768
804.375	742
804.63	750
804.884	714
805.138	746
805.392	720
805.646	731.111
805.9	698.339
806.154	676.349
806.408	697.99
806.662	704.006
806.916	691.386
807.17	672
807.424	673.178
807.678	687.845
807.931	680.992
808.185	663.902
808.439	666.231
808.693	658.878
808.947	648.677
809.201	639.07
809.454	640.681
809.708	637.596
809.962	625.886
810.216	639.366
810.469	622.243
810.678	626
810.933	616
811.188	614
811.443	594
811.699	618
811.954	600
812.209	572
812.464	612
812.719	580
812.974	560
813.229	598
813.484	540
813.739	562
813.994	550
814.249	572
814.504	528
814.759	548
815.014	556
815.268	578
815.523	528
815.778	512
816.033	540
816.288	526
816.543	512
816.798	524
817.052	540
817.307	528
817.562	510
817.817	520
818.071	490
818.326	498
818.581	506
818.836	520
819.09	492
819.345	480
819.6	482
819.854	458
820.109	484
820.364	470
820.618	470
820.873	464
821.127	464
821.382	472
821.637	444
821.891	436
822.146	430
822.4	468
822.655	462
822.909	468
823.164	414
823.418	432
823.672	434
823.927	428
824.181	416
824.436	420
824.69	420
824.944	432
825.199	410
825.453	398
825.707	414
825.962	416
826.216	406
826.47	396
826.725	384
826.979	386
827.233	384
827.487	386
827.741	378
827.996	398
828.25	398
828.504	386
828.758	374
829.012	388
829.266	374
829.52	370
829.774	378
830.029	358
830.283	350
830.537	378
830.791	354
831.045	346
831.299	356
831.553	342
831.807	364
832.061	342
832.315	360
832.568	342
832.822	340
833.076	348
833.33	326
833.584	324
833.838	330
834.092	314
834.345	326
834.599	328
834.853	318
835.107	324
835.36	322
835.614	308
835.868	320
836.122	300
836.375	318
836.629	324
836.883	306
837.136	300
837.39	320
837.643	306
837.897	302
838.151	306
838.404	284
838.658	306
838.911	282
839.165	278
839.418	306
839.672	284
839.925	290
840.179	288
840.432	290
840.686	288
840.939	260
841.192	280
841.446	280
841.699	254
841.952	260
842.206	270
842.459	276
842.712	274
842.966	268
843.219	254
843.472	280
843.725	256
843.979	268
844.232	254
844.485	250
844.738	252
844.991	244
845.244	254
845.497	252
845.75	268
846.004	250
846.257	224
846.51	228
846.763	250
847.016	260
847.269	236
847.522	242
847.775	230
848.028	214
848.281	222
848.534	242
848.786	246
849.039	224
849.292	220
849.545	234
849.798	220
850.051	232
850.303	208
850.556	224
850.809	218
851.062	226
851.314	224
851.567	218
851.82	210
852.073	224
852.325	222.01
852.578	225.342
852.831	224.498
853.083	215.137
853.336	202.872
853.588	207.976
853.841	206.51
854.093	208.098
854.346	194.743
854.598	210.682
854.851	206.503
855.103	192.397
855.356	195.803
855.608	194.337
855.861	190.746
856.113	191.913
856.366	189.933
856.618	186.19
856.87	185.165
857.123	202.831
857.352	204
857.606	184
857.859	190
858.113	186
858.367	186
858.621	194
858.875	182
859.128	188
859.382	170
859.636	184
859.889	170
860.143	202
860.397	176
860.65	168
860.904	172
861.158	176
861.411	190
861.665	182
861.918	170
862.172	162
862.425	178
862.679	154
862.932	176
863.186	156
863.439	164
863.693	172
863.946	160
864.2	152
864.453	166
864.707	174
864.96	160
865.213	152
865.467	168
865.72	156
865.973	150
866.227	164
866.48	168
866.733	160
866.987	164
867.24	152
867.493	158
867.746	152
867.999	158
868.253	142
868.506	150
868.759	140
869.012	156
869.265	148
869.518	158
869.771	138
870.025	158
870.278	136
870.531	142
870.784	138
871.037	144
871.29	128
871.543	150
871.796	144
872.049	146
872.302	134
872.555	132
872.808	142
873.06	138
873.313	142
873.566	136
873.819	136
874.072	130
874.325	140
874.578	130
874.83	126
875.083	128
875.336	132
875.589	142
875.841	124
876.094	128
876.347	130
876.6	126
876.852	120
877.105	136
877.358	134
877.61	128
877.863	130
878.115	134
878.368	138
878.621	128
878.873	110
879.126	126
879.378	114
879.631	122
879.883	114
880.136	120
880.388	114
880.641	110
880.893	118
881.145	120
881.398	108
881.65	120
881.902	114
882.155	114
882.407	120
882.659	118
882.912	104
883.164	114
883.416	116
883.669	108
883.921	114
884.173	108
884.425	126
884.677	104
884.93	114
885.182	116
885.434	114
885.686	110
885.938	98
886.19	110
886.442	98
886.694	108
886.946	94
887.198	98
887.45	104
887.702	102
887.954	104
888.206	98
888.458	94
888.71	92
888.962	102
889.214	96
889.466	92
889.718	96
889.969	100
890.221	102
890.473	88
890.725	106
890.977	94
891.228	92
891.48	94
891.732	98
891.983	100
892.235	96
892.487	92
892.738	82
892.99	98
893.242	92
893.493	86
893.745	96
893.996	90
894.248	88
894.5	96
894.751	94
895.003	88
895.254	88
895.505	88
895.757	80
896.008	82
896.26	80
896.511	86
896.763	86
897.014	74
897.265	86
897.517	80
897.768	78
898.019	70
898.27	80
898.522	78
898.773	74
899.024	82
899.275	76
899.527	86
899.778	86
899.979	82