File: PL_230124_Amostra_branca_sem_semente_HPHT_sem_polir_01.txt
#Acq. time (s)=	3
#Accumulations=	2
#Range (nm)=	520...900
#Windows=	16
#Auto scanning=	On
#Autofocus=	Off
#AutoExposure=	Off
#Spike filter=	Multiple accum.
#Delay time (s)=	0
#Binning=	1
#Readout mode=	Signal
#DeNoise=	Off
#ICS correction=	Off
#Dark correction=	Off
#Inst. Process=	Off
#Detector temperature (°C)=	-59.98
#Instrument=	LabRAM HR Evol
#Detector=	Syncerity OE
#Objective=	x50_VIS
#Grating=	600 (500nm)
#ND Filter=	10%
#Laser=	514nm_Edge
#Hole=	199.981
#Range=	Auto
#StageXY=	Marzhauser
#StageZ=	Marzhauser
#X (µm)=	-3464.9
#Y (µm)=	-1556.1
#Z (µm)=	307.6
#Full time(mm:ss)=	2:39
#Project=
#Sample=
#Site=
#Title=	PL_230124_Amostra_branca_sem_semente_HPHT_sem_polir
#Remark=
#Date=	31.01.2024 11:35
#Acquired=	31.01.2024 11:35:10
520.042	43
520.304	38.8463
520.565	40.8813
520.827	38.7907
521.089	38.0791
521.351	37.5372
521.612	36.4889
521.874	38.7835
522.136	36.2372
522.397	45.6403
522.659	40.7253
522.921	39.8533
523.182	42
523.444	41.8382
523.705	43.4692
523.967	42.5623
524.229	42.4098
524.49	46
524.752	48
525.013	39.681
525.275	38.4179
525.536	44
525.798	44.7427
526.059	47.2678
526.321	38.8347
526.582	42.8661
526.844	46.8951
527.105	45
527.367	45.2774
527.628	45.3403
527.889	45.3193
528.151	39.4033
528.412	46.4435
528.674	49.3974
528.935	43.7646
529.196	40.7855
529.458	39.8065
529.719	48.345
529.98	47.1492
530.242	40.6154
530.503	51.1049
530.764	44.2902
531.025	44.3427
531.287	44.9604
531.548	49.0629
531.809	47.4965
532.07	45.0466
532.332	50.4301
532.593	44.8648
532.854	46.2727
533.115	48.7855
533.376	45.5676
533.638	49.171
533.899	48.5039
534.16	43.9012
534.421	42.5198
534.682	50.9022
534.943	52.7735
535.204	54.5274
535.465	55.0148
535.726	57.9671
535.987	50.3174
536.248	53.7282
536.509	55.5303
536.77	53.4075
537.031	54.638
537.292	53.499
537.553	54.3345
537.814	56.6654
538.075	56.288
538.336	56.7585
538.597	54.7186
538.858	57.4666
539.119	57.1011
539.38	58.0541
539.641	59.4697
539.901	52.0431
540.162	55.1761
540.423	56.6007
540.684	59.3498
540.945	72.6818
541.205	58.1628
541.466	57.23
541.727	62.9261
541.988	64.5002
542.248	65.3891
542.509	59.3394
542.77	68.4748
543.031	62.8479
543.291	64.3867
543.552	78.1349
543.813	76.0046
544.073	67.1028
544.334	73.9794
544.594	70.1664
544.855	72.2407
545.116	73.8345
545.376	72.6569
545.637	73.2397
545.897	79.3148
546.158	85.5655
546.418	73.5573
546.679	76.5386
546.898	87.8833
547.159	85.9738
547.42	91.8264
547.681	97.2223
547.942	101.664
548.203	95.5474
548.464	93.828
548.725	88.695
548.987	92.4016
549.248	88.8748
549.509	111.188
549.77	106.581
550.031	105.488
550.292	115.068
550.553	113.195
550.814	122.54
551.075	121.293
551.336	126.99
551.597	129.627
551.858	163.711
552.119	237.692
552.38	1330
552.641	10818.1
552.901	368.229
553.162	189.369
553.423	161.211
553.684	143.588
553.945	146.21
554.206	131.236
554.467	147.916
554.727	144.102
554.988	145.781
555.249	142.607
555.51	148.058
555.771	146.547
556.031	158.861
556.292	151.816
556.553	146.557
556.814	159.474
557.074	153.158
557.335	161.697
557.596	167.303
557.856	171.787
558.117	169.174
558.378	166.885
558.638	165.169
558.899	178.534
559.16	188.168
559.42	183.338
559.681	185.42
559.941	194.628
560.202	206.492
560.463	188.868
560.723	204.244
560.984	205.481
561.244	211.099
561.505	211.625
561.765	208.589
562.026	226.153
562.286	219.139
562.547	214.404
562.807	224.392
563.067	231.958
563.328	233.957
563.588	252.096
563.849	243.566
564.109	242.699
564.369	250.394
564.63	257.226
564.89	264.995
565.15	263.1
565.411	273.039
565.671	271.66
565.931	280.356
566.192	287.648
566.452	291.201
566.712	299.291
566.972	311.989
567.232	308
567.493	322.374
567.753	313.799
568.013	329.607
568.273	333.403
568.533	339.448
568.794	340.197
569.054	343.875
569.314	348.714
569.574	352.271
569.834	355.925
570.094	380.928
570.354	384.614
570.614	399.44
570.874	398.481
571.134	427.792
571.394	442.11
571.654	476.174
571.914	485.511
572.174	506.443
572.434	528.498
572.694	553.818
572.954	606.28
573.214	645.605
573.459	664.031
573.719	739.308
573.98	808.154
574.241	851.342
574.501	899.544
574.762	1009.09
575.022	1072.2
575.283	1157.18
575.543	1227.15
575.804	1223.21
576.064	1214.12
576.325	1211.81
576.585	1141.37
576.846	1093.83
577.106	1070.4
577.366	986.718
577.627	955.709
577.887	872.459
578.148	844.983
578.408	832.253
578.668	788.28
578.929	797.891
579.189	754.066
579.449	750.708
579.71	761.212
579.97	739.561
580.23	751.588
580.49	772.992
580.751	753.041
581.011	753.632
581.271	775.057
581.531	783.727
581.792	791.923
582.052	792.372
582.312	824.132
582.572	809.027
582.832	811.649
583.092	844.192
583.353	835.077
583.613	870.128
583.873	882.472
584.133	888.31
584.393	911.993
584.653	908.487
584.913	938.319
585.173	967.841
585.433	942.824
585.693	1012.61
585.953	1002.03
586.213	1015.42
586.473	1021.54
586.733	1055.41
586.993	1036.63
587.253	1019.09
587.513	1040.17
587.773	1060.14
588.033	1069.18
588.293	1070.71
588.552	1083.15
588.812	1094.41
589.072	1087.55
589.332	1109.45
589.592	1114.03
589.852	1103.54
590.112	1104.86
590.371	1106.03
590.631	1115.16
590.891	1108.42
591.151	1081.71
591.41	1057.93
591.67	1063.8
591.93	1091.71
592.189	1061.54
592.449	1079.18
592.709	1092.79
592.968	1076.47
593.228	1054.4
593.488	1066.98
593.747	1083.08
594.007	1076.02
594.266	1089.16
594.526	1109.73
594.786	1087.98
595.045	1118.33
595.305	1111.8
595.564	1129.35
595.824	1121.11
596.083	1160.65
596.343	1168.04
596.602	1166.87
596.862	1164.9
597.121	1176.04
597.38	1183.1
597.64	1203.95
597.899	1173.87
598.159	1241.33
598.418	1193.53
598.677	1218.92
598.937	1209.64
599.196	1216.62
599.455	1248.3
599.715	1248.03
599.959	1233.92
600.219	1225.9
600.479	1270.81
600.738	1305.69
600.998	1237.61
601.258	1272.91
601.518	1276.42
601.778	1292.76
602.038	1260.81
602.298	1283.41
602.558	1260.02
602.818	1277.5
603.078	1300.23
603.337	1305.99
603.597	1317.28
603.857	1271.79
604.117	1305.51
604.377	1282.89
604.636	1301.87
604.896	1346.69
605.156	1327.47
605.416	1321.21
605.675	1340.12
605.935	1347.54
606.195	1311.75
606.455	1286.62
606.714	1322.62
606.974	1339.29
607.234	1335.22
607.493	1291.25
607.753	1351.34
608.012	1338.78
608.272	1356.89
608.532	1377.18
608.791	1367.82
609.051	1347.95
609.31	1383.71
609.57	1382.91
609.829	1416.14
610.089	1418.62
610.348	1417.31
610.608	1391.01
610.867	1414.87
611.127	1427.89
611.386	1440.52
611.646	1435.83
611.905	1457.17
612.164	1464.46
612.424	1462.97
612.683	1473.9
612.943	1473.25
613.202	1490.83
613.461	1493.14
613.721	1512.73
613.98	1522.2
614.239	1550.7
614.498	1571.01
614.758	1575.8
615.017	1575.5
615.276	1592.86
615.535	1600.29
615.795	1620.96
616.054	1608.35
616.313	1655.75
616.572	1651.39
616.831	1645.84
617.091	1687.04
617.35	1713.37
617.609	1706.19
617.868	1745.83
618.127	1738.73
618.386	1769.69
618.645	1776.84
618.904	1793.92
619.163	1823.3
619.422	1811.75
619.681	1839.68
619.94	1866.62
620.199	1878.43
620.458	1869.76
620.717	1908.11
620.976	1883.3
621.235	1899.08
621.494	1910.15
621.753	1927.26
622.012	1902.12
622.271	1946.54
622.53	1926.15
622.788	1925.84
623.047	1933.89
623.306	1897.38
623.565	1927.23
623.824	1960.16
624.082	1966.41
624.341	1982.68
624.6	1983.1
624.859	1991.98
625.117	2028.71
625.376	2028.41
625.635	2016.86
625.893	2032.41
626.152	2044.27
626.368	2029.99
626.627	2051.84
626.887	2074.07
627.146	2117.61
627.405	2064.37
627.665	2092.09
627.924	2141.09
628.183	2110.71
628.443	2119.35
628.702	2157.36
628.961	2121.55
629.22	2194.33
629.479	2199.33
629.739	2248.63
629.998	2239.29
630.257	2247.59
630.516	2235.52
630.776	2287.19
631.035	2280.22
631.294	2341.04
631.553	2351.62
631.812	2352.39
632.071	2383.06
632.33	2369.85
632.589	2415.63
632.848	2423.92
633.107	2459.95
633.366	2485.3
633.625	2505.66
633.885	2541.37
634.143	2532.86
634.403	2588.73
634.661	2636.08
634.92	2656.78
635.179	2703.22
635.438	2731.33
635.697	2814.45
635.956	2883.4
636.215	2949.98
636.474	3060.01
636.733	3220.44
636.992	3365.91
637.25	3543.5
637.509	3769.4
637.768	3983.15
638.027	4092.62
638.286	4198.27
638.544	4112.94
638.803	4038.27
639.062	3940.23
639.321	3812.14
639.579	3729.7
639.838	3618.92
640.097	3530.86
640.356	3471.88
640.614	3412.07
640.873	3398.58
641.131	3329.5
641.39	3356.32
641.649	3371.95
641.907	3301.12
642.166	3314.66
642.424	3323.87
642.683	3338.27
642.942	3324.93
643.2	3334.89
643.459	3340.33
643.717	3361.07
643.976	3365.02
644.234	3370.82
644.493	3389.35
644.751	3438.92
645.009	3463.48
645.268	3475.09
645.526	3435.98
645.785	3475.25
646.043	3479.18
646.301	3505.5
646.56	3558.13
646.818	3588.99
647.076	3540.42
647.335	3603.21
647.593	3621.11
647.851	3628.9
648.109	3689.72
648.368	3707.06
648.626	3621.95
648.884	3731.23
649.142	3724.44
649.401	3802.65
649.659	3835.8
649.917	3834.34
650.175	3850.88
650.433	3904.68
650.691	3870.67
650.949	3961.95
651.208	3991.35
651.466	4007.02
651.724	4020.3
651.982	4071.97
652.24	4100.48
652.498	4143.17
652.756	4190.67
652.979	4104.61
653.238	4205.6
653.497	4261.24
653.755	4333.76
654.014	4305.31
654.273	4408.87
654.531	4394.59
654.79	4431.56
655.049	4453.62
655.307	4537.45
655.566	4532.99
655.824	4689.53
656.083	4754.89
656.342	4766.99
656.6	4838.99
656.859	4834.12
657.117	4954.06
657.376	4978.34
657.634	5011.42
657.893	5046.05
658.151	5110.64
658.41	5139.54
658.668	5159.58
658.927	5196.64
659.185	5224.73
659.443	5246.5
659.702	5243.31
659.96	5264.58
660.219	5275.05
660.477	5247.25
660.735	5289.35
660.994	5294.74
661.252	5286.11
661.51	5300.22
661.768	5296.75
662.027	5314.44
662.285	5298.46
662.543	5310.48
662.802	5322.46
663.06	5255.3
663.318	5305.96
663.576	5320.52
663.834	5320.83
664.093	5289.88
664.351	5330.38
664.609	5330.05
664.867	5233.59
665.125	5287.02
665.383	5253.38
665.641	5282.75
665.899	5277.2
666.157	5287.99
666.415	5258.82
666.673	5235.95
666.931	5286.79
667.189	5248.97
667.447	5271.8
667.705	5297.22
667.963	5258.21
668.221	5327.06
668.479	5294
668.737	5306.69
668.995	5271.14
669.253	5290.68
669.511	5274.95
669.769	5240.64
670.027	5309.05
670.284	5292.35
670.542	5297.48
670.8	5311.97
671.058	5310.33
671.316	5305.24
671.573	5252.26
671.831	5302.14
672.089	5312.51
672.347	5366.07
672.604	5359.31
672.862	5339
673.12	5444.35
673.377	5396.24
673.635	5424.05
673.893	5457.36
674.15	5533.79
674.408	5484.66
674.665	5548.69
674.923	5491.55
675.18	5607.17
675.438	5571.57
675.696	5655.09
675.953	5629.95
676.211	5710.63
676.468	5668.86
676.726	5711.1
676.983	5692.01
677.24	5710.5
677.498	5731.27
677.755	5718.02
678.013	5761.9
678.27	5704.49
678.527	5708.18
678.785	5732.71
679.042	5758.31
679.277	5706.85
679.535	5700.83
679.793	5690.76
680.051	5806.15
680.309	5742.59
680.567	5856.97
680.825	5881.52
681.083	5847.33
681.341	5944.19
681.599	5862.91
681.857	5871.69
682.115	5949.18
682.373	5948.22
682.631	5950.95
682.889	5952.94
683.146	5926.28
683.404	5979.79
683.662	6010.43
683.92	5928.99
684.178	6011.64
684.436	5930
684.694	5960.72
684.951	5861.19
685.209	5893.06
685.467	5876.41
685.725	5868.26
685.982	5906.11
686.24	5777.51
686.498	5866.99
686.756	5867.85
687.013	5784.49
687.271	5836.68
687.529	5792.59
687.786	5761.82
688.044	5809.41
688.302	5837.79
688.559	5810.17
688.817	5853.32
689.074	5815.38
689.332	5813.9
689.589	5740.89
689.847	5814.63
690.104	5724.47
690.362	5763.22
690.619	5756.61
690.877	5757.09
691.134	5707.54
691.392	5664.7
691.649	5722.56
691.907	5689.77
692.164	5634.85
692.421	5611.78
692.679	5607.73
692.936	5609.03
693.194	5592.11
693.451	5576.38
693.708	5569.01
693.966	5589.34
694.223	5580.21
694.48	5506.98
694.737	5499.81
694.995	5522.27
695.252	5574.87
695.509	5510.69
695.766	5514.34
696.023	5484.31
696.281	5468.89
696.538	5470.25
696.795	5443.67
697.052	5407.42
697.309	5426.19
697.566	5347.28
697.823	5362.9
698.08	5353.01
698.338	5298.4
698.595	5267.27
698.852	5266.19
699.109	5213.04
699.366	5242.58
699.623	5246.12
699.88	5229.63
700.137	5232.52
700.393	5174.5
700.65	5171.04
700.907	5236.59
701.164	5188.56
701.421	5189.65
701.678	5230.06
701.935	5178.52
702.192	5151.79
702.448	5212.02
702.705	5226.15
702.962	5244.43
703.219	5242.19
703.476	5197.91
703.732	5197.48
703.989	5211.3
704.246	5135.94
704.503	5137.2
704.759	5101.74
705.016	5133.68
705.273	5093.59
705.511	5032.13
705.768	5070.06
706.026	4996.56
706.283	4961.15
706.541	4987.19
706.798	4969.38
707.055	4952.72
707.313	4898.17
707.57	4789.38
707.827	4876.98
708.084	4908.32
708.342	4899.88
708.599	4835.86
708.856	4845.02
709.114	4832.59
709.371	4846.95
709.628	4814.43
709.885	4829.34
710.142	4723.12
710.4	4781.9
710.657	4780.56
710.914	4730.25
711.171	4724.5
711.428	4707.63
711.685	4595.19
711.942	4703.05
712.199	4631.13
712.456	4632.44
712.713	4553.77
712.97	4551.39
713.227	4538.18
713.484	4522.75
713.741	4472.67
713.998	4491.89
714.255	4414.42
714.512	4422.44
714.769	4363.62
715.026	4358.03
715.283	4349.32
715.54	4327.63
715.797	4304.35
716.054	4284.74
716.31	4292.29
716.567	4266.12
716.824	4286.24
717.081	4258.83
717.338	4238.86
717.594	4243.4
717.851	4200.37
718.108	4197.1
718.365	4163.95
718.621	4137.72
718.878	4089.56
719.135	4120.59
719.391	4104.93
719.648	4096.27
719.905	4075.39
720.161	4062.7
720.418	4059.34
720.675	4011.25
720.931	4013.56
721.188	3928.63
721.444	3954.02
721.701	3923.26
721.957	3915.97
722.214	3884.91
722.47	3879.32
722.727	3844.62
722.983	3832.49
723.24	3821.05
723.496	3784.4
723.753	3755.22
724.009	3770.91
724.265	3731.84
724.522	3722.76
724.778	3697.03
725.034	3703.29
725.291	3711.08
725.547	3687.55
725.803	3650.59
726.06	3652.39
726.316	3632.24
726.572	3608.12
726.828	3578.13
727.085	3574.87
727.341	3578
727.597	3491.09
727.853	3518.18
728.109	3493.46
728.366	3475.87
728.622	3497.86
728.878	3462.46
729.134	3389.98
729.39	3426.36
729.646	3374.37
729.902	3312.89
730.158	3314.34
730.414	3289.91
730.67	3277.21
730.926	3228.98
731.182	3163.64
731.438	3155.49
731.643	3162
731.9	3218.47
732.156	3187.69
732.413	3180.98
732.67	3165.87
732.927	3200.17
733.183	3187.82
733.44	3149.94
733.697	3167.57
733.953	3114.02
734.21	3166.04
734.466	3144.78
734.723	3137.78
734.98	3163.46
735.236	3193.74
735.493	3148.26
735.749	3192.26
736.006	3161.48
736.262	3228.97
736.519	3241.81
736.775	3242.33
737.032	3302.08
737.288	3375.44
737.544	3343.77
737.801	3400.73
738.057	3422.21
738.314	3395.74
738.57	3390.18
738.826	3360.77
739.083	3318.89
739.339	3300.99
739.595	3235.5
739.852	3222.74
740.108	3163.92
740.364	3107.77
740.621	3058.64
740.877	3055.16
741.133	3023.2
741.389	3019.63
741.645	3010.2
741.902	2947.18
742.158	2919.69
742.414	2885.17
742.67	2879.04
742.926	2860.37
743.182	2833.72
743.438	2794
743.694	2802.18
743.951	2732.56
744.207	2744.41
744.463	2746.79
744.719	2734.09
744.975	2729.87
745.231	2677.05
745.487	2704.76
745.743	2648.91
745.998	2666.24
746.254	2641.86
746.51	2623.94
746.766	2613.38
747.022	2598.3
747.278	2562.68
747.534	2569.02
747.79	2588.38
748.046	2579.81
748.301	2556.9
748.557	2590.1
748.813	2540.35
749.069	2505.31
749.324	2491.25
749.58	2498.23
749.836	2501.98
750.092	2495.86
750.347	2485.65
750.603	2468.02
750.859	2460.64
751.114	2443.79
751.37	2469.87
751.625	2400.51
751.881	2354.43
752.137	2393.05
752.392	2385.86
752.648	2369.54
752.903	2345.74
753.159	2311.04
753.414	2282.78
753.67	2301.64
753.925	2316.51
754.181	2312.42
754.436	2241.11
754.692	2215.26
754.947	2196.94
755.202	2226.99
755.458	2251.56
755.713	2225.1
755.968	2190.41
756.224	2156.95
756.479	2149.88
756.734	2146.06
756.99	2100.34
757.245	2118.02
757.5	2150.83
757.755	2123.96
757.968	2100.01
758.224	2123.59
758.48	2115.96
758.736	2091.18
758.992	2035.23
759.248	2017.67
759.504	2007.93
759.76	2005.68
760.016	2025.89
760.272	1980.24
760.528	1995.12
760.784	1944.52
761.04	1963.57
761.296	1951.93
761.552	1908.22
761.807	1919.49
762.063	1916.23
762.319	1921.65
762.575	1895.91
762.831	1902.78
763.086	1892.7
763.342	1866.94
763.598	1819.28
763.853	1792.39
764.109	1819.14
764.365	1822.06
764.621	1822.16
764.876	1796.69
765.132	1785.49
765.387	1783.21
765.643	1759.92
765.899	1757.74
766.154	1752.55
766.41	1725.35
766.665	1734.44
766.921	1738.27
767.176	1695.88
767.432	1669.33
767.687	1694.05
767.943	1655.64
768.198	1651.44
768.454	1653.43
768.709	1663.97
768.965	1619.83
769.22	1632.31
769.475	1622.85
769.731	1615.25
769.986	1589.37
770.242	1569.25
770.497	1552.7
770.752	1550.57
771.007	1562.06
771.263	1545.93
771.518	1498.16
771.773	1509.86
772.028	1504.94
772.284	1479.01
772.539	1470.52
772.794	1455.85
773.049	1435.27
773.304	1445.16
773.56	1426.12
773.815	1430.66
774.07	1411.95
774.325	1414.63
774.58	1385.71
774.835	1383.28
775.09	1382.4
775.345	1351.4
775.6	1351.05
775.855	1355.21
776.11	1329.5
776.365	1329.91
776.62	1313.95
776.875	1287.7
777.13	1272.57
777.385	1293.47
777.64	1292.71
777.895	1274.69
778.149	1254.66
778.404	1242.87
778.659	1219.05
778.914	1228.33
779.169	1218.66
779.424	1252.22
779.678	1232.81
779.933	1188.18
780.188	1192.39
780.442	1180.86
780.697	1169.61
780.952	1124.78
781.207	1152.85
781.461	1149.04
781.716	1148.54
781.97	1109.68
782.225	1126.42
782.48	1101.72
782.734	1109.17
782.989	1079.01
783.243	1098.52
783.498	1066.7
783.752	1071.52
784.007	1074.93
784.253	1057.99
784.509	1067.66
784.764	1067.77
785.019	1043.4
785.274	1017.14
785.53	1002.61
785.785	991.246
786.04	1000.87
786.295	1021.32
786.551	1005.86
786.806	995.162
787.061	940.512
787.316	956.766
787.571	944.887
787.826	952.005
788.081	931.428
788.336	923.985
788.591	923.346
788.847	936.756
789.102	940.049
789.357	936.631
789.612	899.11
789.867	882.658
790.122	900.789
790.377	876.824
790.632	869.992
790.886	856.051
791.141	863.241
791.396	862.621
791.651	877.005
791.906	840.236
792.161	854.456
792.416	841.214
792.671	805.18
792.925	839.121
793.18	823.98
793.435	817.694
793.69	805.182
793.945	793.086
794.199	806.744
794.454	786.909
794.709	765.582
794.963	772.043
795.218	765.851
795.473	770.766
795.727	760.972
795.982	753.154
796.237	754.191
796.491	738.336
796.746	734.429
797	716.784
797.255	725.389
797.509	713.971
797.764	704.276
798.018	720.482
798.273	721.395
798.527	689.515
798.782	677.463
799.036	696.139
799.291	676.791
799.545	674.718
799.8	667.303
800.054	645.545
800.308	665.416
800.563	653.609
800.817	653.843
801.071	655.572
801.326	641.011
801.58	641.39
801.834	634.803
802.088	630.446
802.343	610.037
802.597	611.404
802.851	587.272
803.105	617.026
803.359	615.365
803.614	610.897
803.868	594.486
804.122	592.198
804.376	598.082
804.63	569.304
804.884	588.792
805.138	582.481
805.392	592.675
805.646	557.043
805.9	559.288
806.154	587.909
806.408	564.562
806.662	559.294
806.916	563.005
807.17	568.323
807.424	551.945
807.678	537.081
807.932	534.868
808.186	533.058
808.439	524.749
808.693	517.15
808.947	528.736
809.201	512.692
809.455	515.968
809.708	509.27
809.962	504.925
810.183	504
810.438	510.07
810.693	493.812
810.947	502.028
811.202	507.883
811.456	491.877
811.711	487.178
811.965	460.758
812.22	486.089
812.474	477.772
812.729	471.377
812.983	474.893
813.237	451.373
813.492	482.936
813.746	454.716
814.001	456.112
814.255	444.622
814.509	443.918
814.764	437.101
815.018	433.479
815.272	433.839
815.526	434.767
815.781	426.541
816.035	419.618
816.289	446.544
816.543	426.508
816.798	420.297
817.052	426.496
817.306	419.335
817.56	411.453
817.814	411.062
818.068	407.977
818.323	401.624
818.577	391.703
818.831	415.219
819.085	385.575
819.339	381.763
819.593	394.982
819.847	398.902
820.101	381.549
820.355	379.15
820.609	373.413
820.863	367.765
821.117	375.804
821.371	373.338
821.624	356.136
821.878	360.42
822.132	359.315
822.386	362.084
822.64	366.198
822.894	350.162
823.148	353.285
823.401	357.7
823.655	355.805
823.909	348.397
824.163	340.98
824.416	345.815
824.67	339.714
824.924	332.981
825.177	344.39
825.431	341.673
825.685	333.255
825.938	327.107
826.192	325.742
826.446	328.75
826.699	325.827
826.953	313.75
827.206	315.989
827.46	317.878
827.713	316.97
827.967	315.662
828.22	305.822
828.474	303.407
828.727	310.317
828.981	297.366
829.234	297.133
829.488	306.163
829.741	297.315
829.994	298.327
830.248	287.186
830.501	291.163
830.754	289.535
831.008	295.139
831.261	286.658
831.514	294.974
831.767	291.232
832.021	283.746
832.274	287.138
832.527	278.192
832.78	285.747
833.034	275.194
833.287	278.793
833.54	276.908
833.793	276.846
834.046	263.002
834.299	264
834.552	268.042
834.805	256.968
835.058	268.597
835.311	254.387
835.564	246.523
835.817	257.597
836.07	275.788
836.314	249.994
836.568	255.924
836.821	245.65
837.075	265.635
837.329	252.432
837.583	248.704
837.836	263.468
838.09	236.881
838.344	238.916
838.598	244.973
838.851	236.331
839.105	248.746
839.359	254.869
839.612	255.04
839.866	235.726
840.119	246.268
840.373	246.761
840.627	236.319
840.88	232.696
841.134	232.157
841.387	229.048
841.641	232
841.894	231.958
842.148	230.176
842.401	217.105
842.655	228.162
842.908	232.229
843.161	226.108
843.415	218.512
843.668	211.325
843.922	220.771
844.175	214.613
844.428	218.417
844.682	216.045
844.935	212.865
845.188	217.129
845.442	209.935
845.695	207.133
845.948	212.306
846.201	208.002
846.455	205.755
846.708	203.23
846.961	212.016
847.214	206.086
847.467	195.57
847.72	198.963
847.973	201.671
848.227	191.74
848.48	193.948
848.733	195.696
848.986	197.367
849.239	193.919
849.492	187.869
849.745	195.914
849.998	201.418
850.251	188.972
850.504	198.845
850.757	179.693
851.01	196.185
851.263	183.846
851.515	186.516
851.768	195.773
852.021	181.852
852.274	175.327
852.527	180.165
852.78	182.434
853.032	183.624
853.285	175.485
853.538	182.487
853.791	185.219
854.043	171.817
854.296	174
854.549	176.449
854.801	169.594
855.054	171.775
855.307	181.573
855.559	175.054
855.812	170.747
856.065	171.271
856.317	168.267
856.57	171.128
856.822	169.78
857.075	168.925
857.327	174.37
857.58	162.523
857.832	165.782
858.085	162.7
858.337	158.29
858.589	166.02
858.842	161.739
859.094	157.181
859.347	156.097
859.599	160.887
859.851	172.432
860.104	150.022
860.356	159.865
860.608	150.404
860.861	159.535
861.113	157.398
861.365	159.009
861.617	155.332
861.869	157.522
862.112	153.988
862.365	134.155
862.618	147.858
862.871	157.734
863.124	146.126
863.377	153.404
863.63	130.364
863.883	149.814
864.136	129.755
864.389	143.999
864.642	155.356
864.894	153.557
865.147	149.439
865.4	132.682
865.653	139.531
865.906	145.778
866.159	134.88
866.412	137.257
866.664	144.014
866.917	136.77
867.17	130.2
867.423	138.689
867.675	137.599
867.928	118.768
868.181	132.436
868.433	140.628
868.686	132.895
868.939	136.134
869.191	124.237
869.444	134.039
869.697	136.957
869.949	127.202
870.202	122.292
870.454	128.064
870.707	116.241
870.959	123.517
871.212	120.723
871.464	129.661
871.717	117.863
871.969	129.694
872.222	124.686
872.474	127.575
872.727	127.175
872.979	125.635
873.231	118.561
873.484	124.004
873.736	118.036
873.988	123.771
874.241	120.382
874.493	125.029
874.745	114.432
874.998	129.421
875.25	117.078
875.502	114.488
875.754	110.738
876.006	110.685
876.259	110.124
876.511	109.405
876.763	112.769
877.015	109.409
877.267	117.994
877.519	114.829
877.771	112.767
878.023	111.329
878.276	112.238
878.528	104.96
878.78	117.529
879.031	106.92
879.284	109.033
879.535	113.543
879.787	107.594
880.039	104.823
880.291	104.203
880.543	110.392
880.795	99.8175
881.047	103.586
881.299	104.251
881.551	98.5872
881.802	104.507
882.054	106.576
882.306	107.071
882.558	106.281
882.809	101.614
883.061	101.326
883.313	109.943
883.565	102.567
883.816	96.4605
884.068	91.8726
884.319	106.437
884.571	94.6167
884.823	92.027
885.074	98.8903
885.326	93.879
885.577	94.5564
885.829	89.6481
886.08	100.604
886.332	104.329
886.583	97.8246
886.835	95.3966
887.086	98.8967
887.338	99.4822
887.589	99.9412
887.841	91.8972
888.044	92
888.296	107.371
888.548	102.694
888.8	82.5126
889.053	92.8299
889.305	99.2428
889.557	93.6176
889.809	93.361
890.061	87.9757
890.313	86.3412
890.566	82.5188
890.818	81.1738
891.07	89.305
891.322	81.533
891.574	82.1987
891.826	87.8523
892.078	86.0792
892.33	86.023
892.582	89.0008
892.834	88.142
893.086	86.8527
893.338	77.1392
893.59	88.6791
893.842	80.2018
894.094	77.0362
894.346	73.0423
894.597	78.9275
894.849	82.0399
895.101	89.0556
895.353	77.786
895.605	80.3913
895.857	85.8961
896.108	80.4783
896.36	78.8647
896.612	77.4565
896.864	75.8488
897.115	79.7391
897.367	74.6014
897.619	78.6493
897.87	72.867
898.122	77.7509
898.374	72.1463
898.625	73.2817
898.877	74.2987
899.128	72.4281
899.38	73
899.631	72.0411
899.883	76.5441
899.984	73.2954