File: PL_230124_Amostra_marrom_01.txt
#Acq. time (s)=	3
#Accumulations=	2
#Range (nm)=	520...900
#Windows=	16
#Auto scanning=	On
#Autofocus=	Off
#AutoExposure=	Off
#Spike filter=	Multiple accum.
#Delay time (s)=	0
#Binning=	1
#Readout mode=	Signal
#DeNoise=	Off
#ICS correction=	Off
#Dark correction=	Off
#Inst. Process=	Off
#Detector temperature (°C)=	-59.98
#Instrument=	LabRAM HR Evol
#Detector=	Syncerity OE
#Objective=	x50_VIS
#Grating=	600 (500nm)
#ND Filter=	10%
#Laser=	514nm_Edge
#Hole=	199.981
#Range=	Auto
#StageXY=	Marzhauser
#StageZ=	Marzhauser
#X (µm)=	-9419.6
#Y (µm)=	-697.2
#Z (µm)=	273.7
#Full time(mm:ss)=	2:39
#Project=
#Sample=
#Site=
#Title=	PL_230124_Amostra_marrom
#Remark=
#Date=	31.01.2024 11:22
#Acquired=	31.01.2024 11:22:10
520.042	47
520.304	39.8463
520.565	50.0594
520.827	49.0698
521.089	47.7628
521.351	40.5372
521.612	40
521.874	45.7835
522.136	39.8302
522.397	47.3842
522.659	45.8626
522.921	46.2666
523.182	41.943
523.444	42
523.705	44.4156
523.967	43
524.229	44.213
524.49	46.5856
524.752	50.3504
525.013	45
525.275	46
525.536	49.4959
525.798	45.5145
526.059	41.6065
526.321	46
526.582	52.4226
526.844	52.1049
527.105	42.383
527.367	41.042
527.628	52.6492
527.889	49.6807
528.151	45.4033
528.412	46
528.674	55.8846
528.935	49.6177
529.196	44.4289
529.458	49.1935
529.719	48.5862
529.98	47.8508
530.242	51
530.503	52.5524
530.764	53.542
531.025	46.1888
531.287	51.0793
531.548	46.4476
531.809	49.5012
532.07	48.0466
532.332	51.4301
532.593	52
532.854	51.2727
533.115	52.4569
533.376	52.8648
533.638	54.9022
533.899	53.0106
534.16	58.6077
534.421	58.8184
534.682	68.4326
534.943	65.8743
535.204	72.1061
535.465	65.3212
535.726	65.2123
535.987	64.064
536.248	58.5893
536.509	63.9179
536.77	61.3533
537.031	58.9511
537.292	59.5773
537.553	63.9159
537.814	61.4406
538.075	60.7045
538.336	65.5022
538.597	55.9309
538.858	64.3562
539.119	69.4305
539.38	64.8071
539.641	68.7147
539.901	65.2318
540.162	70.4912
540.423	67.5284
540.684	64.3379
540.945	63.2782
541.205	65.6275
541.466	66.1759
541.727	69.9665
541.988	69.2086
542.248	78.4591
542.509	79.8113
542.77	67.2178
543.031	72.8278
543.291	74.5409
543.552	76.7659
543.813	85.1901
544.073	83.7058
544.334	88.9109
544.594	80.1823
544.855	83.2505
545.116	81.0472
545.376	85.285
545.637	99.6791
545.897	93.1303
546.158	90.9748
546.418	86.7656
546.679	90.2926
546.898	99.9726
547.159	105.846
547.42	92.3912
547.681	104.065
547.942	119.159
548.203	108.466
548.464	111.132
548.725	118.942
548.987	105.077
549.248	108.768
549.509	119.56
549.77	124.493
550.031	127.055
550.292	118.766
550.553	120.111
550.814	134.977
551.075	135.938
551.336	153.065
551.597	167.949
551.858	185.785
552.119	239.096
552.38	1361.88
552.641	10453.9
552.901	403.705
553.162	204.374
553.423	188.256
553.684	172.186
553.945	164.337
554.206	173.026
554.467	171.934
554.727	172.642
554.988	175.414
555.249	180.921
555.51	174.099
555.771	172.063
556.031	185.104
556.292	180.377
556.553	199.446
556.814	208.526
557.074	204.019
557.335	207.253
557.596	223.804
557.856	213.013
558.117	226.558
558.378	242.327
558.638	234.642
558.899	230.663
559.16	241.087
559.42	238.162
559.681	227.106
559.941	239.01
560.202	249.992
560.463	245.06
560.723	250.37
560.984	262.441
561.244	272.587
561.505	271.802
561.765	278.196
562.026	275.118
562.286	295.511
562.547	292.722
562.807	296.906
563.067	312.907
563.328	315.49
563.588	316.222
563.849	320.593
564.109	319.574
564.369	333.481
564.63	332.333
564.89	339.948
565.15	352.43
565.411	339.413
565.671	349.175
565.931	374.733
566.192	377.621
566.452	380.695
566.712	396.162
566.972	383.784
567.232	401.911
567.493	398.663
567.753	419.486
568.013	420.753
568.273	421.275
568.533	437.772
568.794	444.49
569.054	444.987
569.314	465.798
569.574	464.992
569.834	469.007
570.094	490.869
570.354	512.44
570.614	521.407
570.874	540.934
571.134	570.137
571.394	569.931
571.654	626.664
571.914	654.781
572.174	675.789
572.434	703.046
572.694	754.428
572.954	779.879
573.214	812.594
573.459	882.022
573.719	971.532
573.98	1041.39
574.241	1117.16
574.501	1203.46
574.762	1278.97
575.022	1443.15
575.283	1481.29
575.543	1583.46
575.804	1608.11
576.064	1674.57
576.325	1612.75
576.585	1577.84
576.846	1494.52
577.106	1404.61
577.366	1342.48
577.627	1269.53
577.887	1186.65
578.148	1166.41
578.408	1115.86
578.668	1098.14
578.929	1062.63
579.189	1045.75
579.449	1043.96
579.71	994.551
579.97	1033.78
580.23	996.156
580.49	1014.69
580.751	1017.48
581.011	1028.2
581.271	1009.87
581.531	1043.75
581.792	1071.73
582.052	1065.71
582.312	1060.37
582.572	1076.64
582.832	1106.48
583.092	1114.84
583.353	1129.57
583.613	1140.67
583.873	1187.29
584.133	1186.19
584.393	1167.17
584.653	1210.66
584.913	1249.49
585.173	1272.16
585.433	1292.07
585.693	1313.09
585.953	1340.58
586.213	1324.86
586.473	1375.6
586.733	1353.61
586.993	1386.63
587.253	1380.44
587.513	1373.39
587.773	1414.94
588.033	1405.56
588.293	1422.36
588.552	1447.15
588.812	1457.56
589.072	1448.99
589.332	1473.39
589.592	1473.69
589.852	1470.01
590.112	1469.78
590.371	1477.83
590.631	1461.96
590.891	1457.29
591.151	1457.35
591.41	1462.94
591.67	1447.89
591.93	1444.7
592.189	1447.21
592.449	1463.28
592.709	1424.52
592.968	1459.65
593.228	1482.4
593.488	1483.03
593.747	1445.21
594.007	1474.42
594.266	1487.81
594.526	1491.7
594.786	1498.06
595.045	1505.95
595.305	1499.43
595.564	1540.64
595.824	1544.4
596.083	1553.89
596.343	1601.52
596.602	1638.54
596.862	1661.54
597.121	1647.41
597.38	1657.65
597.64	1698.44
597.899	1700.87
598.159	1708.46
598.418	1722.58
598.677	1718.08
598.937	1709.65
599.196	1716.11
599.455	1718.99
599.715	1692.49
599.959	1703.91
600.219	1719.84
600.479	1717.32
600.738	1692.14
600.998	1750.26
601.258	1738.05
601.518	1738.55
601.778	1739.68
602.038	1731.38
602.298	1750.58
602.558	1766.19
602.818	1736.61
603.078	1762.22
603.337	1757.56
603.597	1788.41
603.857	1776.67
604.117	1794.94
604.377	1804.96
604.636	1782.95
604.896	1815.97
605.156	1810.45
605.416	1822.61
605.675	1819.12
605.935	1811.9
606.195	1830.08
606.455	1805.05
606.714	1796.81
606.974	1819.89
607.234	1780.53
607.493	1801.1
607.753	1823.43
608.012	1841.99
608.272	1870.96
608.532	1857.41
608.791	1884.62
609.051	1873.73
609.31	1879.77
609.57	1901.27
609.829	1891.44
610.089	1909.28
610.348	1947.46
610.608	1924.68
610.867	1930.99
611.127	1947.06
611.386	1955.15
611.646	1951.85
611.905	1978.18
612.164	1994.56
612.424	1975.69
612.683	1988.96
612.943	2003.14
613.202	2025.25
613.461	2038.63
613.721	2064.71
613.98	2079.72
614.239	2084.64
614.498	2098.13
614.758	2111.35
615.017	2115.13
615.276	2139.55
615.535	2190.68
615.795	2169.86
616.054	2184.97
616.313	2202.9
616.572	2222.56
616.831	2225.11
617.091	2243.36
617.35	2257.01
617.609	2259.06
617.868	2259.83
618.127	2316.35
618.386	2356.65
618.645	2352.11
618.904	2345.49
619.163	2380.7
619.422	2416.05
619.681	2420.74
619.94	2476.53
620.199	2455.44
620.458	2460.37
620.717	2421.53
620.976	2437.59
621.235	2527.27
621.494	2516.92
621.753	2522.61
622.012	2495.59
622.271	2522.91
622.53	2536.14
622.788	2506.58
623.047	2523.44
623.306	2523.72
623.565	2502.66
623.824	2513.4
624.082	2530.93
624.341	2564.52
624.6	2536.61
624.859	2538.67
625.117	2577.64
625.376	2538.1
625.635	2562.32
625.893	2603.83
626.152	2642.28
626.368	2639.23
626.627	2591.42
626.887	2673.69
627.146	2663.49
627.405	2646.71
627.665	2666.31
627.924	2672.06
628.183	2646.1
628.443	2712.97
628.702	2735.8
628.961	2722.38
629.22	2757.84
629.479	2746.52
629.739	2762.52
629.998	2739.61
630.257	2796.28
630.516	2804.54
630.776	2802.01
631.035	2846.7
631.294	2868.47
631.553	2882.31
631.812	2908.61
632.071	2891.36
632.33	2919.39
632.589	2945.8
632.848	2971.86
633.107	3012.12
633.366	3044.05
633.625	3069.81
633.885	3073.96
634.143	3064.3
634.403	3131.68
634.661	3170.77
634.92	3177.4
635.179	3176.31
635.438	3269.98
635.697	3316.57
635.956	3380.88
636.215	3454.59
636.474	3522.76
636.733	3671.82
636.992	3773.58
637.25	3934.91
637.509	4134.11
637.768	4341.45
638.027	4468.82
638.286	4611.21
638.544	4656.42
638.803	4601.16
639.062	4480.12
639.321	4424.33
639.579	4281.18
639.838	4150.85
640.097	4116.42
640.356	4013.29
640.614	3962.97
640.873	3877.89
641.131	3886.41
641.39	3836.25
641.649	3836.7
641.907	3810.54
642.166	3801.99
642.424	3792.37
642.683	3834.41
642.942	3824.99
643.2	3883.4
643.459	3849.97
643.717	3858.26
643.976	3886.25
644.234	3869.32
644.493	3896.08
644.751	3915.26
645.009	3905.94
645.268	3932.18
645.526	3954.87
645.785	3926.37
646.043	4022.6
646.301	3979.41
646.56	3955.25
646.818	4047.12
647.076	4064.15
647.335	4033.59
647.593	4018.34
647.851	4059.9
648.109	4002.47
648.368	4130.54
648.626	4111.41
648.884	4152.13
649.142	4167.01
649.401	4192.82
649.659	4251.22
649.917	4273.01
650.175	4295.06
650.433	4351.87
650.691	4361.26
650.949	4347.09
651.208	4399.55
651.466	4421.76
651.724	4460.91
651.982	4502.06
652.24	4472.52
652.498	4484.24
652.756	4515.01
652.979	4565.46
653.238	4607.53
653.497	4549.5
653.755	4582.9
654.014	4706.95
654.273	4717.34
654.531	4751.49
654.79	4765.94
655.049	4865.82
655.307	4897.21
655.566	4975.35
655.824	4965.08
656.083	5080.61
656.342	5118.76
656.6	5125.95
656.859	5140.54
657.117	5225.36
657.376	5295.43
657.634	5269.81
657.893	5348.1
658.151	5420.19
658.41	5407.28
658.668	5465.71
658.927	5429.97
659.185	5520.44
659.443	5491.36
659.702	5473.58
659.96	5594.63
660.219	5508.77
660.477	5585.77
660.735	5533.02
660.994	5528.56
661.252	5451.65
661.51	5516.82
661.768	5572.82
662.027	5593.05
662.285	5532.63
662.543	5598.2
662.802	5579.92
663.06	5616.81
663.318	5636.06
663.576	5570.54
663.834	5570.7
664.093	5582.23
664.351	5554.94
664.609	5587.88
664.867	5534.89
665.125	5551.88
665.383	5543.15
665.641	5554.4
665.899	5523.82
666.157	5520.35
666.415	5560.42
666.673	5536.16
666.931	5543.64
667.189	5518.24
667.447	5494.12
667.705	5479.71
667.963	5576.71
668.221	5499
668.479	5531.18
668.737	5429.01
668.995	5555.97
669.253	5541.44
669.511	5522
669.769	5479.19
670.027	5547.64
670.284	5453.76
670.542	5449.01
670.8	5484.82
671.058	5470.6
671.316	5502.69
671.573	5439.09
671.831	5493.76
672.089	5521.67
672.347	5544.46
672.604	5557.47
672.862	5524.66
673.12	5566.58
673.377	5583.3
673.635	5628.77
673.893	5638.54
674.15	5660.64
674.408	5733.56
674.665	5723.03
674.923	5757.87
675.18	5747.19
675.438	5771.49
675.696	5835.49
675.953	5820.26
676.211	5776.85
676.468	5841.68
676.726	5856.85
676.983	5846.58
677.24	5809.07
677.498	5890.08
677.755	5837.53
678.013	5875.35
678.27	5810.27
678.527	5871.43
678.785	5749.39
679.042	5848.35
679.277	5769.48
679.535	5925.5
679.793	5873.78
680.051	5910.92
680.309	5941.53
680.567	5929.9
680.825	6022.66
681.083	6006.95
681.341	6024.32
681.599	5983.12
681.857	6071.07
682.115	5969.66
682.373	6142.55
682.631	6092
682.889	6054.52
683.146	6152.48
683.404	6075.5
683.662	6086.21
683.92	6050.92
684.178	6070.71
684.436	6019.2
684.694	6101.84
684.951	5993.4
685.209	5982.01
685.467	5968.73
685.725	6049.78
685.982	5956.73
686.24	6020.41
686.498	5978.05
686.756	5929.35
687.013	5915.01
687.271	5941.97
687.529	5951.73
687.786	5926.09
688.044	5925.67
688.302	5853.94
688.559	5904.7
688.817	5905.5
689.074	5947.1
689.332	5847.11
689.589	5913.64
689.847	5842.75
690.104	5827.21
690.362	5931.28
690.619	5853.59
690.877	5853.77
691.134	5811.4
691.392	5748.31
691.649	5797.58
691.907	5779.14
692.164	5728.92
692.421	5691.29
692.679	5738.87
692.936	5668.31
693.194	5675.59
693.451	5679.38
693.708	5594.95
693.966	5610.12
694.223	5602.89
694.48	5597.79
694.737	5650.56
694.995	5582.98
695.252	5620.7
695.509	5607.71
695.766	5519.18
696.023	5516.8
696.281	5487.25
696.538	5496.46
696.795	5508.42
697.052	5503.25
697.309	5467.89
697.566	5446.06
697.823	5449.62
698.08	5366.73
698.338	5393.66
698.595	5375.02
698.852	5338.74
699.109	5281.69
699.366	5293.53
699.623	5261.76
699.88	5234.08
700.137	5291.21
700.393	5272.72
700.65	5221.79
700.907	5234.38
701.164	5253.27
701.421	5223.87
701.678	5264.24
701.935	5239.48
702.192	5193.04
702.448	5239.4
702.705	5257.18
702.962	5204.63
703.219	5241.38
703.476	5215.2
703.732	5196.82
703.989	5194.52
704.246	5175.33
704.503	5194.41
704.759	5157.07
705.016	5148.6
705.273	5087.36
705.511	5136.03
705.768	5126.01
706.026	5065.21
706.283	5039.86
706.541	4970.79
706.798	4947.72
707.055	4966.19
707.313	4988.26
707.57	4934.46
707.827	4967.39
708.084	4932.63
708.342	4946.91
708.599	4954.67
708.856	4794.81
709.114	4864
709.371	4904.74
709.628	4834.6
709.885	4851.98
710.142	4814.8
710.4	4810.44
710.657	4704.35
710.914	4782.85
711.171	4671.11
711.428	4706.7
711.685	4698.1
711.942	4646.56
712.199	4620.2
712.456	4679.26
712.713	4642.41
712.97	4568.29
713.227	4549.08
713.484	4566.4
713.741	4567.89
713.998	4463.76
714.255	4453.8
714.512	4426.12
714.769	4467.33
715.026	4377.19
715.283	4390.27
715.54	4373.45
715.797	4322.27
716.054	4357.82
716.31	4271.73
716.567	4294.79
716.824	4316.31
717.081	4211.03
717.338	4309.41
717.594	4253.95
717.851	4250.5
718.108	4246.15
718.365	4196.11
718.621	4214.22
718.878	4195
719.135	4174.62
719.391	4095.75
719.648	4115.2
719.905	4095.6
720.161	4069.27
720.418	4113.72
720.675	4024.01
720.931	4008.98
721.188	3989.89
721.444	4013.04
721.701	3891.77
721.957	3932.13
722.214	3955.63
722.47	3931.08
722.727	3898.17
722.983	3856.95
723.24	3830.53
723.496	3858.78
723.753	3810.63
724.009	3791.14
724.265	3785.89
724.522	3781.79
724.778	3764.82
725.034	3783.33
725.291	3771.19
725.547	3718.53
725.803	3688.85
726.06	3724.1
726.316	3618.97
726.572	3659.23
726.828	3635.44
727.085	3630.5
727.341	3641.11
727.597	3603.5
727.853	3616.31
728.109	3580.37
728.366	3562.68
728.622	3494.62
728.878	3492.26
729.134	3478.56
729.39	3463.56
729.646	3458.24
729.902	3405.84
730.158	3412.45
730.414	3362.58
730.67	3319.13
730.926	3312.79
731.182	3279.07
731.438	3403.98
731.643	3284
731.9	3334.49
732.156	3277.45
732.413	3325.5
732.67	3292.36
732.927	3274.72
733.183	3286.58
733.44	3268.61
733.697	3233.63
733.953	3276.6
734.21	3335.75
734.466	3342.95
734.723	3293.04
734.98	3319.82
735.236	3418.24
735.493	3413.01
735.749	3466.24
736.006	3505.36
736.262	3523.66
736.519	3583.34
736.775	3668.84
737.032	3744.71
737.288	3794.9
737.544	3909.5
737.801	3976.36
738.057	3941.01
738.314	4040.45
738.57	3973.75
738.826	3918.51
739.083	3911.79
739.339	3834.65
739.595	3757.28
739.852	3636
740.108	3529.18
740.364	3475.41
740.621	3439.06
740.877	3392.51
741.133	3302.23
741.389	3261.6
741.645	3196.51
741.902	3161.93
742.158	3132.31
742.414	3108.12
742.67	3023.85
742.926	3023.03
743.182	2976.92
743.438	2945.46
743.694	2933.08
743.951	2914.42
744.207	2899.62
744.463	2857.23
744.719	2823.49
744.975	2826.4
745.231	2813.12
745.487	2802.7
745.743	2770.81
745.998	2774.34
746.254	2692.23
746.51	2700.27
746.766	2670.62
747.022	2664.99
747.278	2691.83
747.534	2624.28
747.79	2671.62
748.046	2619.3
748.301	2634.14
748.557	2580.35
748.813	2626.45
749.069	2576.48
749.324	2541.16
749.58	2566.94
749.836	2559.54
750.092	2541.89
750.347	2535.84
750.603	2521.53
750.859	2513.11
751.114	2473.68
751.37	2477.24
751.625	2455.51
751.881	2403.42
752.137	2441.97
752.392	2410.62
752.648	2428.83
752.903	2384.86
753.159	2349.97
753.414	2347.44
753.67	2354.5
753.925	2315.96
754.181	2304.17
754.436	2289.38
754.692	2330.57
754.947	2257.73
755.202	2245.86
755.458	2256.61
755.713	2250.75
755.968	2230.07
756.224	2200.79
756.479	2174.51
756.734	2177.11
756.99	2179.5
757.245	2143.07
757.5	2147.88
757.755	2118.45
757.968	2122.03
758.224	2110.38
758.48	2131.36
758.736	2075.43
758.992	2109.4
759.248	2090.41
759.504	2069.2
759.76	2055.82
760.016	2004.6
760.272	1991.57
760.528	1954.69
760.784	1977.4
761.04	2011.99
761.296	1956.95
761.552	1997.37
761.807	1930.7
762.063	1941.22
762.319	1972.03
762.575	1949.58
762.831	1912.17
763.086	1871.08
763.342	1893.68
763.598	1909.28
763.853	1832.9
764.109	1892.41
764.365	1865.7
764.621	1816.39
764.876	1846.05
765.132	1844.95
765.387	1831.17
765.643	1821.2
765.899	1808.92
766.154	1812.02
766.41	1743.57
766.665	1763.89
766.921	1750.06
767.176	1741.13
767.432	1741.77
767.687	1762.63
767.943	1699.49
768.198	1707.42
768.454	1678.56
768.709	1686.18
768.965	1650.02
769.22	1624.85
769.475	1630.53
769.731	1629.31
769.986	1612.52
770.242	1599.77
770.497	1576.41
770.752	1553.48
771.007	1566.24
771.263	1547.79
771.518	1531.32
771.773	1527.51
772.028	1505.6
772.284	1507.44
772.539	1490.37
772.794	1462.33
773.049	1479.48
773.304	1461.54
773.56	1446.46
773.815	1434.63
774.07	1446.48
774.325	1423.3
774.58	1402.64
774.835	1392.46
775.09	1382.91
775.345	1381.33
775.6	1375.15
775.855	1378.67
776.11	1372.45
776.365	1320
776.62	1329.99
776.875	1311.79
777.13	1312.77
777.385	1297
777.64	1298.81
777.895	1274.19
778.149	1267.29
778.404	1271.25
778.659	1283.39
778.914	1252.78
779.169	1219.75
779.424	1227.23
779.678	1230.89
779.933	1209.08
780.188	1213.82
780.442	1214.16
780.697	1182.38
780.952	1174.58
781.207	1160.09
781.461	1155.87
781.716	1157.24
781.97	1136.09
782.225	1141.24
782.48	1132.17
782.734	1111
782.989	1115.39
783.243	1113.66
783.498	1059.87
783.752	1084.96
784.007	1067.17
784.253	1097.8
784.509	1040.2
784.764	1044.01
785.019	1052.24
785.274	1062.34
785.53	1024.65
785.785	1020.36
786.04	1026.53
786.295	994.349
786.551	1001.24
786.806	999.396
787.061	990.312
787.316	958.023
787.571	969.054
787.826	972.668
788.081	940.167
788.336	934.607
788.591	931.607
788.847	936.102
789.102	953.059
789.357	903.537
789.612	899.706
789.867	916.891
790.122	894.858
790.377	906.128
790.632	874.326
790.886	882.359
791.141	880.746
791.396	876.01
791.651	844.223
791.906	851.098
792.161	846.301
792.416	845.912
792.671	834.361
792.925	817.897
793.18	843.818
793.435	825.95
793.69	807.523
793.945	817.678
794.199	786.324
794.454	821.571
794.709	805.219
794.963	789.968
795.218	759.09
795.473	754.629
795.727	769.358
795.982	767.247
796.237	754.675
796.491	753.618
796.746	719.053
797	736.562
797.255	729.441
797.509	728.797
797.764	698.307
798.018	736.045
798.273	713.568
798.527	708.304
798.782	699.526
799.036	701.563
799.291	687.061
799.545	672.699
799.8	680.896
800.054	677.061
800.308	673.366
800.563	663.178
800.817	650.927
801.071	657.415
801.326	657.725
801.58	657.461
801.834	658.319
802.088	633.253
802.343	621.195
802.597	632.796
802.851	636.529
803.105	605.276
803.359	606.575
803.614	621.299
803.868	618.117
804.122	589.172
804.376	574.11
804.63	602.127
804.884	580.234
805.138	566.274
805.392	574.209
805.646	589.588
805.9	584.086
806.154	538.282
806.408	558.496
806.662	548.463
806.916	537.978
807.17	554.514
807.424	550.011
807.678	525.484
807.932	544.666
808.186	546.394
808.439	536.224
808.693	523.201
808.947	516.392
809.201	531.112
809.455	522.786
809.708	505.554
809.962	529.433
810.183	488
810.438	499.994
810.693	505.823
810.947	501.774
811.202	506.855
811.456	493.382
811.711	500.94
811.965	488.07
812.22	506.653
812.474	472.548
812.729	464.63
812.983	494.201
813.237	477.277
813.492	456.614
813.746	470.64
814.001	471.555
814.255	458.73
814.509	456.941
814.764	461.348
815.018	451.795
815.272	450.587
815.526	435.562
815.781	444.106
816.035	428.56
816.289	432.048
816.543	442.441
816.798	410.132
817.052	440.956
817.306	413.478
817.56	389.058
817.814	421.074
818.068	406.372
818.323	407.71
818.577	409.425
818.831	403.894
819.085	394.094
819.339	393.442
819.593	397.426
819.847	387.957
820.101	383.6
820.355	380.497
820.609	381.613
820.863	374.189
821.117	380.461
821.371	358.036
821.624	361.67
821.878	368.874
822.132	355.193
822.386	368.236
822.64	349.382
822.894	367.734
823.148	343.09
823.401	358.474
823.655	355.909
823.909	341.694
824.163	347.521
824.416	324.383
824.67	352
824.924	346.152
825.177	350.883
825.431	337.775
825.685	329.08
825.938	324
826.192	328.151
826.446	332.269
826.699	325.323
826.953	317.894
827.206	323.508
827.46	323.273
827.713	323.872
827.967	316.896
828.22	313.372
828.474	318.938
828.727	310.438
828.981	307.88
829.234	308.391
829.488	302.089
829.741	297.479
829.994	301.172
830.248	297.644
830.501	303.175
830.754	292.468
831.008	282.384
831.261	297.03
831.514	292.433
831.767	288.863
832.021	293.757
832.274	286.405
832.527	285.34
832.78	281.531
833.034	276.317
833.287	279.023
833.54	271.756
833.793	271.905
834.046	278.759
834.299	273.949
834.552	254.49
834.805	277.894
835.058	251.699
835.311	270.681
835.564	249.121
835.817	276.208
836.07	274.404
836.314	249.989
836.568	267.796
836.821	253.534
837.075	260.006
837.329	261.117
837.583	260.988
837.836	258.994
838.09	246.136
838.344	244.545
838.598	250.623
838.851	236.331
839.105	245.349
839.359	237.058
839.612	255.743
839.866	251.229
840.119	240.268
840.373	227.228
840.627	234.593
840.88	235.505
841.134	221.044
841.387	231.273
841.641	232.154
841.894	228.9
842.148	237.858
842.401	224.629
842.655	229.113
842.908	227.427
843.161	231.313
843.415	223.799
843.668	229.247
843.922	210.918
844.175	230.647
844.428	215.975
844.682	213.523
844.935	222.216
845.188	216.809
845.442	216.918
845.695	220.149
845.948	199.911
846.201	207.142
846.455	208.125
846.708	205.56
846.961	201.015
847.214	206.078
847.467	211.331
847.72	208.507
847.973	207.295
848.227	213.365
848.48	209.615
848.733	199.84
848.986	202.79
849.239	196.737
849.492	192.183
849.745	196.534
849.998	195.776
850.251	195.476
850.504	189.017
850.757	188.069
851.01	187.971
851.263	188.154
851.515	193.067
851.768	186.754
852.021	190.683
852.274	191.376
852.527	190.906
852.78	181.179
853.032	188.726
853.285	188.48
853.538	181.659
853.791	174.277
854.043	183.312
854.296	173.188
854.549	172.3
854.801	168.477
855.054	174.561
855.307	172.916
855.559	169.783
855.812	172.91
856.065	171.562
856.317	170.601
856.57	165.195
856.822	161.095
857.075	167.907
857.327	171.131
857.58	165.994
857.832	160.13
858.085	164.05
858.337	159.194
858.589	160.452
858.842	156.014
859.094	158.421
859.347	153.192
859.599	160.214
859.851	151.756
860.104	154.419
860.356	157.595
860.608	157.769
860.861	156.288
861.113	149.856
861.365	158.918
861.617	154.415
861.869	163.009
862.112	156
862.365	148.013
862.618	144.288
862.871	143.998
863.124	151.68
863.377	157.087
863.63	147.751
863.883	145.926
864.136	140.504
864.389	149.824
864.642	151.012
864.894	147.578
865.147	148.547
865.4	139.348
865.653	152.038
865.906	137.511
866.159	143.929
866.412	130.743
866.664	137.687
866.917	139.439
867.17	142.424
867.423	134.689
867.675	131.955
867.928	140.517
868.181	140.712
868.433	144.988
868.686	132.769
868.939	140.119
869.191	128.881
869.444	138.298
869.697	137.218
869.949	129.508
870.202	133.78
870.454	138.297
870.707	132.171
870.959	129.124
871.212	122.9
871.464	122.23
871.717	127.029
871.969	126.733
872.222	127.286
872.474	122.006
872.727	128.62
872.979	118.46
873.231	117.843
873.484	128.048
873.736	117.865
873.988	129.816
874.241	125.847
874.493	121.632
874.745	116.397
874.998	123.839
875.25	115.638
875.502	118.593
875.754	116.218
876.006	120.926
876.259	115.025
876.511	114
876.763	121.254
877.015	120.625
877.267	116.825
877.519	109.588
877.771	117.217
878.023	110.645
878.276	112.942
878.528	106.096
878.78	112.375
879.031	107.545
879.284	112.569
879.535	108.041
879.787	113.899
880.039	110.316
880.291	109.196
880.543	107.542
880.795	104.061
881.047	106.161
881.299	99.1778
881.551	101.085
881.802	112.784
882.054	107.918
882.306	104.71
882.558	98.6488
882.809	111.019
883.061	96.1476
883.313	102.315
883.565	101.743
883.816	98.0853
884.068	103.608
884.319	102.813
884.571	104.598
884.823	101.313
885.074	96.6216
885.326	94.1834
885.577	101.198
885.829	98.97
886.08	95.1313
886.332	97.4575
886.583	103.851
886.835	97.5951
887.086	93.8727
887.338	98.3291
887.589	99.5765
887.841	104.014
888.044	105.873
888.296	82.2058
888.548	95.888
888.8	103.131
889.053	95.4573
889.305	89.6924
889.557	103.817
889.809	89.1053
890.061	95.3811
890.313	85.16
890.566	90.4895
890.818	90.261
891.07	92
891.322	88.3045
891.574	85.5744
891.826	90.5038
892.078	85.4774
892.33	84.0314
892.582	82.5926
892.834	94.6146
893.086	83.6639
893.338	91.7553
893.59	89.0617
893.842	87.0153
894.094	73.1014
894.346	87.0085
894.597	88.9034
894.849	74.8804
895.101	92.2222
895.353	83.8573
895.605	75.913
895.857	73.9348
896.108	82.7609
896.36	85.4589
896.612	83.5435
896.864	76.8319
897.115	76.4456
897.367	80.4034
897.619	77
897.87	73.2999
898.122	77
898.374	77.7352
898.625	76.2817
898.877	78
899.128	80.3144
899.38	81.6626
899.631	72
899.883	71.636
899.984	72.7409