File: PL_230124_Amostra_mais_branca_02.txt
#Acq. time (s)=	3
#Accumulations=	2
#Range (nm)=	520...900
#Windows=	16
#Auto scanning=	On
#Autofocus=	Off
#AutoExposure=	Off
#Spike filter=	Multiple accum.
#Delay time (s)=	0
#Binning=	1
#Readout mode=	Signal
#DeNoise=	Off
#ICS correction=	Off
#Dark correction=	Off
#Inst. Process=	Off
#Detector temperature (°C)=	-59.98
#Instrument=	LabRAM HR Evol
#Detector=	Syncerity OE
#Objective=	x50_VIS
#Grating=	600 (500nm)
#ND Filter=	10%
#Laser=	514nm_Edge
#Hole=	199.981
#Range=	Auto
#StageXY=	Marzhauser
#StageZ=	Marzhauser
#X (µm)=	-7385.9
#Y (µm)=	8016.4
#Z (µm)=	84.7
#Full time(mm:ss)=	2:39
#Project=
#Sample=
#Site=
#Title=	PL_230124_Amostra_mais_branca
#Remark=
#Date=	31.01.2024 11:08
#Acquired=	31.01.2024 11:08:41
520.042	43
520.304	48.5902
520.565	44.1781
520.827	44.7907
521.089	47.0791
521.351	43.5523
521.612	39.1735
521.874	49.7835
522.136	46.8814
522.397	39.7439
522.659	45.099
522.921	45.8533
523.182	42.6857
523.444	39.3411
523.705	44.8231
523.967	46.3749
524.229	51.213
524.49	43.5856
524.752	44.9173
525.013	43.454
525.275	42.2363
525.536	42.7439
525.798	46.5145
526.059	46
526.321	41.4435
526.582	42.1339
526.844	42.8951
527.105	46
527.367	40.9161
527.628	41.3508
527.889	49.6597
528.151	45.5967
528.412	40.8044
528.674	44.7436
528.935	43.1469
529.196	44.2145
529.458	43.4359
529.719	47.9312
529.98	42.4033
530.242	48
530.503	45.3427
530.764	46
531.025	48.1259
531.287	46.4802
531.548	47.4476
531.809	50.9953
532.07	52.4883
532.332	48.3834
532.593	45.4662
532.854	46
533.115	46.4429
533.376	49
533.638	51.7179
533.899	56.9922
534.16	53.1464
534.421	52.4842
534.682	55.4292
534.943	59.1523
535.204	54.993
535.465	57.0446
535.726	56.849
535.987	56.1165
536.248	56.2382
536.509	53.4943
536.77	55.4912
537.031	55.9667
537.292	52.5871
537.553	48.5068
537.814	62.0379
538.075	56.0568
538.336	52.8496
538.597	62.4987
538.858	59.1442
539.119	56.1538
539.38	61.2691
539.641	65.9194
539.901	63.7599
540.162	64.6496
540.423	58.5356
540.684	68.4164
540.945	69.8345
541.205	62.0054
541.466	61.3975
541.727	66.887
541.988	69.3445
542.248	67.3891
542.509	65.7641
542.77	71.5133
543.031	73.7523
543.291	74.6856
543.552	75.1639
543.813	83.8215
544.073	69.7923
544.334	80.4086
544.594	80.7609
544.855	76.8434
545.116	76.6796
545.376	82.0581
545.637	83.4931
545.897	85.3324
546.158	83.8942
546.418	89.9354
546.679	102.106
546.898	78.2128
547.159	92.0185
547.42	98.235
547.681	92.623
547.942	109.555
548.203	109.621
548.464	109.768
548.725	94.5959
548.987	115.662
549.248	119.951
549.509	114.588
549.77	112.993
550.031	119.751
550.292	124.277
550.553	125.61
550.814	148.511
551.075	146.874
551.336	155.925
551.597	173.563
551.858	202.201
552.119	270.891
552.38	1384.51
552.641	14649.6
552.901	517.225
553.162	240.866
553.423	208.879
553.684	173.459
553.945	175.552
554.206	168.624
554.467	179.218
554.727	181.034
554.988	183.914
555.249	183.097
555.51	185.5
555.771	190.106
556.031	204.506
556.292	200.861
556.553	195.567
556.814	204.408
557.074	210.775
557.335	206.28
557.596	229.876
557.856	213.351
558.117	233.429
558.378	224.033
558.638	237.784
558.899	241.279
559.16	241.056
559.42	245.47
559.681	253.595
559.941	255.373
560.202	249.046
560.463	261.208
560.723	268.777
560.984	272.881
561.244	283.623
561.505	298.303
561.765	307.141
562.026	299.441
562.286	308.458
562.547	322.515
562.807	327.884
563.067	333.5
563.328	325.015
563.588	348.212
563.849	346.074
564.109	343.434
564.369	377.415
564.63	367.876
564.89	378.838
565.15	378.502
565.411	393.842
565.671	405.837
565.931	403.888
566.192	398.344
566.452	426.59
566.712	427.969
566.972	441.363
567.232	432.551
567.493	451.676
567.753	462.852
568.013	477.58
568.273	487.332
568.533	493.651
568.794	493.574
569.054	506.333
569.314	519.56
569.574	534.888
569.834	543.698
570.094	560.938
570.354	586.482
570.614	597.973
570.874	623.257
571.134	653.307
571.394	671.989
571.654	703.532
571.914	731.763
572.174	804.52
572.434	852.809
572.694	862.619
572.954	931.052
573.214	1009.23
573.459	1054.1
573.719	1157.78
573.98	1249.39
574.241	1343.57
574.501	1445.31
574.762	1572.57
575.022	1633.17
575.283	1729.8
575.543	1816.72
575.804	1840.54
576.064	1848.01
576.325	1790.77
576.585	1778.48
576.846	1677.37
577.106	1576.69
577.366	1519.09
577.627	1433.26
577.887	1371.87
578.148	1311.26
578.408	1290.59
578.668	1270.07
578.929	1223.99
579.189	1185.17
579.449	1182.53
579.71	1179.31
579.97	1129.2
580.23	1165.64
580.49	1153.3
580.751	1195.06
581.011	1158.68
581.271	1205.79
581.531	1205.45
581.792	1201.8
582.052	1214.4
582.312	1229.59
582.572	1257.62
582.832	1232.6
583.092	1297.31
583.353	1286.96
583.613	1339.08
583.873	1351.26
584.133	1345.86
584.393	1389.8
584.653	1414.83
584.913	1431.19
585.173	1427.06
585.433	1452.12
585.693	1489.76
585.953	1487.37
586.213	1532.47
586.473	1562.39
586.733	1542.02
586.993	1568.81
587.253	1574.93
587.513	1588.21
587.773	1602.02
588.033	1594.67
588.293	1625.92
588.552	1598.23
588.812	1627.36
589.072	1630.78
589.332	1644.86
589.592	1664.8
589.852	1655.18
590.112	1664.62
590.371	1629.5
590.631	1624.58
590.891	1664.8
591.151	1659.99
591.41	1627.29
591.67	1645.61
591.93	1631.04
592.189	1627.01
592.449	1610.04
592.709	1632.08
592.968	1597.98
593.228	1606.09
593.488	1639.71
593.747	1624.67
594.007	1620.58
594.266	1633.97
594.526	1669.23
594.786	1657.66
595.045	1672.54
595.305	1690.32
595.564	1718.09
595.824	1717.21
596.083	1744.11
596.343	1738.84
596.602	1794.08
596.862	1780.64
597.121	1763.63
597.38	1821.1
597.64	1819.35
597.899	1824.46
598.159	1861.01
598.418	1850.17
598.677	1862.02
598.937	1820.14
599.196	1831.13
599.455	1857.47
599.715	1852.96
599.959	1882.05
600.219	1899.65
600.479	1908.13
600.738	1908.3
600.998	1912.13
601.258	1902.48
601.518	1955.28
601.778	1936.92
602.038	1932.01
602.298	1943.74
602.558	1927.78
602.818	1966.2
603.078	1954.62
603.337	1975.84
603.597	1991.67
603.857	1961.67
604.117	1976.24
604.377	1971.92
604.636	1984.2
604.896	2031.78
605.156	2015.18
605.416	1983.63
605.675	1982.16
605.935	2005.47
606.195	2001.81
606.455	2005.45
606.714	2000.31
606.974	1995.28
607.234	1980.28
607.493	2027.05
607.753	2020.96
608.012	2028.42
608.272	2054.25
608.532	2025.58
608.791	2048.66
609.051	2025.57
609.31	2093.35
609.57	2080.53
609.829	2125.82
610.089	2114.95
610.348	2150.5
610.608	2123.37
610.867	2140.82
611.127	2172.66
611.386	2128.05
611.646	2188.43
611.905	2204.4
612.164	2175.04
612.424	2232.61
612.683	2261.78
612.943	2247.88
613.202	2233.29
613.461	2278.5
613.721	2278.75
613.98	2320.78
614.239	2317.69
614.498	2350.25
614.758	2366.2
615.017	2361.24
615.276	2368.22
615.535	2393.86
615.795	2447.06
616.054	2451.32
616.313	2479.93
616.572	2496.96
616.831	2533.4
617.091	2541.22
617.35	2542.32
617.609	2589.22
617.868	2599.63
618.127	2630.69
618.386	2666.52
618.645	2665.59
618.904	2673.36
619.163	2716.7
619.422	2742.2
619.681	2766.34
619.94	2753.17
620.199	2813.94
620.458	2774.45
620.717	2785.92
620.976	2848.24
621.235	2840.38
621.494	2843.7
621.753	2856.25
622.012	2857.75
622.271	2812.79
622.53	2881.99
622.788	2928.75
623.047	2875.96
623.306	2911.44
623.565	2939.87
623.824	2932.35
624.082	2978.77
624.341	2927.86
624.6	2940.67
624.859	2946.32
625.117	2990.31
625.376	3049.8
625.635	3078.44
625.893	3027.72
626.152	3023.67
626.368	3049.61
626.627	3083.95
626.887	3091.97
627.146	3115.22
627.405	3065.9
627.665	3143.12
627.924	3189.12
628.183	3181.67
628.443	3179.9
628.702	3200.58
628.961	3249.35
629.22	3271.6
629.479	3235.77
629.739	3302.46
629.998	3310.55
630.257	3334.52
630.516	3374.13
630.776	3381.55
631.035	3393.43
631.294	3430.36
631.553	3435.57
631.812	3437.06
632.071	3538.49
632.33	3566.67
632.589	3539.91
632.848	3554
633.107	3608.87
633.366	3671.6
633.625	3736.3
633.885	3731.1
634.143	3774.7
634.403	3821.47
634.661	3888.3
634.92	3950.28
635.179	4047.65
635.438	4116.05
635.697	4230.1
635.956	4339.11
636.215	4464.5
636.474	4632.51
636.733	4820.84
636.992	5033.74
637.25	5203.34
637.509	5372.89
637.768	5553.87
638.027	5592.27
638.286	5738.24
638.544	5758.98
638.803	5712.79
639.062	5644.45
639.321	5467.14
639.579	5376.79
639.838	5170.06
640.097	5105.4
640.356	4989.86
640.614	4948.28
640.873	4864.7
641.131	4806
641.39	4802.83
641.649	4820.1
641.907	4752.23
642.166	4775.07
642.424	4778.22
642.683	4814.83
642.942	4795.93
643.2	4815.28
643.459	4856.01
643.717	4857.84
643.976	4903.12
644.234	4826.96
644.493	4966.03
644.751	4899.03
645.009	4968.56
645.268	4957.65
645.526	4950.81
645.785	4964.65
646.043	5051.12
646.301	5081.16
646.56	5062.83
646.818	5135.31
647.076	5102.89
647.335	5159.75
647.593	5242.09
647.851	5204.2
648.109	5206.51
648.368	5261.73
648.626	5249.99
648.884	5322.85
649.142	5438.38
649.401	5360.02
649.659	5445.33
649.917	5458.01
650.175	5495.84
650.433	5558.82
650.691	5585.84
650.949	5650.27
651.208	5639.02
651.466	5729.91
651.724	5705.75
651.982	5723.96
652.24	5842.27
652.498	5885.58
652.756	5950.75
652.979	5993.56
653.238	6054.33
653.497	6016.41
653.755	6109.33
654.014	6137.67
654.273	6158.9
654.531	6256.73
654.79	6312.09
655.049	6391.44
655.307	6452.05
655.566	6573.57
655.824	6600.38
656.083	6648.69
656.342	6725.77
656.6	6830.1
656.859	6845.84
657.117	6988.83
657.376	7082.77
657.634	7135.93
657.893	7139.45
658.151	7203.17
658.41	7198.41
658.668	7213.15
658.927	7304.33
659.185	7303.32
659.443	7410.61
659.702	7277.46
659.96	7274.31
660.219	7296.38
660.477	7379.14
660.735	7415.84
660.994	7337.59
661.252	7350.6
661.51	7373.37
661.768	7344.12
662.027	7393.21
662.285	7406.61
662.543	7404.73
662.802	7370.1
663.06	7408
663.318	7346.06
663.576	7372.29
663.834	7409.91
664.093	7453.96
664.351	7386.76
664.609	7400.84
664.867	7404.73
665.125	7396.92
665.383	7352.33
665.641	7350.84
665.899	7377.52
666.157	7371.15
666.415	7409.07
666.673	7275.61
666.931	7342.16
667.189	7366.74
667.447	7356.12
667.705	7403.56
667.963	7339.09
668.221	7338.59
668.479	7320.85
668.737	7357.06
668.995	7375.19
669.253	7366.89
669.511	7327.93
669.769	7407.87
670.027	7338.17
670.284	7322.03
670.542	7350.42
670.8	7340.56
671.058	7285.44
671.316	7340.18
671.573	7315.72
671.831	7362.42
672.089	7368.73
672.347	7454.72
672.604	7437.25
672.862	7470.48
673.12	7461
673.377	7496.08
673.635	7511.34
673.893	7581.73
674.15	7635.02
674.408	7682.97
674.665	7694.67
674.923	7705.46
675.18	7679.52
675.438	7781.72
675.696	7801.22
675.953	7883.43
676.211	7876.35
676.468	7852.13
676.726	7904.23
676.983	7900.17
677.24	7868.8
677.498	7881.34
677.755	7908.6
678.013	7872.41
678.27	7965.47
678.527	7889.89
678.785	7907.15
679.042	7899.59
679.277	7998.14
679.535	7960.22
679.793	7979.1
680.051	7967.74
680.309	7991.48
680.567	8000.45
680.825	8036.94
681.083	8079.66
681.341	8126.36
681.599	8015.21
681.857	8129.93
682.115	8157.77
682.373	8080.3
682.631	8225.33
682.889	8229.24
683.146	8237.33
683.404	8180.54
683.662	8155.42
683.92	8183.34
684.178	8159.44
684.436	8137.06
684.694	8209.51
684.951	8153.96
685.209	8105.23
685.467	8108.86
685.725	8093.8
685.982	8003.49
686.24	8055.39
686.498	7936.87
686.756	8018.86
687.013	7993.31
687.271	7990.98
687.529	7887.44
687.786	7869.91
688.044	7970.56
688.302	7910.78
688.559	8018.53
688.817	7937.2
689.074	7982.48
689.332	7937.48
689.589	7916.08
689.847	7900.48
690.104	7923.25
690.362	7898.7
690.619	7898.51
690.877	7821.34
691.134	7807.06
691.392	7803.39
691.649	7770.32
691.907	7707.3
692.164	7736.17
692.421	7680.84
692.679	7705.58
692.936	7731.79
693.194	7607.5
693.451	7655.94
693.708	7617
693.966	7536.39
694.223	7585.62
694.48	7552.96
694.737	7586.31
694.995	7624.88
695.252	7535.8
695.509	7493.46
695.766	7513.81
696.023	7459.55
696.281	7435.94
696.538	7418.78
696.795	7332.53
697.052	7398.5
697.309	7352.92
697.566	7311.89
697.823	7253.92
698.08	7210.59
698.338	7171.31
698.595	7175.6
698.852	7181.27
699.109	7099.07
699.366	7093.17
699.623	7081.67
699.88	7100.22
700.137	7102.95
700.393	7033.06
700.65	7080.4
700.907	7042.79
701.164	7021.42
701.421	7003.82
701.678	7047.83
701.935	7017.38
702.192	7024.19
702.448	7026.5
702.705	7112.52
702.962	7055.04
703.219	7049
703.476	6976.33
703.732	6987.15
703.989	6998.52
704.246	6903.81
704.503	6940.83
704.759	6861.5
705.016	6884.36
705.273	6777.1
705.511	6856.11
705.768	6796.67
706.026	6791.83
706.283	6713.39
706.541	6641.03
706.798	6607.22
707.055	6642
707.313	6575.76
707.57	6660.65
707.827	6594.93
708.084	6556.47
708.342	6574.53
708.599	6520.85
708.856	6513.85
709.114	6486.79
709.371	6402.83
709.628	6418.69
709.885	6432.09
710.142	6357.97
710.4	6433.48
710.657	6346.44
710.914	6390.99
711.171	6378.86
711.428	6240.77
711.685	6244.68
711.942	6248.75
712.199	6216.84
712.456	6161.68
712.713	6199.31
712.97	6143.98
713.227	6092.31
713.484	6067.56
713.741	5971.09
713.998	6030.99
714.255	5981.65
714.512	5850.17
714.769	5909.65
715.026	5882.43
715.283	5754.23
715.54	5810.22
715.797	5807.12
716.054	5738.2
716.31	5716.31
716.567	5762.23
716.824	5706.45
717.081	5691.1
717.338	5633.37
717.594	5638.65
717.851	5629.41
718.108	5622.62
718.365	5561.33
718.621	5565.27
718.878	5535.18
719.135	5517.29
719.391	5477.24
719.648	5447.51
719.905	5447.02
720.161	5390.68
720.418	5361.94
720.675	5327.18
720.931	5335.16
721.188	5288.49
721.444	5238.69
721.701	5232.88
721.957	5208.38
722.214	5134.73
722.47	5128.99
722.727	5139.59
722.983	5078.17
723.24	5067.36
723.496	5047.5
723.753	5012.19
724.009	5018.88
724.265	4932.74
724.522	4947.7
724.778	4959.13
725.034	4938.65
725.291	4944.6
725.547	4883.49
725.803	4912.7
726.06	4814.26
726.316	4802.12
726.572	4814.66
726.828	4758.89
727.085	4775.03
727.341	4743.99
727.597	4674.45
727.853	4690.43
728.109	4691.65
728.366	4588.15
728.622	4564.42
728.878	4600.81
729.134	4548.04
729.39	4515.46
729.646	4428.87
729.902	4470.37
730.158	4396.26
730.414	4334.71
730.67	4324.78
730.926	4266.62
731.182	4248.46
731.438	4241.86
731.643	4262
731.9	4119.15
732.156	4227.9
732.413	4227.65
732.67	4150.39
732.927	4181.25
733.183	4129.7
733.44	4157.15
733.697	4132.59
733.953	4133.13
734.21	4155.19
734.466	4112.65
734.723	4145.02
734.98	4141.03
735.236	4149.89
735.493	4180.37
735.749	4141.83
736.006	4152.34
736.262	4195.72
736.519	4152.93
736.775	4314.36
737.032	4318.28
737.288	4284.2
737.544	4346.72
737.801	4347.68
738.057	4352.3
738.314	4368.05
738.57	4396.01
738.826	4351.34
739.083	4260.59
739.339	4277.11
739.595	4183.76
739.852	4079.47
740.108	4080.57
740.364	4016.41
740.621	3987.12
740.877	3945.5
741.133	3919.01
741.389	3903.06
741.645	3867.12
741.902	3834.23
742.158	3773.22
742.414	3732.97
742.67	3696.45
742.926	3729.83
743.182	3688.62
743.438	3647.78
743.694	3615.85
743.951	3629.09
744.207	3567.58
744.463	3533.07
744.719	3537.65
744.975	3541.79
745.231	3488.5
745.487	3452.39
745.743	3453.79
745.998	3460.07
746.254	3390.93
746.51	3417.77
746.766	3395.83
747.022	3359.12
747.278	3357.9
747.534	3368.98
747.79	3322.68
748.046	3311.2
748.301	3302.37
748.557	3263.52
748.813	3244.43
749.069	3261.77
749.324	3234.5
749.58	3219.62
749.836	3204.75
750.092	3205.86
750.347	3201.59
750.603	3175.93
750.859	3128.64
751.114	3129.4
751.37	3116.1
751.625	3084.99
751.881	3069.6
752.137	3096.86
752.392	3026.78
752.648	3008.84
752.903	3000.05
753.159	2927.35
753.414	2964.91
753.67	2948.5
753.925	2911.58
754.181	2901.97
754.436	2884
754.692	2883.37
754.947	2818.51
755.202	2830.74
755.458	2850.59
755.713	2841.53
755.968	2800.37
756.224	2779.17
756.479	2790.4
756.734	2778.05
756.99	2730.13
757.245	2742.46
757.5	2681.08
757.755	2704.58
757.968	2700.07
758.224	2690.3
758.48	2675.55
758.736	2598.52
758.992	2617.66
759.248	2615
759.504	2610.92
759.76	2617.08
760.016	2531.82
760.272	2536.71
760.528	2486.82
760.784	2503.44
761.04	2486.4
761.296	2497.31
761.552	2482.69
761.807	2500.71
762.063	2470.16
762.319	2419.2
762.575	2388.06
762.831	2397.43
763.086	2354.81
763.342	2371.63
763.598	2337.59
763.853	2359.77
764.109	2314.66
764.365	2307.03
764.621	2289.22
764.876	2273.84
765.132	2280.34
765.387	2255
765.643	2217.34
765.899	2267.75
766.154	2232.15
766.41	2192.97
766.665	2191.05
766.921	2204.9
767.176	2150.87
767.432	2187.22
767.687	2146.51
767.943	2137.13
768.198	2107.89
768.454	2100.87
768.709	2046.52
768.965	2047.3
769.22	2044.67
769.475	2055.6
769.731	2023.55
769.986	1961.96
770.242	1988.16
770.497	1968.59
770.752	1955.59
771.007	1935.82
771.263	1920.01
771.518	1891.46
771.773	1910.13
772.028	1867.94
772.284	1875.3
772.539	1857.52
772.794	1805.5
773.049	1804.49
773.304	1801.05
773.56	1801.73
773.815	1785.46
774.07	1767.09
774.325	1767.63
774.58	1741.26
774.835	1721.35
775.09	1735.69
775.345	1707.92
775.6	1708.65
775.855	1709.61
776.11	1661.66
776.365	1660.32
776.62	1651.27
776.875	1640.22
777.13	1624.81
777.385	1600.18
777.64	1604.11
777.895	1574.21
778.149	1589.03
778.404	1568.71
778.659	1536.25
778.914	1537.1
779.169	1531.4
779.424	1512.91
779.678	1548.11
779.933	1494.21
780.188	1495.43
780.442	1489.42
780.697	1465.08
780.952	1445.35
781.207	1441.24
781.461	1444.3
781.716	1428.84
781.97	1423.28
782.225	1400.74
782.48	1415.63
782.734	1382.27
782.989	1367.63
783.243	1373.61
783.498	1352.17
783.752	1361.28
784.007	1334.47
784.253	1308
784.509	1292.09
784.764	1291.5
785.019	1294.68
785.274	1308.28
785.53	1239.57
785.785	1258.23
786.04	1253.95
786.295	1251.19
786.551	1230.55
786.806	1236.98
787.061	1223.31
787.316	1213.05
787.571	1206.97
787.826	1184.58
788.081	1154.81
788.336	1177.92
788.591	1156.13
788.847	1144.09
789.102	1139.2
789.357	1163.95
789.612	1141.89
789.867	1102.81
790.122	1127.85
790.377	1115.9
790.632	1094.73
790.886	1103.44
791.141	1067.18
791.396	1075.37
791.651	1060.88
791.906	1090.14
792.161	1032.46
792.416	1045.21
792.671	1039.02
792.925	1017.87
793.18	1008.57
793.435	990.735
793.69	990.623
793.945	997.13
794.199	989.463
794.454	958.409
794.709	970.682
794.963	969.169
795.218	948.528
795.473	949.273
795.727	950.145
795.982	908.685
796.237	906.902
796.491	922.078
796.746	914.729
797	901.807
797.255	904.056
797.509	882.902
797.764	883.743
798.018	870.09
798.273	871.567
798.527	871.748
798.782	855.782
799.036	862.718
799.291	838.619
799.545	823.309
799.8	850.44
800.054	818.635
800.308	840.69
800.563	826.439
800.817	813.583
801.071	777.913
801.326	792.643
801.58	788.029
801.834	770.8
802.088	758.99
802.343	761.568
802.597	754.827
802.851	753.744
803.105	772.287
803.359	718.567
803.614	745.487
803.868	729.562
804.122	734.038
804.376	706.387
804.63	741.884
804.884	711.888
805.138	694.9
805.392	691.591
805.646	681.071
805.9	694.825
806.154	663.414
806.408	677.425
806.662	679.664
806.916	667.996
807.17	670.504
807.424	651.46
807.678	673.945
807.932	641.766
808.186	631.667
808.439	647.472
808.693	611.759
808.947	615.032
809.201	645.695
809.455	644.285
809.708	611.885
809.962	618.076
810.183	602
810.438	619.76
810.693	595.892
810.947	590.894
811.202	592.423
811.456	595.724
811.711	597.674
811.965	609.623
812.22	575.531
812.474	576.811
812.729	561.519
812.983	572.939
813.237	574.932
813.492	560.629
813.746	569.774
814.001	551.099
814.255	563.667
814.509	531.421
814.764	539.961
815.018	543.892
815.272	524.79
815.526	532.963
815.781	536.454
816.035	519.934
816.289	518.129
816.543	509.318
816.798	503.868
817.052	503.008
817.306	498.51
817.56	505.462
817.814	479.905
818.068	486.024
818.323	487.364
818.577	499.531
818.831	470.991
819.085	472.05
819.339	468.184
819.593	471.168
819.847	472.811
820.101	449.38
820.355	478.049
820.609	451.324
820.863	443.23
821.117	446.738
821.371	437.002
821.624	442.187
821.878	442.873
822.132	441.357
822.386	435.86
822.64	428.115
822.894	426.899
823.148	434.386
823.401	418.978
823.655	401.039
823.909	414.843
824.163	415.938
824.416	402.989
824.67	413.947
824.924	419.847
825.177	406.251
825.431	401.685
825.685	375.194
825.938	403.011
826.192	388.03
826.446	388.409
826.699	378.16
826.953	381.121
827.206	381.931
827.46	389.204
827.713	383.225
827.967	371.511
828.22	370.909
828.474	362.868
828.727	369.258
828.981	365.644
829.234	353.399
829.488	350.515
829.741	356.365
829.994	348.898
830.248	353.874
830.501	358.975
830.754	366.974
831.008	328.385
831.261	341.438
831.514	345.481
831.767	337.936
832.021	350.492
832.274	338.24
832.527	320.21
832.78	326.691
833.034	335.024
833.287	334.452
833.54	328.416
833.793	323.864
834.046	305.791
834.299	320.42
834.552	318.105
834.805	321.241
835.058	327.263
835.311	306.868
835.564	305.543
835.817	301.175
836.07	302.09
836.314	305.973
836.568	321.531
836.821	284.334
837.075	305.605
837.329	299.728
837.583	286.676
837.836	293.105
838.09	285.325
838.344	282.319
838.598	286
838.851	288.718
839.105	284.747
839.359	293.496
839.612	276.355
839.866	282.986
840.119	289.07
840.373	272.092
840.627	265.497
840.88	275.466
841.134	257.925
841.387	261.301
841.641	265.219
841.894	266.042
842.148	274.072
842.401	267.025
842.655	256.785
842.908	267.771
843.161	260.076
843.415	247.947
843.668	259.033
843.922	255.437
844.175	251.1
844.428	254.984
844.682	252.432
844.935	258.684
845.188	239.825
845.442	236.543
845.695	247.468
845.948	246.812
846.201	244.631
846.455	237.517
846.708	239.428
846.961	247.339
847.214	242.606
847.467	227.432
847.72	236.403
847.973	236.622
848.227	241.854
848.48	227.199
848.733	240.061
848.986	226.448
849.239	218.44
849.492	227.744
849.745	222.688
849.998	218.803
850.251	215.53
850.504	227.257
850.757	219.953
851.01	223.184
851.263	217.565
851.515	219.334
851.768	220.172
852.021	208.292
852.274	211.869
852.527	198.681
852.78	214.05
853.032	210.023
853.285	213.52
853.538	211.024
853.791	208.96
854.043	205.671
854.296	205.459
854.549	190.091
854.801	200.928
855.054	198.102
855.307	194.383
855.559	200.31
855.812	201.957
856.065	190.594
856.317	192.956
856.57	191.4
856.822	186.531
857.075	180.773
857.327	184.052
857.58	190.877
857.832	177.636
858.085	181.689
858.337	175.703
858.589	184.344
858.842	183.555
859.094	174.336
859.347	180.375
859.599	183.254
859.851	181.995
860.104	189.209
860.356	181.923
860.608	177.543
860.861	175.086
861.113	182.805
861.365	166.826
861.617	173.205
861.869	164.712
862.112	171.998
862.365	170.041
862.618	167.941
862.871	164.074
863.124	165.908
863.377	169.409
863.63	163.858
863.883	169.537
864.136	165.475
864.389	171.378
864.642	158.109
864.894	171.145
865.147	157.656
865.4	157.86
865.653	162.583
865.906	146.733
866.159	147.57
866.412	160.077
866.664	157.346
866.917	144.133
867.17	157.225
867.423	147.11
867.675	151.435
867.928	149.59
868.181	150.276
868.433	145.081
868.686	150.821
868.939	151.517
869.191	149.666
869.444	145.357
869.697	143.133
869.949	139.886
870.202	141.086
870.454	145.497
870.707	141.835
870.959	140.706
871.212	138.307
871.464	134.554
871.717	137.303
871.969	144.151
872.222	134.732
872.474	144.815
872.727	138.002
872.979	127.97
873.231	133.835
873.484	128.42
873.736	138.66
873.988	134
874.241	132.845
874.493	124.971
874.745	134.604
874.998	130.61
875.25	129.181
875.502	125.162
875.754	127.712
876.006	133.46
876.259	127.224
876.511	127.726
876.763	121.224
877.015	122.438
877.267	126.343
877.519	123.658
877.771	129.594
878.023	126.735
878.276	118.811
878.528	118.308
878.78	121.047
879.031	120.161
879.284	125.639
879.535	129.18
879.787	121.494
880.039	115.946
880.291	105.895
880.543	115.576
880.795	112.273
881.047	114.269
881.299	114.443
881.551	113.13
881.802	119.382
882.054	112.305
882.306	109.361
882.558	106.825
882.809	108.498
883.061	115.532
883.313	105.649
883.565	113.085
883.816	118.725
884.068	114.088
884.319	103.547
884.571	116.012
884.823	107.316
885.074	110.423
885.326	99.7423
885.577	105.36
885.829	102.412
886.08	106.782
886.332	96.9418
886.583	105.024
886.835	108.717
887.086	99.788
887.338	86.8678
887.589	103.906
887.841	107.754
888.044	105.913
888.296	101.839
888.548	86.2241
888.8	100.155
889.053	105.035
889.305	88.7329
889.557	102.662
889.809	96.9585
890.061	102.287
890.313	95.5975
890.566	95.7012
890.818	92.6883
891.07	89.2576
891.322	92.3961
891.574	98.4821
891.826	86.5548
892.078	90.2984
892.33	90.5542
892.582	91.8055
892.834	94.5883
893.086	80.583
893.338	93.6971
893.59	91.8838
893.842	94.0545
894.094	88.9855
894.346	94.0169
894.597	88.8551
894.849	86.1594
895.101	85.1111
895.353	86
895.605	90.2609
895.857	88.5193
896.108	78.9239
896.36	83.7295
896.612	80
896.864	78
897.115	83.7391
897.367	85.1981
897.619	85
897.87	81.9335
898.122	77.2491
898.374	79.9408
898.625	78.9722
898.877	82.7013
899.128	79.6288
899.38	88.6747
899.631	82
899.883	79
899.984	85.4068