File: PL_230124_Amostra_HPHT_sem_polir_01.txt
#Acq. time (s)=	3
#Accumulations=	2
#Range (nm)=	520...900
#Windows=	16
#Auto scanning=	On
#Autofocus=	Off
#AutoExposure=	Off
#Spike filter=	Multiple accum.
#Delay time (s)=	0
#Binning=	1
#Readout mode=	Signal
#DeNoise=	Off
#ICS correction=	Off
#Dark correction=	Off
#Inst. Process=	Off
#Detector temperature (°C)=	-59.98
#Instrument=	LabRAM HR Evol
#Detector=	Syncerity OE
#Objective=	x50_VIS
#Grating=	600 (500nm)
#ND Filter=	10%
#Laser=	514nm_Edge
#Hole=	199.981
#Range=	Auto
#StageXY=	Marzhauser
#StageZ=	Marzhauser
#X (µm)=	-58.2
#Y (µm)=	8027.4
#Z (µm)=	33.3
#Full time(mm:ss)=	2:38
#Project=
#Sample=
#Site=
#Title=	PL_230124_Amostra_HPHT_sem_polir
#Remark=
#Date=	31.01.2024 11:13
#Acquired=	31.01.2024 11:13:04
520.042	42
520.304	36.3586
520.565	39.0594
520.827	37.5116
521.089	37.0791
521.351	42.6419
521.612	37.3912
521.874	37.8917
522.136	38.8814
522.397	40.2561
522.659	41
522.921	38.1467
523.182	37.8428
523.444	37.8324
523.705	38.2922
523.967	40.3749
524.229	38.5902
524.49	37.0361
524.752	42.0512
525.013	41.865
525.275	38.6543
525.536	39.5041
525.798	39.7718
526.059	47.8033
526.321	43.3912
526.582	42.7113
526.844	43.4033
527.105	44.0745
527.367	40
527.628	44.6807
527.889	44.7016
528.151	48.0524
528.412	42.8044
528.674	42.2564
528.935	42.8531
529.196	42.8217
529.458	40.6131
529.719	40.345
529.98	46
530.242	45.8718
530.503	49.7622
530.764	44.0839
531.025	47
531.287	44.4406
531.548	46.5105
531.809	47.9977
532.07	43.0699
532.332	51.0466
532.593	47.1958
532.854	49
533.115	49
533.376	45.4324
533.638	51.2234
533.899	46.9111
534.16	48.2051
534.421	48.6232
534.682	54.1957
534.943	54
535.204	49.9556
535.465	50.1943
535.726	50.0942
535.987	58.053
536.248	58.3939
536.509	55.9801
536.77	51.3381
537.031	50.7025
537.292	50.5225
537.553	48.0938
537.814	54.7393
538.075	54.1476
538.336	51.5626
538.597	53.0119
538.858	57.1007
539.119	59.4926
539.38	53.4653
539.641	58.4497
539.901	56.0902
540.162	58.243
540.423	62.4066
540.684	61.7041
540.945	60.5949
541.205	62.1574
541.466	54.7617
541.727	65.032
541.988	57.3439
542.248	59.1557
542.509	62.0792
542.77	69.6479
543.031	68.8761
543.291	62.8994
543.552	70.1904
543.813	71.0318
544.073	77.215
544.334	66.6598
544.594	64.325
544.855	74.8062
545.116	68.2387
545.376	65.2557
545.637	81.4657
545.897	77.7168
546.158	74.3617
546.418	71.213
546.679	80.8511
546.898	75.9399
547.159	83.8355
547.42	76.0988
547.681	89.6111
547.942	80.1571
548.203	84.1465
548.464	84.0339
548.725	86
548.987	89.0759
549.248	89.3872
549.509	79.061
549.77	91.8644
550.031	97.4885
550.292	105.844
550.553	93.7924
550.814	109.81
551.075	105.126
551.336	117.911
551.597	127.138
551.858	141.434
552.119	211.428
552.38	1087.9
552.641	10595.9
552.901	354.971
553.162	170.695
553.423	136.048
553.684	123.56
553.945	127.425
554.206	130
554.467	129.166
554.727	136.48
554.988	126.339
555.249	133.032
555.51	126.815
555.771	132.941
556.031	137.907
556.292	129.9
556.553	132.619
556.814	143.122
557.074	148.108
557.335	148.003
557.596	142.051
557.856	157.856
558.117	157.895
558.378	154.021
558.638	156.642
558.899	155.914
559.16	156.426
559.42	163.333
559.681	166.156
559.941	166.938
560.202	168.31
560.463	172.019
560.723	176.135
560.984	182.363
561.244	184.702
561.505	178.949
561.765	186.835
562.026	200.162
562.286	193.292
562.547	202.757
562.807	209.917
563.067	202.545
563.328	211.093
563.588	219.866
563.849	226.753
564.109	216.233
564.369	224.887
564.63	231.155
564.89	229.675
565.15	227.359
565.411	234.624
565.671	242.925
565.931	242.525
566.192	246.331
566.452	256.955
566.712	255.43
566.972	267.496
567.232	261.947
567.493	266.334
567.753	275.102
568.013	280.623
568.273	288.511
568.533	301.015
568.794	301.574
569.054	305.742
569.314	324.833
569.574	328.283
569.834	323.341
570.094	319.702
570.354	344.12
570.614	364.941
570.874	356.695
571.134	385.084
571.394	376.806
571.654	414.174
571.914	436.833
572.174	450.049
572.434	471.383
572.694	511.461
572.954	508.565
573.214	561.776
573.459	581.884
573.719	606.335
573.98	691.303
574.241	724.914
574.501	791.827
574.762	874.471
575.022	926.056
575.283	978.739
575.543	1029.96
575.804	1054.62
576.064	1056.18
576.325	998.045
576.585	982.634
576.846	907.661
577.106	893.145
577.366	834.826
577.627	802.219
577.887	754.939
578.148	732.786
578.408	700.754
578.668	676.631
578.929	645.97
579.189	685.043
579.449	670.293
579.71	647.11
579.97	653.334
580.23	638.657
580.49	641.75
580.751	650.746
581.011	654.876
581.271	661.861
581.531	668.925
581.792	691.164
582.052	693.124
582.312	686.978
582.572	691.047
582.832	716.307
583.092	726.42
583.353	711.846
583.613	739.311
583.873	764.984
584.133	755.061
584.393	767.281
584.653	778.83
584.913	811.617
585.173	813.554
585.433	828.717
585.693	829.303
585.953	845.977
586.213	857.957
586.473	874.373
586.733	887.008
586.993	882.997
587.253	894.987
587.513	887.514
587.773	920.073
588.033	921.462
588.293	904.224
588.552	903.611
588.812	915.521
589.072	923.955
589.332	936.743
589.592	947.416
589.852	956.828
590.112	935.597
590.371	943.528
590.631	938.851
590.891	926.989
591.151	910.095
591.41	918.834
591.67	916.27
591.93	918.412
592.189	908.904
592.449	913.597
592.709	888.568
592.968	909.04
593.228	905.768
593.488	897.365
593.747	895.851
594.007	915.909
594.266	914.86
594.526	953.278
594.786	922.538
595.045	938.112
595.305	928.633
595.564	947.593
595.824	953.345
596.083	972.481
596.343	991.291
596.602	998.936
596.862	986.052
597.121	1016.38
597.38	1016.37
597.64	1031.95
597.899	1040.03
598.159	1027.46
598.418	1047.34
598.677	1036.24
598.937	1044.98
599.196	1064.53
599.455	1034.98
599.715	1067.54
599.959	1065.7
600.219	1061.4
600.479	1041.91
600.738	1072.4
600.998	1057.89
601.258	1078.68
601.518	1062.02
601.778	1080.2
602.038	1061.66
602.298	1096.17
602.558	1097.29
602.818	1080.92
603.078	1090.25
603.337	1094.5
603.597	1104.44
603.857	1087.97
604.117	1073.25
604.377	1113.83
604.636	1069.24
604.896	1098.61
605.156	1114.13
605.416	1104.04
605.675	1108.17
605.935	1119.3
606.195	1143.65
606.455	1113.23
606.714	1096.32
606.974	1092.87
607.234	1132.65
607.493	1136.83
607.753	1141.65
608.012	1104.12
608.272	1104.6
608.532	1125.69
608.791	1124.36
609.051	1119.42
609.31	1145.09
609.57	1143.22
609.829	1155.67
610.089	1163.69
610.348	1205.95
610.608	1169.35
610.867	1192.38
611.127	1209.17
611.386	1209.83
611.646	1190.89
611.905	1213.65
612.164	1187.07
612.424	1221.29
612.683	1218.31
612.943	1237.17
613.202	1261.25
613.461	1261.91
613.721	1267.32
613.98	1274.07
614.239	1272.86
614.498	1314.6
614.758	1289.55
615.017	1320.76
615.276	1328.56
615.535	1312.74
615.795	1363.18
616.054	1356.12
616.313	1351.71
616.572	1365.97
616.831	1393.66
617.091	1384.56
617.35	1394.77
617.609	1424
617.868	1434.49
618.127	1440.24
618.386	1439.62
618.645	1447.52
618.904	1455.73
619.163	1496.76
619.422	1491.01
619.681	1508.95
619.94	1497.14
620.199	1530.97
620.458	1542.23
620.717	1554.23
620.976	1538.11
621.235	1533.41
621.494	1550.41
621.753	1516.66
622.012	1581.6
622.271	1545.42
622.53	1558.6
622.788	1599.18
623.047	1561.15
623.306	1562.98
623.565	1586.87
623.824	1590.16
624.082	1606.36
624.341	1570.87
624.6	1605.53
624.859	1607.88
625.117	1584.68
625.376	1623.31
625.635	1581.84
625.893	1655.67
626.152	1683.15
626.368	1647.87
626.627	1685.19
626.887	1658.91
627.146	1677.6
627.405	1646.79
627.665	1699.94
627.924	1725.01
628.183	1716.94
628.443	1703.11
628.702	1683.77
628.961	1765.17
629.22	1746.92
629.479	1779.69
629.739	1757.02
629.998	1786.21
630.257	1776.94
630.516	1806
630.776	1805.85
631.035	1785.4
631.294	1803.63
631.553	1862.42
631.812	1894.32
632.071	1879.9
632.33	1908.96
632.589	1903.51
632.848	1927.22
633.107	1895.83
633.366	1941.75
633.625	1945.68
633.885	1941.41
634.143	1962.04
634.403	2012.37
634.661	2041.24
634.92	2053.95
635.179	2112.11
635.438	2148.98
635.697	2153.43
635.956	2225.38
636.215	2256.45
636.474	2373.07
636.733	2468.57
636.992	2561.18
637.25	2713.47
637.509	2852.2
637.768	3015.05
638.027	3080.7
638.286	3102.15
638.544	3062.94
638.803	2964.04
639.062	2936.2
639.321	2844.16
639.579	2788.06
639.838	2716.54
640.097	2677.7
640.356	2630.58
640.614	2576.36
640.873	2568.18
641.131	2545.33
641.39	2551.57
641.649	2505.43
641.907	2500.37
642.166	2502.8
642.424	2499.36
642.683	2490.82
642.942	2506.54
643.2	2523.09
643.459	2524.74
643.717	2512.09
643.976	2554.15
644.234	2548.15
644.493	2608.48
644.751	2554.64
645.009	2582.97
645.268	2586.19
645.526	2611.69
645.785	2642.18
646.043	2651.63
646.301	2641.25
646.56	2637.65
646.818	2633.26
647.076	2684.93
647.335	2687.21
647.593	2677.71
647.851	2672.41
648.109	2733.34
648.368	2738.05
648.626	2788.92
648.884	2767.36
649.142	2807.72
649.401	2827.76
649.659	2828.11
649.917	2809.05
650.175	2824.69
650.433	2910.07
650.691	2930.46
650.949	2935.41
651.208	2949.67
651.466	2976.92
651.724	3013.21
651.982	3001.27
652.24	3001.65
652.498	3017.74
652.756	3099.39
652.979	3077.74
653.238	3101.79
653.497	3124.22
653.755	3142.44
654.014	3196.07
654.273	3173.91
654.531	3239.88
654.79	3267.67
655.049	3344.66
655.307	3356.45
655.566	3412.46
655.824	3419.33
656.083	3478.43
656.342	3421.07
656.6	3497.35
656.859	3567.73
657.117	3598.69
657.376	3598.81
657.634	3658.28
657.893	3672.56
658.151	3729.81
658.41	3693.9
658.668	3721.18
658.927	3766.7
659.185	3767.12
659.443	3762.93
659.702	3780.6
659.96	3754.31
660.219	3826.89
660.477	3787.16
660.735	3743.58
660.994	3779.07
661.252	3834.1
661.51	3837.42
661.768	3801.96
662.027	3829.78
662.285	3814.25
662.543	3789.86
662.802	3835.15
663.06	3827.48
663.318	3821.95
663.576	3839.03
663.834	3836
664.093	3825.23
664.351	3825.07
664.609	3781.61
664.867	3820.91
665.125	3780.95
665.383	3813.9
665.641	3798.68
665.899	3803.99
666.157	3812.82
666.415	3794.5
666.673	3784.36
666.931	3765.05
667.189	3776.58
667.447	3767.48
667.705	3770.73
667.963	3794.22
668.221	3785
668.479	3796.51
668.737	3799.25
668.995	3807.05
669.253	3813.41
669.511	3817.05
669.769	3762.92
670.027	3765.33
670.284	3830.77
670.542	3834.84
670.8	3800.76
671.058	3824.54
671.316	3812.75
671.573	3795.24
671.831	3836.89
672.089	3808.33
672.347	3839.21
672.604	3846.9
672.862	3869.97
673.12	3860.16
673.377	3901.31
673.635	3923.06
673.893	3951.75
674.15	3949.53
674.408	3941.17
674.665	3998.8
674.923	3945.76
675.18	3980.41
675.438	3994.04
675.696	4040.11
675.953	4026.14
676.211	4095.3
676.468	4060.54
676.726	4050.73
676.983	4056.1
677.24	4084.57
677.498	4039.19
677.755	4063.85
678.013	4103.46
678.27	4037.43
678.527	4106.17
678.785	4107.82
679.042	4137.27
679.277	4138.37
679.535	4136.34
679.793	4064.59
680.051	4130.15
680.309	4047.95
680.567	4161.07
680.825	4191.23
681.083	4131.84
681.341	4178.83
681.599	4176.19
681.857	4246.41
682.115	4158.1
682.373	4237.74
682.631	4218.36
682.889	4284.36
683.146	4240.64
683.404	4285.27
683.662	4229.38
683.92	4234.52
684.178	4249.67
684.436	4206.01
684.694	4235.99
684.951	4158.09
685.209	4154.05
685.467	4210.9
685.725	4220.48
685.982	4173.52
686.24	4167.54
686.498	4184.23
686.756	4198.54
687.013	4192.3
687.271	4100.36
687.529	4142.54
687.786	4120.35
688.044	4124.78
688.302	4138.73
688.559	4125.29
688.817	4170.6
689.074	4139.04
689.332	4086.08
689.589	4141.95
689.847	4110.47
690.104	4091.05
690.362	4111.19
690.619	4083.73
690.877	4113.47
691.134	4044.94
691.392	4007.24
691.649	4054.5
691.907	4004.83
692.164	3982.16
692.421	3987.9
692.679	3967.91
692.936	3920.66
693.194	3949.75
693.451	3970.78
693.708	3944.11
693.966	3981.62
694.223	3943.96
694.48	3908.78
694.737	3920.33
694.995	3916.92
695.252	3940.89
695.509	3944.24
695.766	3897.58
696.023	3822.96
696.281	3845.92
696.538	3853.04
696.795	3867.56
697.052	3810.81
697.309	3811.21
697.566	3810.48
697.823	3748.72
698.08	3787.62
698.338	3747.43
698.595	3741.59
698.852	3758.25
699.109	3704.44
699.366	3696.01
699.623	3708.46
699.88	3702.52
700.137	3646.88
700.393	3666.31
700.65	3712.08
700.907	3658.22
701.164	3659.88
701.421	3668.82
701.678	3684.25
701.935	3674.95
702.192	3671.57
702.448	3685.1
702.705	3685.42
702.962	3679.3
703.219	3654.74
703.476	3646.38
703.732	3651.35
703.989	3643.99
704.246	3617.74
704.503	3670.25
704.759	3665.53
705.016	3606.88
705.273	3570.46
705.511	3562.07
705.768	3529.17
706.026	3536.16
706.283	3534.26
706.541	3500.19
706.798	3490.24
707.055	3473.76
707.313	3479.45
707.57	3486
707.827	3468.95
708.084	3359.45
708.342	3428.76
708.599	3454.56
708.856	3392.84
709.114	3386.11
709.371	3404.74
709.628	3391.56
709.885	3361.28
710.142	3374.13
710.4	3363.29
710.657	3342.7
710.914	3356.35
711.171	3353.87
711.428	3330.32
711.685	3333.98
711.942	3279.84
712.199	3241.75
712.456	3266.31
712.713	3213.94
712.97	3205.39
713.227	3160.96
713.484	3185.83
713.741	3113.5
713.998	3166.03
714.255	3164.11
714.512	3095.8
714.769	3075.94
715.026	3070.02
715.283	3043.41
715.54	3058.28
715.797	3034.8
716.054	3022.38
716.31	2982.91
716.567	3010.81
716.824	2999.39
717.081	3008.02
717.338	2992.97
717.594	2964.94
717.851	2993.64
718.108	2982.7
718.365	2923.4
718.621	2937.47
718.878	2885.01
719.135	2890.02
719.391	2882.39
719.648	2901.51
719.905	2887.46
720.161	2860.22
720.418	2851.5
720.675	2832.99
720.931	2799.26
721.188	2783.17
721.444	2764.29
721.701	2756.68
721.957	2746.64
722.214	2730.09
722.47	2728.22
722.727	2716.25
722.983	2669.97
723.24	2683.26
723.496	2625.02
723.753	2643.84
724.009	2658.29
724.265	2636.51
724.522	2636.74
724.778	2619.71
725.034	2627.53
725.291	2586.99
725.547	2566.89
725.803	2613.01
726.06	2589.18
726.316	2557.65
726.572	2561.7
726.828	2522.83
727.085	2511.62
727.341	2491.15
727.597	2485.78
727.853	2457.89
728.109	2469.56
728.366	2463.01
728.622	2419.19
728.878	2410.06
729.134	2409.42
729.39	2382.44
729.646	2390.47
729.902	2353.83
730.158	2350.95
730.414	2300.28
730.67	2253.69
730.926	2230.34
731.182	2256.38
731.438	2276.49
731.643	2262
731.9	2248.38
732.156	2259.01
732.413	2239.63
732.67	2210.94
732.927	2252.57
733.183	2194.51
733.44	2219.14
733.697	2223.61
733.953	2254.54
734.21	2241.19
734.466	2177.57
734.723	2191.5
734.98	2194.4
735.236	2181.6
735.493	2238.9
735.749	2203.33
736.006	2213.57
736.262	2209.09
736.519	2249.43
736.775	2261.52
737.032	2281.45
737.288	2292.04
737.544	2233.06
737.801	2284.61
738.057	2320.83
738.314	2307.36
738.57	2295.58
738.826	2249.94
739.083	2270.64
739.339	2235.98
739.595	2199.49
739.852	2169.97
740.108	2134.52
740.364	2117.66
740.621	2100.2
740.877	2059.35
741.133	2079.34
741.389	2055.68
741.645	2046.74
741.902	2053.94
742.158	2037.51
742.414	1981.79
742.67	1984.1
742.926	1972.76
743.182	1958.62
743.438	1918.98
743.694	1943.92
743.951	1931.15
744.207	1905.34
744.463	1905.99
744.719	1881.95
744.975	1905.41
745.231	1830.12
745.487	1875.26
745.743	1841.95
745.998	1861.66
746.254	1846.72
746.51	1796.73
746.766	1834.07
747.022	1800.21
747.278	1804.61
747.534	1802.01
747.79	1771.59
748.046	1781.09
748.301	1761.26
748.557	1757.63
748.813	1769.73
749.069	1746.72
749.324	1738.31
749.58	1725.74
749.836	1747.49
750.092	1720.55
750.347	1727.38
750.603	1671.37
750.859	1681.1
751.114	1691.7
751.37	1687.44
751.625	1684.12
751.881	1656.19
752.137	1641.97
752.392	1605.26
752.648	1650.27
752.903	1624.38
753.159	1621.14
753.414	1640.21
753.67	1614.88
753.925	1602.7
754.181	1560.88
754.436	1528.27
754.692	1527.2
754.947	1546.68
755.202	1549.14
755.458	1550.71
755.713	1527.85
755.968	1530.17
756.224	1506.38
756.479	1523.75
756.734	1490.57
756.99	1450.5
757.245	1456.31
757.5	1448.25
757.755	1444.97
757.968	1422.03
758.224	1408.31
758.48	1406.45
758.736	1445.66
758.992	1383.12
759.248	1397.61
759.504	1423.64
759.76	1386.01
760.016	1416.15
760.272	1381.11
760.528	1337.4
760.784	1366.74
761.04	1343.14
761.296	1331.02
761.552	1346.99
761.807	1320.74
762.063	1325.73
762.319	1305.82
762.575	1303.08
762.831	1282.45
763.086	1292.67
763.342	1329.5
763.598	1272.32
763.853	1273.22
764.109	1273.81
764.365	1279.62
764.621	1260.34
764.876	1253.87
765.132	1222.67
765.387	1239.88
765.643	1222.85
765.899	1213.91
766.154	1209.29
766.41	1165.43
766.665	1186.8
766.921	1188.89
767.176	1207.67
767.432	1188.59
767.687	1159.88
767.943	1145.09
768.198	1154.14
768.454	1139.23
768.709	1110.6
768.965	1124.16
769.22	1110.9
769.475	1095.64
769.731	1108.95
769.986	1073.17
770.242	1101.93
770.497	1066.92
770.752	1074.14
771.007	1053.86
771.263	1057.85
771.518	1067.37
771.773	1028.84
772.028	1043.17
772.284	1031.27
772.539	1030.2
772.794	1013.74
773.049	998.578
773.304	1006.59
773.56	998.561
773.815	982.442
774.07	974.746
774.325	971.658
774.58	963.714
774.835	947.695
775.09	936.878
775.345	950.233
775.6	948.668
775.855	937.93
776.11	916.129
776.365	916.782
776.62	896.782
776.875	909.647
777.13	875.902
777.385	891.137
777.64	878.129
777.895	872.351
778.149	886.814
778.404	866.646
778.659	856.492
778.914	843.646
779.169	846.56
779.424	848.483
779.678	834.076
779.933	849.113
780.188	829.653
780.442	811.241
780.697	820.916
780.952	802.042
781.207	807.378
781.461	796.55
781.716	806.073
781.97	793.093
782.225	795.472
782.48	740.721
782.734	769.034
782.989	754.795
783.243	748.343
783.498	754.492
783.752	743.185
784.007	712.263
784.253	725.941
784.509	743.218
784.764	741.489
785.019	725.079
785.274	723.133
785.53	693.968
785.785	709.517
786.04	678.246
786.295	701.131
786.551	673.145
786.806	686.533
787.061	677.604
787.316	673.794
787.571	671.001
787.826	672.914
788.081	646.933
788.336	669.058
788.591	652.874
788.847	626.047
789.102	626.053
789.357	642.326
789.612	640.486
789.867	622.865
790.122	634.428
790.377	605.388
790.632	622.363
790.886	619.473
791.141	611.847
791.396	617.408
791.651	587.464
791.906	594.451
792.161	579.845
792.416	595.18
792.671	585.925
792.925	584.14
793.18	571.932
793.435	572.362
793.69	556.241
793.945	555.442
794.199	536.146
794.454	540.485
794.709	554.616
794.963	534.772
795.218	536.321
795.473	536.36
795.727	521.693
795.982	535.188
796.237	513.069
796.491	518.866
796.746	512.748
797	508.728
797.255	508.339
797.509	500.001
797.764	493.136
798.018	499.518
798.273	498.941
798.527	484.868
798.782	478.182
799.036	476.053
799.291	470.273
799.545	473.022
799.8	480.991
800.054	467.936
800.308	472.971
800.563	470.361
800.817	467.127
801.071	453.54
801.326	446.422
801.58	440.237
801.834	471.594
802.088	431.56
802.343	430.606
802.597	451.544
802.851	423.307
803.105	425.596
803.359	444.609
803.614	431.874
803.868	423.49
804.122	428.433
804.376	409.694
804.63	407.886
804.884	419.615
805.138	397.626
805.392	393.984
805.646	403.938
805.9	390.689
806.154	400.453
806.408	379.759
806.662	376.035
806.916	395.467
807.17	387.195
807.424	369.069
807.678	391.361
807.932	371.054
808.186	373.196
808.439	380.325
808.693	363.382
808.947	374.671
809.201	371.586
809.455	359.613
809.708	356.804
809.962	351.915
810.183	366
810.438	367.998
810.693	359.8
810.947	338.154
811.202	346.076
811.456	350.73
811.711	343.076
811.965	340.207
812.22	345.536
812.474	327.478
812.729	321.4
812.983	321.533
813.237	322.699
813.492	330.907
813.746	319.084
814.001	319.417
814.255	316.81
814.509	315.454
814.764	311.663
815.018	307.501
815.272	306.081
815.526	317.317
815.781	287.274
816.035	306.317
816.289	292.983
816.543	303.279
816.798	291.199
817.052	301.022
817.306	284.244
817.56	295.787
817.814	292.067
818.068	285.372
818.323	278.666
818.577	281.067
818.831	277.925
819.085	270.094
819.339	274.323
819.593	269.407
819.847	268.787
820.101	277.154
820.355	279.055
820.609	277.423
820.863	260.746
821.117	265.423
821.371	258.47
821.624	254.238
821.878	251.389
822.132	258.356
822.386	246.041
822.64	256.457
822.894	254.31
823.148	245.106
823.401	240.224
823.655	236.037
823.909	240.348
824.163	245.128
824.416	237.917
824.67	237.455
824.924	229.4
825.177	237.188
825.431	227.993
825.685	227.352
825.938	232.096
826.192	228.826
826.446	231.539
826.699	224.12
826.953	231.55
827.206	227.314
827.46	221.232
827.713	212.663
827.967	217.822
828.22	214.693
828.474	217.109
828.727	224.125
828.981	210.847
829.234	214.268
829.488	218.353
829.741	215.941
829.994	211.734
830.248	208.747
830.501	220.631
830.754	206.225
831.008	197.459
831.261	205.646
831.514	204.396
831.767	202.717
832.021	200.416
832.274	197.651
832.527	203.604
832.78	200.773
833.034	201.673
833.287	189.235
833.54	198.85
833.793	194.351
834.046	188.601
834.299	185.453
834.552	177.152
834.805	187.001
835.058	188.709
835.311	188.129
835.564	182.89
835.817	182.297
836.07	183.62
836.314	183.997
836.568	185.873
836.821	174.172
837.075	176.238
837.329	181.896
837.583	180.237
837.836	178.721
838.09	175.182
838.344	171.906
838.598	162.783
838.851	168.347
839.105	166.515
839.359	182.701
839.612	171.785
839.866	170.734
840.119	162.663
840.373	169.811
840.627	174.632
840.88	157.81
841.134	166.977
841.387	165.679
841.641	167.067
841.894	152.876
842.148	169.739
842.401	164.074
842.655	160.949
842.908	164.969
843.161	162.611
843.415	162.946
843.668	159.758
843.922	158.503
844.175	162.743
844.428	163.146
844.682	142.996
844.935	154.699
845.188	152.126
845.442	156.755
845.695	142.718
845.948	155.335
846.201	141.593
846.455	140.301
846.708	151.192
846.961	143.827
847.214	150.915
847.467	149.349
847.72	145.188
847.973	141.689
848.227	150.036
848.48	139.044
848.733	143.743
848.986	136.57
849.239	147.753
849.492	141.06
849.745	140.039
849.998	138.107
850.251	124.203
850.504	136.841
850.757	139.644
851.01	136.733
851.263	131.986
851.515	133.023
851.768	136.574
852.021	133.168
852.274	129.125
852.527	131.775
852.78	127.084
853.032	134.921
853.285	130.886
853.538	124.576
853.791	133.284
854.043	115.024
854.296	125.71
854.549	129.135
854.801	123.731
855.054	126.362
855.307	124.365
855.559	118.527
855.812	117.794
856.065	125.535
856.317	120.932
856.57	116.752
856.822	124.961
857.075	117.558
857.327	116.68
857.58	117.09
857.832	116.9
858.085	118.311
858.337	118.475
858.589	122.516
858.842	115.995
859.094	114.482
859.347	118.213
859.599	109.859
859.851	113.773
860.104	116.781
860.356	105.586
860.608	119.071
860.861	115.295
861.113	103.415
861.365	114.571
861.617	102.842
861.869	103.489
862.112	115.992
862.365	115.853
862.618	108.016
862.871	107.783
863.124	106.105
863.377	109.62
863.63	107.869
863.883	111.53
864.136	111.824
864.389	107.638
864.642	109.417
864.894	96.7947
865.147	108.566
865.4	102.229
865.653	100.393
865.906	106.095
866.159	112.306
866.412	99.795
866.664	104.262
866.917	102.265
867.17	103.516
867.423	103.033
867.675	104.173
867.928	103.179
868.181	98.4067
868.433	99.5107
868.686	97.7475
868.939	93.0668
869.191	107.285
869.444	90.5741
869.697	89.7823
869.949	92.6677
870.202	103.18
870.454	90.2062
870.707	94.7471
870.959	87.6126
871.212	97.6083
871.464	88.1115
871.717	87.4397
871.969	87.9705
872.222	92.9637
872.474	85.5928
872.727	89.9026
872.979	92.1645
873.231	83.2565
873.484	92.5748
873.736	91.4157
873.988	85.4746
874.241	86.4423
874.493	88.7606
874.745	90.6534
874.998	88.1622
875.25	93.4865
875.502	80.5826
875.754	83.8105
876.006	77.8432
876.259	88.7159
876.511	90.2739
876.763	86.1309
877.015	81.597
877.267	80.5502
877.519	81.4137
877.771	86.384
878.023	79.7608
878.276	80.3452
878.528	79.4993
878.78	78.8851
879.031	81.9147
879.284	82.9459
879.535	77.7108
879.787	79.9006
880.039	79.5974
880.291	77.4055
880.543	80.1581
880.795	85.2324
881.047	80.4081
881.299	81.9066
881.551	74.4098
881.802	75.423
882.054	77.987
882.306	81.9162
882.558	79.5275
882.809	74.547
883.061	73.6809
883.313	79.8519
883.565	73.7984
883.816	73.2303
884.068	77.2582
884.319	77.2467
884.571	69.7433
884.823	71.6575
885.074	84.3196
885.326	76.7407
885.577	65.5309
885.829	67.0113
886.08	73.3449
886.332	69.5463
886.583	62.1096
886.835	69.5951
887.086	72.1698
887.338	69.9309
887.589	75.8118
887.841	68.0134
888.044	75.9382
888.296	77.6785
888.548	71.6251
888.8	82.5155
889.053	71.0249
889.305	70.6762
889.557	60.2667
889.809	61.9775
890.061	74.4641
890.313	63.9038
890.566	62.1451
890.818	62.0797
891.07	68.4191
891.322	66.264
891.574	62.0285
891.826	70.8394
892.078	69.095
892.33	67.0937
892.582	58.6556
892.834	61.8156
893.086	59.8382
893.338	67.8532
893.59	66.7167
893.842	61.1056
894.094	65.9928
894.346	65.0169
894.597	58
894.849	59.3587
895.101	62.8889
895.353	63.3567
895.605	59.1739
895.857	61.7271
896.108	64.7609
896.36	59.4589
896.612	56
896.864	56.5042
897.115	66.6304
897.367	57.6014
897.619	59.8658
897.87	60.0665
898.122	57.7473
898.374	56.2648
898.625	56.7183
898.877	56.104
899.128	61.6856
899.38	57.3374
899.631	59.0411
899.883	59.5441
899.984	51.2591