File: PL_230124_Amostra_marrom_02.txt
#Acq. time (s)=	3
#Accumulations=	2
#Range (nm)=	520...900
#Windows=	16
#Auto scanning=	On
#Autofocus=	Off
#AutoExposure=	Off
#Spike filter=	Multiple accum.
#Delay time (s)=	0
#Binning=	1
#Readout mode=	Signal
#DeNoise=	Off
#ICS correction=	Off
#Dark correction=	Off
#Inst. Process=	Off
#Detector temperature (°C)=	-59.98
#Instrument=	LabRAM HR Evol
#Detector=	Syncerity OE
#Objective=	x50_VIS
#Grating=	600 (500nm)
#ND Filter=	10%
#Laser=	514nm_Edge
#Hole=	199.981
#Range=	Auto
#StageXY=	Marzhauser
#StageZ=	Marzhauser
#X (µm)=	-3440.6
#Y (µm)=	-678.3
#Z (µm)=	304.9
#Full time(mm:ss)=	2:39
#Project=
#Sample=
#Site=
#Title=	PL_230124_Amostra_marrom
#Remark=
#Date=	31.01.2024 11:25
#Acquired=	31.01.2024 11:25:56
520.042	32
520.304	34.7439
520.565	31.9406
520.827	39.7209
521.089	30.4744
521.351	32.1791
521.612	38.4133
521.874	30.3248
522.136	37.7628
522.397	38
522.659	42
522.921	39.56
523.182	33.1572
523.444	37.9942
523.705	30.7078
523.967	35.5623
524.229	33.0163
524.49	38
524.752	39.3504
525.013	36.5891
525.275	34.7637
525.536	34.0081
525.798	36.2864
526.059	36
526.321	32.1129
526.582	38.4226
526.844	36.2984
527.105	37.9255
527.367	37.042
527.628	38.6702
527.889	38.6807
528.151	40.0524
528.412	37.4435
528.674	39.8846
528.935	37.1469
529.196	36.5711
529.458	33.5967
529.719	36.4138
529.98	36.8508
530.242	35.8718
530.503	40.1049
530.764	40.8322
531.025	41.5315
531.287	35
531.548	40.5315
531.809	37.4988
532.07	42.535
532.332	34.9534
532.593	43.3986
532.854	45.1818
533.115	41.3287
533.376	41.5676
533.638	45.4191
533.899	43.0677
534.16	39.8025
534.421	44.5053
534.682	41.4704
534.943	44.6137
535.204	48.6713
535.465	44.9028
535.726	51.9639
535.987	44.3594
536.248	43.4107
536.509	49.8227
536.77	48.4241
537.031	41.6536
537.292	46.8787
537.553	49.6145
537.814	49.4367
538.075	40.9507
538.336	41.8328
538.597	48.7137
538.858	49.7551
539.119	45.8622
539.38	44.1269
539.641	55.5104
539.901	50.1333
540.162	48.1937
540.423	52.4221
540.684	55.8018
540.945	50.1624
541.205	46.9872
541.466	52.0083
541.727	59.6262
541.988	44.1359
542.248	52.6381
542.509	60.0944
542.77	57.9403
543.031	52.2779
543.291	54.0326
543.552	69.8981
543.813	60.5136
544.073	67.3105
544.334	55.5502
544.594	62.1902
544.855	65.7513
545.116	64.1655
545.376	64.4283
545.637	69.6771
545.897	73.593
546.158	70.6729
546.418	70.026
546.679	72.0118
546.898	73.8678
547.159	70.0371
547.42	75.9079
547.681	81.7964
547.942	83.6181
548.203	72.3994
548.464	72.6436
548.725	79.4384
548.987	85.0843
549.248	78.9148
549.509	91.4442
549.77	90.9594
550.031	88.4469
550.292	88.4684
550.553	89.4054
550.814	104.585
551.075	101.362
551.336	108.14
551.597	120.758
551.858	155.262
552.119	204.21
552.38	1151.6
552.641	11344.1
552.901	391.264
553.162	177.651
553.423	143.595
553.684	127.425
553.945	119.98
554.206	119.706
554.467	125.613
554.727	124.038
554.988	128.443
555.249	122.67
555.51	133.401
555.771	127.039
556.031	122.503
556.292	137.691
556.553	141.003
556.814	141.945
557.074	129.26
557.335	152.609
557.596	152.342
557.856	151.715
558.117	151.416
558.378	154.004
558.638	147.434
558.899	159.593
559.16	156.398
559.42	153.544
559.681	158.475
559.941	164.205
560.202	165.733
560.463	181.5
560.723	176.421
560.984	181.121
561.244	186.151
561.505	194.815
561.765	194.11
562.026	181.176
562.286	202.491
562.547	204.862
562.807	194.824
563.067	217.719
563.328	227.062
563.588	223.921
563.849	220.276
564.109	219.546
564.369	228.442
564.63	236.115
564.89	231.496
565.15	231.264
565.411	242.697
565.671	243.076
565.931	246.643
566.192	252.125
566.452	260.887
566.712	268.432
566.972	266.553
567.232	279.396
567.493	286.215
567.753	288.381
568.013	294.286
568.273	308.916
568.533	298.09
568.794	305.574
569.054	316.818
569.314	328.797
569.574	326.942
569.834	335.302
570.094	356.063
570.354	351.798
570.614	370.023
570.874	377.994
571.134	389.477
571.394	410.683
571.654	429.103
571.914	441.469
572.174	478.626
572.434	499.529
572.694	504.492
572.954	539.323
573.214	577.271
573.459	588.355
573.719	644.144
573.98	705.97
574.241	780.989
574.501	844.96
574.762	896.203
575.022	987.938
575.283	1046.82
575.543	1102.01
575.804	1107.78
576.064	1125.25
576.325	1156.48
576.585	1073.96
576.846	1025.11
577.106	959.234
577.366	923.456
577.627	876.363
577.887	818.432
578.148	789.544
578.408	761.554
578.668	722.792
578.929	720.838
579.189	710.9
579.449	718.221
579.71	698.603
579.97	674.296
580.23	693.354
580.49	698.523
580.751	707.922
581.011	703.526
581.271	720.627
581.531	708.79
581.792	715.638
582.052	748.568
582.312	730.5
582.572	727.558
582.832	746.817
583.092	774.479
583.353	762.711
583.613	786.661
583.873	798.762
584.133	814.703
584.393	841.582
584.653	848.073
584.913	848.404
585.173	875.228
585.433	900.985
585.693	914.363
585.953	929.138
586.213	933.239
586.473	943.387
586.733	960.375
586.993	953.178
587.253	969.478
587.513	974.619
587.773	962.736
588.033	989.95
588.293	982.599
588.552	978.309
588.812	999.828
589.072	1018.52
589.332	1032.19
589.592	1042.08
589.852	1020.81
590.112	1019.7
590.371	1023.57
590.631	1000.51
590.891	1034.86
591.151	1017.85
591.41	996.69
591.67	982.943
591.93	995.346
592.189	992.436
592.449	996.103
592.709	999.915
592.968	1004.08
593.228	995.433
593.488	989.691
593.747	999.617
594.007	977.533
594.266	997.531
594.526	989.982
594.786	1010.36
595.045	1002.54
595.305	1022.44
595.564	1049.56
595.824	1042.72
596.083	1073.51
596.343	1083.33
596.602	1106.44
596.862	1112.66
597.121	1109.18
597.38	1114.83
597.64	1123.45
597.899	1133.79
598.159	1133.06
598.418	1133.95
598.677	1157.86
598.937	1160.63
599.196	1153.17
599.455	1163.35
599.715	1183.86
599.959	1156
600.219	1141.97
600.479	1167.55
600.738	1138.68
600.998	1178.95
601.258	1162.14
601.518	1164.4
601.778	1172.44
602.038	1131.2
602.298	1198.11
602.558	1184.39
602.818	1170.55
603.078	1198.3
603.337	1201.85
603.597	1201.54
603.857	1221.01
604.117	1207.88
604.377	1215.02
604.636	1203.23
604.896	1218.26
605.156	1235.77
605.416	1213.55
605.675	1228.31
605.935	1228.09
606.195	1214.94
606.455	1215.55
606.714	1205.73
606.974	1206.09
607.234	1210.23
607.493	1220.9
607.753	1224.85
608.012	1233.01
608.272	1250.46
608.532	1242.53
608.791	1284.23
609.051	1270.59
609.31	1258.94
609.57	1301.33
609.829	1282.37
610.089	1283.85
610.348	1286.55
610.608	1300.83
610.867	1305.65
611.127	1309.88
611.386	1315.98
611.646	1333.49
611.905	1321.58
612.164	1344.3
612.424	1339
612.683	1336.77
612.943	1341.01
613.202	1362.89
613.461	1371.81
613.721	1359.69
613.98	1383.32
614.239	1418
614.498	1433.18
614.758	1411.51
615.017	1448.4
615.276	1451.93
615.535	1457.67
615.795	1468.13
616.054	1495.38
616.313	1517.06
616.572	1501.33
616.831	1515.37
617.091	1524.92
617.35	1518.22
617.609	1550.77
617.868	1586.45
618.127	1595.62
618.386	1578.94
618.645	1626.37
618.904	1602.54
619.163	1613.75
619.422	1646.05
619.681	1672.57
619.94	1661.85
620.199	1673.91
620.458	1697.33
620.717	1707.34
620.976	1705.81
621.235	1701.55
621.494	1750.66
621.753	1740.22
622.012	1697.82
622.271	1710.61
622.53	1760.74
622.788	1749.48
623.047	1731.62
623.306	1741.57
623.565	1721
623.824	1743.96
624.082	1722.99
624.341	1724.81
624.6	1729.5
624.859	1757.11
625.117	1760.82
625.376	1787.24
625.635	1770.31
625.893	1796.44
626.152	1774.16
626.368	1853.42
626.627	1837.16
626.887	1844.97
627.146	1874.5
627.405	1880.47
627.665	1880.27
627.924	1879.53
628.183	1886.14
628.443	1949.44
628.702	1872.69
628.961	1895.48
629.22	1943.01
629.479	1968.1
629.739	1928.35
629.998	1946.58
630.257	1963.55
630.516	2003.39
630.776	2000.7
631.035	2000.05
631.294	2007.43
631.553	2014.98
631.812	2028.61
632.071	2051.23
632.33	2057.48
632.589	2104.18
632.848	2089.78
633.107	2121.23
633.366	2131.85
633.625	2162.13
633.885	2178.93
634.143	2181.41
634.403	2187.11
634.661	2247.67
634.92	2262.97
635.179	2312.82
635.438	2312.14
635.697	2364.19
635.956	2418.52
636.215	2508.6
636.474	2568.41
636.733	2662.95
636.992	2767.53
637.25	2901.27
637.509	3079.31
637.768	3245.25
638.027	3339.72
638.286	3437.67
638.544	3422.32
638.803	3398.74
639.062	3302.24
639.321	3205.81
639.579	3113.85
639.838	3052.59
640.097	2957.88
640.356	2893.18
640.614	2876.58
640.873	2836.89
641.131	2819.44
641.39	2795.84
641.649	2784.49
641.907	2772.09
642.166	2777.66
642.424	2732.79
642.683	2744.18
642.942	2774.29
643.2	2751.16
643.459	2759.14
643.717	2817.99
643.976	2766.56
644.234	2833.29
644.493	2828.67
644.751	2852.9
645.009	2831.08
645.268	2855.8
645.526	2878.12
645.785	2874.08
646.043	2871.24
646.301	2916.99
646.56	2917.54
646.818	2980.13
647.076	2952.92
647.335	2951.86
647.593	2990.79
647.851	2972.53
648.109	2958.93
648.368	3043.75
648.626	3013.49
648.884	3051.87
649.142	3063.68
649.401	3062.28
649.659	3141.05
649.917	3127.35
650.175	3196.22
650.433	3132.23
650.691	3183.51
650.949	3198.48
651.208	3260.78
651.466	3231
651.724	3266.39
651.982	3277.75
652.24	3350.51
652.498	3347.44
652.756	3345.3
652.979	3387.51
653.238	3423.76
653.497	3434.12
653.755	3462.96
654.014	3493.13
654.273	3508.67
654.531	3564.04
654.79	3576.48
655.049	3591.97
655.307	3631.67
655.566	3682.96
655.824	3732.82
656.083	3715
656.342	3800.04
656.6	3854.39
656.859	3894.18
657.117	3933.24
657.376	3958.84
657.634	4016.83
657.893	4075.13
658.151	4066.65
658.41	4108.79
658.668	4108.28
658.927	4122.96
659.185	4183.67
659.443	4183.53
659.702	4152.58
659.96	4198.46
660.219	4174.75
660.477	4181.95
660.735	4201.05
660.994	4212.63
661.252	4208
661.51	4172.92
661.768	4182.72
662.027	4179.82
662.285	4228.8
662.543	4208.22
662.802	4182.04
663.06	4217.76
663.318	4176.29
663.576	4181.77
663.834	4172.3
664.093	4196.81
664.351	4217.42
664.609	4195.5
664.867	4202.55
665.125	4225.41
665.383	4210.25
665.641	4190.98
665.899	4176.59
666.157	4178.83
666.415	4134.7
666.673	4176.74
666.931	4150.86
667.189	4150.21
667.447	4182.15
667.705	4187.47
667.963	4121.02
668.221	4139.51
668.479	4169.97
668.737	4140.49
668.995	4088.94
669.253	4144.37
669.511	4118.34
669.769	4173.72
670.027	4158.22
670.284	4171.83
670.542	4154.47
670.8	4150.53
671.058	4157.48
671.316	4127.45
671.573	4143.84
671.831	4184.83
672.089	4192.05
672.347	4201.51
672.604	4211.09
672.862	4227.2
673.12	4212.24
673.377	4241.83
673.635	4244.37
673.893	4293.05
674.15	4260.93
674.408	4287.63
674.665	4337.11
674.923	4371.59
675.18	4416.94
675.438	4428.61
675.696	4419.77
675.953	4384.3
676.211	4442.5
676.468	4375.72
676.726	4447.27
676.983	4431.59
677.24	4448.03
677.498	4460.83
677.755	4468.49
678.013	4478.77
678.27	4461.76
678.527	4460.62
678.785	4478.37
679.042	4414.78
679.277	4509.92
679.535	4375.81
679.793	4547.94
680.051	4539
680.309	4501.26
680.567	4463.92
680.825	4584.95
681.083	4532.7
681.341	4573.26
681.599	4551.21
681.857	4633.3
682.115	4634.35
682.373	4599.77
682.631	4647.31
682.889	4552.95
683.146	4673.43
683.404	4590.79
683.662	4664.74
683.92	4648.55
684.178	4609.46
684.436	4602.5
684.694	4573.54
684.951	4591.48
685.209	4568.02
685.467	4533.22
685.725	4552
685.982	4525.51
686.24	4558.4
686.498	4514.1
686.756	4481.53
687.013	4526.04
687.271	4494.28
687.529	4493.07
687.786	4540.37
688.044	4505.56
688.302	4518.62
688.559	4493.68
688.817	4481.83
689.074	4502.52
689.332	4499.17
689.589	4460.19
689.847	4484.44
690.104	4489.75
690.362	4481.46
690.619	4453.78
690.877	4464.21
691.134	4404.4
691.392	4452.67
691.649	4413.42
691.907	4345.29
692.164	4402.75
692.421	4367.55
692.679	4338.17
692.936	4340.43
693.194	4306.87
693.451	4305.85
693.708	4264.57
693.966	4276.89
694.223	4299.11
694.48	4273.13
694.737	4249.8
694.995	4201.41
695.252	4265.3
695.509	4245.88
695.766	4188.17
696.023	4255.15
696.281	4159.39
696.538	4207.54
696.795	4147.7
697.052	4174.04
697.309	4133.08
697.566	4106.27
697.823	4128.63
698.08	4115.2
698.338	4074.1
698.595	4065.5
698.852	4039.29
699.109	4016.45
699.366	4028.58
699.623	3985.26
699.88	3997.5
700.137	4004.36
700.393	3999.26
700.65	4012.78
700.907	3955.89
701.164	4007.18
701.421	3959.46
701.678	3997.02
701.935	4029.58
702.192	3965.04
702.448	3999.55
702.705	3977.14
702.962	3994.15
703.219	3982.9
703.476	3925.41
703.732	3936.16
703.989	3971.42
704.246	3957.29
704.503	3934.98
704.759	3886.67
705.016	3903.66
705.273	3901.13
705.511	3858.12
705.768	3825.04
706.026	3852.97
706.283	3826.82
706.541	3794.47
706.798	3817.86
707.055	3701.2
707.313	3775.38
707.57	3709.58
707.827	3734.68
708.084	3682.06
708.342	3749.02
708.599	3678.41
708.856	3707.46
709.114	3662.85
709.371	3744.85
709.628	3672.87
709.885	3652.9
710.142	3664.35
710.4	3608.73
710.657	3659.4
710.914	3643.92
711.171	3582.5
711.428	3574.97
711.685	3537.39
711.942	3592.49
712.199	3558.21
712.456	3420.51
712.713	3525.55
712.97	3501.28
713.227	3442.36
713.484	3411.43
713.741	3453.15
713.998	3373.24
714.255	3383.3
714.512	3337.42
714.769	3366.41
715.026	3314.55
715.283	3296.5
715.54	3331.06
715.797	3290.79
716.054	3257.44
716.31	3280.38
716.567	3295.98
716.824	3257.56
717.081	3258.83
717.338	3241.11
717.594	3224.83
717.851	3191.5
718.108	3175.99
718.365	3201.82
718.621	3183.02
718.878	3125.42
719.135	3100.28
719.391	3131.07
719.648	3095.03
719.905	3076.99
720.161	3075.45
720.418	3052.4
720.675	3047.68
720.931	2986.38
721.188	3002.24
721.444	3020.38
721.701	3000.11
721.957	2964.42
722.214	2944.46
722.47	2911.36
722.727	2923.42
722.983	2937.32
723.24	2903.76
723.496	2871.12
723.753	2864.74
724.009	2860.96
724.265	2858.11
724.522	2824.14
724.778	2806.36
725.034	2851.19
725.291	2821.61
725.547	2766.17
725.803	2760.8
726.06	2767
726.316	2755.6
726.572	2725.59
726.828	2696.81
727.085	2711.05
727.341	2706.19
727.597	2690.57
727.853	2668.32
728.109	2672.73
728.366	2686.76
728.622	2621.62
728.878	2589.93
729.134	2631.49
729.39	2600.44
729.646	2556.75
729.902	2531.37
730.158	2557.23
730.414	2462.92
730.67	2516.67
730.926	2444.21
731.182	2450.66
731.438	2454.99
731.643	2454
731.9	2442.46
732.156	2445.09
732.413	2407.79
732.67	2396.25
732.927	2465.61
733.183	2417.29
733.44	2380.34
733.697	2358.86
733.953	2427.32
734.21	2393.87
734.466	2426.57
734.723	2408.62
734.98	2417.05
735.236	2440.65
735.493	2463.42
735.749	2437.98
736.006	2469.13
736.262	2501.51
736.519	2499.5
736.775	2502.51
737.032	2550.43
737.288	2589.37
737.544	2627.61
737.801	2623.87
738.057	2647.68
738.314	2621.8
738.57	2654.78
738.826	2579.7
739.083	2590.99
739.339	2519.87
739.595	2498.63
739.852	2476.5
740.108	2432.23
740.364	2423.61
740.621	2361.18
740.877	2358.22
741.133	2326.79
741.389	2260.36
741.645	2253.95
741.902	2269.89
742.158	2228.65
742.414	2175.71
742.67	2184.65
742.926	2145.94
743.182	2164.2
743.438	2137.47
743.694	2128.36
743.951	2092.99
744.207	2068.14
744.463	2059.17
744.719	2057.28
744.975	2040.88
745.231	2037.65
745.487	2011.54
745.743	2001.24
745.998	2018.7
746.254	1983.32
746.51	1995.52
746.766	2010.32
747.022	1964.84
747.278	1941.92
747.534	1944.47
747.79	1912.84
748.046	1933.28
748.301	1913.52
748.557	1900.11
748.813	1898.62
749.069	1898.79
749.324	1872.91
749.58	1862.9
749.836	1850.07
750.092	1848.85
750.347	1853.7
750.603	1856.79
750.859	1827.05
751.114	1794.15
751.37	1797.09
751.625	1794.82
751.881	1806.88
752.137	1766.57
752.392	1746.33
752.648	1739.6
752.903	1733.32
753.159	1765.32
753.414	1730.78
753.67	1707.81
753.925	1710.85
754.181	1694.1
754.436	1695.24
754.692	1719.69
754.947	1677.21
755.202	1685.45
755.458	1615.05
755.713	1617.74
755.968	1637.42
756.224	1616.22
756.479	1578.87
756.734	1582.05
756.99	1578.75
757.245	1589.77
757.5	1571.52
757.755	1571.1
757.968	1550
758.224	1551.78
758.48	1534.61
758.736	1555.29
758.992	1515.15
759.248	1509.25
759.504	1496.16
759.76	1488.11
760.016	1438.92
760.272	1462.41
760.528	1488.96
760.784	1456.41
761.04	1446.89
761.296	1415.42
761.552	1446.9
761.807	1454.16
762.063	1424.79
762.319	1419.67
762.575	1443.65
762.831	1396.29
763.086	1370.66
763.342	1376.07
763.598	1355.31
763.853	1362.78
764.109	1356.79
764.365	1328.64
764.621	1326.22
764.876	1351.71
765.132	1306.57
765.387	1306.47
765.643	1299.47
765.899	1286.73
766.154	1327.58
766.41	1275.64
766.665	1272.82
766.921	1243.05
767.176	1297.24
767.432	1263.64
767.687	1208.07
767.943	1217.31
768.198	1231.05
768.454	1213.03
768.709	1218.11
768.965	1186.42
769.22	1202.42
769.475	1192.12
769.731	1198.11
769.986	1164.35
770.242	1159.19
770.497	1167.54
770.752	1153.78
771.007	1131.55
771.263	1141.63
771.518	1133.09
771.773	1101.17
772.028	1098.71
772.284	1081.2
772.539	1075.14
772.794	1045.81
773.049	1072.62
773.304	1062.12
773.56	1050.48
773.815	1045.88
774.07	1032.72
774.325	1015.16
774.58	1021.61
774.835	1018.56
775.09	1011.22
775.345	1015.29
775.6	998.007
775.855	979.66
776.11	990.427
776.365	1000
776.62	984.14
776.875	959.019
777.13	937.688
777.385	940.783
777.64	947.465
777.895	941.42
778.149	932.949
778.404	927.209
778.659	913.189
778.914	925.678
779.169	912.762
779.424	915.025
779.678	896.128
779.933	862.776
780.188	880.13
780.442	876.189
780.697	862.43
780.952	863.044
781.207	845.967
781.461	857.701
781.716	833.419
781.97	862.359
782.225	848.606
782.48	800.586
782.734	810.069
782.989	806.545
783.243	810.366
783.498	807.757
783.752	778.08
784.007	779.168
784.253	777.891
784.509	759.98
784.764	778.331
785.019	719.978
785.274	736.847
785.53	731.375
785.785	736.738
786.04	730.287
786.295	749.017
786.551	748.335
786.806	721.133
787.061	706.294
787.316	725.371
787.571	685.326
787.826	708.614
788.081	715.678
788.336	684.751
788.591	683.653
788.847	660.234
789.102	681.668
789.357	676.476
789.612	680.34
789.867	653.04
790.122	648.056
790.377	664.644
790.632	660.433
790.886	636.074
791.141	648.059
791.396	637.427
791.651	647.214
791.906	617.112
792.161	633.371
792.416	617.02
792.671	603.935
792.925	601.949
793.18	610.305
793.435	586.495
793.69	593.195
793.945	593.445
794.199	571.411
794.454	576.492
794.709	566.663
794.963	575.091
795.218	579.888
795.473	557.269
795.727	544.254
795.982	549.407
796.237	550.645
796.491	539.722
796.746	539.609
797	535.094
797.255	542.152
797.509	529.44
797.764	531.543
798.018	521.601
798.273	521.137
798.527	514.472
798.782	518.866
799.036	499.668
799.291	502.596
799.545	504.358
799.8	495.032
800.054	492.839
800.308	488.603
800.563	490.141
800.817	488.734
801.071	483.897
801.326	477.378
801.58	475.927
801.834	481.592
802.088	462.168
802.343	456.849
802.597	460.356
802.851	454.865
803.105	436.332
803.359	449.745
803.614	440.897
803.868	440.662
804.122	432.653
804.376	442.053
804.63	423.117
804.884	415.715
805.138	424.978
805.392	420.732
805.646	410.525
805.9	408.268
806.154	399.309
806.408	408.95
806.662	401.914
806.916	411.617
807.17	393.268
807.424	403.135
807.678	397.996
807.932	395.741
808.186	394.924
808.439	381.61
808.693	390.244
808.947	378.517
809.201	377.529
809.455	363.458
809.708	380.51
809.962	390.878
810.183	368
810.438	375.994
810.693	358.059
810.947	362.014
811.202	361.578
811.456	354.318
811.711	360.628
811.965	360.983
812.22	368.443
812.474	363.685
812.729	347.914
812.983	343.827
813.237	330.104
813.492	329.46
813.746	325.371
814.001	336.031
814.255	331.242
814.509	321.505
814.764	330.837
815.018	336.135
815.272	336.698
815.526	338.068
815.781	330.293
816.035	320.767
816.289	312.367
816.543	318.305
816.798	301.18
817.052	304.758
817.306	310.707
817.56	300.407
817.814	309.336
818.068	299.813
818.323	287.834
818.577	289.052
818.831	298.273
819.085	275.313
819.339	285.495
819.593	269.332
819.847	288.854
820.101	275.717
820.355	276.818
820.609	279.667
820.863	278.137
821.117	271.803
821.371	266.327
821.624	278.201
821.878	272.491
822.132	267.234
822.386	262.376
822.64	257.769
822.894	254.33
823.148	256.679
823.401	255.926
823.655	256.733
823.909	253.788
824.163	246.169
824.416	231.439
824.67	248.379
824.924	252.905
825.177	243.744
825.431	249.638
825.685	242.553
825.938	237.207
826.192	245.434
826.446	234.852
826.699	244.718
826.953	239.566
827.206	238.076
827.46	230.149
827.713	224.703
827.967	228.252
828.22	228.762
828.474	225.256
828.727	225.325
828.981	228.34
829.234	223.256
829.488	225.94
829.741	222.571
829.994	208.744
830.248	208.786
830.501	216
830.754	214.138
831.008	214.397
831.261	212.828
831.514	205.877
831.767	207.024
832.021	215.449
832.274	207.46
832.527	205.949
832.78	205.264
833.034	199.739
833.287	202.415
833.54	213.05
833.793	206.053
834.046	198.601
834.299	196.705
834.552	189.398
834.805	197.963
835.058	202.502
835.311	189.881
835.564	203.155
835.817	201.576
836.07	175.771
836.314	187.998
836.568	215.66
836.821	191.739
837.075	174.474
837.329	194.005
837.583	191.351
837.836	180.63
838.09	184.079
838.344	194.229
838.598	190.79
838.851	178.951
839.105	174.885
839.359	197.677
839.612	176.793
839.866	178.632
840.119	165.198
840.373	169.979
840.627	172.854
840.88	172.496
841.134	164.022
841.387	165.815
841.641	175.962
841.894	166.849
842.148	163.591
842.401	162.999
842.655	170.722
842.908	166.342
843.161	172.413
843.415	157.161
843.668	167.427
843.922	154.251
844.175	162.194
844.428	161.59
844.682	160.378
844.935	165.581
845.188	158.302
845.442	152.622
845.695	153.912
845.948	148.998
846.201	148.958
846.455	148.298
846.708	165.151
846.961	152.509
847.214	150.765
847.467	155.829
847.72	140.113
847.973	152.962
848.227	148.702
848.48	146.649
848.733	146.585
848.986	143.634
849.239	149.811
849.492	141.117
849.745	135.219
849.998	143.481
850.251	145.192
850.504	141.336
850.757	141.141
851.01	141.373
851.263	129.749
851.515	140.253
851.768	136.126
852.021	144.342
852.274	140.843
852.527	129.643
852.78	133.661
853.032	129.096
853.285	134.311
853.538	137.024
853.791	133.782
854.043	128.886
854.296	134.919
854.549	123.654
854.801	130.002
855.054	130.914
855.307	119.486
855.559	126.283
855.812	124.801
856.065	128.819
856.317	130.267
856.57	118.752
856.822	120.653
857.075	121.215
857.327	123.819
857.58	113.999
857.832	120.167
858.085	118.779
858.337	117.912
858.589	127.856
858.842	119.739
859.094	124.654
859.347	115.61
859.599	112.46
859.851	116.59
860.104	112.044
860.356	119.069
860.608	112.63
860.861	109.168
861.113	120.805
861.365	112.336
861.617	112.149
861.869	113.736
862.112	119.99
862.365	106.013
862.618	104.212
862.871	112.11
863.124	109.908
863.377	115.751
863.63	106.077
863.883	111.843
864.136	109.551
864.389	105.909
864.642	111.703
864.894	109.248
865.147	101.273
865.4	106.455
865.653	102.867
865.906	103.756
866.159	112.674
866.412	95.1781
866.664	116.028
866.917	110.699
867.17	106.275
867.423	105.635
867.675	104.955
867.928	96.8347
868.181	102.382
868.433	94.4199
868.686	91.9125
868.939	106.559
869.191	98.6659
869.444	98.2982
869.697	104.568
869.949	96.2175
870.202	93.9027
870.454	96.7997
870.707	101.347
870.959	90.5625
871.212	100.75
871.464	99.7212
871.717	99.4981
871.969	85.9853
872.222	93.7228
872.474	100.727
872.727	97.3393
872.979	94.7641
873.231	99.1482
873.484	102.531
873.736	91.948
873.988	84.9523
874.241	92.4027
874.493	87.7893
874.745	91.4202
874.998	82.8885
875.25	88.9299
875.502	86.6283
875.754	86.2005
876.006	88.3719
876.259	84.9064
876.511	91.9522
876.763	82.7693
877.015	87.7156
877.267	86.4791
877.519	91.1612
877.771	78.5029
878.023	87.1855
878.276	79.715
878.528	82.731
878.78	84.1622
879.031	82.7677
879.284	82.3959
879.535	83.6807
879.787	77.6734
880.039	80.6634
880.291	80.9591
880.543	81.7824
880.795	78.9195
881.047	84.8027
881.299	80.3672
881.551	77.1804
881.802	78.7124
882.054	82.3737
882.306	78.3355
882.558	78.8328
882.809	74.547
883.061	72.1853
883.313	80.2581
883.565	73.6342
883.816	81.1079
884.068	77.5646
884.319	75.6234
884.571	76.7854
884.823	70.6015
885.074	74.1034
885.326	70.9241
885.577	76.7526
885.829	74.3171
886.08	79.3172
886.332	73.9381
886.583	75.3311
886.835	69.5914
887.086	69.5616
887.338	71.6939
887.589	68.2234
887.841	77.6861
888.044	74.0036
888.296	70.059
888.548	62.4438
888.8	75.4366
889.053	74.8808
889.305	64.804
889.557	77.2179
889.809	68.4922
890.061	69.0942
890.313	65.1287
890.566	71.2906
890.818	67.616
891.07	70.1136
891.322	68.7006
891.574	69.3758
891.826	68.239
892.078	63.5019
892.33	66.5626
892.582	68.5139
892.834	69.858
893.086	72.0415
893.338	68.4962
893.59	63.2494
893.842	62.0903
894.094	62.942
894.346	61.0254
894.597	64.9034
894.849	58.2391
895.101	58.9444
895.353	66
895.605	63.913
895.857	64.7923
896.108	56.1957
896.36	63.8647
896.612	61.6304
896.864	65.4958
897.115	63
897.367	61.599
897.619	66.6493
897.87	61.7666
898.122	53.7437
898.374	66.1463
898.625	58.8452
898.877	57.7013
899.128	61.2576
899.38	57.6687
899.631	66.3059
899.883	56.8198
899.984	56.6295