File: PL_230124_Amostra_branca_sem_semente_CVD_01.txt
#Acq. time (s)=	3
#Accumulations=	2
#Range (nm)=	520...900
#Windows=	16
#Auto scanning=	On
#Autofocus=	Off
#AutoExposure=	Off
#Spike filter=	Multiple accum.
#Delay time (s)=	0
#Binning=	1
#Readout mode=	Signal
#DeNoise=	Off
#ICS correction=	Off
#Dark correction=	Off
#Inst. Process=	Off
#Detector temperature (°C)=	-59.98
#Instrument=	LabRAM HR Evol
#Detector=	Syncerity OE
#Objective=	x50_VIS
#Grating=	600 (500nm)
#ND Filter=	10%
#Laser=	514nm_Edge
#Hole=	199.981
#Range=	Auto
#StageXY=	Marzhauser
#StageZ=	Marzhauser
#X (µm)=	-3464.4
#Y (µm)=	-659.6
#Z (µm)=	304.6
#Full time(mm:ss)=	2:39
#Project=
#Sample=
#Site=
#Title=	PL_230124_Amostra_branca_sem_semente_CVD
#Remark=
#Date=	31.01.2024 11:30
#Acquired=	31.01.2024 11:30:54
520.042	39
520.304	35.0512
520.565	40.8219
520.827	36
521.089	34
521.351	37.1791
521.612	40.7066
521.874	37.8917
522.136	35.4744
522.397	36
522.659	33.9616
522.921	43.6799
523.182	38.943
523.444	39.6647
523.705	37.7078
523.967	43.2503
524.229	37.1967
524.49	39.9639
524.752	35.8661
525.013	43.319
525.275	41
525.536	42.2561
525.798	40.8009
526.059	43.1967
526.321	45.4435
526.582	41.5774
526.844	41.8065
527.105	37.617
527.367	39.2774
527.628	39.6492
527.889	46.3193
528.151	33.1573
528.412	40.8347
528.674	45
528.935	42.2354
529.196	38
529.458	42.3869
529.719	44.8275
529.98	43.7016
530.242	42.5641
530.503	42.3427
530.764	42.6259
531.025	38.5315
531.287	48.5594
531.548	49
531.809	47
532.07	41.0699
532.332	45.9068
532.593	38.3986
532.854	45.8182
533.115	48
533.376	48.7296
533.638	50.9453
533.899	43.1985
534.16	43.0401
534.421	47.6869
534.682	51.4936
534.943	50.8826
535.204	51.1987
535.465	54.5303
535.726	49.6226
535.987	49.2492
536.248	53.374
536.509	48.1904
536.77	49.6595
537.031	52.2917
537.292	48.6204
537.553	54.3993
537.814	56.6693
538.075	48
538.336	57.0954
538.597	57.9309
538.858	56.0894
539.119	53.8864
539.38	62.3299
539.641	61.6313
539.901	61.0215
540.162	57.632
540.423	58.8287
540.684	55.3982
540.945	59.1528
541.205	59.7794
541.466	62.4605
541.727	62.7642
541.988	65.8748
542.248	65.1051
542.509	50.3942
542.77	65.1462
543.031	66.3263
543.291	65.5382
543.552	69.3452
543.813	61.2242
544.073	62.091
544.334	69.9794
544.594	63.8784
544.855	66.6204
545.116	66.1311
545.376	70.8275
545.637	75.8943
545.897	74.3819
546.158	74.1644
546.418	71.1529
546.679	71.4473
546.898	69.8523
547.159	68.0262
547.42	83.6729
547.681	72.2057
547.942	85.3727
548.203	83.6607
548.464	83.5623
548.725	80.578
548.987	88.4727
549.248	80.3597
549.509	88.7477
549.77	84.7296
550.031	91.9126
550.292	95.521
550.553	90.899
550.814	106.571
551.075	97.5546
551.336	113.173
551.597	117.949
551.858	143.454
552.119	182.19
552.38	1074.02
552.641	10873.8
552.901	400.728
553.162	167.615
553.423	129.128
553.684	118.504
553.945	114.004
554.206	113.912
554.467	104
554.727	104.676
554.988	114.395
555.249	121.329
555.51	118.401
555.771	116.996
556.031	119.963
556.292	121.691
556.553	114.756
556.814	125.366
557.074	122.992
557.335	124.887
557.596	120.042
557.856	130.406
558.117	118.334
558.378	130.033
558.638	128.578
558.899	134.455
559.16	128.113
559.42	142.178
559.681	121.738
559.941	138.226
560.202	144.315
560.463	139.022
560.723	141.958
560.984	135.641
561.244	152.361
561.505	154.484
561.765	148.313
562.026	150.811
562.286	160.516
562.547	156.479
562.807	158.037
563.067	164.725
563.328	169.884
563.588	162.833
563.849	174.475
564.109	175.808
564.369	180.315
564.63	177.871
564.89	177.248
565.15	176.089
565.411	184.377
565.671	192.152
565.931	181.949
566.192	203.292
566.452	196.731
566.712	202.706
566.972	195.325
567.232	207.422
567.493	208.698
567.753	211.141
568.013	204.381
568.273	219.87
568.533	218.726
568.794	231.251
569.054	238.082
569.314	235.203
569.574	238.166
569.834	247.407
570.094	240.641
570.354	263.028
570.614	259.214
570.874	256.165
571.134	279.592
571.394	288.78
571.654	297.745
571.914	305.632
572.174	326.513
572.434	337.708
572.694	360.743
572.954	383.205
573.214	383.733
573.459	411.959
573.719	478.896
573.98	461.97
574.241	519.35
574.501	565.052
574.762	618.976
575.022	647.804
575.283	702.227
575.543	719.199
575.804	712.814
576.064	746.744
576.325	718.369
576.585	681.752
576.846	647.981
577.106	614.93
577.366	585.54
577.627	553.844
577.887	512.919
578.148	505.383
578.408	512.305
578.668	489.121
578.929	475.793
579.189	467.295
579.449	460.895
579.71	469.914
579.97	455.794
580.23	457.76
580.49	463.537
580.751	464.885
581.011	463.105
581.271	491.028
581.531	464.74
581.792	475.251
582.052	467.532
582.312	501.558
582.572	489.641
582.832	508.503
583.092	505.475
583.353	501.831
583.613	531.475
583.873	528.501
584.133	530.293
584.393	561.25
584.653	553.596
584.913	570.291
585.173	584.912
585.433	580.279
585.693	578.91
585.953	602.123
586.213	616.371
586.473	610.555
586.733	619.179
586.993	623.788
587.253	640.893
587.513	630.985
587.773	636.083
588.033	639.019
588.293	654.93
588.552	650.377
588.812	637.706
589.072	666.183
589.332	679.348
589.592	669.472
589.852	652.574
590.112	653.737
590.371	657.27
590.631	653.143
590.891	642.018
591.151	648.66
591.41	646.729
591.67	654.966
591.93	629.773
592.189	639.491
592.449	642.719
592.709	620.126
592.968	638.284
593.228	638.697
593.488	644.26
593.747	636.94
594.007	640.969
594.266	641.319
594.526	674.852
594.786	667.264
595.045	653.006
595.305	674.753
595.564	670.206
595.824	687.888
596.083	669.627
596.343	683.841
596.602	694.373
596.862	672.378
597.121	701.794
597.38	694.436
597.64	702.142
597.899	691.105
598.159	709.851
598.418	713.06
598.677	717.787
598.937	735.003
599.196	720.084
599.455	736.64
599.715	749.025
599.959	728.086
600.219	726.251
600.479	714.214
600.738	739.694
600.998	743.327
601.258	729.267
601.518	754.745
601.778	739.233
602.038	733.497
602.298	718.78
602.558	752.158
602.818	763.302
603.078	766.958
603.337	759.945
603.597	742.941
603.857	771.626
604.117	754.783
604.377	738.281
604.636	753.712
604.896	768.01
605.156	755.46
605.416	763.674
605.675	752.145
605.935	772.362
606.195	776.07
606.455	761.99
606.714	754.265
606.974	768.239
607.234	767.112
607.493	768.868
607.753	789.776
608.012	793.252
608.272	798.002
608.532	792.062
608.791	819.276
609.051	811.099
609.31	801.508
609.57	804.449
609.829	799.642
610.089	832.607
610.348	815.291
610.608	815.164
610.867	837.894
611.127	841.086
611.386	853.513
611.646	836.616
611.905	848.392
612.164	856.689
612.424	847.074
612.683	859.437
612.943	864.599
613.202	870.904
613.461	870.464
613.721	888.359
613.98	890.412
614.239	910.239
614.498	903.483
614.758	915.144
615.017	913.28
615.276	918.34
615.535	929.3
615.795	933.091
616.054	953.915
616.313	955.382
616.572	974.288
616.831	964.439
617.091	979.056
617.35	975.727
617.609	1003.13
617.868	1021.62
618.127	1006.78
618.386	1024.58
618.645	1034.7
618.904	1050.69
619.163	1048.9
619.422	1064.9
619.681	1072.03
619.94	1058.84
620.199	1090.62
620.458	1077.3
620.717	1100.32
620.976	1112
621.235	1094.01
621.494	1108.08
621.753	1097.77
622.012	1118.49
622.271	1133.42
622.53	1150
622.788	1119.3
623.047	1143.47
623.306	1116.88
623.565	1137.71
623.824	1150.05
624.082	1126.64
624.341	1141.48
624.6	1129.12
624.859	1142.76
625.117	1182.51
625.376	1162.68
625.635	1150.89
625.893	1167.96
626.152	1213.09
626.368	1219.75
626.627	1217.28
626.887	1190.3
627.146	1236.76
627.405	1184.91
627.665	1264.88
627.924	1214.15
628.183	1226
628.443	1277.03
628.702	1271.86
628.961	1282
629.22	1268.63
629.479	1288.87
629.739	1323.2
629.998	1303.4
630.257	1265.82
630.516	1296.33
630.776	1295.33
631.035	1349.11
631.294	1373.74
631.553	1371.01
631.812	1368.16
632.071	1385.67
632.33	1406.7
632.589	1388.25
632.848	1411.8
633.107	1441.87
633.366	1442.7
633.625	1465.41
633.885	1468.36
634.143	1481.81
634.403	1506.84
634.661	1523.47
634.92	1568.69
635.179	1607.74
635.438	1586.56
635.697	1624.27
635.956	1723.58
636.215	1726.92
636.474	1831.34
636.733	1910.78
636.992	2017.75
637.25	2139.22
637.509	2260.76
637.768	2307.28
638.027	2382.03
638.286	2380.83
638.544	2378.85
638.803	2288.42
639.062	2252.73
639.321	2181.28
639.579	2094.41
639.838	2044.68
640.097	2022.57
640.356	1971.8
640.614	1975.4
640.873	1956.6
641.131	1924.21
641.39	1944.51
641.649	1926.53
641.907	1898.83
642.166	1927.14
642.424	1904.23
642.683	1908.92
642.942	1931.45
643.2	1903.2
643.459	1969.33
643.717	1957.29
643.976	1953.46
644.234	1955.13
644.493	1979.49
644.751	2019.79
645.009	1978.08
645.268	2010.19
645.526	2004.51
645.785	1993.85
646.043	2071.45
646.301	2007.32
646.56	2030.47
646.818	2060.87
647.076	2117.92
647.335	2078.36
647.593	2065.01
647.851	2067.25
648.109	2095.11
648.368	2117.83
648.626	2133.75
648.884	2182.82
649.142	2164.82
649.401	2174.25
649.659	2190.58
649.917	2221.54
650.175	2198.47
650.433	2256.34
650.691	2239.72
650.949	2250.32
651.208	2262.73
651.466	2260.66
651.724	2296.18
651.982	2351.52
652.24	2370.54
652.498	2369.74
652.756	2380.76
652.979	2425.78
653.238	2449.31
653.497	2502.86
653.755	2500.47
654.014	2521.45
654.273	2528.15
654.531	2566.35
654.79	2551.88
655.049	2579.12
655.307	2624.74
655.566	2612.74
655.824	2696.75
656.083	2732.96
656.342	2754.14
656.6	2791.9
656.859	2856.43
657.117	2845.23
657.376	2868.08
657.634	2888.7
657.893	2894.95
658.151	2970.98
658.41	2916.73
658.668	2923.82
658.927	2971.92
659.185	2971.98
659.443	2977.14
659.702	3032.77
659.96	3023.54
660.219	3022.06
660.477	3013.95
660.735	3045.32
660.994	3047.81
661.252	3023.04
661.51	3027.59
661.768	3042.82
662.027	3060.78
662.285	3040.47
662.543	3037.36
662.802	3038.92
663.06	3069.5
663.318	3016.24
663.576	3033.78
663.834	3061.83
664.093	3038.85
664.351	3044.47
664.609	3027.88
664.867	3081.42
665.125	3088.06
665.383	3027.15
665.641	3061.67
665.899	3044.17
666.157	3031.9
666.415	3073.36
666.673	3027.03
666.931	3014.29
667.189	3048.03
667.447	3051.41
667.705	3034.92
667.963	3041.19
668.221	3007.68
668.479	3004.58
668.737	2994.24
668.995	3041.77
669.253	3063.8
669.511	3053.28
669.769	3062.3
670.027	3021.08
670.284	3043.85
670.542	3059.45
670.8	3040.5
671.058	3061.29
671.316	3065.27
671.573	3036
671.831	3038.95
672.089	3055.35
672.347	3066.18
672.604	3099.16
672.862	3090.44
673.12	3089.79
673.377	3173.8
673.635	3126.71
673.893	3138.62
674.15	3145.42
674.408	3167.67
674.665	3197.84
674.923	3217.14
675.18	3257.32
675.438	3295.38
675.696	3238.27
675.953	3274.71
676.211	3295.44
676.468	3290.1
676.726	3260.33
676.983	3300.04
677.24	3311.78
677.498	3298.45
677.755	3311.61
678.013	3255.99
678.27	3324.27
678.527	3307.48
678.785	3282.98
679.042	3296.04
679.277	3321.52
679.535	3265.27
679.793	3321.25
680.051	3318.96
680.309	3370.35
680.567	3337.62
680.825	3382.79
681.083	3333.45
681.341	3368.47
681.599	3343.8
681.857	3359.68
682.115	3389
682.373	3394.96
682.631	3452.32
682.889	3355.93
683.146	3424.63
683.404	3455.13
683.662	3442.92
683.92	3434.1
684.178	3426.44
684.436	3362.82
684.694	3410.9
684.951	3391.9
685.209	3392.08
685.467	3442.33
685.725	3430.04
685.982	3372.69
686.24	3361.4
686.498	3393.33
686.756	3348.77
687.013	3384.12
687.271	3351.63
687.529	3355.94
687.786	3365.64
688.044	3398.47
688.302	3323.4
688.559	3335.99
688.817	3335.37
689.074	3320.65
689.332	3306.15
689.589	3339.16
689.847	3292
690.104	3348.15
690.362	3316.08
690.619	3313.63
690.877	3308.45
691.134	3292.22
691.392	3293.33
691.649	3275.38
691.907	3306.69
692.164	3304.57
692.421	3265.25
692.679	3276.65
692.936	3252.76
693.194	3186.98
693.451	3238.64
693.708	3216.23
693.966	3215.97
694.223	3244.04
694.48	3217.45
694.737	3201.37
694.995	3172.99
695.252	3161.72
695.509	3199.73
695.766	3164.53
696.023	3174.08
696.281	3175.85
696.538	3141.63
696.795	3122.46
697.052	3122.44
697.309	3128.93
697.566	3093.63
697.823	3126.54
698.08	3032.16
698.338	3072.36
698.595	3073.31
698.852	3049.52
699.109	3074.81
699.366	3018.77
699.623	3028.3
699.88	3025.11
700.137	2967.61
700.393	3014.23
700.65	3004.29
700.907	3029.47
701.164	2999.64
701.421	3014.77
701.678	2971.51
701.935	3000.78
702.192	3026.72
702.448	3001.95
702.705	2988.94
702.962	3004.34
703.219	2995.12
703.476	2971.17
703.732	2957.41
703.989	2978.96
704.246	2942.53
704.503	2950.24
704.759	2968.21
705.016	2915.62
705.273	2881.54
705.511	2918.06
705.768	2904.64
706.026	2870.06
706.283	2925.28
706.541	2855.92
706.798	2848.32
707.055	2858.93
707.313	2825.91
707.57	2815.53
707.827	2829.19
708.084	2805.78
708.342	2811.18
708.599	2804.52
708.856	2782.01
709.114	2781.95
709.371	2800.22
709.628	2746.28
709.885	2770.3
710.142	2793.57
710.4	2726.55
710.657	2739.94
710.914	2706.4
711.171	2681.69
711.428	2702.88
711.685	2709.64
711.942	2688.6
712.199	2674.12
712.456	2686.43
712.713	2660.11
712.97	2648.4
713.227	2574.28
713.484	2614.53
713.741	2573.55
713.998	2595.49
714.255	2546.12
714.512	2558.73
714.769	2532.76
715.026	2546.97
715.283	2517.31
715.54	2508.34
715.797	2456.21
716.054	2495.22
716.31	2481.97
716.567	2478.33
716.824	2471.46
717.081	2438.72
717.338	2379.79
717.594	2437.63
717.851	2394.04
718.108	2424.08
718.365	2401.64
718.621	2419.95
718.878	2393.93
719.135	2350.89
719.391	2384.83
719.648	2366.65
719.905	2326.53
720.161	2346.21
720.418	2333.01
720.675	2300.31
720.931	2284.29
721.188	2315.49
721.444	2274.84
721.701	2240.78
721.957	2261.99
722.214	2219.62
722.47	2218.24
722.727	2241.59
722.983	2214.13
723.24	2172.24
723.496	2207.37
723.753	2151.25
724.009	2181.54
724.265	2138.76
724.522	2176.32
724.778	2136.24
725.034	2136.89
725.291	2127.04
725.547	2105.46
725.803	2138
726.06	2086.57
726.316	2108.38
726.572	2085.64
726.828	2054.26
727.085	2041.16
727.341	2046.47
727.597	2044.57
727.853	2009.59
728.109	2011.89
728.366	1994.83
728.622	1987.63
728.878	2015.37
729.134	1950.38
729.39	1970.85
729.646	1925.41
729.902	1921.24
730.158	1897.53
730.414	1899.53
730.67	1868.3
730.926	1883.9
731.182	1850.12
731.438	1846.51
731.643	1872
731.9	1834.19
732.156	1804.59
732.413	1844.98
732.67	1782.45
732.927	1850.55
733.183	1768.12
733.44	1809.01
733.697	1837.67
733.953	1834.96
734.21	1796.95
734.466	1790.91
734.723	1823.08
734.98	1798.2
735.236	1813.62
735.493	1818.9
735.749	1791.02
736.006	1784.64
736.262	1803.03
736.519	1743.54
736.775	1775.18
737.032	1798.5
737.288	1860.99
737.544	1803.88
737.801	1839.89
738.057	1826.16
738.314	1817.23
738.57	1849.67
738.826	1814.14
739.083	1803.02
739.339	1794.9
739.595	1779.52
739.852	1743.68
740.108	1752.15
740.364	1719.61
740.621	1697.6
740.877	1696.2
741.133	1698.6
741.389	1681.12
741.645	1653.05
741.902	1647.57
742.158	1626.2
742.414	1637.97
742.67	1627.72
742.926	1603.23
743.182	1603.77
743.438	1600.62
743.694	1573.28
743.951	1593.79
744.207	1560.83
744.463	1535.97
744.719	1524.79
744.975	1541.19
745.231	1527.09
745.487	1539.09
745.743	1521.69
745.998	1517.28
746.254	1510.83
746.51	1502.87
746.766	1493.74
747.022	1467.84
747.278	1482.17
747.534	1468.63
747.79	1465.46
748.046	1479.69
748.301	1423.69
748.557	1450.35
748.813	1430.31
749.069	1442.96
749.324	1411.52
749.58	1445.18
749.836	1439.26
750.092	1421.24
750.347	1412.28
750.603	1394.43
750.859	1385.24
751.114	1397.79
751.37	1364.61
751.625	1346.28
751.881	1366.15
752.137	1356.11
752.392	1326.64
752.648	1314.92
752.903	1296.93
753.159	1298.44
753.414	1328.99
753.67	1340.5
753.925	1305.13
754.181	1304.49
754.436	1277.34
754.692	1256.42
754.947	1285.51
755.202	1290.43
755.458	1247.89
755.713	1227.19
755.968	1235.63
756.224	1256.1
756.479	1257.76
756.734	1216.97
756.99	1203.92
757.245	1199.42
757.5	1199.42
757.755	1229.71
757.968	1204
758.224	1187.8
758.48	1176.26
758.736	1186.99
758.992	1166.61
759.248	1162.05
759.504	1169.03
759.76	1123.8
760.016	1146.53
760.272	1145.77
760.528	1090.04
760.784	1126.1
761.04	1102.07
761.296	1112.8
761.552	1126.08
761.807	1092.76
762.063	1058.81
762.319	1079.57
762.575	1066.87
762.831	1056.72
763.086	1066.96
763.342	1062.49
763.598	1041.71
763.853	1024.36
764.109	1048.97
764.365	1034.79
764.621	1032.37
764.876	1001.95
765.132	1020.77
765.387	995.127
765.643	1002.15
765.899	987.167
766.154	990.746
766.41	979.19
766.665	966.858
766.921	973.452
767.176	965.51
767.432	950.983
767.687	974.559
767.943	947.491
768.198	950.071
768.454	930.674
768.709	921.342
768.965	927.893
769.22	922.064
769.475	902.089
769.731	902.9
769.986	872.726
770.242	885.024
770.497	898.698
770.752	883.785
771.007	887.694
771.263	858.266
771.518	850.263
771.773	852.473
772.028	836.997
772.284	832.054
772.539	849.965
772.794	816.795
773.049	813.648
773.304	819.115
773.56	818.055
773.815	811.931
774.07	810.212
774.325	800.782
774.58	806.831
774.835	800.932
775.09	763.496
775.345	787.619
775.6	775.854
775.855	761.565
776.11	764.901
776.365	756.959
776.62	761.529
776.875	745.078
777.13	727.439
777.385	725.905
777.64	720.738
777.895	729.97
778.149	714.171
778.404	713.419
778.659	708.425
778.914	699.483
779.169	698.867
779.424	695.547
779.678	695.334
779.933	684.417
780.188	695.078
780.442	680.896
780.697	674.467
780.952	663.791
781.207	664.227
781.461	663.393
781.716	647.421
781.97	665.687
782.225	637.451
782.48	651.052
782.734	634.724
782.989	605.248
783.243	617.935
783.498	617.36
783.752	612.721
784.007	601.144
784.253	607.95
784.509	613.741
784.764	580.163
785.019	579.705
785.274	604.264
785.53	578.182
785.785	568.83
786.04	575.234
786.295	581.249
786.551	565.399
786.806	565.02
787.061	553.88
787.316	556.198
787.571	574.48
787.826	546.606
788.081	528.379
788.336	536.577
788.591	527.119
788.847	525.314
789.102	519.497
789.357	528.909
789.612	512.849
789.867	513.136
790.122	519.952
790.377	513.46
790.632	511.072
790.886	524.691
791.141	496.867
791.396	501.538
791.651	485.929
791.906	499.118
792.161	506.909
792.416	482.905
792.671	458.379
792.925	472.51
793.18	477.802
793.435	472.923
793.69	470.913
793.945	462.063
794.199	455.604
794.454	444.456
794.709	455.966
794.963	443.237
795.218	461.339
795.473	446.124
795.727	437.973
795.982	441.304
796.237	430.079
796.491	426.102
796.746	415.955
797	415.988
797.255	435.291
797.509	420.944
797.764	406.548
798.018	418.074
798.273	402.281
798.527	419.76
798.782	392.957
799.036	405.806
799.291	403.432
799.545	395.156
799.8	391.575
800.054	388.291
800.308	375.589
800.563	377.129
800.817	382.765
801.071	385.173
801.326	375.523
801.58	372.766
801.834	363.998
802.088	349.643
802.343	364.229
802.597	362.66
802.851	360.55
803.105	343.443
803.359	350.143
803.614	341.5
803.868	348.947
804.122	342.304
804.376	357.583
804.63	325.359
804.884	346.545
805.138	321.101
805.392	337.755
805.646	322.65
805.9	344.134
806.154	320.341
806.408	323.336
806.662	326.715
806.916	309.553
807.17	323.256
807.424	308.755
807.678	329.694
807.932	315.938
808.186	302.452
808.439	315.197
808.693	304.326
808.947	312.304
809.201	295.629
809.455	300.525
809.708	296.003
809.962	297.465
810.183	294
810.438	299.875
810.693	283.988
810.947	270.511
811.202	295.384
811.456	286.675
811.711	274.856
811.965	295.647
812.22	296.598
812.474	281.999
812.729	278.64
812.983	272.412
813.237	258.723
813.492	263.406
813.746	279.552
814.001	270.834
814.255	258.135
814.509	273.237
814.764	262.761
815.018	271.459
815.272	254.848
815.526	258.859
815.781	265
816.035	254.896
816.289	244.997
816.543	250.53
816.798	250.108
817.052	246.532
817.306	231.127
817.56	248.702
817.814	245.157
818.068	233.209
818.323	246.633
818.577	244.236
818.831	254.07
819.085	241.076
819.339	233.748
819.593	233.388
819.847	222.227
820.101	225.46
820.355	225.208
820.609	223.299
820.863	220.497
821.117	211.818
821.371	227.741
821.624	220.01
821.878	209.437
822.132	216.81
822.386	220.656
822.64	217.53
822.894	193.362
823.148	211.683
823.401	215.748
823.655	200.141
823.909	205.792
824.163	209.211
824.416	200.047
824.67	197.447
824.924	199.764
825.177	199.962
825.431	199.405
825.685	197.745
825.938	197.264
826.192	198.125
826.446	192.056
826.699	189.092
826.953	190.802
827.206	193.523
827.46	190.602
827.713	174.478
827.967	184.928
828.22	189.412
828.474	172.711
828.727	191.143
828.981	192.007
829.234	178.686
829.488	183.175
829.741	179.464
829.994	182.808
830.248	180.171
830.501	172.631
830.754	173.379
831.008	163.894
831.261	179.423
831.514	173.508
831.767	179.427
832.021	173.77
832.274	167.892
832.527	171.248
832.78	160.721
833.034	167.346
833.287	162.94
833.54	164.491
833.793	165.232
834.046	164.304
834.299	164.033
834.552	159.338
834.805	159.757
835.058	156.237
835.311	163.308
835.564	175.257
835.817	161.334
836.07	162.055
836.314	148.044
836.568	157.868
836.821	159.874
837.075	157.784
837.329	140.544
837.583	152.182
837.836	164.702
838.09	150.222
838.344	149.471
838.598	146.987
838.851	146.411
839.105	160.158
839.359	143.939
839.612	147.918
839.866	150.031
840.119	140.417
840.373	141.751
840.627	143.768
840.88	144.046
841.134	133.777
841.387	152.294
841.641	143.25
841.894	144.038
842.148	137.069
842.401	136.499
842.655	135.34
842.908	134.227
843.161	129.084
843.415	137.256
843.668	136.97
843.922	129.641
844.175	131.678
844.428	140.838
844.682	130.149
844.935	127.879
845.188	133.024
845.442	135.837
845.695	128.528
845.948	136.828
846.201	125.97
846.455	131.827
846.708	125.004
846.961	122
847.214	123.312
847.467	132.387
847.72	121.167
847.973	120.68
848.227	119.742
848.48	123.596
848.733	118.656
848.986	117.16
849.239	125.112
849.492	116.955
849.745	121.731
849.998	122.197
850.251	118.777
850.504	121.54
850.757	115.782
851.01	114.845
851.263	121.191
851.515	113.896
851.768	120.618
852.021	111.072
852.274	106.235
852.527	123.038
852.78	115.834
853.032	111.143
853.285	110.301
853.538	107.288
853.791	110.251
854.043	111.76
854.296	119.663
854.549	108.749
854.801	108
855.054	106.061
855.307	99.0777
855.559	110.276
855.812	112.61
856.065	107.658
856.317	101.645
856.57	99.0524
856.822	103.448
857.075	111.611
857.327	102.34
857.58	100.594
857.832	103.393
858.085	99.8381
858.337	100.902
858.589	100.037
858.842	105.923
859.094	102.091
859.347	94.6399
859.599	96.7653
859.851	98.4216
860.104	108.096
860.356	100.27
860.608	95.7691
860.861	96.7528
861.113	94.2963
861.365	104.519
861.617	86.0488
861.869	101.062
862.112	96.002
862.365	88.1101
862.618	90.0217
862.871	101.698
863.124	92.1136
863.377	97.8392
863.63	93.9232
863.883	93.7042
864.136	86.2277
864.389	94.7658
864.642	99.0116
864.894	95.053
865.147	92.6038
865.4	93.3476
865.653	88.8246
865.906	84.5164
866.159	89.7473
866.412	99.7702
866.664	86.9672
866.917	85.1227
867.17	88.4497
867.423	81.2235
867.675	91.2519
867.928	82.5827
868.181	80.165
868.433	89.8446
868.686	90.0949
868.939	84.0699
869.191	82.7864
869.444	95.2786
869.697	84.9354
869.949	85.565
870.202	83.2515
870.454	82.5152
870.707	84.4175
870.959	79.4115
871.212	86.6773
871.464	84.7703
871.717	76.7883
871.969	84.3929
872.222	76.6675
872.474	83.5705
872.727	82.002
872.979	72.076
873.231	77.9129
873.484	80.1113
873.736	77.0179
873.988	78.0453
874.241	80.4745
874.493	76.7606
874.745	81.467
874.998	78.4097
875.25	73.284
875.502	68.1404
875.754	71.884
876.006	71.9188
876.259	71.4987
876.511	74.7739
876.763	73.1653
877.015	76.6971
877.267	69.8703
877.519	78.4369
877.771	69.2027
878.023	75.1503
878.276	77.394
878.528	67.6923
878.78	71.1148
879.031	73.384
879.284	73.9649
879.535	69.8445
879.787	74.2061
880.039	74.1043
880.291	71.902
880.543	67.9747
880.795	66.6473
881.047	73.6054
881.299	67.6909
881.551	67.8614
881.802	71.904
882.054	64.963
882.306	66.8194
882.558	71.2924
882.809	67.8092
883.061	70.1315
883.313	63.8608
883.565	62.1644
883.816	65.5395
884.068	68.4321
884.319	70.1264
884.571	68.3411
884.823	70.7421
885.074	74.1253
885.326	65.2127
885.577	63.6183
885.829	67.794
886.08	68.0921
886.332	57.5468
886.583	57.7765
886.835	65.4372
887.086	65.5616
887.338	63.9309
887.589	63.9294
887.841	71.8093
888.044	71.8003
888.296	63.9607
888.548	61.8449
888.8	69.0775
889.053	61.5379
889.305	63.8579
889.557	49.3495
889.809	64.722
890.061	57.1073
890.313	59.6763
890.566	59.4564
890.818	60.8262
891.07	61.9939
891.322	61.6345
891.574	54.7093
891.826	58.4323
892.078	58.0124
892.33	53.8281
892.582	58.8963
892.834	59.858
893.086	59.5436
893.338	59.5072
893.59	57.3655
893.842	52.1912
894.094	58.0145
894.346	54.0169
894.597	55.0483
894.849	57.8406
895.101	55.8333
895.353	58.1427
895.605	51.3478
895.857	55.1039
896.108	52.7609
896.36	59.1353
896.612	58.2391
896.864	55.8235
897.115	53.4457
897.367	52.6014
897.619	52.7836
897.87	55.2334
898.122	45.4982
898.374	56.2648
898.625	55.5635
898.877	56.5067
899.128	53.0568
899.38	57.994
899.631	56.9589
899.883	55.7279
899.984	55.1114