File: PL_230124_Amostra_HPHT_polida_01.txt
#Acq. time (s)=	3
#Accumulations=	2
#Range (nm)=	520...900
#Windows=	16
#Auto scanning=	On
#Autofocus=	Off
#AutoExposure=	Off
#Spike filter=	Multiple accum.
#Delay time (s)=	0
#Binning=	1
#Readout mode=	Signal
#DeNoise=	Off
#ICS correction=	Off
#Dark correction=	Off
#Inst. Process=	Off
#Detector temperature (°C)=	-59.98
#Instrument=	LabRAM HR Evol
#Detector=	Syncerity OE
#Objective=	x50_VIS
#Grating=	600 (500nm)
#ND Filter=	10%
#Laser=	514nm_Edge
#Hole=	199.981
#Range=	Auto
#StageXY=	Marzhauser
#StageZ=	Marzhauser
#X (µm)=	6837.6
#Y (µm)=	8027.4
#Z (µm)=	80.2
#Full time(mm:ss)=	2:45
#Project=
#Sample=
#Site=
#Title=	PL_230124_Amostra_HPHT_polida
#Remark=
#Date=	31.01.2024 11:16
#Acquired=	31.01.2024 11:16:51
520.042	41
520.304	35.1537
520.565	39.1187
520.827	47.5116
521.089	36.1581
521.351	38.9105
521.612	38.7066
521.874	37.3248
522.136	41.2372
522.397	40.4878
522.659	41.3132
522.921	38.1467
523.182	35.3143
523.444	39.1618
523.705	36.6461
523.967	36
524.229	45.787
524.49	40.6217
524.752	45
525.013	39
525.275	41
525.536	39
525.798	43.2573
526.059	35.071
526.321	45.2782
526.582	45.1339
526.844	46.8065
527.105	43.3085
527.367	36
527.628	48.6807
527.889	43.979
528.151	38.3508
528.412	47.2782
528.674	50.2564
528.935	40.3823
529.196	42.7855
529.458	42.4033
529.719	41.9312
529.98	40
530.242	43
530.503	41.4476
530.764	45.458
531.025	44.5315
531.287	40.9604
531.548	42.042
531.809	43.0047
532.07	45.0699
532.332	48.5233
532.593	48.7972
532.854	43.5455
533.115	44.1142
533.376	50.8648
533.638	46.6201
533.899	47.6841
534.16	42.2927
534.421	54.4521
534.682	48.6696
534.943	49.0546
535.204	45.8527
535.465	47.4926
535.726	54.5187
535.987	50.8358
536.248	48.51
536.509	53.3891
536.77	49.1355
537.031	57.2193
537.292	47.9217
537.553	51.0724
537.814	56.6673
538.075	48.1476
538.336	52.0455
538.597	54.5444
538.858	52.1233
539.119	51.0769
539.38	58.5685
539.641	49.0199
539.901	53.9098
540.162	50.456
540.423	55.5779
540.684	57.6749
540.945	51.2797
541.205	53.9072
541.466	50.4771
541.727	55.113
541.988	54.5002
542.248	59.8755
542.509	58.0944
542.77	60.5433
543.031	60.5418
543.291	57.6133
543.552	58.5291
543.813	65.2288
544.073	59.0938
544.334	56.0206
544.594	59.1334
544.855	62.1761
545.116	63.2399
545.376	64.1415
545.637	65.32
545.897	56.5259
546.158	61.3857
546.418	61.17
546.679	70.4892
546.898	71.7872
547.159	75.57
547.42	66.0614
547.681	64.3298
547.942	75.8763
548.203	73.8203
548.464	68.2997
548.725	77.4704
548.987	83.1397
549.248	79.5338
549.509	85.954
549.77	78.3788
550.031	85.1475
550.292	78.0105
550.553	91.6017
550.814	98.3807
551.075	93.424
551.336	101.818
551.597	106.707
551.858	130.074
552.119	185.213
552.38	940.373
552.641	10115.7
552.901	335.825
553.162	160.575
553.423	121.754
553.684	127.534
553.945	113.597
554.206	108.764
554.467	110.101
554.727	119.22
554.988	110.981
555.249	110.18
555.51	114.886
555.771	120.754
556.031	114.654
556.292	103.952
556.553	111.867
556.814	120.949
557.074	119.952
557.335	123.839
557.596	126.765
557.856	132.99
558.117	124.013
558.378	130.029
558.638	136.35
558.899	144.782
559.16	141.338
559.42	138.343
559.681	140.088
559.941	140.668
560.202	135.716
560.463	146.676
560.723	155.638
560.984	156.079
561.244	153.504
561.505	152.492
561.765	160.506
562.026	168.647
562.286	166.929
562.547	166.181
562.807	175.807
563.067	174.543
563.328	168.231
563.588	178.468
563.849	179.49
564.109	176.373
564.369	194.023
564.63	191.61
564.89	195.318
565.15	198.173
565.411	199.882
565.671	205.599
565.931	215.466
566.192	214.759
566.452	210.679
566.712	205.605
566.972	218.148
567.232	228.435
567.493	233.521
567.753	235.334
568.013	237.628
568.273	242.253
568.533	248.189
568.794	251.047
569.054	252.294
569.314	253.441
569.574	268.163
569.834	274.98
570.094	282.297
570.354	280.864
570.614	283.342
570.874	295.183
571.134	324.369
571.394	319.179
571.654	320.833
571.914	348.121
572.174	339.412
572.434	381.17
572.694	400.447
572.954	429.185
573.214	438.457
573.459	452.134
573.719	509.694
573.98	549.576
574.241	605.197
574.501	651.328
574.762	697.675
575.022	777.591
575.283	808.847
575.543	817.788
575.804	879.122
576.064	850.912
576.325	826.588
576.585	809.968
576.846	768.948
577.106	719.605
577.366	673.861
577.627	658.002
577.887	624.945
578.148	576.112
578.408	557.358
578.668	567.212
578.929	554.832
579.189	530.514
579.449	545.718
579.71	526.795
579.97	531.191
580.23	543.665
580.49	539.736
580.751	541.208
581.011	532.328
581.271	537.599
581.531	556.802
581.792	561.148
582.052	569.136
582.312	563.672
582.572	582.145
582.832	569.241
583.092	583.655
583.353	604.838
583.613	589.527
583.873	607.802
584.133	622.546
584.393	639.993
584.653	646.663
584.913	658.748
585.173	683.109
585.433	695.495
585.693	684.605
585.953	684.135
586.213	704.338
586.473	727.155
586.733	712.873
586.993	723.434
587.253	716.391
587.513	716.155
587.773	735.458
588.033	731.782
588.293	773.24
588.552	769.537
588.812	749.024
589.072	762.163
589.332	772.014
589.592	754.098
589.852	777.726
590.112	768.558
590.371	771.897
590.631	799.275
590.891	757.617
591.151	754.165
591.41	762.5
591.67	759.753
591.93	747.279
592.189	752.163
592.449	742.781
592.709	746.324
592.968	739.699
593.228	740.617
593.488	759.94
593.747	756.011
594.007	759.028
594.266	742.522
594.526	764.816
594.786	758.242
595.045	762.475
595.305	775.955
595.564	777.564
595.824	788.452
596.083	796.979
596.343	813.844
596.602	817.408
596.862	840.014
597.121	828.414
597.38	825.444
597.64	827.365
597.899	846.755
598.159	840.207
598.418	832.39
598.677	833.688
598.937	848.41
599.196	861.26
599.455	862.082
599.715	861.737
599.959	845.964
600.219	863.831
600.479	851.989
600.738	879.172
600.998	839.814
601.258	878.115
601.518	897.933
601.778	869.828
602.038	906.157
602.298	885.626
602.558	886.777
602.818	890.806
603.078	890.159
603.337	907.562
603.597	912.402
603.857	889.874
604.117	909.399
604.377	905.953
604.636	917.617
604.896	910.557
605.156	915.369
605.416	915.081
605.675	915.406
605.935	903.971
606.195	899.593
606.455	914.868
606.714	921.393
606.974	913.638
607.234	907.639
607.493	932.209
607.753	935.805
608.012	918.887
608.272	918.003
608.532	945.994
608.791	923.549
609.051	934.156
609.31	956.808
609.57	957.039
609.829	968.893
610.089	938.369
610.348	976.113
610.608	961.012
610.867	965.933
611.127	967.889
611.386	986.031
611.646	989.442
611.905	980.668
612.164	995.241
612.424	999.935
612.683	1001.22
612.943	1019.74
613.202	1019.04
613.461	1013.7
613.721	1050.21
613.98	1077.04
614.239	1057.05
614.498	1058.92
614.758	1072.29
615.017	1086.34
615.276	1110.99
615.535	1089.92
615.795	1109.63
616.054	1124
616.313	1113.27
616.572	1106.77
616.831	1153.65
617.091	1141.01
617.35	1156.92
617.609	1163.84
617.868	1154.8
618.127	1176.46
618.386	1207.62
618.645	1215.89
618.904	1209.77
619.163	1243.94
619.422	1240.98
619.681	1251.25
619.94	1235.76
620.199	1238.87
620.458	1276.41
620.717	1285.59
620.976	1254.25
621.235	1311.22
621.494	1247.65
621.753	1305.69
622.012	1270.71
622.271	1286.82
622.53	1305.81
622.788	1309.94
623.047	1298.17
623.306	1290.4
623.565	1323.62
623.824	1337.49
624.082	1322.04
624.341	1327.08
624.6	1318.5
624.859	1299.09
625.117	1351.75
625.376	1312.49
625.635	1344.55
625.893	1352.48
626.152	1382.88
626.368	1369.76
626.627	1369.2
626.887	1403.91
627.146	1370.65
627.405	1390.59
627.665	1422.1
627.924	1416.65
628.183	1378.79
628.443	1399.2
628.702	1421.77
628.961	1463.49
629.22	1447.75
629.479	1445.99
629.739	1479.25
629.998	1461.91
630.257	1482.83
630.516	1494.01
630.776	1514.09
631.035	1499.29
631.294	1507.79
631.553	1512.67
631.812	1543.43
632.071	1531.43
632.33	1580.7
632.589	1559.92
632.848	1547.74
633.107	1599.32
633.366	1635.82
633.625	1623.07
633.885	1659.91
634.143	1629
634.403	1676.84
634.661	1672.9
634.92	1737.83
635.179	1737.25
635.438	1774.65
635.697	1816.62
635.956	1866.93
636.215	1920.59
636.474	1956.92
636.733	2050.9
636.992	2136.26
637.25	2264.45
637.509	2406
637.768	2520.52
638.027	2619.57
638.286	2614.35
638.544	2567.82
638.803	2520.1
639.062	2442.97
639.321	2368.35
639.579	2289.5
639.838	2244.71
640.097	2194.26
640.356	2153.21
640.614	2115.12
640.873	2133.9
641.131	2112.5
641.39	2093.35
641.649	2122.05
641.907	2068.91
642.166	2087.18
642.424	2095.18
642.683	2086.62
642.942	2103.67
643.2	2107.32
643.459	2134.55
643.717	2131.23
643.976	2151.74
644.234	2130.2
644.493	2160.14
644.751	2130.74
645.009	2131.94
645.268	2167.29
645.526	2212.55
645.785	2168.3
646.043	2189.79
646.301	2187.54
646.56	2218.96
646.818	2208.65
647.076	2220.23
647.335	2233.29
647.593	2261.69
647.851	2261.69
648.109	2275.73
648.368	2278.7
648.626	2358.53
648.884	2347.55
649.142	2293.87
649.401	2319.22
649.659	2367.2
649.917	2373.9
650.175	2403.81
650.433	2409.77
650.691	2432.25
650.949	2462.21
651.208	2464.53
651.466	2473.15
651.724	2488.84
651.982	2490.53
652.24	2496.81
652.498	2524.55
652.756	2606.8
652.979	2532.28
653.238	2610.49
653.497	2576.92
653.755	2650.26
654.014	2672.32
654.273	2741.91
654.531	2685.83
654.79	2797.13
655.049	2758.72
655.307	2808.44
655.566	2829.83
655.824	2844.28
656.083	2925.74
656.342	2943.35
656.6	2995.85
656.859	3014.01
657.117	2963.93
657.376	3048.58
657.634	3046.53
657.893	3095.39
658.151	3156.46
658.41	3154.96
658.668	3113.18
658.927	3192.36
659.185	3152.65
659.443	3180.41
659.702	3200.32
659.96	3210.24
660.219	3178.87
660.477	3226.84
660.735	3223.32
660.994	3192.62
661.252	3159.6
661.51	3189.75
661.768	3206
662.027	3208.05
662.285	3232.99
662.543	3184.68
662.802	3227.17
663.06	3200.32
663.318	3200.47
663.576	3194.26
663.834	3226.12
664.093	3274.28
664.351	3214.65
664.609	3189.39
664.867	3203.65
665.125	3205.57
665.383	3189.14
665.641	3225.08
665.899	3206.25
666.157	3209.75
666.415	3234.96
666.673	3227.76
666.931	3206.68
667.189	3188.33
667.447	3181.65
667.705	3188.04
667.963	3193.62
668.221	3184.68
668.479	3203.04
668.737	3218.71
668.995	3222.26
669.253	3180.61
669.511	3160.94
669.769	3217.77
670.027	3236.21
670.284	3244.66
670.542	3271.48
670.8	3223.88
671.058	3203.44
671.316	3155.14
671.573	3224.01
671.831	3207.59
672.089	3208.1
672.347	3259.55
672.604	3244.6
672.862	3241.71
673.12	3246.03
673.377	3279.45
673.635	3293.09
673.893	3319.27
674.15	3315.86
674.408	3347.99
674.665	3369.88
674.923	3410.49
675.18	3409.46
675.438	3440.53
675.696	3453.88
675.953	3418.79
676.211	3401.96
676.468	3429.59
676.726	3455.2
676.983	3448.92
677.24	3451.53
677.498	3448.37
677.755	3437.2
678.013	3467.51
678.27	3429.36
678.527	3454.8
678.785	3458.49
679.042	3470.87
679.277	3496.17
679.535	3476.51
679.793	3455.01
680.051	3510.61
680.309	3519.75
680.567	3458.58
680.825	3490.96
681.083	3545.66
681.341	3563.68
681.599	3541.04
681.857	3593.05
682.115	3587.03
682.373	3515.8
682.631	3608.76
682.889	3669.66
683.146	3614
683.404	3612.16
683.662	3616.03
683.92	3648.23
684.178	3584.66
684.436	3631.36
684.694	3574.76
684.951	3534.75
685.209	3558.61
685.467	3550.66
685.725	3534.13
685.982	3552.27
686.24	3519.48
686.498	3479.24
686.756	3522.39
687.013	3508.37
687.271	3529.04
687.529	3487.62
687.786	3513.23
688.044	3530.57
688.302	3515.89
688.559	3525.67
688.817	3530.98
689.074	3473.2
689.332	3554.71
689.589	3475.59
689.847	3538.16
690.104	3515.64
690.362	3505.32
690.619	3454.28
690.877	3453.87
691.134	3437.48
691.392	3461.02
691.649	3440.66
691.907	3448.89
692.164	3410.54
692.421	3429.57
692.679	3408.31
692.936	3408.33
693.194	3375.66
693.451	3392.78
693.708	3373.76
693.966	3357.68
694.223	3384.94
694.48	3340.99
694.737	3382.33
694.995	3352.82
695.252	3359.34
695.509	3313.96
695.766	3331.24
696.023	3329.03
696.281	3271.14
696.538	3277.47
696.795	3300.62
697.052	3284.83
697.309	3262.16
697.566	3216.95
697.823	3239.87
698.08	3203.86
698.338	3183.78
698.595	3176.02
698.852	3209.96
699.109	3168.16
699.366	3185.93
699.623	3216.18
699.88	3199.02
700.137	3163.09
700.393	3182
700.65	3193.87
700.907	3175.17
701.164	3174.96
701.421	3149.14
701.678	3191.84
701.935	3146.96
702.192	3181.93
702.448	3153.79
702.705	3179.12
702.962	3129.31
703.219	3152.79
703.476	3157.38
703.732	3156.71
703.989	3157.56
704.246	3118.06
704.503	3138.86
704.759	3150.23
705.016	3078.97
705.273	3137.68
705.511	3084.05
705.768	3090.16
706.026	3075.92
706.283	3042.45
706.541	2970.89
706.798	2999.74
707.055	3031.79
707.313	2968.6
707.57	2992.7
707.827	2998.7
708.084	2975.44
708.342	2987.59
708.599	2962.12
708.856	2929.42
709.114	2916.28
709.371	2921.74
709.628	2938.32
709.885	2906.71
710.142	2898.63
710.4	2883.96
710.657	2919.15
710.914	2840.49
711.171	2896.86
711.428	2862.26
711.685	2876.48
711.942	2869.39
712.199	2818.52
712.456	2771.64
712.713	2844.62
712.97	2807
713.227	2728.1
713.484	2723.27
713.741	2765.03
713.998	2691.41
714.255	2721.37
714.512	2721.55
714.769	2663.2
715.026	2666.1
715.283	2652.84
715.54	2637.72
715.797	2591.72
716.054	2614.72
716.31	2581.41
716.567	2633.03
716.824	2611.64
717.081	2589.32
717.338	2579.33
717.594	2585.96
717.851	2576.31
718.108	2597.63
718.365	2557.4
718.621	2538.51
718.878	2525.47
719.135	2534.78
719.391	2517.82
719.648	2492.65
719.905	2494.86
720.161	2464.37
720.418	2461.78
720.675	2446.13
720.931	2415.05
721.188	2422.42
721.444	2417.88
721.701	2394.18
721.957	2371.34
722.214	2379.26
722.47	2341.17
722.727	2357.02
722.983	2320.08
723.24	2339.84
723.496	2327.34
723.753	2296.98
724.009	2319.05
724.265	2306.36
724.522	2249.09
724.778	2273.54
725.034	2274.15
725.291	2255.03
725.547	2248.9
725.803	2242.95
726.06	2206.19
726.316	2216.2
726.572	2208.36
726.828	2165.57
727.085	2167.38
727.341	2184.64
727.597	2158.59
727.853	2118.95
728.109	2147.48
728.366	2140.09
728.622	2142.9
728.878	2116.04
729.134	2099.43
729.39	2077.68
729.646	2077.33
729.902	2036.51
730.158	2033.6
730.414	2026.8
730.67	1981.89
730.926	1959.38
731.182	1958.25
731.438	1958.7
731.643	1964
731.9	1950.35
732.156	1882.01
732.413	1957.56
732.67	1926.52
732.927	1929.22
733.183	1919.29
733.44	1929.69
733.697	1914.46
733.953	1938.36
734.21	1924.18
734.466	1922.53
734.723	1896.3
734.98	1926.97
735.236	1932.76
735.493	1882.36
735.749	1920.46
736.006	1889.45
736.262	1964.11
736.519	1925.66
736.775	1938.1
737.032	1943.91
737.288	1957.35
737.544	1976.22
737.801	2014.15
738.057	1978.85
738.314	2015.24
738.57	1994.03
738.826	1970.23
739.083	1941.13
739.339	1953.48
739.595	1873.15
739.852	1850.52
740.108	1863.67
740.364	1896.64
740.621	1869.92
740.877	1833.94
741.133	1819.75
741.389	1830.2
741.645	1763.44
741.902	1782.86
742.158	1738.12
742.414	1781.75
742.67	1721.08
742.926	1710.48
743.182	1727.42
743.438	1711.09
743.694	1716.86
743.951	1696.11
744.207	1686.06
744.463	1663.03
744.719	1653.73
744.975	1650.66
745.231	1651.81
745.487	1621.56
745.743	1616.63
745.998	1661.85
746.254	1607.99
746.51	1608.53
746.766	1614.07
747.022	1613.89
747.278	1583.07
747.534	1571.21
747.79	1573.4
748.046	1557.11
748.301	1535.77
748.557	1555.33
748.813	1534.44
749.069	1552.14
749.324	1529.55
749.58	1536.05
749.836	1519.69
750.092	1518.55
750.347	1527.74
750.603	1483.47
750.859	1504.17
751.114	1488.52
751.37	1479.04
751.625	1469.39
751.881	1447.41
752.137	1457.95
752.392	1458.88
752.648	1414.49
752.903	1419.69
753.159	1413.67
753.414	1413.82
753.67	1411.54
753.925	1381.75
754.181	1405.63
754.436	1379.68
754.692	1378.56
754.947	1392.41
755.202	1359.81
755.458	1354.32
755.713	1320.58
755.968	1312.02
756.224	1338.09
756.479	1323.61
756.734	1317.66
756.99	1270.05
757.245	1312.98
757.5	1267.48
757.755	1261.05
757.968	1298.01
758.224	1282.12
758.48	1261.73
758.736	1267.51
758.992	1245.97
759.248	1273.4
759.504	1270.23
759.76	1226.1
760.016	1206.24
760.272	1203.64
760.528	1226.58
760.784	1217.84
761.04	1213.56
761.296	1182.1
761.552	1189.52
761.807	1187.97
762.063	1185.35
762.319	1182.57
762.575	1172.8
762.831	1133.4
763.086	1140.06
763.342	1165.44
763.598	1104.39
763.853	1127.35
764.109	1110.88
764.365	1123.35
764.621	1116.85
764.876	1106.71
765.132	1075.92
765.387	1082.75
765.643	1070.58
765.899	1072.83
766.154	1072.61
766.41	1068.06
766.665	1058.24
766.921	1041.94
767.176	1041.26
767.432	1049.95
767.687	1045.3
767.943	1025.16
768.198	1031.05
768.454	1001.83
768.709	1001.46
768.965	1017.53
769.22	974.277
769.475	990.094
769.731	983.594
769.986	959.183
770.242	975.441
770.497	963.49
770.752	963.557
771.007	931.942
771.263	956.476
771.518	925.341
771.773	931.494
772.028	942.983
772.284	930.361
772.539	914.41
772.794	891.38
773.049	901.899
773.304	894.116
773.56	899.546
773.815	878.852
774.07	878.297
774.325	870.212
774.58	851.784
774.835	855.718
775.09	843.78
775.345	826.834
775.6	827.375
775.855	836.351
776.11	834.655
776.365	817.551
776.62	799.302
776.875	801.959
777.13	793.019
777.385	786.477
777.64	796.654
777.895	787.126
778.149	765.39
778.404	754.58
778.659	781.891
778.914	763.224
779.169	769.426
779.424	750.174
779.678	754.274
779.933	741.223
780.188	730.458
780.442	748.235
780.697	714.942
780.952	713.599
781.207	725.102
781.461	716.14
781.716	715.098
781.97	687.131
782.225	707.421
782.48	680.808
782.734	691.345
782.989	640.754
783.243	673.677
783.498	676.416
783.752	645.943
784.007	663.107
784.253	669.88
784.509	644.19
784.764	665.545
785.019	645.91
785.274	645.6
785.53	617.491
785.785	637.936
786.04	636.009
786.295	612.406
786.551	612.458
786.806	621.348
787.061	584.051
787.316	622.637
787.571	603.464
787.826	608.033
788.081	593.856
788.336	586.816
788.591	602.161
788.847	588.899
789.102	571.766
789.357	570.26
789.612	563.52
789.867	560.599
790.122	555.784
790.377	558.906
790.632	540.586
790.886	543.143
791.141	534.304
791.396	524.686
791.651	534.182
791.906	518.311
792.161	530.152
792.416	526.912
792.671	505.204
792.925	518.172
793.18	511.309
793.435	519.735
793.69	515.951
793.945	504.681
794.199	498.401
794.454	483.097
794.709	497.648
794.963	484.549
795.218	493.127
795.473	482.115
795.727	485.857
795.982	465.525
796.237	460.391
796.491	482.063
796.746	464.467
797	463.298
797.255	472.263
797.509	455.219
797.764	457.783
798.018	459.14
798.273	454.517
798.527	445.202
798.782	436.328
799.036	442.635
799.291	430.292
799.545	432.941
799.8	436.839
800.054	417.048
800.308	404.372
800.563	411.152
800.817	413.686
801.071	410.664
801.326	403.504
801.58	402.066
801.834	390.245
802.088	382.408
802.343	395.007
802.597	387.277
802.851	387.106
803.105	378.055
803.359	372.361
803.614	373.716
803.868	377.676
804.122	375.893
804.376	377.056
804.63	366
804.884	371.215
805.138	354.587
805.392	354.429
805.646	359.307
805.9	375.817
806.154	354.575
806.408	362.539
806.662	350.878
806.916	339.069
807.17	345.031
807.424	336.099
807.678	343.298
807.932	339.692
808.186	334.243
808.439	354.017
808.693	326.172
808.947	324.145
809.201	322.351
809.455	326.818
809.708	326.039
809.962	336.87
810.183	308
810.438	302.129
810.693	308.124
810.947	308.596
811.202	302.26
811.456	320.4
811.711	321.749
811.965	304.921
812.22	297.332
812.474	301.476
812.729	299.261
812.983	295.3
813.237	294.53
813.492	293.534
813.746	304.207
814.001	278.118
814.255	298.216
814.509	279.554
814.764	295.112
815.018	282.98
815.272	290.676
815.526	296.1
815.781	275.143
816.035	268.001
816.289	269.81
816.543	260.33
816.798	257.546
817.052	269.255
817.306	269.246
817.56	256.393
817.814	251.22
818.068	261.372
818.323	258.876
818.577	253.523
818.831	242.4
819.085	252.532
819.339	253.664
819.593	251.797
819.847	256.447
820.101	247.869
820.355	252.38
820.609	255.282
820.863	235.045
821.117	243.679
821.371	242.057
821.624	237.68
821.878	242.755
822.132	239.877
822.386	238.81
822.64	232.944
822.894	238.271
823.148	226.297
823.401	215.895
823.655	222.948
823.909	211.308
824.163	217.95
824.416	217.203
824.67	225.557
824.924	218.259
825.177	216.553
825.431	212.714
825.685	217.238
825.938	212.989
826.192	210.282
826.446	210.242
826.699	215.062
826.953	201.634
827.206	197.714
827.46	204.481
827.713	205.019
827.967	194.94
828.22	200.597
828.474	193.005
828.727	198.736
828.981	201.667
829.234	195.208
829.488	198.103
829.741	195.565
829.994	194.881
830.248	191.631
830.501	199.049
830.754	189.997
831.008	196.474
831.261	178.922
831.514	182.396
831.767	183.578
832.021	187.12
832.274	181.875
832.527	189.545
832.78	185.271
833.034	178.557
833.287	184.148
833.54	181.781
833.793	183.506
834.046	182.401
834.299	166.353
834.552	173.462
834.805	171.07
835.058	172.677
835.311	174.7
835.564	172.811
835.817	165.96
836.07	168.849
836.314	150.056
836.568	172.007
836.821	169.669
837.075	168.123
837.329	167.717
837.583	178.649
837.836	165.747
838.09	164.365
838.344	171.324
838.598	166.599
838.851	154.202
839.105	162.747
839.359	157.16
839.612	166.272
839.866	152.945
840.119	155.583
840.373	156.913
840.627	153.572
840.88	167.695
841.134	156.379
841.387	147.061
841.641	153.599
841.894	146.189
842.148	153.85
842.401	151.498
842.655	136.724
842.908	147.945
843.161	150.184
843.415	149.5
843.668	151.706
843.922	151.866
844.175	141.681
844.428	150.945
844.682	141.946
844.935	145.964
845.188	147.909
845.442	140.82
845.695	138.517
845.948	132.665
846.201	145.386
846.455	137.389
846.708	135.981
846.961	141.371
847.214	139.075
847.467	133.649
847.72	134.496
847.973	135.159
848.227	133.371
848.48	132.329
848.733	136.383
848.986	140.366
849.239	132.988
849.492	129.864
849.745	134.738
849.998	130.919
850.251	120.172
850.504	128.045
850.757	112.401
851.01	131.107
851.263	120.572
851.515	123.851
851.768	127.83
852.021	124.964
852.274	121.968
852.527	122.093
852.78	124.362
853.032	123.267
853.285	121.933
853.538	122.966
853.791	119.288
854.043	117.495
854.296	115.811
854.549	119.478
854.801	117.268
855.054	114.607
855.307	118.526
855.559	118.973
855.812	118.715
856.065	106.627
856.317	115.197
856.57	115.624
856.822	107.087
857.075	110.099
857.327	116.151
857.58	112.629
857.832	117.19
858.085	110.734
858.337	110.875
858.589	105.6
858.842	109.526
859.094	103.728
859.347	109.347
859.599	101.774
859.851	104.242
860.104	112.159
860.356	108.284
860.608	104.745
860.861	94.7384
861.113	110.068
861.365	103.735
861.617	96.0744
861.869	101.472
862.112	94.0117
862.365	96.0886
862.618	103.827
862.871	105.888
863.124	103.714
863.377	93.8065
863.63	90.4872
863.883	97.9715
864.136	105.192
864.389	100.089
864.642	96.3014
864.894	92.0107
865.147	99.5796
865.4	93.1333
865.653	97.2178
865.906	94.4165
866.159	93.0585
866.412	100.128
866.664	99.4646
866.917	100.404
867.17	93.7331
867.423	85.3006
867.675	96.8709
867.928	98.8347
868.181	87.3463
868.433	88.1983
868.686	86.0277
868.939	81.9795
869.191	90.834
869.444	79.3248
869.697	92.3486
869.949	80.72
870.202	96.2367
870.454	89.1359
870.707	91.7589
870.959	85.8301
871.212	91.9736
871.464	91.0491
871.717	84.0001
871.969	94.7814
872.222	81.2409
872.474	90.472
872.727	81.4565
872.979	84.9953
873.231	77.876
873.484	85.4061
873.736	80.6525
873.988	82.9181
874.241	85.6295
874.493	83.7786
874.745	84.3033
874.998	84.2854
875.25	77.2919
875.502	82.9649
875.754	78.8294
876.006	78.6068
876.259	83.6533
876.511	86.4697
876.763	79.9085
877.015	79.0805
877.267	77.4404
877.519	77.4984
877.771	82.4132
878.023	81.2488
878.276	76.9418
878.528	77.1334
878.78	81.4622
879.031	75.545
879.284	79.0333
879.535	80.5493
879.787	77.6676
880.039	75.8421
880.291	75.649
880.543	77.4409
880.795	73.2823
881.047	76.128
881.299	75.0495
881.551	70.9365
881.802	76.7124
882.054	71.8158
882.306	76.5612
882.558	73.29
882.809	74.764
883.061	73.235
883.313	76.4069
883.565	68.1489
883.816	70.7778
884.068	75.6506
884.319	78.1264
884.571	73.8502
884.823	68.5174
885.074	61.8665
885.326	70.3043
885.577	67.58
885.829	72.8983
886.08	74.3318
886.332	73.4844
886.583	59.8534
886.835	64.1297
887.086	72
887.338	71.1992
887.589	74.1413
887.841	61.9184
888.044	69.971
888.296	67.4866
888.548	63.8578
888.8	71.1257
889.053	68.6243
889.305	68.5575
889.557	82.6639
889.809	58.0639
890.061	66.2561
890.313	58.5775
890.566	63.8008
890.818	57.5795
891.07	60.2994
891.322	64.3252
891.574	62.6382
891.826	58.1225
892.078	65.2282
892.33	59.7967
892.582	60.8547
892.834	64.9696
893.086	62.6846
893.338	58.7933
893.59	57.8427
893.842	65.7079
894.094	63.0217
894.346	58.9746
894.597	54.0483
894.849	61.9601
895.101	63.3333
895.353	58.786
895.605	61.1304
895.857	57.2077
896.108	53.5978
896.36	59.1353
896.612	57
896.864	62.5042
897.115	60
897.367	52
897.619	59.7013
897.87	58.7666
898.122	59.2491
898.374	51.2056
898.625	58.1548
898.877	52.1947
899.128	55
899.38	54.3495
899.631	60.6941
899.883	54.364
899.984	55.5182