File: PL_Fatia_SCD_021223_03.txt
#Acq. time (s)=	3
#Accumulations=	2
#Range (nm)=	520...900
#Windows=	16
#Auto scanning=	On
#Autofocus=	Off
#AutoExposure=	Off
#Spike filter=	Multiple accum.
#Delay time (s)=	0
#Binning=	1
#Readout mode=	Signal
#DeNoise=	Off
#ICS correction=	Off
#Dark correction=	Off
#Inst. Process=	Off
#Detector temperature (°C)=	-59.98
#Instrument=	LabRAM HR Evol
#Detector=	Syncerity OE
#Objective=	x50_VIS
#Grating=	600 (500nm)
#ND Filter=	10%
#Laser=	514nm_Edge
#Hole=	199.981
#Range=	Auto
#StageXY=	Marzhauser
#StageZ=	Marzhauser
#X (µm)=	3093.7
#Y (µm)=	-1092.4
#Z (µm)=	-209.5
#Full time(mm:ss)=	2:39
#Project=
#Sample=
#Site=
#Title=	PL_Fatia_SCD_021223
#Remark=
#Date=	18.12.2023 18:04
#Acquired=	18.12.2023 18:04:23
520.042	44
520.304	44.1537
520.565	38.9406
520.827	43.0698
521.089	50.9209
521.351	49.6419
521.612	42.8801
521.874	43.4331
522.136	46.2372
522.397	43
522.659	46.8626
522.921	39.9732
523.182	49.1572
523.444	45.4971
523.705	46
523.967	47.6251
524.229	45.0163
524.49	39.6217
524.752	39.2165
525.013	41.454
525.275	48.4726
525.536	37
525.798	44
526.059	41.8033
526.321	40
526.582	39.3097
526.844	41.5082
527.105	42.9255
527.367	40.7226
527.628	38.9685
527.889	38.2984
528.151	47.9476
528.412	38.6391
528.674	38.2308
528.935	48.4709
529.196	40.8217
529.458	40.6131
529.719	37
529.98	49.8508
530.242	43.6923
530.503	45.6573
530.764	45.7098
531.025	44.4685
531.287	41.5991
531.548	42.958
531.809	42.9977
532.07	47
532.332	43.0932
532.593	46.6014
532.854	43.8182
533.115	53
533.376	42.2972
533.638	42.2297
533.899	44.8614
534.16	47.754
534.421	48.7506
534.682	49.1785
534.943	48.1379
535.204	49.3048
535.465	52.0297
535.726	49.2845
535.987	48.0215
536.248	51.2
536.509	49.9639
536.77	49.5749
537.031	47.8531
537.292	46.1977
537.553	49.9021
537.814	47.6863
538.075	46.867
538.336	52.7892
538.597	45.7256
538.858	50.3006
539.119	49.4684
539.38	47.6497
539.641	47.5503
539.901	50.7641
540.162	50.2289
540.423	56.7986
540.684	47.6749
540.945	52.4132
541.205	52.3833
541.466	50.8954
541.727	56.7167
541.988	52.9374
542.248	48.4864
542.509	49.071
542.77	53.2297
543.031	51.1239
543.291	58.1586
543.552	56.8862
543.813	47.699
544.073	53.6047
544.334	53.2877
544.594	49.062
544.855	58.1018
545.116	65.1183
545.376	55.1435
545.637	54.4139
545.897	58.4045
546.158	59.4504
546.418	57.7203
546.679	63.2464
546.898	61.9536
547.159	71.6595
547.42	67.7717
547.681	56.1488
547.942	73.4964
548.203	63.9668
548.464	74.1537
548.725	71.702
548.987	67.8152
549.248	71.5626
549.509	78.5169
549.77	82.756
550.031	78.4332
550.292	81.7179
550.553	80.8905
550.814	83.4318
551.075	88.9786
551.336	92.575
551.597	105.453
551.858	121.717
552.119	166.207
552.38	445.157
552.641	9655.79
552.901	741.857
553.162	175.429
553.423	129.924
553.684	113.125
553.945	111.552
554.206	116.245
554.467	95.8814
554.727	96.6128
554.988	109.527
555.249	97.5547
555.51	105.602
555.771	110.305
556.031	112.636
556.292	112.063
556.553	107.374
556.814	119.208
557.074	117.464
557.335	121.697
557.596	123.276
557.856	120.205
558.117	129.416
558.378	112.467
558.638	131.47
558.899	122.373
559.16	135.998
559.42	132.165
559.681	131.158
559.941	134.93
560.202	145.152
560.463	127.113
560.723	140.476
560.984	148.001
561.244	149.044
561.505	152.323
561.765	159.364
562.026	151.409
562.286	147.485
562.547	161.572
562.807	161.375
563.067	167.051
563.328	175.1
563.588	183.742
563.849	176.946
564.109	181.373
564.369	182.944
564.63	183.019
564.89	193.33
565.15	193.232
565.411	194.482
565.671	206.39
565.931	213.399
566.192	210.482
566.452	206.606
566.712	216.601
566.972	226.133
567.232	229.511
567.493	224.708
567.753	223.182
568.013	226.443
568.273	236.477
568.533	243.788
568.794	247.411
569.054	249.651
569.314	252.108
569.574	255.778
569.834	257.607
570.094	275.107
570.354	276.871
570.614	280.57
570.874	302
571.134	306.707
571.394	325.998
571.654	330.098
571.914	350.781
572.174	368.612
572.434	388.832
572.694	415.935
572.954	422.788
573.214	457.026
573.459	468.119
573.719	474.54
573.98	571.031
574.241	592.201
574.501	663.657
574.762	689.86
575.022	755.18
575.283	822.114
575.543	855.843
575.804	865.014
576.064	902.118
576.325	883.791
576.585	860.851
576.846	811.612
577.106	764.98
577.366	738.368
577.627	704.092
577.887	684.951
578.148	616.762
578.408	611.646
578.668	567.012
578.929	562.419
579.189	555.42
579.449	571
579.71	554.568
579.97	565.715
580.23	547.059
580.49	538.61
580.751	566.263
581.011	557.016
581.271	551.923
581.531	564.765
581.792	570.277
582.052	581.481
582.312	575.992
582.572	594.838
582.832	589.494
583.092	614.579
583.353	614.104
583.613	631.11
583.873	633.025
584.133	636.644
584.393	642.858
584.653	659.804
584.913	673.896
585.173	684.167
585.433	709.176
585.693	712.969
585.953	733.578
586.213	727.914
586.473	744.829
586.733	750.404
586.993	727.026
587.253	753.363
587.513	745.938
587.773	770.521
588.033	764.486
588.293	768.08
588.552	779.068
588.812	788.372
589.072	776.621
589.332	785.159
589.592	796.556
589.852	797.956
590.112	781.437
590.371	794.718
590.631	811.411
590.891	801.457
591.151	803.2
591.41	789.307
591.67	769.758
591.93	778.287
592.189	766.855
592.449	782.519
592.709	765.023
592.968	768.716
593.228	777.34
593.488	783.597
593.747	780.318
594.007	787.916
594.266	783.437
594.526	805.544
594.786	800.363
595.045	802.496
595.305	812.799
595.564	807.266
595.824	817.185
596.083	832.959
596.343	849.918
596.602	856.564
596.862	832.423
597.121	862.047
597.38	873.885
597.64	877.123
597.899	874.003
598.159	890.118
598.418	909.686
598.677	897.85
598.937	899.328
599.196	903.914
599.455	899.454
599.715	903.617
599.959	896.08
600.219	939.031
600.479	889.53
600.738	880.473
600.998	925.761
601.258	910.962
601.518	907.93
601.778	925.084
602.038	947.619
602.298	935.804
602.558	910.986
602.818	911.086
603.078	943.897
603.337	949.352
603.597	938.746
603.857	946.74
604.117	942.908
604.377	940.787
604.636	941.242
604.896	941.296
605.156	934.621
605.416	960.81
605.675	974.376
605.935	948.027
606.195	944.248
606.455	934.926
606.714	969.909
606.974	949.359
607.234	942.593
607.493	960.913
607.753	956.554
608.012	963.172
608.272	955.406
608.532	943.859
608.791	991.69
609.051	983.177
609.31	985.688
609.57	988.752
609.829	1025.88
610.089	1003.78
610.348	1004.23
610.608	997.412
610.867	1020.83
611.127	997.885
611.386	1017.7
611.646	1022.49
611.905	1020.2
612.164	1027.39
612.424	1006.38
612.683	1051.04
612.943	1050.17
613.202	1071.01
613.461	1061.41
613.721	1084.74
613.98	1084.56
614.239	1085.75
614.498	1110.42
614.758	1104.85
615.017	1111.63
615.276	1133.16
615.535	1132.69
615.795	1122
616.054	1156.24
616.313	1173.9
616.572	1164.02
616.831	1187.63
617.091	1175.73
617.35	1192.9
617.609	1214.93
617.868	1222.37
618.127	1237.16
618.386	1223.36
618.645	1261.38
618.904	1260.17
619.163	1238.31
619.422	1244.06
619.681	1280.67
619.94	1301.09
620.199	1261.59
620.458	1311.54
620.717	1314.98
620.976	1333.86
621.235	1309.77
621.494	1291.82
621.753	1319.21
622.012	1339.63
622.271	1325.72
622.53	1350.69
622.788	1323.23
623.047	1350.31
623.306	1357.26
623.565	1349.64
623.824	1374.31
624.082	1336
624.341	1347.61
624.6	1362.39
624.859	1344.17
625.117	1383.65
625.376	1389.53
625.635	1369.19
625.893	1399.23
626.152	1398.47
626.368	1395.98
626.627	1408.19
626.887	1431.44
627.146	1446.3
627.405	1430.67
627.665	1419.66
627.924	1435.85
628.183	1416.86
628.443	1483.52
628.702	1468.81
628.961	1460.45
629.22	1460.75
629.479	1506.21
629.739	1476.95
629.998	1488.2
630.257	1485.98
630.516	1518.95
630.776	1541.64
631.035	1499.49
631.294	1534.91
631.553	1564.65
631.812	1574.13
632.071	1620.05
632.33	1593.13
632.589	1583.71
632.848	1630.57
633.107	1625.87
633.366	1666.58
633.625	1630.36
633.885	1631.96
634.143	1669.53
634.403	1691.33
634.661	1713.06
634.92	1748.95
635.179	1774.45
635.438	1811.04
635.697	1816.23
635.956	1895.36
636.215	1935.28
636.474	1938.48
636.733	1983.19
636.992	2116.86
637.25	2169.63
637.509	2284.97
637.768	2407.56
638.027	2475.45
638.286	2518.38
638.544	2556.62
638.803	2540.85
639.062	2527.73
639.321	2435.42
639.579	2373
639.838	2321.53
640.097	2306.31
640.356	2228.12
640.614	2219.34
640.873	2187.55
641.131	2167.01
641.39	2150.26
641.649	2136.63
641.907	2134.74
642.166	2141.11
642.424	2115.49
642.683	2149.33
642.942	2140.13
643.2	2150.4
643.459	2130.99
643.717	2153.63
643.976	2169.14
644.234	2178.71
644.493	2172.56
644.751	2177.89
645.009	2211.06
645.268	2157.26
645.526	2141.58
645.785	2212.77
646.043	2223.62
646.301	2240.25
646.56	2249.85
646.818	2288.72
647.076	2281.1
647.335	2227.26
647.593	2267.41
647.851	2267
648.109	2253.72
648.368	2308.19
648.626	2322.18
648.884	2359.44
649.142	2354.53
649.401	2368.56
649.659	2389.92
649.917	2395.31
650.175	2414.57
650.433	2448.48
650.691	2469.5
650.949	2487.29
651.208	2472.55
651.466	2516.73
651.724	2503.96
651.982	2545.17
652.24	2574.51
652.498	2525.29
652.756	2582.58
652.979	2597.75
653.238	2628.97
653.497	2665.8
653.755	2652.4
654.014	2660.51
654.273	2721.44
654.531	2767.48
654.79	2733.63
655.049	2749.27
655.307	2774.93
655.566	2849.06
655.824	2849.28
656.083	2918.69
656.342	2919.51
656.6	2977.58
656.859	2999.03
657.117	2976.68
657.376	3028.89
657.634	3056.07
657.893	3100.83
658.151	3121.83
658.41	3098.81
658.668	3081.9
658.927	3147.92
659.185	3178.26
659.443	3162.3
659.702	3200.45
659.96	3200.35
660.219	3193.85
660.477	3257.12
660.735	3185.14
660.994	3189
661.252	3213.53
661.51	3212.42
661.768	3203.19
662.027	3240.39
662.285	3179.64
662.543	3218.92
662.802	3172.04
663.06	3201.96
663.318	3196.63
663.576	3174.69
663.834	3207.36
664.093	3202.16
664.351	3202.7
664.609	3217.03
664.867	3217.56
665.125	3155.67
665.383	3183.79
665.641	3204.76
665.899	3202.35
666.157	3177.72
666.415	3172.1
666.673	3190.97
666.931	3168.24
667.189	3127.32
667.447	3147.4
667.705	3176.11
667.963	3172.62
668.221	3150.52
668.479	3172.68
668.737	3168.78
668.995	3163.65
669.253	3175.53
669.511	3155.43
669.769	3187.78
670.027	3153.33
670.284	3177.02
670.542	3152.38
670.8	3169.98
671.058	3131.51
671.316	3174.9
671.573	3146.57
671.831	3145.2
672.089	3181.45
672.347	3179.54
672.604	3205.07
672.862	3199.75
673.12	3194.2
673.377	3228.06
673.635	3212.32
673.893	3265.92
674.15	3277.03
674.408	3297.11
674.665	3315.35
674.923	3307.86
675.18	3314.02
675.438	3309.95
675.696	3386.16
675.953	3379.47
676.211	3387.13
676.468	3408.65
676.726	3354.16
676.983	3325.04
677.24	3362.59
677.498	3398.98
677.755	3369.33
678.013	3418.91
678.27	3374.42
678.527	3382.72
678.785	3372.17
679.042	3404.23
679.277	3368.25
679.535	3408.07
679.793	3422.24
680.051	3362.05
680.309	3451.55
680.567	3394.11
680.825	3422.15
681.083	3464.08
681.341	3471.65
681.599	3503.56
681.857	3485.58
682.115	3503.82
682.373	3497.69
682.631	3491.95
682.889	3499.27
683.146	3534.83
683.404	3587.72
683.662	3526.85
683.92	3478.09
684.178	3483.74
684.436	3498.98
684.694	3464.64
684.951	3482.23
685.209	3433.22
685.467	3468.66
685.725	3493.09
685.982	3445.35
686.24	3453.06
686.498	3471.32
686.756	3446.33
687.013	3439.18
687.271	3444.5
687.529	3403.32
687.786	3425.46
688.044	3415.89
688.302	3404.76
688.559	3444.99
688.817	3439.29
689.074	3402.92
689.332	3421.63
689.589	3396.8
689.847	3453.98
690.104	3404.6
690.362	3364.07
690.619	3372.7
690.877	3363.24
691.134	3347.69
691.392	3359.28
691.649	3335.1
691.907	3311.02
692.164	3329.99
692.421	3278.26
692.679	3291.89
692.936	3280.29
693.194	3286.92
693.451	3250.04
693.708	3253.91
693.966	3243.99
694.223	3265.42
694.48	3269.28
694.737	3258.73
694.995	3265.37
695.252	3218.97
695.509	3223.03
695.766	3221.52
696.023	3173.68
696.281	3198.61
696.538	3167.94
696.795	3177.35
697.052	3146.46
697.309	3140.64
697.566	3132.97
697.823	3091
698.08	3165.76
698.338	3068.32
698.595	3060.22
698.852	3097.37
699.109	3045.34
699.366	3054.16
699.623	3057.28
699.88	3013.61
700.137	3052.12
700.393	3065.72
700.65	3052.56
700.907	3047.83
701.164	3034.9
701.421	3051.9
701.678	3050.86
701.935	3017.85
702.192	2995.88
702.448	3038.54
702.705	2998.89
702.962	3016.68
703.219	3011
703.476	3041.61
703.732	3011.09
703.989	3043.75
704.246	3002.72
704.503	3031.59
704.759	2965.25
705.016	2963.26
705.273	2973.82
705.511	2904.05
705.768	2872.58
706.026	2973.54
706.283	2910.04
706.541	2901.77
706.798	2930.65
707.055	2892.72
707.313	2839.11
707.57	2839.02
707.827	2833.54
708.084	2843.68
708.342	2812.15
708.599	2776.38
708.856	2822.29
709.114	2768.99
709.371	2795.97
709.628	2736.28
709.885	2771.14
710.142	2779.76
710.4	2825.37
710.657	2745.01
710.914	2776.39
711.171	2705.15
711.428	2749.01
711.685	2711.57
711.942	2704.06
712.199	2653.31
712.456	2637.18
712.713	2645.74
712.97	2644.2
713.227	2603.99
713.484	2567.13
713.741	2595.27
713.998	2562.39
714.255	2563.91
714.512	2556.59
714.769	2546.56
715.026	2546
715.283	2503.39
715.54	2543.98
715.797	2531.24
716.054	2476.28
716.31	2461.01
716.567	2459.02
716.824	2451.63
717.081	2489.08
717.338	2461.45
717.594	2411.23
717.851	2435.03
718.108	2436.12
718.365	2393.3
718.621	2384.82
718.878	2404.59
719.135	2368.3
719.391	2371.48
719.648	2342.37
719.905	2344.84
720.161	2349.89
720.418	2311.12
720.675	2306.1
720.931	2276.18
721.188	2269.48
721.444	2277.16
721.701	2247.26
721.957	2214.15
722.214	2255.78
722.47	2244.96
722.727	2207.97
722.983	2190.09
723.24	2177.41
723.496	2175.17
723.753	2166.56
724.009	2155.66
724.265	2143.88
724.522	2137.26
724.778	2143.99
725.034	2142.83
725.291	2106.12
725.547	2102.57
725.803	2096.06
726.06	2088.16
726.316	2077.11
726.572	2079.23
726.828	2056.35
727.085	2049.82
727.341	2026.24
727.597	2015.96
727.853	1986.05
728.109	1975.71
728.366	1982.28
728.622	1944.6
728.878	1957.72
729.134	1928.85
729.39	1920.13
729.646	1891.38
729.902	1892.25
730.158	1854.12
730.414	1874.46
730.67	1841.37
730.926	1843.09
731.182	1793.63
731.438	1814.94
731.643	1810
731.9	1792.31
732.156	1796.65
732.413	1757.29
732.67	1758.86
732.927	1762.76
733.183	1736.05
733.44	1756.91
733.697	1760.26
733.953	1776.78
734.21	1763.9
734.466	1711.64
734.723	1750.26
734.98	1727.47
735.236	1712.03
735.493	1717.7
735.749	1702.02
736.006	1706.98
736.262	1685.7
736.519	1691.46
736.775	1707.97
737.032	1641.01
737.288	1670.19
737.544	1681.76
737.801	1683.77
738.057	1685.22
738.314	1695.92
738.57	1645.98
738.826	1670.62
739.083	1640.97
739.339	1654.15
739.595	1649.15
739.852	1632.25
740.108	1624.03
740.364	1652.14
740.621	1604.43
740.877	1611.69
741.133	1615.7
741.389	1610.91
741.645	1574.92
741.902	1584.46
742.158	1583.97
742.414	1570.43
742.67	1561.84
742.926	1544.6
743.182	1546.12
743.438	1546.55
743.694	1540.67
743.951	1547.38
744.207	1505.46
744.463	1531.03
744.719	1506.88
744.975	1486.02
745.231	1496.33
745.487	1514.22
745.743	1484.99
745.998	1478.63
746.254	1468.01
746.51	1465.1
746.766	1475.75
747.022	1471.16
747.278	1437.19
747.534	1438.11
747.79	1455.36
748.046	1428.37
748.301	1402.84
748.557	1407.23
748.813	1404.22
749.069	1433.69
749.324	1398.41
749.58	1396.69
749.836	1411.57
750.092	1404.63
750.347	1366.45
750.603	1374.35
750.859	1363.63
751.114	1358.69
751.37	1347.1
751.625	1348.22
751.881	1333.69
752.137	1323.03
752.392	1318.72
752.648	1287.77
752.903	1310.08
753.159	1280.56
753.414	1298.14
753.67	1269.3
753.925	1269.33
754.181	1260.35
754.436	1298.56
754.692	1262.39
754.947	1262.51
755.202	1221.29
755.458	1260.03
755.713	1198.44
755.968	1200.13
756.224	1217.54
756.479	1232.98
756.734	1195.22
756.99	1191.75
757.245	1214.86
757.5	1168.91
757.755	1191.45
757.968	1164.04
758.224	1136.34
758.48	1140.52
758.736	1177
758.992	1129.83
759.248	1109.8
759.504	1156.64
759.76	1142.52
760.016	1102.12
760.272	1108.24
760.528	1085.9
760.784	1101.22
761.04	1081.58
761.296	1082.77
761.552	1078.66
761.807	1089.15
762.063	1071.87
762.319	1075.1
762.575	1054.39
762.831	1058.37
763.086	1018.98
763.342	1047.06
763.598	1019.14
763.853	1025.53
764.109	1013.97
764.365	1018.74
764.621	1017.11
764.876	1010.6
765.132	1004.07
765.387	992.818
765.643	1003.25
765.899	982.225
766.154	973.679
766.41	974.793
766.665	971.001
766.921	953.782
767.176	945.679
767.432	941.802
767.687	939.441
767.943	941.637
768.198	937.462
768.454	929.766
768.709	917.183
768.965	913.947
769.22	914.975
769.475	888.92
769.731	887.006
769.986	874.659
770.242	891.343
770.497	872.643
770.752	883.054
771.007	856.193
771.263	850.945
771.518	856.314
771.773	852.699
772.028	861.206
772.284	841.004
772.539	837.005
772.794	839.288
773.049	815.105
773.304	803.406
773.56	800.547
773.815	802.56
774.07	796.386
774.325	784.912
774.58	782.203
774.835	774.713
775.09	775.033
775.345	764.726
775.6	750.698
775.855	756.594
776.11	754.895
776.365	762.857
776.62	755.977
776.875	739.533
777.13	727.825
777.385	739.231
777.64	728.947
777.895	715.976
778.149	706.059
778.404	715.988
778.659	703.253
778.914	701.971
779.169	696.295
779.424	697.545
779.678	678.828
779.933	686.04
780.188	684.968
780.442	677.917
780.697	668.254
780.952	671.013
781.207	653.804
781.461	667.331
781.716	664.907
781.97	647.684
782.225	639.166
782.48	623.74
782.734	624.724
782.989	607.583
783.243	637.139
783.498	621.742
783.752	605.312
784.007	598.863
784.253	615.926
784.509	615.388
784.764	603.706
785.019	588.596
785.274	581.289
785.53	597.231
785.785	572.881
786.04	586.806
786.295	593.591
786.551	579.683
786.806	554.212
787.061	562.886
787.316	550.489
787.571	549.148
787.826	521.997
788.081	553.035
788.336	537.653
788.591	528.448
788.847	526.584
789.102	545.075
789.357	537.013
789.612	536.274
789.867	509.411
790.122	516.398
790.377	502.662
790.632	500.158
790.886	499.866
791.141	490.563
791.396	518.587
791.651	488.438
791.906	496.197
792.161	482.624
792.416	468.285
792.671	485.625
792.925	471.879
793.18	473.454
793.435	464.429
793.69	457.105
793.945	453.432
794.199	448.124
794.454	439.019
794.709	435.254
794.963	440.276
795.218	442.66
795.473	434.06
795.727	433.239
795.982	443.904
796.237	435.406
796.491	412.319
796.746	413.831
797	428.739
797.255	413.128
797.509	409.93
797.764	410.883
798.018	406.031
798.273	409.568
798.527	402.805
798.782	398.364
799.036	394.124
799.291	385.618
799.545	386.77
799.8	398.662
800.054	391.96
800.308	389.087
800.563	382.586
800.817	377.643
801.071	371.922
801.326	362.699
801.58	368.774
801.834	366.152
802.088	365.604
802.343	354.607
802.597	352.237
802.851	361.709
803.105	362.658
803.359	339.707
803.614	345.303
803.868	353.388
804.122	331.238
804.376	354.639
804.63	334.444
804.884	325.799
805.138	338.536
805.392	346.965
805.646	320.041
805.9	317.942
806.154	322.973
806.408	322.475
806.662	323.128
806.916	330.243
807.17	306.928
807.424	313.339
807.678	316.004
807.932	302.2
808.186	283.186
808.439	311.738
808.693	306.618
808.947	303.853
809.201	308.231
809.455	306.917
809.708	309.895
809.962	297.246
810.183	294
810.438	282.098
810.693	278.053
810.947	285.973
811.202	289.848
811.456	291.379
811.711	277.959
811.965	276.228
812.22	277.128
812.474	260.637
812.729	281.262
812.983	281.109
813.237	282.659
813.492	278.07
813.746	260.165
814.001	257.494
814.255	257.34
814.509	251.454
814.764	264.235
815.018	248.386
815.272	259.029
815.526	260.352
815.781	254.913
816.035	250.512
816.289	246.42
816.543	239.165
816.798	249.65
817.052	248.831
817.306	247.821
817.56	246.819
817.814	240.962
818.068	236.954
818.323	251.429
818.577	238.099
818.831	239.923
819.085	227.542
819.339	234.252
819.593	238.371
819.847	225.773
820.101	220.311
820.355	228.25
820.609	226.343
820.863	214.659
821.117	221.161
821.371	209.544
821.624	216.645
821.878	215.701
822.132	216.096
822.386	212.378
822.64	216.472
822.894	207.859
823.148	211.926
823.401	209.001
823.655	214.207
823.909	207.656
824.163	209.922
824.416	198.682
824.67	198.037
824.924	196.456
825.177	206.447
825.431	189.142
825.685	196.046
825.938	198.876
826.192	194.566
826.446	194.014
826.699	188.766
826.953	198.46
827.206	193.043
827.46	191.865
827.713	185.761
827.967	186.454
828.22	187.794
828.474	189.256
828.727	178.071
828.981	183.321
829.234	184.565
829.488	173.883
829.741	181.516
829.994	180.168
830.248	176.132
830.501	178.09
830.754	167.79
831.008	178.397
831.261	172.163
831.514	170.518
831.767	177.374
832.021	174.069
832.274	167.237
832.527	170.881
832.78	166.468
833.034	162.798
833.287	170.516
833.54	172.736
833.793	170.364
834.046	161.35
834.299	163.571
834.552	162.764
834.805	158.345
835.058	167.636
835.311	157.623
835.564	162.811
835.817	154.569
836.07	161.163
836.314	156.005
836.568	153.922
836.821	152
837.075	146.05
837.329	159.792
837.583	154.155
837.836	136.396
838.09	146.341
838.344	153.371
838.598	148.087
838.851	150.233
839.105	154.599
839.359	149.436
839.612	138.615
839.866	151.614
840.119	139.433
840.373	143.303
840.627	145.589
840.88	146.625
841.134	137.962
841.387	144.424
841.641	138.695
841.894	140.209
842.148	141.478
842.401	134.476
842.655	149.237
842.908	145.943
843.161	136.229
843.415	132.783
843.668	138.1
843.922	140.543
844.175	141.937
844.428	134.183
844.682	130.265
844.935	131.388
845.188	126.605
845.442	134.503
845.695	133.407
845.948	129.25
846.201	130.511
846.455	130.724
846.708	115.736
846.961	127.508
847.214	126.232
847.467	131.829
847.72	118.764
847.973	129.904
848.227	129.664
848.48	111.869
848.733	129.914
848.986	120.082
849.239	124.796
849.492	113.076
849.745	119.093
849.998	116.955
850.251	109.256
850.504	120.098
850.757	124.304
851.01	110.097
851.263	117.665
851.515	113.387
851.768	110.251
852.021	113.219
852.274	111.805
852.527	114.484
852.78	120.916
853.032	115.862
853.285	112.364
853.538	110.38
853.791	113.668
854.043	103.503
854.296	108.794
854.549	115.909
854.801	102.34
855.054	108.423
855.307	106.841
855.559	115.534
855.812	110.787
856.065	103.748
856.317	105.369
856.57	106.866
856.822	102.385
857.075	97.1687
857.327	110.731
857.58	105.015
857.832	106.567
858.085	104.91
858.337	103.166
858.589	101.424
858.842	106.026
859.094	105.092
859.347	104.78
859.599	98.9195
859.851	99.1237
860.104	99.135
860.356	102.606
860.608	96
860.861	96.5633
861.113	103.772
861.365	94.0544
861.617	98.0372
861.869	90.1961
862.112	97.998
862.365	103.86
862.618	91.9606
862.871	92.1924
863.124	101.647
863.377	103.174
863.63	97.4823
863.883	96.9762
864.136	110.385
864.389	106.319
864.642	88.3857
864.894	98.6911
865.147	89.8916
865.4	93.7726
865.653	95.1797
865.906	99.6729
866.159	81.7496
866.412	93.0269
866.664	88.5492
866.917	93.4498
867.17	89.6491
867.423	83.378
867.675	91.8756
867.928	90.7815
868.181	92.2949
868.433	86.4133
868.686	91.846
868.939	85.3484
869.191	85.1907
869.444	84.9803
869.697	84.8061
869.949	91.274
870.202	88.9686
870.454	85.4708
870.707	79.3294
870.959	82.2873
871.212	84.0509
871.464	84.9957
871.717	81.9999
871.969	76.3929
872.222	74.0226
872.474	77.9528
872.727	83.5479
872.979	77.5403
873.231	76.2982
873.484	78.42
873.736	77.7376
873.988	82.6439
874.241	78.1172
874.493	72.75
874.745	73.9333
874.998	75.7369
875.25	83.8891
875.502	78.1159
875.754	71.5785
876.006	74.9259
876.259	78.3776
876.511	75.852
876.763	68.1242
877.015	74.1186
877.267	79.3107
877.519	75.5731
877.771	74.4367
878.023	69.0354
878.276	73.7658
878.528	74.1166
878.78	71.0195
879.031	72
879.284	72.2259
879.535	73.1505
879.787	70.1974
880.039	78.2101
880.291	73.419
880.543	71.4663
880.795	72.5556
881.047	74.6938
881.299	75.7667
881.551	68.0274
881.802	69.2876
882.054	71.879
882.306	72.0325
882.558	65.4534
882.809	65.8691
883.061	69.9623
883.313	68.8429
883.565	59.8697
883.816	68.008
884.068	65.6059
884.319	61.8736
884.571	66.56
884.823	63.9444
885.074	71.5163
885.326	61.4751
885.577	62.727
885.829	69.1204
886.08	65.3449
886.332	61.725
886.583	64.706
886.835	63.0568
887.086	66.0566
887.338	61.9057
887.589	69.7531
887.841	70.164
888.044	58.1561
888.296	63.9098
888.548	54.3016
888.8	65.5889
889.053	62.39
889.305	60.7472
889.557	52.6757
889.809	58.38
890.061	65.2715
890.313	58.2887
890.566	55.3234
890.818	61.3117
891.07	62.3173
891.322	55.6955
891.574	60.2409
891.826	64.6971
892.078	48.3525
892.33	61.1167
892.582	54.3936
892.834	62.8723
893.086	56.7988
893.338	52.9983
893.59	56.2663
893.842	57.9442
894.094	53.9783
894.346	52.0169
894.597	60.8792
894.849	49.1196
895.101	52.6667
895.353	55.4994
895.605	61.6522
895.857	51.3116
896.108	50.6413
896.36	57.2705
896.612	57.6304
896.864	55.1681
897.115	56.2609
897.367	58.5966
897.619	53.6493
897.87	54.2999
898.122	55.4982
898.374	54.4111
898.625	54.7183
898.877	47.7013
899.128	51
899.38	56.3434
899.631	48.347
899.883	48.364
899.984	53.7409