File: PL_Fatia_SCD_021223_01.txt
#Acq. time (s)=	3
#Accumulations=	2
#Range (nm)=	520...900
#Windows=	16
#Auto scanning=	On
#Autofocus=	Off
#AutoExposure=	Off
#Spike filter=	Multiple accum.
#Delay time (s)=	0
#Binning=	1
#Readout mode=	Signal
#DeNoise=	Off
#ICS correction=	Off
#Dark correction=	Off
#Inst. Process=	Off
#Detector temperature (°C)=	-59.98
#Instrument=	LabRAM HR Evol
#Detector=	Syncerity OE
#Objective=	x50_VIS
#Grating=	600 (500nm)
#ND Filter=	10%
#Laser=	514nm_Edge
#Hole=	199.981
#Range=	Auto
#StageXY=	Marzhauser
#StageZ=	Marzhauser
#X (µm)=	1452.2
#Y (µm)=	-2592
#Z (µm)=	-214.6
#Full time(mm:ss)=	2:39
#Project=
#Sample=
#Site=
#Title=	PL_Fatia_SCD_021223
#Remark=
#Date=	18.12.2023 17:57
#Acquired=	18.12.2023 17:57:45
520.042	40
520.304	28.1537
520.565	38.6438
520.827	35.3488
521.089	30.9209
521.351	32.1791
521.612	36.6088
521.874	40.5669
522.136	35
522.397	34.8719
522.659	37.5879
522.921	36
523.182	32.943
523.444	38.1618
523.705	40.4692
523.967	35.8126
524.229	31
524.49	31.7928
524.752	34.8661
525.013	32.908
525.275	31.9453
525.536	34.7602
525.798	35.7718
526.059	34.4645
526.321	33.4435
526.582	32.1339
526.844	41.5967
527.105	31.5425
527.367	38.0839
527.628	31.0105
527.889	32.6807
528.151	29.0524
528.412	38.9173
528.674	38.6282
528.935	27.8531
529.196	30
529.458	34.3869
529.719	37.1725
529.98	26.127
530.242	33.5641
530.503	33.8951
530.764	36.458
531.025	31.3427
531.287	37.0793
531.548	40
531.809	39.9977
532.07	28.9767
532.332	28.9534
532.593	37.669
532.854	32.5455
533.115	30.1002
533.376	36.8648
533.638	37.449
533.899	38.4855
534.16	31.3737
534.421	40
534.682	35.6455
534.943	35.897
535.204	38.2534
535.465	35.9177
535.726	38.0361
535.987	36.053
536.248	32.9832
536.509	44.5057
536.77	37.7974
537.031	34.7046
537.292	39.2603
537.553	33.6145
537.814	38.3536
538.075	37.5494
538.336	38.5976
538.597	40.2744
538.858	42.2885
539.119	36.4076
539.38	33.8883
539.641	37.6939
539.901	40.1374
540.162	37.8063
540.423	44.4066
540.684	44.7644
540.945	34.5756
541.205	42.4129
541.466	40.7196
541.727	39.4951
541.988	37.3545
542.248	39.3074
542.509	39.2288
542.77	46.1673
543.031	36.0302
543.291	45.2591
543.552	41.9299
543.813	42.9139
544.073	42.009
544.334	48.3356
544.594	42.1664
544.855	46.7026
545.116	43.6324
545.376	41.6425
545.637	42.6673
545.897	44.4045
546.158	45.3775
546.418	47.0453
546.679	49.2289
546.898	45.9811
547.159	38.105
547.42	47.8531
547.681	49.6111
547.942	55.8321
548.203	42.5259
548.464	45.5544
548.725	47.8019
548.987	46.2571
549.248	46.1266
549.509	58.1524
549.77	67.3249
550.031	51.8433
550.292	52.1916
550.553	56.6914
550.814	64.8182
551.075	58.8907
551.336	72.995
551.597	76.9132
551.858	93.0241
552.119	122.356
552.38	373.19
552.641	8795.48
552.901	629.569
553.162	130.604
553.423	87.1903
553.684	72.4263
553.945	68.8751
554.206	66.1582
554.467	74.6595
554.727	71.8425
554.988	70.9895
555.249	60.4707
555.51	66.6421
555.771	69.4791
556.031	65.4578
556.292	67.9842
556.553	69.6233
556.814	78.6754
557.074	66.651
557.335	72.3879
557.596	73.8967
557.856	74.869
558.117	65.7447
558.378	82.4467
558.638	82.6886
558.899	76.5071
559.16	74.738
559.42	76.3054
559.681	84.8419
559.941	82.6235
560.202	86
560.463	82.2926
560.723	87.2593
560.984	84.9996
561.244	83.7381
561.505	90.3889
561.765	92.9717
562.026	91.7856
562.286	94.0674
562.547	98.428
562.807	97.5685
563.067	107.058
563.328	103.648
563.588	97.1602
563.849	106.901
564.109	102.293
564.369	108.581
564.63	105.992
564.89	111.036
565.15	106.15
565.411	104.589
565.671	110.024
565.931	112.256
566.192	117.33
566.452	113.07
566.712	122.49
566.972	123.945
567.232	121.867
567.493	121.576
567.753	127.727
568.013	132.012
568.273	129.929
568.533	136.491
568.794	140.971
569.054	132.958
569.314	137.774
569.574	143.831
569.834	138.27
570.094	140.891
570.354	152.524
570.614	161.334
570.874	159.599
571.134	174.877
571.394	172.39
571.654	187.057
571.914	189.597
572.174	189.926
572.434	204.749
572.694	210.622
572.954	214.177
573.214	241.16
573.459	251.875
573.719	273.958
573.98	283.909
574.241	315.066
574.501	348.986
574.762	356.882
575.022	396.613
575.283	442.102
575.543	445.91
575.804	455.41
576.064	465.832
576.325	447.086
576.585	434.295
576.846	417.638
577.106	387.815
577.366	372.232
577.627	362.215
577.887	330.693
578.148	325.052
578.408	310.932
578.668	306.415
578.929	304.212
579.189	277.742
579.449	281.412
579.71	306.675
579.97	284.271
580.23	294.824
580.49	300.199
580.751	303.872
581.011	272.85
581.271	290.417
581.531	303.746
581.792	304.681
582.052	298.217
582.312	315.982
582.572	313.031
582.832	316.513
583.092	324.107
583.353	318.629
583.613	325.667
583.873	320.487
584.133	342.892
584.393	341.314
584.653	362.547
584.913	364.768
585.173	372.862
585.433	369.796
585.693	368.697
585.953	381.16
586.213	393.007
586.473	385.722
586.733	398.793
586.993	377.138
587.253	395.379
587.513	413.738
587.773	411.744
588.033	417.539
588.293	400.583
588.552	422.229
588.812	428.15
589.072	422.48
589.332	433.336
589.592	434.331
589.852	433.971
590.112	421.38
590.371	433.853
590.631	438.119
590.891	411.72
591.151	416.305
591.41	425.193
591.67	405.29
591.93	404.543
592.189	405.34
592.449	406.973
592.709	407.092
592.968	396.514
593.228	395.146
593.488	397.236
593.747	400.826
594.007	405.119
594.266	408.303
594.526	413.823
594.786	417.156
595.045	402.408
595.305	415.443
595.564	408.56
595.824	411.099
596.083	423.943
596.343	425.504
596.602	424.939
596.862	436.584
597.121	438.391
597.38	420.322
597.64	425.306
597.899	429.329
598.159	414.239
598.418	429.47
598.677	433.436
598.937	452.404
599.196	450.046
599.455	455.238
599.715	447.518
599.959	440.034
600.219	445.689
600.479	470.942
600.738	467.081
600.998	431.913
601.258	451.006
601.518	463.544
601.778	467.013
602.038	471.453
602.298	462.675
602.558	455.791
602.818	470.199
603.078	479.45
603.337	465.928
603.597	465.929
603.857	449.101
604.117	484.62
604.377	441.576
604.636	481.156
604.896	459.686
605.156	471.026
605.416	476.789
605.675	483.861
605.935	478.596
606.195	469.827
606.455	480.572
606.714	472.362
606.974	474.141
607.234	480.138
607.493	487.907
607.753	459.996
608.012	487.381
608.272	491.314
608.532	476.393
608.791	476.077
609.051	503.534
609.31	502.37
609.57	482.924
609.829	493.699
610.089	507.679
610.348	487.566
610.608	512.22
610.867	513.445
611.127	517.651
611.386	505.319
611.646	520.219
611.905	523.435
612.164	534.691
612.424	520.174
612.683	536.448
612.943	536.21
613.202	526.336
613.461	538.161
613.721	546.339
613.98	540.036
614.239	553.133
614.498	557.96
614.758	579.991
615.017	574.491
615.276	580.803
615.535	560.701
615.795	578.602
616.054	602.293
616.313	584.557
616.572	597.214
616.831	612.159
617.091	597.999
617.35	622.346
617.609	629.486
617.868	613.389
618.127	631.601
618.386	649.667
618.645	628.166
618.904	647.81
619.163	665.967
619.422	660.067
619.681	666.518
619.94	672.083
620.199	669.244
620.458	675.989
620.717	674.68
620.976	686.96
621.235	696.998
621.494	699.132
621.753	692.423
622.012	697.019
622.271	679.317
622.53	702.423
622.788	679.998
623.047	692.579
623.306	710.674
623.565	677.732
623.824	725.426
624.082	725.877
624.341	704.197
624.6	702.244
624.859	701.023
625.117	713.998
625.376	731.211
625.635	717.948
625.893	752.612
626.152	732.717
626.368	745.768
626.627	735.539
626.887	761.616
627.146	768.796
627.405	742.132
627.665	755.526
627.924	787.535
628.183	763.265
628.443	789.956
628.702	758.576
628.961	788.643
629.22	798.735
629.479	790.911
629.739	814.202
629.998	822.416
630.257	788.919
630.516	833.247
630.776	842.012
631.035	832.51
631.294	846.346
631.553	868.317
631.812	859.459
632.071	865.495
632.33	895.082
632.589	885.768
632.848	896.476
633.107	906.016
633.366	894.546
633.625	904.703
633.885	921.06
634.143	934.964
634.403	939.379
634.661	951.783
634.92	967.127
635.179	985.371
635.438	1005.5
635.697	1030.69
635.956	1067.02
636.215	1092.45
636.474	1138.57
636.733	1188.45
636.992	1255.98
637.25	1341.51
637.509	1413.32
637.768	1474.84
638.027	1525.24
638.286	1553.42
638.544	1541.44
638.803	1505.4
639.062	1478.79
639.321	1403.26
639.579	1379.22
639.838	1353.5
640.097	1302.63
640.356	1281.1
640.614	1250.84
640.873	1252.16
641.131	1222.79
641.39	1242.49
641.649	1217.65
641.907	1236.34
642.166	1227.2
642.424	1228.34
642.683	1242.68
642.942	1229.44
643.2	1220.48
643.459	1241.98
643.717	1238.85
643.976	1230.72
644.234	1259.84
644.493	1274.29
644.751	1284.28
645.009	1281.86
645.268	1281.82
645.526	1287.17
645.785	1271.11
646.043	1306.12
646.301	1290.84
646.56	1295.2
646.818	1294.92
647.076	1292.45
647.335	1312.05
647.593	1344.26
647.851	1340.8
648.109	1355.79
648.368	1347.87
648.626	1378.79
648.884	1378.85
649.142	1385.2
649.401	1421.37
649.659	1406.8
649.917	1426.11
650.175	1453.63
650.433	1460.48
650.691	1496.4
650.949	1471.32
651.208	1483.56
651.466	1479.86
651.724	1479.25
651.982	1514.26
652.24	1505.88
652.498	1533.06
652.756	1550.62
652.979	1569.91
653.238	1598.43
653.497	1571.13
653.755	1630.49
654.014	1615.52
654.273	1645.99
654.531	1656.47
654.79	1617.78
655.049	1713.87
655.307	1697.4
655.566	1743.69
655.824	1705.26
656.083	1780.39
656.342	1792.37
656.6	1804.92
656.859	1787.54
657.117	1866.81
657.376	1885.78
657.634	1850.32
657.893	1908.77
658.151	1933.51
658.41	1934.03
658.668	1952.3
658.927	1964.34
659.185	1936.92
659.443	1979.88
659.702	1992.39
659.96	2012.45
660.219	1970.67
660.477	1981.12
660.735	1963.47
660.994	2002.67
661.252	2002.49
661.51	2014.28
661.768	2009.49
662.027	2034.61
662.285	2009.92
662.543	2028.06
662.802	2009.71
663.06	2009.52
663.318	2019.02
663.576	1980.14
663.834	2028.88
664.093	2011.83
664.351	2029.74
664.609	2035.01
664.867	2011.21
665.125	2022.18
665.383	2003.33
665.641	1994.02
665.899	2011.05
666.157	2006.53
666.415	1993.67
666.673	2002.73
666.931	2017.51
667.189	2008.38
667.447	2004.21
667.705	2027.41
667.963	1989.91
668.221	2018.68
668.479	2009.17
668.737	2044.16
668.995	2011.19
669.253	2042.15
669.511	2016.73
669.769	2012.07
670.027	2012.17
670.284	2015.72
670.542	2014.35
670.8	2028.05
671.058	2017.52
671.316	2043.55
671.573	2059.93
671.831	2032.27
672.089	2054.62
672.347	2062.56
672.604	2081.26
672.862	2065.13
673.12	2098.69
673.377	2061.57
673.635	2105.4
673.893	2096.49
674.15	2131.64
674.408	2145.44
674.665	2145.73
674.923	2147.6
675.18	2156.4
675.438	2191.64
675.696	2201.12
675.953	2204.36
676.211	2206.08
676.468	2216.16
676.726	2225.46
676.983	2219.31
677.24	2244.11
677.498	2212.27
677.755	2243.66
678.013	2220.54
678.27	2233.58
678.527	2239.36
678.785	2230.8
679.042	2212.09
679.277	2248.34
679.535	2204.22
679.793	2257.44
680.051	2263.77
680.309	2271.81
680.567	2277.47
680.825	2257.2
681.083	2288.41
681.341	2311.88
681.599	2328.03
681.857	2263.45
682.115	2295.37
682.373	2328.73
682.631	2363.34
682.889	2306.18
683.146	2342.07
683.404	2311.91
683.662	2364.43
683.92	2330.91
684.178	2325.36
684.436	2319.25
684.694	2324.51
684.951	2333.41
685.209	2307.48
685.467	2271.89
685.725	2283.83
685.982	2294.05
686.24	2323.67
686.498	2289.51
686.756	2299.8
687.013	2294.58
687.271	2273.61
687.529	2300.59
687.786	2303.62
688.044	2284.92
688.302	2283.7
688.559	2271.05
688.817	2264.43
689.074	2303.48
689.332	2263.93
689.589	2258.59
689.847	2260.67
690.104	2276.09
690.362	2280.66
690.619	2232.93
690.877	2255.17
691.134	2245.81
691.392	2236.87
691.649	2214.21
691.907	2213.94
692.164	2234.34
692.421	2214.21
692.679	2230.06
692.936	2213.95
693.194	2214.81
693.451	2189.83
693.708	2171.58
693.966	2180.02
694.223	2191.84
694.48	2188.91
694.737	2166.77
694.995	2185.95
695.252	2184.84
695.509	2160.9
695.766	2168.59
696.023	2172.15
696.281	2178.35
696.538	2162.56
696.795	2165.53
697.052	2143.44
697.309	2142.53
697.566	2131.47
697.823	2116.98
698.08	2125.89
698.338	2120.91
698.595	2095.6
698.852	2105.22
699.109	2081.14
699.366	2095.04
699.623	2065.15
699.88	2107.5
700.137	2097.75
700.393	2071.07
700.65	2081.03
700.907	2070.32
701.164	2062.33
701.421	2091.91
701.678	2069.36
701.935	2050.92
702.192	2061.37
702.448	2058.16
702.705	2088.18
702.962	2055.97
703.219	2082.25
703.476	2049.42
703.732	2055.24
703.989	2066.09
704.246	2069.6
704.503	2064.29
704.759	2060.92
705.016	2067.65
705.273	2025.84
705.511	2050.01
705.768	1994.37
706.026	2030.01
706.283	2017.12
706.541	1994.33
706.798	1975.24
707.055	1984.94
707.313	1988.36
707.57	2000.59
707.827	1951.38
708.084	1932.49
708.342	1975.74
708.599	1941.81
708.856	1928.89
709.114	1983.78
709.371	1978.08
709.628	1894.45
709.885	1904.09
710.142	1953.99
710.4	1920.35
710.657	1925.8
710.914	1929.78
711.171	1897.42
711.428	1893.5
711.685	1901.93
711.942	1924.12
712.199	1854.75
712.456	1872.27
712.713	1843.82
712.97	1846.21
713.227	1832.83
713.484	1813.67
713.741	1803.65
713.998	1783.18
714.255	1765.37
714.512	1772.69
714.769	1785.08
715.026	1722.2
715.283	1788.02
715.54	1753.18
715.797	1732.83
716.054	1713.02
716.31	1721.19
716.567	1747.98
716.824	1709.74
717.081	1735.09
717.338	1706.91
717.594	1684.42
717.851	1720.76
718.108	1679.51
718.365	1673.63
718.621	1687.02
718.878	1667.05
719.135	1677.02
719.391	1662.76
719.648	1654.8
719.905	1634.64
720.161	1628.11
720.418	1633.83
720.675	1610.48
720.931	1589.04
721.188	1591.58
721.444	1587.62
721.701	1583.65
721.957	1579.38
722.214	1546.67
722.47	1553.74
722.727	1545.73
722.983	1532.66
723.24	1534.42
723.496	1543.97
723.753	1525.07
724.009	1522.51
724.265	1533.25
724.522	1504.53
724.778	1505.46
725.034	1484.43
725.291	1484.41
725.547	1469.83
725.803	1472.42
726.06	1464.16
726.316	1493.07
726.572	1459.99
726.828	1436.19
727.085	1446.7
727.341	1425.02
727.597	1423.01
727.853	1399.29
728.109	1400.55
728.366	1399.86
728.622	1417.31
728.878	1376.41
729.134	1385.37
729.39	1326.78
729.646	1345.76
729.902	1356.28
730.158	1354.19
730.414	1314.01
730.67	1309.67
730.926	1328.51
731.182	1315.54
731.438	1292.83
731.643	1288
731.9	1274.08
732.156	1268.54
732.413	1300.38
732.67	1240.88
732.927	1265.04
733.183	1243.78
733.44	1277.41
733.697	1271.35
733.953	1246.84
734.21	1209.11
734.466	1261.31
734.723	1218.73
734.98	1253.28
735.236	1242.46
735.493	1240.26
735.749	1208.46
736.006	1218.4
736.262	1207.65
736.519	1210.24
736.775	1223.25
737.032	1205.39
737.288	1189.7
737.544	1204.79
737.801	1219.71
738.057	1163.19
738.314	1228.21
738.57	1190.94
738.826	1181.43
739.083	1169.23
739.339	1168.58
739.595	1169.46
739.852	1126.96
740.108	1164.59
740.364	1167.65
740.621	1135.62
740.877	1154.52
741.133	1145.34
741.389	1123.76
741.645	1129.65
741.902	1134.07
742.158	1124.72
742.414	1123.3
742.67	1104.78
742.926	1122.27
743.182	1102.28
743.438	1113.55
743.694	1088.22
743.951	1089.18
744.207	1093.48
744.463	1100.64
744.719	1085.76
744.975	1074.47
745.231	1073.06
745.487	1065.33
745.743	1073.01
745.998	1041.16
746.254	1043.37
746.51	1037.47
746.766	1050.27
747.022	1061.11
747.278	1020.39
747.534	1032.77
747.79	1019.38
748.046	1024.96
748.301	1016.54
748.557	1032.14
748.813	1020.81
749.069	995.255
749.324	1004.34
749.58	1009.54
749.836	967.689
750.092	998.019
750.347	976.35
750.603	991.414
750.859	993.678
751.114	964.153
751.37	951.164
751.625	930.184
751.881	948.332
752.137	941.65
752.392	920.242
752.648	902.947
752.903	928.234
753.159	919.124
753.414	932.417
753.67	916.229
753.925	907.194
754.181	922.885
754.436	905.908
754.692	920.963
754.947	888.447
755.202	886.111
755.458	858.995
755.713	857.59
755.968	877.4
756.224	873.339
756.479	886.425
756.734	875.789
756.99	844.595
757.245	839.639
757.5	864.047
757.755	838.875
757.968	824.039
758.224	824.18
758.48	830.591
758.736	832.204
758.992	818.652
759.248	819.473
759.504	804.621
759.76	809.18
760.016	791.784
760.272	768.948
760.528	788.241
760.784	791.685
761.04	773.117
761.296	770.56
761.552	764.897
761.807	774.394
762.063	767.947
762.319	766.064
762.575	753.859
762.831	764.359
763.086	743.178
763.342	772.352
763.598	736.208
763.853	739.278
764.109	727.578
764.365	733.384
764.621	740.665
764.876	728.762
765.132	723.978
765.387	716.585
765.643	730.145
765.899	699.076
766.154	697.261
766.41	695.758
766.665	719.576
766.921	696.364
767.176	709.523
767.432	682.055
767.687	689.768
767.943	702.436
768.198	687.977
768.454	669.913
768.709	671.289
768.965	645.42
769.22	652.322
769.475	647.473
769.731	640.493
769.986	625.511
770.242	637.298
770.497	639.036
770.752	640.633
771.007	616.468
771.263	640.837
771.518	626.573
771.773	619.333
772.028	590.935
772.284	599.847
772.539	603.612
772.794	584.104
773.049	596.532
773.304	593.68
773.56	593.299
773.815	592.497
774.07	575.615
774.325	565.651
774.58	561.674
774.835	573.22
775.09	580.535
775.345	556.949
775.6	559.046
775.855	548.15
776.11	562.835
776.365	550.348
776.62	541.525
776.875	545.219
777.13	542.487
777.385	530.091
777.64	532.153
777.895	537.099
778.149	537.518
778.404	508.86
778.659	526.924
778.914	533.178
779.169	510.344
779.424	493.671
779.678	515.562
779.933	505.632
780.188	504.366
780.442	499.416
780.697	489.545
780.952	496.867
781.207	480.323
781.461	486.59
781.716	476.252
781.97	483.023
782.225	488.909
782.48	481.047
782.734	464.654
782.989	459.129
783.243	460.129
783.498	442.063
783.752	425.29
784.007	462.336
784.253	460.033
784.509	455.853
784.764	449.444
785.019	443.755
785.274	434.648
785.53	412.314
785.785	419.132
786.04	417.13
786.295	420.105
786.551	427.836
786.806	432.175
787.061	413.165
787.316	421.864
787.571	404.009
787.826	397.143
788.081	415.58
788.336	408.173
788.591	393.03
788.847	391.249
789.102	380.366
789.357	399.08
789.612	373.53
789.867	399.73
790.122	370.668
790.377	374.093
790.632	369.895
790.886	371.195
791.141	358.02
791.396	365.873
791.651	377.941
791.906	358.419
792.161	347.542
792.416	369.187
792.671	348.943
792.925	353.376
793.18	345.955
793.435	332.944
793.69	346.605
793.945	343.336
794.199	349.754
794.454	331.849
794.709	341.759
794.963	331.44
795.218	333.955
795.473	334.242
795.727	330.521
795.982	326.536
796.237	324.48
796.491	312.178
796.746	311.476
797	317.188
797.255	310.016
797.509	311.824
797.764	308.751
798.018	307.169
798.273	293.863
798.527	301.106
798.782	301.709
799.036	292.856
799.291	286.56
799.545	287.606
799.8	289.371
800.054	293.647
800.308	296.017
800.563	283.989
800.817	287.432
801.071	279.179
801.326	285.761
801.58	275.456
801.834	268.883
802.088	264.067
802.343	262.47
802.597	272.325
802.851	260.163
803.105	267.064
803.359	272.936
803.614	269.399
803.868	253.312
804.122	251.885
804.376	263.75
804.63	265.867
804.884	250.018
805.138	253.911
805.392	256.02
805.646	247.691
805.9	258.5
806.154	250.378
806.408	256.366
806.662	241.556
806.916	251.979
807.17	243.26
807.424	237.608
807.678	239.568
807.932	254.636
808.186	239.161
808.439	238.025
808.693	233.743
808.947	236.416
809.201	237.75
809.455	226.37
809.708	224.069
809.962	226.706
810.183	224
810.438	220.034
810.693	233.878
810.947	235.547
811.202	218.046
811.456	243.034
811.711	212.21
811.965	204.103
812.22	223.602
812.474	212.233
812.729	214.464
812.983	196.487
813.237	213.422
813.492	220.287
813.746	194.548
814.001	193.304
814.255	208.793
814.509	201.587
814.764	205.122
815.018	203.051
815.272	204.581
815.526	195.043
815.781	197.272
816.035	206.83
816.289	189.504
816.543	191.28
816.798	187.203
817.052	192.516
817.306	189.519
817.56	187.149
817.814	183.639
818.068	190.604
818.323	184.494
818.577	177.561
818.831	181.547
819.085	179.076
819.339	179.855
819.593	174.463
819.847	180.273
820.101	178.466
820.355	171.005
820.609	169.601
820.863	180
821.117	170.559
821.371	171.682
821.624	170.769
821.878	162
822.132	167.548
822.386	157.944
822.64	167.901
822.894	166.115
823.148	156.418
823.401	171.944
823.655	158.861
823.909	164.718
824.163	156.744
824.416	155.543
824.67	159.664
824.924	158.342
825.177	160
825.431	152.694
825.685	156.816
825.938	152.257
826.192	163.405
826.446	147.91
826.699	157.222
826.953	148.448
827.206	149.103
827.46	149.506
827.713	146.609
827.967	144.118
828.22	144.013
828.474	144.044
828.727	145.831
828.981	141.446
829.234	148.036
829.488	143.323
829.741	139.844
829.994	143.969
830.248	138.873
830.501	139.934
830.754	134.872
831.008	138.014
831.261	137.649
831.514	133.037
831.767	134.307
832.021	139.922
832.274	133.921
832.527	130.752
832.78	143.137
833.034	130.481
833.287	129.715
833.54	130.933
833.793	125.156
834.046	128.791
834.299	126.806
834.552	132.06
834.805	134.929
835.058	126.966
835.311	128.94
835.564	126.874
835.817	128.479
836.07	138.392
836.314	125.982
836.568	125.902
836.821	129.693
837.075	116.214
837.329	123.921
837.583	121.974
837.836	125.844
838.09	115.253
838.344	112.514
838.598	122.861
838.851	127.29
839.105	116.66
839.359	117.843
839.612	121.941
839.866	111.857
840.119	120.075
840.373	114.059
840.627	101.763
840.88	111.44
841.134	110.341
841.387	111.562
841.641	108.911
841.894	110.178
842.148	109.991
842.401	110.395
842.655	116.225
842.908	103.999
843.161	100.382
843.415	97.7957
843.668	112.229
843.922	107.819
844.175	111.455
844.428	106.551
844.682	105.128
844.935	107.338
845.188	99.828
845.442	99.7162
845.695	101.886
845.948	103.424
846.201	101.763
846.455	107.457
846.708	102.094
846.961	108.164
847.214	97.1483
847.467	99.9641
847.72	106.134
847.973	100.537
848.227	103.334
848.48	98.9345
848.733	97.2584
848.986	94.4887
849.239	97.1119
849.492	101.843
849.745	86.0645
849.998	98.6869
850.251	88.5339
850.504	96.4252
850.757	91.2349
851.01	88.6452
851.263	99.8188
851.515	91.3874
851.768	90.4799
852.021	90.7826
852.274	87.6601
852.527	94.8737
852.78	85.3514
853.032	94.484
853.285	88.2557
853.538	86.2732
853.791	88.8226
854.043	86.2056
854.296	86.0603
854.549	92.7843
854.801	85.692
855.054	88.6482
855.307	86.3772
855.559	82.891
855.812	79.6277
856.065	81.1875
856.317	83.8525
856.57	83.076
856.822	87.7338
857.075	84.1912
857.327	83.3289
857.58	85.0207
857.832	77.5232
858.085	81.6385
858.337	82.4748
858.589	79.184
858.842	81.5178
859.094	81.881
859.347	87.3601
859.599	77.4713
859.851	76.4693
860.104	81.8232
860.356	83.8506
860.608	85.0237
860.861	75.7939
861.113	80.8137
861.365	79.084
861.617	76.382
861.869	69.8615
862.112	74
862.365	83.9543
862.618	77.9254
862.871	83.5325
863.124	89.2258
863.377	83.671
863.63	75.4243
863.883	80.9667
864.136	75.9362
864.389	76
864.642	72.1125
864.894	75.4644
865.147	68.9625
865.4	75.206
865.653	60.7442
865.906	73.1892
866.159	65.6961
866.412	75.6149
866.664	75.7385
866.917	72.4547
867.17	77.0914
867.423	71.5679
867.675	74.1726
867.928	69.9468
868.181	78.2417
868.433	69.081
868.686	68.9437
868.939	69.852
869.191	70.2386
869.444	61.1413
869.697	72.4575
869.949	68.285
870.202	67.8605
870.454	69.5491
870.707	64.4941
870.959	75.0932
871.212	69.9805
871.464	67.0537
871.717	61.9545
871.969	71.3205
872.222	62.0226
872.474	69.9894
872.727	68.7233
872.979	65.6803
873.231	69.1694
873.484	63.2948
873.736	62.9225
873.988	62.667
874.241	61.7505
874.493	64.7251
874.745	62.4636
874.998	61.2659
875.25	66.0718
875.502	58.9996
875.754	66.6508
876.006	61.5241
876.259	53.3476
876.511	57.5
876.763	56.5235
877.015	59.152
877.267	65.8609
877.519	58.8289
877.771	61.6316
878.023	62.77
878.276	54.9645
878.528	60.6154
878.78	59.1931
879.031	61.9147
879.284	58.4849
879.535	56.3929
879.787	60.0994
880.039	55.9492
880.291	55.5808
880.543	61.1248
880.795	56.9796
881.047	62.8161
881.299	52.449
881.551	56.8038
881.802	54.113
882.054	48.4737
882.306	55.4191
882.558	55.645
882.809	59.6104
883.061	52.2229
883.313	54.4914
883.565	55.2498
883.816	58.7456
884.068	52.8262
884.319	59.2659
884.571	51.5054
884.823	57.3437
885.074	56.3803
885.326	59.8696
885.577	56.8657
885.829	51.1017
886.08	48.7404
886.332	56.0894
886.583	59.5984
886.835	52.6519
887.086	52.4669
887.338	55.5996
887.589	52.2586
887.841	48.3689
888.044	46.1416
888.296	51.8277
888.548	63.302
888.8	53.4861
889.053	48.3286
889.305	51.5504
889.557	48.1177
889.809	51.6805
890.061	47.1683
890.313	46.5475
890.566	49.8549
890.818	43.1738
891.07	45.5809
891.322	52.9646
891.574	54.7233
891.826	51.3942
892.078	49.3071
892.33	46.703
892.582	53.7638
892.834	45.1277
893.086	49.5975
893.338	49.9418
893.59	52.7917
893.842	47.9774
894.094	44.0507
894.346	49.0169
894.597	42.1449
894.849	42.2391
895.101	47.9444
895.353	52.7146
895.605	45.8261
895.857	53.4807
896.108	44.8804
896.36	45.5411
896.612	42.913
896.864	48.8319
897.115	51
897.367	48.401
897.619	41.2987
897.87	46.2334
898.122	45.9964
898.374	43.4111
898.625	42.6904
898.877	45.5067
899.128	47.7993
899.38	43.994
899.631	45.653
899.883	43.1838
899.984	41