File: PL_Fatia_SCD_021223_05.txt
#Acq. time (s)=	3
#Accumulations=	2
#Range (nm)=	520...900
#Windows=	16
#Auto scanning=	On
#Autofocus=	Off
#AutoExposure=	Off
#Spike filter=	Multiple accum.
#Delay time (s)=	0
#Binning=	1
#Readout mode=	Signal
#DeNoise=	Off
#ICS correction=	Off
#Dark correction=	Off
#Inst. Process=	Off
#Detector temperature (°C)=	-59.98
#Instrument=	LabRAM HR Evol
#Detector=	Syncerity OE
#Objective=	x50_VIS
#Grating=	600 (500nm)
#ND Filter=	10%
#Laser=	514nm_Edge
#Hole=	199.981
#Range=	Auto
#StageXY=	Marzhauser
#StageZ=	Marzhauser
#X (µm)=	2160.7
#Y (µm)=	-221.9
#Z (µm)=	-218.9
#Full time(mm:ss)=	2:39
#Project=
#Sample=
#Site=
#Title=	PL_Fatia_SCD_021223
#Remark=
#Date=	18.12.2023 18:12
#Acquired=	18.12.2023 18:12:18
520.042	73
520.304	63.9488
520.565	61.3562
520.827	64.6977
521.089	64.7628
521.351	57.4477
521.612	67.3155
521.874	65.2165
522.136	64.2372
522.397	63.1525
522.659	59.1374
522.921	57.5867
523.182	57.3143
523.444	67.3353
523.705	57.4156
523.967	57.6251
524.229	61.5902
524.49	66
524.752	56.9488
525.013	66
525.275	70
525.536	65
525.798	63.0291
526.059	61.5902
526.321	57.8347
526.582	61.1339
526.844	58.4033
527.105	60.766
527.367	65.3194
527.628	61.9895
527.889	59.6597
528.151	58
528.412	63.4435
528.674	63.7436
528.935	58.8531
529.196	59.3928
529.458	61.5804
529.719	59.2413
529.98	65.2984
530.242	61.3077
530.503	60.2098
530.764	62.2902
531.025	60.1888
531.287	69.9604
531.548	66.5105
531.809	60.4965
532.07	68.0233
532.332	66.5233
532.593	68.0676
532.854	64.0909
533.115	65.5571
533.376	73.2972
533.638	77.2534
533.899	67.6241
534.16	71.1277
534.421	65.8079
534.682	72.1957
534.943	73.0144
535.204	77.4487
535.465	72.5897
535.726	71.6729
535.987	73.502
536.248	71.316
536.509	69.0575
536.77	75.0166
537.031	72.6829
537.292	73.8434
537.553	75.8103
537.814	80.5954
538.075	76.7954
538.336	81.9545
538.597	83.1073
538.858	77.1225
539.119	85.9001
539.38	80.8612
539.641	79.6536
539.901	87.8841
540.162	86.1039
540.423	83.1218
540.684	76.8484
540.945	87.4229
541.205	89.9718
541.466	102.528
541.727	96.1869
541.988	98.0623
542.248	96.2841
542.509	102.613
542.77	95.3971
543.031	104.542
543.291	99.9392
543.552	99.4062
543.813	108.434
544.073	117.099
544.334	112.105
544.594	113.379
544.855	122.497
545.116	106.073
545.376	115.156
545.637	122.186
545.897	109.638
546.158	124.092
546.418	119.785
546.679	131.964
546.898	135.873
547.159	124.277
547.42	133.734
547.681	141.835
547.942	144.411
548.203	145.88
548.464	143.227
548.725	142.498
548.987	151.839
549.248	150.895
549.509	158.076
549.77	160.662
550.031	180.175
550.292	169.309
550.553	171.909
550.814	187.298
551.075	191.493
551.336	203.135
551.597	213.949
551.858	241.095
552.119	261.106
552.38	479.271
552.641	7907.05
552.901	1019.49
553.162	308.703
553.423	248.996
553.684	243.379
553.945	254.234
554.206	241.285
554.467	246.335
554.727	248.613
554.988	239.691
555.249	256.834
555.51	270.159
555.771	274.432
556.031	273.456
556.292	283.8
556.553	296.244
556.814	308.354
557.074	320.52
557.335	313.958
557.596	331.334
557.856	333.598
558.117	321.195
558.378	325.382
558.638	337.863
558.899	339.393
559.16	336.371
559.42	362.776
559.681	362.756
559.941	367.444
560.202	372.928
560.463	397.258
560.723	402.014
560.984	408.6
561.244	419.857
561.505	431.545
561.765	435.198
562.026	465.687
562.286	447.482
562.547	487.722
562.807	498.543
563.067	485.776
563.328	485.135
563.588	510.284
563.849	528.399
564.109	522.474
564.369	533.056
564.63	552.182
564.89	564.604
565.15	566.915
565.411	575.027
565.671	592.23
565.931	615.169
566.192	611.064
566.452	627.253
566.712	645.675
566.972	659.883
567.232	656.418
567.493	679.835
567.753	678.892
568.013	707.102
568.273	723.297
568.533	735.516
568.794	750.928
569.054	770.347
569.314	794.56
569.574	801.053
569.834	815.89
570.094	853.204
570.354	885.961
570.614	933.248
570.874	923.217
571.134	981.308
571.394	1008.85
571.654	1086.73
571.914	1143.49
572.174	1191.76
572.434	1244.54
572.694	1317.89
572.954	1394.96
573.214	1521.02
573.459	1649.88
573.719	1731.98
573.98	1888.15
574.241	2043.46
574.501	2196.71
574.762	2355.42
575.022	2569.06
575.283	2766.42
575.543	2821.7
575.804	2851.4
576.064	2871.31
576.325	2800.88
576.585	2745.97
576.846	2596
577.106	2452.37
577.366	2315.66
577.627	2196.48
577.887	2061.16
578.148	2001.3
578.408	1920.16
578.668	1889.17
578.929	1861.6
579.189	1813.75
579.449	1802
579.71	1752.75
579.97	1768.6
580.23	1766.96
580.49	1761.17
580.751	1796.55
581.011	1779.41
581.271	1799.16
581.531	1799.87
581.792	1806.71
582.052	1873.37
582.312	1845.87
582.572	1892.9
582.832	1906.24
583.092	1924.57
583.353	1980.04
583.613	2005.3
583.873	2029.71
584.133	2042.21
584.393	2089.53
584.653	2123.99
584.913	2182.69
585.173	2196.11
585.433	2232.99
585.693	2262.48
585.953	2335.74
586.213	2350.12
586.473	2369.63
586.733	2406.06
586.993	2408.26
587.253	2379.61
587.513	2455.52
587.773	2482.09
588.033	2424.82
588.293	2458.74
588.552	2457.39
588.812	2495.43
589.072	2523.65
589.332	2525.39
589.592	2521.33
589.852	2525.11
590.112	2504.9
590.371	2535.48
590.631	2501.64
590.891	2537.19
591.151	2531.62
591.41	2496.55
591.67	2523.57
591.93	2511.47
592.189	2451.16
592.449	2496.4
592.709	2486.98
592.968	2487.34
593.228	2493.86
593.488	2507.24
593.747	2509.13
594.007	2495.31
594.266	2552.42
594.526	2569.62
594.786	2556.42
595.045	2596.7
595.305	2604.58
595.564	2613.75
595.824	2632.34
596.083	2674.73
596.343	2711.48
596.602	2738.78
596.862	2753.21
597.121	2777.8
597.38	2791.24
597.64	2805.18
597.899	2857.63
598.159	2841.39
598.418	2895.29
598.677	2908.85
598.937	2901.25
599.196	2911.86
599.455	2960.08
599.715	2952.61
599.959	2961.7
600.219	2933.39
600.479	2958.69
600.738	2930.29
600.998	2979.56
601.258	2995.53
601.518	2922.47
601.778	3033.39
602.038	3019.11
602.298	3023.73
602.558	3001.11
602.818	3049.77
603.078	3034.22
603.337	3026.63
603.597	3092.92
603.857	3041.98
604.117	3074.72
604.377	3104.62
604.636	3038.88
604.896	3094.99
605.156	3111.09
605.416	3096.22
605.675	3114.35
605.935	3070.68
606.195	3059.76
606.455	3088.03
606.714	3061.34
606.974	3103.34
607.234	3140.68
607.493	3155.58
607.753	3141.07
608.012	3169.8
608.272	3179.52
608.532	3182.65
608.791	3159.54
609.051	3220.61
609.31	3235.06
609.57	3199.37
609.829	3241.11
610.089	3269.97
610.348	3255.46
610.608	3324.83
610.867	3329.85
611.127	3346.18
611.386	3353.28
611.646	3374.02
611.905	3335.19
612.164	3379.74
612.424	3399.09
612.683	3416.17
612.943	3471.4
613.202	3487.81
613.461	3538.67
613.721	3504.97
613.98	3571.68
614.239	3545.75
614.498	3614.56
614.758	3639.51
615.017	3626.26
615.276	3667.3
615.535	3727.32
615.795	3681.91
616.054	3775.31
616.313	3790.55
616.572	3794.03
616.831	3835.79
617.091	3848.33
617.35	3883.77
617.609	3880.61
617.868	3993.16
618.127	3997.65
618.386	3982.58
618.645	4037.4
618.904	4118.23
619.163	4116.15
619.422	4121.19
619.681	4177.51
619.94	4179.39
620.199	4211.65
620.458	4208.65
620.717	4218.84
620.976	4242.75
621.235	4272.52
621.494	4319.42
621.753	4342.83
622.012	4320.61
622.271	4321.02
622.53	4284.82
622.788	4329.41
623.047	4360.81
623.306	4375.65
623.565	4416.07
623.824	4457.93
624.082	4426.52
624.341	4416.67
624.6	4448.17
624.859	4364.49
625.117	4445.09
625.376	4459.66
625.635	4486.74
625.893	4516.08
626.152	4544.6
626.368	4568.51
626.627	4554.37
626.887	4594.77
627.146	4559.15
627.405	4663.68
627.665	4629.38
627.924	4583.02
628.183	4666.04
628.443	4713.75
628.702	4794.49
628.961	4813.93
629.22	4783.04
629.479	4788.89
629.739	4818.95
629.998	4845.97
630.257	4820.97
630.516	4844.41
630.776	4931.89
631.035	4928.89
631.294	4974.69
631.553	5014.99
631.812	5011.71
632.071	5065.43
632.33	5129.17
632.589	5188.58
632.848	5232.55
633.107	5190.58
633.366	5283.57
633.625	5379.87
633.885	5434.39
634.143	5454.3
634.403	5486.22
634.661	5559.73
634.92	5701.82
635.179	5739.54
635.438	5873.22
635.697	5996.44
635.956	6124.7
636.215	6325.82
636.474	6524.01
636.733	6824.94
636.992	7144.96
637.25	7414.68
637.509	7663.61
637.768	7763.34
638.027	7880.67
638.286	7923.65
638.544	7860.43
638.803	7762.23
639.062	7624.29
639.321	7454.49
639.579	7222.21
639.838	7045.73
640.097	7010.3
640.356	6889.54
640.614	6807.18
640.873	6669.22
641.131	6725.92
641.39	6723.86
641.649	6667.79
641.907	6659.43
642.166	6671.75
642.424	6599.12
642.683	6620.78
642.942	6673.33
643.2	6670.42
643.459	6725.83
643.717	6690.38
643.976	6682.78
644.234	6766.66
644.493	6732.43
644.751	6720.81
645.009	6916.79
645.268	6839.08
645.526	6892.3
645.785	6937.87
646.043	6917.68
646.301	6911.36
646.56	7012.21
646.818	6953.06
647.076	7020.36
647.335	7027.66
647.593	7121.81
647.851	7165.61
648.109	7106.21
648.368	7243.29
648.626	7230.02
648.884	7255.49
649.142	7273.31
649.401	7350.06
649.659	7441.04
649.917	7507.29
650.175	7555.62
650.433	7527.21
650.691	7597.61
650.949	7651.72
651.208	7791.35
651.466	7828.03
651.724	7734.95
651.982	7841.51
652.24	7902.04
652.498	7938.46
652.756	8015.95
652.979	8107.74
653.238	8087.22
653.497	8180.56
653.755	8047.77
654.014	8316.01
654.273	8320.59
654.531	8435.02
654.79	8453.54
655.049	8581.43
655.307	8695.65
655.566	8762.64
655.824	8787.27
656.083	8948.49
656.342	9012.32
656.6	9040.75
656.859	9167.15
657.117	9272.25
657.376	9317.02
657.634	9467.11
657.893	9580.6
658.151	9523.71
658.41	9649.6
658.668	9602
658.927	9689.98
659.185	9634.65
659.443	9722.29
659.702	9645.74
659.96	9789.59
660.219	9744.94
660.477	9812.8
660.735	9763.11
660.994	9770.89
661.252	9773.08
661.51	9727.91
661.768	9695.39
662.027	9683.36
662.285	9728.85
662.543	9722.71
662.802	9774.1
663.06	9755.19
663.318	9762.18
663.576	9769.83
663.834	9705.11
664.093	9794.38
664.351	9744.31
664.609	9770.38
664.867	9803.32
665.125	9751.71
665.383	9749.3
665.641	9744.63
665.899	9684.6
666.157	9672.04
666.415	9606.81
666.673	9635.4
666.931	9742.93
667.189	9692.35
667.447	9678.32
667.705	9733.52
667.963	9714.8
668.221	9801.36
668.479	9665.94
668.737	9694.75
668.995	9650.61
669.253	9764.7
669.511	9744.49
669.769	9731.63
670.027	9694.87
670.284	9632.03
670.542	9688.76
670.8	9743.43
671.058	9688.65
671.316	9745.26
671.573	9767.82
671.831	9674.75
672.089	9695.76
672.347	9765.21
672.604	9800.8
672.862	9781.17
673.12	9891
673.377	9891.2
673.635	9895.97
673.893	10031.8
674.15	10041.7
674.408	10093.7
674.665	10215
674.923	10184.8
675.18	10196.9
675.438	10283.5
675.696	10339.3
675.953	10302.3
676.211	10321.9
676.468	10427.9
676.726	10322.1
676.983	10368.4
677.24	10391.3
677.498	10361
677.755	10354.1
678.013	10285.6
678.27	10393.7
678.527	10417.9
678.785	10366.4
679.042	10297.1
679.277	10380.3
679.535	10363.3
679.793	10338.2
680.051	10497.3
680.309	10498.7
680.567	10528.8
680.825	10652.5
681.083	10432.4
681.341	10602.9
681.599	10528.1
681.857	10589.8
682.115	10686.1
682.373	10669.4
682.631	10776
682.889	10725.8
683.146	10781
683.404	10729.3
683.662	10607
683.92	10775.8
684.178	10740.3
684.436	10650.3
684.694	10702.2
684.951	10684.7
685.209	10657.8
685.467	10539
685.725	10497.5
685.982	10579.3
686.24	10501.3
686.498	10428.7
686.756	10472.1
687.013	10371.1
687.271	10418.3
687.529	10425.6
687.786	10451.6
688.044	10375.2
688.302	10429.1
688.559	10414.6
688.817	10427.3
689.074	10340.9
689.332	10335.7
689.589	10376
689.847	10388.9
690.104	10296.7
690.362	10325.4
690.619	10252.7
690.877	10278
691.134	10185.6
691.392	10206.9
691.649	10122.4
691.907	10149.3
692.164	10099.9
692.421	9979.8
692.679	10070.7
692.936	10012
693.194	9944.97
693.451	9981.78
693.708	9960.01
693.966	9892.93
694.223	9853.16
694.48	9908.44
694.737	9817.37
694.995	9787.7
695.252	9801.53
695.509	9797.63
695.766	9801.24
696.023	9698.65
696.281	9749.04
696.538	9701.03
696.795	9647.45
697.052	9649.82
697.309	9604.54
697.566	9584.53
697.823	9544.62
698.08	9449.13
698.338	9391.05
698.595	9386.29
698.852	9352.5
699.109	9297.38
699.366	9293.33
699.623	9296.14
699.88	9237.14
700.137	9223.31
700.393	9201.53
700.65	9163.96
700.907	9175.83
701.164	9255.57
701.421	9146.19
701.678	9217.6
701.935	9193.47
702.192	9219.77
702.448	9202.78
702.705	9156.69
702.962	9235.8
703.219	9193.27
703.476	9200.7
703.732	9093.18
703.989	9068.03
704.246	9050.62
704.503	9185.4
704.759	9038.94
705.016	9039.88
705.273	8933.1
705.511	8968.01
705.768	8941.77
706.026	8831.95
706.283	8805.35
706.541	8778.22
706.798	8715.28
707.055	8719.1
707.313	8691.55
707.57	8607.1
707.827	8527.86
708.084	8599.36
708.342	8525.94
708.599	8605.79
708.856	8485.24
709.114	8542.32
709.371	8416.07
709.628	8369.56
709.885	8338.2
710.142	8394.39
710.4	8387.29
710.657	8409.74
710.914	8352.95
711.171	8292.86
711.428	8260.11
711.685	8247.68
711.942	8189.18
712.199	8144.77
712.456	8142.44
712.713	8100.85
712.97	8012.01
713.227	7948.4
713.484	7973.77
713.741	7799.2
713.998	7858.63
714.255	7740.33
714.512	7770.85
714.769	7732.04
715.026	7634.04
715.283	7572.05
715.54	7630.62
715.797	7561.6
716.054	7543.76
716.31	7486.37
716.567	7434.89
716.824	7452.09
717.081	7484.29
717.338	7419.54
717.594	7380.27
717.851	7403.52
718.108	7295.14
718.365	7342.77
718.621	7260.07
718.878	7242.32
719.135	7217.51
719.391	7193.74
719.648	7170.73
719.905	7091.04
720.161	7079.18
720.418	7067.71
720.675	6971.69
720.931	6929.29
721.188	6953.52
721.444	6912.57
721.701	6881.63
721.957	6871.98
722.214	6812.79
722.47	6767.6
722.727	6707.72
722.983	6666.88
723.24	6650.28
723.496	6646.83
723.753	6595.4
724.009	6607.91
724.265	6606.81
724.522	6480.34
724.778	6463.88
725.034	6500.1
725.291	6404.18
725.547	6427.73
725.803	6381.93
726.06	6345.79
726.316	6283.65
726.572	6301.08
726.828	6270.75
727.085	6262.59
727.341	6180.39
727.597	6163.69
727.853	6153.7
728.109	6132
728.366	6064.51
728.622	6025.36
728.878	5975.43
729.134	5933.68
729.39	6000.36
729.646	5922.24
729.902	5820.91
730.158	5782.59
730.414	5716.4
730.67	5687.15
730.926	5646.06
731.182	5621.16
731.438	5602.18
731.643	5536
731.9	5578.57
732.156	5476.45
732.413	5456.09
732.67	5472.67
732.927	5510.11
733.183	5465.87
733.44	5502.45
733.697	5500.03
733.953	5437.99
734.21	5445.82
734.466	5397.87
734.723	5446.18
734.98	5374.36
735.236	5432.45
735.493	5426.19
735.749	5459.76
736.006	5452.19
736.262	5461.37
736.519	5470.33
736.775	5519.6
737.032	5536.92
737.288	5622.41
737.544	5672.67
737.801	5654.88
738.057	5641.57
738.314	5733.48
738.57	5643.42
738.826	5666.26
739.083	5554.04
739.339	5516.34
739.595	5450.62
739.852	5395.25
740.108	5354.72
740.364	5265.37
740.621	5191.8
740.877	5176.8
741.133	5146.19
741.389	5094.66
741.645	5059.48
741.902	4988.11
742.158	4970.83
742.414	4914.34
742.67	4886.21
742.926	4894.2
743.182	4810.04
743.438	4807.11
743.694	4768.3
743.951	4730.35
744.207	4745.97
744.463	4680.8
744.719	4638.86
744.975	4614.01
745.231	4558.8
745.487	4536.95
745.743	4558.78
745.998	4534.05
746.254	4522.91
746.51	4522.45
746.766	4480.31
747.022	4469.51
747.278	4446.82
747.534	4413.85
747.79	4362.83
748.046	4378.65
748.301	4380.97
748.557	4297.36
748.813	4309.93
749.069	4294.92
749.324	4292.44
749.58	4238.21
749.836	4260.64
750.092	4253.03
750.347	4235.11
750.603	4189.09
750.859	4160.64
751.114	4110.51
751.37	4144.3
751.625	4112.89
751.881	4065.29
752.137	4075.04
752.392	4007.48
752.648	4003.15
752.903	4014.5
753.159	3939.03
753.414	3939.02
753.67	3935.72
753.925	3894.53
754.181	3852.68
754.436	3853.7
754.692	3848.42
754.947	3788.25
755.202	3762.37
755.458	3777.63
755.713	3730.38
755.968	3705.34
756.224	3698.19
756.479	3686.83
756.734	3619.65
756.99	3619.28
757.245	3652.29
757.5	3572.36
757.755	3593.37
757.968	3530.04
758.224	3511.72
758.48	3456.7
758.736	3467.17
758.992	3517.27
759.248	3435.32
759.504	3444.5
759.76	3388.12
760.016	3406.64
760.272	3372.23
760.528	3332.28
760.784	3295.08
761.04	3313.4
761.296	3254.35
761.552	3291.23
761.807	3276.75
762.063	3297.79
762.319	3270.51
762.575	3206.61
762.831	3143.33
763.086	3142.39
763.342	3150.14
763.598	3128.63
763.853	3114.36
764.109	3157.84
764.365	3043.22
764.621	3016.87
764.876	3061.23
765.132	3044.15
765.387	3015.72
765.643	2973.51
765.899	2974.32
766.154	2992.8
766.41	2906.12
766.665	2935.38
766.921	2918.22
767.176	2888.28
767.432	2886.95
767.687	2839.4
767.943	2786.69
768.198	2793.39
768.454	2817.32
768.709	2786.92
768.965	2774.07
769.22	2734.49
769.475	2674.88
769.731	2658.6
769.986	2664.38
770.242	2664.97
770.497	2615.87
770.752	2655.84
771.007	2612.74
771.263	2594.43
771.518	2548.24
771.773	2500.26
772.028	2490.9
772.284	2507.65
772.539	2478.28
772.794	2449.72
773.049	2466.51
773.304	2423.7
773.56	2396.14
773.815	2363.57
774.07	2399.81
774.325	2367.13
774.58	2339.68
774.835	2367.06
775.09	2327.07
775.345	2309.57
775.6	2281.89
775.855	2276.59
776.11	2264.36
776.365	2214.14
776.62	2212.72
776.875	2195.69
777.13	2190.13
777.385	2167.04
777.64	2152.71
777.895	2151.11
778.149	2119.19
778.404	2095.21
778.659	2082.38
778.914	2063.86
779.169	2062.66
779.424	2047.65
779.678	2037.01
779.933	2003.82
780.188	1995.53
780.442	2027.09
780.697	1955.32
780.952	1974.08
781.207	1938.64
781.461	1947.41
781.716	1945.78
781.97	1930.41
782.225	1898.73
782.48	1875.81
782.734	1831.59
782.989	1838.85
783.243	1830.66
783.498	1815.08
783.752	1801.02
784.007	1802.05
784.253	1797.77
784.509	1727.39
784.764	1752.91
785.019	1771.02
785.274	1727.24
785.53	1770.87
785.785	1659.91
786.04	1690.6
786.295	1686.98
786.551	1662.08
786.806	1660.84
787.061	1642.17
787.316	1626.1
787.571	1613.99
787.826	1619.44
788.081	1593.36
788.336	1582.16
788.591	1583.36
788.847	1587.55
789.102	1577.74
789.357	1512.8
789.612	1517.96
789.867	1518.69
790.122	1527.77
790.377	1484.67
790.632	1503.6
790.886	1489.44
791.141	1473.75
791.396	1461.48
791.651	1408.87
791.906	1399.13
792.161	1418.77
792.416	1395.13
792.671	1401.66
792.925	1380.53
793.18	1372.43
793.435	1372.28
793.69	1364.76
793.945	1335.71
794.199	1343.64
794.454	1341.28
794.709	1318.5
794.963	1280.31
795.218	1290.3
795.473	1318.36
795.727	1289.32
795.982	1262.43
796.237	1253.31
796.491	1229.92
796.746	1243.5
797	1204.13
797.255	1209.14
797.509	1194.13
797.764	1225.82
798.018	1179.68
798.273	1161.87
798.527	1184.13
798.782	1184.44
799.036	1175.75
799.291	1146.15
799.545	1137.93
799.8	1101.66
800.054	1111.42
800.308	1096.53
800.563	1085.58
800.817	1119.7
801.071	1066.43
801.326	1079.47
801.58	1075.12
801.834	1073.73
802.088	1067.12
802.343	1044.27
802.597	1057.92
802.851	1037
803.105	1028.53
803.359	1010.3
803.614	1013.07
803.868	1013.81
804.122	1002.17
804.376	989.195
804.63	979.392
804.884	970.556
805.138	954.502
805.392	960.333
805.646	932.023
805.9	940.859
806.154	942.962
806.408	952.743
806.662	919.217
806.916	929.293
807.17	934.618
807.424	908.128
807.678	929.503
807.932	882.108
808.186	897.093
808.439	874.656
808.693	856.493
808.947	872.298
809.201	872.874
809.455	857.971
809.708	844.005
809.962	861.349
810.183	856
810.438	844.124
810.693	826.319
810.947	816.467
811.202	813.15
811.456	812.671
811.711	771.542
811.965	794.467
812.22	815.465
812.474	804.14
812.729	767.17
812.983	780.297
813.237	770.794
813.492	754.691
813.746	779.266
814.001	744.558
814.255	751.164
814.509	750.961
814.764	734.315
815.018	735.947
815.272	727.547
815.526	723.2
815.781	713.926
816.035	716.673
816.289	702.357
816.543	695.915
816.798	705.816
817.052	707.354
817.306	707.265
817.56	698.349
817.814	690.245
818.068	661.395
818.323	669.127
818.577	672.879
818.831	660.591
819.085	663.755
819.339	645.833
819.593	668.836
819.847	649.21
820.101	636.913
820.355	632.293
820.609	629.655
820.863	648.819
821.117	621.837
821.371	621.243
821.624	605.039
821.878	613.064
822.132	596.275
822.386	597.941
822.64	592.615
822.894	583.562
823.148	564.848
823.401	575.348
823.655	577.175
823.909	584.753
824.163	579
824.416	565.584
824.67	554.31
824.924	554.54
825.177	563.6
825.431	531.152
825.685	548.495
825.938	548.17
826.192	537.983
826.446	540.317
826.699	533.317
826.953	535.078
827.206	526.811
827.46	521.451
827.713	524.746
827.967	521.06
828.22	507.132
828.474	514.088
828.727	522.624
828.981	501.071
829.234	502.895
829.488	502.471
829.741	470.48
829.994	487.848
830.248	487.357
830.501	481.333
830.754	487.799
831.008	479.923
831.261	489.229
831.514	484.075
831.767	468.708
832.021	467.612
832.274	464.533
832.527	461.027
832.78	474.982
833.034	462.786
833.287	465.531
833.54	452.331
833.793	456.138
834.046	445.352
834.299	439.875
834.552	446.457
834.805	438.482
835.058	448.842
835.311	450.406
835.564	419.493
835.817	443.165
836.07	418.396
836.314	425.969
836.568	423.903
836.821	422.357
837.075	408.129
837.329	405.9
837.583	436.57
837.836	406.616
838.09	415.712
838.344	412.234
838.598	402.119
838.851	398.386
839.105	401.494
839.359	385.41
839.612	396.169
839.866	401.898
840.119	386.792
840.373	371.151
840.627	367.386
840.88	377.172
841.134	378.161
841.387	382.501
841.641	385.608
841.894	371.795
842.148	371.059
842.401	371.345
842.655	368.822
842.908	356.516
843.161	377.497
843.415	361.46
843.668	353.935
843.922	343.015
844.175	353.261
844.428	365.457
844.682	352.891
844.935	350.68
845.188	357.484
845.442	330.261
845.695	333.775
845.948	345.13
846.201	340.765
846.455	330.486
846.708	332.305
846.961	332.92
847.214	333.617
847.467	329.295
847.72	327.37
847.973	311.023
848.227	322.633
848.48	330.902
848.733	324.661
848.986	324.277
849.239	323.926
849.492	312.168
849.745	299.53
849.998	297.535
850.251	309.074
850.504	308.978
850.757	302.022
851.01	317.339
851.263	308.544
851.515	314.611
851.768	304.152
852.021	298.292
852.274	300.285
852.527	279.154
852.78	282.328
853.032	303.694
853.285	294.024
853.538	291.902
853.791	279.398
854.043	271.689
854.296	279.122
854.549	278.262
854.801	278.727
855.054	275.112
855.307	281.95
855.559	276.31
855.812	281.253
856.065	269.416
856.317	271.528
856.57	271.519
856.822	271.601
857.075	259.116
857.327	259.26
857.58	258.872
857.832	268.177
858.085	265.433
858.337	252.429
858.589	247.504
858.842	249.342
859.094	252.955
859.347	248.603
859.599	251.274
859.851	246.887
860.104	242.702
860.356	248.419
860.608	236.462
860.861	249.616
861.113	240.916
861.365	236.488
861.617	251.246
861.869	224.996
862.112	236.01
862.365	227.992
862.618	241.724
862.871	235.773
863.124	247.613
863.377	235.863
863.63	236.934
863.883	229.926
864.136	237.217
864.389	217.912
864.642	231.61
864.894	229.691
865.147	231.986
865.4	213.333
865.653	217.095
865.906	218.905
866.159	215.183
866.412	217.563
866.664	207.137
866.917	218.7
867.17	210.517
867.423	207.743
867.675	213.317
867.928	205.365
868.181	201.685
868.433	192.585
868.686	209.881
868.939	198.158
869.191	204.544
869.444	197.472
869.697	194.437
869.949	204.901
870.202	197.358
870.454	200.439
870.707	207.512
870.959	199.613
871.212	196.755
871.464	199.277
871.717	189.016
871.969	194.204
872.222	193.769
872.474	189.973
872.727	192.9
872.979	194.995
873.231	195.942
873.484	187.169
873.736	179.63
873.988	185.924
874.241	188.994
874.493	186.897
874.745	195.09
874.998	180.324
875.25	171.284
875.502	170.919
875.754	173.102
876.006	186.868
876.259	178.843
876.511	162.661
876.763	174.239
877.015	179.008
877.267	177.23
877.519	177.146
877.771	171.918
878.023	169.329
878.276	176.205
878.528	168.115
878.78	172.107
879.031	161.678
879.284	163.811
879.535	169.399
879.787	157.589
880.039	163.545
880.291	159.422
880.543	160.417
880.795	159.819
881.047	160.283
881.299	155.615
881.551	161.003
881.802	158.692
882.054	155.295
882.306	159.6
882.558	155.594
882.809	151.468
883.061	150.821
883.313	158.722
883.565	150.552
883.816	148.498
884.068	145.997
884.319	139.206
884.571	149.897
884.823	150.687
885.074	134.804
885.326	142.009
885.577	146.469
885.829	148.708
886.08	145.11
886.332	136.131
886.583	141.572
886.835	128.292
887.086	134.438
887.338	136.753
887.589	150.071
887.841	143.959
888.044	136.087
888.296	141.69
888.548	141.401
888.8	134.099
889.053	139.671
889.305	126.592
889.557	133.166
889.809	132.54
890.061	144.042
890.313	136.084
890.566	135.158
890.818	118.145
891.07	120.401
891.322	126.416
891.574	124.071
891.826	120.657
892.078	120.274
892.33	128.172
892.582	127.908
892.834	122.381
893.086	123.616
893.338	128.659
893.59	118.731
893.842	120.301
894.094	120.993
894.346	116.017
894.597	110.145
894.849	115
895.101	126.778
895.353	118.499
895.605	116.87
895.857	115.104
896.108	121.402
896.36	114.729
896.612	112.239
896.864	117
897.115	118
897.367	113.002
897.619	108.515
897.87	110.467
898.122	107.495
898.374	110.206
898.625	108.127
898.877	115.221
899.128	108.057
899.38	109.337
899.631	113.694
899.883	110.364
899.984	104.518