File: PL_Fatia_SCD_021223_04.txt
#Acq. time (s)=	3
#Accumulations=	2
#Range (nm)=	520...900
#Windows=	16
#Auto scanning=	On
#Autofocus=	Off
#AutoExposure=	Off
#Spike filter=	Multiple accum.
#Delay time (s)=	0
#Binning=	1
#Readout mode=	Signal
#DeNoise=	Off
#ICS correction=	Off
#Dark correction=	Off
#Inst. Process=	Off
#Detector temperature (°C)=	-59.98
#Instrument=	LabRAM HR Evol
#Detector=	Syncerity OE
#Objective=	x50_VIS
#Grating=	600 (500nm)
#ND Filter=	10%
#Laser=	514nm_Edge
#Hole=	199.981
#Range=	Auto
#StageXY=	Marzhauser
#StageZ=	Marzhauser
#X (µm)=	1931.1
#Y (µm)=	-221.9
#Z (µm)=	-219.5
#Full time(mm:ss)=	2:39
#Project=
#Sample=
#Site=
#Title=	PL_Fatia_SCD_021223
#Remark=
#Date=	18.12.2023 18:08
#Acquired=	18.12.2023 18:08:42
520.042	95
520.304	90.2049
520.565	93.6438
520.827	95.0698
521.089	82.1581
521.351	93.7314
521.612	88.9022
521.874	88.7835
522.136	85.1186
522.397	90.8719
522.659	84.6868
522.921	88.7334
523.182	86.1572
523.444	89.4971
523.705	87.4691
523.967	81.8126
524.229	83.5902
524.49	81.4144
524.752	87.5669
525.013	88.546
525.275	81.1816
525.536	76.4878
525.798	77.7718
526.059	79
526.321	84.4435
526.582	81.8452
526.844	82.4033
527.105	73.0745
527.367	73.4033
527.628	79.6702
527.889	78.3403
528.151	81.4033
528.412	84.4738
528.674	79.6282
528.935	81.6177
529.196	76.8217
529.458	83.3869
529.719	78.655
529.98	83
530.242	75.9487
530.503	85.3147
530.764	81.2063
531.025	75.4685
531.287	81
531.548	80.5734
531.809	87
532.07	76
532.332	80.5233
532.593	82.7972
532.854	92.6364
533.115	75.1142
533.376	92.5944
533.638	88.3212
533.899	88.4598
534.16	88.9302
534.421	92.3487
534.682	95.3529
534.943	89.5705
535.204	92.2262
535.465	99.1498
535.726	100.363
535.987	97.1322
536.248	93.5512
536.509	92.0131
536.77	93.0014
537.031	94.4579
537.292	96.6204
537.553	102.64
537.814	100.703
538.075	90.0072
538.336	101.05
538.597	96.0599
538.858	103.411
539.119	107.315
539.38	103.631
539.641	105.02
539.901	106.3
540.162	111.613
540.423	107.106
540.684	102.394
540.945	105.585
541.205	117.966
541.466	112.143
541.727	115.821
541.988	116.927
542.248	117.265
542.509	122.836
542.77	130.072
543.031	124.276
543.291	131.217
543.552	124.056
543.813	127.704
544.073	133.499
544.334	129.068
544.594	127.221
544.855	127.335
545.116	147.667
545.376	143.385
545.637	134.069
545.897	146.301
546.158	150.205
546.418	146.615
546.679	169.366
546.898	169.894
547.159	152.378
547.42	164.123
547.681	163.748
547.942	170.122
548.203	176.02
548.464	173.69
548.725	173.869
548.987	179.879
549.248	188.705
549.509	199.834
549.77	185.853
550.031	193.852
550.292	214.121
550.553	224.797
550.814	216.205
551.075	239.696
551.336	241.617
551.597	258.103
551.858	274.379
552.119	327.511
552.38	554.889
552.641	9586.85
552.901	1023.33
553.162	359.961
553.423	306.259
553.684	289.891
553.945	296
554.206	297.338
554.467	305.951
554.727	301.016
554.988	299.708
555.249	314.653
555.51	319.501
555.771	325.122
556.031	326.729
556.292	344.609
556.553	351.316
556.814	364.621
557.074	372.465
557.335	359.776
557.596	382.812
557.856	388.004
558.117	396.99
558.378	395.586
558.638	397.731
558.899	395.914
559.16	404.029
559.42	432.338
559.681	442.63
559.941	427.043
560.202	451.069
560.463	456.733
560.723	467.859
560.984	470.963
561.244	494.135
561.505	506.779
561.765	524.449
562.026	531.235
562.286	541.275
562.547	551.6
562.807	574.938
563.067	571.897
563.328	581.328
563.588	599.833
563.849	595.216
564.109	621.261
564.369	627.167
564.63	632.457
564.89	656.921
565.15	669.836
565.411	680.12
565.671	684.367
565.931	701.466
566.192	711.807
566.452	727.2
566.712	752.814
566.972	761.338
567.232	793.91
567.493	785.38
567.753	803.539
568.013	817.739
568.273	846.18
568.533	844.19
568.794	860.632
569.054	878.897
569.314	900.489
569.574	918.352
569.834	962.235
570.094	985.172
570.354	1016.5
570.614	1056.81
570.874	1087.23
571.134	1121.88
571.394	1187.45
571.654	1259.9
571.914	1287.67
572.174	1355.54
572.434	1441.03
572.694	1525.54
572.954	1620.81
573.214	1734.49
573.459	1848
573.719	1990.6
573.98	2159.64
574.241	2296.8
574.501	2477.66
574.762	2713.1
575.022	2911.37
575.283	3107.4
575.543	3193.33
575.804	3272
576.064	3291.64
576.325	3237.81
576.585	3162.46
576.846	3037.15
577.106	2859.35
577.366	2759.55
577.627	2577.32
577.887	2483.21
578.148	2375.78
578.408	2274.4
578.668	2246.29
578.929	2149
579.189	2133.94
579.449	2098.3
579.71	2076.99
579.97	2042.05
580.23	2062.78
580.49	2051.49
580.751	2101.68
581.011	2062.02
581.271	2105.36
581.531	2100.75
581.792	2134.88
582.052	2144.03
582.312	2150.49
582.572	2183.59
582.832	2187.94
583.092	2239.38
583.353	2259.62
583.613	2304.03
583.873	2318.17
584.133	2378.78
584.393	2437.21
584.653	2485.81
584.913	2504.18
585.173	2509.02
585.433	2568.66
585.693	2606.12
585.953	2624.79
586.213	2700.83
586.473	2724.36
586.733	2745.22
586.993	2770.93
587.253	2796.46
587.513	2817.66
587.773	2840.8
588.033	2797.54
588.293	2813.22
588.552	2872.38
588.812	2878.06
589.072	2876.23
589.332	2902.15
589.592	2871.61
589.852	2881.17
590.112	2884.26
590.371	2875.15
590.631	2889.59
590.891	2890.39
591.151	2908.42
591.41	2931.64
591.67	2869.41
591.93	2857.28
592.189	2843.72
592.449	2883.53
592.709	2869.6
592.968	2895.93
593.228	2893.32
593.488	2900.32
593.747	2884.9
594.007	2925.74
594.266	2921.28
594.526	2946.15
594.786	2938.41
595.045	2960.78
595.305	2980.88
595.564	3014.11
595.824	3067.64
596.083	3075.43
596.343	3099.2
596.602	3118.18
596.862	3168.23
597.121	3198.24
597.38	3194.04
597.64	3240.62
597.899	3236.86
598.159	3252.14
598.418	3313.45
598.677	3288.17
598.937	3348.63
599.196	3341.02
599.455	3380.04
599.715	3321.44
599.959	3383.97
600.219	3328.96
600.479	3363.75
600.738	3382.82
600.998	3366.92
601.258	3443.77
601.518	3381.77
601.778	3442.34
602.038	3481.54
602.298	3452.34
602.558	3489.89
602.818	3486.15
603.078	3447.26
603.337	3506.49
603.597	3518.64
603.857	3529.98
604.117	3559.54
604.377	3534.17
604.636	3611.51
604.896	3558.96
605.156	3529.9
605.416	3513.39
605.675	3602.83
605.935	3546.06
606.195	3537.55
606.455	3567.62
606.714	3555.34
606.974	3565.63
607.234	3569.31
607.493	3595.13
607.753	3593.69
608.012	3581.9
608.272	3614.67
608.532	3618.7
608.791	3657.78
609.051	3621.39
609.31	3667.13
609.57	3704.51
609.829	3711.86
610.089	3755.38
610.348	3699.47
610.608	3751.1
610.867	3784.57
611.127	3778.8
611.386	3793.78
611.646	3793.84
611.905	3850.78
612.164	3868.63
612.424	3863.39
612.683	3846.8
612.943	3904.24
613.202	3921.11
613.461	3990.61
613.721	4004.2
613.98	4023.6
614.239	4009.35
614.498	4074.32
614.758	4114.31
615.017	4115.69
615.276	4154.81
615.535	4178.6
615.795	4184.7
616.054	4267.58
616.313	4286.36
616.572	4320.97
616.831	4329.16
617.091	4396.31
617.35	4381.05
617.609	4469.3
617.868	4463.45
618.127	4553.57
618.386	4548.31
618.645	4610.25
618.904	4620.62
619.163	4616.63
619.422	4651.45
619.681	4707.57
619.94	4730.53
620.199	4732.34
620.458	4807.31
620.717	4815.27
620.976	4824.02
621.235	4829.14
621.494	4805.55
621.753	4827.16
622.012	4848.57
622.271	4848.51
622.53	4873.97
622.788	4900.8
623.047	4908.26
623.306	4965.49
623.565	4950.52
623.824	4963.69
624.082	4953.38
624.341	5015.58
624.6	4952.2
624.859	5029.34
625.117	5029.84
625.376	5058.86
625.635	4999.82
625.893	5011.05
626.152	5118.19
626.368	5068.32
626.627	5185.6
626.887	5145.1
627.146	5143.18
627.405	5179.83
627.665	5205.96
627.924	5253.48
628.183	5244.5
628.443	5288.23
628.702	5372.56
628.961	5345.44
629.22	5362.99
629.479	5397.66
629.739	5437.32
629.998	5445.71
630.257	5413.55
630.516	5470.3
630.776	5450.87
631.035	5558.14
631.294	5605.53
631.553	5623.92
631.812	5611.38
632.071	5652.28
632.33	5765.53
632.589	5712.42
632.848	5861.64
633.107	5865.33
633.366	5970.9
633.625	5959.51
633.885	5968.33
634.143	6070.27
634.403	6128.67
634.661	6193.84
634.92	6297.74
635.179	6364.01
635.438	6513.09
635.697	6647.38
635.956	6814.7
636.215	6989.5
636.474	7231.88
636.733	7457.65
636.992	7690.62
637.25	7986.75
637.509	8146.75
637.768	8405.37
638.027	8501.26
638.286	8492.57
638.544	8580.78
638.803	8557.53
639.062	8392.34
639.321	8275.34
639.579	8147.92
639.838	8009.87
640.097	7866.98
640.356	7794.09
640.614	7691.99
640.873	7621.4
641.131	7555.56
641.39	7450.13
641.649	7525.13
641.907	7424.29
642.166	7410.22
642.424	7438.87
642.683	7436.86
642.942	7460.92
643.2	7469.28
643.459	7487.13
643.717	7531.42
643.976	7557.75
644.234	7623
644.493	7572.41
644.751	7601.12
645.009	7637.98
645.268	7595.37
645.526	7732.04
645.785	7737.21
646.043	7792.34
646.301	7734.92
646.56	7736.85
646.818	7918.77
647.076	7922.45
647.335	7952.96
647.593	7926.91
647.851	8014.82
648.109	7976.4
648.368	8009.73
648.626	8093.01
648.884	8127.39
649.142	8154.23
649.401	8241.45
649.659	8340.96
649.917	8348.68
650.175	8386.54
650.433	8492.3
650.691	8533.51
650.949	8604.46
651.208	8586.5
651.466	8623.97
651.724	8682.38
651.982	8653.98
652.24	8772.4
652.498	8790.09
652.756	8853.7
652.979	8914.77
653.238	8994.94
653.497	9069.88
653.755	9161.41
654.014	9250.29
654.273	9366.77
654.531	9368.34
654.79	9433.73
655.049	9571.29
655.307	9567.84
655.566	9739.79
655.824	9763.81
656.083	9895.98
656.342	10001.4
656.6	10030.7
656.859	10087.6
657.117	10185.7
657.376	10419
657.634	10469.3
657.893	10535.8
658.151	10566.4
658.41	10575.8
658.668	10676.6
658.927	10569.6
659.185	10726.8
659.443	10751.1
659.702	10738.3
659.96	10825.6
660.219	10884.1
660.477	10866.3
660.735	10804.7
660.994	10816.2
661.252	10817.1
661.51	10845.9
661.768	10825
662.027	10929.6
662.285	10893.7
662.543	10830.9
662.802	10877.4
663.06	10889.8
663.318	10844.9
663.576	10876.2
663.834	10859
664.093	10916.1
664.351	10890.4
664.609	10886.8
664.867	10867
665.125	10833.9
665.383	10796.4
665.641	10767.9
665.899	10773.3
666.157	10778.4
666.415	10820.4
666.673	10848.5
666.931	10782.1
667.189	10771.7
667.447	10847.1
667.705	10808.3
667.963	10868.5
668.221	10814.2
668.479	10826.9
668.737	10817
668.995	10727.2
669.253	10865.2
669.511	10777.4
669.769	10808.7
670.027	10812.1
670.284	10743.4
670.542	10816.6
670.8	10873.1
671.058	10766.1
671.316	10807.2
671.573	10880.7
671.831	10807.3
672.089	10822.1
672.347	10856.7
672.604	10969.3
672.862	10904.9
673.12	10930.7
673.377	11032
673.635	11068
673.893	11106.8
674.15	11187.1
674.408	11256.8
674.665	11273.2
674.923	11289.2
675.18	11288.2
675.438	11393.8
675.696	11469.6
675.953	11415.2
676.211	11521.6
676.468	11527.7
676.726	11517.8
676.983	11525.8
677.24	11585.1
677.498	11533.1
677.755	11511.3
678.013	11468.1
678.27	11556
678.527	11538.8
678.785	11505.3
679.042	11407.7
679.277	11565.3
679.535	11490.5
679.793	11548.6
680.051	11713.5
680.309	11566.7
680.567	11686.9
680.825	11662.9
681.083	11701.8
681.341	11715.1
681.599	11831.2
681.857	11808.3
682.115	11777
682.373	11832.7
682.631	11884.7
682.889	11798.2
683.146	11865.3
683.404	11927.1
683.662	11863.7
683.92	11926.3
684.178	11869.4
684.436	11808.3
684.694	11771.3
684.951	11787.9
685.209	11762
685.467	11671.1
685.725	11763.4
685.982	11639.7
686.24	11757.7
686.498	11681.3
686.756	11635.1
687.013	11525.8
687.271	11598.3
687.529	11541.2
687.786	11593.7
688.044	11535.6
688.302	11500.4
688.559	11542.6
688.817	11523.2
689.074	11556.1
689.332	11513.5
689.589	11515.3
689.847	11518.3
690.104	11495
690.362	11399.5
690.619	11357.8
690.877	11371.5
691.134	11313.3
691.392	11304.6
691.649	11277.9
691.907	11227.6
692.164	11173.3
692.421	11106.6
692.679	11098.7
692.936	11066.7
693.194	11048.6
693.451	11134.1
693.708	11027.2
693.966	10982.4
694.223	11009.1
694.48	10952
694.737	10966.5
694.995	10926.4
695.252	10934.4
695.509	10882.2
695.766	10827.3
696.023	10883.7
696.281	10784.6
696.538	10795.6
696.795	10744.8
697.052	10694.5
697.309	10672.9
697.566	10578.3
697.823	10600.9
698.08	10460.1
698.338	10491.2
698.595	10380.3
698.852	10390
699.109	10371.7
699.366	10310.9
699.623	10335.1
699.88	10340.9
700.137	10289.8
700.393	10237
700.65	10233.4
700.907	10275
701.164	10214.5
701.421	10280.5
701.678	10221.9
701.935	10190.9
702.192	10225.3
702.448	10202.6
702.705	10275.2
702.962	10295.3
703.219	10196.6
703.476	10158.6
703.732	10111.1
703.989	10198.5
704.246	10153.8
704.503	10121.9
704.759	10050.6
705.016	9959.12
705.273	10006.7
705.511	9882.23
705.768	9939.33
706.026	9791.66
706.283	9766.93
706.541	9745.05
706.798	9663.74
707.055	9627.13
707.313	9500.83
707.57	9577.53
707.827	9564.95
708.084	9534.04
708.342	9472.88
708.599	9486.19
708.856	9475.17
709.114	9541.32
709.371	9339.91
709.628	9371.27
709.885	9444.72
710.142	9329.87
710.4	9313.72
710.657	9332.11
710.914	9221.12
711.171	9230.52
711.428	9183.49
711.685	9225.57
711.942	9084
712.199	9047.5
712.456	9066.21
712.713	8985.47
712.97	8892.38
713.227	8885.36
713.484	8868.1
713.741	8812.26
713.998	8694.26
714.255	8678.09
714.512	8607.13
714.769	8583.21
715.026	8548.7
715.283	8500.09
715.54	8507.97
715.797	8456.83
716.054	8404.09
716.31	8308.4
716.567	8346.2
716.824	8287.31
717.081	8364.27
717.338	8264.12
717.594	8224.27
717.851	8196.77
718.108	8214.06
718.365	8101.19
718.621	8168.43
718.878	8061.97
719.135	8087.33
719.391	8020.14
719.648	7990.82
719.905	7948.32
720.161	7946.7
720.418	7861.33
720.675	7836.44
720.931	7809.19
721.188	7756.92
721.444	7712.82
721.701	7688.13
721.957	7640.6
722.214	7569.38
722.47	7553.84
722.727	7480.8
722.983	7507.52
723.24	7467.29
723.496	7442.17
723.753	7453.07
724.009	7392.21
724.265	7362.82
724.522	7305.22
724.778	7275.34
725.034	7336.55
725.291	7237.48
725.547	7218.21
725.803	7165.86
726.06	7191.75
726.316	7200.32
726.572	7094.45
726.828	7101.62
727.085	7051.56
727.341	7070.96
727.597	7024.26
727.853	7014.22
728.109	6930.09
728.366	6950.46
728.622	6820.86
728.878	6845.22
729.134	6793.03
729.39	6746.06
729.646	6682.1
729.902	6660.69
730.158	6616.73
730.414	6556.34
730.67	6447.57
730.926	6459.15
731.182	6522.42
731.438	6428.49
731.643	6388
731.9	6348.76
732.156	6347.31
732.413	6346.34
732.67	6317.11
732.927	6383.91
733.183	6337.15
733.44	6331.64
733.697	6358.41
733.953	6396.04
734.21	6466.19
734.466	6513.6
734.723	6469.39
734.98	6484.61
735.236	6560.39
735.493	6613.22
735.749	6674.53
736.006	6771.27
736.262	6893.53
736.519	7028.2
736.775	7047.08
737.032	7203.3
737.288	7332.64
737.544	7479.99
737.801	7585.79
738.057	7565.86
738.314	7670.72
738.57	7649.78
738.826	7567.5
739.083	7489.3
739.339	7355.78
739.595	7241.95
739.852	7013.06
740.108	6828.75
740.364	6747.17
740.621	6632.62
740.877	6506.8
741.133	6395.59
741.389	6259.08
741.645	6150.09
741.902	6013.71
742.158	5987.76
742.414	5943.94
742.67	5895.28
742.926	5757.86
743.182	5724.91
743.438	5711.34
743.694	5645.41
743.951	5565.36
744.207	5551.88
744.463	5494.3
744.719	5413.66
744.975	5414.6
745.231	5386.64
745.487	5315.97
745.743	5282.09
745.998	5293.88
746.254	5203.92
746.51	5209.01
746.766	5174.97
747.022	5097.32
747.278	5127.26
747.534	5095.86
747.79	5072.22
748.046	5086.42
748.301	5029.41
748.557	5051.6
748.813	4940.43
749.069	4980.97
749.324	4914.61
749.58	4929.03
749.836	4851.18
750.092	4857.36
750.347	4841.08
750.603	4752.69
750.859	4800.16
751.114	4754.24
751.37	4737.14
751.625	4684.59
751.881	4702.89
752.137	4652.76
752.392	4630.93
752.648	4606.04
752.903	4596.7
753.159	4545.28
753.414	4529.04
753.67	4500.37
753.925	4464.69
754.181	4481.26
754.436	4430.57
754.692	4343.78
754.947	4381.43
755.202	4309.82
755.458	4243.1
755.713	4334.69
755.968	4310.39
756.224	4191.57
756.479	4236.46
756.734	4199.7
756.99	4120.85
757.245	4165.43
757.5	4076.31
757.755	4121.63
757.968	4086.04
758.224	4036.34
758.48	4020.97
758.736	3968.99
758.992	4019.26
759.248	3933.98
759.504	3992.19
759.76	3890.61
760.016	3883.99
760.272	3889.97
760.528	3830.42
760.784	3808.57
761.04	3763.34
761.296	3708.11
761.552	3749.78
761.807	3697.97
762.063	3666.32
762.319	3700.09
762.575	3687.69
762.831	3623.19
763.086	3635.8
763.342	3658.4
763.598	3603.5
763.853	3514.77
764.109	3529.83
764.365	3502.6
764.621	3508.25
764.876	3497.69
765.132	3509.33
765.387	3449.32
765.643	3445.13
765.899	3439.52
766.154	3432.97
766.41	3363.88
766.665	3378.54
766.921	3296.72
767.176	3356.02
767.432	3257.41
767.687	3287.02
767.943	3225.96
768.198	3226.28
768.454	3209.08
768.709	3173.92
768.965	3121.8
769.22	3126.26
769.475	3131.62
769.731	3085.98
769.986	3070.11
770.242	3026.79
770.497	3015.08
770.752	2951.86
771.007	2998.6
771.263	2945.52
771.518	2933.4
771.773	2886.34
772.028	2870.61
772.284	2852.11
772.539	2829.73
772.794	2855.55
773.049	2746.83
773.304	2791.61
773.56	2757.63
773.815	2750.52
774.07	2673.11
774.325	2710.07
774.58	2658.8
774.835	2633.29
775.09	2633.26
775.345	2605.92
775.6	2615.49
775.855	2600.92
776.11	2561.56
776.365	2538.69
776.62	2525.63
776.875	2533.28
777.13	2469.7
777.385	2470.86
777.64	2437.71
777.895	2414.01
778.149	2411.27
778.404	2436.68
778.659	2359.72
778.914	2373.68
779.169	2339.91
779.424	2345.22
779.678	2318.55
779.933	2295.87
780.188	2279.46
780.442	2246.86
780.697	2205.53
780.952	2230.57
781.207	2224.45
781.461	2184.67
781.716	2179.78
781.97	2169.88
782.225	2126.19
782.48	2138.76
782.734	2112.9
782.989	2114.87
783.243	2093.25
783.498	2042.13
783.752	2039.83
784.007	2076.36
784.253	1996.18
784.509	2008.48
784.764	1995.83
785.019	1965.08
785.274	1976.15
785.53	1955.58
785.785	1970.6
786.04	1920.35
786.295	1893.44
786.551	1890.13
786.806	1890.1
787.061	1848.44
787.316	1854.39
787.571	1805.62
787.826	1808.57
788.081	1783.56
788.336	1793.51
788.591	1787.98
788.847	1790.65
789.102	1771.51
789.357	1755.89
789.612	1761.65
789.867	1725.63
790.122	1725.43
790.377	1706.26
790.632	1691.89
790.886	1677.23
791.141	1673.42
791.396	1665.16
791.651	1616.04
791.906	1646.59
792.161	1624.48
792.416	1600.97
792.671	1560.71
792.925	1575.17
793.18	1546.71
793.435	1576.72
793.69	1552.65
793.945	1523.86
794.199	1521.94
794.454	1541.84
794.709	1486.92
794.963	1492.85
795.218	1493.57
795.473	1457.72
795.727	1460.18
795.982	1448.64
796.237	1454.03
796.491	1415.79
796.746	1427.08
797	1402.91
797.255	1390.37
797.509	1389.08
797.764	1387.93
798.018	1344.56
798.273	1332.45
798.527	1320.4
798.782	1320.71
799.036	1323.03
799.291	1310.36
799.545	1316.22
799.8	1290.71
800.054	1298.59
800.308	1282.13
800.563	1266.02
800.817	1248.5
801.071	1252.94
801.326	1248.77
801.58	1224.22
801.834	1209.6
802.088	1215.33
802.343	1183.56
802.597	1172.93
802.851	1174.25
803.105	1179.37
803.359	1171.96
803.614	1151.84
803.868	1137.02
804.122	1118.61
804.376	1139.11
804.63	1105.9
804.884	1081.54
805.138	1087.76
805.392	1083.85
805.646	1068.45
805.9	1108.55
806.154	1080.02
806.408	1063.25
806.662	1055.6
806.916	1059.02
807.17	1053.27
807.424	1038.23
807.678	1043.15
807.932	1027.08
808.186	1011.37
808.439	1010.07
808.693	1032.28
808.947	992.241
809.201	981.014
809.455	973.966
809.708	971.557
809.962	972.207
810.183	942
810.438	958.132
810.693	959.768
810.947	931.148
811.202	931.852
811.456	933.009
811.711	904.544
811.965	912.718
812.22	900.042
812.474	908.096
812.729	880.511
812.983	898.444
813.237	875.245
813.492	883.035
813.746	868.672
814.001	859.003
814.255	860.243
814.509	848.775
814.764	844.802
815.018	828.943
815.272	819.794
815.526	839.182
815.781	806.099
816.035	816.017
816.289	831.777
816.543	795.534
816.798	778.139
817.052	771.812
817.306	795.149
817.56	783.239
817.814	780.086
818.068	769.651
818.323	776.958
818.577	750.241
818.831	740.769
819.085	754.716
819.339	751.943
819.593	724.405
819.847	723.663
820.101	740.987
820.355	709.86
820.609	721.284
820.863	719.724
821.117	711.918
821.371	694.315
821.624	683.048
821.878	695.402
822.132	673.367
822.386	663.006
822.64	686.528
822.894	668.131
823.148	649.934
823.401	650.273
823.655	638.054
823.909	658.287
824.163	641.603
824.416	641.001
824.67	652.149
824.924	663.574
825.177	624.427
825.431	634.917
825.685	627.966
825.938	601.538
826.192	612.638
826.446	625.479
826.699	602.369
826.953	601.982
827.206	594.901
827.46	576.011
827.713	565.06
827.967	588.208
828.22	587.859
828.474	562.818
828.727	571.471
828.981	573.816
829.234	572.288
829.488	562.133
829.741	554.826
829.994	566.09
830.248	555.294
830.501	565.809
830.754	542.117
831.008	512.437
831.261	540.815
831.514	546.752
831.767	526.681
832.021	530.393
832.274	523.968
832.527	541.022
832.78	510.246
833.034	528.784
833.287	517.456
833.54	508.734
833.793	496.665
834.046	509.561
834.299	500.781
834.552	488.307
834.805	494.311
835.058	490.902
835.311	481.28
835.564	481.076
835.817	496.573
836.07	507.415
836.314	476.001
836.568	460.105
836.821	448.334
837.075	483.277
837.329	459.91
837.583	473.659
837.836	465.325
838.09	440.033
838.344	451.356
838.598	447.314
838.851	446.033
839.105	449.545
839.359	451.998
839.612	426.116
839.866	447.767
840.119	437.957
840.373	424.455
840.627	424.534
840.88	440.19
841.134	430.711
841.387	430.411
841.641	435.522
841.894	409.484
842.148	417.516
842.401	406.086
842.655	408.331
842.908	400.859
843.161	396.166
843.415	422.328
843.668	391.784
843.922	404.211
844.175	402.226
844.428	402.369
844.682	394.925
844.935	401.554
845.188	376.588
845.442	376.707
845.695	400.123
845.948	374.838
846.201	378.379
846.455	375.924
846.708	379.835
846.961	378.55
847.214	377.145
847.467	376.011
847.72	363.597
847.973	365.915
848.227	354.629
848.48	359.472
848.733	348.426
848.986	363.273
849.239	358.174
849.492	351.686
849.745	333.219
849.998	334.599
850.251	334.478
850.504	354.058
850.757	341.862
851.01	337.098
851.263	334.646
851.515	327.139
851.768	334.379
852.021	326.047
852.274	327.522
852.527	325.802
852.78	320.385
853.032	331.029
853.285	324.494
853.538	312.683
853.791	322.86
854.043	318.453
854.296	306.599
854.549	312.898
854.801	298.255
855.054	314.108
855.307	292.458
855.559	298.391
855.812	304.455
856.065	292.398
856.317	300.557
856.57	311.734
856.822	303.626
857.075	287.36
857.327	293.041
857.58	295.786
857.832	298.606
858.085	280.178
858.337	283.844
858.589	286.796
858.842	297.544
859.094	280.949
859.347	280.828
859.599	288.329
859.851	283.336
860.104	279.831
860.356	272.063
860.608	275.423
860.861	251.489
861.113	268.449
861.365	272.717
861.617	271.083
861.869	263.63
862.112	264.008
862.365	252.07
862.618	250.222
862.871	244.497
863.124	258.273
863.377	260.007
863.63	259.524
863.883	268.995
864.136	254.556
864.389	259.377
864.642	259.337
864.894	249.493
865.147	239.103
865.4	245.219
865.653	249.526
865.906	240
866.159	246.253
866.412	243.642
866.664	252.301
866.917	234.77
867.17	243.132
867.423	244.91
867.675	241.703
867.928	234.94
868.181	227.593
868.433	240.919
868.686	227.965
868.939	224.687
869.191	230.358
869.444	233.495
869.697	228.022
869.949	219.42
870.202	207.818
870.454	229.265
870.707	229.429
870.959	217.978
871.212	224.377
871.464	214.893
871.717	218.743
871.969	220.111
872.222	225.242
872.474	203.635
872.727	213.454
872.979	212.152
873.231	210.099
873.484	216.29
873.736	206.06
873.988	206.113
874.241	201.337
874.493	197.118
874.745	213.793
874.998	201.289
875.25	192.496
875.502	199.628
875.754	195.48
876.006	208.386
876.259	193.936
876.511	188.744
876.763	196.959
877.015	194.732
877.267	193.941
877.519	186.357
877.771	200.412
878.023	195.425
878.276	192.419
878.528	187.482
878.78	191.529
879.031	185.232
879.284	180.208
879.535	183.024
879.787	184.832
880.039	183.066
880.291	180.902
880.543	177.166
880.795	181.082
881.047	169.197
881.299	178.158
881.551	172.498
881.802	177.455
882.054	170.766
882.306	178.942
882.558	173.535
882.809	168.195
883.061	175.294
883.313	169.453
883.565	173.03
883.816	165.193
884.068	164
884.319	161.196
884.571	158.642
884.823	159.317
885.074	163.654
885.326	159.568
885.577	167.78
885.829	162.69
886.08	147.182
886.332	158.907
886.583	150.011
886.835	149.668
887.086	159.505
887.338	167.367
887.589	152.035
887.841	140.765
888.044	159.956
888.296	151.916
888.548	155.854
888.8	147.796
889.053	150.654
889.305	143.953
889.557	150.689
889.809	155.827
890.061	148.359
890.313	129.01
890.566	153.112
890.818	140.123
891.07	138.832
891.322	140.498
891.574	135.319
891.826	127.212
892.078	133.058
892.33	136.477
892.582	132.593
892.834	138.872
893.086	136.089
893.338	141.648
893.59	135.58
893.842	129.252
894.094	135.014
894.346	132.924
894.597	132.048
894.849	136.96
895.101	137.056
895.353	132.214
895.605	124
895.857	125.208
896.108	123.761
896.36	124.676
896.612	130.152
896.864	122.681
897.115	131
897.367	124.599
897.619	130.164
897.87	121.767
898.122	127.245
898.374	125.206
898.625	124.619
898.877	120.701
899.128	120.629
899.38	122.331
899.631	118.429
899.883	121.092
899.984	120.259