File: PL_Fatia_SCD_021223_02.txt
#Acq. time (s)=	3
#Accumulations=	2
#Range (nm)=	520...900
#Windows=	16
#Auto scanning=	On
#Autofocus=	Off
#AutoExposure=	Off
#Spike filter=	Multiple accum.
#Delay time (s)=	0
#Binning=	1
#Readout mode=	Signal
#DeNoise=	Off
#ICS correction=	Off
#Dark correction=	Off
#Inst. Process=	Off
#Detector temperature (°C)=	-59.98
#Instrument=	LabRAM HR Evol
#Detector=	Syncerity OE
#Objective=	x50_VIS
#Grating=	600 (500nm)
#ND Filter=	10%
#Laser=	514nm_Edge
#Hole=	199.981
#Range=	Auto
#StageXY=	Marzhauser
#StageZ=	Marzhauser
#X (µm)=	1452.2
#Y (µm)=	-1092.6
#Z (µm)=	-216.2
#Full time(mm:ss)=	2:42
#Project=
#Sample=
#Site=
#Title=	PL_Fatia_SCD_021223
#Remark=
#Date=	18.12.2023 18:01
#Acquired=	18.12.2023 18:01:03
520.042	66
520.304	61.8463
520.565	56.8219
520.827	61.7209
521.089	64.6047
521.351	64.5523
521.612	56.3912
521.874	56.7835
522.136	60.5256
522.397	55.2561
522.659	55.2747
522.921	55.8265
523.182	62.4715
523.444	57.3353
523.705	52.8231
523.967	58
524.229	62.8033
524.49	54.4144
524.752	54.7835
525.013	61.638
525.275	59.7637
525.536	56.752
525.798	56.4563
526.059	54.3935
526.321	60
526.582	58.4435
526.844	55.1049
527.105	55
527.367	53.6807
527.628	53.6597
527.889	55.958
528.151	56.7016
528.412	57.4435
528.674	49.6026
528.935	59.2354
529.196	58.7855
529.458	59.8065
529.719	57.5175
529.98	57
530.242	60.1282
530.503	49.7902
530.764	54.0839
531.025	57.9371
531.287	59.5198
531.548	51.021
531.809	61.4988
532.07	57.9767
532.332	61.0466
532.593	56.2704
532.854	65.2727
533.115	63.5571
533.376	60.1084
533.638	55.2585
533.899	59.6555
534.16	60.52
534.421	63.1671
534.682	58.3339
534.943	68.5447
535.204	67.6199
535.465	62.8299
535.726	61.9168
535.987	63.1427
536.248	63.9603
536.509	62.8703
536.77	63.7442
537.031	64.9374
537.292	67.775
537.553	63.0724
537.814	64.7052
538.075	73.697
538.336	72.091
538.597	64.3342
538.858	65.9782
539.119	76.0379
539.38	66.1303
539.641	66.5526
539.901	70.5108
540.162	71.5774
540.423	70.1785
540.684	74.9041
540.945	75.299
541.205	78.4129
541.466	67.9079
541.727	85.4978
541.988	76.0107
542.248	77.2296
542.509	75.8422
542.77	81.5014
543.031	80.8278
543.291	81.1232
543.552	75.6985
543.813	89.3871
544.073	92.0921
544.334	85.5183
544.594	92.4703
544.855	82.769
545.116	89.286
545.376	81.4133
545.637	83.6556
545.897	86.0632
546.158	103.387
546.418	93.4021
546.679	103.741
546.898	97.9416
547.159	104.056
547.42	90.4526
547.681	113.678
547.942	111.616
548.203	109.78
548.464	106.396
548.725	110.43
548.987	115.14
549.248	124.233
549.509	116.115
549.77	121.466
550.031	131.318
550.292	136.978
550.553	139.294
550.814	147.125
551.075	147.957
551.336	157.77
551.597	161.788
551.858	193.262
552.119	211.333
552.38	481.279
552.641	9050.69
552.901	760.484
553.162	247.111
553.423	189.215
553.684	179.782
553.945	155.656
554.206	173.335
554.467	187.459
554.727	186.089
554.988	182.916
555.249	185.574
555.51	194.085
555.771	195.096
556.031	198.036
556.292	200.582
556.553	212.439
556.814	212.345
557.074	221.54
557.335	225.858
557.596	231.866
557.856	229.347
558.117	236.99
558.378	231.34
558.638	242.413
558.899	240.555
559.16	244.659
559.42	248.507
559.681	260.211
559.941	263.871
560.202	271.639
560.463	261.746
560.723	269.472
560.984	291.921
561.244	294.389
561.505	302.55
561.765	301.361
562.026	311.825
562.286	311.473
562.547	318.012
562.807	328.903
563.067	341.392
563.328	348.433
563.588	352.177
563.849	358.905
564.109	364.028
564.369	352.648
564.63	381.836
564.89	393.854
565.15	370.303
565.411	394.424
565.671	398.755
565.931	417.793
566.192	404.877
566.452	427.69
566.712	439.057
566.972	445.904
567.232	448.044
567.493	458.353
567.753	464.856
568.013	490.859
568.273	500.613
568.533	501.485
568.794	502.496
569.054	515.099
569.314	510.215
569.574	523.4
569.834	549.662
570.094	561.162
570.354	573.867
570.614	589.229
570.874	620.418
571.134	634.022
571.394	689.278
571.654	702.159
571.914	743.382
572.174	774.091
572.434	805.836
572.694	845.053
572.954	927.669
573.214	992.206
573.459	1047.47
573.719	1121.38
573.98	1181.06
574.241	1246.64
574.501	1412.45
574.762	1499.11
575.022	1651.53
575.283	1803.28
575.543	1861.68
575.804	1931.75
576.064	1936.11
576.325	1941.32
576.585	1855.84
576.846	1775.98
577.106	1667.36
577.366	1588.14
577.627	1475.54
577.887	1430.2
578.148	1372.03
578.408	1293.93
578.668	1251.84
578.929	1265.38
579.189	1211.49
579.449	1221.62
579.71	1205.36
579.97	1165.21
580.23	1195.67
580.49	1190.52
580.751	1179.51
581.011	1205.45
581.271	1192.66
581.531	1224.92
581.792	1199.88
582.052	1234.79
582.312	1250.65
582.572	1271.8
582.832	1251.75
583.092	1300.57
583.353	1284.95
583.613	1345.66
583.873	1327.51
584.133	1360.31
584.393	1372.23
584.653	1400.86
584.913	1456.18
585.173	1423.05
585.433	1465.98
585.693	1517.3
585.953	1571.57
586.213	1546.23
586.473	1582.46
586.733	1589.6
586.993	1607.04
587.253	1613.72
587.513	1631.19
587.773	1606.25
588.033	1618.24
588.293	1644.4
588.552	1637.07
588.812	1631.73
589.072	1695.86
589.332	1652.73
589.592	1671.03
589.852	1688.07
590.112	1674.18
590.371	1680.19
590.631	1641.77
590.891	1718.25
591.151	1672.68
591.41	1662.43
591.67	1653.36
591.93	1660.84
592.189	1670.54
592.449	1641.5
592.709	1655.96
592.968	1686.66
593.228	1665.87
593.488	1698.97
593.747	1656.06
594.007	1651.4
594.266	1652.76
594.526	1686.31
594.786	1701.8
595.045	1725.68
595.305	1709.25
595.564	1746.36
595.824	1753.26
596.083	1790.64
596.343	1798.31
596.602	1822.86
596.862	1849.84
597.121	1881.01
597.38	1867.6
597.64	1850.03
597.899	1907.23
598.159	1937.82
598.418	1910.37
598.677	1941.7
598.937	1944.43
599.196	1964.54
599.455	1938.47
599.715	1953.29
599.959	1979.69
600.219	1999
600.479	1967.25
600.738	1932.52
600.998	1952.66
601.258	1947.29
601.518	1970.22
601.778	1977.65
602.038	2019.18
602.298	1973
602.558	1973.68
602.818	2012.8
603.078	2015.57
603.337	2033.82
603.597	2043.64
603.857	2027.5
604.117	2026.88
604.377	2039.44
604.636	2111.32
604.896	2101.44
605.156	2039.52
605.416	2054.47
605.675	2056.24
605.935	2066.67
606.195	2075.57
606.455	2080.54
606.714	2074.86
606.974	2069.98
607.234	2064.67
607.493	2056.26
607.753	2107.41
608.012	2079.83
608.272	2071.71
608.532	2122.13
608.791	2131.39
609.051	2127.28
609.31	2153.06
609.57	2159.7
609.829	2168.68
610.089	2174.05
610.348	2171.84
610.608	2185.18
610.867	2217.5
611.127	2233.78
611.386	2252.75
611.646	2228.97
611.905	2229.04
612.164	2253.15
612.424	2271.85
612.683	2287.71
612.943	2287.75
613.202	2293
613.461	2323.72
613.721	2320.77
613.98	2332.04
614.239	2363.68
614.498	2410.65
614.758	2400.86
615.017	2434.59
615.276	2444.53
615.535	2478.64
615.795	2499.99
616.054	2486.86
616.313	2506.65
616.572	2535.73
616.831	2571.82
617.091	2539.55
617.35	2591.92
617.609	2620.69
617.868	2624.63
618.127	2640.56
618.386	2662.62
618.645	2666.29
618.904	2715.81
619.163	2723.33
619.422	2779.96
619.681	2760.04
619.94	2790.06
620.199	2815.43
620.458	2824.39
620.717	2839.83
620.976	2857.45
621.235	2906.77
621.494	2879.64
621.753	2873.78
622.012	2865.93
622.271	2888.41
622.53	2903.12
622.788	2967.36
623.047	2915.36
623.306	2896.83
623.565	2863.82
623.824	2917.8
624.082	2911.41
624.341	2966.09
624.6	3003.67
624.859	2942.46
625.117	2927.59
625.376	2981.57
625.635	2986.48
625.893	2999.64
626.152	3030.84
626.368	3023.85
626.627	3065.69
626.887	3077.09
627.146	3079.61
627.405	3053.49
627.665	3118.15
627.924	3132.84
628.183	3136.21
628.443	3155.65
628.702	3113.78
628.961	3163.23
629.22	3215.4
629.479	3255.9
629.739	3177.6
629.998	3198.24
630.257	3262.25
630.516	3298.11
630.776	3309.05
631.035	3314.71
631.294	3345.02
631.553	3376.01
631.812	3367.35
632.071	3412.13
632.33	3441.16
632.589	3443.05
632.848	3499.4
633.107	3463.63
633.366	3559.66
633.625	3562.53
633.885	3625.82
634.143	3590.07
634.403	3652.74
634.661	3730.1
634.92	3713.5
635.179	3774.4
635.438	3824.07
635.697	3878.37
635.956	3974.58
636.215	4062.39
636.474	4168.88
636.733	4297.29
636.992	4442.43
637.25	4662.79
637.509	4874.11
637.768	5079.45
638.027	5248.42
638.286	5366.38
638.544	5397.28
638.803	5416.65
639.062	5338.71
639.321	5227.93
639.579	5107.57
639.838	5001.32
640.097	4819.62
640.356	4733.94
640.614	4718.95
640.873	4626.61
641.131	4616.22
641.39	4553.8
641.649	4577.65
641.907	4547.44
642.166	4542.16
642.424	4508.34
642.683	4553.24
642.942	4502.62
643.2	4540
643.459	4556.19
643.717	4474.91
643.976	4561.15
644.234	4591.79
644.493	4594.08
644.751	4575.15
645.009	4607.65
645.268	4701.88
645.526	4632.74
645.785	4650.87
646.043	4679.55
646.301	4700.38
646.56	4755.34
646.818	4706.73
647.076	4781.42
647.335	4798.99
647.593	4741.58
647.851	4744.44
648.109	4829.17
648.368	4835.88
648.626	4820.02
648.884	4907.39
649.142	4939.71
649.401	4988.88
649.659	5043.12
649.917	5013.36
650.175	5069.42
650.433	5099.87
650.691	5186.73
650.949	5183.06
651.208	5202.27
651.466	5225.83
651.724	5245.56
651.982	5285.65
652.24	5272.39
652.498	5368.21
652.756	5431.79
652.979	5464.46
653.238	5407.21
653.497	5501.29
653.755	5566.31
654.014	5624.02
654.273	5668.83
654.531	5714.31
654.79	5779.14
655.049	5783.66
655.307	5868.29
655.566	5811.04
655.824	5886.82
656.083	6063.17
656.342	6062.92
656.6	6164.36
656.859	6163.48
657.117	6278.64
657.376	6350.47
657.634	6354.01
657.893	6460.18
658.151	6428.55
658.41	6502.76
658.668	6566.13
658.927	6514.24
659.185	6561.95
659.443	6651.3
659.702	6644.48
659.96	6667.34
660.219	6629.99
660.477	6727.41
660.735	6678.8
660.994	6742.3
661.252	6670.62
661.51	6701.84
661.768	6706.21
662.027	6690.3
662.285	6712.25
662.543	6656.47
662.802	6692.34
663.06	6755.78
663.318	6757.7
663.576	6733.4
663.834	6721.52
664.093	6760.31
664.351	6729.37
664.609	6737.51
664.867	6689.61
665.125	6735.06
665.383	6712.82
665.641	6738.5
665.899	6706.84
666.157	6687.48
666.415	6729.08
666.673	6662.58
666.931	6705.03
667.189	6655.1
667.447	6642.33
667.705	6652.74
667.963	6645.64
668.221	6661.76
668.479	6657.15
668.737	6665.84
668.995	6663.74
669.253	6651.62
669.511	6670.1
669.769	6694.99
670.027	6643.56
670.284	6651.07
670.542	6621.39
670.8	6668.66
671.058	6616.4
671.316	6584.26
671.573	6690.94
671.831	6677.82
672.089	6701.57
672.347	6713.36
672.604	6695.59
672.862	6738.65
673.12	6759.1
673.377	6796.56
673.635	6837.76
673.893	6859.29
674.15	6884.79
674.408	6912.79
674.665	6948.1
674.923	6973.31
675.18	7005.89
675.438	7048.01
675.696	7014.28
675.953	7077.81
676.211	7128.21
676.468	7136.23
676.726	7131.21
676.983	7140.46
677.24	7104.15
677.498	7140.94
677.755	7179.08
678.013	7171.85
678.27	7135.51
678.527	7149.12
678.785	7178.47
679.042	7145.84
679.277	7131.22
679.535	7104.14
679.793	7167.83
680.051	7218.42
680.309	7285.01
680.567	7174.33
680.825	7286.64
681.083	7323.21
681.341	7360.74
681.599	7282.79
681.857	7361.85
682.115	7277.07
682.373	7319.76
682.631	7448.93
682.889	7424.77
683.146	7448.26
683.404	7454.12
683.662	7385.87
683.92	7470.3
684.178	7450.02
684.436	7406.86
684.694	7334.84
684.951	7337.15
685.209	7351.92
685.467	7393.74
685.725	7326.04
685.982	7343.83
686.24	7300.97
686.498	7281.96
686.756	7287.06
687.013	7224.94
687.271	7246.99
687.529	7225
687.786	7275.99
688.044	7244.98
688.302	7275.64
688.559	7263.04
688.817	7279.12
689.074	7276.76
689.332	7265.62
689.589	7232.41
689.847	7165.91
690.104	7193.84
690.362	7142.89
690.619	7197.49
690.877	7196.53
691.134	7106.59
691.392	7112.43
691.649	7083.85
691.907	7033.75
692.164	7077.24
692.421	7007.23
692.679	7035.55
692.936	6995.21
693.194	6970.24
693.451	6923.95
693.708	6900.34
693.966	6908.38
694.223	6907.85
694.48	6935.95
694.737	6859.08
694.995	6937.79
695.252	6873.71
695.509	6855.25
695.766	6871.86
696.023	6843.47
696.281	6770.96
696.538	6708.5
696.795	6766.99
697.052	6721.09
697.309	6706.84
697.566	6686.42
697.823	6646.28
698.08	6683.08
698.338	6656.39
698.595	6567.69
698.852	6542.03
699.109	6542.59
699.366	6531.19
699.623	6518.14
699.88	6492.08
700.137	6474.02
700.393	6454.48
700.65	6404.6
700.907	6411.81
701.164	6457
701.421	6469.2
701.678	6474.58
701.935	6396.05
702.192	6419.06
702.448	6409.36
702.705	6436.33
702.962	6477.76
703.219	6460.52
703.476	6453
703.732	6417.97
703.989	6412.7
704.246	6339.44
704.503	6389.95
704.759	6319.22
705.016	6323.75
705.273	6279.67
705.511	6256.16
705.768	6181.61
706.026	6206.73
706.283	6196.99
706.541	6139.85
706.798	6154.75
707.055	6152.52
707.313	6027.4
707.57	6092.87
707.827	6059.54
708.084	6035.75
708.342	6020.6
708.599	5868.03
708.856	6013.01
709.114	5925.07
709.371	6040.15
709.628	5922.82
709.885	5929.38
710.142	5920.22
710.4	5858.96
710.657	5936.53
710.914	5901.46
711.171	5850.55
711.428	5836.14
711.685	5815.52
711.942	5771.8
712.199	5736.28
712.456	5740.57
712.713	5763.11
712.97	5689.5
713.227	5612.78
713.484	5577.42
713.741	5566.31
713.998	5541.84
714.255	5497.65
714.512	5464.07
714.769	5393.63
715.026	5384.68
715.283	5385.3
715.54	5417.99
715.797	5337.95
716.054	5300.62
716.31	5296.61
716.567	5333.58
716.824	5228.15
717.081	5247.51
717.338	5251.35
717.594	5216.35
717.851	5205.82
718.108	5199.25
718.365	5133.14
718.621	5157.83
718.878	5084.94
719.135	5073.7
719.391	5063.76
719.648	5061.52
719.905	5021.77
720.161	5021.78
720.418	5037.39
720.675	5016.76
720.931	4957.3
721.188	4910.23
721.444	4900.21
721.701	4880.84
721.957	4816.48
722.214	4772.97
722.47	4764.95
722.727	4731.78
722.983	4735.12
723.24	4717.08
723.496	4677.3
723.753	4642.04
724.009	4630.08
724.265	4633.89
724.522	4587.48
724.778	4574.42
725.034	4582.19
725.291	4571.91
725.547	4513.37
725.803	4529.52
726.06	4502.14
726.316	4461.76
726.572	4424.91
726.828	4393.05
727.085	4397.96
727.341	4377.11
727.597	4337.65
727.853	4318.32
728.109	4311.45
728.366	4298.86
728.622	4233.72
728.878	4230.76
729.134	4227.04
729.39	4206.48
729.646	4127.62
729.902	4102.13
730.158	4074.43
730.414	4052.25
730.67	3965.02
730.926	3925.73
731.182	3913.09
731.438	3951.05
731.643	3806
731.9	3912.2
732.156	3887.52
732.413	3846.86
732.67	3875.19
732.927	3819.33
733.183	3773.46
733.44	3821.41
733.697	3795.48
733.953	3777.83
734.21	3764.14
734.466	3796.66
734.723	3759.51
734.98	3706.31
735.236	3686.69
735.493	3740.26
735.749	3716.13
736.006	3758.87
736.262	3666.77
736.519	3659.65
736.775	3649.1
737.032	3647.62
737.288	3657.68
737.544	3664.97
737.801	3636.05
738.057	3657.08
738.314	3591.24
738.57	3628.99
738.826	3600.62
739.083	3614.58
739.339	3611.52
739.595	3614
739.852	3590.17
740.108	3535.62
740.364	3504.96
740.621	3482.7
740.877	3510.69
741.133	3458.26
741.389	3432.51
741.645	3408.54
741.902	3447.98
742.158	3416.39
742.414	3427.39
742.67	3382.57
742.926	3357.53
743.182	3357.78
743.438	3342.76
743.694	3306.35
743.951	3328.39
744.207	3301.29
744.463	3264.63
744.719	3287.76
744.975	3263.7
745.231	3251.37
745.487	3213.08
745.743	3207.49
745.998	3174.5
746.254	3168.09
746.51	3175.09
746.766	3160.35
747.022	3148.21
747.278	3104.16
747.534	3121.19
747.79	3105.88
748.046	3097.46
748.301	3071.16
748.557	3073.07
748.813	3078.2
749.069	3053.8
749.324	3024.45
749.58	3014.32
749.836	3010.91
750.092	2993.14
750.347	2934.07
750.603	2953.08
750.859	2954.74
751.114	2920.72
751.37	2945.33
751.625	2915.59
751.881	2909.81
752.137	2900.66
752.392	2830.23
752.648	2855.75
752.903	2834.45
753.159	2772.93
753.414	2794.87
753.67	2801.3
753.925	2718.38
754.181	2760.25
754.436	2734.98
754.692	2701.26
754.947	2668.49
755.202	2718.6
755.458	2651.3
755.713	2631.19
755.968	2677.2
756.224	2617.14
756.479	2635.45
756.734	2549.47
756.99	2596.41
757.245	2583.52
757.5	2526.05
757.755	2565.5
757.968	2543.99
758.224	2456.16
758.48	2507.43
758.736	2482.1
758.992	2443.35
759.248	2464.25
759.504	2512.43
759.76	2435.79
760.016	2429.26
760.272	2406.1
760.528	2362.67
760.784	2379.28
761.04	2339.59
761.296	2314.17
761.552	2294.54
761.807	2310.82
762.063	2279.06
762.319	2279.56
762.575	2261.37
762.831	2251.65
763.086	2237.45
763.342	2269.67
763.598	2202.21
763.853	2182.06
764.109	2196.82
764.365	2165.29
764.621	2145.54
764.876	2171.61
765.132	2150.15
765.387	2104.08
765.643	2171.22
765.899	2115.11
766.154	2052.85
766.41	2108.98
766.665	2061.47
766.921	2066.52
767.176	2053.71
767.432	2022.17
767.687	2047.21
767.943	2011.71
768.198	2001.59
768.454	1977.01
768.709	1983.11
768.965	1953.73
769.22	1969.2
769.475	1939.04
769.731	1939.93
769.986	1887.65
770.242	1869.74
770.497	1872.56
770.752	1848.09
771.007	1851.02
771.263	1826.98
771.518	1805.81
771.773	1823.8
772.028	1808.43
772.284	1786.23
772.539	1773.59
772.794	1798.51
773.049	1765.64
773.304	1761.22
773.56	1728.24
773.815	1702.27
774.07	1733.92
774.325	1683.63
774.58	1656.95
774.835	1660.62
775.09	1650.05
775.345	1624.17
775.6	1602.38
775.855	1608.49
776.11	1594.16
776.365	1588.26
776.62	1582.89
776.875	1567.37
777.13	1546.87
777.385	1553.46
777.64	1537.05
777.895	1529.64
778.149	1501.56
778.404	1509.56
778.659	1484.94
778.914	1507.64
779.169	1452
779.424	1460.66
779.678	1450.85
779.933	1462.19
780.188	1421.34
780.442	1446.69
780.697	1439.19
780.952	1425.21
781.207	1398.11
781.461	1399.44
781.716	1378.5
781.97	1380.98
782.225	1352.89
782.48	1357.42
782.734	1373.14
782.989	1350.42
783.243	1325.18
783.498	1299.99
783.752	1301.96
784.007	1300.06
784.253	1301.86
784.509	1266.11
784.764	1262.66
785.019	1256.14
785.274	1274.9
785.53	1235.96
785.785	1236.86
786.04	1206.14
786.295	1222
786.551	1221.54
786.806	1200.11
787.061	1189.19
787.316	1175.73
787.571	1181.47
787.826	1165.99
788.081	1138.14
788.336	1111.73
788.591	1125.13
788.847	1115.82
789.102	1135.25
789.357	1122.9
789.612	1099.55
789.867	1074.84
790.122	1095.67
790.377	1079.22
790.632	1083.59
790.886	1063.41
791.141	1081
791.396	1031.86
791.651	1045.72
791.906	1023.74
792.161	1041.4
792.416	998.501
792.671	999.789
792.925	1016.98
793.18	995.211
793.435	999.173
793.69	968.805
793.945	977.758
794.199	982.151
794.454	959.178
794.709	939.828
794.963	960.007
795.218	923.573
795.473	923.555
795.727	931.467
795.982	904.381
796.237	889.462
796.491	915.09
796.746	895.829
797	879.012
797.255	877.115
797.509	882.379
797.764	860.145
798.018	856.955
798.273	882.803
798.527	858.475
798.782	823.84
799.036	837.49
799.291	836.63
799.545	838.278
799.8	828.13
800.054	809.23
800.308	794.911
800.563	803.012
800.817	785.345
801.071	787.864
801.326	769.723
801.58	777.226
801.834	777.679
802.088	763.138
802.343	760.963
802.597	758.543
802.851	752.829
803.105	731.49
803.359	744.154
803.614	720.886
803.868	747.305
804.122	734.899
804.376	742.335
804.63	720.684
804.884	703.659
805.138	689.944
805.392	711.748
805.646	699.632
805.9	697.465
806.154	669.394
806.408	673.698
806.662	677.796
806.916	671.265
807.17	655.37
807.424	670.81
807.678	652.296
807.932	647.64
808.186	638.541
808.439	630.66
808.693	658.876
808.947	634.315
809.201	631.049
809.455	613.023
809.708	628.084
809.962	622.914
810.183	618
810.438	588.198
810.693	633.272
810.947	584.669
811.202	594.199
811.456	620.462
811.711	615.076
811.965	594.463
812.22	576.999
812.474	573.63
812.729	577.185
812.983	570.326
813.237	562.289
813.492	569.45
813.746	555.567
814.001	551.54
814.255	516.389
814.509	552.313
814.764	527.666
815.018	538.885
815.272	538.342
815.526	530.75
815.781	526.36
816.035	527.296
816.289	508.562
816.543	519.64
816.798	520.107
817.052	497.721
817.306	493.235
817.56	517.095
817.814	500.647
818.068	488.745
818.323	495.246
818.577	486.767
818.831	493.011
819.085	479.542
819.339	477.901
819.593	482.001
819.847	464.969
820.101	471.418
820.355	477.282
820.609	468.945
820.863	456.756
821.117	461.121
821.371	452.294
821.624	444.759
821.878	432.48
822.132	452.658
822.386	449.887
822.64	424.041
822.894	435.452
823.148	433.785
823.401	436.632
823.655	428.104
823.909	435.97
824.163	413.516
824.416	406.678
824.67	402.74
824.924	405.818
825.177	411.965
825.431	399.457
825.685	397.126
825.938	391.303
826.192	414.667
826.446	388.717
826.699	383.009
826.953	395.092
827.206	398.401
827.46	393.671
827.713	396.038
827.967	387.457
828.22	379.807
828.474	379.779
828.727	381.528
828.981	374.123
829.234	368.051
829.488	370.809
829.741	368.11
829.994	362.918
830.248	358.462
830.501	371.109
830.754	360.144
831.008	352.757
831.261	360.214
831.514	340.889
831.767	341.828
832.021	345.351
832.274	349.379
832.527	340.084
832.78	333.375
833.034	344.537
833.287	337.337
833.54	330.156
833.793	349.868
834.046	329.762
834.299	325.444
834.552	329.071
834.805	332.31
835.058	333.395
835.311	344.062
835.564	323.588
835.817	316.974
836.07	316.085
836.314	296.087
836.568	325.795
836.821	327.71
837.075	311.819
837.329	328.693
837.583	310.26
837.836	311.851
838.09	308.657
838.344	305.985
838.598	307.62
838.851	293.072
839.105	299.851
839.359	308.433
839.612	303.811
839.866	291.235
840.119	282.781
840.373	294.319
840.627	284.788
840.88	268.162
841.134	281.891
841.387	290.022
841.641	291.437
841.894	287.12
842.148	285.078
842.401	274.677
842.655	278.266
842.908	274.455
843.161	275.787
843.415	286.652
843.668	263.62
843.922	258.861
844.175	265.065
844.428	257.039
844.682	239.137
844.935	265.774
845.188	251.648
845.442	266.372
845.695	247.11
845.948	259.872
846.201	253.316
846.455	245.763
846.708	249.805
846.961	250.844
847.214	254.227
847.467	251.458
847.72	247.621
847.973	250.537
848.227	235.034
848.48	244.243
848.733	237.602
848.986	249.67
849.239	234.177
849.492	229.796
849.745	242.796
849.998	237.696
850.251	227.884
850.504	233.788
850.757	240.57
851.01	226.796
851.263	226.43
851.515	225.446
851.768	224.904
852.021	219.417
852.274	219.869
852.527	219.291
852.78	220.678
853.032	222.192
853.285	212.634
853.538	215.902
853.791	223.445
854.043	215.357
854.296	224.642
854.549	224.164
854.801	224.575
855.054	207.904
855.307	209.127
855.559	218.398
855.812	220.838
856.065	222.222
856.317	209.186
856.57	215.114
856.822	210.521
857.075	202.535
857.327	206.77
857.58	202.7
857.832	195.485
858.085	195.757
858.337	199.049
858.589	194.729
858.842	191.986
859.094	195.806
859.347	187.955
859.599	192.561
859.851	183.419
860.104	192.173
860.356	196.529
860.608	189.879
860.861	183.727
861.113	186.661
861.365	191.943
861.617	177.073
861.869	178.85
862.112	176.012
862.365	180.091
862.618	185.973
862.871	174.009
863.124	185.457
863.377	183.246
863.63	172.012
863.883	177.816
864.136	173.748
864.389	173.38
864.642	171.602
864.894	174.33
865.147	183.693
865.4	178.155
865.653	165.374
865.906	171.545
866.159	169.99
866.412	171
866.664	160.079
866.917	179.205
867.17	162.417
867.423	156.622
867.675	162.124
867.928	161.749
868.181	163.773
868.433	165.521
868.686	159.996
868.939	161.803
869.191	149.714
869.444	153.088
869.697	152.913
869.949	164.725
870.202	149.26
870.454	146.542
870.707	142.494
870.959	157.072
871.212	149.27
871.464	144.116
871.717	138.834
871.969	142.233
872.222	149.264
872.474	155.533
872.727	143.911
872.979	143.62
873.231	150.095
873.484	144.788
873.736	148.016
873.988	135.178
874.241	141.372
874.493	132.836
874.745	150.382
874.998	136.725
875.25	138.354
875.502	137.221
875.754	138.156
876.006	137.919
876.259	138.407
876.511	135.857
876.763	130.828
877.015	138.865
877.267	124.634
877.519	141.905
877.771	136.376
878.023	132.566
878.276	125.805
878.528	137.848
878.78	125.809
879.031	125.849
879.284	126.483
879.535	131.584
879.787	126.736
880.039	130.983
880.291	137.825
880.543	125.184
880.795	132.98
881.047	126.237
881.299	135.452
881.551	121.789
881.802	115.235
882.054	118.611
882.306	128.684
882.558	115.586
882.809	121.116
883.061	118.54
883.313	115.741
883.565	114.31
883.816	122.485
884.068	120.472
884.319	119.788
884.571	120.019
884.823	116.315
885.074	115.028
885.326	119.517
885.577	106.55
885.829	117.438
886.08	109.489
886.332	108.508
886.583	112.801
886.835	112.971
887.086	108.255
887.338	113.268
887.589	106
887.841	94.2865
888.044	111.935
888.296	106.251
888.548	98.7886
888.8	111.538
889.053	100.719
889.305	100.544
889.557	106.45
889.809	111.53
890.061	99.0699
890.313	100.805
890.566	106
890.818	109.471
891.07	101.473
891.322	101.472
891.574	102.142
891.826	94.7481
892.078	110.553
892.33	98.9922
892.582	97.0408
892.834	104.97
893.086	102.624
893.338	92.2422
893.59	96.5362
893.842	102.167
894.094	97.9855
894.346	99.0169
894.597	91.0966
894.849	93.279
895.101	92.8889
895.353	96.7146
895.605	87.087
895.857	93.8961
896.108	90.4456
896.36	88.4058
896.612	92.9348
896.864	86.8404
897.115	86.1087
897.367	81.2005
897.619	90.9178
897.87	96.133
898.122	90.2491
898.374	90.9408
898.625	88.873
898.877	87.5973
899.128	78.5151
899.38	91.3313
899.631	78
899.883	85.0919
899.984	83.1114