File: PL_M2_011123_01.txt
#Acq. time (s)=	5
#Accumulations=	2
#Range (nm)=	520...900
#Windows=	8
#Auto scanning=	Off
#Autofocus=	Off
#AutoExposure=	Off
#Spike filter=	Multiple accum.
#Delay time (s)=	0
#Binning=	1
#Readout mode=	Signal
#DeNoise=	Off
#ICS correction=	On
#Dark correction=	Off
#Inst. Process=	Off
#Detector temperature (°C)=	-59.98
#Instrument=	LabRAM HR Evol
#Detector=	Syncerity OE
#Objective=	x50_VIS
#Grating=	600 (500nm)
#ND Filter=	10%
#Laser=	514nm_Edge
#Hole=	199.981
#Range=	Auto
#StageXY=	Marzhauser
#StageZ=	Marzhauser
#X (µm)=	18192.9
#Y (µm)=	3611.8
#Z (µm)=	-57.4
#Full time(mm:ss)=	2:05
#Project=
#Sample=
#Site=
#Title=	PL_M2_011123
#Remark=
#Date=	11.11.2023 11:41
#Acquired=	11.11.2023 11:41:37
520.044	91.8875
520.306	96.3106
520.569	83.514
520.831	83.8718
521.093	93.0439
521.355	89.3705
521.617	94.2605
521.88	85.0784
522.142	85.117
522.404	94.482
522.666	91.2349
522.928	89.5126
523.19	94.205
523.453	97.0897
523.715	102.013
523.977	91.5619
524.239	102.772
524.501	98.0101
524.763	109.007
525.025	97.957
525.287	99.4461
525.549	102.996
525.811	104.809
526.073	100.155
526.335	100.838
526.597	108.5
526.859	97.6077
527.121	108.121
527.383	98.9993
527.645	102.383
527.907	109.516
528.169	108.124
528.431	108.794
528.693	107.687
528.955	111.724
529.217	107.933
529.479	120.244
529.741	105.081
530.003	115.725
530.264	106.544
530.526	121.337
530.788	111.239
531.05	121.277
531.312	117.959
531.574	112.952
531.835	118.747
532.097	119.113
532.359	115.593
532.621	127.345
532.883	112.536
533.144	118.103
533.406	125.511
533.668	131.116
533.93	130.707
534.191	135.804
534.453	142.525
534.715	133.371
534.976	129.976
535.238	136.015
535.5	134.251
535.761	132.827
536.023	146.525
536.285	133.345
536.546	149.712
536.808	145.827
537.069	128.276
537.331	127.597
537.593	136.298
537.854	139.654
538.116	148.436
538.377	148.736
538.639	156.227
538.9	147.25
539.162	161.97
539.423	154.292
539.685	159.7
539.946	155.812
540.208	140.906
540.469	163.011
540.731	156.13
540.992	172.745
541.254	158.49
541.515	167.959
541.776	162.461
542.038	168.396
542.299	180.806
542.56	176.383
542.822	174.203
543.083	179.287
543.344	190.127
543.606	177.867
543.867	175.819
544.128	181.45
544.39	194.629
544.651	183.831
544.912	187.517
545.174	194.694
545.435	199.774
545.696	177.061
545.957	193.179
546.218	206.91
546.48	206.38
546.741	204.504
547.002	201.238
547.263	203.046
547.524	217.487
547.785	234.129
548.047	230.567
548.308	239.787
548.569	215.765
548.83	224.718
549.091	246.202
549.352	243.301
549.613	237.483
549.874	236.64
550.135	245.359
550.396	238.967
550.657	235.377
550.918	276.074
551.179	263.11
551.44	283.777
551.701	283.962
551.962	333.349
552.223	459.528
552.484	3227.91
552.745	11337.4
553.006	634.934
553.267	365.701
553.528	311.412
553.788	289.434
554.049	293.117
554.31	284.374
554.571	312.444
554.832	299.586
555.093	291.88
555.353	299.915
555.614	307.292
555.875	313.466
556.136	283.395
556.396	293.233
556.657	326.675
556.918	312.344
557.179	307.488
557.439	324.168
557.7	319.712
557.961	320.726
558.221	323.495
558.482	346.507
558.743	337.357
559.003	332.156
559.264	357.192
559.525	348.245
559.785	347.355
560.046	346.934
560.306	355.477
560.567	340.802
560.827	369.642
561.088	369.736
561.348	377.233
561.609	381.974
561.869	392.405
562.13	394.353
562.39	385.962
562.651	405.654
562.911	402.989
563.172	405.513
563.432	427.881
563.692	408.789
563.953	438.355
564.213	441.485
564.474	408.021
564.734	458.089
564.994	457
565.255	435.26
565.515	447.292
565.775	440.322
566.035	445.256
566.296	459.674
566.556	441.663
566.816	458.073
567.076	412.595
567.337	450.312
567.597	476.92
567.857	471.14
568.117	475.256
568.377	460.485
568.637	488.68
568.898	495.905
569.158	506.547
569.418	514.937
569.678	531.457
569.938	521.837
570.198	533.713
570.458	539.299
570.718	560.976
570.978	560.914
571.238	572.919
571.498	605.841
571.758	603.752
572.018	640.795
572.278	648.698
572.538	684.521
572.798	687.678
573.058	712.078
573.312	718.958
573.573	756.208
573.834	769.382
574.095	801.922
574.356	815.188
574.617	847.451
574.878	840.715
575.139	841.597
575.4	877.928
575.661	870.867
575.922	883.492
576.183	879.885
576.444	864.829
576.705	881.817
576.965	878.191
577.226	857.362
577.487	831.223
577.748	836.07
578.009	827.077
578.27	807.674
578.531	807.415
578.791	816.22
579.052	788.929
579.313	778.877
579.574	797.694
579.835	790.761
580.095	781.636
580.356	780.43
580.617	744.971
580.878	772.964
581.138	775.253
581.399	801.086
581.66	800.02
581.92	772.342
582.181	801.576
582.442	813.761
582.703	786.469
582.963	782.6
583.224	812.426
583.484	828.082
583.745	827.511
584.006	844.167
584.266	832.732
584.527	859.016
584.787	871.572
585.048	834.109
585.308	861.57
585.569	877.726
585.83	861.996
586.09	892.314
586.351	900.729
586.611	906.65
586.872	898.422
587.132	900.891
587.392	919.79
587.653	939.232
587.913	924.402
588.174	940.916
588.434	927.463
588.695	953.925
588.955	929.373
589.215	957.083
589.476	945.436
589.736	973.125
589.996	945.745
590.257	932.66
590.517	954.574
590.777	954.809
591.038	943.057
591.298	941.294
591.558	937.964
591.818	950.515
592.079	941.876
592.339	948.247
592.599	943.722
592.859	962.844
593.12	941.69
593.38	957.183
593.64	945.881
593.9	945.42
594.16	965.46
594.42	983.848
594.68	978.372
594.941	998.611
595.201	989.02
595.461	980.346
595.721	995.015
595.981	1026.47
596.241	1021.45
596.501	1031.41
596.761	1046.67
597.021	1039.54
597.281	1035.05
597.541	1063.74
597.801	1058.87
598.061	1050.9
598.321	1006.15
598.581	1028.15
598.841	1064.18
599.101	1040.37
599.361	1037.99
599.62	1032.92
599.88	1054.5
600.14	1082.92
600.4	1053.17
600.66	1045.73
600.92	1034.22
601.18	1070.54
601.439	1054.16
601.699	1042.99
601.959	1036.5
602.219	1052.77
602.478	1058.76
602.738	1058.16
602.998	1044.06
603.258	1056.07
603.517	1040.44
603.777	1051.31
604.037	1070.42
604.296	1075.3
604.556	1083.9
604.816	1087.74
605.075	1095.78
605.335	1075.7
605.594	1066.68
605.854	1108.67
606.114	1078.96
606.373	1103.51
606.633	1096.9
606.892	1078.49
607.152	1103.6
607.411	1098.65
607.671	1115.18
607.93	1118.36
608.19	1107.71
608.449	1098.2
608.709	1102.32
608.968	1095.97
609.228	1153.72
609.487	1092.58
609.746	1116.78
610.006	1110.18
610.265	1129.51
610.524	1113.55
610.784	1152.27
611.043	1130.49
611.302	1153.95
611.562	1159.98
611.821	1151.21
612.08	1160.71
612.339	1192.21
612.599	1179.45
612.858	1203.16
613.117	1149.81
613.376	1186.03
613.635	1211.32
613.895	1176.46
614.154	1201.09
614.413	1189.13
614.672	1213.9
614.931	1190.94
615.19	1246.05
615.449	1217.46
615.709	1203.24
615.968	1258.18
616.227	1226.91
616.486	1235.16
616.745	1253.95
617.004	1231.77
617.263	1222.95
617.522	1237.58
617.781	1240.84
618.04	1234.88
618.299	1225.66
618.557	1243.73
618.816	1243.8
619.075	1250.93
619.334	1244.61
619.593	1240.88
619.852	1241.43
620.111	1237.41
620.37	1247.13
620.628	1234.26
620.887	1263.89
621.146	1250.96
621.373	1233.06
621.633	1289.24
621.893	1255.79
622.153	1258.52
622.413	1265.05
622.673	1252.63
622.932	1250.12
623.192	1262.4
623.452	1282.63
623.712	1243.22
623.972	1279.87
624.232	1262.1
624.492	1294.9
624.751	1256.82
625.011	1291.73
625.271	1283.11
625.531	1332.52
625.791	1296.97
626.05	1269.85
626.31	1315.55
626.57	1306
626.83	1311.12
627.089	1314.65
627.349	1314.35
627.609	1327.54
627.868	1319.23
628.128	1367.04
628.388	1348.68
628.647	1340.15
628.907	1336.66
629.167	1386.17
629.426	1394.3
629.686	1354.96
629.945	1383.41
630.205	1390.81
630.465	1398.27
630.724	1432.55
630.984	1370.17
631.243	1413.23
631.503	1450.08
631.762	1480.3
632.022	1481.29
632.281	1484.43
632.541	1509
632.8	1519.21
633.06	1521.38
633.319	1511.39
633.579	1570.89
633.838	1577.9
634.097	1599.35
634.357	1566.55
634.616	1639.78
634.876	1622.27
635.135	1623.05
635.394	1658.8
635.654	1672.45
635.913	1668.74
636.172	1712.17
636.431	1713.79
636.691	1747.87
636.95	1761.59
637.209	1747.28
637.469	1778.88
637.728	1802.23
637.987	1825.84
638.246	1805.3
638.505	1850.22
638.765	1836.68
639.024	1830.08
639.283	1850.04
639.542	1845.94
639.801	1830.59
640.06	1857.11
640.319	1820.35
640.578	1821.75
640.838	1812.57
641.097	1818.84
641.356	1801.14
641.615	1812.82
641.874	1773.86
642.133	1760.3
642.392	1807.51
642.651	1786.52
642.91	1815.05
643.169	1803.3
643.428	1768.96
643.687	1766.56
643.946	1802.01
644.205	1773.36
644.463	1795.93
644.722	1799.64
644.981	1785.7
645.24	1812.13
645.499	1822.51
645.758	1831.46
646.017	1833.61
646.275	1832.49
646.534	1812.13
646.793	1827.77
647.052	1839.44
647.31	1865.91
647.569	1865.01
647.828	1862.78
648.087	1895.34
648.345	1908.21
648.604	1873.06
648.863	1904.59
649.121	1911.39
649.38	1918.71
649.639	1929.16
649.897	1929.17
650.156	1957.68
650.415	1983.18
650.673	1949.53
650.932	2017.18
651.19	1984.72
651.449	2016.86
651.707	2018.12
651.966	2044
652.224	2042.71
652.483	2066.56
652.741	2062.48
653	2063.17
653.258	2116.88
653.517	2082.79
653.775	2108.81
654.034	2129.46
654.292	2140.1
654.55	2155.44
654.809	2169.19
655.067	2178.49
655.326	2154.78
655.584	2181.42
655.842	2206.63
656.1	2251.11
656.359	2204.65
656.617	2276.69
656.875	2243.95
657.134	2286.59
657.392	2263.67
657.65	2335
657.908	2319.87
658.166	2335.29
658.425	2299.38
658.683	2370.57
658.941	2313.6
659.199	2361.25
659.457	2335.97
659.715	2362.24
659.973	2343.25
660.231	2348.07
660.49	2392.41
660.748	2367.12
661.006	2355.81
661.264	2342.92
661.522	2326.77
661.78	2327.13
662.038	2351.75
662.296	2345.4
662.554	2366.46
662.811	2362.19
663.069	2306.72
663.327	2366.56
663.585	2337.41
663.843	2359.53
664.101	2346.13
664.359	2367.53
664.617	2356.8
664.874	2337.78
665.132	2376.12
665.39	2351.33
665.648	2356.52
665.906	2368.55
666.163	2367.65
666.421	2387.2
666.679	2346.44
666.937	2348.74
667.194	2354.75
667.452	2335.22
667.71	2379.77
667.967	2358.9
668.225	2362.98
668.482	2368.37
668.74	2369.69
668.987	2359.97
669.245	2398.42
669.504	2359.04
669.763	2406.35
670.022	2368.84
670.281	2364.37
670.539	2368.43
670.798	2366.24
671.057	2384.25
671.316	2382.44
671.575	2360.36
671.833	2351.31
672.092	2389.82
672.351	2373.45
672.609	2380
672.868	2364.26
673.127	2368.93
673.385	2364.67
673.644	2437.24
673.903	2443.13
674.161	2407.32
674.42	2416.09
674.678	2371.86
674.937	2427.99
675.195	2415.33
675.454	2462.1
675.713	2449.5
675.971	2436.66
676.23	2489.16
676.488	2477.56
676.747	2470.55
677.005	2489.82
677.263	2515.93
677.522	2506.54
677.78	2513.27
678.039	2516.29
678.297	2531.31
678.556	2532.69
678.814	2542.41
679.072	2485.53
679.331	2489.07
679.589	2494.73
679.847	2462.5
680.106	2498.06
680.364	2486.12
680.622	2457.9
680.881	2491.82
681.139	2485.15
681.397	2485.22
681.656	2527.02
681.914	2489.83
682.172	2533.58
682.43	2538.11
682.688	2519.2
682.947	2507.58
683.205	2520.25
683.463	2520.02
683.721	2548.75
683.979	2533.83
684.237	2538.72
684.495	2541.06
684.754	2526.13
685.012	2509.94
685.27	2504.59
685.528	2529.53
685.786	2541.52
686.044	2504.27
686.302	2527.05
686.56	2478.79
686.818	2417.35
687.076	2496.85
687.334	2489.9
687.592	2490.03
687.85	2468.44
688.108	2494.9
688.366	2471.05
688.623	2459.28
688.881	2456.48
689.139	2457.9
689.397	2455.12
689.655	2440.9
689.913	2397.24
690.171	2478.37
690.428	2471.34
690.686	2452.76
690.944	2439.67
691.202	2472.13
691.459	2448.63
691.717	2451.63
691.975	2441.39
692.233	2435.25
692.49	2440.58
692.748	2409.31
693.006	2373.94
693.263	2387.75
693.521	2393.5
693.779	2417.73
694.036	2378.31
694.294	2395.11
694.552	2423.87
694.809	2381.7
695.067	2396.17
695.324	2441.25
695.582	2378.2
695.839	2398.59
696.097	2362.84
696.354	2397.86
696.612	2373.73
696.869	2388.89
697.127	2401.75
697.384	2410.38
697.642	2391.43
697.899	2373.86
698.156	2369.59
698.414	2371.17
698.671	2382.52
698.928	2335.32
699.186	2357.18
699.443	2350.23
699.7	2353.2
699.958	2360.67
700.215	2352.22
700.472	2340.85
700.73	2307.68
700.987	2307.37
701.244	2293.82
701.501	2342.77
701.758	2339.57
702.016	2297.91
702.273	2292.61
702.53	2305.19
702.787	2309.9
703.044	2293.71
703.301	2311.14
703.558	2325.18
703.816	2305.91
704.073	2296.48
704.33	2285.09
704.587	2301.98
704.844	2318.75
705.101	2289.95
705.358	2248.7
705.615	2252.26
705.872	2259.68
706.129	2282.15
706.386	2248.81
706.643	2274.2
706.899	2307.58
707.156	2261.89
707.413	2289.51
707.67	2236.11
707.927	2267.76
708.184	2226.72
708.441	2231.34
708.697	2232.13
708.954	2251.2
709.211	2216.99
709.468	2240.55
709.725	2200.72
709.981	2206.91
710.238	2208.69
710.495	2227.38
710.751	2187.78
711.008	2241.9
711.265	2209.89
711.521	2209.41
711.778	2183.11
712.035	2226.14
712.291	2194.75
712.548	2193.55
712.804	2178.26
713.061	2200.22
713.317	2197.77
713.574	2173.43
713.831	2158.27
714.087	2151.27
714.343	2168.73
714.6	2167.66
714.856	2159.03
715.113	2149.6
715.369	2127.04
715.626	2122.15
715.882	2139.24
716.138	2114.37
716.395	2087.86
716.639	2118.7
716.897	2065.22
717.155	2057.35
717.412	2097.42
717.67	2071.21
717.927	2057.54
718.185	2055.04
718.443	2054.47
718.7	2068.31
718.958	2076.44
719.215	2044.31
719.473	2020.8
719.73	2058.37
719.988	2050.95
720.245	2025.84
720.503	2017.19
720.76	1996.18
721.018	1960.5
721.275	2003.36
721.532	2030.32
721.79	1999.7
722.047	1983.38
722.305	1977.03
722.562	1970.7
722.819	1959.55
723.077	1962.66
723.334	1944.93
723.591	1955.83
723.849	1912.34
724.106	1931.26
724.363	1897.31
724.621	1931.42
724.878	1917.71
725.135	1913.98
725.392	1924.37
725.65	1909.46
725.907	1881.13
726.164	1902.9
726.421	1878.18
726.678	1880.98
726.935	1862.93
727.193	1884.8
727.45	1842.2
727.707	1903.44
727.964	1872.41
728.221	1868.49
728.478	1845.57
728.735	1861.96
728.992	1813.02
729.249	1816.02
729.506	1841.58
729.763	1789.58
730.02	1814.08
730.277	1819.04
730.534	1756.67
730.791	1794.37
731.048	1772.27
731.305	1803.44
731.562	1777.57
731.819	1751.61
732.076	1750.57
732.333	1803.68
732.589	1767.07
732.846	1753.46
733.103	1755.09
733.36	1762.06
733.617	1723.12
733.873	1733.8
734.13	1727.75
734.387	1718.5
734.644	1697.94
734.901	1720.59
735.157	1706.66
735.414	1702.06
735.671	1679.94
735.927	1703.32
736.184	1640.79
736.441	1660.45
736.697	1662.31
736.954	1651.63
737.211	1653.38
737.467	1656.39
737.724	1662.14
737.98	1622.77
738.237	1646.14
738.493	1674.97
738.75	1559.44
739.006	1619.19
739.263	1620.55
739.519	1576.05
739.776	1638.07
740.032	1623.54
740.289	1570.54
740.545	1568.79
740.802	1565.72
741.058	1584.2
741.314	1598.68
741.571	1554.97
741.827	1568.19
742.083	1550.25
742.34	1531.83
742.596	1540.4
742.852	1566.75
743.109	1534.25
743.365	1537.89
743.621	1537.11
743.878	1539.63
744.134	1557.33
744.39	1518.11
744.646	1513.03
744.902	1484.31
745.159	1506.45
745.415	1472.98
745.671	1476.5
745.927	1478.43
746.183	1443.87
746.439	1456.32
746.695	1437.53
746.951	1460.37
747.207	1423.93
747.463	1449.72
747.719	1469.42
747.975	1425.63
748.231	1445.44
748.487	1464.22
748.743	1416.15
748.999	1443.41
749.255	1390.73
749.511	1411.52
749.767	1425.9
750.023	1397.35
750.279	1367.16
750.535	1392.53
750.791	1358.39
751.046	1344.98
751.302	1380.42
751.558	1423.48
751.814	1384.5
752.07	1363.09
752.325	1366.71
752.581	1350.76
752.837	1356.47
753.092	1328.78
753.348	1388.59
753.604	1340.32
753.859	1329.07
754.115	1332.7
754.371	1316.09
754.626	1323.74
754.882	1303.08
755.138	1313.56
755.393	1305.96
755.649	1282.08
755.904	1298.72
756.16	1278.64
756.415	1316.24
756.671	1247.75
756.926	1261.15
757.182	1294.42
757.437	1243.49
757.693	1245.11
757.948	1238.36
758.203	1233.77
758.459	1236.88
758.714	1219.11
758.97	1251.47
759.225	1196.96
759.48	1198.81
759.736	1209.51
759.991	1208.52
760.246	1246.79
760.501	1207.48
760.757	1196.1
761.012	1223.74
761.267	1186.5
761.522	1205.37
761.777	1179.22
762.033	1197.99
762.288	1195.77
762.543	1173.96
762.798	1161.11
763.053	1187.2
763.308	1146.37
763.563	1141.42
763.78	1131.36
764.037	1148.17
764.293	1160.02
764.55	1120.19
764.806	1123.9
765.062	1134.81
765.319	1154.56
765.575	1109.84
765.831	1114.22
766.088	1088.71
766.344	1102.76
766.6	1082.41
766.857	1089.14
767.113	1105.95
767.369	1079.4
767.625	1088.79
767.882	1080.29
768.138	1057.55
768.394	1066.98
768.65	1089.82
768.906	1067.15
769.163	1076.16
769.419	1061.95
769.675	1022.52
769.931	1002.97
770.187	1014.12
770.443	1057.65
770.699	1026.63
770.955	1004.68
771.211	1014.96
771.467	1006.97
771.723	1008.97
771.979	1026.37
772.235	993.143
772.491	961.547
772.747	994.67
773.003	992.297
773.259	964.103
773.515	994.091
773.771	975.769
774.027	959.66
774.283	975.283
774.539	956.709
774.795	935.667
775.05	922.1
775.306	950.897
775.562	943.001
775.818	948.266
776.074	929.443
776.329	910.656
776.585	938.898
776.841	889.812
777.097	903.283
777.352	924.615
777.608	888.249
777.864	913.403
778.12	891.849
778.375	889.049
778.631	881.402
778.886	890.75
779.142	909.073
779.398	874.782
779.653	858.731
779.909	905.154
780.164	867.002
780.42	883.878
780.675	867.273
780.931	871.701
781.187	848.542
781.442	837.905
781.698	833.478
781.953	885.778
782.208	846.507
782.464	829.381
782.719	807.038
782.975	828.927
783.23	773.626
783.485	836.949
783.741	787.49
783.996	819.983
784.252	798.106
784.507	785.954
784.762	806.541
785.017	837.086
785.273	776.916
785.528	782.378
785.783	795.116
786.038	774.72
786.294	788.702
786.549	768.106
786.804	804.012
787.059	788.857
787.314	750.093
787.57	775.381
787.825	769.012
788.08	762.546
788.335	737.035
788.59	730.685
788.845	738.033
789.1	735.609
789.355	749.508
789.61	748.312
789.865	742.315
790.12	736.771
790.375	733.008
790.63	716.42
790.885	712.12
791.14	714.313
791.395	728.857
791.65	711.029
791.905	698.493
792.16	689.095
792.414	690.982
792.669	707.841
792.924	703.832
793.179	677.78
793.434	696.621
793.689	686.03
793.943	687.372
794.198	666.571
794.453	674.071
794.708	656.854
794.962	648.739
795.217	657.73
795.472	673.04
795.726	641.126
795.981	650.767
796.236	659.76
796.49	626.688
796.745	615.84
796.999	627.208
797.254	603.516
797.508	636.542
797.763	631.268
798.018	616.499
798.272	620.776
798.526	598.599
798.781	630.758
799.035	616.902
799.29	588.689
799.544	589.662
799.799	607.987
800.053	610.368
800.307	555.793
800.562	611.007
800.816	599.629
801.07	583.363
801.325	556.689
801.579	573.342
801.833	600.249
802.088	586.085
802.342	578.146
802.596	579.043
802.85	573.756
803.105	562.145
803.359	545.607
803.613	548.687
803.867	561.305
804.121	542.62
804.375	547.964
804.63	542.231
804.884	560.533
805.138	552.641
805.392	541.968
805.646	557.743
805.9	526.904
806.154	522.17
806.408	540.345
806.662	525.996
806.916	508.926
807.17	514.214
807.424	527.663
807.678	517.283
807.931	530.244
808.185	508.614
808.439	508.921
808.693	506.604
808.947	496.303
809.201	481.222
809.454	507.545
809.708	499.53
809.962	478.401
810.216	487.947
810.469	488.883
810.678	480.14
810.933	490.568
811.188	486.451
811.443	464.01
811.699	492.997
811.954	445.008
812.209	459.346
812.464	462.373
812.719	439.875
812.974	460.991
813.229	464.793
813.484	436.991
813.739	433.15
813.994	455.84
814.249	468.387
814.504	448.994
814.759	429.42
815.014	420.466
815.268	447.233
815.523	438.269
815.778	457.319
816.033	442.555
816.288	446.588
816.543	413.445
816.798	425.966
817.052	419.983
817.307	422.692
817.562	431.167
817.817	417.718
818.071	427.437
818.326	420.926
818.581	421.66
818.836	427.622
819.09	401.574
819.345	419.284
819.6	413
819.854	417.124
820.109	415.332
820.364	415.404
820.618	409.173
820.873	399.756
821.127	408.324
821.382	391.24
821.637	391.788
821.891	399.934
822.146	390.742
822.4	378.61
822.655	405.211
822.909	380.912
823.164	396.297
823.418	385.92
823.672	378.806
823.927	371.208
824.181	391.679
824.436	404.906
824.69	403.025
824.944	382.957
825.199	365.69
825.453	351.005
825.707	377.143
825.962	349.025
826.216	356.8
826.47	382.008
826.725	364.165
826.979	346.752
827.233	342.149
827.487	365.625
827.741	367.698
827.996	361.087
828.25	354.495
828.504	349.071
828.758	349.853
829.012	350.209
829.266	334.83
829.52	348.003
829.774	366.418
830.029	333.641
830.283	339.243
830.537	334.286
830.791	323.764
831.045	334.7
831.299	319.442
831.553	340.54
831.807	345.931
832.061	333.123
832.315	338.552
832.568	326.135
832.822	331.591
833.076	321.407
833.33	334.997
833.584	322.152
833.838	322.412
834.092	309.662
834.345	283.406
834.599	289.139
834.853	323.571
835.107	307.855
835.36	307.754
835.614	321.21
835.868	300.22
836.122	308.855
836.375	290.359
836.629	292.559
836.883	297.847
837.136	284.992
837.39	295.333
837.643	295.577
837.897	282.648
838.151	300.774
838.404	279.504
838.658	302.97
838.911	303.091
839.165	305.955
839.418	282.567
839.672	287.729
839.925	261.6
840.179	288.392
840.432	277.832
840.686	275.275
840.939	272.992
841.192	273.342
841.446	292.162
841.699	271.223
841.952	260.808
842.206	265.69
842.459	294.932
842.712	284.442
842.966	284.416
843.219	289.953
843.472	266.275
843.725	258.713
843.979	269.492
844.232	274.693
844.485	245.598
844.738	269.859
844.991	256.596
845.244	259.413
845.497	264.897
845.75	265.253
846.004	268.082
846.257	268.276
846.51	249.604
846.763	258.002
847.016	263.109
847.269	252.529
847.522	255.239
847.775	242.081
848.028	247.61
848.281	237.119
848.534	239.983
848.786	248.497
849.039	262.244
849.292	232.884
849.545	243.724
849.798	249.67
850.051	233.348
850.303	225.266
850.556	233.57
850.809	222.946
851.062	217.545
851.314	228.524
851.567	229.183
851.82	229.333
852.073	245.912
852.325	221.667
852.578	224.131
852.831	207.905
853.083	238.036
853.336	214.694
853.588	230.727
853.841	230.995
854.093	215.627
854.346	210.457
854.598	222.638
854.851	213.694
855.103	227.803
855.356	214.374
855.608	206.984
855.861	203.91
856.113	209.818
856.366	204.752
856.618	210.09
856.87	207.842
857.123	206.609
857.352	216.192
857.606	221.789
857.859	218.968
858.113	210.861
858.367	202.568
858.621	188.528
858.875	207.846
859.128	205.181
859.382	199.547
859.636	219.049
859.889	210.71
860.143	199.823
860.397	205.228
860.65	202.753
860.904	194.377
861.158	211.071
861.411	211.314
861.665	194.714
861.918	208.414
862.172	199.768
862.425	194.316
862.679	185.851
862.932	196.997
863.186	191.936
863.439	194.36
863.693	188.836
863.946	200.246
864.2	178.023
864.453	197.681
864.707	186.404
864.96	191.789
865.213	183.581
865.467	172.48
865.72	189.334
865.973	172.834
866.227	175.752
866.48	161.767
866.733	172.951
866.987	186.93
867.24	170.514
867.493	167.64
867.746	192.982
867.999	176.331
868.253	173.61
868.506	148.537
868.759	174.063
869.012	185.438
869.265	165.905
869.518	171.572
869.771	182.76
870.025	194.082
870.278	174.435
870.531	152.214
870.784	186.349
871.037	163.838
871.29	166.614
871.543	183.835
871.796	169.897
872.049	184.069
872.302	181.385
872.555	169.987
872.808	169.998
873.06	164.379
873.313	175.898
873.566	158.841
873.819	150.505
874.072	164.336
874.325	178.545
874.578	159.046
874.83	150.512
875.083	170.349
875.336	156.115
875.589	144.886
875.841	161.895
876.094	156.229
876.347	167.76
876.6	156.364
876.852	147.975
877.105	153.774
877.358	151.06
877.61	151.033
877.863	162.459
878.115	156.885
878.368	145.732
878.621	163.145
878.873	151.693
879.126	143.018
879.378	172.063
879.631	157.963
879.883	152.209
880.136	146.534
880.388	158.292
880.641	158.575
880.893	138.562
881.145	147.231
881.398	156.197
881.65	147.695
881.902	147.811
882.155	150.791
882.407	136.274
882.659	171.201
882.912	157.008
883.164	133.861
883.416	134.022
883.669	136.981
883.921	131.323
884.173	137.275
884.425	137.451
884.677	146.238
884.93	137.64
885.182	137.568
885.434	143.334
885.686	143.453
885.938	128.827
886.19	137.764
886.442	146.553
886.694	149.615
886.946	129.125
887.198	141.205
887.45	123.675
887.702	129.608
887.954	126.839
888.206	138.747
888.458	144.899
888.71	135.978
888.962	142.036
889.214	133.216
889.466	130.372
889.718	136.387
889.969	124.723
890.221	112.969
890.473	142.846
890.725	140.324
890.977	113.532
891.228	119.59
891.48	131.709
891.732	119.808
891.983	120.177
892.235	129.29
892.487	117.532
892.738	135.909
892.99	124.099
893.242	121.101
893.493	124.156
893.745	127.361
893.996	124.507
894.248	118.592
894.5	145.952
894.751	134.093
895.003	116.074
895.254	101.082
895.505	119.583
895.757	110.504
896.008	135.202
896.26	110.772
896.511	117.036
896.763	120.117
897.014	132.81
897.265	123.626
897.517	114.25
897.768	98.941
898.019	117.815
898.27	108.296
898.522	102.237
898.773	127.5
899.024	124.416
899.275	108.901
899.527	121.21
899.778	124.691
899.979	115.524