File: PL_M3_180324_01.txt
#Acq. time (s)=	3
#Accumulations=	2
#Range (nm)=	520...900
#Windows=	8
#Auto scanning=	Off
#Autofocus=	Off
#AutoExposure=	Off
#Spike filter=	Multiple accum.
#Delay time (s)=	0
#Binning=	1
#Readout mode=	Signal
#DeNoise=	Off
#ICS correction=	Off
#Dark correction=	Off
#Inst. Process=	Off
#Detector temperature (°C)=	-59.98
#Instrument=	LabRAM HR Evol
#Detector=	Syncerity OE
#Objective=	x50_VIS
#Grating=	600 (500nm)
#ND Filter=	25%
#Laser=	514nm_Edge
#Hole=	199.981
#Range=	Auto
#StageXY=	Marzhauser
#StageZ=	Marzhauser
#X (µm)=	-454.1
#Y (µm)=	5366.7
#Z (µm)=	-6.6
#Full time(mm:ss)=	1:32
#Project=
#Sample=
#Site=
#Title=	PL_M3_180324
#Remark=
#Date=	28.03.2024 09:16
#Acquired=	28.03.2024 09:16:14
520.044	38
520.306	44
520.569	38
520.831	22
521.093	38
521.355	36
521.617	38
521.88	32
522.142	38
522.404	36
522.666	46
522.928	32
523.19	34
523.453	42
523.715	42
523.977	38
524.239	32
524.501	42
524.763	38
525.025	24
525.287	34
525.549	34
525.811	34
526.073	32
526.335	32
526.597	40
526.859	38
527.121	26
527.383	34
527.645	38
527.907	36
528.169	36
528.431	42
528.693	38
528.955	42
529.217	38
529.479	26
529.741	42
530.003	34
530.264	28
530.526	36
530.788	42
531.05	36
531.312	38
531.574	40
531.835	34
532.097	36
532.359	28
532.621	38
532.883	34
533.144	40
533.406	40
533.668	46
533.93	50
534.191	44
534.453	42
534.715	52
534.976	54
535.238	50
535.5	48
535.761	42
536.023	50
536.285	52
536.546	48
536.808	38
537.069	60
537.331	48
537.593	42
537.854	48
538.116	52
538.377	46
538.639	52
538.9	40
539.162	52
539.423	54
539.685	56
539.946	46
540.208	56
540.469	50
540.731	54
540.992	44
541.254	58
541.515	54
541.776	54
542.038	48
542.299	58
542.56	58
542.822	56
543.083	56
543.344	68
543.606	62
543.867	66
544.128	52
544.39	70
544.651	60
544.912	64
545.174	56
545.435	72
545.696	72
545.957	66
546.218	68
546.48	80
546.741	66
547.002	70
547.263	72
547.524	92
547.785	84
548.047	84
548.308	76
548.569	90
548.83	84
549.091	92
549.352	86
549.613	96
549.874	104
550.135	104
550.396	96
550.657	108
550.918	118
551.179	122
551.44	142
551.701	166
551.962	220
552.223	360
552.484	3172
552.745	22524
553.006	592
553.267	246
553.528	164
553.788	158
554.049	138
554.31	134
554.571	122
554.832	142
555.093	132
555.353	134
555.614	124
555.875	142
556.136	138
556.396	142
556.657	136
556.918	152
557.179	156
557.439	160
557.7	152
557.961	156
558.221	164
558.482	168
558.743	148
559.003	176
559.264	162
559.525	164
559.785	168
560.046	172
560.306	170
560.567	174
560.827	186
561.088	196
561.348	192
561.609	208
561.869	198
562.13	208
562.39	198
562.651	214
562.911	240
563.172	222
563.432	244
563.692	262
563.953	286
564.213	294
564.474	298
564.734	278
564.994	268
565.255	274
565.515	272
565.775	274
566.035	256
566.296	268
566.556	296
566.816	292
567.076	274
567.337	318
567.597	298
567.857	300
568.117	313.91
568.377	313.625
568.637	322.954
568.898	334.19
569.158	326.223
569.418	336.179
569.678	350.316
569.938	367.53
570.198	373.23
570.458	365.76
570.718	385.578
570.978	404.312
571.238	417.58
571.498	446.954
571.758	459.261
572.018	478.193
572.278	508.051
572.538	531.397
572.798	563.228
573.058	611.683
573.312	622
573.573	676
573.834	738
574.095	812
574.356	882
574.617	942
574.878	1012
575.139	1014
575.4	1110
575.661	1098
575.922	1126
576.183	1102
576.444	1074
576.705	1010
576.965	980
577.226	962
577.487	888
577.748	884
578.009	810
578.27	804
578.531	782
578.791	786
579.052	760
579.313	736
579.574	772
579.835	784
580.095	768
580.356	762
580.617	770
580.878	786
581.138	770
581.399	748
581.66	772
581.92	792
582.181	802
582.442	782
582.703	830
582.963	820
583.224	814
583.484	842
583.745	838
584.006	866
584.266	844
584.527	898
584.787	936
585.048	906
585.308	960
585.569	1000
585.83	992
586.09	1000
586.351	1004
586.611	1042
586.872	1014
587.132	1036
587.392	1022
587.653	1048
587.913	1060
588.174	1060
588.434	1068
588.695	1090
588.955	1092
589.215	1124
589.476	1094
589.736	1096
589.996	1128
590.257	1112
590.517	1096
590.777	1074
591.038	1078
591.298	1096
591.558	1038
591.818	996
592.079	1046
592.339	1034
592.599	1010
592.859	1046
593.12	1070
593.38	1072
593.64	1062
593.9	1048
594.16	1046
594.42	1064
594.68	1028
594.941	1116
595.201	1100
595.461	1082
595.721	1074
595.981	1146
596.241	1118
596.501	1156
596.761	1168
597.021	1164
597.281	1146
597.541	1176
597.801	1124
598.061	1180
598.321	1192
598.581	1162
598.841	1182
599.101	1188
599.361	1216
599.62	1170
599.88	1176
600.14	1202
600.4	1214
600.66	1204
600.92	1216
601.18	1222
601.439	1208
601.699	1238
601.959	1148
602.219	1222
602.478	1194
602.738	1228
602.998	1244
603.258	1216
603.517	1256
603.777	1244
604.037	1256
604.296	1286
604.556	1286
604.816	1248
605.075	1270
605.335	1260
605.594	1284
605.854	1258
606.114	1244
606.373	1248
606.633	1288
606.892	1268
607.152	1286
607.411	1270
607.671	1274
607.93	1300
608.19	1306
608.449	1300
608.709	1328
608.968	1300
609.228	1332
609.487	1336
609.746	1342
610.006	1334
610.265	1350
610.524	1344
610.784	1384
611.043	1382
611.302	1384
611.562	1384
611.821	1416
612.08	1382
612.339	1398
612.599	1426
612.858	1428
613.117	1486
613.376	1480
613.635	1486
613.895	1454
614.154	1558
614.413	1472
614.672	1566
614.931	1546
615.19	1536
615.449	1562
615.709	1582
615.968	1570
616.227	1580.15
616.486	1555.23
616.745	1623.16
617.004	1618.12
617.263	1617.14
617.522	1604.45
617.781	1639.12
618.04	1651.92
618.299	1682.34
618.557	1667.2
618.816	1677.23
619.075	1654.44
619.334	1698.52
619.593	1690.75
619.852	1700.92
620.111	1724.87
620.37	1683.78
620.628	1736.8
620.887	1716.4
621.146	1702.1
621.373	1736
621.633	1768
621.893	1752
622.153	1742
622.413	1732
622.673	1746
622.932	1810
623.192	1828
623.452	1794
623.712	1808
623.972	1816
624.232	1796
624.492	1792
624.751	1792
625.011	1824
625.271	1798
625.531	1840
625.791	1848
626.05	1860
626.31	1874
626.57	1854
626.83	1894
627.089	1912
627.349	1934
627.609	1958
627.868	1942
628.128	1916
628.388	1936
628.647	1950
628.907	1962
629.167	1924
629.426	1984
629.686	2022
629.945	2052
630.205	2060
630.465	2022
630.724	2044
630.984	2078
631.243	2118
631.503	2122
631.762	2136
632.022	2122
632.281	2182
632.541	2230
632.8	2190
633.06	2250
633.319	2246
633.579	2264
633.838	2308
634.097	2340
634.357	2308
634.616	2412
634.876	2466
635.135	2474
635.394	2570
635.654	2606
635.913	2650
636.172	2770
636.431	2864
636.691	2974
636.95	3070
637.209	3168
637.469	3228
637.728	3318
637.987	3366
638.246	3374
638.505	3408
638.765	3466
639.024	3392
639.283	3306
639.542	3242
639.801	3106
640.06	3144
640.319	3152
640.578	3040
640.838	2964
641.097	2992
641.356	2958
641.615	2970
641.874	2960
642.133	2964
642.392	2922
642.651	2934
642.91	2914
643.169	2912
643.428	2938
643.687	2998
643.946	2970
644.205	3014
644.463	2948
644.722	2976
644.981	2986
645.24	3022
645.499	3066
645.758	3100
646.017	3078
646.275	3142
646.534	3098
646.793	3116
647.052	3094
647.31	3140
647.569	3210
647.828	3156
648.087	3180
648.345	3282
648.604	3216
648.863	3242
649.121	3256
649.38	3236
649.639	3328
649.897	3274
650.156	3374
650.415	3374
650.673	3394
650.932	3380
651.19	3446
651.449	3472
651.707	3510
651.966	3584
652.224	3510
652.483	3554
652.741	3546
653	3602
653.258	3636
653.517	3662
653.775	3708
654.034	3724
654.292	3740
654.55	3836
654.809	3842
655.067	3854
655.326	3870
655.584	3982
655.842	4066
656.1	4066
656.359	4138
656.617	4182
656.875	4196
657.134	4222
657.392	4280
657.65	4334
657.908	4254
658.166	4320
658.425	4354
658.683	4408
658.941	4398
659.199	4456
659.457	4404
659.715	4444
659.973	4530
660.231	4426
660.49	4476
660.748	4512
661.006	4528
661.264	4420
661.522	4472
661.78	4494
662.038	4482
662.296	4480
662.554	4474
662.811	4522
663.069	4472
663.327	4474
663.585	4510
663.843	4442.67
664.101	4527.71
664.359	4528.94
664.617	4472.74
664.874	4503.01
665.132	4505.52
665.39	4500.67
665.648	4567.49
665.906	4528.44
666.163	4520.91
666.421	4563.34
666.679	4512.09
666.937	4542.46
667.194	4529.28
667.452	4486.4
667.71	4503.66
667.967	4543.73
668.225	4534.71
668.482	4498.4
668.74	4583.1
668.987	4574
669.245	4466
669.504	4550
669.763	4578
670.022	4556
670.281	4560
670.539	4570
670.798	4602
671.057	4538
671.316	4588
671.575	4542
671.833	4526
672.092	4516
672.351	4560
672.609	4608
672.868	4612
673.127	4578
673.385	4630
673.644	4712
673.903	4708
674.161	4686
674.42	4756
674.678	4752
674.937	4836
675.195	4854
675.454	4796
675.713	4792
675.971	4852
676.23	4794
676.488	4880
676.747	4860
677.005	4874
677.263	4898
677.522	4858
677.78	4842
678.039	4870
678.297	4954
678.556	4914
678.814	4944
679.072	4958
679.331	4934
679.589	4962
679.847	4900
680.106	4956
680.364	4920
680.622	4924
680.881	4974
681.139	5024
681.397	5042
681.656	5042
681.914	5046
682.172	5116
682.43	5026
682.688	5022
682.947	5004
683.205	4930
683.463	5082
683.721	5138
683.979	5060
684.237	4992
684.495	5094
684.754	4934
685.012	5044
685.27	5018
685.528	4996
685.786	4946
686.044	5006
686.302	4992
686.56	4936
686.818	5016
687.076	4948
687.334	5022
687.592	4930
687.85	4964
688.108	4958
688.366	4954
688.623	4932
688.881	4918
689.139	4920
689.397	4954
689.655	4836
689.913	4884
690.171	4926
690.428	4808
690.686	4872
690.944	4860
691.202	4826
691.459	4828
691.717	4818
691.975	4844
692.233	4818
692.49	4806
692.748	4728
693.006	4810
693.263	4654
693.521	4730
693.779	4748
694.036	4744
694.294	4738
694.552	4770
694.809	4638
695.067	4662
695.324	4714
695.582	4682
695.839	4668
696.097	4606
696.354	4700
696.612	4640
696.869	4590
697.127	4572
697.384	4514
697.642	4540
697.899	4516
698.156	4558
698.414	4488
698.671	4458
698.928	4532
699.186	4438
699.443	4498
699.7	4408
699.958	4478
700.215	4434
700.472	4410
700.73	4456
700.987	4400
701.244	4374
701.501	4408
701.758	4338
702.016	4380
702.273	4414
702.53	4382
702.787	4348
703.044	4428
703.301	4426
703.558	4390
703.816	4462
704.073	4362
704.33	4376
704.587	4344
704.844	4264
705.101	4326
705.358	4332
705.615	4270
705.872	4320
706.129	4174
706.386	4224
706.643	4234
706.899	4232
707.156	4158
707.413	4126
707.67	4108
707.927	4100
708.184	4108
708.441	4094
708.697	4134
708.954	4164
709.211	4130
709.468	4066
709.725	4088
709.981	4096
710.238	4074
710.495	4016
710.751	4052
711.008	4106
711.265	4030.18
711.521	4034.29
711.778	3910.11
712.035	3969
712.291	3996.8
712.548	3967.24
712.804	3899.54
713.061	3878.86
713.317	3889.85
713.574	3818.22
713.831	3832.31
714.087	3808.67
714.343	3782.99
714.6	3781.36
714.856	3736.78
715.113	3724.44
715.369	3753.11
715.626	3707.43
715.882	3680.05
716.138	3725.16
716.395	3667.62
716.639	3618
716.897	3688
717.155	3634
717.412	3608
717.67	3620
717.927	3616
718.185	3586
718.443	3590
718.7	3500
718.958	3546
719.215	3572
719.473	3496
719.73	3504
719.988	3462
720.245	3446
720.503	3464
720.76	3406
721.018	3418
721.275	3432
721.532	3364
721.79	3324
722.047	3322
722.305	3316
722.562	3320
722.819	3282
723.077	3240
723.334	3240
723.591	3262
723.849	3178
724.106	3206
724.363	3168
724.621	3146
724.878	3188
725.135	3120
725.392	3122
725.65	3092
725.907	3082
726.164	3080
726.421	3106
726.678	3044
726.935	3012
727.193	2956
727.45	3028
727.707	2980
727.964	2872
728.221	2980
728.478	2942
728.735	2904
728.992	2852
729.249	2846
729.506	2834
729.763	2812
730.02	2738
730.277	2732
730.534	2788
730.791	2746
731.048	2748
731.305	2714
731.562	2716
731.819	2734
732.076	2694
732.333	2708
732.589	2678
732.846	2650
733.103	2596
733.36	2624
733.617	2598
733.873	2608
734.13	2594
734.387	2640
734.644	2636
734.901	2614
735.157	2596
735.414	2590
735.671	2568
735.927	2506
736.184	2578
736.441	2566
736.697	2552
736.954	2532
737.211	2492
737.467	2560
737.724	2532
737.98	2544
738.237	2574
738.493	2522
738.75	2540
739.006	2532
739.263	2474
739.519	2482
739.776	2468
740.032	2438
740.289	2484
740.545	2468
740.802	2452
741.058	2352
741.314	2390
741.571	2400
741.827	2388
742.083	2322
742.34	2396
742.596	2336
742.852	2326
743.109	2334
743.365	2222
743.621	2288
743.878	2282
744.134	2228
744.39	2268
744.646	2266
744.902	2238
745.159	2240
745.415	2174
745.671	2216
745.927	2184
746.183	2162
746.439	2218
746.695	2190
746.951	2132
747.207	2186
747.463	2156
747.719	2140
747.975	2102
748.231	2142
748.487	2116
748.743	2106
748.999	2052
749.255	2150
749.511	2070
749.767	2086
750.023	2070
750.279	2054
750.535	2038
750.791	2046
751.046	2042
751.302	2022
751.558	2020
751.814	2002
752.07	1952
752.325	1926
752.581	1934
752.837	1910
753.092	1926
753.348	1922
753.604	1884
753.859	1890
754.115	1884
754.371	1858
754.626	1846
754.882	1884
755.138	1852
755.393	1854
755.649	1824
755.904	1858
756.16	1822
756.415	1822
756.671	1806
756.926	1752
757.182	1786
757.437	1768
757.693	1758
757.948	1732
758.203	1720
758.459	1752
758.714	1726.23
758.97	1726.43
759.225	1681.95
759.48	1720.24
759.736	1678.67
759.991	1693.76
760.246	1668.13
760.501	1649.61
760.757	1601.8
761.012	1624.13
761.267	1610.93
761.522	1626.14
761.777	1618.55
762.033	1614.18
762.288	1598.9
762.543	1591.03
762.798	1563.88
763.053	1567.5
763.308	1527.57
763.563	1538.62
763.78	1544
764.037	1536
764.293	1498
764.55	1504
764.806	1494
765.062	1442
765.319	1488
765.575	1450
765.831	1444
766.088	1446
766.344	1460
766.6	1448
766.857	1432
767.113	1380
767.369	1416
767.625	1416
767.882	1418
768.138	1360
768.394	1326
768.65	1384
768.906	1390
769.163	1374
769.419	1358
769.675	1324
769.931	1294
770.187	1326
770.443	1292
770.699	1302
770.955	1282
771.211	1244
771.467	1248
771.723	1254
771.979	1206
772.235	1234
772.491	1232
772.747	1208
773.003	1214
773.259	1256
773.515	1178
773.771	1172
774.027	1190
774.283	1198
774.539	1174
774.795	1152
775.05	1136
775.306	1130
775.562	1136
775.818	1128
776.074	1126
776.329	1092
776.585	1092
776.841	1080
777.097	1086
777.352	1100
777.608	1054
777.864	1040
778.12	1062
778.375	1058
778.631	1034
778.886	1022
779.142	1038
779.398	1032
779.653	996
779.909	1038
780.164	1008
780.42	998
780.675	996
780.931	990
781.187	968
781.442	972
781.698	942
781.953	968
782.208	920
782.464	926
782.719	916
782.975	950
783.23	906
783.485	904
783.741	912
783.996	898
784.252	900
784.507	904
784.762	892
785.017	872
785.273	892
785.528	866
785.783	850
786.038	850
786.294	852
786.549	804
786.804	804
787.059	814
787.314	814
787.57	802
787.825	812
788.08	776
788.335	790
788.59	792
788.845	766
789.1	780
789.355	796
789.61	778
789.865	756
790.12	752
790.375	754
790.63	758
790.885	728
791.14	764
791.395	714
791.65	720
791.905	710
792.16	696
792.414	728
792.669	692
792.924	692
793.179	684
793.434	708
793.689	666
793.943	694
794.198	662
794.453	668
794.708	644
794.962	670
795.217	636
795.472	644
795.726	614
795.981	648
796.236	610
796.49	606
796.745	606
796.999	632
797.254	618
797.508	606
797.763	582
798.018	606
798.272	588
798.526	598
798.781	578
799.035	570
799.29	570
799.544	580
799.799	578
800.053	562
800.307	550
800.562	570
800.816	550
801.07	552
801.325	522
801.579	548
801.833	546
802.088	510
802.342	524
802.596	526
802.85	516
803.105	510
803.359	510
803.613	512
803.867	530
804.121	500
804.375	498
804.63	500
804.884	496
805.138	478
805.392	490
805.646	493.678
805.9	489.926
806.154	460.71
806.408	467.099
806.662	470.572
806.916	453.051
807.17	464.392
807.424	468.823
807.678	455.707
807.931	444.237
808.185	437.681
808.439	435.189
808.693	439.354
808.947	452.422
809.201	432.782
809.454	427.156
809.708	430.196
809.962	423.54
810.216	429.57
810.469	424.68
810.678	430
810.933	398
811.188	406
811.443	410
811.699	420
811.954	408
812.209	388
812.464	386
812.719	380
812.974	396
813.229	368
813.484	384
813.739	378
813.994	376
814.249	388
814.504	360
814.759	374
815.014	380
815.268	380
815.523	366
815.778	380
816.033	348
816.288	374
816.543	360
816.798	334
817.052	346
817.307	350
817.562	352
817.817	332
818.071	338
818.326	346
818.581	348
818.836	340
819.09	336
819.345	328
819.6	316
819.854	322
820.109	326
820.364	326
820.618	328
820.873	310
821.127	302
821.382	316
821.637	320
821.891	300
822.146	306
822.4	300
822.655	290
822.909	306
823.164	282
823.418	294
823.672	294
823.927	294
824.181	288
824.436	296
824.69	310
824.944	278
825.199	286
825.453	260
825.707	288
825.962	260
826.216	278
826.47	282
826.725	272
826.979	266
827.233	268
827.487	274
827.741	274
827.996	252
828.25	268
828.504	260
828.758	256
829.012	258
829.266	260
829.52	260
829.774	260
830.029	252
830.283	244
830.537	250
830.791	256
831.045	238
831.299	248
831.553	250
831.807	242
832.061	244
832.315	242
832.568	242
832.822	242
833.076	234
833.33	220
833.584	226
833.838	236
834.092	224
834.345	228
834.599	232
834.853	212
835.107	228
835.36	214
835.614	242
835.868	214
836.122	216
836.375	204
836.629	224
836.883	214
837.136	226
837.39	210
837.643	212
837.897	208
838.151	204
838.404	202
838.658	216
838.911	226
839.165	202
839.418	200
839.672	194
839.925	210
840.179	206
840.432	196
840.686	202
840.939	210
841.192	200
841.446	190
841.699	200
841.952	198
842.206	186
842.459	182
842.712	208
842.966	186
843.219	200
843.472	184
843.725	178
843.979	178
844.232	184
844.485	184
844.738	174
844.991	178
845.244	172
845.497	180
845.75	190
846.004	184
846.257	182
846.51	162
846.763	182
847.016	162
847.269	182
847.522	166
847.775	190
848.028	176
848.281	146
848.534	164
848.786	188
849.039	170
849.292	168
849.545	170
849.798	158
850.051	180
850.303	152
850.556	160
850.809	152
851.062	152
851.314	164
851.567	170
851.82	152
852.073	142
852.325	152.02
852.578	146.548
852.831	137.612
853.083	157.327
853.336	153.334
853.588	153.41
853.841	155.15
854.093	147.188
854.346	140.113
854.598	139.387
854.851	135.05
855.103	144.966
855.356	143.63
855.608	145.867
855.861	129.356
856.113	138.065
856.366	143.867
856.618	138.036
856.87	136.38
857.123	139.045
857.352	128
857.606	142
857.859	140
858.113	132
858.367	142
858.621	142
858.875	138
859.128	130
859.382	130
859.636	128
859.889	128
860.143	132
860.397	130
860.65	118
860.904	120
861.158	124
861.411	126
861.665	128
861.918	126
862.172	118
862.425	134
862.679	132
862.932	120
863.186	132
863.439	126
863.693	126
863.946	114
864.2	114
864.453	124
864.707	118
864.96	120
865.213	106
865.467	116
865.72	120
865.973	102
866.227	116
866.48	106
866.733	120
866.987	120
867.24	120
867.493	108
867.746	116
867.999	114
868.253	116
868.506	106
868.759	114
869.012	116
869.265	112
869.518	112
869.771	108
870.025	100
870.278	114
870.531	112
870.784	114
871.037	102
871.29	106
871.543	116
871.796	114
872.049	94
872.302	106
872.555	100
872.808	100
873.06	102
873.313	106
873.566	104
873.819	102
874.072	102
874.325	96
874.578	98
874.83	98
875.083	98
875.336	96
875.589	92
875.841	98
876.094	96
876.347	92
876.6	88
876.852	94
877.105	114
877.358	82
877.61	96
877.863	102
878.115	94
878.368	102
878.621	88
878.873	96
879.126	86
879.378	88
879.631	84
879.883	90
880.136	84
880.388	98
880.641	88
880.893	96
881.145	82
881.398	88
881.65	92
881.902	86
882.155	88
882.407	84
882.659	88
882.912	92
883.164	82
883.416	86
883.669	86
883.921	90
884.173	80
884.425	90
884.677	82
884.93	84
885.182	82
885.434	86
885.686	76
885.938	82
886.19	74
886.442	72
886.694	82
886.946	82
887.198	86
887.45	74
887.702	84
887.954	82
888.206	66
888.458	78
888.71	72
888.962	80
889.214	78
889.466	80
889.718	78
889.969	84
890.221	76
890.473	68
890.725	78
890.977	72
891.228	74
891.48	64
891.732	66
891.983	72
892.235	66
892.487	70
892.738	72
892.99	76
893.242	74
893.493	64
893.745	68
893.996	74
894.248	60
894.5	70
894.751	74
895.003	62
895.254	64
895.505	66
895.757	74
896.008	70
896.26	74
896.511	62
896.763	56
897.014	70
897.265	64
897.517	58
897.768	66
898.019	64
898.27	66
898.522	56
898.773	60
899.024	58
899.275	58
899.527	62
899.778	52
899.979	56