File: PL_M5_180324_01.txt
#Acq. time (s)=	3
#Accumulations=	2
#Range (nm)=	520...900
#Windows=	8
#Auto scanning=	Off
#Autofocus=	Off
#AutoExposure=	Off
#Spike filter=	Multiple accum.
#Delay time (s)=	0
#Binning=	1
#Readout mode=	Signal
#DeNoise=	Off
#ICS correction=	Off
#Dark correction=	Off
#Inst. Process=	Off
#Detector temperature (°C)=	-59.98
#Instrument=	LabRAM HR Evol
#Detector=	Syncerity OE
#Objective=	x50_VIS
#Grating=	600 (500nm)
#ND Filter=	25%
#Laser=	514nm_Edge
#Hole=	199.981
#Range=	Auto
#StageXY=	Marzhauser
#StageZ=	Marzhauser
#X (µm)=	-94.9
#Y (µm)=	6302
#Z (µm)=	-9.9
#Full time(mm:ss)=	1:32
#Project=
#Sample=
#Site=
#Title=	PL_M5_180324
#Remark=
#Date=	28.03.2024 09:26
#Acquired=	28.03.2024 09:26:05
520.044	50
520.306	40
520.569	40
520.831	52
521.093	48
521.355	44
521.617	44
521.88	50
522.142	38
522.404	48
522.666	42
522.928	46
523.19	40
523.453	40
523.715	32
523.977	38
524.239	52
524.501	42
524.763	40
525.025	46
525.287	50
525.549	40
525.811	34
526.073	42
526.335	40
526.597	50
526.859	48
527.121	44
527.383	44
527.645	32
527.907	40
528.169	50
528.431	38
528.693	44
528.955	36
529.217	46
529.479	42
529.741	40
530.003	44
530.264	46
530.526	46
530.788	42
531.05	46
531.312	48
531.574	48
531.835	48
532.097	50
532.359	46
532.621	52
532.883	56
533.144	48
533.406	60
533.668	48
533.93	52
534.191	58
534.453	74
534.715	82
534.976	86
535.238	78
535.5	96
535.761	76
536.023	72
536.285	68
536.546	78
536.808	64
537.069	64
537.331	58
537.593	62
537.854	64
538.116	62
538.377	60
538.639	60
538.9	56
539.162	64
539.423	54
539.685	68
539.946	64
540.208	70
540.469	62
540.731	70
540.992	72
541.254	82
541.515	70
541.776	76
542.038	56
542.299	72
542.56	70
542.822	72
543.083	80
543.344	80
543.606	82
543.867	82
544.128	82
544.39	92
544.651	84
544.912	98
545.174	88
545.435	88
545.696	86
545.957	92
546.218	96
546.48	94
546.741	92
547.002	94
547.263	98
547.524	110
547.785	88
548.047	114
548.308	104
548.569	92
548.83	104
549.091	118
549.352	120
549.613	128
549.874	120
550.135	130
550.396	130
550.657	144
550.918	148
551.179	162
551.44	176
551.701	208
551.962	236
552.223	428
552.484	3410
552.745	22360
553.006	622
553.267	290
553.528	216
553.788	216
554.049	172
554.31	176
554.571	164
554.832	182
555.093	170
555.353	176
555.614	176
555.875	192
556.136	182
556.396	196
556.657	188
556.918	188
557.179	204
557.439	206
557.7	208
557.961	208
558.221	208
558.482	216
558.743	216
559.003	232
559.264	218
559.525	234
559.785	214
560.046	240
560.306	238
560.567	244
560.827	238
561.088	256
561.348	274
561.609	282
561.869	278
562.13	288
562.39	256
562.651	304
562.911	308
563.172	328
563.432	350
563.692	356
563.953	360
564.213	398
564.474	384
564.734	384
564.994	356
565.255	362
565.515	366
565.775	382
566.035	396
566.296	384
566.556	394
566.816	416
567.076	396
567.337	414
567.597	410
567.857	444
568.117	427.93
568.377	446.806
568.637	429.785
568.898	463.416
569.158	461.576
569.418	456.404
569.678	481.522
569.938	496.745
570.198	509.09
570.458	510.67
570.718	534.909
570.978	552.297
571.238	576.031
571.498	602.32
571.758	642.016
572.018	654.767
572.278	675.039
572.538	719.863
572.798	758.275
573.058	805.304
573.312	854
573.573	936
573.834	1000
574.095	1072
574.356	1168
574.617	1302
574.878	1402
575.139	1518
575.4	1572
575.661	1652
575.922	1692
576.183	1604
576.444	1586
576.705	1474
576.965	1366
577.226	1336
577.487	1296
577.748	1196
578.009	1158
578.27	1114
578.531	1116
578.791	1040
579.052	1034
579.313	1050
579.574	1070
579.835	1044
580.095	1068
580.356	1054
580.617	1070
580.878	1072
581.138	1028
581.399	1050
581.66	1044
581.92	1050
582.181	1106
582.442	1130
582.703	1100
582.963	1110
583.224	1150
583.484	1140
583.745	1176
584.006	1194
584.266	1196
584.527	1242
584.787	1270
585.048	1252
585.308	1366
585.569	1314
585.83	1388
586.09	1380
586.351	1400
586.611	1370
586.872	1434
587.132	1414
587.392	1422
587.653	1428
587.913	1460
588.174	1492
588.434	1454
588.695	1472
588.955	1504
589.215	1534
589.476	1546
589.736	1498
589.996	1544
590.257	1508
590.517	1522
590.777	1528
591.038	1528
591.298	1472
591.558	1480
591.818	1468
592.079	1450
592.339	1470
592.599	1482
592.859	1486
593.12	1432
593.38	1432
593.64	1494
593.9	1460
594.16	1454
594.42	1478
594.68	1504
594.941	1462
595.201	1512
595.461	1542
595.721	1576
595.981	1570
596.241	1562
596.501	1638
596.761	1656
597.021	1636
597.281	1654
597.541	1638
597.801	1706
598.061	1718
598.321	1642
598.581	1656
598.841	1698
599.101	1666
599.361	1680
599.62	1662
599.88	1710
600.14	1676
600.4	1684
600.66	1678
600.92	1690
601.18	1706
601.439	1714
601.699	1690
601.959	1722
602.219	1690
602.478	1710
602.738	1736
602.998	1702
603.258	1718
603.517	1748
603.777	1780
604.037	1774
604.296	1734
604.556	1768
604.816	1796
605.075	1758
605.335	1764
605.594	1732
605.854	1768
606.114	1772
606.373	1770
606.633	1786
606.892	1778
607.152	1774
607.411	1750
607.671	1814
607.93	1766
608.19	1856
608.449	1818
608.709	1822
608.968	1834
609.228	1874
609.487	1866
609.746	1884
610.006	1894
610.265	1920
610.524	1926
610.784	1896
611.043	1914
611.302	1888
611.562	1924
611.821	1930
612.08	1932
612.339	1990
612.599	1982
612.858	2022
613.117	2050
613.376	2018
613.635	2076
613.895	2078
614.154	2038
614.413	2094
614.672	2172
614.931	2186
615.19	2150
615.449	2146
615.709	2214
615.968	2194
616.227	2206.94
616.486	2202.54
616.745	2261.77
617.004	2237.85
617.263	2244.22
617.522	2293.33
617.781	2315.43
618.04	2296.15
618.299	2328.8
618.557	2345.7
618.816	2309.43
619.075	2355.17
619.334	2379.37
619.593	2391.03
619.852	2416.56
620.111	2413.24
620.37	2413.59
620.628	2399.13
620.887	2415.76
621.146	2457.62
621.373	2486
621.633	2438
621.893	2406
622.153	2424
622.413	2454
622.673	2506
622.932	2442
623.192	2512
623.452	2410
623.712	2542
623.972	2546
624.232	2494
624.492	2532
624.751	2494
625.011	2616
625.271	2580
625.531	2600
625.791	2618
626.05	2644
626.31	2588
626.57	2594
626.83	2634
627.089	2710
627.349	2672
627.609	2678
627.868	2682
628.128	2722
628.388	2732
628.647	2820
628.907	2790
629.167	2840
629.426	2834
629.686	2760
629.945	2882
630.205	2856
630.465	2914
630.724	2904
630.984	2914
631.243	3002
631.503	2904
631.762	2958
632.022	2990
632.281	3018
632.541	3038
632.8	3072
633.06	3096
633.319	3128
633.579	3180
633.838	3160
634.097	3200
634.357	3206
634.616	3278
634.876	3296
635.135	3404
635.394	3454
635.654	3490
635.913	3536
636.172	3720
636.431	3762
636.691	3926
636.95	4136
637.209	4368
637.469	4562
637.728	4844
637.987	5060
638.246	5094
638.505	5062
638.765	4992
639.024	4834
639.283	4760
639.542	4596
639.801	4472
640.06	4412
640.319	4288
640.578	4186
640.838	4136
641.097	4122
641.356	4114
641.615	4056
641.874	4088
642.133	4076
642.392	4094
642.651	4110
642.91	4094
643.169	4086
643.428	4148
643.687	4096
643.946	4122
644.205	4124
644.463	4188
644.722	4238
644.981	4190
645.24	4192
645.499	4320
645.758	4206
646.017	4316
646.275	4278
646.534	4320
646.793	4392
647.052	4270
647.31	4320
647.569	4444
647.828	4410
648.087	4414
648.345	4424
648.604	4452
648.863	4458
649.121	4472
649.38	4472
649.639	4636
649.897	4550
650.156	4580
650.415	4706
650.673	4748
650.932	4702
651.19	4708
651.449	4856
651.707	4804
651.966	4844
652.224	4856
652.483	4922
652.741	4934
653	4978
653.258	5044
653.517	5056
653.775	5120
654.034	5192
654.292	5154
654.55	5234
654.809	5356
655.067	5324
655.326	5424
655.584	5440
655.842	5552
656.1	5586
656.359	5640
656.617	5694
656.875	5834
657.134	5802
657.392	5832
657.65	5920
657.908	5938
658.166	5962
658.425	6076
658.683	6096
658.941	6126
659.199	6160
659.457	6186
659.715	6184
659.973	6234
660.231	6142
660.49	6260
660.748	6210
661.006	6264
661.264	6168
661.522	6240
661.78	6158
662.038	6240
662.296	6284
662.554	6222
662.811	6140
663.069	6214
663.327	6244
663.585	6212
663.843	6246.21
664.101	6227.66
664.359	6218.96
664.617	6262.21
664.874	6233.12
665.132	6273.05
665.39	6232.35
665.648	6170.13
665.906	6237.54
666.163	6265.45
666.421	6198.1
666.679	6235.69
666.937	6209.51
667.194	6237.8
667.452	6228.67
667.71	6215.86
667.967	6258.02
668.225	6203.41
668.482	6190.34
668.74	6196.18
668.987	6320
669.245	6328
669.504	6196
669.763	6184
670.022	6234
670.281	6276
670.539	6162
670.798	6216
671.057	6234
671.316	6266
671.575	6338
671.833	6260
672.092	6304
672.351	6396
672.609	6324
672.868	6374
673.127	6404
673.385	6328
673.644	6360
673.903	6382
674.161	6468
674.42	6500
674.678	6500
674.937	6602
675.195	6604
675.454	6620
675.713	6636
675.971	6596
676.23	6614
676.488	6698
676.747	6720
677.005	6664
677.263	6680
677.522	6690
677.78	6712
678.039	6706
678.297	6582
678.556	6708
678.814	6718
679.072	6692
679.331	6744
679.589	6710
679.847	6760
680.106	6714
680.364	6688
680.622	6726
680.881	6846
681.139	6872
681.397	6856
681.656	6860
681.914	6866
682.172	6892
682.43	6852
682.688	6864
682.947	6914
683.205	6954
683.463	6990
683.721	6932
683.979	6830
684.237	7018
684.495	6908
684.754	6866
685.012	6888
685.27	6854
685.528	6732
685.786	6874
686.044	6786
686.302	6852
686.56	6848
686.818	6778
687.076	6798
687.334	6754
687.592	6716
687.85	6740
688.108	6726
688.366	6844
688.623	6788
688.881	6756
689.139	6622
689.397	6680
689.655	6694
689.913	6772
690.171	6704
690.428	6622
690.686	6640
690.944	6630
691.202	6528
691.459	6568
691.717	6554
691.975	6456
692.233	6558
692.49	6458
692.748	6504
693.006	6454
693.263	6450
693.521	6448
693.779	6440
694.036	6374
694.294	6352
694.552	6438
694.809	6410
695.067	6372
695.324	6350
695.582	6286
695.839	6272
696.097	6332
696.354	6324
696.612	6268
696.869	6282
697.127	6176
697.384	6150
697.642	6206
697.899	6162
698.156	6214
698.414	6138
698.671	6092
698.928	6070
699.186	6046
699.443	6068
699.7	6038
699.958	6108
700.215	5972
700.472	5960
700.73	5996
700.987	6040
701.244	5958
701.501	5944
701.758	5968
702.016	5946
702.273	5954
702.53	5994
702.787	5888
703.044	5936
703.301	5918
703.558	5828
703.816	5860
704.073	5950
704.33	5854
704.587	5868
704.844	5840
705.101	5818
705.358	5776
705.615	5784
705.872	5778
706.129	5700
706.386	5758
706.643	5670
706.899	5668
707.156	5684
707.413	5578
707.67	5616
707.927	5590
708.184	5544
708.441	5548
708.697	5518
708.954	5560
709.211	5534
709.468	5428
709.725	5526
709.981	5440
710.238	5484
710.495	5434
710.751	5428
711.008	5396
711.265	5362.68
711.521	5391.29
711.778	5364.62
712.035	5345.16
712.291	5241.7
712.548	5267.92
712.804	5245.53
713.061	5265.46
713.317	5235.59
713.574	5218.73
713.831	5174.68
714.087	5124.49
714.343	5101.45
714.6	5081.95
714.856	5053.05
715.113	5038.74
715.369	5054.88
715.626	4998.2
715.882	5005.13
716.138	4911.24
716.395	4954.45
716.639	4926
716.897	4950
717.155	4844
717.412	4872
717.67	4818
717.927	4832
718.185	4802
718.443	4758
718.7	4790
718.958	4820
719.215	4774
719.473	4670
719.73	4720
719.988	4646
720.245	4618
720.503	4592
720.76	4586
721.018	4562
721.275	4536
721.532	4528
721.79	4478
722.047	4492
722.305	4446
722.562	4418
722.819	4366
723.077	4386
723.334	4376
723.591	4238
723.849	4234
724.106	4310
724.363	4282
724.621	4328
724.878	4272
725.135	4164
725.392	4184
725.65	4138
725.907	4154
726.164	4160
726.421	3996
726.678	4108
726.935	4054
727.193	3998
727.45	3996
727.707	3968
727.964	3886
728.221	3886
728.478	3916
728.735	3872
728.992	3848
729.249	3836
729.506	3764
729.763	3794
730.02	3740
730.277	3734
730.534	3712
730.791	3636
731.048	3710
731.305	3666
731.562	3608
731.819	3526
732.076	3556
732.333	3582
732.589	3518
732.846	3528
733.103	3560
733.36	3510
733.617	3524
733.873	3468
734.13	3476
734.387	3500
734.644	3508
734.901	3520
735.157	3498
735.414	3444
735.671	3430
735.927	3484
736.184	3468
736.441	3440
736.697	3482
736.954	3438
737.211	3448
737.467	3478
737.724	3474
737.98	3460
738.237	3466
738.493	3422
738.75	3384
739.006	3354
739.263	3396
739.519	3396
739.776	3320
740.032	3276
740.289	3274
740.545	3252
740.802	3216
741.058	3238
741.314	3204
741.571	3266
741.827	3174
742.083	3194
742.34	3130
742.596	3146
742.852	3130
743.109	3110
743.365	3094
743.621	3070
743.878	3060
744.134	3056
744.39	3006
744.646	2998
744.902	3032
745.159	2950
745.415	2928
745.671	2944
745.927	2920
746.183	2910
746.439	2884
746.695	2876
746.951	2860
747.207	2898
747.463	2864
747.719	2872
747.975	2824
748.231	2788
748.487	2810
748.743	2804
748.999	2788
749.255	2806
749.511	2768
749.767	2760
750.023	2770
750.279	2738
750.535	2744
750.791	2686
751.046	2660
751.302	2672
751.558	2662
751.814	2606
752.07	2606
752.325	2614
752.581	2586
752.837	2576
753.092	2554
753.348	2540
753.604	2472
753.859	2474
754.115	2518
754.371	2510
754.626	2454
754.882	2448
755.138	2442
755.393	2412
755.649	2370
755.904	2356
756.16	2386
756.415	2348
756.671	2382
756.926	2348
757.182	2336
757.437	2286
757.693	2312
757.948	2320
758.203	2270
758.459	2300
758.714	2238.13
758.97	2277.06
759.225	2254.77
759.48	2222.85
759.736	2190.49
759.991	2213.69
760.246	2180.22
760.501	2171.54
760.757	2140.66
761.012	2120.88
761.267	2120.54
761.522	2131.82
761.777	2143.77
762.033	2130.85
762.288	2092.96
762.543	2075.38
762.798	2055.29
763.053	2080.96
763.308	2054.66
763.563	1994.67
763.78	2010
764.037	2004
764.293	1978
764.55	1996
764.806	1956
765.062	1956
765.319	1952
765.575	1914
765.831	1906
766.088	1904
766.344	1948
766.6	1886
766.857	1924
767.113	1910
767.369	1862
767.625	1854
767.882	1826
768.138	1822
768.394	1798
768.65	1816
768.906	1776
769.163	1742
769.419	1734
769.675	1780
769.931	1738
770.187	1710
770.443	1682
770.699	1678
770.955	1684
771.211	1656
771.467	1682
771.723	1622
771.979	1628
772.235	1628
772.491	1622
772.747	1628
773.003	1618
773.259	1576
773.515	1536
773.771	1522
774.027	1562
774.283	1514
774.539	1538
774.795	1526
775.05	1468
775.306	1472
775.562	1488
775.818	1436
776.074	1472
776.329	1488
776.585	1458
776.841	1454
777.097	1442
777.352	1398
777.608	1356
777.864	1432
778.12	1376
778.375	1370
778.631	1314
778.886	1380
779.142	1326
779.398	1328
779.653	1350
779.909	1328
780.164	1318
780.42	1302
780.675	1296
780.931	1262
781.187	1298
781.442	1260
781.698	1230
781.953	1240
782.208	1254
782.464	1234
782.719	1200
782.975	1232
783.23	1210
783.485	1162
783.741	1152
783.996	1156
784.252	1150
784.507	1148
784.762	1114
785.017	1162
785.273	1148
785.528	1116
785.783	1122
786.038	1130
786.294	1072
786.549	1100
786.804	1092
787.059	1082
787.314	1062
787.57	1072
787.825	1030
788.08	1052
788.335	1038
788.59	1004
788.845	1024
789.1	1028
789.355	1000
789.61	978
789.865	972
790.12	994
790.375	946
790.63	948
790.885	952
791.14	934
791.395	920
791.65	948
791.905	926
792.16	914
792.414	896
792.669	906
792.924	910
793.179	892
793.434	870
793.689	910
793.943	872
794.198	866
794.453	884
794.708	868
794.962	876
795.217	846
795.472	836
795.726	840
795.981	820
796.236	766
796.49	800
796.745	806
796.999	834
797.254	796
797.508	796
797.763	786
798.018	782
798.272	786
798.526	770
798.781	754
799.035	746
799.29	744
799.544	722
799.799	730
800.053	754
800.307	728
800.562	736
800.816	694
801.07	702
801.325	676
801.579	670
801.833	700
802.088	668
802.342	666
802.596	658
802.85	664
803.105	670
803.359	678
803.613	636
803.867	642
804.121	640
804.375	642
804.63	608
804.884	626
805.138	624
805.392	612
805.646	616.066
805.9	583.858
806.154	610.878
806.408	632.455
806.662	596.198
806.916	602.746
807.17	600.539
807.424	582.328
807.678	594.266
807.931	577.413
808.185	575.999
808.439	573.166
808.693	564.529
808.947	559.813
809.201	557.314
809.454	551.465
809.708	547.825
809.962	556.742
810.216	526.23
810.469	533.225
810.678	552
810.933	548
811.188	520
811.443	516
811.699	512
811.954	514
812.209	530
812.464	508
812.719	474
812.974	524
813.229	478
813.484	486
813.739	474
813.994	490
814.249	470
814.504	482
814.759	474
815.014	468
815.268	454
815.523	460
815.778	448
816.033	462
816.288	438
816.543	456
816.798	454
817.052	460
817.307	446
817.562	448
817.817	456
818.071	438
818.326	426
818.581	432
818.836	436
819.09	414
819.345	416
819.6	430
819.854	408
820.109	402
820.364	430
820.618	436
820.873	414
821.127	398
821.382	414
821.637	390
821.891	404
822.146	380
822.4	366
822.655	384
822.909	376
823.164	378
823.418	374
823.672	350
823.927	374
824.181	372
824.436	346
824.69	354
824.944	366
825.199	394
825.453	364
825.707	346
825.962	344
826.216	352
826.47	334
826.725	340
826.979	346
827.233	352
827.487	330
827.741	366
827.996	328
828.25	326
828.504	324
828.758	326
829.012	328
829.266	324
829.52	326
829.774	312
830.029	330
830.283	314
830.537	320
830.791	316
831.045	306
831.299	308
831.553	294
831.807	292
832.061	302
832.315	304
832.568	298
832.822	314
833.076	284
833.33	296
833.584	280
833.838	276
834.092	280
834.345	286
834.599	284
834.853	272
835.107	280
835.36	284
835.614	276
835.868	280
836.122	262
836.375	284
836.629	266
836.883	284
837.136	276
837.39	288
837.643	268
837.897	260
838.151	278
838.404	262
838.658	260
838.911	260
839.165	252
839.418	266
839.672	242
839.925	250
840.179	234
840.432	250
840.686	250
840.939	238
841.192	240
841.446	240
841.699	226
841.952	238
842.206	252
842.459	242
842.712	228
842.966	250
843.219	236
843.472	244
843.725	238
843.979	242
844.232	238
844.485	238
844.738	232
844.991	226
845.244	224
845.497	238
845.75	222
846.004	222
846.257	214
846.51	222
846.763	220
847.016	232
847.269	232
847.522	222
847.775	200
848.028	192
848.281	218
848.534	218
848.786	218
849.039	220
849.292	210
849.545	200
849.798	190
850.051	216
850.303	202
850.556	204
850.809	200
851.062	196
851.314	176
851.567	206
851.82	196
852.073	196
852.325	181.991
852.578	199.231
852.831	191.171
853.083	196.157
853.336	170.988
853.588	189.109
853.841	194.865
854.093	188.573
854.346	195.887
854.598	181.861
854.851	179.477
855.103	172.374
855.356	175.297
855.608	180.274
855.861	179.328
856.113	168.33
856.366	176.739
856.618	170.095
856.87	169.668
857.123	175.729
857.352	162
857.606	188
857.859	174
858.113	174
858.367	156
858.621	174
858.875	158
859.128	162
859.382	158
859.636	158
859.889	162
860.143	168
860.397	168
860.65	166
860.904	158
861.158	154
861.411	150
861.665	158
861.918	176
862.172	164
862.425	154
862.679	144
862.932	152
863.186	150
863.439	140
863.693	162
863.946	156
864.2	154
864.453	156
864.707	158
864.96	142
865.213	148
865.467	156
865.72	138
865.973	128
866.227	144
866.48	146
866.733	144
866.987	134
867.24	140
867.493	124
867.746	146
867.999	122
868.253	130
868.506	154
868.759	134
869.012	138
869.265	134
869.518	126
869.771	134
870.025	138
870.278	128
870.531	130
870.784	132
871.037	140
871.29	132
871.543	128
871.796	126
872.049	126
872.302	118
872.555	120
872.808	116
873.06	126
873.313	132
873.566	128
873.819	116
874.072	118
874.325	118
874.578	132
874.83	120
875.083	112
875.336	122
875.589	120
875.841	128
876.094	102
876.347	126
876.6	122
876.852	116
877.105	106
877.358	114
877.61	112
877.863	122
878.115	106
878.368	106
878.621	110
878.873	120
879.126	108
879.378	106
879.631	116
879.883	100
880.136	114
880.388	106
880.641	114
880.893	98
881.145	106
881.398	110
881.65	106
881.902	110
882.155	102
882.407	104
882.659	118
882.912	102
883.164	102
883.416	104
883.669	102
883.921	102
884.173	106
884.425	98
884.677	108
884.93	92
885.182	98
885.434	100
885.686	98
885.938	92
886.19	88
886.442	96
886.694	110
886.946	96
887.198	96
887.45	94
887.702	100
887.954	106
888.206	94
888.458	84
888.71	96
888.962	90
889.214	78
889.466	86
889.718	90
889.969	90
890.221	78
890.473	80
890.725	96
890.977	92
891.228	86
891.48	78
891.732	96
891.983	92
892.235	80
892.487	90
892.738	94
892.99	78
893.242	84
893.493	84
893.745	76
893.996	82
894.248	72
894.5	78
894.751	80
895.003	90
895.254	84
895.505	80
895.757	82
896.008	78
896.26	90
896.511	76
896.763	78
897.014	72
897.265	82
897.517	78
897.768	80
898.019	74
898.27	76
898.522	74
898.773	80
899.024	66
899.275	72
899.527	76
899.778	78
899.979	62