File: PL_M3_280424_01.txt
#Acq. time (s)=	3
#Accumulations=	2
#Range (nm)=	520...900
#Windows=	8
#Auto scanning=	Off
#Autofocus=	Off
#AutoExposure=	Off
#Spike filter=	Off
#Delay time (s)=	0
#Binning=	1
#Readout mode=	Signal
#DeNoise=	Off
#ICS correction=	Off
#Dark correction=	Off
#Inst. Process=	Off
#Detector temperature (°C)=	-59.98
#Instrument=	LabRAM HR Evol
#Detector=	Syncerity OE
#Objective=	x50_VIS
#Grating=	600 (500nm)
#ND Filter=	25%
#Laser=	514nm_Edge
#Hole=	199.981
#Range=	Visible
#StageXY=	Marzhauser
#StageZ=	Marzhauser
#X (µm)=	-0.3
#Y (µm)=	-9993.1
#Z (µm)=	-259.4
#Full time(mm:ss)=	1:32
#Project=
#Sample=
#Site=
#Title=	PL_M3_280424
#Remark=
#Date=	06.05.2024 16:32
#Acquired=	06.05.2024 16:32:18
520.044	87
520.306	72
520.569	93
520.831	94
521.093	85
521.355	86
521.617	81
521.88	78
522.142	91
522.404	81
522.666	86
522.928	83
523.19	85
523.453	75
523.715	78
523.977	86
524.239	79
524.501	80
524.763	72
525.025	75
525.287	69
525.549	90
525.811	71
526.073	83
526.335	77
526.597	73
526.859	73
527.121	71
527.383	81
527.645	65
527.907	66
528.169	83
528.431	78
528.693	75
528.955	69
529.217	73
529.479	87
529.741	82
530.003	77
530.264	78
530.526	71
530.788	75
531.05	75
531.312	83
531.574	86
531.835	82
532.097	74
532.359	77
532.621	84
532.883	94
533.144	76
533.406	88
533.668	100
533.93	96
534.191	107
534.453	115
534.715	128
534.976	152
535.238	149
535.5	162
535.761	140
536.023	136
536.285	105
536.546	108
536.808	106
537.069	114
537.331	103
537.593	102
537.854	108
538.116	97
538.377	108
538.639	101
538.9	111
539.162	113
539.423	113
539.685	102
539.946	112
540.208	121
540.469	116
540.731	120
540.992	127
541.254	122
541.515	124
541.776	120
542.038	129
542.299	130
542.56	131
542.822	119
543.083	132
543.344	134
543.606	133
543.867	132
544.128	154
544.39	145
544.651	156
544.912	151
545.174	151
545.435	163
545.696	145
545.957	154
546.218	164
546.48	169
546.741	165
547.002	174
547.263	170
547.524	187
547.785	190
548.047	197
548.308	186
548.569	193
548.83	193
549.091	188
549.352	206
549.613	217
549.874	214
550.135	221
550.396	225
550.657	236
550.918	238
551.179	259
551.44	268
551.701	307
551.962	373
552.223	542
552.484	3250
552.745	35779
553.006	935
553.267	428
553.528	362
553.788	332
554.049	316
554.31	307
554.571	299
554.832	318
555.093	307
555.353	299
555.614	303
555.875	320
556.136	325
556.396	330
556.657	331
556.918	364
557.179	357
557.439	370
557.7	366
557.961	378
558.221	378
558.482	382
558.743	389
559.003	405
559.264	393
559.525	404
559.785	406
560.046	424
560.306	441
560.567	430
560.827	453
561.088	481
561.348	467
561.609	486
561.869	512
562.13	507
562.39	543
562.651	556
562.911	562
563.172	574
563.432	606
563.692	638
563.953	678
564.213	726
564.474	726
564.734	700
564.994	700
565.255	634
565.515	684
565.775	668
566.035	679
566.296	686
566.556	707
566.816	706
567.076	756
567.337	730
567.597	739
567.857	769
568.117	771.92
568.377	783.574
568.637	808.53
568.898	830.349
569.158	836.199
569.418	860.487
569.678	885.626
569.938	888.718
570.198	928.911
570.458	938.8
570.718	979.725
570.978	1007.83
571.238	1048.8
571.498	1082.37
571.758	1146.12
572.018	1204.65
572.278	1268.97
572.538	1322.26
572.798	1368.27
573.058	1448.2
573.312	1510
573.573	1667
573.834	1737
574.095	1916
574.356	2058
574.617	2218
574.878	2409
575.139	2618
575.4	2856
575.661	2975
575.922	3044
576.183	3108
576.444	2934
576.705	2837
576.965	2756
577.226	2573
577.487	2410
577.748	2291
578.009	2200
578.27	2068
578.531	1999
578.791	1939
579.052	1923
579.313	1948
579.574	1913
579.835	1920
580.095	1932
580.356	1950
580.617	1897
580.878	1882
581.138	1904
581.399	1940
581.66	1927
581.92	1971
582.181	1957
582.442	2010
582.703	2013
582.963	2056
583.224	2044
583.484	2051
583.745	2104
584.006	2140
584.266	2174
584.527	2233
584.787	2288
585.048	2315
585.308	2345
585.569	2392
585.83	2382
586.09	2470
586.351	2499
586.611	2541
586.872	2579
587.132	2579
587.392	2582
587.653	2610
587.913	2590
588.174	2642
588.434	2650
588.695	2648
588.955	2702
589.215	2734
589.476	2759
589.736	2746
589.996	2713
590.257	2730
590.517	2749
590.777	2721
591.038	2708
591.298	2721
591.558	2733
591.818	2704
592.079	2614
592.339	2651
592.599	2702
592.859	2624
593.12	2673
593.38	2691
593.64	2636
593.9	2669
594.16	2734
594.42	2696
594.68	2716
594.941	2779
595.201	2796
595.461	2814
595.721	2822
595.981	2871
596.241	2931
596.501	2925
596.761	3059
597.021	3015
597.281	3063
597.541	3108
597.801	3112
598.061	3151
598.321	3116
598.581	3106
598.841	3158
599.101	3118
599.361	3155
599.62	3143
599.88	3151
600.14	3141
600.4	3185
600.66	3138
600.92	3157
601.18	3123
601.439	3179
601.699	3151
601.959	3160
602.219	3144
602.478	3197
602.738	3167
602.998	3187
603.258	3247
603.517	3253
603.777	3201
604.037	3241
604.296	3272
604.556	3264
604.816	3313
605.075	3335
605.335	3287
605.594	3354
605.854	3328
606.114	3299
606.373	3378
606.633	3356
606.892	3350
607.152	3328
607.411	3322
607.671	3376
607.93	3401
608.19	3358
608.449	3377
608.709	3388
608.968	3481
609.228	3467
609.487	3485
609.746	3504
610.006	3531
610.265	3529
610.524	3505
610.784	3547
611.043	3544
611.302	3542
611.562	3594
611.821	3644
612.08	3663
612.339	3629
612.599	3719
612.858	3684
613.117	3726
613.376	3709
613.635	3767
613.895	3790
614.154	3817
614.413	3903
614.672	3925
614.931	3953
615.19	3953
615.449	3965
615.709	4012
615.968	4085
616.227	4099.12
616.486	4105.58
616.745	4142.07
617.004	4138.8
617.263	4108.91
617.522	4188.86
617.781	4154.12
618.04	4168.49
618.299	4275.16
618.557	4210.94
618.816	4264.67
619.075	4274.97
619.334	4336.01
619.593	4327.9
619.852	4325.84
620.111	4344.19
620.37	4344.13
620.628	4366.9
620.887	4350.88
621.146	4413.77
621.373	4296
621.633	4445
621.893	4420
622.153	4436
622.413	4397
622.673	4467
622.932	4522
623.192	4548
623.452	4503
623.712	4528
623.972	4513
624.232	4553
624.492	4518
624.751	4596
625.011	4551
625.271	4631
625.531	4656
625.791	4625
626.05	4645
626.31	4605
626.57	4691
626.83	4762
627.089	4710
627.349	4771
627.609	4776
627.868	4800
628.128	4850
628.388	4816
628.647	4858
628.907	4933
629.167	4942
629.426	5001
629.686	4973
629.945	4997
630.205	5032
630.465	5028
630.724	5098
630.984	5087
631.243	5155
631.503	5184
631.762	5196
632.022	5262
632.281	5294
632.541	5363
632.8	5335
633.06	5430
633.319	5430
633.579	5458
633.838	5489
634.097	5621
634.357	5615
634.616	5661
634.876	5758
635.135	5797
635.394	5851
635.654	5932
635.913	6049
636.172	6125
636.431	6352
636.691	6481
636.95	6648
637.209	6996
637.469	7331
637.728	7763
637.987	8094
638.246	8435
638.505	8474
638.765	8427
639.024	8312
639.283	8003
639.542	7754
639.801	7484
640.06	7436
640.319	7249
640.578	7149
640.838	7070
641.097	6921
641.356	6896
641.615	6935
641.874	6929
642.133	6910
642.392	6902
642.651	6981
642.91	6868
643.169	6945
643.428	6905
643.687	6976
643.946	6886
644.205	6919
644.463	6986
644.722	7010
644.981	7034
645.24	7036
645.499	6988
645.758	7093
646.017	7154
646.275	7128
646.534	7170
646.793	7173
647.052	7250
647.31	7197
647.569	7241
647.828	7330
648.087	7391
648.345	7329
648.604	7383
648.863	7391
649.121	7574
649.38	7475
649.639	7509
649.897	7632
650.156	7690
650.415	7729
650.673	7741
650.932	7771
651.19	7882
651.449	7841
651.707	8017
651.966	7967
652.224	8046
652.483	8043
652.741	8230
653	8159
653.258	8236
653.517	8234
653.775	8255
654.034	8392
654.292	8490
654.55	8509
654.809	8584
655.067	8718
655.326	8841
655.584	8824
655.842	8954
656.1	9109
656.359	9113
656.617	9217
656.875	9282
657.134	9299
657.392	9432
657.65	9563
657.908	9620
658.166	9594
658.425	9746
658.683	9828
658.941	9872
659.199	9918
659.457	9897
659.715	9999
659.973	9868
660.231	9953
660.49	9981
660.748	10003
661.006	9975
661.264	9976
661.522	9947
661.78	10029
662.038	10008
662.296	9963
662.554	9948
662.811	9973
663.069	10020
663.327	9994
663.585	10027
663.843	10094.8
664.101	10038.6
664.359	10001.5
664.617	10057.4
664.874	10007.7
665.132	10012.9
665.39	10068.3
665.648	10015.7
665.906	10020.3
666.163	10025.7
666.421	9998.52
666.679	10020.3
666.937	10032.8
667.194	10075.1
667.452	10029.5
667.71	10009
667.967	10021.1
668.225	10064
668.482	10007.2
668.74	10042.4
668.987	10031
669.245	10015
669.504	10020
669.763	9997
670.022	10045
670.281	10029
670.539	10012
670.798	10014
671.057	10035
671.316	10058
671.575	10064
671.833	9970
672.092	10105
672.351	10136
672.609	10092
672.868	10139
673.127	10094
673.385	10208
673.644	10253
673.903	10340
674.161	10350
674.42	10368
674.678	10475
674.937	10486
675.195	10505
675.454	10636
675.713	10622
675.971	10621
676.23	10570
676.488	10527
676.747	10655
677.005	10594
677.263	10692
677.522	10630
677.78	10726
678.039	10706
678.297	10682
678.556	10697
678.814	10698
679.072	10676
679.331	10635
679.589	10718
679.847	10615
680.106	10741
680.364	10644
680.622	10803
680.881	10800
681.139	10852
681.397	10861
681.656	10997
681.914	10999
682.172	10953
682.43	11000
682.688	11071
682.947	10913
683.205	11031
683.463	11084
683.721	11045
683.979	11028
684.237	11093
684.495	11023
684.754	11057
685.012	11039
685.27	10835
685.528	10844
685.786	10862
686.044	10934
686.302	10868
686.56	10770
686.818	10781
687.076	10836
687.334	10837
687.592	10850
687.85	10771
688.108	10758
688.366	10727
688.623	10772
688.881	10759
689.139	10681
689.397	10701
689.655	10712
689.913	10745
690.171	10687
690.428	10667
690.686	10592
690.944	10586
691.202	10485
691.459	10403
691.717	10463
691.975	10418
692.233	10406
692.49	10387
692.748	10311
693.006	10299
693.263	10295
693.521	10283
693.779	10207
694.036	10328
694.294	10233
694.552	10181
694.809	10190
695.067	10297
695.324	10169
695.582	10135
695.839	10156
696.097	10110
696.354	10021
696.612	10069
696.869	10003
697.127	9999
697.384	9875
697.642	9841
697.899	9853
698.156	9767
698.414	9713
698.671	9758
698.928	9636
699.186	9575
699.443	9555
699.7	9563
699.958	9552
700.215	9602
700.472	9554
700.73	9616
700.987	9410
701.244	9535
701.501	9527
701.758	9550
702.016	9495
702.273	9493
702.53	9574
702.787	9492
703.044	9491
703.301	9578
703.558	9478
703.816	9445
704.073	9525
704.33	9521
704.587	9361
704.844	9356
705.101	9383
705.358	9243
705.615	9303
705.872	9213
706.129	9152
706.386	9129
706.643	9138
706.899	9060
707.156	8968
707.413	8957
707.67	9011
707.927	8948
708.184	8851
708.441	8941
708.697	8779
708.954	8885
709.211	8842
709.468	8748
709.725	8845
709.981	8802
710.238	8715
710.495	8803
710.751	8560
711.008	8699
711.265	8703.77
711.521	8629.42
711.778	8609.12
712.035	8622.28
712.291	8517.07
712.548	8526.6
712.804	8417.47
713.061	8433.7
713.317	8350.93
713.574	8339
713.831	8300.72
714.087	8359.92
714.343	8170.71
714.6	8155.69
714.856	8152.46
715.113	8115.97
715.369	8063.87
715.626	7998.77
715.882	7963.24
716.138	7937.01
716.395	7900.58
716.639	7887
716.897	7850
717.155	7784
717.412	7788
717.67	7842
717.927	7748
718.185	7690
718.443	7672
718.7	7786
718.958	7633
719.215	7545
719.473	7577
719.73	7505
719.988	7475
720.245	7391
720.503	7416
720.76	7324
721.018	7493
721.275	7301
721.532	7231
721.79	7250
722.047	7156
722.305	7192
722.562	7120
722.819	7071
723.077	6987
723.334	7008
723.591	6897
723.849	6883
724.106	6893
724.363	6893
724.621	6754
724.878	6797
725.135	6742
725.392	6713
725.65	6717
725.907	6707
726.164	6686
726.421	6641
726.678	6599
726.935	6606
727.193	6478
727.45	6489
727.707	6393
727.964	6421
728.221	6338
728.478	6283
728.735	6224
728.992	6230
729.249	6103
729.506	6117
729.763	6121
730.02	5995
730.277	6006
730.534	5972
730.791	5914
731.048	5907
731.305	5891
731.562	5933
731.819	5861
732.076	5764
732.333	5790
732.589	5769
732.846	5806
733.103	5749
733.36	5725
733.617	5749
733.873	5694
734.13	5637
734.387	5658
734.644	5618
734.901	5581
735.157	5615
735.414	5605
735.671	5587
735.927	5621
736.184	5573
736.441	5560
736.697	5652
736.954	5581
737.211	5590
737.467	5593
737.724	5584
737.98	5603
738.237	5547
738.493	5651
738.75	5669
739.006	5533
739.263	5485
739.519	5496
739.776	5467
740.032	5438
740.289	5293
740.545	5326
740.802	5269
741.058	5273
741.314	5240
741.571	5168
741.827	5195
742.083	5131
742.34	5113
742.596	5051
742.852	5067
743.109	5018
743.365	4951
743.621	4987
743.878	4948
744.134	4958
744.39	4905
744.646	4874
744.902	4836
745.159	4833
745.415	4820
745.671	4784
745.927	4777
746.183	4730
746.439	4734
746.695	4673
746.951	4735
747.207	4673
747.463	4662
747.719	4602
747.975	4568
748.231	4575
748.487	4535
748.743	4563
748.999	4485
749.255	4543
749.511	4466
749.767	4536
750.023	4501
750.279	4409
750.535	4400
750.791	4408
751.046	4380
751.302	4367
751.558	4355
751.814	4294
752.07	4312
752.325	4244
752.581	4225
752.837	4175
753.092	4160
753.348	4134
753.604	4152
753.859	4114
754.115	4085
754.371	4058
754.626	4047
754.882	4014
755.138	4001
755.393	3959
755.649	3946
755.904	3927
756.16	3906
756.415	3814
756.671	3886
756.926	3818
757.182	3831
757.437	3777
757.693	3832
757.948	3755
758.203	3739
758.459	3752
758.714	3744.82
758.97	3720.85
759.225	3687.92
759.48	3687.82
759.736	3623.95
759.991	3642.69
760.246	3606.04
760.501	3614.52
760.757	3527.83
761.012	3542.92
761.267	3483.62
761.522	3495.65
761.777	3505.94
762.033	3500.23
762.288	3446.99
762.543	3412.03
762.798	3428.21
763.053	3389.19
763.308	3365.87
763.563	3316.54
763.78	3317
764.037	3307
764.293	3279
764.55	3287
764.806	3216
765.062	3218
765.319	3170
765.575	3187
765.831	3215
766.088	3195
766.344	3107
766.6	3106
766.857	3120
767.113	3068
767.369	3068
767.625	3018
767.882	3055
768.138	3027
768.394	3003
768.65	2998
768.906	2952
769.163	2920
769.419	2925
769.675	2858
769.931	2851
770.187	2886
770.443	2854
770.699	2784
770.955	2764
771.211	2795
771.467	2735
771.723	2730
771.979	2729
772.235	2666
772.491	2686
772.747	2649
773.003	2660
773.259	2573
773.515	2577
773.771	2576
774.027	2560
774.283	2540
774.539	2517
774.795	2507
775.05	2499
775.306	2481
775.562	2452
775.818	2406
776.074	2441
776.329	2416
776.585	2428
776.841	2368
777.097	2328
777.352	2315
777.608	2342
777.864	2294
778.12	2296
778.375	2267
778.631	2267
778.886	2210
779.142	2234
779.398	2227
779.653	2217
779.909	2186
780.164	2195
780.42	2175
780.675	2144
780.931	2103
781.187	2130
781.442	2091
781.698	2054
781.953	2060
782.208	2050
782.464	2052
782.719	2045
782.975	2049
783.23	1967
783.485	1956
783.741	1968
783.996	1952
784.252	1906
784.507	1937
784.762	1905
785.017	1854
785.273	1905
785.528	1884
785.783	1849
786.038	1796
786.294	1796
786.549	1777
786.804	1806
787.059	1813
787.314	1785
787.57	1748
787.825	1754
788.08	1701
788.335	1695
788.59	1714
788.845	1691
789.1	1691
789.355	1664
789.61	1676
789.865	1656
790.12	1657
790.375	1598
790.63	1608
790.885	1585
791.14	1599
791.395	1563
791.65	1551
791.905	1532
792.16	1563
792.414	1588
792.669	1537
792.924	1491
793.179	1486
793.434	1505
793.689	1491
793.943	1438
794.198	1461
794.453	1464
794.708	1414
794.962	1399
795.217	1421
795.472	1412
795.726	1402
795.981	1376
796.236	1362
796.49	1357
796.745	1392
796.999	1324
797.254	1340
797.508	1315
797.763	1308
798.018	1292
798.272	1269
798.526	1268
798.781	1307
799.035	1257
799.29	1235
799.544	1265
799.799	1230
800.053	1217
800.307	1187
800.562	1228
800.816	1210
801.07	1189
801.325	1159
801.579	1167
801.833	1190
802.088	1174
802.342	1146
802.596	1135
802.85	1120
803.105	1145
803.359	1122
803.613	1092
803.867	1103
804.121	1080
804.375	1078
804.63	1078
804.884	1074
805.138	1062
805.392	1038
805.646	1051.42
805.9	1060.34
806.154	1030.07
806.408	1024.05
806.662	1025.92
806.916	1033.42
807.17	1011.88
807.424	992.814
807.678	989.682
807.931	984.98
808.185	986.17
808.439	976.234
808.693	959.385
808.947	955.339
809.201	951.491
809.454	942.698
809.708	939.505
809.962	921.17
810.216	942.839
810.469	927.766
810.678	931
810.933	889
811.188	897
811.443	898
811.699	868
811.954	878
812.209	858
812.464	849
812.719	861
812.974	852
813.229	863
813.484	845
813.739	808
813.994	822
814.249	866
814.504	828
814.759	813
815.014	819
815.268	797
815.523	795
815.778	786
816.033	797
816.288	798
816.543	762
816.798	763
817.052	770
817.307	752
817.562	759
817.817	726
818.071	753
818.326	734
818.581	762
818.836	750
819.09	723
819.345	725
819.6	698
819.854	726
820.109	713
820.364	696
820.618	686
820.873	693
821.127	681
821.382	684
821.637	670
821.891	663
822.146	668
822.4	666
822.655	662
822.909	658
823.164	635
823.418	652
823.672	626
823.927	606
824.181	630
824.436	648
824.69	622
824.944	626
825.199	614
825.453	593
825.707	607
825.962	599
826.216	610
826.47	570
826.725	598
826.979	581
827.233	569
827.487	599
827.741	570
827.996	577
828.25	599
828.504	554
828.758	546
829.012	565
829.266	558
829.52	554
829.774	558
830.029	555
830.283	550
830.537	536
830.791	537
831.045	523
831.299	528
831.553	515
831.807	530
832.061	509
832.315	531
832.568	522
832.822	516
833.076	496
833.33	511
833.584	501
833.838	507
834.092	482
834.345	496
834.599	488
834.853	499
835.107	472
835.36	462
835.614	496
835.868	458
836.122	456
836.375	450
836.629	473
836.883	472
837.136	458
837.39	445
837.643	445
837.897	457
838.151	446
838.404	443
838.658	469
838.911	435
839.165	441
839.418	450
839.672	420
839.925	434
840.179	430
840.432	432
840.686	408
840.939	419
841.192	446
841.446	422
841.699	416
841.952	424
842.206	419
842.459	435
842.712	423
842.966	415
843.219	411
843.472	401
843.725	394
843.979	392
844.232	377
844.485	396
844.738	396
844.991	403
845.244	396
845.497	391
845.75	387
846.004	384
846.257	359
846.51	362
846.763	377
847.016	379
847.269	379
847.522	362
847.775	387
848.028	361
848.281	367
848.534	356
848.786	367
849.039	344
849.292	339
849.545	346
849.798	363
850.051	348
850.303	344
850.556	349
850.809	333
851.062	332
851.314	330
851.567	316
851.82	342
852.073	332
852.325	346.929
852.578	326.988
852.831	320.321
853.083	335.32
853.336	322.378
853.588	313.694
853.841	315.058
854.093	313.965
854.346	310.061
854.598	311.567
854.851	311.495
855.103	303.072
855.356	303.652
855.608	307.808
855.861	306.76
856.113	299.372
856.366	294.684
856.618	292.958
856.87	292.491
857.123	299.255
857.352	291
857.606	283
857.859	279
858.113	269
858.367	281
858.621	274
858.875	276
859.128	291
859.382	264
859.636	285
859.889	280
860.143	266
860.397	273
860.65	270
860.904	281
861.158	284
861.411	270
861.665	260
861.918	285
862.172	277
862.425	261
862.679	278
862.932	250
863.186	273
863.439	261
863.693	255
863.946	253
864.2	253
864.453	256
864.707	245
864.96	256
865.213	261
865.467	241
865.72	249
865.973	242
866.227	249
866.48	234
866.733	248
866.987	256
867.24	257
867.493	255
867.746	231
867.999	251
868.253	237
868.506	232
868.759	244
869.012	236
869.265	239
869.518	221
869.771	229
870.025	222
870.278	215
870.531	222
870.784	219
871.037	225
871.29	224
871.543	228
871.796	225
872.049	208
872.302	223
872.555	220
872.808	201
873.06	210
873.313	221
873.566	218
873.819	216
874.072	210
874.325	217
874.578	209
874.83	208
875.083	200
875.336	211
875.589	207
875.841	203
876.094	194
876.347	215
876.6	204
876.852	205
877.105	192
877.358	195
877.61	215
877.863	189
878.115	186
878.368	196
878.621	203
878.873	191
879.126	209
879.378	201
879.631	187
879.883	190
880.136	192
880.388	191
880.641	195
880.893	182
881.145	177
881.398	183
881.65	175
881.902	176
882.155	173
882.407	182
882.659	174
882.912	175
883.164	165
883.416	171
883.669	184
883.921	178
884.173	171
884.425	182
884.677	175
884.93	169
885.182	172
885.434	172
885.686	165
885.938	174
886.19	157
886.442	157
886.694	164
886.946	167
887.198	168
887.45	166
887.702	163
887.954	164
888.206	153
888.458	152
888.71	157
888.962	158
889.214	152
889.466	153
889.718	158
889.969	156
890.221	148
890.473	145
890.725	154
890.977	155
891.228	151
891.48	146
891.732	141
891.983	149
892.235	143
892.487	128
892.738	142
892.99	156
893.242	139
893.493	134
893.745	137
893.996	148
894.248	154
894.5	140
894.751	139
895.003	134
895.254	144
895.505	126
895.757	129
896.008	141
896.26	137
896.511	144
896.763	129
897.014	121
897.265	130
897.517	124
897.768	132
898.019	122
898.27	140
898.522	134
898.773	124
899.024	126
899.275	120
899.527	121
899.778	129
899.979	120