File: PL_M4_180324_01.txt
#Acq. time (s)=	3
#Accumulations=	2
#Range (nm)=	520...900
#Windows=	8
#Auto scanning=	Off
#Autofocus=	Off
#AutoExposure=	Off
#Spike filter=	Multiple accum.
#Delay time (s)=	0
#Binning=	1
#Readout mode=	Signal
#DeNoise=	Off
#ICS correction=	Off
#Dark correction=	Off
#Inst. Process=	Off
#Detector temperature (°C)=	-59.98
#Instrument=	LabRAM HR Evol
#Detector=	Syncerity OE
#Objective=	x50_VIS
#Grating=	600 (500nm)
#ND Filter=	25%
#Laser=	514nm_Edge
#Hole=	199.981
#Range=	Auto
#StageXY=	Marzhauser
#StageZ=	Marzhauser
#X (µm)=	-51.3
#Y (µm)=	6302
#Z (µm)=	-7
#Full time(mm:ss)=	1:32
#Project=
#Sample=
#Site=
#Title=	PL_M4_180324
#Remark=
#Date=	28.03.2024 09:20
#Acquired=	28.03.2024 09:20:04
520.044	36
520.306	38
520.569	40
520.831	34
521.093	42
521.355	44
521.617	40
521.88	46
522.142	32
522.404	42
522.666	40
522.928	40
523.19	34
523.453	40
523.715	46
523.977	42
524.239	34
524.501	54
524.763	46
525.025	42
525.287	36
525.549	42
525.811	46
526.073	38
526.335	46
526.597	52
526.859	50
527.121	34
527.383	34
527.645	42
527.907	42
528.169	44
528.431	48
528.693	50
528.955	46
529.217	44
529.479	38
529.741	44
530.003	54
530.264	48
530.526	32
530.788	48
531.05	48
531.312	48
531.574	42
531.835	52
532.097	54
532.359	44
532.621	48
532.883	50
533.144	44
533.406	52
533.668	42
533.93	44
534.191	54
534.453	54
534.715	54
534.976	64
535.238	72
535.5	78
535.761	52
536.023	60
536.285	60
536.546	58
536.808	54
537.069	60
537.331	54
537.593	58
537.854	58
538.116	54
538.377	54
538.639	52
538.9	54
539.162	70
539.423	66
539.685	72
539.946	58
540.208	64
540.469	72
540.731	64
540.992	58
541.254	82
541.515	66
541.776	74
542.038	60
542.299	72
542.56	78
542.822	68
543.083	64
543.344	80
543.606	84
543.867	84
544.128	68
544.39	78
544.651	82
544.912	70
545.174	84
545.435	86
545.696	78
545.957	90
546.218	82
546.48	84
546.741	96
547.002	100
547.263	86
547.524	98
547.785	100
548.047	106
548.308	108
548.569	98
548.83	100
549.091	116
549.352	102
549.613	116
549.874	114
550.135	130
550.396	120
550.657	124
550.918	130
551.179	160
551.44	170
551.701	190
551.962	244
552.223	420
552.484	3298
552.745	22358
553.006	656
553.267	284
553.528	214
553.788	184
554.049	186
554.31	176
554.571	166
554.832	166
555.093	182
555.353	176
555.614	164
555.875	166
556.136	178
556.396	182
556.657	182
556.918	180
557.179	188
557.439	202
557.7	198
557.961	184
558.221	200
558.482	198
558.743	202
559.003	204
559.264	218
559.525	202
559.785	220
560.046	204
560.306	226
560.567	242
560.827	226
561.088	214
561.348	246
561.609	256
561.869	256
562.13	254
562.39	278
562.651	270
562.911	296
563.172	288
563.432	300
563.692	318
563.953	336
564.213	330
564.474	340
564.734	336
564.994	326
565.255	338
565.515	342
565.775	306
566.035	348
566.296	336
566.556	348
566.816	374
567.076	366
567.337	356
567.597	392
567.857	392
568.117	417.74
568.377	414.219
568.637	436.648
568.898	427.307
569.158	422.77
569.418	424.838
569.678	431.889
569.938	451.635
570.198	465.263
570.458	480.09
570.718	499.598
570.978	520.353
571.238	527.467
571.498	548.162
571.758	572.418
572.018	595.096
572.278	633.807
572.538	638.918
572.798	707.612
573.058	733.945
573.312	810
573.573	860
573.834	902
574.095	990
574.356	1056
574.617	1126
574.878	1288
575.139	1356
575.4	1386
575.661	1470
575.922	1472
576.183	1440
576.444	1442
576.705	1378
576.965	1296
577.226	1254
577.487	1164
577.748	1052
578.009	1046
578.27	1054
578.531	970
578.791	948
579.052	956
579.313	968
579.574	940
579.835	954
580.095	930
580.356	952
580.617	940
580.878	954
581.138	952
581.399	938
581.66	1006
581.92	966
582.181	982
582.442	984
582.703	1004
582.963	1024
583.224	1052
583.484	1052
583.745	1058
584.006	1090
584.266	1100
584.527	1126
584.787	1126
585.048	1158
585.308	1188
585.569	1230
585.83	1214
586.09	1216
586.351	1250
586.611	1268
586.872	1324
587.132	1308
587.392	1320
587.653	1340
587.913	1280
588.174	1320
588.434	1330
588.695	1358
588.955	1366
589.215	1338
589.476	1390
589.736	1374
589.996	1338
590.257	1346
590.517	1368
590.777	1340
591.038	1346
591.298	1372
591.558	1328
591.818	1326
592.079	1356
592.339	1338
592.599	1342
592.859	1288
593.12	1294
593.38	1312
593.64	1310
593.9	1326
594.16	1350
594.42	1348
594.68	1342
594.941	1344
595.201	1352
595.461	1390
595.721	1408
595.981	1406
596.241	1430
596.501	1434
596.761	1446
597.021	1454
597.281	1472
597.541	1462
597.801	1476
598.061	1480
598.321	1462
598.581	1490
598.841	1510
599.101	1518
599.361	1518
599.62	1524
599.88	1516
600.14	1512
600.4	1538
600.66	1520
600.92	1484
601.18	1498
601.439	1522
601.699	1500
601.959	1528
602.219	1518
602.478	1552
602.738	1514
602.998	1536
603.258	1564
603.517	1558
603.777	1510
604.037	1608
604.296	1588
604.556	1594
604.816	1596
605.075	1590
605.335	1574
605.594	1614
605.854	1586
606.114	1594
606.373	1542
606.633	1654
606.892	1572
607.152	1600
607.411	1562
607.671	1622
607.93	1620
608.19	1634
608.449	1648
608.709	1612
608.968	1674
609.228	1678
609.487	1668
609.746	1694
610.006	1702
610.265	1672
610.524	1692
610.784	1730
611.043	1690
611.302	1702
611.562	1750
611.821	1766
612.08	1756
612.339	1794
612.599	1774
612.858	1834
613.117	1814
613.376	1778
613.635	1872
613.895	1842
614.154	1856
614.413	1860
614.672	1936
614.931	1874
615.19	1918
615.449	1892
615.709	1944
615.968	1934
616.227	1941.82
616.486	1981.95
616.745	2013.19
617.004	1989.79
617.263	1951.82
617.522	2054.88
617.781	2050.88
618.04	2051.86
618.299	2043.67
618.557	2068.33
618.816	2093.58
619.075	2103.05
619.334	2073.44
619.593	2104.29
619.852	2123.12
620.111	2144.7
620.37	2140.21
620.628	2130
620.887	2128.67
621.146	2122.29
621.373	2150
621.633	2166
621.893	2134
622.153	2190
622.413	2176
622.673	2192
622.932	2192
623.192	2224
623.452	2156
623.712	2228
623.972	2228
624.232	2244
624.492	2240
624.751	2228
625.011	2232
625.271	2238
625.531	2220
625.791	2252
626.05	2308
626.31	2300
626.57	2342
626.83	2344
627.089	2296
627.349	2382
627.609	2376
627.868	2406
628.128	2370
628.388	2410
628.647	2404
628.907	2404
629.167	2484
629.426	2410
629.686	2476
629.945	2490
630.205	2502
630.465	2488
630.724	2520
630.984	2544
631.243	2578
631.503	2556
631.762	2566
632.022	2550
632.281	2604
632.541	2638
632.8	2690
633.06	2668
633.319	2694
633.579	2706
633.838	2774
634.097	2786
634.357	2798
634.616	2852
634.876	2852
635.135	2916
635.394	2928
635.654	3042
635.913	3094
636.172	3190
636.431	3300
636.691	3458
636.95	3536
637.209	3764
637.469	3846
637.728	4090
637.987	4132
638.246	4288
638.505	4316
638.765	4132
639.024	4150
639.283	3992
639.542	3828
639.801	3786
640.06	3702
640.319	3652
640.578	3560
640.838	3544
641.097	3528
641.356	3530
641.615	3456
641.874	3450
642.133	3504
642.392	3484
642.651	3448
642.91	3488
643.169	3438
643.428	3486
643.687	3464
643.946	3478
644.205	3452
644.463	3570
644.722	3494
644.981	3574
645.24	3632
645.499	3578
645.758	3574
646.017	3588
646.275	3590
646.534	3642
646.793	3680
647.052	3668
647.31	3636
647.569	3690
647.828	3726
648.087	3782
648.345	3714
648.604	3744
648.863	3794
649.121	3850
649.38	3862
649.639	3818
649.897	3894
650.156	3896
650.415	3910
650.673	3994
650.932	3976
651.19	3996
651.449	4068
651.707	4072
651.966	4134
652.224	4130
652.483	4120
652.741	4172
653	4158
653.258	4252
653.517	4166
653.775	4282
654.034	4362
654.292	4442
654.55	4420
654.809	4460
655.067	4538
655.326	4508
655.584	4584
655.842	4688
656.1	4624
656.359	4746
656.617	4732
656.875	4776
657.134	4810
657.392	4956
657.65	4898
657.908	4890
658.166	4972
658.425	5060
658.683	5024
658.941	5060
659.199	5154
659.457	5090
659.715	5170
659.973	5156
660.231	5136
660.49	5102
660.748	5186
661.006	5156
661.264	5182
661.522	5120
661.78	5208
662.038	5214
662.296	5180
662.554	5112
662.811	5130
663.069	5052
663.327	5190
663.585	5192
663.843	5091.25
664.101	5162.32
664.359	5147.27
664.617	5170.52
664.874	5157.05
665.132	5106.21
665.39	5166.39
665.648	5146.18
665.906	5087.58
666.163	5188.59
666.421	5145.02
666.679	5167.61
666.937	5155.14
667.194	5148.86
667.452	5179.92
667.71	5128.93
667.967	5162.59
668.225	5181.89
668.482	5153.69
668.74	5087.63
668.987	5212
669.245	5174
669.504	5182
669.763	5172
670.022	5112
670.281	5158
670.539	5096
670.798	5110
671.057	5038
671.316	5204
671.575	5120
671.833	5194
672.092	5060
672.351	5120
672.609	5202
672.868	5162
673.127	5198
673.385	5220
673.644	5172
673.903	5308
674.161	5288
674.42	5300
674.678	5336
674.937	5356
675.195	5412
675.454	5426
675.713	5408
675.971	5474
676.23	5458
676.488	5540
676.747	5472
677.005	5478
677.263	5476
677.522	5486
677.78	5474
678.039	5486
678.297	5518
678.556	5450
678.814	5476
679.072	5512
679.331	5496
679.589	5490
679.847	5472
680.106	5564
680.364	5524
680.622	5532
680.881	5610
681.139	5634
681.397	5604
681.656	5670
681.914	5680
682.172	5682
682.43	5704
682.688	5650
682.947	5594
683.205	5700
683.463	5708
683.721	5658
683.979	5652
684.237	5654
684.495	5614
684.754	5608
685.012	5572
685.27	5568
685.528	5656
685.786	5584
686.044	5586
686.302	5606
686.56	5498
686.818	5592
687.076	5490
687.334	5560
687.592	5546
687.85	5540
688.108	5590
688.366	5526
688.623	5556
688.881	5554
689.139	5576
689.397	5542
689.655	5480
689.913	5462
690.171	5520
690.428	5364
690.686	5464
690.944	5408
691.202	5372
691.459	5382
691.717	5336
691.975	5300
692.233	5366
692.49	5244
692.748	5230
693.006	5250
693.263	5328
693.521	5280
693.779	5330
694.036	5236
694.294	5164
694.552	5234
694.809	5162
695.067	5140
695.324	5186
695.582	5176
695.839	5136
696.097	5152
696.354	5202
696.612	5016
696.869	5130
697.127	5100
697.384	5068
697.642	5048
697.899	4972
698.156	5020
698.414	4966
698.671	4962
698.928	4884
699.186	4946
699.443	4874
699.7	4966
699.958	4804
700.215	4844
700.472	4918
700.73	4924
700.987	4896
701.244	4966
701.501	4824
701.758	4804
702.016	4826
702.273	4934
702.53	4844
702.787	4880
703.044	4890
703.301	4844
703.558	4880
703.816	4810
704.073	4902
704.33	4810
704.587	4862
704.844	4820
705.101	4764
705.358	4716
705.615	4736
705.872	4720
706.129	4704
706.386	4652
706.643	4572
706.899	4536
707.156	4600
707.413	4618
707.67	4576
707.927	4576
708.184	4498
708.441	4518
708.697	4552
708.954	4498
709.211	4546
709.468	4486
709.725	4370
709.981	4506
710.238	4444
710.495	4468
710.751	4430
711.008	4404
711.265	4382.34
711.521	4374
711.778	4335.21
712.035	4343.67
712.291	4324.55
712.548	4332.74
712.804	4264.95
713.061	4246.29
713.317	4244.27
713.574	4226.5
713.831	4206.46
714.087	4186.74
714.343	4127.72
714.6	4132.91
714.856	4144.82
715.113	4123.18
715.369	4093.78
715.626	4061.65
715.882	4059.12
716.138	3997.55
716.395	3995.25
716.639	3982
716.897	4028
717.155	3960
717.412	3956
717.67	3920
717.927	3882
718.185	3862
718.443	3898
718.7	3882
718.958	3914
719.215	3798
719.473	3796
719.73	3850
719.988	3796
720.245	3718
720.503	3678
720.76	3708
721.018	3632
721.275	3680
721.532	3674
721.79	3644
722.047	3560
722.305	3612
722.562	3582
722.819	3592
723.077	3554
723.334	3488
723.591	3490
723.849	3474
724.106	3426
724.363	3466
724.621	3448
724.878	3384
725.135	3384
725.392	3434
725.65	3368
725.907	3376
726.164	3366
726.421	3328
726.678	3276
726.935	3300
727.193	3328
727.45	3266
727.707	3210
727.964	3216
728.221	3226
728.478	3172
728.735	3108
728.992	3128
729.249	3118
729.506	3054
729.763	3042
730.02	2986
730.277	3024
730.534	2972
730.791	3010
731.048	3018
731.305	2918
731.562	2914
731.819	2954
732.076	2964
732.333	2876
732.589	2938
732.846	2908
733.103	2902
733.36	2774
733.617	2862
733.873	2832
734.13	2876
734.387	2870
734.644	2848
734.901	2808
735.157	2862
735.414	2820
735.671	2864
735.927	2854
736.184	2790
736.441	2834
736.697	2794
736.954	2812
737.211	2820
737.467	2900
737.724	2854
737.98	2856
738.237	2886
738.493	2880
738.75	2886
739.006	2824
739.263	2768
739.519	2762
739.776	2748
740.032	2746
740.289	2756
740.545	2720
740.802	2656
741.058	2638
741.314	2618
741.571	2600
741.827	2574
742.083	2614
742.34	2538
742.596	2542
742.852	2570
743.109	2504
743.365	2500
743.621	2496
743.878	2458
744.134	2434
744.39	2468
744.646	2404
744.902	2410
745.159	2430
745.415	2410
745.671	2386
745.927	2366
746.183	2394
746.439	2350
746.695	2342
746.951	2324
747.207	2294
747.463	2284
747.719	2326
747.975	2320
748.231	2312
748.487	2308
748.743	2254
748.999	2264
749.255	2246
749.511	2200
749.767	2246
750.023	2226
750.279	2262
750.535	2184
750.791	2196
751.046	2170
751.302	2176
751.558	2162
751.814	2112
752.07	2120
752.325	2062
752.581	2104
752.837	2070
753.092	2040
753.348	2054
753.604	2020
753.859	1990
754.115	1992
754.371	1980
754.626	2010
754.882	2016
755.138	1974
755.393	1978
755.649	1946
755.904	1948
756.16	1966
756.415	1910
756.671	1940
756.926	1952
757.182	1892
757.437	1886
757.693	1892
757.948	1858
758.203	1848
758.459	1834
758.714	1847.7
758.97	1870.07
759.225	1824.81
759.48	1823.77
759.736	1817.75
759.991	1767.97
760.246	1759.28
760.501	1778.93
760.757	1726.42
761.012	1759.18
761.267	1741.54
761.522	1719.38
761.777	1692.36
762.033	1752.85
762.288	1711.97
762.543	1699.06
762.798	1679.88
763.053	1658.7
763.308	1677.96
763.563	1638.23
763.78	1614
764.037	1638
764.293	1648
764.55	1612
764.806	1596
765.062	1628
765.319	1604
765.575	1572
765.831	1564
766.088	1558
766.344	1558
766.6	1528
766.857	1542
767.113	1490
767.369	1566
767.625	1506
767.882	1504
768.138	1478
768.394	1516
768.65	1472
768.906	1438
769.163	1442
769.419	1412
769.675	1434
769.931	1406
770.187	1418
770.443	1404
770.699	1400
770.955	1414
771.211	1368
771.467	1366
771.723	1310
771.979	1318
772.235	1264
772.491	1308
772.747	1322
773.003	1290
773.259	1282
773.515	1260
773.771	1252
774.027	1266
774.283	1210
774.539	1238
774.795	1230
775.05	1234
775.306	1232
775.562	1178
775.818	1198
776.074	1228
776.329	1186
776.585	1134
776.841	1172
777.097	1184
777.352	1116
777.608	1158
777.864	1120
778.12	1144
778.375	1126
778.631	1080
778.886	1122
779.142	1104
779.398	1092
779.653	1080
779.909	1078
780.164	1044
780.42	1044
780.675	1072
780.931	1022
781.187	1030
781.442	1024
781.698	1016
781.953	1024
782.208	990
782.464	994
782.719	992
782.975	980
783.23	996
783.485	980
783.741	956
783.996	962
784.252	954
784.507	908
784.762	902
785.017	918
785.273	930
785.528	904
785.783	904
786.038	886
786.294	896
786.549	892
786.804	846
787.059	864
787.314	836
787.57	862
787.825	846
788.08	872
788.335	816
788.59	852
788.845	834
789.1	828
789.355	830
789.61	804
789.865	796
790.12	826
790.375	774
790.63	772
790.885	792
791.14	772
791.395	798
791.65	752
791.905	740
792.16	718
792.414	734
792.669	730
792.924	726
793.179	708
793.434	738
793.689	722
793.943	714
794.198	704
794.453	712
794.708	710
794.962	676
795.217	680
795.472	694
795.726	680
795.981	666
796.236	670
796.49	660
796.745	652
796.999	644
797.254	634
797.508	636
797.763	640
798.018	644
798.272	636
798.526	628
798.781	634
799.035	626
799.29	646
799.544	622
799.799	610
800.053	598
800.307	588
800.562	618
800.816	578
801.07	584
801.325	564
801.579	580
801.833	564
802.088	566
802.342	554
802.596	542
802.85	564
803.105	554
803.359	544
803.613	538
803.867	548
804.121	518
804.375	526
804.63	496
804.884	506
805.138	512
805.392	522
805.646	511.83
805.9	519.364
806.154	484.244
806.408	506.63
806.662	502.94
806.916	479.945
807.17	485.314
807.424	487.38
807.678	487.442
807.931	470.307
808.185	474.367
808.439	477.009
808.693	485.75
808.947	451.96
809.201	457.732
809.454	453.494
809.708	457.029
809.962	453.425
810.216	445.811
810.469	417.962
810.678	422
810.933	446
811.188	438
811.443	434
811.699	418
811.954	436
812.209	434
812.464	420
812.719	438
812.974	432
813.229	422
813.484	414
813.739	410
813.994	406
814.249	408
814.504	406
814.759	384
815.014	404
815.268	380
815.523	398
815.778	380
816.033	384
816.288	368
816.543	380
816.798	366
817.052	380
817.307	372
817.562	364
817.817	366
818.071	364
818.326	348
818.581	344
818.836	362
819.09	350
819.345	338
819.6	346
819.854	338
820.109	344
820.364	340
820.618	354
820.873	320
821.127	316
821.382	326
821.637	332
821.891	322
822.146	328
822.4	330
822.655	326
822.909	302
823.164	276
823.418	318
823.672	304
823.927	322
824.181	298
824.436	294
824.69	308
824.944	280
825.199	304
825.453	288
825.707	286
825.962	278
826.216	300
826.47	292
826.725	296
826.979	278
827.233	298
827.487	280
827.741	284
827.996	278
828.25	264
828.504	268
828.758	286
829.012	278
829.266	282
829.52	274
829.774	258
830.029	254
830.283	254
830.537	256
830.791	260
831.045	270
831.299	254
831.553	264
831.807	246
832.061	254
832.315	254
832.568	256
832.822	252
833.076	246
833.33	258
833.584	228
833.838	232
834.092	232
834.345	242
834.599	236
834.853	246
835.107	230
835.36	220
835.614	228
835.868	214
836.122	204
836.375	222
836.629	234
836.883	244
837.136	228
837.39	212
837.643	210
837.897	224
838.151	218
838.404	220
838.658	210
838.911	230
839.165	212
839.418	216
839.672	216
839.925	216
840.179	212
840.432	204
840.686	182
840.939	212
841.192	214
841.446	214
841.699	200
841.952	188
842.206	210
842.459	198
842.712	198
842.966	212
843.219	190
843.472	208
843.725	202
843.979	198
844.232	200
844.485	202
844.738	178
844.991	210
845.244	186
845.497	198
845.75	194
846.004	188
846.257	188
846.51	180
846.763	180
847.016	180
847.269	178
847.522	172
847.775	188
848.028	182
848.281	166
848.534	154
848.786	170
849.039	176
849.292	156
849.545	174
849.798	174
850.051	174
850.303	176
850.556	154
850.809	170
851.062	164
851.314	164
851.567	162
851.82	166
852.073	156
852.325	164.011
852.578	157.892
852.831	146.399
853.083	159.173
853.336	147.64
853.588	152.55
853.841	156.34
854.093	150.58
854.346	161.17
854.598	160.616
854.851	143.03
855.103	152.263
855.356	148.427
855.608	148.134
855.861	143.004
856.113	143.953
856.366	143.386
856.618	151.479
856.87	154.004
857.123	133.195
857.352	156
857.606	144
857.859	142
858.113	148
858.367	138
858.621	152
858.875	136
859.128	136
859.382	142
859.636	142
859.889	150
860.143	132
860.397	130
860.65	136
860.904	146
861.158	140
861.411	136
861.665	144
861.918	130
862.172	136
862.425	128
862.679	130
862.932	128
863.186	132
863.439	114
863.693	136
863.946	138
864.2	124
864.453	120
864.707	130
864.96	126
865.213	118
865.467	112
865.72	126
865.973	130
866.227	124
866.48	108
866.733	128
866.987	140
867.24	122
867.493	106
867.746	118
867.999	120
868.253	122
868.506	120
868.759	122
869.012	120
869.265	110
869.518	114
869.771	120
870.025	118
870.278	108
870.531	116
870.784	106
871.037	118
871.29	108
871.543	98
871.796	114
872.049	108
872.302	114
872.555	108
872.808	110
873.06	114
873.313	100
873.566	98
873.819	110
874.072	108
874.325	108
874.578	104
874.83	112
875.083	102
875.336	88
875.589	96
875.841	112
876.094	106
876.347	98
876.6	102
876.852	100
877.105	98
877.358	104
877.61	98
877.863	98
878.115	100
878.368	92
878.621	90
878.873	98
879.126	98
879.378	100
879.631	90
879.883	108
880.136	104
880.388	86
880.641	84
880.893	92
881.145	104
881.398	94
881.65	92
881.902	96
882.155	76
882.407	90
882.659	90
882.912	94
883.164	84
883.416	94
883.669	88
883.921	90
884.173	94
884.425	86
884.677	82
884.93	88
885.182	90
885.434	84
885.686	78
885.938	74
886.19	96
886.442	84
886.694	78
886.946	92
887.198	84
887.45	84
887.702	76
887.954	88
888.206	80
888.458	84
888.71	88
888.962	82
889.214	74
889.466	80
889.718	74
889.969	76
890.221	74
890.473	66
890.725	62
890.977	82
891.228	82
891.48	80
891.732	76
891.983	72
892.235	76
892.487	74
892.738	74
892.99	74
893.242	68
893.493	70
893.745	62
893.996	80
894.248	82
894.5	72
894.751	72
895.003	76
895.254	68
895.505	70
895.757	54
896.008	74
896.26	68
896.511	74
896.763	58
897.014	74
897.265	70
897.517	68
897.768	62
898.019	64
898.27	66
898.522	74
898.773	58
899.024	70
899.275	68
899.527	70
899.778	60
899.979	56