File: PL_M4_280424_01.txt
#Acq. time (s)=	3
#Accumulations=	2
#Range (nm)=	520...900
#Windows=	8
#Auto scanning=	Off
#Autofocus=	Off
#AutoExposure=	Off
#Spike filter=	Off
#Delay time (s)=	0
#Binning=	1
#Readout mode=	Signal
#DeNoise=	Off
#ICS correction=	Off
#Dark correction=	Off
#Inst. Process=	Off
#Detector temperature (°C)=	-59.98
#Instrument=	LabRAM HR Evol
#Detector=	Syncerity OE
#Objective=	x50_VIS
#Grating=	600 (500nm)
#ND Filter=	25%
#Laser=	514nm_Edge
#Hole=	199.981
#Range=	Visible
#StageXY=	Marzhauser
#StageZ=	Marzhauser
#X (µm)=	8994.7
#Y (µm)=	4749.1
#Z (µm)=	-261.7
#Full time(mm:ss)=	1:32
#Project=
#Sample=
#Site=
#Title=	PL_M4_280424
#Remark=
#Date=	06.05.2024 16:41
#Acquired=	06.05.2024 16:41:24
520.044	60
520.306	51
520.569	49
520.831	61
521.093	58
521.355	65
521.617	56
521.88	56
522.142	59
522.404	52
522.666	50
522.928	64
523.19	57
523.453	59
523.715	48
523.977	65
524.239	57
524.501	58
524.763	54
525.025	62
525.287	62
525.549	60
525.811	51
526.073	53
526.335	63
526.597	54
526.859	49
527.121	58
527.383	58
527.645	67
527.907	49
528.169	60
528.431	55
528.693	56
528.955	63
529.217	54
529.479	60
529.741	55
530.003	49
530.264	56
530.526	62
530.788	64
531.05	52
531.312	62
531.574	71
531.835	67
532.097	65
532.359	62
532.621	67
532.883	68
533.144	58
533.406	61
533.668	60
533.93	66
534.191	82
534.453	78
534.715	84
534.976	98
535.238	99
535.5	103
535.761	105
536.023	88
536.285	87
536.546	77
536.808	85
537.069	72
537.331	72
537.593	77
537.854	83
538.116	72
538.377	81
538.639	75
538.9	83
539.162	88
539.423	73
539.685	70
539.946	78
540.208	78
540.469	85
540.731	71
540.992	89
541.254	79
541.515	97
541.776	84
542.038	85
542.299	99
542.56	93
542.822	95
543.083	88
543.344	90
543.606	100
543.867	102
544.128	104
544.39	102
544.651	97
544.912	93
545.174	104
545.435	103
545.696	108
545.957	106
546.218	100
546.48	121
546.741	114
547.002	110
547.263	117
547.524	121
547.785	126
548.047	128
548.308	119
548.569	140
548.83	135
549.091	136
549.352	143
549.613	141
549.874	154
550.135	155
550.396	152
550.657	156
550.918	167
551.179	192
551.44	188
551.701	221
551.962	279
552.223	430
552.484	2621
552.745	36015
553.006	891
553.267	334
553.528	264
553.788	227
554.049	213
554.31	210
554.571	208
554.832	207
555.093	213
555.353	199
555.614	214
555.875	220
556.136	206
556.396	217
556.657	228
556.918	225
557.179	222
557.439	232
557.7	218
557.961	242
558.221	250
558.482	259
558.743	249
559.003	249
559.264	277
559.525	249
559.785	277
560.046	274
560.306	270
560.567	290
560.827	289
561.088	290
561.348	296
561.609	299
561.869	300
562.13	307
562.39	322
562.651	350
562.911	328
563.172	311
563.432	348
563.692	359
563.953	384
564.213	404
564.474	390
564.734	390
564.994	386
565.255	384
565.515	387
565.775	409
566.035	417
566.296	402
566.556	447
566.816	425
567.076	435
567.337	436
567.597	465
567.857	473
568.117	467.91
568.377	479.513
568.637	491.108
568.898	502.166
569.158	501.652
569.418	496.078
569.678	535.65
569.938	533.999
570.198	540.296
570.458	558.5
570.718	579.613
570.978	597.954
571.238	616.398
571.498	635.277
571.758	676.422
572.018	691.65
572.278	725.787
572.538	757.865
572.798	791.937
573.058	841.318
573.312	871
573.573	954
573.834	1054
574.095	1073
574.356	1185
574.617	1294
574.878	1410
575.139	1523
575.4	1622
575.661	1704
575.922	1789
576.183	1762
576.444	1704
576.705	1692
576.965	1577
577.226	1508
577.487	1413
577.748	1330
578.009	1294
578.27	1196
578.531	1174
578.791	1126
579.052	1128
579.313	1117
579.574	1076
579.835	1116
580.095	1112
580.356	1109
580.617	1114
580.878	1098
581.138	1083
581.399	1137
581.66	1170
581.92	1132
582.181	1146
582.442	1166
582.703	1181
582.963	1202
583.224	1204
583.484	1240
583.745	1250
584.006	1271
584.266	1281
584.527	1346
584.787	1358
585.048	1373
585.308	1415
585.569	1420
585.83	1462
586.09	1432
586.351	1468
586.611	1489
586.872	1494
587.132	1524
587.392	1537
587.653	1541
587.913	1579
588.174	1556
588.434	1570
588.695	1586
588.955	1580
589.215	1619
589.476	1641
589.736	1659
589.996	1623
590.257	1600
590.517	1637
590.777	1612
591.038	1613
591.298	1621
591.558	1579
591.818	1580
592.079	1592
592.339	1512
592.599	1551
592.859	1527
593.12	1548
593.38	1553
593.64	1552
593.9	1564
594.16	1560
594.42	1583
594.68	1605
594.941	1609
595.201	1651
595.461	1657
595.721	1686
595.981	1664
596.241	1690
596.501	1720
596.761	1771
597.021	1694
597.281	1724
597.541	1742
597.801	1780
598.061	1742
598.321	1764
598.581	1772
598.841	1815
599.101	1773
599.361	1782
599.62	1815
599.88	1817
600.14	1803
600.4	1808
600.66	1790
600.92	1828
601.18	1822
601.439	1786
601.699	1789
601.959	1797
602.219	1804
602.478	1866
602.738	1798
602.998	1837
603.258	1832
603.517	1845
603.777	1833
604.037	1849
604.296	1853
604.556	1875
604.816	1884
605.075	1889
605.335	1866
605.594	1887
605.854	1883
606.114	1857
606.373	1881
606.633	1919
606.892	1893
607.152	1906
607.411	1853
607.671	1884
607.93	1940
608.19	1931
608.449	1922
608.709	1933
608.968	1948
609.228	1995
609.487	1955
609.746	1997
610.006	2028
610.265	2029
610.524	2031
610.784	2037
611.043	2055
611.302	2035
611.562	2077
611.821	2078
612.08	2063
612.339	2087
612.599	2065
612.858	2111
613.117	2142
613.376	2153
613.635	2168
613.895	2209
614.154	2192
614.413	2231
614.672	2243
614.931	2290
615.19	2247
615.449	2268
615.709	2333
615.968	2330
616.227	2343.59
616.486	2353.9
616.745	2386.34
617.004	2345.19
617.263	2383.06
617.522	2398.91
617.781	2438.47
618.04	2406.98
618.299	2441.55
618.557	2435.35
618.816	2492
619.075	2478.83
619.334	2496.39
619.593	2467.88
619.852	2512.13
620.111	2543.53
620.37	2525.87
620.628	2539.26
620.887	2508.44
621.146	2540.88
621.373	2605
621.633	2541
621.893	2572
622.153	2507
622.413	2542
622.673	2547
622.932	2579
623.192	2593
623.452	2609
623.712	2612
623.972	2594
624.232	2610
624.492	2638
624.751	2645
625.011	2629
625.271	2674
625.531	2669
625.791	2677
626.05	2715
626.31	2714
626.57	2738
626.83	2739
627.089	2716
627.349	2753
627.609	2828
627.868	2801
628.128	2818
628.388	2782
628.647	2821
628.907	2888
629.167	2851
629.426	2911
629.686	2914
629.945	2934
630.205	2958
630.465	2963
630.724	2987
630.984	3004
631.243	2984
631.503	3063
631.762	3073
632.022	3030
632.281	3123
632.541	3103
632.8	3154
633.06	3195
633.319	3136
633.579	3171
633.838	3208
634.097	3282
634.357	3285
634.616	3335
634.876	3377
635.135	3434
635.394	3470
635.654	3500
635.913	3599
636.172	3666
636.431	3760
636.691	5153
636.95	4076
637.209	4279
637.469	4460
637.728	4705
637.987	4851
638.246	5051
638.505	5043
638.765	4993
639.024	4913
639.283	4764
639.542	4595
639.801	4500
640.06	4444
640.319	4324
640.578	4290
640.838	4198
641.097	4133
641.356	4202
641.615	4132
641.874	4103
642.133	4137
642.392	4113
642.651	4016
642.91	4103
643.169	4148
643.428	4094
643.687	4180
643.946	4177
644.205	4111
644.463	4179
644.722	4232
644.981	4189
645.24	4197
645.499	4221
645.758	4286
646.017	4255
646.275	4247
646.534	4308
646.793	4332
647.052	4368
647.31	4344
647.569	4419
647.828	4392
648.087	4405
648.345	4421
648.604	4452
648.863	4504
649.121	4500
649.38	4547
649.639	4580
649.897	4613
650.156	4654
650.415	4634
650.673	4696
650.932	4709
651.19	4706
651.449	4782
651.707	4826
651.966	4799
652.224	4882
652.483	4885
652.741	4982
653	4937
653.258	4940
653.517	5017
653.775	5060
654.034	5121
654.292	5128
654.55	5216
654.809	5274
655.067	5377
655.326	5365
655.584	5436
655.842	5454
656.1	5539
656.359	5617
656.617	5577
656.875	5680
657.134	5707
657.392	5747
657.65	5870
657.908	5817
658.166	5929
658.425	5985
658.683	6003
658.941	6020
659.199	6049
659.457	6058
659.715	6010
659.973	6138
660.231	6076
660.49	6089
660.748	6137
661.006	6114
661.264	6146
661.522	6125
661.78	6120
662.038	6126
662.296	6141
662.554	6150
662.811	6191
663.069	6118
663.327	6184
663.585	6198
663.843	6175.93
664.101	6151.09
664.359	6233.17
664.617	6096
664.874	6149.77
665.132	6178.84
665.39	6122.84
665.648	6155.98
665.906	6136.25
666.163	6180.62
666.421	6170.28
666.679	6115.31
666.937	6135.91
667.194	6157
667.452	6137.5
667.71	6146.68
667.967	6157.94
668.225	6119.64
668.482	6154.21
668.74	6132.53
668.987	6187
669.245	6131
669.504	6165
669.763	6122
670.022	6143
670.281	6222
670.539	6141
670.798	6183
671.057	6054
671.316	6162
671.575	6233
671.833	6077
672.092	6225
672.351	6168
672.609	6247
672.868	6174
673.127	6273
673.385	6307
673.644	6380
673.903	6313
674.161	6358
674.42	6418
674.678	6383
674.937	6454
675.195	6439
675.454	6502
675.713	6563
675.971	6516
676.23	6580
676.488	6525
676.747	6580
677.005	6581
677.263	6591
677.522	6690
677.78	6548
678.039	6542
678.297	6604
678.556	6498
678.814	6576
679.072	6671
679.331	6605
679.589	6653
679.847	6641
680.106	6638
680.364	6645
680.622	6714
680.881	6682
681.139	6716
681.397	6725
681.656	6772
681.914	6850
682.172	6777
682.43	6802
682.688	6800
682.947	6846
683.205	6805
683.463	6875
683.721	6844
683.979	6800
684.237	6887
684.495	6808
684.754	6828
685.012	6786
685.27	6830
685.528	6704
685.786	6731
686.044	6798
686.302	6773
686.56	6704
686.818	6697
687.076	6704
687.334	6688
687.592	6622
687.85	6694
688.108	6700
688.366	6615
688.623	6633
688.881	6650
689.139	6651
689.397	6579
689.655	6595
689.913	6648
690.171	6634
690.428	6570
690.686	6547
690.944	6482
691.202	6593
691.459	6509
691.717	6579
691.975	6423
692.233	6461
692.49	6437
692.748	6454
693.006	6446
693.263	6448
693.521	6376
693.779	6398
694.036	6311
694.294	6366
694.552	6329
694.809	6348
695.067	6331
695.324	6285
695.582	6313
695.839	6201
696.097	6326
696.354	6169
696.612	6213
696.869	6186
697.127	6189
697.384	6239
697.642	6164
697.899	6097
698.156	6085
698.414	6087
698.671	6056
698.928	6000
699.186	6019
699.443	6008
699.7	5935
699.958	5927
700.215	5928
700.472	5950
700.73	6008
700.987	5930
701.244	5930
701.501	5933
701.758	5879
702.016	5999
702.273	5954
702.53	5946
702.787	5919
703.044	5911
703.301	5924
703.558	5947
703.816	5969
704.073	5925
704.33	5878
704.587	5865
704.844	5876
705.101	5840
705.358	5802
705.615	5783
705.872	5696
706.129	5704
706.386	5738
706.643	5634
706.899	5679
707.156	5640
707.413	5528
707.67	5589
707.927	5568
708.184	5597
708.441	5512
708.697	5497
708.954	5469
709.211	5510
709.468	5528
709.725	5476
709.981	5469
710.238	5524
710.495	5436
710.751	5455
711.008	5448
711.265	5401.59
711.521	5413.7
711.778	5331.18
712.035	5424.36
712.291	5368.24
712.548	5326.14
712.804	5312.45
713.061	5261.48
713.317	5252.92
713.574	5204.8
713.831	5216.65
714.087	5191.94
714.343	5111.36
714.6	5089.44
714.856	5110.13
715.113	5067.84
715.369	5028.42
715.626	5044.94
715.882	5038.18
716.138	5021.58
716.395	4996.64
716.639	4972
716.897	4942
717.155	4910
717.412	4843
717.67	4869
717.927	4915
718.185	4842
718.443	4804
718.7	4876
718.958	4770
719.215	4747
719.473	4758
719.73	4748
719.988	4737
720.245	4734
720.503	4715
720.76	4638
721.018	4581
721.275	4594
721.532	4544
721.79	4537
722.047	4542
722.305	4461
722.562	4457
722.819	4427
723.077	4436
723.334	4436
723.591	4354
723.849	4368
724.106	4364
724.363	4318
724.621	4285
724.878	4202
725.135	4256
725.392	4266
725.65	4221
725.907	4207
726.164	4176
726.421	4173
726.678	4120
726.935	4169
727.193	4079
727.45	4093
727.707	4074
727.964	4023
728.221	4023
728.478	4007
728.735	3924
728.992	3894
729.249	3894
729.506	3840
729.763	3803
730.02	3804
730.277	3759
730.534	3725
730.791	3727
731.048	3692
731.305	3674
731.562	3621
731.819	3649
732.076	3637
732.333	3593
732.589	3548
732.846	3613
733.103	3566
733.36	3618
733.617	3598
733.873	3610
734.13	3552
734.387	3524
734.644	3546
734.901	3494
735.157	3480
735.414	3505
735.671	3431
735.927	3430
736.184	3473
736.441	3447
736.697	3409
736.954	3462
737.211	3447
737.467	3466
737.724	3393
737.98	3434
738.237	3455
738.493	3453
738.75	3452
739.006	3442
739.263	3406
739.519	3372
739.776	3359
740.032	3365
740.289	3351
740.545	3368
740.802	3261
741.058	3256
741.314	3246
741.571	3289
741.827	3203
742.083	3203
742.34	3144
742.596	3157
742.852	3206
743.109	3165
743.365	3123
743.621	3123
743.878	3107
744.134	3072
744.39	3066
744.646	3053
744.902	3031
745.159	2998
745.415	2991
745.671	2953
745.927	3003
746.183	2931
746.439	2973
746.695	2947
746.951	2939
747.207	2951
747.463	2928
747.719	2887
747.975	2912
748.231	2901
748.487	2892
748.743	2900
748.999	2886
749.255	2877
749.511	2805
749.767	2843
750.023	2846
750.279	2756
750.535	2756
750.791	2755
751.046	2729
751.302	2710
751.558	2680
751.814	2677
752.07	2668
752.325	2689
752.581	2638
752.837	2643
753.092	2589
753.348	2642
753.604	2594
753.859	2593
754.115	2580
754.371	2568
754.626	2574
754.882	2513
755.138	2517
755.393	2510
755.649	2457
755.904	2497
756.16	2465
756.415	2456
756.671	2455
756.926	2415
757.182	2417
757.437	2393
757.693	2364
757.948	2374
758.203	2326
758.459	2354
758.714	2381.94
758.97	2348.15
759.225	2321.41
759.48	2287.9
759.736	2301.46
759.991	2254.71
760.246	2262.49
760.501	2243.77
760.757	2238.44
761.012	2223.92
761.267	2206.46
761.522	2184.52
761.777	2209.11
762.033	2197.52
762.288	2166.89
762.543	2160.98
762.798	2172.31
763.053	2162.7
763.308	2104.45
763.563	2099.55
763.78	2097
764.037	2088
764.293	2038
764.55	2033
764.806	2020
765.062	2023
765.319	2018
765.575	2005
765.831	1988
766.088	2017
766.344	1979
766.6	1928
766.857	1942
767.113	1966
767.369	1902
767.625	1936
767.882	1905
768.138	1917
768.394	1909
768.65	1858
768.906	1835
769.163	1846
769.419	1808
769.675	1836
769.931	1836
770.187	1804
770.443	1771
770.699	1776
770.955	1775
771.211	1762
771.467	1708
771.723	1741
771.979	1722
772.235	1681
772.491	1688
772.747	1677
773.003	1647
773.259	1684
773.515	1662
773.771	1663
774.027	1618
774.283	1633
774.539	1658
774.795	1557
775.05	1574
775.306	1586
775.562	1550
775.818	1539
776.074	1548
776.329	1527
776.585	1553
776.841	1546
777.097	1526
777.352	1498
777.608	1487
777.864	1465
778.12	1457
778.375	1447
778.631	1445
778.886	1424
779.142	1407
779.398	1412
779.653	1404
779.909	1401
780.164	1379
780.42	1387
780.675	1352
780.931	1396
781.187	1334
781.442	1329
781.698	1344
781.953	1323
782.208	1315
782.464	1285
782.719	1270
782.975	1288
783.23	1280
783.485	1260
783.741	1267
783.996	1226
784.252	1242
784.507	1227
784.762	1222
785.017	1206
785.273	1193
785.528	1178
785.783	1178
786.038	1147
786.294	1188
786.549	1165
786.804	1147
787.059	1124
787.314	1132
787.57	1109
787.825	1093
788.08	1127
788.335	1087
788.59	1083
788.845	1108
789.1	1059
789.355	1059
789.61	1104
789.865	1068
790.12	1038
790.375	1049
790.63	1044
790.885	1009
791.14	1033
791.395	991
791.65	996
791.905	1014
792.16	1003
792.414	981
792.669	954
792.924	989
793.179	928
793.434	940
793.689	921
793.943	949
794.198	920
794.453	910
794.708	920
794.962	927
795.217	904
795.472	891
795.726	902
795.981	893
796.236	897
796.49	873
796.745	875
796.999	862
797.254	858
797.508	847
797.763	850
798.018	835
798.272	831
798.526	819
798.781	807
799.035	826
799.29	799
799.544	794
799.799	788
800.053	785
800.307	772
800.562	799
800.816	754
801.07	767
801.325	748
801.579	753
801.833	734
802.088	762
802.342	743
802.596	745
802.85	718
803.105	728
803.359	701
803.613	691
803.867	705
804.121	699
804.375	691
804.63	691
804.884	670
805.138	704
805.392	691
805.646	684.813
805.9	664.009
806.154	657.557
806.408	666.901
806.662	669.794
806.916	660.992
807.17	654.476
807.424	644.947
807.678	622.127
807.931	635.538
808.185	624.338
808.439	626.39
808.693	616.662
808.947	606.695
809.201	617.437
809.454	608.37
809.708	606.5
809.962	607.773
810.216	598.245
810.469	598.599
810.678	591
810.933	617
811.188	582
811.443	558
811.699	572
811.954	572
812.209	565
812.464	550
812.719	566
812.974	558
813.229	524
813.484	549
813.739	536
813.994	536
814.249	527
814.504	519
814.759	519
815.014	550
815.268	502
815.523	515
815.778	520
816.033	520
816.288	496
816.543	485
816.798	494
817.052	499
817.307	505
817.562	516
817.817	475
818.071	496
818.326	478
818.581	497
818.836	482
819.09	486
819.345	496
819.6	475
819.854	451
820.109	472
820.364	462
820.618	449
820.873	449
821.127	441
821.382	426
821.637	434
821.891	420
822.146	427
822.4	440
822.655	427
822.909	411
823.164	420
823.418	417
823.672	428
823.927	406
824.181	405
824.436	414
824.69	417
824.944	397
825.199	401
825.453	402
825.707	382
825.962	388
826.216	395
826.47	393
826.725	408
826.979	383
827.233	361
827.487	396
827.741	372
827.996	380
828.25	362
828.504	367
828.758	382
829.012	369
829.266	366
829.52	359
829.774	355
830.029	337
830.283	365
830.537	357
830.791	337
831.045	344
831.299	364
831.553	350
831.807	336
832.061	337
832.315	346
832.568	339
832.822	351
833.076	328
833.33	329
833.584	338
833.838	324
834.092	301
834.345	319
834.599	317
834.853	307
835.107	311
835.36	323
835.614	326
835.868	307
836.122	311
836.375	313
836.629	310
836.883	308
837.136	304
837.39	293
837.643	306
837.897	295
838.151	292
838.404	278
838.658	307
838.911	303
839.165	290
839.418	275
839.672	287
839.925	288
840.179	288
840.432	281
840.686	284
840.939	287
841.192	268
841.446	281
841.699	280
841.952	279
842.206	283
842.459	272
842.712	265
842.966	279
843.219	270
843.472	271
843.725	252
843.979	274
844.232	261
844.485	255
844.738	264
844.991	258
845.244	259
845.497	258
845.75	245
846.004	251
846.257	265
846.51	253
846.763	257
847.016	248
847.269	253
847.522	238
847.775	244
848.028	236
848.281	242
848.534	247
848.786	243
849.039	247
849.292	239
849.545	245
849.798	233
850.051	235
850.303	228
850.556	223
850.809	234
851.062	229
851.314	239
851.567	232
851.82	225
852.073	225
852.325	237.92
852.578	216.218
852.831	226.047
853.083	214.158
853.336	207.392
853.588	215.919
853.841	207.255
854.093	213.357
854.346	213.729
854.598	215.84
854.851	214.591
855.103	207.882
855.356	200.265
855.608	209.036
855.861	200.768
856.113	199.37
856.366	198.378
856.618	191.032
856.87	196.751
857.123	200
857.352	200
857.606	198
857.859	194
858.113	194
858.367	196
858.621	187
858.875	194
859.128	189
859.382	190
859.636	192
859.889	195
860.143	179
860.397	193
860.65	193
860.904	190
861.158	185
861.411	183
861.665	190
861.918	182
862.172	170
862.425	189
862.679	175
862.932	193
863.186	177
863.439	190
863.693	164
863.946	184
864.2	169
864.453	172
864.707	159
864.96	177
865.213	163
865.467	167
865.72	169
865.973	175
866.227	180
866.48	171
866.733	170
866.987	163
867.24	165
867.493	179
867.746	161
867.999	163
868.253	172
868.506	164
868.759	157
869.012	157
869.265	151
869.518	159
869.771	158
870.025	153
870.278	156
870.531	150
870.784	155
871.037	144
871.29	158
871.543	162
871.796	141
872.049	150
872.302	164
872.555	150
872.808	143
873.06	150
873.313	149
873.566	151
873.819	151
874.072	142
874.325	154
874.578	141
874.83	136
875.083	137
875.336	147
875.589	145
875.841	152
876.094	143
876.347	142
876.6	134
876.852	136
877.105	142
877.358	149
877.61	136
877.863	135
878.115	129
878.368	132
878.621	127
878.873	143
879.126	125
879.378	137
879.631	136
879.883	138
880.136	134
880.388	135
880.641	133
880.893	117
881.145	127
881.398	139
881.65	129
881.902	128
882.155	120
882.407	122
882.659	135
882.912	129
883.164	110
883.416	123
883.669	113
883.921	109
884.173	111
884.425	129
884.677	118
884.93	111
885.182	118
885.434	122
885.686	116
885.938	119
886.19	118
886.442	117
886.694	114
886.946	120
887.198	116
887.45	109
887.702	109
887.954	115
888.206	120
888.458	109
888.71	111
888.962	102
889.214	110
889.466	103
889.718	107
889.969	115
890.221	110
890.473	106
890.725	116
890.977	101
891.228	91
891.48	103
891.732	100
891.983	96
892.235	107
892.487	102
892.738	107
892.99	112
893.242	93
893.493	105
893.745	109
893.996	100
894.248	100
894.5	87
894.751	99
895.003	90
895.254	91
895.505	96
895.757	101
896.008	93
896.26	88
896.511	94
896.763	93
897.014	89
897.265	96
897.517	93
897.768	93
898.019	92
898.27	86
898.522	98
898.773	86
899.024	88
899.275	91
899.527	89
899.778	87
899.979	90