File: PL_M2_280424_02.txt
#Acq. time (s)=	3
#Accumulations=	2
#Range (nm)=	520...900
#Windows=	8
#Auto scanning=	Off
#Autofocus=	Off
#AutoExposure=	Off
#Spike filter=	Off
#Delay time (s)=	0
#Binning=	1
#Readout mode=	Signal
#DeNoise=	Off
#ICS correction=	Off
#Dark correction=	Off
#Inst. Process=	Off
#Detector temperature (°C)=	-59.98
#Instrument=	LabRAM HR Evol
#Detector=	Syncerity OE
#Objective=	x50_VIS
#Grating=	600 (500nm)
#ND Filter=	25%
#Laser=	514nm_Edge
#Hole=	199.981
#Range=	Visible
#StageXY=	Marzhauser
#StageZ=	Marzhauser
#X (µm)=	19.4
#Y (µm)=	-924.1
#Z (µm)=	-259.1
#Full time(mm:ss)=	1:32
#Project=
#Sample=
#Site=
#Title=	PL_M2_280424
#Remark=
#Date=	06.05.2024 16:35
#Acquired=	06.05.2024 16:35:02
520.044	68
520.306	56
520.569	68
520.831	62
521.093	60
521.355	67
521.617	67
521.88	62
522.142	59
522.404	65
522.666	66
522.928	63
523.19	65
523.453	64
523.715	55
523.977	51
524.239	65
524.501	60
524.763	62
525.025	61
525.287	55
525.549	59
525.811	58
526.073	64
526.335	58
526.597	59
526.859	57
527.121	62
527.383	55
527.645	59
527.907	62
528.169	60
528.431	57
528.693	63
528.955	56
529.217	57
529.479	58
529.741	61
530.003	61
530.264	57
530.526	61
530.788	69
531.05	53
531.312	62
531.574	56
531.835	68
532.097	62
532.359	66
532.621	63
532.883	72
533.144	74
533.406	72
533.668	71
533.93	76
534.191	69
534.453	87
534.715	80
534.976	90
535.238	87
535.5	96
535.761	90
536.023	91
536.285	81
536.546	77
536.808	72
537.069	80
537.331	74
537.593	75
537.854	73
538.116	81
538.377	90
538.639	77
538.9	78
539.162	98
539.423	87
539.685	98
539.946	96
540.208	98
540.469	93
540.731	84
540.992	95
541.254	99
541.515	112
541.776	90
542.038	106
542.299	96
542.56	88
542.822	96
543.083	92
543.344	93
543.606	107
543.867	99
544.128	110
544.39	113
544.651	115
544.912	113
545.174	120
545.435	108
545.696	120
545.957	119
546.218	126
546.48	124
546.741	124
547.002	117
547.263	135
547.524	145
547.785	152
548.047	141
548.308	158
548.569	147
548.83	157
549.091	153
549.352	152
549.613	157
549.874	169
550.135	160
550.396	192
550.657	180
550.918	207
551.179	213
551.44	219
551.701	266
551.962	315
552.223	449
552.484	2299
552.745	42795
553.006	1045
553.267	424
553.528	306
553.788	262
554.049	251
554.31	257
554.571	236
554.832	234
555.093	241
555.353	246
555.614	247
555.875	235
556.136	237
556.396	256
556.657	270
556.918	267
557.179	269
557.439	261
557.7	280
557.961	279
558.221	283
558.482	293
558.743	307
559.003	299
559.264	286
559.525	311
559.785	307
560.046	318
560.306	337
560.567	331
560.827	333
561.088	334
561.348	341
561.609	380
561.869	359
562.13	364
562.39	384
562.651	391
562.911	393
563.172	403
563.432	420
563.692	428
563.953	442
564.213	452
564.474	471
564.734	473
564.994	437
565.255	478
565.515	483
565.775	494
566.035	498
566.296	494
566.556	517
566.816	506
567.076	524
567.337	537
567.597	562
567.857	555
568.117	585.835
568.377	582.116
568.637	590.321
568.898	594.07
569.158	607.21
569.418	625.974
569.678	638.681
569.938	640.899
570.198	660.358
570.458	686.67
570.718	707.697
570.978	717.736
571.238	759.077
571.498	780.03
571.758	819.677
572.018	863.032
572.278	912.484
572.538	953.46
572.798	1003.66
573.058	1060.1
573.312	1100
573.573	1215
573.834	1302
574.095	1412
574.356	1505
574.617	1686
574.878	1829
575.139	1935
575.4	2049
575.661	2157
575.922	2207
576.183	2192
576.444	2153
576.705	2057
576.965	1921
577.226	1825
577.487	1770
577.748	1641
578.009	1577
578.27	1516
578.531	1446
578.791	1407
579.052	1397
579.313	1370
579.574	1350
579.835	1369
580.095	1377
580.356	1370
580.617	1340
580.878	1381
581.138	1378
581.399	1381
581.66	1402
581.92	1421
582.181	1435
582.442	1446
582.703	1467
582.963	1470
583.224	1513
583.484	1503
583.745	1520
584.006	1564
584.266	1630
584.527	1619
584.787	1611
585.048	1713
585.308	1702
585.569	1777
585.83	1747
586.09	1787
586.351	1843
586.611	1854
586.872	1847
587.132	1852
587.392	1896
587.653	1931
587.913	1902
588.174	1933
588.434	1939
588.695	1954
588.955	1967
589.215	1954
589.476	2004
589.736	2003
589.996	2023
590.257	1950
590.517	2023
590.777	2022
591.038	1981
591.298	1982
591.558	1953
591.818	1899
592.079	1922
592.339	1910
592.599	1915
592.859	1907
593.12	1907
593.38	1900
593.64	1927
593.9	1895
594.16	1904
594.42	1963
594.68	1964
594.941	1945
595.201	1970
595.461	1979
595.721	2022
595.981	2066
596.241	2106
596.501	2062
596.761	2173
597.021	2112
597.281	2096
597.541	2091
597.801	2088
598.061	2129
598.321	2165
598.581	2147
598.841	2169
599.101	2182
599.361	2181
599.62	2168
599.88	2229
600.14	2182
600.4	2285
600.66	2214
600.92	2224
601.18	2217
601.439	2241
601.699	2231
601.959	2257
602.219	2190
602.478	2237
602.738	2250
602.998	2245
603.258	2231
603.517	2288
603.777	2261
604.037	2268
604.296	2284
604.556	2320
604.816	2295
605.075	2287
605.335	2335
605.594	2330
605.854	2300
606.114	2281
606.373	2289
606.633	2300
606.892	2313
607.152	2320
607.411	2307
607.671	2340
607.93	2326
608.19	2336
608.449	2377
608.709	2373
608.968	2399
609.228	2397
609.487	2433
609.746	2442
610.006	2390
610.265	2434
610.524	2474
610.784	2493
611.043	2502
611.302	2507
611.562	2503
611.821	2516
612.08	2563
612.339	2579
612.599	2546
612.858	2541
613.117	2571
613.376	2621
613.635	2640
613.895	2633
614.154	2680
614.413	2675
614.672	2753
614.931	2716
615.19	2809
615.449	2798
615.709	2842
615.968	2842
616.227	2861.91
616.486	2831.11
616.745	2895.39
617.004	2891.28
617.263	2908.91
617.522	2907.25
617.781	2935.66
618.04	2932.69
618.299	2980.25
618.557	2999.62
618.816	2984.03
619.075	2995.36
619.334	3014.59
619.593	3046.35
619.852	3040.11
620.111	3075.63
620.37	3083.69
620.628	3077.08
620.887	3097.75
621.146	3104.26
621.373	3133
621.633	3099
621.893	3154
622.153	3148
622.413	3149
622.673	3148
622.932	3169
623.192	3166
623.452	3152
623.712	3143
623.972	3167
624.232	3181
624.492	3236
624.751	3255
625.011	3267
625.271	3219
625.531	3281
625.791	3311
626.05	3308
626.31	3319
626.57	3354
626.83	3324
627.089	3428
627.349	3393
627.609	3457
627.868	3425
628.128	3457
628.388	3434
628.647	3492
628.907	3537
629.167	3496
629.426	3536
629.686	3577
629.945	3558
630.205	3663
630.465	3630
630.724	3689
630.984	3662
631.243	3747
631.503	3725
631.762	3797
632.022	3768
632.281	3806
632.541	3828
632.8	3880
633.06	3861
633.319	3938
633.579	3987
633.838	3991
634.097	3998
634.357	4089
634.616	4144
634.876	4140
635.135	4242
635.394	4325
635.654	4380
635.913	4480
636.172	4574
636.431	4736
636.691	4867
636.95	5096
637.209	5333
637.469	5568
637.728	5913
637.987	6259
638.246	6415
638.505	6371
638.765	6219
639.024	6050
639.283	5807
639.542	5772
639.801	5639
640.06	5518
640.319	5339
640.578	5313
640.838	5234
641.097	5140
641.356	5072
641.615	5139
641.874	5082
642.133	5165
642.392	5090
642.651	5112
642.91	5083
643.169	5129
643.428	5066
643.687	5092
643.946	5097
644.205	5131
644.463	5196
644.722	5224
644.981	5248
645.24	5193
645.499	5260
645.758	5272
646.017	5291
646.275	5318
646.534	5366
646.793	5394
647.052	5420
647.31	5467
647.569	5420
647.828	5491
648.087	5507
648.345	5556
648.604	5522
648.863	5618
649.121	5640
649.38	5680
649.639	5711
649.897	5712
650.156	5811
650.415	5798
650.673	5789
650.932	5813
651.19	5915
651.449	5908
651.707	5929
651.966	6004
652.224	6123
652.483	6091
652.741	6136
653	6189
653.258	6181
653.517	6232
653.775	6287
654.034	6368
654.292	6481
654.55	6487
654.809	6558
655.067	6594
655.326	6625
655.584	6749
655.842	6764
656.1	6898
656.359	6964
656.617	7067
656.875	7128
657.134	7187
657.392	7207
657.65	7284
657.908	7389
658.166	7406
658.425	7456
658.683	7441
658.941	7554
659.199	7546
659.457	7558
659.715	7638
659.973	7651
660.231	7655
660.49	7692
660.748	7715
661.006	7631
661.264	7649
661.522	7622
661.78	7560
662.038	7630
662.296	7629
662.554	7650
662.811	7601
663.069	7643
663.327	7717
663.585	7604
663.843	7633.93
664.101	7688.94
664.359	7674.82
664.617	7713.27
664.874	7674.14
665.132	7687.75
665.39	7636.93
665.648	7687.98
665.906	7675.25
666.163	7660.45
666.421	7648.77
666.679	7646.42
666.937	7671.22
667.194	7686.3
667.452	7575.39
667.71	7609.14
667.967	7671.42
668.225	7689.64
668.482	7705.31
668.74	7621.09
668.987	7633
669.245	7567
669.504	7633
669.763	7657
670.022	7659
670.281	7694
670.539	7645
670.798	7721
671.057	7694
671.316	7667
671.575	7665
671.833	7707
672.092	7717
672.351	7676
672.609	7697
672.868	7740
673.127	7799
673.385	7901
673.644	7832
673.903	7906
674.161	7956
674.42	8020
674.678	7913
674.937	8054
675.195	8047
675.454	8033
675.713	8111
675.971	8152
676.23	8210
676.488	8217
676.747	8216
677.005	8242
677.263	8153
677.522	8182
677.78	8168
678.039	8196
678.297	8169
678.556	8155
678.814	8150
679.072	8216
679.331	8257
679.589	8275
679.847	8208
680.106	8237
680.364	8307
680.622	8310
680.881	8296
681.139	8384
681.397	8370
681.656	8461
681.914	8408
682.172	8464
682.43	8493
682.688	8521
682.947	8432
683.205	8494
683.463	8537
683.721	8586
683.979	8477
684.237	8473
684.495	8463
684.754	8454
685.012	8413
685.27	8364
685.528	8450
685.786	8332
686.044	8331
686.302	8415
686.56	8369
686.818	8265
687.076	8357
687.334	8327
687.592	8318
687.85	8212
688.108	8319
688.366	8352
688.623	8242
688.881	8250
689.139	8229
689.397	8203
689.655	8208
689.913	8240
690.171	8145
690.428	8190
690.686	8216
690.944	8121
691.202	8243
691.459	8057
691.717	8021
691.975	8052
692.233	7985
692.49	7920
692.748	7962
693.006	7987
693.263	7880
693.521	7933
693.779	7898
694.036	7902
694.294	7884
694.552	7821
694.809	7822
695.067	7862
695.324	7888
695.582	7919
695.839	7773
696.097	7844
696.354	7732
696.612	7668
696.869	7641
697.127	7658
697.384	7694
697.642	7598
697.899	7548
698.156	7531
698.414	7560
698.671	7524
698.928	7427
699.186	7401
699.443	7483
699.7	7320
699.958	7294
700.215	7386
700.472	7329
700.73	7302
700.987	7435
701.244	7287
701.501	7341
701.758	7310
702.016	7279
702.273	7272
702.53	7399
702.787	7295
703.044	7330
703.301	7318
703.558	7304
703.816	7282
704.073	7343
704.33	7255
704.587	7235
704.844	7221
705.101	7257
705.358	7175
705.615	7094
705.872	7025
706.129	7062
706.386	7047
706.643	7037
706.899	6984
707.156	6913
707.413	6896
707.67	6871
707.927	6856
708.184	6870
708.441	6830
708.697	6728
708.954	6831
709.211	6791
709.468	6739
709.725	6745
709.981	6670
710.238	6739
710.495	6773
710.751	6657
711.008	6720
711.265	6683.46
711.521	6611.06
711.778	6682.31
712.035	6578.26
712.291	6546.23
712.548	6520.45
712.804	6482.25
713.061	6456.44
713.317	6430.98
713.574	6384.35
713.831	6337.2
714.087	6351.88
714.343	6313.78
714.6	6308.32
714.856	6259.8
715.113	6214.28
715.369	6184.11
715.626	6186.08
715.882	6144.3
716.138	6084.58
716.395	6075.77
716.639	6108
716.897	6021
717.155	6027
717.412	5984
717.67	5930
717.927	5976
718.185	5869
718.443	5909
718.7	5876
718.958	5861
719.215	5788
719.473	5801
719.73	5739
719.988	5712
720.245	5720
720.503	5648
720.76	5631
721.018	5615
721.275	5567
721.532	5580
721.79	5520
722.047	5469
722.305	5476
722.562	5337
722.819	5429
723.077	5310
723.334	5320
723.591	5275
723.849	5288
724.106	5264
724.363	5236
724.621	5208
724.878	5178
725.135	5153
725.392	5149
725.65	5139
725.907	5114
726.164	5050
726.421	5140
726.678	5031
726.935	4956
727.193	4931
727.45	4891
727.707	4874
727.964	4962
728.221	4868
728.478	4808
728.735	4753
728.992	4742
729.249	4711
729.506	4656
729.763	4696
730.02	4612
730.277	4577
730.534	4541
730.791	4517
731.048	4509
731.305	4443
731.562	4500
731.819	4496
732.076	4426
732.333	4433
732.589	4428
732.846	4377
733.103	4372
733.36	4310
733.617	4334
733.873	4320
734.13	4363
734.387	4287
734.644	4293
734.901	4284
735.157	4269
735.414	4234
735.671	4271
735.927	4199
736.184	4184
736.441	4177
736.697	4166
736.954	4191
737.211	4207
737.467	4178
737.724	4203
737.98	4252
738.237	4176
738.493	4195
738.75	4176
739.006	4118
739.263	4094
739.519	4111
739.776	4077
740.032	4032
740.289	4055
740.545	4000
740.802	3985
741.058	3971
741.314	3960
741.571	3953
741.827	3908
742.083	3858
742.34	3867
742.596	3873
742.852	3794
743.109	3805
743.365	3787
743.621	3749
743.878	3741
744.134	3761
744.39	3694
744.646	3724
744.902	3651
745.159	3662
745.415	3690
745.671	3595
745.927	3607
746.183	3585
746.439	3579
746.695	3559
746.951	3659
747.207	3530
747.463	3511
747.719	3497
747.975	3515
748.231	3479
748.487	3494
748.743	3487
748.999	3387
749.255	3460
749.511	3382
749.767	3376
750.023	3352
750.279	3335
750.535	3337
750.791	3317
751.046	3288
751.302	3286
751.558	3268
751.814	3302
752.07	3248
752.325	3220
752.581	3192
752.837	3180
753.092	3199
753.348	3171
753.604	3138
753.859	3114
754.115	3161
754.371	3066
754.626	3119
754.882	3043
755.138	3038
755.393	3021
755.649	3003
755.904	2944
756.16	3000
756.415	3006
756.671	2977
756.926	2918
757.182	2935
757.437	2918
757.693	2887
757.948	2808
758.203	2875
758.459	2861
758.714	2830.32
758.97	2787.19
759.225	2759.6
759.48	2773.86
759.736	2739.65
759.991	2775.39
760.246	2702.29
760.501	2707.51
760.757	2684.03
761.012	2679.52
761.267	2658.52
761.522	2659.94
761.777	2620.18
762.033	2620.53
762.288	2608.16
762.543	2592.88
762.798	2587.19
763.053	2549.81
763.308	2517.66
763.563	2523.29
763.78	2490
764.037	2515
764.293	2433
764.55	2480
764.806	2448
765.062	2494
765.319	2469
765.575	2468
765.831	2414
766.088	2413
766.344	2372
766.6	2388
766.857	2330
767.113	2332
767.369	2310
767.625	2307
767.882	2285
768.138	2299
768.394	2236
768.65	2238
768.906	2200
769.163	2202
769.419	2204
769.675	2214
769.931	2156
770.187	2141
770.443	2109
770.699	2139
770.955	2098
771.211	2066
771.467	2060
771.723	2072
771.979	2060
772.235	2040
772.491	1983
772.747	2026
773.003	1992
773.259	1960
773.515	1949
773.771	1976
774.027	1888
774.283	1960
774.539	1919
774.795	1879
775.05	1895
775.306	1867
775.562	1845
775.818	1843
776.074	1867
776.329	1865
776.585	1802
776.841	1804
777.097	1815
777.352	1771
777.608	1768
777.864	1737
778.12	1730
778.375	1699
778.631	1690
778.886	1702
779.142	1716
779.398	1697
779.653	1628
779.909	1653
780.164	1670
780.42	1616
780.675	1613
780.931	1596
781.187	1589
781.442	1610
781.698	1580
781.953	1588
782.208	1587
782.464	1542
782.719	1531
782.975	1538
783.23	1505
783.485	1476
783.741	1477
783.996	1489
784.252	1491
784.507	1455
784.762	1456
785.017	1423
785.273	1411
785.528	1414
785.783	1431
786.038	1425
786.294	1379
786.549	1331
786.804	1366
787.059	1327
787.314	1351
787.57	1298
787.825	1324
788.08	1327
788.335	1301
788.59	1294
788.845	1260
789.1	1331
789.355	1245
789.61	1237
789.865	1261
790.12	1237
790.375	1209
790.63	1225
790.885	1235
791.14	1235
791.395	1186
791.65	1171
791.905	1169
792.16	1155
792.414	1156
792.669	1164
792.924	1144
793.179	1112
793.434	1134
793.689	1107
793.943	1116
794.198	1096
794.453	1098
794.708	1075
794.962	1064
795.217	1071
795.472	1030
795.726	1031
795.981	1057
796.236	1031
796.49	1029
796.745	1016
796.999	996
797.254	1011
797.508	986
797.763	988
798.018	980
798.272	967
798.526	965
798.781	951
799.035	934
799.29	926
799.544	938
799.799	925
800.053	901
800.307	918
800.562	901
800.816	918
801.07	890
801.325	897
801.579	899
801.833	857
802.088	872
802.342	845
802.596	878
802.85	862
803.105	845
803.359	824
803.613	841
803.867	831
804.121	813
804.375	816
804.63	786
804.884	794
805.138	815
805.392	793
805.646	773.549
805.9	777.207
806.154	775.855
806.408	775.789
806.662	756.453
806.916	765.278
807.17	754.494
807.424	757.428
807.678	745.431
807.931	730.042
808.185	724.37
808.439	738.779
808.693	724.055
808.947	707.881
809.201	717.24
809.454	710.707
809.708	712.371
809.962	684.689
810.216	688.43
810.469	688.016
810.678	672
810.933	682
811.188	690
811.443	677
811.699	650
811.954	664
812.209	650
812.464	652
812.719	634
812.974	637
813.229	648
813.484	635
813.739	607
813.994	611
814.249	634
814.504	616
814.759	624
815.014	619
815.268	614
815.523	598
815.778	607
816.033	571
816.288	584
816.543	581
816.798	567
817.052	573
817.307	575
817.562	554
817.817	554
818.071	549
818.326	556
818.581	556
818.836	534
819.09	536
819.345	575
819.6	537
819.854	525
820.109	535
820.364	517
820.618	523
820.873	513
821.127	508
821.382	514
821.637	505
821.891	488
822.146	502
822.4	494
822.655	487
822.909	484
823.164	474
823.418	489
823.672	472
823.927	498
824.181	482
824.436	471
824.69	475
824.944	470
825.199	458
825.453	454
825.707	451
825.962	450
826.216	466
826.47	453
826.725	438
826.979	443
827.233	447
827.487	448
827.741	440
827.996	441
828.25	437
828.504	454
828.758	423
829.012	418
829.266	418
829.52	410
829.774	413
830.029	416
830.283	415
830.537	412
830.791	413
831.045	401
831.299	399
831.553	398
831.807	397
832.061	375
832.315	401
832.568	388
832.822	403
833.076	386
833.33	381
833.584	369
833.838	370
834.092	377
834.345	377
834.599	383
834.853	371
835.107	364
835.36	341
835.614	365
835.868	356
836.122	357
836.375	347
836.629	362
836.883	354
837.136	350
837.39	346
837.643	324
837.897	333
838.151	338
838.404	341
838.658	341
838.911	336
839.165	332
839.418	335
839.672	335
839.925	332
840.179	326
840.432	324
840.686	322
840.939	322
841.192	320
841.446	319
841.699	314
841.952	320
842.206	326
842.459	333
842.712	310
842.966	313
843.219	311
843.472	302
843.725	302
843.979	298
844.232	307
844.485	289
844.738	289
844.991	291
845.244	292
845.497	285
845.75	275
846.004	289
846.257	291
846.51	274
846.763	275
847.016	291
847.269	281
847.522	265
847.775	279
848.028	288
848.281	260
848.534	270
848.786	270
849.039	282
849.292	283
849.545	264
849.798	269
850.051	255
850.303	265
850.556	263
850.809	256
851.062	270
851.314	258
851.567	250
851.82	252
852.073	249
852.325	248.024
852.578	249.998
852.831	240.184
853.083	264.402
853.336	241.718
853.588	241.656
853.841	238.467
854.093	245.852
854.346	237.063
854.598	229.118
854.851	240.294
855.103	238.877
855.356	229.57
855.608	228.278
855.861	224.034
856.113	222.539
856.366	230.623
856.618	227.775
856.87	225.392
857.123	223.374
857.352	229
857.606	223
857.859	209
858.113	217
858.367	216
858.621	217
858.875	209
859.128	203
859.382	209
859.636	212
859.889	203
860.143	223
860.397	223
860.65	215
860.904	198
861.158	200
861.411	205
861.665	218
861.918	196
862.172	201
862.425	191
862.679	201
862.932	194
863.186	196
863.439	194
863.693	183
863.946	216
864.2	188
864.453	197
864.707	198
864.96	188
865.213	189
865.467	193
865.72	178
865.973	185
866.227	186
866.48	190
866.733	202
866.987	185
867.24	188
867.493	186
867.746	189
867.999	189
868.253	189
868.506	189
868.759	180
869.012	193
869.265	180
869.518	177
869.771	182
870.025	167
870.278	162
870.531	178
870.784	180
871.037	184
871.29	173
871.543	165
871.796	180
872.049	162
872.302	173
872.555	166
872.808	167
873.06	170
873.313	157
873.566	173
873.819	173
874.072	159
874.325	167
874.578	159
874.83	165
875.083	153
875.336	151
875.589	139
875.841	152
876.094	160
876.347	149
876.6	148
876.852	160
877.105	150
877.358	145
877.61	139
877.863	167
878.115	152
878.368	148
878.621	144
878.873	149
879.126	146
879.378	145
879.631	134
879.883	145
880.136	155
880.388	148
880.641	142
880.893	154
881.145	153
881.398	144
881.65	151
881.902	133
882.155	150
882.407	135
882.659	137
882.912	151
883.164	135
883.416	142
883.669	136
883.921	133
884.173	138
884.425	120
884.677	131
884.93	130
885.182	133
885.434	129
885.686	127
885.938	141
886.19	127
886.442	125
886.694	124
886.946	126
887.198	131
887.45	124
887.702	126
887.954	114
888.206	133
888.458	121
888.71	126
888.962	108
889.214	127
889.466	124
889.718	122
889.969	117
890.221	128
890.473	113
890.725	107
890.977	126
891.228	127
891.48	106
891.732	110
891.983	108
892.235	111
892.487	113
892.738	104
892.99	107
893.242	108
893.493	113
893.745	114
893.996	108
894.248	98
894.5	114
894.751	112
895.003	98
895.254	104
895.505	110
895.757	111
896.008	105
896.26	99
896.511	108
896.763	109
897.014	95
897.265	98
897.517	105
897.768	103
898.019	95
898.27	93
898.522	109
898.773	107
899.024	96
899.275	95
899.527	107
899.778	100
899.979	104