File: PL_M5_280424_01.txt
#Acq. time (s)=	3
#Accumulations=	2
#Range (nm)=	520...900
#Windows=	8
#Auto scanning=	Off
#Autofocus=	Off
#AutoExposure=	Off
#Spike filter=	Off
#Delay time (s)=	0
#Binning=	1
#Readout mode=	Signal
#DeNoise=	Off
#ICS correction=	Off
#Dark correction=	Off
#Inst. Process=	Off
#Detector temperature (°C)=	-59.98
#Instrument=	LabRAM HR Evol
#Detector=	Syncerity OE
#Objective=	x50_VIS
#Grating=	600 (500nm)
#ND Filter=	25%
#Laser=	514nm_Edge
#Hole=	199.981
#Range=	Visible
#StageXY=	Marzhauser
#StageZ=	Marzhauser
#X (µm)=	8995.1
#Y (µm)=	-4227
#Z (µm)=	-261.6
#Full time(mm:ss)=	1:32
#Project=
#Sample=
#Site=
#Title=	PL_M5_280424
#Remark=
#Date=	06.05.2024 16:44
#Acquired=	06.05.2024 16:44:15
520.044	36
520.306	39
520.569	46
520.831	46
521.093	40
521.355	39
521.617	46
521.88	40
522.142	44
522.404	44
522.666	42
522.928	41
523.19	45
523.453	39
523.715	44
523.977	38
524.239	41
524.501	45
524.763	47
525.025	51
525.287	43
525.549	43
525.811	42
526.073	47
526.335	47
526.597	33
526.859	50
527.121	55
527.383	41
527.645	42
527.907	49
528.169	49
528.431	46
528.693	47
528.955	38
529.217	46
529.479	45
529.741	40
530.003	44
530.264	44
530.526	47
530.788	38
531.05	47
531.312	51
531.574	46
531.835	49
532.097	39
532.359	48
532.621	50
532.883	40
533.144	55
533.406	54
533.668	47
533.93	48
534.191	46
534.453	59
534.715	61
534.976	60
535.238	75
535.5	65
535.761	67
536.023	59
536.285	50
536.546	60
536.808	63
537.069	46
537.331	57
537.593	59
537.854	57
538.116	49
538.377	50
538.639	61
538.9	49
539.162	56
539.423	63
539.685	55
539.946	60
540.208	59
540.469	56
540.731	70
540.992	61
541.254	48
541.515	63
541.776	64
542.038	56
542.299	63
542.56	57
542.822	63
543.083	66
543.344	64
543.606	63
543.867	68
544.128	72
544.39	70
544.651	65
544.912	71
545.174	81
545.435	79
545.696	61
545.957	77
546.218	82
546.48	74
546.741	77
547.002	83
547.263	91
547.524	97
547.785	80
548.047	90
548.308	96
548.569	87
548.83	95
549.091	96
549.352	98
549.613	107
549.874	94
550.135	119
550.396	119
550.657	123
550.918	116
551.179	134
551.44	148
551.701	192
551.962	234
552.223	368
552.484	1824
552.745	39158
553.006	1067
553.267	322
553.528	209
553.788	172
554.049	160
554.31	152
554.571	138
554.832	149
555.093	135
555.353	138
555.614	146
555.875	148
556.136	128
556.396	151
556.657	140
556.918	141
557.179	147
557.439	142
557.7	160
557.961	159
558.221	150
558.482	161
558.743	156
559.003	175
559.264	178
559.525	174
559.785	174
560.046	191
560.306	171
560.567	177
560.827	193
561.088	187
561.348	187
561.609	189
561.869	211
562.13	202
562.39	209
562.651	202
562.911	216
563.172	225
563.432	217
563.692	230
563.953	257
564.213	265
564.474	249
564.734	256
564.994	259
565.255	265
565.515	246
565.775	251
566.035	266
566.296	266
566.556	275
566.816	278
567.076	284
567.337	294
567.597	291
567.857	267
568.117	315.92
568.377	304.929
568.637	305.212
568.898	306.977
569.158	324.116
569.418	335.953
569.678	334.777
569.938	346.086
570.198	345.573
570.458	354.84
570.718	372.54
570.978	387.061
571.238	392.857
571.498	408.721
571.758	433.784
572.018	438.468
572.278	478.769
572.538	483.125
572.798	534.853
573.058	553.711
573.312	583
573.573	624
573.834	690
574.095	726
574.356	792
574.617	866
574.878	940
575.139	1011
575.4	1081
575.661	1112
575.922	1123
576.183	1110
576.444	1047
576.705	1039
576.965	976
577.226	906
577.487	860
577.748	850
578.009	770
578.27	766
578.531	710
578.791	718
579.052	715
579.313	714
579.574	712
579.835	729
580.095	709
580.356	710
580.617	705
580.878	734
581.138	715
581.399	726
581.66	714
581.92	755
582.181	719
582.442	757
582.703	772
582.963	792
583.224	775
583.484	807
583.745	811
584.006	836
584.266	858
584.527	862
584.787	889
585.048	908
585.308	904
585.569	944
585.83	978
586.09	963
586.351	990
586.611	986
586.872	974
587.132	974
587.392	1006
587.653	996
587.913	1015
588.174	1056
588.434	1056
588.695	1025
588.955	1047
589.215	1122
589.476	1109
589.736	1121
589.996	1106
590.257	1073
590.517	1058
590.777	1102
591.038	1041
591.298	1069
591.558	1045
591.818	1022
592.079	1030
592.339	1008
592.599	1002
592.859	1003
593.12	1025
593.38	1029
593.64	1012
593.9	1010
594.16	999
594.42	995
594.68	1000
594.941	1031
595.201	1057
595.461	1058
595.721	1089
595.981	1064
596.241	1079
596.501	1118
596.761	1143
597.021	1124
597.281	1102
597.541	1086
597.801	1106
598.061	1075
598.321	1113
598.581	1140
598.841	1113
599.101	1090
599.361	1114
599.62	1127
599.88	1110
600.14	1147
600.4	1151
600.66	1138
600.92	1135
601.18	1151
601.439	1162
601.699	1158
601.959	1150
602.219	1140
602.478	1137
602.738	1158
602.998	1135
603.258	1166
603.517	1153
603.777	1171
604.037	1192
604.296	1185
604.556	1179
604.816	1168
605.075	1156
605.335	1189
605.594	1158
605.854	1195
606.114	1181
606.373	1186
606.633	1152
606.892	1204
607.152	1219
607.411	1214
607.671	1208
607.93	1202
608.19	1207
608.449	1230
608.709	1242
608.968	1233
609.228	1245
609.487	1244
609.746	1258
610.006	1231
610.265	1270
610.524	1292
610.784	1254
611.043	1271
611.302	1312
611.562	1290
611.821	1298
612.08	1327
612.339	1312
612.599	1316
612.858	1332
613.117	1361
613.376	1343
613.635	1329
613.895	1387
614.154	1370
614.413	1425
614.672	1434
614.931	1407
615.19	1439
615.449	1449
615.709	1452
615.968	1464
616.227	1462.64
616.486	1471.76
616.745	1480.49
617.004	1505.14
617.263	1506.7
617.522	1511.47
617.781	1508.76
618.04	1535.53
618.299	1516.08
618.557	1531.89
618.816	1548.51
619.075	1572.62
619.334	1590.77
619.593	1569.87
619.852	1579.76
620.111	1602.94
620.37	1606.33
620.628	1633.01
620.887	1602.69
621.146	1611.81
621.373	1628
621.633	1577
621.893	1636
622.153	1641
622.413	1634
622.673	1638
622.932	1609
623.192	1639
623.452	1652
623.712	1642
623.972	1658
624.232	1649
624.492	1676
624.751	1666
625.011	1664
625.271	1686
625.531	1701
625.791	1710
626.05	1743
626.31	1752
626.57	1741
626.83	1734
627.089	1777
627.349	1795
627.609	1791
627.868	1767
628.128	1769
628.388	1807
628.647	1841
628.907	1816
629.167	1841
629.426	1883
629.686	1828
629.945	1866
630.205	1901
630.465	1918
630.724	1938
630.984	1927
631.243	1914
631.503	1926
631.762	1992
632.022	2046
632.281	1956
632.541	1989
632.8	2015
633.06	2071
633.319	2069
633.579	2074
633.838	2073
634.097	2147
634.357	2160
634.616	2210
634.876	2209
635.135	2249
635.394	2266
635.654	2290
635.913	2364
636.172	2415
636.431	2536
636.691	2668
636.95	2773
637.209	2908
637.469	3047
637.728	3261
637.987	3262
638.246	3324
638.505	3299
638.765	3234
639.024	3117
639.283	3030
639.542	2926
639.801	2883
640.06	2871
640.319	2805
640.578	2726
640.838	2747
641.097	2723
641.356	2644
641.615	2677
641.874	2690
642.133	2652
642.392	2649
642.651	2663
642.91	2669
643.169	2677
643.428	2740
643.687	2724
643.946	2694
644.205	2704
644.463	2772
644.722	2775
644.981	2738
645.24	2731
645.499	2795
645.758	2846
646.017	2816
646.275	2836
646.534	2799
646.793	2841
647.052	2840
647.31	2823
647.569	2872
647.828	2890
648.087	2898
648.345	2904
648.604	2881
648.863	2956
649.121	2937
649.38	3005
649.639	3033
649.897	2978
650.156	3064
650.415	3065
650.673	3104
650.932	3082
651.19	3114
651.449	3155
651.707	3204
651.966	3173
652.224	3246
652.483	3214
652.741	3247
653	3255
653.258	3293
653.517	3346
653.775	3356
654.034	3410
654.292	3411
654.55	3439
654.809	3506
655.067	3537
655.326	3586
655.584	3656
655.842	3706
656.1	3714
656.359	3734
656.617	3747
656.875	3850
657.134	3813
657.392	3911
657.65	3935
657.908	3970
658.166	3957
658.425	4036
658.683	4045
658.941	4021
659.199	4051
659.457	4035
659.715	4049
659.973	4041
660.231	4005
660.49	4116
660.748	4034
661.006	4080
661.264	4085
661.522	4086
661.78	4104
662.038	4086
662.296	4108
662.554	4063
662.811	4067
663.069	4044
663.327	4032
663.585	4100
663.843	4101.33
664.101	4105.28
664.359	4135.77
664.617	4110.34
664.874	4098.92
665.132	4091.7
665.39	4065.59
665.648	4100.53
665.906	4096.35
666.163	4110.21
666.421	4115.5
666.679	4089.74
666.937	4052.56
667.194	4094.98
667.452	4079.95
667.71	4065.95
667.967	4107.14
668.225	4066.32
668.482	4085.92
668.74	4113.5
668.987	4157
669.245	4075
669.504	4101
669.763	4070
670.022	4129
670.281	4124
670.539	4052
670.798	4137
671.057	4116
671.316	4115
671.575	4122
671.833	4104
672.092	4092
672.351	4149
672.609	4143
672.868	4153
673.127	4203
673.385	4205
673.644	4219
673.903	4242
674.161	4264
674.42	4233
674.678	4350
674.937	4358
675.195	4341
675.454	4450
675.713	4367
675.971	4425
676.23	4351
676.488	4327
676.747	4397
677.005	4416
677.263	4381
677.522	4438
677.78	4396
678.039	4428
678.297	4479
678.556	4447
678.814	4441
679.072	4440
679.331	4445
679.589	4394
679.847	4393
680.106	4419
680.364	4464
680.622	4437
680.881	4499
681.139	4486
681.397	4507
681.656	4564
681.914	4560
682.172	4540
682.43	4558
682.688	4540
682.947	4541
683.205	4614
683.463	4638
683.721	4597
683.979	4530
684.237	4596
684.495	4574
684.754	4551
685.012	4601
685.27	4533
685.528	4538
685.786	4581
686.044	4488
686.302	4520
686.56	4455
686.818	4425
687.076	4495
687.334	4428
687.592	4481
687.85	4417
688.108	4461
688.366	4469
688.623	4419
688.881	4454
689.139	4428
689.397	4391
689.655	4378
689.913	4381
690.171	4449
690.428	4404
690.686	4399
690.944	4404
691.202	4371
691.459	4352
691.717	4352
691.975	4347
692.233	4305
692.49	4348
692.748	4315
693.006	4290
693.263	4318
693.521	4234
693.779	4269
694.036	4232
694.294	4208
694.552	4220
694.809	4264
695.067	4203
695.324	4227
695.582	4213
695.839	4163
696.097	4194
696.354	4148
696.612	4176
696.869	4155
697.127	4135
697.384	4123
697.642	4092
697.899	4107
698.156	4052
698.414	4061
698.671	4052
698.928	4013
699.186	3988
699.443	4003
699.7	3977
699.958	4012
700.215	4012
700.472	3953
700.73	3949
700.987	4001
701.244	3993
701.501	3983
701.758	3914
702.016	3991
702.273	4028
702.53	3942
702.787	3918
703.044	3910
703.301	3989
703.558	3953
703.816	3921
704.073	3953
704.33	3884
704.587	3906
704.844	3902
705.101	3903
705.358	3927
705.615	3856
705.872	3759
706.129	3816
706.386	3771
706.643	3816
706.899	3766
707.156	3767
707.413	3713
707.67	3735
707.927	3735
708.184	3735
708.441	3718
708.697	3704
708.954	3745
709.211	3693
709.468	3608
709.725	3701
709.981	3683
710.238	3680
710.495	3610
710.751	3643
711.008	3608
711.265	3617.33
711.521	3608.73
711.778	3576.81
712.035	3580.14
712.291	3557.74
712.548	3557.91
712.804	3538.68
713.061	3520.17
713.317	3487.14
713.574	3501.32
713.831	3450.47
714.087	3440.27
714.343	3395.28
714.6	3414.82
714.856	3397.01
715.113	3380.09
715.369	3345.13
715.626	3357.72
715.882	3350.03
716.138	3330.82
716.395	3290.96
716.639	3251
716.897	3312
717.155	3226
717.412	3328
717.67	3228
717.927	3234
718.185	3264
718.443	3245
718.7	3240
718.958	3164
719.215	3173
719.473	3151
719.73	3131
719.988	3151
720.245	3123
720.503	3029
720.76	3103
721.018	3095
721.275	3020
721.532	3010
721.79	3029
722.047	3003
722.305	3014
722.562	2998
722.819	2942
723.077	2869
723.334	2910
723.591	2945
723.849	2876
724.106	2896
724.363	2847
724.621	2787
724.878	2828
725.135	2818
725.392	2770
725.65	2782
725.907	2769
726.164	2780
726.421	2752
726.678	2758
726.935	2769
727.193	2690
727.45	2713
727.707	2664
727.964	2664
728.221	2678
728.478	2612
728.735	2579
728.992	2601
729.249	2582
729.506	2529
729.763	2589
730.02	2556
730.277	2500
730.534	2521
730.791	2496
731.048	2500
731.305	2472
731.562	2443
731.819	2407
732.076	2404
732.333	2445
732.589	2386
732.846	2402
733.103	2437
733.36	2359
733.617	2366
733.873	2348
734.13	2343
734.387	2333
734.644	2336
734.901	2317
735.157	2335
735.414	2294
735.671	2359
735.927	2316
736.184	2275
736.441	2280
736.697	2324
736.954	2287
737.211	2289
737.467	2291
737.724	2312
737.98	2313
738.237	2282
738.493	2320
738.75	2268
739.006	2269
739.263	2303
739.519	2290
739.776	2233
740.032	2223
740.289	2212
740.545	2173
740.802	2193
741.058	2186
741.314	2147
741.571	2128
741.827	2124
742.083	2138
742.34	2121
742.596	2121
742.852	2089
743.109	2075
743.365	2083
743.621	2056
743.878	2067
744.134	2046
744.39	2060
744.646	2028
744.902	2010
745.159	1996
745.415	1968
745.671	1939
745.927	1982
746.183	1978
746.439	1937
746.695	1937
746.951	1936
747.207	1946
747.463	1916
747.719	1927
747.975	1885
748.231	1897
748.487	1858
748.743	1873
748.999	1863
749.255	1911
749.511	1876
749.767	1860
750.023	1855
750.279	1819
750.535	1845
750.791	1848
751.046	1752
751.302	1842
751.558	1800
751.814	1794
752.07	1786
752.325	1748
752.581	1774
752.837	1753
753.092	1739
753.348	1729
753.604	1703
753.859	1704
754.115	1651
754.371	1694
754.626	1696
754.882	1664
755.138	1638
755.393	1676
755.649	1615
755.904	1628
756.16	1605
756.415	1612
756.671	1616
756.926	1605
757.182	1573
757.437	1591
757.693	1532
757.948	1570
758.203	1555
758.459	1567
758.714	1553.45
758.97	1548.71
759.225	1532.16
759.48	1502.7
759.736	1534.64
759.991	1485.58
760.246	1477.55
760.501	1480.29
760.757	1469.05
761.012	1457.38
761.267	1474.91
761.522	1457.59
761.777	1439.82
762.033	1437.07
762.288	1416.64
762.543	1417.11
762.798	1427.07
763.053	1405.53
763.308	1368.36
763.563	1361.72
763.78	1385
764.037	1348
764.293	1352
764.55	1375
764.806	1346
765.062	1328
765.319	1318
765.575	1291
765.831	1299
766.088	1328
766.344	1291
766.6	1306
766.857	1296
767.113	1287
767.369	1265
767.625	1262
767.882	1242
768.138	1244
768.394	1221
768.65	1219
768.906	1214
769.163	1212
769.419	1215
769.675	1188
769.931	1185
770.187	1159
770.443	1184
770.699	1138
770.955	1140
771.211	1153
771.467	1128
771.723	1104
771.979	1119
772.235	1105
772.491	1088
772.747	1093
773.003	1050
773.259	1074
773.515	1070
773.771	1071
774.027	1073
774.283	1054
774.539	1045
774.795	1057
775.05	1002
775.306	1039
775.562	1019
775.818	1000
776.074	1000
776.329	999
776.585	980
776.841	1005
777.097	981
777.352	984
777.608	957
777.864	970
778.12	961
778.375	976
778.631	936
778.886	947
779.142	933
779.398	910
779.653	916
779.909	900
780.164	890
780.42	903
780.675	874
780.931	884
781.187	871
781.442	886
781.698	879
781.953	861
782.208	848
782.464	860
782.719	836
782.975	827
783.23	811
783.485	861
783.741	826
783.996	801
784.252	802
784.507	792
784.762	775
785.017	794
785.273	790
785.528	774
785.783	772
786.038	779
786.294	775
786.549	748
786.804	764
787.059	728
787.314	700
787.57	748
787.825	734
788.08	746
788.335	713
788.59	723
788.845	713
789.1	717
789.355	695
789.61	710
789.865	692
790.12	672
790.375	700
790.63	669
790.885	687
791.14	661
791.395	669
791.65	653
791.905	630
792.16	636
792.414	648
792.669	633
792.924	636
793.179	620
793.434	606
793.689	623
793.943	620
794.198	613
794.453	615
794.708	597
794.962	596
795.217	625
795.472	588
795.726	572
795.981	577
796.236	599
796.49	589
796.745	564
796.999	563
797.254	549
797.508	538
797.763	539
798.018	536
798.272	541
798.526	539
798.781	537
799.035	505
799.29	529
799.544	503
799.799	537
800.053	508
800.307	518
800.562	515
800.816	525
801.07	498
801.325	500
801.579	503
801.833	492
802.088	485
802.342	498
802.596	470
802.85	476
803.105	481
803.359	462
803.613	475
803.867	467
804.121	442
804.375	466
804.63	443
804.884	444
805.138	442
805.392	438
805.646	436.48
805.9	439.071
806.154	422.91
806.408	435.824
806.662	418.084
806.916	431.52
807.17	432.986
807.424	425.648
807.678	412.663
807.931	415.266
808.185	407.608
808.439	411.276
808.693	403.878
808.947	409.977
809.201	387.978
809.454	392.649
809.708	384.279
809.962	390.694
810.216	377.997
810.469	379.48
810.678	377
810.933	380
811.188	402
811.443	371
811.699	380
811.954	365
812.209	354
812.464	374
812.719	367
812.974	351
813.229	359
813.484	346
813.739	345
813.994	352
814.249	357
814.504	352
814.759	350
815.014	352
815.268	334
815.523	332
815.778	333
816.033	337
816.288	340
816.543	327
816.798	322
817.052	314
817.307	321
817.562	312
817.817	316
818.071	310
818.326	311
818.581	309
818.836	300
819.09	305
819.345	325
819.6	312
819.854	312
820.109	279
820.364	286
820.618	291
820.873	280
821.127	285
821.382	288
821.637	293
821.891	282
822.146	278
822.4	298
822.655	276
822.909	287
823.164	278
823.418	276
823.672	258
823.927	276
824.181	274
824.436	285
824.69	256
824.944	259
825.199	253
825.453	251
825.707	261
825.962	267
826.216	262
826.47	250
826.725	239
826.979	238
827.233	241
827.487	247
827.741	262
827.996	258
828.25	231
828.504	257
828.758	241
829.012	228
829.266	243
829.52	238
829.774	230
830.029	231
830.283	238
830.537	241
830.791	235
831.045	241
831.299	237
831.553	221
831.807	222
832.061	218
832.315	232
832.568	236
832.822	212
833.076	226
833.33	210
833.584	224
833.838	224
834.092	216
834.345	211
834.599	205
834.853	212
835.107	206
835.36	221
835.614	209
835.868	198
836.122	197
836.375	199
836.629	203
836.883	196
837.136	209
837.39	197
837.643	192
837.897	203
838.151	202
838.404	194
838.658	197
838.911	207
839.165	197
839.418	194
839.672	202
839.925	202
840.179	189
840.432	186
840.686	174
840.939	185
841.192	199
841.446	189
841.699	188
841.952	180
842.206	182
842.459	183
842.712	182
842.966	180
843.219	169
843.472	172
843.725	178
843.979	177
844.232	168
844.485	181
844.738	158
844.991	160
845.244	179
845.497	164
845.75	178
846.004	158
846.257	169
846.51	175
846.763	164
847.016	164
847.269	158
847.522	160
847.775	161
848.028	172
848.281	172
848.534	155
848.786	152
849.039	158
849.292	152
849.545	148
849.798	161
850.051	151
850.303	156
850.556	152
850.809	159
851.062	166
851.314	144
851.567	144
851.82	157
852.073	137
852.325	156.94
852.578	141.824
852.831	147.044
853.083	147.732
853.336	148.197
853.588	127.449
853.841	141.398
854.093	141.123
854.346	142.846
854.598	138.997
854.851	138.751
855.103	142.319
855.356	140.485
855.608	140.969
855.861	140.484
856.113	136.612
856.366	134.701
856.618	132.601
856.87	130.417
857.123	129.612
857.352	131
857.606	126
857.859	131
858.113	116
858.367	133
858.621	134
858.875	129
859.128	121
859.382	124
859.636	121
859.889	136
860.143	117
860.397	127
860.65	120
860.904	124
861.158	126
861.411	117
861.665	124
861.918	131
862.172	120
862.425	132
862.679	124
862.932	109
863.186	130
863.439	122
863.693	123
863.946	121
864.2	127
864.453	121
864.707	113
864.96	119
865.213	118
865.467	105
865.72	113
865.973	111
866.227	107
866.48	115
866.733	108
866.987	108
867.24	112
867.493	124
867.746	108
867.999	115
868.253	110
868.506	109
868.759	91
869.012	105
869.265	113
869.518	115
869.771	106
870.025	110
870.278	106
870.531	114
870.784	105
871.037	104
871.29	94
871.543	111
871.796	98
872.049	97
872.302	104
872.555	96
872.808	104
873.06	89
873.313	99
873.566	102
873.819	97
874.072	95
874.325	100
874.578	108
874.83	97
875.083	100
875.336	93
875.589	96
875.841	104
876.094	89
876.347	99
876.6	97
876.852	100
877.105	86
877.358	89
877.61	99
877.863	89
878.115	97
878.368	107
878.621	95
878.873	95
879.126	89
879.378	95
879.631	87
879.883	102
880.136	97
880.388	97
880.641	87
880.893	94
881.145	87
881.398	75
881.65	87
881.902	88
882.155	88
882.407	97
882.659	89
882.912	86
883.164	88
883.416	85
883.669	91
883.921	91
884.173	90
884.425	82
884.677	89
884.93	85
885.182	92
885.434	88
885.686	85
885.938	83
886.19	82
886.442	74
886.694	86
886.946	90
887.198	79
887.45	84
887.702	78
887.954	80
888.206	72
888.458	79
888.71	77
888.962	73
889.214	74
889.466	77
889.718	84
889.969	77
890.221	71
890.473	71
890.725	77
890.977	76
891.228	79
891.48	71
891.732	63
891.983	66
892.235	75
892.487	76
892.738	77
892.99	73
893.242	72
893.493	74
893.745	70
893.996	71
894.248	72
894.5	69
894.751	71
895.003	74
895.254	70
895.505	66
895.757	67
896.008	71
896.26	65
896.511	63
896.763	68
897.014	61
897.265	75
897.517	60
897.768	66
898.019	61
898.27	68
898.522	66
898.773	62
899.024	57
899.275	69
899.527	69
899.778	64
899.979	70