File: PL_M4_011123_01.txt
#Acq. time (s)=	5
#Accumulations=	2
#Range (nm)=	520...900
#Windows=	8
#Auto scanning=	Off
#Autofocus=	Off
#AutoExposure=	Off
#Spike filter=	Multiple accum.
#Delay time (s)=	0
#Binning=	1
#Readout mode=	Signal
#DeNoise=	Off
#ICS correction=	On
#Dark correction=	Off
#Inst. Process=	Off
#Detector temperature (°C)=	-59.98
#Instrument=	LabRAM HR Evol
#Detector=	Syncerity OE
#Objective=	x50_VIS
#Grating=	600 (500nm)
#ND Filter=	10%
#Laser=	514nm_Edge
#Hole=	199.981
#Range=	Auto
#StageXY=	Marzhauser
#StageZ=	Marzhauser
#X (µm)=	15179.1
#Y (µm)=	-995.7
#Z (µm)=	-19.1
#Full time(mm:ss)=	2:04
#Project=
#Sample=
#Site=
#Title=	PL_M4_011123
#Remark=
#Date=	11.11.2023 11:46
#Acquired=	11.11.2023 11:46:49
520.044	41.4395
520.306	42.8047
520.569	40.8685
520.831	41.0437
521.093	28.6289
521.355	41.1104
521.617	39.127
521.88	37.2218
522.142	33.6921
522.404	39.2189
522.666	32.2006
522.928	39.3855
523.19	37.3265
523.453	37.0706
523.715	38.6947
523.977	38.7377
524.239	33.6668
524.501	42.7681
524.763	35.7401
525.025	40.9638
525.287	31.9648
525.549	37.2918
525.811	40.8579
526.073	42.9235
526.335	41.4155
526.597	39.7832
526.859	37.9586
527.121	46.8524
527.383	35.9997
527.645	41.3125
527.907	39.4977
528.169	39.6453
528.431	39.891
528.693	41.9798
528.955	49.4518
529.217	51.2223
529.479	38.2593
529.741	45.2936
530.003	45.2052
530.264	45.1457
530.526	41.6531
530.788	38.2953
531.05	33.0755
531.312	49.7639
531.574	40.7368
531.835	42.6748
532.097	40.945
532.359	42.8814
532.621	41.1998
532.883	45.0144
533.144	48.7409
533.406	46.8323
533.668	48.7003
533.93	42.9464
534.191	42.7877
534.453	48.1254
534.715	46.3093
534.976	53.8473
535.238	57.7597
535.5	52.2088
535.761	43.0286
536.023	58.2342
536.285	54.4647
536.546	43.0421
536.808	48.6089
537.069	52.0541
537.331	53.6278
537.593	58.9398
537.854	60.6394
538.116	60.4738
538.377	73.4498
538.639	69.8425
538.9	62.5812
539.162	58.8983
539.423	55.1043
539.685	53.2333
539.946	58.6585
540.208	49.4086
540.469	45.7895
540.731	62.4519
540.992	56.9691
541.254	51.6015
541.515	49.834
541.776	55.3846
542.038	53.6646
542.299	62.7286
542.56	53.2823
542.822	58.6789
543.083	54.8838
543.344	56.6725
543.606	49.5093
543.867	60.4378
544.128	58.6505
544.39	67.9366
544.651	58.8258
544.912	62.5056
545.174	62.4492
545.435	65.9805
545.696	63.8881
545.957	80.1875
546.218	76.2301
546.48	74.2244
546.741	77.8201
547.002	74.3311
547.263	74.3294
547.524	72.4958
547.785	68.9683
548.047	87.1434
548.308	76.2958
548.569	81.5916
548.83	81.5508
549.091	85.0844
549.352	70.2869
549.613	80.9602
549.874	77.0873
550.135	85.9651
550.396	85.6002
550.657	96.2908
550.918	89.056
551.179	101.333
551.44	104.643
551.701	118.909
551.962	171.994
552.223	294.524
552.484	3755.82
552.745	9070.59
553.006	344.07
553.267	165.098
553.528	121.006
553.788	108.316
554.049	115.47
554.31	111.972
554.571	111.841
554.832	113.453
555.093	109.676
555.353	102.324
555.614	96.5775
555.875	105.073
556.136	110.209
556.396	104.726
556.657	115.297
556.918	102.951
557.179	97.8371
557.439	119.154
557.7	101.886
557.961	109.258
558.221	120.206
558.482	125.521
558.743	130.704
559.003	116.608
559.264	109.093
559.525	118.998
559.785	109.967
560.046	124.896
560.306	132.872
560.567	119.88
560.827	141.384
561.088	130.595
561.348	128.564
561.609	126.761
561.869	130.238
562.13	138.785
562.39	143.889
562.651	149.362
562.911	146.232
563.172	149.938
563.432	151.719
563.692	160.109
563.953	161.41
564.213	159.614
564.474	176.075
564.734	149.889
564.994	175.769
565.255	148.422
565.515	175.604
565.775	155.02
566.035	174.159
566.296	155.406
566.556	176.013
566.816	173.808
567.076	172.186
567.337	172.322
567.597	182.304
567.857	174.436
568.117	174.875
568.377	187.545
568.637	178.909
568.898	191.288
569.158	191.295
569.418	203.355
569.678	199.073
569.938	193.405
570.198	213.584
570.458	217.747
570.718	218.555
570.978	215.117
571.238	225.624
571.498	242.363
571.758	249.508
572.018	246.885
572.278	266.429
572.538	281.43
572.798	287.305
573.058	316.886
573.312	313.868
573.573	337.124
573.834	370.787
574.095	384.737
574.356	420.742
574.617	432.971
574.878	459.55
575.139	455.29
575.4	478.731
575.661	492.627
575.922	466.118
576.183	460.458
576.444	456.69
576.705	451.515
576.965	435.317
577.226	406.039
577.487	401.28
577.748	394.685
578.009	360.906
578.27	363.303
578.531	361.015
578.791	353.646
579.052	332.806
579.313	351.751
579.574	339.351
579.835	342.663
580.095	351.445
580.356	328.449
580.617	314.511
580.878	334.372
581.138	354.36
581.399	352.825
581.66	355.886
581.92	357.244
582.181	363.169
582.442	325.215
582.703	358.538
582.963	360.978
583.224	383.846
583.484	358.596
583.745	378.618
584.006	374.233
584.266	405.69
584.527	386.345
584.787	410.401
585.048	388.97
585.308	405.609
585.569	406.07
585.83	414.983
586.09	401.541
586.351	461.519
586.611	428.877
586.872	454.101
587.132	457.44
587.392	431.195
587.653	432.523
587.913	448.915
588.174	451.584
588.434	458.85
588.695	464.448
588.955	471.622
589.215	469.564
589.476	479.589
589.736	472.857
589.996	483.108
590.257	449.311
590.517	469.819
590.777	457.711
591.038	441.719
591.298	447.656
591.558	451.412
591.818	438.803
592.079	442.601
592.339	450.518
592.599	442.201
592.859	409.951
593.12	423.02
593.38	436.917
593.64	449.461
593.9	411.694
594.16	432.515
594.42	437.117
594.68	423.116
594.941	451.372
595.201	436.762
595.461	446.336
595.721	457.707
595.981	461.514
596.241	461.172
596.501	459.724
596.761	489.765
597.021	480.293
597.281	469.522
597.541	446.507
597.801	441.417
598.061	455.261
598.321	472.866
598.581	464.832
598.841	467.713
599.101	468.231
599.361	443.157
599.62	461.715
599.88	461.179
600.14	476.007
600.4	461.756
600.66	487.126
600.92	474.788
601.18	485.648
601.439	476.157
601.699	481.277
601.959	483.439
602.219	475.911
602.478	488.258
602.738	484.881
602.998	470.8
603.258	466.636
603.517	477.028
603.777	500.561
604.037	476.026
604.296	488.19
604.556	486.02
604.816	487.875
605.075	479.567
605.335	484.258
605.594	492.612
605.854	492.166
606.114	482.419
606.373	498.651
606.633	495.999
606.892	483.64
607.152	466.512
607.411	483.56
607.671	499.065
607.93	486.635
608.19	481.503
608.449	477.589
608.709	503.956
608.968	506.615
609.228	515.166
609.487	504.952
609.746	508.783
610.006	508.675
610.265	526.682
610.524	509.267
610.784	490.03
611.043	525.366
611.302	530.161
611.562	532.656
611.821	505.07
612.08	520.057
612.339	531.543
612.599	500.486
612.858	527.397
613.117	529.533
613.376	522.992
613.635	537.129
613.895	530.391
614.154	544.722
614.413	528.365
614.672	549.991
614.931	533.111
615.19	566.833
615.449	572.131
615.709	573.61
615.968	559.191
616.227	570.713
616.486	574.14
616.745	586.122
617.004	579.179
617.263	573.487
617.522	580.741
617.781	589.417
618.04	582.93
618.299	582.004
618.557	588.713
618.816	581.407
619.075	583.834
619.334	594.16
619.593	591.128
619.852	592.234
620.111	588.633
620.37	590.414
620.628	593.023
620.887	586.871
621.146	613.286
621.373	589.518
621.633	588.997
621.893	615.608
622.153	595.893
622.413	599.233
622.673	595.435
622.932	602.384
623.192	622.49
623.452	590.915
623.712	597.9
623.972	608.802
624.232	589.669
624.492	619.897
624.751	605.515
625.011	601.36
625.271	603.416
625.531	617.369
625.791	622.955
626.05	625.299
626.31	618.148
626.57	641.681
626.83	624.502
627.089	633.609
627.349	662.823
627.609	664.332
627.868	630.889
628.128	635.703
628.388	655.233
628.647	653.21
628.907	634.044
629.167	636.312
629.426	680.86
629.686	668.507
629.945	654.771
630.205	669.691
630.465	685.732
630.724	679.459
630.984	675.609
631.243	691.606
631.503	715.046
631.762	719.065
632.022	696.883
632.281	704.608
632.541	721.841
632.8	712.579
633.06	719.782
633.319	733.063
633.579	748.465
633.838	757.523
634.097	769.936
634.357	806.945
634.616	840.29
634.876	878.362
635.135	879.795
635.394	883.371
635.654	883.539
635.913	899.821
636.172	925.911
636.431	937.192
636.691	964.455
636.95	979.639
637.209	991.078
637.469	1003.97
637.728	1036.42
637.987	1021.42
638.246	1027.06
638.505	1013.19
638.765	1013.45
639.024	1004.69
639.283	972.5
639.542	978.096
639.801	973.693
640.06	950.909
640.319	937.426
640.578	932.72
640.838	911.194
641.097	927.956
641.356	929.974
641.615	921.11
641.874	930.979
642.133	905.701
642.392	895.056
642.651	899.778
642.91	890.156
643.169	939.581
643.428	915.317
643.687	909.226
643.946	925.326
644.205	916.883
644.463	941.082
644.722	931.629
644.981	920.887
645.24	905.524
645.499	913.949
645.758	934.615
646.017	951.963
646.275	961.163
646.534	980.671
646.793	966.88
647.052	977.572
647.31	968.631
647.569	978.916
647.828	986.429
648.087	968.153
648.345	992.398
648.604	1021.67
648.863	984.578
649.121	1021.85
649.38	1018.44
649.639	1037.05
649.897	1005.31
650.156	1029.73
650.415	1034.47
650.673	1039.17
650.932	1025.23
651.19	1049.79
651.449	1058.9
651.707	1075.18
651.966	1081.17
652.224	1112.25
652.483	1096.28
652.741	1127.73
653	1115.58
653.258	1118.23
653.517	1111.82
653.775	1109.17
654.034	1141.36
654.292	1161.59
654.55	1156.19
654.809	1168.19
655.067	1181.12
655.326	1189.91
655.584	1186.01
655.842	1217.56
656.1	1217.02
656.359	1208.97
656.617	1234.83
656.875	1259.52
657.134	1246.75
657.392	1260.3
657.65	1276.33
657.908	1262.02
658.166	1310.69
658.425	1303.62
658.683	1308.01
658.941	1296.68
659.199	1328.27
659.457	1326.6
659.715	1324.69
659.973	1313.28
660.231	1323.65
660.49	1326.16
660.748	1315.89
661.006	1330.72
661.264	1292.68
661.522	1317.66
661.78	1332.96
662.038	1318.12
662.296	1308.13
662.554	1313.65
662.811	1309.19
663.069	1321.1
663.327	1311.4
663.585	1283.65
663.843	1307.2
664.101	1302.66
664.359	1302.76
664.617	1276.74
664.874	1291.12
665.132	1293.98
665.39	1310.59
665.648	1302.77
665.906	1302.22
666.163	1303.88
666.421	1298.26
666.679	1310.57
666.937	1305.25
667.194	1313.59
667.452	1298.03
667.71	1294.8
667.967	1309.82
668.225	1316.03
668.482	1310.27
668.74	1305.48
668.987	1319.54
669.245	1322.37
669.504	1314.29
669.763	1317.41
670.022	1332.34
670.281	1315.76
670.539	1353.69
670.798	1342.37
671.057	1347.12
671.316	1358.1
671.575	1339.5
671.833	1351.24
672.092	1336.88
672.351	1360.15
672.609	1343.85
672.868	1337.86
673.127	1344.89
673.385	1346.19
673.644	1337.52
673.903	1347.61
674.161	1393.22
674.42	1341.82
674.678	1365.37
674.937	1374.9
675.195	1383.28
675.454	1415.61
675.713	1393.08
675.971	1381.29
676.23	1388.74
676.488	1405.2
676.747	1411
677.005	1428.87
677.263	1417.31
677.522	1444.46
677.78	1457.65
678.039	1433.66
678.297	1445.71
678.556	1420.55
678.814	1429.84
679.072	1413.82
679.331	1432.27
679.589	1442.1
679.847	1434.62
680.106	1435.86
680.364	1426.93
680.622	1430.64
680.881	1440.44
681.139	1447.33
681.397	1411.37
681.656	1456.18
681.914	1454.04
682.172	1450.43
682.43	1451.39
682.688	1440.73
682.947	1467.6
683.205	1439.99
683.463	1428.26
683.721	1454.49
683.979	1449.09
684.237	1458.61
684.495	1447.4
684.754	1445
685.012	1462.47
685.27	1452.96
685.528	1457
685.786	1452.6
686.044	1475.63
686.302	1415.02
686.56	1457.62
686.818	1433.79
687.076	1426.62
687.334	1443.79
687.592	1409.69
687.85	1426.84
688.108	1426.25
688.366	1443.1
688.623	1423.68
688.881	1386.22
689.139	1430.81
689.397	1423.7
689.655	1420.1
689.913	1411.93
690.171	1405.42
690.428	1397.8
690.686	1381.58
690.944	1424.2
691.202	1397.71
691.459	1369.88
691.717	1421.99
691.975	1405.68
692.233	1390.05
692.49	1401.45
692.748	1380.24
693.006	1406.03
693.263	1383
693.521	1397.9
693.779	1338.56
694.036	1388.77
694.294	1381.92
694.552	1352.41
694.809	1378.37
695.067	1395.54
695.324	1374.34
695.582	1358.51
695.839	1370.62
696.097	1344.5
696.354	1403.33
696.612	1369.08
696.869	1375
697.127	1364.51
697.384	1393.71
697.642	1357.63
697.899	1367.93
698.156	1382.35
698.414	1381.07
698.671	1330.11
698.928	1365.67
699.186	1368.58
699.443	1327.05
699.7	1374.17
699.958	1368.04
700.215	1364.48
700.472	1332.43
700.73	1356.16
700.987	1311.11
701.244	1321.45
701.501	1317.05
701.758	1313.19
702.016	1334.13
702.273	1364.15
702.53	1331.52
702.787	1339.85
703.044	1334.24
703.301	1354.77
703.558	1349.18
703.816	1331.57
704.073	1328.61
704.33	1311.01
704.587	1328.79
704.844	1331.55
705.101	1328.89
705.358	1321.77
705.615	1342.32
705.872	1337.48
706.129	1329.84
706.386	1299.66
706.643	1325.95
706.899	1296.87
707.156	1280.55
707.413	1312.22
707.67	1289.75
707.927	1296.36
708.184	1269.13
708.441	1321.08
708.697	1280.6
708.954	1298.06
709.211	1277.39
709.468	1270.26
709.725	1302.68
709.981	1277.93
710.238	1282.62
710.495	1283.73
710.751	1268.75
711.008	1259.47
711.265	1280.16
711.521	1272.31
711.778	1259.09
712.035	1258.5
712.291	1263.42
712.548	1284.56
712.804	1266.76
713.061	1270.36
713.317	1248.04
713.574	1264.61
713.831	1260.4
714.087	1270.87
714.343	1261.26
714.6	1230.01
714.856	1247.62
715.113	1232.32
715.369	1220.26
715.626	1207.98
715.882	1239.52
716.138	1214.78
716.395	1230.13
716.639	1202.31
716.897	1219.8
717.155	1225.84
717.412	1217.26
717.67	1190.91
717.927	1202.8
718.185	1183.28
718.443	1179.28
718.7	1190.02
718.958	1202.99
719.215	1214.16
719.473	1163.45
719.73	1190.11
719.988	1178.23
720.245	1164.07
720.503	1177.11
720.76	1161.39
721.018	1173.52
721.275	1139.54
721.532	1182.66
721.79	1145.41
722.047	1149.95
722.305	1158.6
722.562	1134.53
722.819	1123.41
723.077	1131.07
723.334	1092.82
723.591	1142.08
723.849	1113.17
724.106	1113.35
724.363	1122.61
724.621	1116.62
724.878	1108.61
725.135	1100.57
725.392	1113.97
725.65	1097.64
725.907	1093.41
726.164	1088.31
726.421	1074.37
726.678	1096.47
726.935	1085.5
727.193	1097.69
727.45	1088.51
727.707	1054.65
727.964	1090.23
728.221	1080.41
728.478	1090.32
728.735	1086.25
728.992	1055.1
729.249	1023.47
729.506	1047.44
729.763	1050.92
730.02	1035.83
730.277	1056.84
730.534	1070.36
730.791	1035.48
731.048	1040.79
731.305	1036.32
731.562	1002.76
731.819	1025.74
732.076	1041.37
732.333	1012.02
732.589	1042.52
732.846	1018.27
733.103	1010.17
733.36	1013.75
733.617	1012.69
733.873	1006.08
734.13	990.52
734.387	992.315
734.644	997.785
734.901	1015.03
735.157	977.673
735.414	968.955
735.671	974.164
735.927	995.261
736.184	991.016
736.441	976.401
736.697	969.563
736.954	992.117
737.211	955.347
737.467	959.71
737.724	955.27
737.98	952.649
738.237	952.205
738.493	943.148
738.75	947.007
739.006	957.629
739.263	940.598
739.519	904.848
739.776	937.252
740.032	942.929
740.289	932.686
740.545	916.07
740.802	938.867
741.058	918.436
741.314	935.641
741.571	892.618
741.827	903.629
742.083	899.685
742.34	897.723
742.596	864.337
742.852	907.514
743.109	889.981
743.365	884.111
743.621	860.954
743.878	878.767
744.134	859.761
744.39	892.498
744.646	852.065
744.902	888.859
745.159	868.22
745.415	881.195
745.671	838.362
745.927	855.934
746.183	864.594
746.439	857.081
746.695	824.743
746.951	837.587
747.207	827.261
747.463	840.979
747.719	840.491
747.975	812.18
748.231	833.576
748.487	829.295
748.743	792.35
748.999	825.009
749.255	816.803
749.511	797.5
749.767	802.611
750.023	815.843
750.279	786.408
750.535	803.605
750.791	796.747
751.046	798.267
751.302	808.156
751.558	778.829
751.814	764.616
752.07	790.854
752.325	762.062
752.581	797.772
752.837	763.106
753.092	786.328
753.348	760.914
753.604	764.204
753.859	768.992
754.115	775.553
754.371	747.372
754.626	769.198
754.882	735.874
755.138	751.033
755.393	753.324
755.649	758.75
755.904	730.528
756.16	722.054
756.415	740.104
756.671	723.333
756.926	737.681
757.182	731.036
757.437	720.073
757.693	702.839
757.948	711.752
758.203	667.024
758.459	704.4
758.714	700.026
758.97	711.893
759.225	688.676
759.48	696.464
759.736	696.194
759.991	690.157
760.246	696.207
760.501	697.479
760.757	677.592
761.012	688.496
761.267	685.781
761.522	677.899
761.777	670.446
762.033	668.366
762.288	658.204
762.543	664.127
762.798	654.182
763.053	634.641
763.308	650.542
763.563	659.361
763.78	654.584
764.037	648.214
764.293	646.205
764.55	635.144
764.806	662.327
765.062	633.089
765.319	644.589
765.575	646.216
765.831	608.765
766.088	609.614
766.344	629.464
766.6	617.836
766.857	626.932
767.113	610.679
767.369	606.262
767.625	619.178
767.882	598.19
768.138	602.241
768.394	602.304
768.65	588.699
768.906	595.393
769.163	590.258
769.419	591.426
769.675	600.422
769.931	594.9
770.187	593.348
770.443	616.14
770.699	576.038
770.955	564.41
771.211	580.451
771.467	579.92
771.723	562.761
771.979	534.046
772.235	562.725
772.491	593.402
772.747	553.717
773.003	573.777
773.259	559.856
773.515	547.004
773.771	526.067
774.027	535.98
774.283	547.318
774.539	543.274
774.795	541.521
775.05	537.462
775.306	521.96
775.562	537.13
775.818	539.889
776.074	515.009
776.329	509.203
776.585	529.546
776.841	512.951
777.097	511.918
777.352	514.842
777.608	509.076
777.864	517.419
778.12	500.564
778.375	489.596
778.631	515.036
778.886	526.998
779.142	512.354
779.398	502.421
779.653	489.173
779.909	506.242
780.164	491.84
780.42	491.443
780.675	499.448
780.931	482.872
781.187	489.543
781.442	483.476
781.698	489.532
781.953	472.05
782.208	460.734
782.464	466.87
782.719	476.886
782.975	466.846
783.23	449.44
783.485	450.807
783.741	459.523
783.996	456.371
784.252	433.47
784.507	464.852
784.762	445.375
785.017	443.824
785.273	425.99
785.528	434.445
785.783	429.589
786.038	442.157
786.294	441.749
786.549	426.725
786.804	456.177
787.059	449.687
787.314	444.712
787.57	421.195
787.825	408.478
788.08	434.094
788.335	394.496
788.59	416.432
788.845	417.317
789.1	416.2
789.355	413.589
789.61	408.17
789.865	416.943
790.12	404.54
790.375	382.184
790.63	410.224
790.885	391.469
791.14	396.621
791.395	395.045
791.65	382.252
791.905	406.793
792.16	382.388
792.414	381.438
792.669	385.913
792.924	397.033
793.179	376.098
793.434	385.666
793.689	376.406
793.943	373.087
794.198	361.737
794.453	348.236
794.708	375.345
794.962	372.462
795.217	364.723
795.472	362.248
795.726	356.639
795.981	363.603
796.236	390.892
796.49	354.846
796.745	362.014
796.999	364.656
797.254	363.363
797.508	360.149
797.763	371.211
798.018	374.528
798.272	363.175
798.526	361.697
798.781	361.04
799.035	353.123
799.29	337.003
799.544	343.97
799.799	351.091
800.053	338.38
800.307	354.077
800.562	335.624
800.816	325.698
801.07	328.412
801.325	331.414
801.579	317.076
801.833	337.096
802.088	335.528
802.342	316.344
802.596	319.02
802.85	313.157
803.105	300.836
803.359	323.404
803.613	315.11
803.867	300.541
804.121	325.572
804.375	312.805
804.63	286.671
804.884	295.837
805.138	325.345
805.392	316.706
805.646	299.594
805.9	304.224
806.154	281.852
806.408	302.597
806.662	301.388
806.916	288.734
807.17	294.832
807.424	299.048
807.678	283.234
807.931	279.304
808.185	283.056
808.439	285.425
808.693	282.399
808.947	272.961
809.201	279.342
809.454	271.131
809.708	277.27
809.962	274.365
810.216	266.06
810.469	285.109
810.678	266.745
810.933	288.296
811.188	267.664
811.443	261.151
811.699	268.695
811.954	297.453
812.209	267.171
812.464	279.301
812.719	254.046
812.974	284.592
813.229	247.732
813.484	264.557
813.739	262.73
813.994	251.662
814.249	254.403
814.504	256.568
814.759	267.194
815.014	269.958
815.268	246.337
815.523	258.651
815.778	249.011
816.033	253.572
816.288	259.309
816.543	233.164
816.798	226.219
817.052	248.611
817.307	239.123
817.562	259.185
817.817	240.431
818.071	250.148
818.326	231.144
818.581	246.172
818.836	232.137
819.09	222.825
819.345	247.647
819.6	240.917
819.854	251.755
820.109	242.277
820.364	227.483
820.618	238.064
820.873	240.847
821.127	236.529
821.382	221.786
821.637	214.61
821.891	217.464
822.146	217.914
822.4	198.081
822.655	231.549
822.909	239.647
823.164	219.604
823.418	216.923
823.672	196.979
823.927	212.119
824.181	214.791
824.436	217.637
824.69	217.988
824.944	215.572
825.199	205.701
825.453	213.655
825.707	198.765
825.962	214.001
826.216	201.337
826.47	206.284
826.725	208.822
826.979	196.323
827.233	209.375
827.487	173.863
827.741	204.277
827.996	202.311
828.25	187.523
828.504	200.202
828.758	200.651
829.012	187.98
829.266	193.171
829.52	190.757
829.774	209.013
830.029	217.255
830.283	199.402
830.537	183.987
830.791	202.029
831.045	168.647
831.299	179.199
831.553	176.769
831.807	189.872
832.061	184.779
832.315	192.714
832.568	174.808
832.822	190.6
833.076	195.98
833.33	177.967
833.584	180.72
833.838	188.729
834.092	178.449
834.345	181.065
834.599	178.741
834.853	176.254
835.107	178.924
835.36	202.539
835.614	179.035
835.868	189.613
836.122	179.505
836.375	184.774
836.629	171.318
836.883	160.784
837.136	171.523
837.39	166.125
837.643	168.901
837.897	169.061
838.151	158.302
838.404	166.12
838.658	147.533
838.911	166.041
839.165	166.165
839.418	155.808
839.672	166.302
839.925	166.473
840.179	158.748
840.432	171.991
840.686	158.812
840.939	161.675
841.192	172.497
841.446	151.393
841.699	156.884
841.952	149.033
842.206	154.1
842.459	154.108
842.712	154.184
842.966	151.511
843.219	154.287
843.472	141.126
843.725	162.696
843.979	170.767
844.232	152.015
844.485	152.164
844.738	152.297
844.991	141.662
845.244	155.113
845.497	157.868
845.75	152.721
846.004	152.807
846.257	139.503
846.51	163.719
846.763	139.751
847.016	139.609
847.269	147.756
847.522	145.083
847.775	147.938
848.028	131.879
848.281	153.588
848.534	148.304
848.786	140.455
849.039	140.584
849.292	132.689
849.545	146.235
849.798	135.69
850.051	127.528
850.303	122.132
850.556	143.944
850.809	130.505
851.062	135.965
851.314	133.306
851.567	130.962
851.82	128.317
852.073	142.082
852.325	150.307
852.578	130.543
852.831	126.839
853.083	141.05
853.336	133.341
853.588	128.86
853.841	120.407
854.093	132.325
854.346	127.712
854.598	134.018
854.851	112.515
855.103	130.254
855.356	119.532
855.608	126.347
855.861	121.409
856.113	130.674
856.366	122.878
856.618	126.549
856.87	121.83
857.123	120.454
857.352	135.813
857.606	116.439
857.859	127.5
858.113	113.754
858.367	99.8967
858.621	116.444
858.875	127.479
859.128	113.681
859.382	116.403
859.636	116.457
859.889	124.763
860.143	122.114
860.397	116.481
860.65	119.43
860.904	105.519
861.158	105.536
861.411	100.096
861.665	108.483
861.918	100.039
862.172	110.982
862.425	108.262
862.679	102.634
862.932	113.759
863.186	125.176
863.439	111.063
863.693	127.742
863.946	114.029
864.2	105.701
864.453	103.017
864.707	114.068
864.96	113.961
865.213	105.698
865.467	105.713
865.72	122.51
865.973	103.143
866.227	106.009
866.48	94.8288
866.733	114.371
866.987	117.18
867.24	100.631
867.493	103.378
867.746	106.28
867.999	100.76
868.253	112.007
868.506	92.485
868.759	106.684
869.012	101.148
869.265	112.478
869.518	104.068
869.771	104.033
870.025	95.6348
870.278	109.725
870.531	101.476
870.784	107.292
871.037	110.167
871.29	101.663
871.543	98.9879
871.796	101.938
872.049	93.4504
872.302	99.1948
872.555	90.6598
872.808	99.1653
873.06	79.3553
873.313	99.2972
873.566	102.112
873.819	102.23
874.072	102.002
874.325	93.5234
874.578	116.445
874.83	90.8755
875.083	102.209
875.336	87.9922
875.589	90.909
875.841	90.8883
876.094	85.2159
876.347	102.362
876.6	85.2896
876.852	102.444
877.105	99.6682
877.358	96.9065
877.61	91.19
877.863	82.6547
878.115	96.9837
878.368	94.2974
878.621	80.1416
878.873	97.3122
879.126	97.252
879.378	94.6344
879.631	91.9058
879.883	86.1561
880.136	83.3232
880.388	89.2189
880.641	86.4952
880.893	89.4882
881.145	86.6063
881.398	80.991
881.65	92.6715
881.902	86.9478
882.155	95.6946
882.407	95.6817
882.659	87.0516
882.912	107.579
883.164	84.3909
883.416	90.3192
883.669	90.3494
883.921	78.7938
884.173	99.3054
884.425	84.8099
884.677	64.3446
884.93	99.569
885.182	84.8825
885.434	93.6061
885.686	84.901
885.938	90.7647
886.19	79.1409
886.442	85.0009
886.694	73.3408
886.946	90.9746
887.198	79.4276
887.45	88.3392
887.702	79.5321
887.954	85.5426
888.206	73.8014
888.458	82.7995
888.71	70.9451
888.962	94.6905
889.214	88.8104
889.466	88.8898
889.718	71.1585
889.969	77.2094
890.221	83.2404
890.473	86.3029
890.725	74.6404
890.977	101.581
891.228	71.7542
891.48	80.8213
891.732	56.909
891.983	78.1152
892.235	66.1481
892.487	87.3955
892.738	81.5453
892.99	90.8043
893.242	81.7434
893.493	81.7613
893.745	90.9718
893.996	78.9555
894.248	72.9795
894.5	79.0574
894.751	79.2365
895.003	79.4188
895.254	79.6402
895.505	79.7222
895.757	70.6
896.008	64.5285
896.26	76.9248
896.511	86.2368
896.763	76.9979
897.014	80.3038
897.265	71.0851
897.517	80.2838
897.768	68.022
898.019	77.51
898.27	74.2598
898.522	83.6483
898.773	80.8537
899.024	74.6494
899.275	71.5633
899.527	74.5909
899.778	62.3456
899.979	78.0567