File: PL_M7_280424_01.txt
#Acq. time (s)=	3
#Accumulations=	2
#Range (nm)=	520...900
#Windows=	8
#Auto scanning=	Off
#Autofocus=	Off
#AutoExposure=	Off
#Spike filter=	Off
#Delay time (s)=	0
#Binning=	1
#Readout mode=	Signal
#DeNoise=	Off
#ICS correction=	Off
#Dark correction=	Off
#Inst. Process=	Off
#Detector temperature (°C)=	-59.98
#Instrument=	LabRAM HR Evol
#Detector=	Syncerity OE
#Objective=	x50_VIS
#Grating=	600 (500nm)
#ND Filter=	25%
#Laser=	514nm_Edge
#Hole=	199.981
#Range=	Visible
#StageXY=	Marzhauser
#StageZ=	Marzhauser
#X (µm)=	-9059.9
#Y (µm)=	4595.4
#Z (µm)=	-261.6
#Full time(mm:ss)=	1:32
#Project=
#Sample=
#Site=
#Title=	PL_M7_280424
#Remark=
#Date=	06.05.2024 16:50
#Acquired=	06.05.2024 16:50:20
520.044	59
520.306	60
520.569	45
520.831	52
521.093	52
521.355	48
521.617	56
521.88	62
522.142	60
522.404	61
522.666	53
522.928	60
523.19	54
523.453	54
523.715	54
523.977	60
524.239	62
524.501	58
524.763	55
525.025	58
525.287	56
525.549	56
525.811	61
526.073	62
526.335	67
526.597	59
526.859	55
527.121	61
527.383	63
527.645	46
527.907	49
528.169	53
528.431	65
528.693	47
528.955	66
529.217	49
529.479	57
529.741	54
530.003	57
530.264	57
530.526	56
530.788	58
531.05	62
531.312	53
531.574	55
531.835	58
532.097	65
532.359	57
532.621	66
532.883	69
533.144	66
533.406	58
533.668	66
533.93	70
534.191	64
534.453	73
534.715	84
534.976	78
535.238	94
535.5	81
535.761	90
536.023	78
536.285	78
536.546	70
536.808	70
537.069	70
537.331	76
537.593	74
537.854	73
538.116	74
538.377	76
538.639	81
538.9	73
539.162	73
539.423	78
539.685	76
539.946	79
540.208	75
540.469	77
540.731	92
540.992	88
541.254	84
541.515	83
541.776	92
542.038	81
542.299	84
542.56	90
542.822	91
543.083	90
543.344	91
543.606	106
543.867	99
544.128	90
544.39	93
544.651	104
544.912	109
545.174	116
545.435	117
545.696	104
545.957	106
546.218	115
546.48	112
546.741	123
547.002	123
547.263	119
547.524	130
547.785	139
548.047	131
548.308	132
548.569	135
548.83	128
549.091	135
549.352	144
549.613	139
549.874	144
550.135	151
550.396	156
550.657	168
550.918	165
551.179	195
551.44	199
551.701	235
551.962	272
552.223	420
552.484	2604
552.745	32889
553.006	804
553.267	349
553.528	249
553.788	249
554.049	218
554.31	233
554.571	213
554.832	218
555.093	205
555.353	207
555.614	213
555.875	221
556.136	223
556.396	226
556.657	228
556.918	242
557.179	237
557.439	249
557.7	246
557.961	249
558.221	250
558.482	253
558.743	254
559.003	247
559.264	276
559.525	258
559.785	280
560.046	271
560.306	296
560.567	284
560.827	315
561.088	295
561.348	300
561.609	322
561.869	333
562.13	319
562.39	331
562.651	341
562.911	349
563.172	342
563.432	356
563.692	373
563.953	401
564.213	395
564.474	437
564.734	412
564.994	397
565.255	400
565.515	409
565.775	401
566.035	430
566.296	433
566.556	451
566.816	439
567.076	469
567.337	461
567.597	471
567.857	480
568.117	492.945
568.377	522.041
568.637	528.647
568.898	534.981
569.158	527.03
569.418	561.395
569.678	551.972
569.938	558.813
570.198	576.766
570.458	584.28
570.718	614.524
570.978	629.749
571.238	651.13
571.498	681.867
571.758	707.062
572.018	733.995
572.278	775.18
572.538	831.057
572.798	854.322
573.058	907.58
573.312	943
573.573	1019
573.834	1086
574.095	1205
574.356	1262
574.617	1367
574.878	1530
575.139	1664
575.4	1774
575.661	1827
575.922	1902
576.183	1892
576.444	1909
576.705	1772
576.965	1708
577.226	1596
577.487	1474
577.748	1375
578.009	1343
578.27	1287
578.531	1253
578.791	1224
579.052	1183
579.313	1199
579.574	1176
579.835	1199
580.095	1143
580.356	1164
580.617	1149
580.878	1151
581.138	1172
581.399	1191
581.66	1202
581.92	1205
582.181	1254
582.442	1235
582.703	1236
582.963	1245
583.224	1278
583.484	1318
583.745	1311
584.006	1317
584.266	1361
584.527	1384
584.787	1426
585.048	1435
585.308	1483
585.569	1491
585.83	1497
586.09	1532
586.351	1563
586.611	1590
586.872	1614
587.132	1585
587.392	1637
587.653	1701
587.913	1702
588.174	1703
588.434	1689
588.695	1693
588.955	1704
589.215	1717
589.476	1699
589.736	1730
589.996	1707
590.257	1790
590.517	1709
590.777	1708
591.038	1712
591.298	1693
591.558	1679
591.818	1666
592.079	1681
592.339	1655
592.599	1666
592.859	1668
593.12	1665
593.38	1664
593.64	1624
593.9	1652
594.16	1690
594.42	1661
594.68	1681
594.941	1691
595.201	1669
595.461	1735
595.721	1768
595.981	1746
596.241	1792
596.501	1796
596.761	1816
597.021	1833
597.281	1845
597.541	1832
597.801	1876
598.061	1868
598.321	1854
598.581	1864
598.841	1906
599.101	1849
599.361	1922
599.62	1878
599.88	1897
600.14	1933
600.4	1887
600.66	1909
600.92	1930
601.18	1901
601.439	1929
601.699	1914
601.959	1917
602.219	1909
602.478	1923
602.738	1962
602.998	1947
603.258	1983
603.517	1973
603.777	1998
604.037	1964
604.296	1992
604.556	1987
604.816	1961
605.075	2021
605.335	1981
605.594	2027
605.854	1974
606.114	2024
606.373	1979
606.633	1981
606.892	1997
607.152	1974
607.411	2022
607.671	2012
607.93	2056
608.19	2000
608.449	2033
608.709	2039
608.968	2077
609.228	2065
609.487	2125
609.746	2114
610.006	2076
610.265	2114
610.524	2124
610.784	2161
611.043	2188
611.302	2156
611.562	2176
611.821	2176
612.08	2239
612.339	2176
612.599	2195
612.858	2215
613.117	2282
613.376	2255
613.635	2322
613.895	2315
614.154	2368
614.413	2320
614.672	2380
614.931	2363
615.19	2416
615.449	2410
615.709	2420
615.968	2493
616.227	2450.42
616.486	2471.51
616.745	2507.15
617.004	2476.34
617.263	2503.68
617.522	2547.88
617.781	2538.71
618.04	2542.77
618.299	2553.54
618.557	2610.21
618.816	2599.76
619.075	2624.7
619.334	2632.53
619.593	2638.71
619.852	2606.51
620.111	2632.75
620.37	2682.39
620.628	2672.69
620.887	2660.07
621.146	2686.11
621.373	2629
621.633	2685
621.893	2740
622.153	2706
622.413	2738
622.673	2687
622.932	2719
623.192	2733
623.452	2742
623.712	2744
623.972	2787
624.232	2792
624.492	2758
624.751	2763
625.011	2790
625.271	2819
625.531	2804
625.791	2819
626.05	2845
626.31	2873
626.57	2858
626.83	2905
627.089	2877
627.349	2931
627.609	2932
627.868	2941
628.128	2997
628.388	2951
628.647	2989
628.907	3002
629.167	2991
629.426	3026
629.686	2997
629.945	3029
630.205	3102
630.465	3060
630.724	3169
630.984	3199
631.243	3113
631.503	3202
631.762	3243
632.022	3241
632.281	3268
632.541	3281
632.8	3289
633.06	3315
633.319	3416
633.579	3350
633.838	3347
634.097	3475
634.357	3472
634.616	3474
634.876	3540
635.135	3585
635.394	3654
635.654	3737
635.913	3781
636.172	3836
636.431	3963
636.691	4054
636.95	4247
637.209	4455
637.469	4706
637.728	4919
637.987	5129
638.246	5307
638.505	5315
638.765	5295
639.024	5188
639.283	5057
639.542	4848
639.801	4699
640.06	4563
640.319	4424
640.578	4431
640.838	4437
641.097	4365
641.356	4350
641.615	4343
641.874	4290
642.133	4307
642.392	4292
642.651	4304
642.91	4329
643.169	4291
643.428	4254
643.687	4417
643.946	4320
644.205	4388
644.463	4376
644.722	4395
644.981	4392
645.24	4419
645.499	4443
645.758	4488
646.017	4472
646.275	4449
646.534	4471
646.793	4530
647.052	4556
647.31	4532
647.569	4599
647.828	4635
648.087	4591
648.345	4644
648.604	4675
648.863	4714
649.121	4691
649.38	4759
649.639	4765
649.897	4765
650.156	4907
650.415	4845
650.673	4950
650.932	4921
651.19	4976
651.449	5019
651.707	5028
651.966	5045
652.224	5146
652.483	5107
652.741	5126
653	5200
653.258	5190
653.517	5253
653.775	5325
654.034	5312
654.292	5437
654.55	5444
654.809	5461
655.067	5480
655.326	5608
655.584	5648
655.842	5690
656.1	5724
656.359	5884
656.617	5844
656.875	5927
657.134	5972
657.392	6053
657.65	6136
657.908	6066
658.166	6221
658.425	6262
658.683	6349
658.941	6255
659.199	6337
659.457	6381
659.715	6400
659.973	6316
660.231	6371
660.49	6348
660.748	6391
661.006	6331
661.264	6475
661.522	6409
661.78	6416
662.038	6428
662.296	6365
662.554	6383
662.811	6301
663.069	6362
663.327	6413
663.585	6437
663.843	6442.43
664.101	6462.23
664.359	6460.8
664.617	6424.49
664.874	6398
665.132	6450.27
665.39	6444.64
665.648	6419.14
665.906	6487.58
666.163	6446.12
666.421	6436.49
666.679	6402.91
666.937	6445.94
667.194	6432.01
667.452	6426.21
667.71	6441.38
667.967	6473.09
668.225	6468.92
668.482	6454.78
668.74	6409.89
668.987	6464
669.245	6496
669.504	6468
669.763	6504
670.022	6429
670.281	6398
670.539	6461
670.798	6480
671.057	6436
671.316	6439
671.575	6464
671.833	6500
672.092	6490
672.351	6482
672.609	6523
672.868	6500
673.127	6485
673.385	6560
673.644	6590
673.903	6610
674.161	6667
674.42	6722
674.678	6635
674.937	6709
675.195	6695
675.454	6698
675.713	6880
675.971	6815
676.23	6874
676.488	6832
676.747	6960
677.005	6883
677.263	6906
677.522	6932
677.78	6940
678.039	6892
678.297	6879
678.556	6884
678.814	6904
679.072	6954
679.331	6975
679.589	6957
679.847	6943
680.106	6996
680.364	6952
680.622	6971
680.881	6993
681.139	7096
681.397	7083
681.656	7036
681.914	7157
682.172	7069
682.43	7111
682.688	7134
682.947	7158
683.205	7151
683.463	7134
683.721	7117
683.979	7200
684.237	7132
684.495	7081
684.754	7086
685.012	7020
685.27	7097
685.528	7072
685.786	7095
686.044	7097
686.302	7010
686.56	6975
686.818	7034
687.076	7064
687.334	7032
687.592	6989
687.85	6956
688.108	7046
688.366	6963
688.623	6972
688.881	6995
689.139	6963
689.397	6955
689.655	7017
689.913	6924
690.171	6922
690.428	6937
690.686	6822
690.944	6782
691.202	6887
691.459	6793
691.717	6815
691.975	6764
692.233	6765
692.49	6796
692.748	6740
693.006	6716
693.263	6694
693.521	6731
693.779	6682
694.036	6699
694.294	6653
694.552	6639
694.809	6676
695.067	6615
695.324	6611
695.582	6576
695.839	6619
696.097	6576
696.354	6578
696.612	6552
696.869	6587
697.127	6544
697.384	6547
697.642	6376
697.899	6482
698.156	6382
698.414	6405
698.671	6370
698.928	6288
699.186	6306
699.443	6239
699.7	6322
699.958	6191
700.215	6221
700.472	6240
700.73	6244
700.987	6280
701.244	6257
701.501	6267
701.758	6210
702.016	6305
702.273	6230
702.53	6285
702.787	6208
703.044	6297
703.301	6271
703.558	6246
703.816	6206
704.073	6188
704.33	6145
704.587	6210
704.844	6130
705.101	6216
705.358	6094
705.615	6058
705.872	6084
706.129	6043
706.386	5975
706.643	5936
706.899	5903
707.156	5911
707.413	5893
707.67	5892
707.927	5813
708.184	5839
708.441	5815
708.697	5839
708.954	5698
709.211	5767
709.468	5708
709.725	5789
709.981	5709
710.238	5686
710.495	5750
710.751	5695
711.008	5747
711.265	5736.32
711.521	5675.15
711.778	5661.84
712.035	5628.39
712.291	5587.06
712.548	5564.27
712.804	5551.2
713.061	5533.88
713.317	5473.68
713.574	5438.44
713.831	5422.81
714.087	5395.79
714.343	5382.65
714.6	5351.74
714.856	5321.38
715.113	5309.68
715.369	5272.38
715.626	5210.99
715.882	5229.41
716.138	5170.64
716.395	5210.14
716.639	5076
716.897	5142
717.155	5110
717.412	5079
717.67	5088
717.927	5025
718.185	5063
718.443	5028
718.7	5034
718.958	5007
719.215	4952
719.473	4947
719.73	4934
719.988	4916
720.245	4938
720.503	4861
720.76	4787
721.018	4793
721.275	4808
721.532	4749
721.79	4703
722.047	4641
722.305	4655
722.562	4665
722.819	4656
723.077	4566
723.334	4593
723.591	4559
723.849	4586
724.106	4466
724.363	4524
724.621	4421
724.878	4477
725.135	4383
725.392	4409
725.65	4442
725.907	4356
726.164	4404
726.421	4386
726.678	4321
726.935	4299
727.193	4317
727.45	4248
727.707	4173
727.964	4180
728.221	4108
728.478	4117
728.735	4090
728.992	4100
729.249	4052
729.506	4034
729.763	3975
730.02	3927
730.277	3922
730.534	3947
730.791	3891
731.048	3952
731.305	3822
731.562	3837
731.819	3824
732.076	3754
732.333	3795
732.589	3800
732.846	3735
733.103	3775
733.36	3750
733.617	3697
733.873	3688
734.13	3753
734.387	3670
734.644	3728
734.901	3710
735.157	3639
735.414	3668
735.671	3677
735.927	3631
736.184	3664
736.441	3583
736.697	3621
736.954	3644
737.211	3636
737.467	3595
737.724	3592
737.98	3574
738.237	3640
738.493	3598
738.75	3581
739.006	3555
739.263	3506
739.519	3522
739.776	3508
740.032	3486
740.289	3532
740.545	3427
740.802	3429
741.058	3411
741.314	3393
741.571	3396
741.827	3311
742.083	3391
742.34	3343
742.596	3321
742.852	3283
743.109	3336
743.365	3297
743.621	3251
743.878	3250
744.134	3220
744.39	3247
744.646	3209
744.902	3214
745.159	3164
745.415	3172
745.671	3090
745.927	3146
746.183	3141
746.439	3129
746.695	3043
746.951	3014
747.207	3079
747.463	3004
747.719	3079
747.975	3048
748.231	3035
748.487	3037
748.743	2946
748.999	2961
749.255	2942
749.511	2916
749.767	2948
750.023	2928
750.279	2955
750.535	2923
750.791	2912
751.046	2837
751.302	2876
751.558	2854
751.814	2785
752.07	2821
752.325	2728
752.581	2778
752.837	2771
753.092	2736
753.348	2727
753.604	2768
753.859	2692
754.115	2669
754.371	2669
754.626	2656
754.882	2611
755.138	2688
755.393	2610
755.649	2603
755.904	2600
756.16	2598
756.415	2594
756.671	2579
756.926	2530
757.182	2511
757.437	2520
757.693	2504
757.948	2453
758.203	2454
758.459	2484
758.714	2463.69
758.97	2441.48
759.225	2457.08
759.48	2451.83
759.736	2400.66
759.991	2397.68
760.246	2382.43
760.501	2329.32
760.757	2352.45
761.012	2358.34
761.267	2319.82
761.522	2267.54
761.777	2303.5
762.033	2301.15
762.288	2307.26
762.543	2273.37
762.798	2230.3
763.053	2241.7
763.308	2225.31
763.563	2202.55
763.78	2205
764.037	2186
764.293	2207
764.55	2154
764.806	2163
765.062	2192
765.319	2137
765.575	2117
765.831	2078
766.088	2100
766.344	2089
766.6	2063
766.857	2073
767.113	2082
767.369	2036
767.625	1988
767.882	1970
768.138	1996
768.394	1976
768.65	1962
768.906	1940
769.163	1949
769.419	1929
769.675	1935
769.931	1929
770.187	1894
770.443	1875
770.699	1846
770.955	1860
771.211	1837
771.467	1823
771.723	1826
771.979	1802
772.235	1813
772.491	1798
772.747	1745
773.003	1777
773.259	1743
773.515	1747
773.771	1740
774.027	1725
774.283	1716
774.539	1687
774.795	1676
775.05	1691
775.306	1661
775.562	1641
775.818	1615
776.074	1628
776.329	1607
776.585	1598
776.841	1566
777.097	1587
777.352	1573
777.608	1502
777.864	1557
778.12	1470
778.375	1523
778.631	1512
778.886	1492
779.142	1478
779.398	1476
779.653	1467
779.909	1474
780.164	1489
780.42	1429
780.675	1433
780.931	1455
781.187	1420
781.442	1401
781.698	1397
781.953	1369
782.208	1406
782.464	1338
782.719	1338
782.975	1343
783.23	1328
783.485	1326
783.741	1327
783.996	1311
784.252	1277
784.507	1273
784.762	1267
785.017	1258
785.273	1286
785.528	1271
785.783	1251
786.038	1215
786.294	1227
786.549	1212
786.804	1193
787.059	1203
787.314	1196
787.57	1165
787.825	1169
788.08	1177
788.335	1165
788.59	1147
788.845	1117
789.1	1166
789.355	1131
789.61	1102
789.865	1080
790.12	1104
790.375	1089
790.63	1090
790.885	1079
791.14	1036
791.395	1078
791.65	1045
791.905	1065
792.16	1037
792.414	1015
792.669	1012
792.924	1030
793.179	1008
793.434	990
793.689	1005
793.943	969
794.198	966
794.453	1001
794.708	972
794.962	969
795.217	946
795.472	969
795.726	937
795.981	932
796.236	944
796.49	893
796.745	934
796.999	909
797.254	898
797.508	869
797.763	882
798.018	888
798.272	865
798.526	880
798.781	847
799.035	863
799.29	860
799.544	856
799.799	839
800.053	820
800.307	820
800.562	829
800.816	816
801.07	802
801.325	784
801.579	790
801.833	783
802.088	792
802.342	799
802.596	783
802.85	783
803.105	782
803.359	745
803.613	755
803.867	772
804.121	757
804.375	730
804.63	711
804.884	741
805.138	727
805.392	716
805.646	704.245
805.9	719.052
806.154	716.563
806.408	702.168
806.662	689.696
806.916	690.899
807.17	679.928
807.424	684.775
807.678	662.67
807.931	686.022
808.185	673.268
808.439	661.458
808.693	649.328
808.947	632.827
809.201	637.347
809.454	624.683
809.708	633.298
809.962	636.663
810.216	615.478
810.469	597.234
810.678	647
810.933	612
811.188	608
811.443	606
811.699	600
811.954	606
812.209	600
812.464	568
812.719	579
812.974	575
813.229	561
813.484	568
813.739	570
813.994	575
814.249	560
814.504	549
814.759	564
815.014	573
815.268	561
815.523	542
815.778	546
816.033	526
816.288	536
816.543	524
816.798	507
817.052	523
817.307	524
817.562	508
817.817	512
818.071	499
818.326	496
818.581	503
818.836	521
819.09	489
819.345	485
819.6	505
819.854	472
820.109	484
820.364	472
820.618	460
820.873	482
821.127	479
821.382	467
821.637	472
821.891	455
822.146	452
822.4	445
822.655	446
822.909	445
823.164	452
823.418	444
823.672	450
823.927	440
824.181	441
824.436	441
824.69	415
824.944	418
825.199	413
825.453	425
825.707	423
825.962	412
826.216	415
826.47	393
826.725	396
826.979	411
827.233	420
827.487	409
827.741	389
827.996	400
828.25	389
828.504	372
828.758	390
829.012	398
829.266	398
829.52	364
829.774	370
830.029	362
830.283	371
830.537	397
830.791	368
831.045	367
831.299	367
831.553	354
831.807	356
832.061	347
832.315	367
832.568	362
832.822	348
833.076	355
833.33	351
833.584	346
833.838	333
834.092	339
834.345	345
834.599	335
834.853	337
835.107	322
835.36	329
835.614	320
835.868	310
836.122	319
836.375	327
836.629	316
836.883	311
837.136	331
837.39	325
837.643	326
837.897	326
838.151	302
838.404	318
838.658	307
838.911	312
839.165	316
839.418	317
839.672	306
839.925	297
840.179	317
840.432	294
840.686	288
840.939	292
841.192	287
841.446	289
841.699	283
841.952	292
842.206	275
842.459	292
842.712	276
842.966	295
843.219	282
843.472	273
843.725	298
843.979	274
844.232	272
844.485	289
844.738	273
844.991	264
845.244	263
845.497	278
845.75	270
846.004	280
846.257	273
846.51	283
846.763	270
847.016	258
847.269	272
847.522	264
847.775	263
848.028	254
848.281	270
848.534	262
848.786	256
849.039	258
849.292	245
849.545	243
849.798	248
850.051	248
850.303	245
850.556	238
850.809	242
851.062	239
851.314	233
851.567	234
851.82	232
852.073	222
852.325	236.004
852.578	228.109
852.831	231.47
853.083	221.869
853.336	235.35
853.588	222.942
853.841	226.27
854.093	224.388
854.346	222.035
854.598	222.802
854.851	218.222
855.103	223.42
855.356	220.362
855.608	225.554
855.861	210.384
856.113	218.249
856.366	211.171
856.618	207.577
856.87	206.842
857.123	211.209
857.352	208
857.606	202
857.859	215
858.113	205
858.367	213
858.621	207
858.875	210
859.128	200
859.382	194
859.636	200
859.889	209
860.143	187
860.397	196
860.65	212
860.904	189
861.158	193
861.411	193
861.665	193
861.918	190
862.172	199
862.425	189
862.679	182
862.932	180
863.186	194
863.439	187
863.693	190
863.946	183
864.2	176
864.453	186
864.707	196
864.96	184
865.213	173
865.467	184
865.72	178
865.973	181
866.227	180
866.48	183
866.733	183
866.987	178
867.24	180
867.493	172
867.746	184
867.999	165
868.253	171
868.506	170
868.759	171
869.012	175
869.265	176
869.518	170
869.771	170
870.025	171
870.278	169
870.531	166
870.784	168
871.037	165
871.29	147
871.543	146
871.796	160
872.049	152
872.302	150
872.555	162
872.808	160
873.06	165
873.313	157
873.566	155
873.819	153
874.072	158
874.325	159
874.578	144
874.83	160
875.083	154
875.336	155
875.589	157
875.841	145
876.094	152
876.347	148
876.6	140
876.852	151
877.105	148
877.358	149
877.61	145
877.863	148
878.115	143
878.368	158
878.621	141
878.873	147
879.126	138
879.378	147
879.631	134
879.883	135
880.136	146
880.388	134
880.641	136
880.893	138
881.145	145
881.398	142
881.65	120
881.902	137
882.155	128
882.407	130
882.659	132
882.912	127
883.164	139
883.416	127
883.669	123
883.921	131
884.173	125
884.425	126
884.677	129
884.93	131
885.182	130
885.434	133
885.686	112
885.938	133
886.19	115
886.442	121
886.694	123
886.946	129
887.198	121
887.45	131
887.702	108
887.954	125
888.206	118
888.458	130
888.71	123
888.962	102
889.214	127
889.466	119
889.718	116
889.969	106
890.221	104
890.473	113
890.725	112
890.977	115
891.228	120
891.48	118
891.732	116
891.983	109
892.235	99
892.487	96
892.738	107
892.99	99
893.242	104
893.493	118
893.745	105
893.996	96
894.248	97
894.5	109
894.751	94
895.003	106
895.254	106
895.505	99
895.757	104
896.008	98
896.26	103
896.511	90
896.763	101
897.014	99
897.265	105
897.517	107
897.768	91
898.019	95
898.27	92
898.522	104
898.773	100
899.024	79
899.275	96
899.527	101
899.778	98
899.979	94