File: PL_M2_180324_01.txt
#Acq. time (s)=	3
#Accumulations=	2
#Range (nm)=	520...900
#Windows=	8
#Auto scanning=	Off
#Autofocus=	Off
#AutoExposure=	Off
#Spike filter=	Multiple accum.
#Delay time (s)=	0
#Binning=	1
#Readout mode=	Signal
#DeNoise=	Off
#ICS correction=	Off
#Dark correction=	Off
#Inst. Process=	Off
#Detector temperature (°C)=	-59.98
#Instrument=	LabRAM HR Evol
#Detector=	Syncerity OE
#Objective=	x50_VIS
#Grating=	600 (500nm)
#ND Filter=	25%
#Laser=	514nm_Edge
#Hole=	199.981
#Range=	Auto
#StageXY=	Marzhauser
#StageZ=	Marzhauser
#X (µm)=	-454.1
#Y (µm)=	5366.7
#Z (µm)=	-6.6
#Full time(mm:ss)=	1:32
#Project=
#Sample=
#Site=
#Title=	PL_M2_180324
#Remark=
#Date=	28.03.2024 09:12
#Acquired=	28.03.2024 09:12:31
520.044	48
520.306	44
520.569	50
520.831	46
521.093	38
521.355	40
521.617	48
521.88	48
522.142	38
522.404	44
522.666	36
522.928	50
523.19	36
523.453	44
523.715	56
523.977	42
524.239	42
524.501	36
524.763	52
525.025	44
525.287	46
525.549	36
525.811	52
526.073	52
526.335	46
526.597	36
526.859	48
527.121	38
527.383	50
527.645	36
527.907	48
528.169	42
528.431	40
528.693	44
528.955	44
529.217	50
529.479	42
529.741	42
530.003	50
530.264	44
530.526	50
530.788	36
531.05	56
531.312	56
531.574	40
531.835	42
532.097	54
532.359	50
532.621	48
532.883	44
533.144	52
533.406	54
533.668	56
533.93	58
534.191	56
534.453	74
534.715	68
534.976	64
535.238	64
535.5	76
535.761	64
536.023	60
536.285	62
536.546	60
536.808	54
537.069	66
537.331	60
537.593	64
537.854	58
538.116	68
538.377	66
538.639	58
538.9	62
539.162	60
539.423	70
539.685	70
539.946	66
540.208	66
540.469	68
540.731	70
540.992	66
541.254	64
541.515	76
541.776	70
542.038	78
542.299	78
542.56	74
542.822	86
543.083	74
543.344	70
543.606	82
543.867	76
544.128	86
544.39	94
544.651	90
544.912	90
545.174	92
545.435	90
545.696	92
545.957	92
546.218	96
546.48	100
546.741	100
547.002	116
547.263	108
547.524	100
547.785	124
548.047	122
548.308	120
548.569	124
548.83	134
549.091	152
549.352	194
549.613	258
549.874	282
550.135	230
550.396	198
550.657	184
550.918	184
551.179	190
551.44	188
551.701	218
551.962	270
552.223	388
552.484	2726
552.745	22292
553.006	638
553.267	296
553.528	234
553.788	200
554.049	202
554.31	190
554.571	208
554.832	196
555.093	190
555.353	186
555.614	190
555.875	194
556.136	206
556.396	216
556.657	202
556.918	204
557.179	226
557.439	234
557.7	222
557.961	232
558.221	240
558.482	220
558.743	242
559.003	240
559.264	256
559.525	262
559.785	264
560.046	266
560.306	262
560.567	278
560.827	266
561.088	280
561.348	292
561.609	308
561.869	308
562.13	298
562.39	336
562.651	314
562.911	346
563.172	338
563.432	364
563.692	384
563.953	420
564.213	408
564.474	432
564.734	422
564.994	398
565.255	390
565.515	426
565.775	410
566.035	424
566.296	416
566.556	434
566.816	446
567.076	484
567.337	446
567.597	462
567.857	486
568.117	481.99
568.377	490.371
568.637	505.585
568.898	517.639
569.158	525.043
569.418	520.106
569.678	529.698
569.938	565.563
570.198	572.576
570.458	582.77
570.718	622.66
570.978	630.481
571.238	678.924
571.498	703.715
571.758	723.758
572.018	769.835
572.278	794.996
572.538	872.03
572.798	891.332
573.058	964.619
573.312	984
573.573	1080
573.834	1160
574.095	1284
574.356	1360
574.617	1480
574.878	1596
575.139	1718
575.4	1820
575.661	1804
575.922	1856
576.183	1840
576.444	1774
576.705	1726
576.965	1622
577.226	1534
577.487	1476
577.748	1402
578.009	1318
578.27	1280
578.531	1246
578.791	1200
579.052	1186
579.313	1198
579.574	1164
579.835	1148
580.095	1208
580.356	1172
580.617	1184
580.878	1150
581.138	1204
581.399	1188
581.66	1186
581.92	1204
582.181	1212
582.442	1234
582.703	1248
582.963	1312
583.224	1320
583.484	1312
583.745	1302
584.006	1394
584.266	1402
584.527	1388
584.787	1438
585.048	1448
585.308	1498
585.569	1480
585.83	1514
586.09	1564
586.351	1614
586.611	1596
586.872	1598
587.132	1614
587.392	1612
587.653	1640
587.913	1678
588.174	1658
588.434	1700
588.695	1678
588.955	1696
589.215	1702
589.476	1690
589.736	1724
589.996	1706
590.257	1654
590.517	1734
590.777	1700
591.038	1708
591.298	1704
591.558	1678
591.818	1658
592.079	1642
592.339	1672
592.599	1648
592.859	1650
593.12	1602
593.38	1614
593.64	1708
593.9	1628
594.16	1644
594.42	1680
594.68	1698
594.941	1664
595.201	1690
595.461	1760
595.721	1774
595.981	1800
596.241	1808
596.501	1852
596.761	1852
597.021	1858
597.281	1850
597.541	1898
597.801	1844
598.061	1854
598.321	1884
598.581	1890
598.841	1904
599.101	1864
599.361	1884
599.62	1866
599.88	1924
600.14	1908
600.4	1950
600.66	1916
600.92	1902
601.18	1910
601.439	1888
601.699	1916
601.959	1926
602.219	1934
602.478	1968
602.738	1946
602.998	1932
603.258	1992
603.517	1954
603.777	1998
604.037	1992
604.296	1988
604.556	1990
604.816	2014
605.075	2030
605.335	2034
605.594	1998
605.854	2016
606.114	2024
606.373	1988
606.633	2008
606.892	2024
607.152	2052
607.411	1998
607.671	2044
607.93	2046
608.19	2056
608.449	2082
608.709	2116
608.968	2100
609.228	2108
609.487	2140
609.746	2188
610.006	2124
610.265	2196
610.524	2188
610.784	2204
611.043	2178
611.302	2188
611.562	2192
611.821	2242
612.08	2196
612.339	2258
612.599	2264
612.858	2288
613.117	2296
613.376	2296
613.635	2336
613.895	2322
614.154	2368
614.413	2410
614.672	2418
614.931	2464
615.19	2460
615.449	2500
615.709	2482
615.968	2580
616.227	2531.82
616.486	2537.65
616.745	2587.41
617.004	2581.79
617.263	2573.14
617.522	2589.57
617.781	2630.29
618.04	2640.84
618.299	2627.4
618.557	2634.95
618.816	2691.57
619.075	2685.62
619.334	2681.4
619.593	2712.68
619.852	2724.96
620.111	2729.74
620.37	2753.14
620.628	2728.25
620.887	2762.65
621.146	2793.01
621.373	2792
621.633	2774
621.893	2810
622.153	2830
622.413	2784
622.673	2812
622.932	2810
623.192	2830
623.452	2862
623.712	2882
623.972	2878
624.232	2822
624.492	2862
624.751	2880
625.011	2940
625.271	2976
625.531	2924
625.791	2988
626.05	2940
626.31	2984
626.57	2982
626.83	3000
627.089	3030
627.349	3086
627.609	3080
627.868	3044
628.128	3098
628.388	3164
628.647	3130
628.907	3128
629.167	3214
629.426	3250
629.686	3254
629.945	3270
630.205	3276
630.465	3310
630.724	3344
630.984	3320
631.243	3360
631.503	3312
631.762	3426
632.022	3380
632.281	3480
632.541	3512
632.8	3610
633.06	3526
633.319	3632
633.579	3632
633.838	3644
634.097	3768
634.357	3788
634.616	3866
634.876	3910
635.135	3942
635.394	4032
635.654	4070
635.913	4266
636.172	4400
636.431	4618
636.691	4792
636.95	5012
637.209	5086
637.469	5350
637.728	5484
637.987	5576
638.246	5594
638.505	5706
638.765	5638
639.024	5518
639.283	5502
639.542	5282
639.801	5120
640.06	5022
640.319	5014
640.578	4900
640.838	4840
641.097	4756
641.356	4762
641.615	4740
641.874	4716
642.133	4774
642.392	4794
642.651	4722
642.91	4726
643.169	4734
643.428	4790
643.687	4806
643.946	4732
644.205	4778
644.463	4812
644.722	4798
644.981	4892
645.24	4858
645.499	4816
645.758	4904
646.017	4910
646.275	4962
646.534	4990
646.793	5054
647.052	5040
647.31	4984
647.569	5074
647.828	5124
648.087	5110
648.345	5128
648.604	5220
648.863	5204
649.121	5308
649.38	5278
649.639	5442
649.897	5314
650.156	5440
650.415	5440
650.673	5402
650.932	5502
651.19	5526
651.449	5604
651.707	5602
651.966	5696
652.224	5668
652.483	5706
652.741	5802
653	5878
653.258	5774
653.517	5952
653.775	6064
654.034	6012
654.292	6094
654.55	6188
654.809	6214
655.067	6324
655.326	6282
655.584	6396
655.842	6410
656.1	6602
656.359	6616
656.617	6646
656.875	6724
657.134	6780
657.392	6842
657.65	6978
657.908	6992
658.166	7042
658.425	7128
658.683	7070
658.941	7190
659.199	7140
659.457	7196
659.715	7240
659.973	7272
660.231	7294
660.49	7140
660.748	7250
661.006	7320
661.264	7318
661.522	7220
661.78	7294
662.038	7230
662.296	7212
662.554	7296
662.811	7188
663.069	7216
663.327	7270
663.585	7278
663.843	7314.69
664.101	7368.53
664.359	7362.46
664.617	7274.67
664.874	7313.54
665.132	7258.66
665.39	7264.92
665.648	7293.81
665.906	7366.27
666.163	7308.98
666.421	7282.33
666.679	7283.01
666.937	7257.53
667.194	7345.93
667.452	7352.59
667.71	7346.79
667.967	7324.28
668.225	7332.15
668.482	7345.09
668.74	7354.76
668.987	7198
669.245	7342
669.504	7376
669.763	7296
670.022	7276
670.281	7354
670.539	7230
670.798	7306
671.057	7354
671.316	7358
671.575	7408
671.833	7310
672.092	7372
672.351	7476
672.609	7450
672.868	7462
673.127	7492
673.385	7494
673.644	7550
673.903	7586
674.161	7556
674.42	7602
674.678	7670
674.937	7802
675.195	7734
675.454	7702
675.713	7836
675.971	7864
676.23	7870
676.488	7918
676.747	7806
677.005	7894
677.263	8010
677.522	7856
677.78	7766
678.039	7866
678.297	7944
678.556	7910
678.814	7904
679.072	7934
679.331	7830
679.589	7924
679.847	7922
680.106	7982
680.364	7978
680.622	8054
680.881	8066
681.139	8050
681.397	8040
681.656	8088
681.914	8144
682.172	8226
682.43	8226
682.688	8182
682.947	8152
683.205	8164
683.463	8162
683.721	8200
683.979	8108
684.237	8142
684.495	8106
684.754	8122
685.012	8120
685.27	8150
685.528	8064
685.786	8116
686.044	8080
686.302	8030
686.56	8052
686.818	8010
687.076	7924
687.334	7932
687.592	7950
687.85	7954
688.108	7944
688.366	7992
688.623	8014
688.881	7910
689.139	7982
689.397	7876
689.655	7870
689.913	7894
690.171	7962
690.428	7806
690.686	7826
690.944	7858
691.202	7806
691.459	7864
691.717	7756
691.975	7668
692.233	7766
692.49	7704
692.748	7702
693.006	7692
693.263	7668
693.521	7634
693.779	7640
694.036	7624
694.294	7630
694.552	7530
694.809	7564
695.067	7496
695.324	7560
695.582	7430
695.839	7398
696.097	7542
696.354	7456
696.612	7430
696.869	7424
697.127	7326
697.384	7410
697.642	7370
697.899	7262
698.156	7210
698.414	7202
698.671	7230
698.928	7146
699.186	7130
699.443	7074
699.7	7190
699.958	7102
700.215	7084
700.472	7028
700.73	6994
700.987	7136
701.244	6962
701.501	7032
701.758	7082
702.016	7036
702.273	7092
702.53	7064
702.787	7078
703.044	7114
703.301	7150
703.558	7102
703.816	6976
704.073	6960
704.33	6990
704.587	6892
704.844	6990
705.101	6920
705.358	6838
705.615	6782
705.872	6772
706.129	6892
706.386	6756
706.643	6664
706.899	6696
707.156	6700
707.413	6630
707.67	6678
707.927	6676
708.184	6664
708.441	6590
708.697	6434
708.954	6596
709.211	6552
709.468	6552
709.725	6500
709.981	6524
710.238	6402
710.495	6470
710.751	6400
711.008	6386
711.265	6408.55
711.521	6404.41
711.778	6363.17
712.035	6252.41
712.291	6284.32
712.548	6285.76
712.804	6212.65
713.061	6187.31
713.317	6186.05
713.574	6159.43
713.831	6149.68
714.087	6082.33
714.343	6097.3
714.6	6025.35
714.856	6056.92
715.113	5997.8
715.369	5913.62
715.626	5968.28
715.882	5948.16
716.138	5855.63
716.395	5866.2
716.639	5872
716.897	5760
717.155	5822
717.412	5800
717.67	5738
717.927	5726
718.185	5654
718.443	5738
718.7	5536
718.958	5644
719.215	5614
719.473	5574
719.73	5546
719.988	5508
720.245	5532
720.503	5460
720.76	5456
721.018	5478
721.275	5342
721.532	5340
721.79	5358
722.047	5262
722.305	5276
722.562	5222
722.819	5160
723.077	5174
723.334	5142
723.591	5054
723.849	5178
724.106	5134
724.363	5070
724.621	4988
724.878	5018
725.135	4930
725.392	4968
725.65	4942
725.907	4872
726.164	4868
726.421	4892
726.678	4790
726.935	4788
727.193	4808
727.45	4758
727.707	4760
727.964	4682
728.221	4686
728.478	4636
728.735	4584
728.992	4656
729.249	4544
729.506	4532
729.763	4452
730.02	4468
730.277	4406
730.534	4384
730.791	4348
731.048	4340
731.305	4318
731.562	4222
731.819	4264
732.076	4252
732.333	4286
732.589	4190
732.846	4206
733.103	4168
733.36	4192
733.617	4116
733.873	4120
734.13	4210
734.387	4126
734.644	4146
734.901	4150
735.157	4160
735.414	4122
735.671	4070
735.927	4132
736.184	4100
736.441	4086
736.697	4064
736.954	4054
737.211	4132
737.467	4134
737.724	4092
737.98	4144
738.237	4086
738.493	4090
738.75	4076
739.006	4022
739.263	4044
739.519	3972
739.776	3964
740.032	3946
740.289	3890
740.545	3886
740.802	3848
741.058	3834
741.314	3816
741.571	3772
741.827	3782
742.083	3744
742.34	3762
742.596	3674
742.852	3724
743.109	3692
743.365	3698
743.621	3584
743.878	3634
744.134	3628
744.39	3540
744.646	3608
744.902	3540
745.159	3582
745.415	3538
745.671	3514
745.927	3450
746.183	3456
746.439	3414
746.695	3360
746.951	3358
747.207	3418
747.463	3410
747.719	3362
747.975	3382
748.231	3374
748.487	3328
748.743	3300
748.999	3222
749.255	3256
749.511	3296
749.767	3232
750.023	3272
750.279	3232
750.535	3240
750.791	3190
751.046	3136
751.302	3160
751.558	3088
751.814	3126
752.07	3070
752.325	3076
752.581	3088
752.837	3050
753.092	3004
753.348	2958
753.604	2956
753.859	3004
754.115	2940
754.371	2954
754.626	2946
754.882	2894
755.138	2852
755.393	2892
755.649	2864
755.904	2810
756.16	2804
756.415	2814
756.671	2822
756.926	2820
757.182	2700
757.437	2742
757.693	2716
757.948	2792
758.203	2728
758.459	2706
758.714	2674.71
758.97	2664.29
759.225	2696.82
759.48	2650.09
759.736	2630.63
759.991	2617.59
760.246	2569.15
760.501	2584.46
760.757	2549.72
761.012	2502.64
761.267	2508.61
761.522	2530.78
761.777	2506.07
762.033	2530.99
762.288	2473.25
762.543	2458.96
762.798	2400.59
763.053	2425.36
763.308	2396.73
763.563	2375.21
763.78	2396
764.037	2390
764.293	2360
764.55	2348
764.806	2366
765.062	2304
765.319	2290
765.575	2348
765.831	2260
766.088	2300
766.344	2234
766.6	2224
766.857	2234
767.113	2228
767.369	2174
767.625	2132
767.882	2158
768.138	2186
768.394	2146
768.65	2142
768.906	2096
769.163	2120
769.419	2026
769.675	2088
769.931	1988
770.187	2012
770.443	1986
770.699	2020
770.955	2006
771.211	1940
771.467	1956
771.723	1960
771.979	1918
772.235	1948
772.491	1902
772.747	1888
773.003	1880
773.259	1896
773.515	1862
773.771	1860
774.027	1862
774.283	1818
774.539	1844
774.795	1752
775.05	1758
775.306	1754
775.562	1772
775.818	1730
776.074	1782
776.329	1730
776.585	1720
776.841	1682
777.097	1660
777.352	1712
777.608	1660
777.864	1624
778.12	1630
778.375	1588
778.631	1526
778.886	1568
779.142	1602
779.398	1564
779.653	1532
779.909	1608
780.164	1562
780.42	1514
780.675	1516
780.931	1496
781.187	1504
781.442	1484
781.698	1462
781.953	1424
782.208	1484
782.464	1442
782.719	1428
782.975	1456
783.23	1414
783.485	1416
783.741	1374
783.996	1328
784.252	1404
784.507	1366
784.762	1332
785.017	1334
785.273	1304
785.528	1370
785.783	1306
786.038	1270
786.294	1294
786.549	1312
786.804	1298
787.059	1252
787.314	1294
787.57	1210
787.825	1232
788.08	1214
788.335	1190
788.59	1204
788.845	1178
789.1	1186
789.355	1174
789.61	1182
789.865	1170
790.12	1148
790.375	1188
790.63	1138
790.885	1128
791.14	1158
791.395	1140
791.65	1112
791.905	1094
792.16	1078
792.414	1066
792.669	1088
792.924	1068
793.179	1068
793.434	1038
793.689	1042
793.943	1006
794.198	1026
794.453	1014
794.708	1006
794.962	1012
795.217	1006
795.472	978
795.726	1008
795.981	962
796.236	994
796.49	960
796.745	958
796.999	956
797.254	918
797.508	922
797.763	930
798.018	906
798.272	896
798.526	914
798.781	888
799.035	876
799.29	850
799.544	878
799.799	848
800.053	858
800.307	896
800.562	848
800.816	826
801.07	838
801.325	816
801.579	802
801.833	790
802.088	784
802.342	776
802.596	796
802.85	770
803.105	794
803.359	796
803.613	790
803.867	772
804.121	762
804.375	742
804.63	756
804.884	756
805.138	732
805.392	758
805.646	747.66
805.9	723.951
806.154	713.499
806.408	716.165
806.662	718.787
806.916	689.368
807.17	726.448
807.424	714.456
807.678	690.262
807.931	679.357
808.185	678.167
808.439	673.691
808.693	669.988
808.947	662.794
809.201	638.845
809.454	653.146
809.708	663.063
809.962	647.107
810.216	637.279
810.469	625.453
810.678	622
810.933	624
811.188	618
811.443	626
811.699	618
811.954	606
812.209	592
812.464	592
812.719	596
812.974	582
813.229	598
813.484	622
813.739	574
813.994	584
814.249	542
814.504	540
814.759	542
815.014	538
815.268	550
815.523	552
815.778	530
816.033	524
816.288	538
816.543	580
816.798	496
817.052	518
817.307	498
817.562	528
817.817	502
818.071	524
818.326	518
818.581	510
818.836	500
819.09	500
819.345	476
819.6	496
819.854	488
820.109	478
820.364	492
820.618	488
820.873	490
821.127	482
821.382	482
821.637	456
821.891	448
822.146	460
822.4	476
822.655	454
822.909	450
823.164	428
823.418	436
823.672	454
823.927	430
824.181	440
824.436	442
824.69	422
824.944	410
825.199	426
825.453	420
825.707	412
825.962	398
826.216	408
826.47	418
826.725	374
826.979	404
827.233	402
827.487	396
827.741	398
827.996	388
828.25	388
828.504	404
828.758	392
829.012	392
829.266	370
829.52	376
829.774	376
830.029	370
830.283	344
830.537	370
830.791	352
831.045	354
831.299	342
831.553	358
831.807	350
832.061	364
832.315	366
832.568	354
832.822	352
833.076	350
833.33	338
833.584	342
833.838	336
834.092	340
834.345	328
834.599	350
834.853	326
835.107	340
835.36	326
835.614	340
835.868	320
836.122	320
836.375	300
836.629	312
836.883	308
837.136	310
837.39	310
837.643	316
837.897	304
838.151	318
838.404	286
838.658	322
838.911	312
839.165	292
839.418	276
839.672	290
839.925	298
840.179	290
840.432	284
840.686	296
840.939	268
841.192	286
841.446	268
841.699	288
841.952	284
842.206	278
842.459	268
842.712	282
842.966	284
843.219	276
843.472	270
843.725	274
843.979	252
844.232	260
844.485	264
844.738	258
844.991	262
845.244	270
845.497	254
845.75	240
846.004	252
846.257	238
846.51	240
846.763	236
847.016	248
847.269	266
847.522	218
847.775	250
848.028	246
848.281	244
848.534	232
848.786	248
849.039	252
849.292	246
849.545	228
849.798	234
850.051	238
850.303	230
850.556	236
850.809	234
851.062	232
851.314	240
851.567	220
851.82	226
852.073	214
852.325	229.969
852.578	199.212
852.831	225.375
853.083	210.444
853.336	214.686
853.588	209.122
853.841	213.83
854.093	206.928
854.346	217.394
854.598	212.028
854.851	204.688
855.103	205.924
855.356	200.747
855.608	202.41
855.861	203.696
856.113	202.417
856.366	200.34
856.618	192.928
856.87	200.021
857.123	198.659
857.352	178
857.606	198
857.859	184
858.113	188
858.367	184
858.621	194
858.875	190
859.128	190
859.382	174
859.636	192
859.889	178
860.143	184
860.397	174
860.65	188
860.904	182
861.158	174
861.411	166
861.665	186
861.918	188
862.172	180
862.425	172
862.679	178
862.932	178
863.186	176
863.439	160
863.693	172
863.946	172
864.2	188
864.453	152
864.707	172
864.96	166
865.213	166
865.467	148
865.72	172
865.973	160
866.227	176
866.48	178
866.733	166
866.987	160
867.24	164
867.493	162
867.746	162
867.999	140
868.253	158
868.506	152
868.759	160
869.012	164
869.265	160
869.518	154
869.771	154
870.025	160
870.278	158
870.531	148
870.784	152
871.037	146
871.29	140
871.543	136
871.796	152
872.049	144
872.302	148
872.555	130
872.808	140
873.06	128
873.313	156
873.566	140
873.819	138
874.072	144
874.325	128
874.578	132
874.83	134
875.083	142
875.336	140
875.589	124
875.841	122
876.094	134
876.347	148
876.6	134
876.852	126
877.105	140
877.358	136
877.61	130
877.863	120
878.115	126
878.368	132
878.621	120
878.873	124
879.126	140
879.378	126
879.631	128
879.883	112
880.136	126
880.388	112
880.641	120
880.893	118
881.145	126
881.398	124
881.65	126
881.902	110
882.155	120
882.407	130
882.659	120
882.912	102
883.164	126
883.416	114
883.669	114
883.921	114
884.173	114
884.425	120
884.677	106
884.93	114
885.182	110
885.434	120
885.686	104
885.938	100
886.19	112
886.442	112
886.694	96
886.946	106
887.198	110
887.45	110
887.702	102
887.954	110
888.206	94
888.458	110
888.71	92
888.962	112
889.214	100
889.466	106
889.718	102
889.969	100
890.221	104
890.473	98
890.725	88
890.977	94
891.228	102
891.48	92
891.732	90
891.983	86
892.235	98
892.487	90
892.738	88
892.99	88
893.242	100
893.493	86
893.745	94
893.996	90
894.248	102
894.5	94
894.751	92
895.003	86
895.254	92
895.505	94
895.757	88
896.008	78
896.26	80
896.511	90
896.763	82
897.014	78
897.265	84
897.517	86
897.768	78
898.019	78
898.27	82
898.522	88
898.773	86
899.024	78
899.275	78
899.527	86
899.778	84
899.979	74