File: PL_M8_280424_01.txt
#Acq. time (s)=	3
#Accumulations=	2
#Range (nm)=	520...900
#Windows=	8
#Auto scanning=	Off
#Autofocus=	Off
#AutoExposure=	Off
#Spike filter=	Off
#Delay time (s)=	0
#Binning=	1
#Readout mode=	Signal
#DeNoise=	Off
#ICS correction=	Off
#Dark correction=	Off
#Inst. Process=	Off
#Detector temperature (°C)=	-59.98
#Instrument=	LabRAM HR Evol
#Detector=	Syncerity OE
#Objective=	x50_VIS
#Grating=	600 (500nm)
#ND Filter=	25%
#Laser=	514nm_Edge
#Hole=	199.981
#Range=	Visible
#StageXY=	Marzhauser
#StageZ=	Marzhauser
#X (µm)=	-9072.9
#Y (µm)=	12449.1
#Z (µm)=	-262.1
#Full time(mm:ss)=	1:32
#Project=
#Sample=
#Site=
#Title=	PL_M8_280424
#Remark=
#Date=	06.05.2024 16:52
#Acquired=	06.05.2024 16:52:47
520.044	48
520.306	49
520.569	56
520.831	49
521.093	49
521.355	59
521.617	54
521.88	45
522.142	54
522.404	51
522.666	51
522.928	53
523.19	48
523.453	59
523.715	54
523.977	53
524.239	56
524.501	58
524.763	47
525.025	51
525.287	48
525.549	62
525.811	55
526.073	55
526.335	45
526.597	48
526.859	56
527.121	51
527.383	50
527.645	60
527.907	53
528.169	54
528.431	46
528.693	51
528.955	57
529.217	55
529.479	56
529.741	53
530.003	51
530.264	58
530.526	49
530.788	50
531.05	55
531.312	63
531.574	63
531.835	59
532.097	61
532.359	54
532.621	60
532.883	64
533.144	60
533.406	69
533.668	64
533.93	59
534.191	69
534.453	79
534.715	73
534.976	80
535.238	97
535.5	77
535.761	77
536.023	77
536.285	69
536.546	78
536.808	69
537.069	69
537.331	70
537.593	69
537.854	68
538.116	75
538.377	77
538.639	68
538.9	75
539.162	74
539.423	65
539.685	71
539.946	70
540.208	78
540.469	83
540.731	79
540.992	76
541.254	69
541.515	75
541.776	82
542.038	84
542.299	82
542.56	77
542.822	83
543.083	87
543.344	95
543.606	85
543.867	94
544.128	90
544.39	91
544.651	91
544.912	92
545.174	99
545.435	92
545.696	89
545.957	96
546.218	104
546.48	108
546.741	95
547.002	101
547.263	120
547.524	116
547.785	116
548.047	119
548.308	112
548.569	120
548.83	117
549.091	126
549.352	127
549.613	132
549.874	151
550.135	150
550.396	160
550.657	157
550.918	166
551.179	196
551.44	195
551.701	215
551.962	282
552.223	465
552.484	2794
552.745	39401
553.006	959
553.267	386
553.528	268
553.788	241
554.049	202
554.31	203
554.571	189
554.832	195
555.093	180
555.353	196
555.614	189
555.875	203
556.136	193
556.396	201
556.657	211
556.918	210
557.179	209
557.439	221
557.7	235
557.961	223
558.221	219
558.482	228
558.743	226
559.003	233
559.264	239
559.525	255
559.785	246
560.046	251
560.306	268
560.567	281
560.827	278
561.088	284
561.348	299
561.609	284
561.869	293
562.13	293
562.39	316
562.651	309
562.911	332
563.172	323
563.432	344
563.692	353
563.953	367
564.213	368
564.474	381
564.734	375
564.994	386
565.255	396
565.515	385
565.775	382
566.035	415
566.296	418
566.556	430
566.816	429
567.076	442
567.337	439
567.597	459
567.857	433
568.117	454.98
568.377	465.876
568.637	472.944
568.898	483.125
569.158	491.08
569.418	491.157
569.678	525.357
569.938	524.956
570.198	534.897
570.458	548.565
570.718	579.729
570.978	579.933
571.238	607.513
571.498	632.978
571.758	675.958
572.018	681.953
572.278	721.882
572.538	749.172
572.798	793.368
573.058	845.502
573.312	889
573.573	960
573.834	1007
574.095	1089
574.356	1191
574.617	1320
574.878	1439
575.139	1528
575.4	1633
575.661	1722
575.922	1751
576.183	1767
576.444	1714
576.705	1654
576.965	1554
577.226	1511
577.487	1436
577.748	1361
578.009	1268
578.27	1217
578.531	1169
578.791	1128
579.052	1128
579.313	1091
579.574	1055
579.835	1104
580.095	1120
580.356	1078
580.617	1132
580.878	1116
581.138	1110
581.399	1158
581.66	1155
581.92	1150
582.181	1131
582.442	1138
582.703	1164
582.963	1171
583.224	1197
583.484	1254
583.745	1261
584.006	1272
584.266	1304
584.527	1327
584.787	1358
585.048	1379
585.308	1384
585.569	1451
585.83	1457
586.09	1478
586.351	1487
586.611	1469
586.872	1545
587.132	1488
587.392	1506
587.653	1565
587.913	1563
588.174	1585
588.434	1595
588.695	1575
588.955	1582
589.215	1660
589.476	1650
589.736	1655
589.996	1625
590.257	1636
590.517	1622
590.777	1640
591.038	1639
591.298	1601
591.558	1609
591.818	1611
592.079	1545
592.339	1567
592.599	1565
592.859	1559
593.12	1564
593.38	1496
593.64	1552
593.9	1571
594.16	1560
594.42	1595
594.68	1616
594.941	1621
595.201	1643
595.461	1600
595.721	1595
595.981	1667
596.241	1668
596.501	1711
596.761	1738
597.021	1735
597.281	1742
597.541	1703
597.801	1724
598.061	1741
598.321	1781
598.581	1775
598.841	1768
599.101	1768
599.361	1807
599.62	1769
599.88	1789
600.14	1822
600.4	1804
600.66	1801
600.92	1777
601.18	1798
601.439	1795
601.699	1777
601.959	1796
602.219	1796
602.478	1842
602.738	1859
602.998	1823
603.258	1837
603.517	1852
603.777	1852
604.037	1858
604.296	1850
604.556	1887
604.816	1884
605.075	1904
605.335	1875
605.594	1859
605.854	1912
606.114	1867
606.373	1866
606.633	1902
606.892	1879
607.152	1873
607.411	1930
607.671	1913
607.93	1955
608.19	1893
608.449	1925
608.709	1928
608.968	1938
609.228	1976
609.487	1996
609.746	1985
610.006	1998
610.265	2011
610.524	2035
610.784	2039
611.043	2032
611.302	2053
611.562	2036
611.821	2078
612.08	2074
612.339	2092
612.599	2122
612.858	2124
613.117	2152
613.376	2143
613.635	2171
613.895	2208
614.154	2212
614.413	2177
614.672	2265
614.931	2269
615.19	2258
615.449	2283
615.709	2285
615.968	2362
616.227	2323.25
616.486	2334.56
616.745	2378.61
617.004	2402.22
617.263	2412.49
617.522	2417.55
617.781	2409.55
618.04	2441.08
618.299	2445.42
618.557	2481.97
618.816	2491.79
619.075	2483.17
619.334	2503.38
619.593	2532.17
619.852	2563.87
620.111	2544.8
620.37	2548.5
620.628	2586.11
620.887	2576.41
621.146	2594.56
621.373	2606
621.633	2645
621.893	2641
622.153	2654
622.413	2614
622.673	2633
622.932	2643
623.192	2688
623.452	2684
623.712	2632
623.972	2658
624.232	2672
624.492	2696
624.751	2723
625.011	2741
625.271	2756
625.531	2757
625.791	2745
626.05	2762
626.31	2844
626.57	2773
626.83	2801
627.089	2859
627.349	2869
627.609	2826
627.868	2901
628.128	2904
628.388	2968
628.647	2921
628.907	2927
629.167	2953
629.426	2990
629.686	3025
629.945	3047
630.205	3089
630.465	3137
630.724	3131
630.984	3098
631.243	3107
631.503	3110
631.762	3185
632.022	3233
632.281	3246
632.541	3232
632.8	3302
633.06	3341
633.319	3421
633.579	3379
633.838	3460
634.097	3415
634.357	3469
634.616	3498
634.876	3629
635.135	3597
635.394	3704
635.654	3701
635.913	3839
636.172	3901
636.431	3973
636.691	4192
636.95	4403
637.209	4582
637.469	4779
637.728	5076
637.987	5291
638.246	5397
638.505	5459
638.765	5390
639.024	5361
639.283	5174
639.542	5067
639.801	4836
640.06	4851
640.319	4691
640.578	4614
640.838	4517
641.097	4558
641.356	4455
641.615	4513
641.874	4433
642.133	4444
642.392	4420
642.651	4441
642.91	4426
643.169	4449
643.428	4459
643.687	4503
643.946	4498
644.205	4547
644.463	4505
644.722	4574
644.981	4553
645.24	4586
645.499	4551
645.758	4579
646.017	4635
646.275	4557
646.534	4607
646.793	4615
647.052	4637
647.31	4700
647.569	4720
647.828	4689
648.087	4764
648.345	4848
648.604	4867
648.863	4914
649.121	4895
649.38	5005
649.639	4917
649.897	5044
650.156	5086
650.415	4989
650.673	5051
650.932	5130
651.19	5205
651.449	5261
651.707	5206
651.966	5276
652.224	5298
652.483	5344
652.741	5410
653	5409
653.258	5418
653.517	5517
653.775	5581
654.034	5640
654.292	5608
654.55	5704
654.809	5757
655.067	5850
655.326	5893
655.584	6000
655.842	5996
656.1	6061
656.359	6092
656.617	6247
656.875	6249
657.134	6295
657.392	6339
657.65	6437
657.908	6505
658.166	6526
658.425	6579
658.683	6630
658.941	6699
659.199	6699
659.457	6716
659.715	6771
659.973	6748
660.231	6766
660.49	6771
660.748	6774
661.006	6846
661.264	6776
661.522	6874
661.78	6887
662.038	6897
662.296	6853
662.554	6855
662.811	6833
663.069	6796
663.327	6904
663.585	6892
663.843	6853.14
664.101	6822.28
664.359	6914.95
664.617	6886.94
664.874	6852.53
665.132	6817.74
665.39	6902.66
665.648	6852.67
665.906	6823.63
666.163	6873.71
666.421	6851.61
666.679	6849.48
666.937	6836.66
667.194	6820.15
667.452	6846.18
667.71	6819.08
667.967	6897.91
668.225	6872.37
668.482	6874.36
668.74	6858.85
668.987	6838
669.245	6856
669.504	6828
669.763	6831
670.022	6852
670.281	6889
670.539	6818
670.798	6901
671.057	6838
671.316	6975
671.575	6861
671.833	6885
672.092	6885
672.351	6930
672.609	6947
672.868	6977
673.127	6963
673.385	7004
673.644	7077
673.903	7028
674.161	7066
674.42	7099
674.678	7175
674.937	7307
675.195	7203
675.454	7284
675.713	7283
675.971	7374
676.23	7349
676.488	7365
676.747	7334
677.005	7329
677.263	7380
677.522	7366
677.78	7306
678.039	7407
678.297	7382
678.556	7401
678.814	7336
679.072	7406
679.331	7413
679.589	7430
679.847	7417
680.106	7506
680.364	7462
680.622	7438
680.881	7499
681.139	7524
681.397	7636
681.656	7642
681.914	7677
682.172	7603
682.43	7690
682.688	7713
682.947	7643
683.205	7694
683.463	7769
683.721	7729
683.979	7688
684.237	7630
684.495	7660
684.754	7793
685.012	7624
685.27	7621
685.528	7528
685.786	7604
686.044	7621
686.302	7557
686.56	7595
686.818	7502
687.076	7552
687.334	7521
687.592	7498
687.85	7524
688.108	7436
688.366	7495
688.623	7539
688.881	7516
689.139	7475
689.397	7433
689.655	7445
689.913	7487
690.171	7452
690.428	7469
690.686	7384
690.944	7408
691.202	7401
691.459	7348
691.717	7299
691.975	7226
692.233	7306
692.49	7289
692.748	7249
693.006	7286
693.263	7211
693.521	7196
693.779	7220
694.036	7144
694.294	7175
694.552	7127
694.809	7205
695.067	7108
695.324	7141
695.582	7192
695.839	7079
696.097	7080
696.354	7049
696.612	7132
696.869	6977
697.127	7017
697.384	7020
697.642	6882
697.899	6887
698.156	6865
698.414	6893
698.671	6901
698.928	6777
699.186	6813
699.443	6774
699.7	6776
699.958	6712
700.215	6765
700.472	6747
700.73	6625
700.987	6702
701.244	6751
701.501	6717
701.758	6690
702.016	6648
702.273	6740
702.53	6703
702.787	6703
703.044	6777
703.301	6700
703.558	6648
703.816	6646
704.073	6646
704.33	6684
704.587	6568
704.844	6605
705.101	6597
705.358	6627
705.615	6513
705.872	6498
706.129	6492
706.386	6461
706.643	6389
706.899	6397
707.156	6408
707.413	6382
707.67	6328
707.927	6315
708.184	6317
708.441	6287
708.697	6283
708.954	6219
709.211	6243
709.468	6174
709.725	6295
709.981	6180
710.238	6194
710.495	6179
710.751	6099
711.008	6199
711.265	6183.28
711.521	6106.18
711.778	6068.78
712.035	6131.37
712.291	6040.63
712.548	6053.45
712.804	6005.36
713.061	5943.83
713.317	5938.62
713.574	5915.97
713.831	5852.52
714.087	5846.86
714.343	5801.07
714.6	5808.92
714.856	5741.72
715.113	5720.34
715.369	5689.93
715.626	5676.65
715.882	5626.61
716.138	5600.61
716.395	5607.89
716.639	5593
716.897	5581
717.155	5591
717.412	5592
717.67	5460
717.927	5505
718.185	5485
718.443	5444
718.7	5459
718.958	5430
719.215	5375
719.473	5339
719.73	5377
719.988	5338
720.245	5224
720.503	5248
720.76	5232
721.018	5291
721.275	5171
721.532	5105
721.79	5095
722.047	5092
722.305	5055
722.562	5016
722.819	5051
723.077	4928
723.334	4966
723.591	4888
723.849	4893
724.106	4905
724.363	4832
724.621	4821
724.878	4877
725.135	4858
725.392	4773
725.65	4750
725.907	4799
726.164	4728
726.421	4680
726.678	4635
726.935	4679
727.193	4636
727.45	4584
727.707	4594
727.964	4536
728.221	4522
728.478	4530
728.735	4451
728.992	4408
729.249	4358
729.506	4370
729.763	4354
730.02	4265
730.277	4254
730.534	4195
730.791	4155
731.048	4212
731.305	4137
731.562	4126
731.819	4151
732.076	4152
732.333	4068
732.589	4074
732.846	4013
733.103	4051
733.36	4023
733.617	4068
733.873	4011
734.13	3920
734.387	3998
734.644	3949
734.901	3976
735.157	3898
735.414	3837
735.671	3911
735.927	3901
736.184	3872
736.441	3835
736.697	3839
736.954	3853
737.211	3853
737.467	3870
737.724	3846
737.98	3817
738.237	3813
738.493	3833
738.75	3835
739.006	3786
739.263	3743
739.519	3744
739.776	3746
740.032	3777
740.289	3732
740.545	3713
740.802	3677
741.058	3673
741.314	3575
741.571	3641
741.827	3640
742.083	3568
742.34	3569
742.596	3550
742.852	3528
743.109	3543
743.365	3490
743.621	3474
743.878	3435
744.134	3493
744.39	3421
744.646	3486
744.902	3386
745.159	3405
745.415	3376
745.671	3381
745.927	3304
746.183	3366
746.439	3346
746.695	3285
746.951	3273
747.207	3318
747.463	3270
747.719	3269
747.975	3228
748.231	3255
748.487	3194
748.743	3244
748.999	3198
749.255	3214
749.511	3203
749.767	3166
750.023	3139
750.279	3064
750.535	3120
750.791	3091
751.046	3107
751.302	3063
751.558	3050
751.814	2977
752.07	3052
752.325	2972
752.581	2996
752.837	2920
753.092	2912
753.348	2938
753.604	2898
753.859	2896
754.115	2913
754.371	2807
754.626	2848
754.882	2811
755.138	2766
755.393	2817
755.649	2778
755.904	2803
756.16	2778
756.415	2787
756.671	2732
756.926	2722
757.182	2675
757.437	2696
757.693	2665
757.948	2706
758.203	2669
758.459	2638
758.714	2639.17
758.97	2637.97
759.225	2618.86
759.48	2572.35
759.736	2565.1
759.991	2556.2
760.246	2528.35
760.501	2522.81
760.757	2506.76
761.012	2515.36
761.267	2483.16
761.522	2471.04
761.777	2498.64
762.033	2476.57
762.288	2410.49
762.543	2408.03
762.798	2379.87
763.053	2385.92
763.308	2362.94
763.563	2376.28
763.78	2325
764.037	2339
764.293	2303
764.55	2340
764.806	2286
765.062	2301
765.319	2275
765.575	2266
765.831	2249
766.088	2235
766.344	2245
766.6	2234
766.857	2211
767.113	2170
767.369	2187
767.625	2165
767.882	2106
768.138	2112
768.394	2135
768.65	2095
768.906	2069
769.163	2059
769.419	2072
769.675	2092
769.931	2044
770.187	2060
770.443	1982
770.699	1983
770.955	1959
771.211	1930
771.467	1936
771.723	1940
771.979	1912
772.235	1915
772.491	1903
772.747	1904
773.003	1860
773.259	1854
773.515	1870
773.771	1825
774.027	1817
774.283	1813
774.539	1808
774.795	1784
775.05	1776
775.306	1735
775.562	1730
775.818	1746
776.074	1694
776.329	1717
776.585	1699
776.841	1724
777.097	1657
777.352	1650
777.608	1687
777.864	1646
778.12	1625
778.375	1620
778.631	1607
778.886	1593
779.142	1605
779.398	1580
779.653	1561
779.909	1560
780.164	1529
780.42	1564
780.675	1502
780.931	1537
781.187	1486
781.442	1507
781.698	1461
781.953	1482
782.208	1466
782.464	1457
782.719	1460
782.975	1424
783.23	1476
783.485	1436
783.741	1369
783.996	1405
784.252	1383
784.507	1339
784.762	1351
785.017	1367
785.273	1324
785.528	1337
785.783	1334
786.038	1321
786.294	1291
786.549	1301
786.804	1263
787.059	1270
787.314	1241
787.57	1245
787.825	1232
788.08	1210
788.335	1234
788.59	1217
788.845	1199
789.1	1208
789.355	1214
789.61	1194
789.865	1174
790.12	1175
790.375	1161
790.63	1150
790.885	1141
791.14	1100
791.395	1139
791.65	1096
791.905	1112
792.16	1110
792.414	1111
792.669	1075
792.924	1086
793.179	1071
793.434	1062
793.689	1070
793.943	1033
794.198	1009
794.453	1030
794.708	1034
794.962	1025
795.217	1016
795.472	1007
795.726	975
795.981	993
796.236	958
796.49	975
796.745	961
796.999	978
797.254	955
797.508	948
797.763	936
798.018	941
798.272	932
798.526	910
798.781	901
799.035	895
799.29	906
799.544	906
799.799	915
800.053	868
800.307	885
800.562	879
800.816	881
801.07	859
801.325	851
801.579	851
801.833	826
802.088	843
802.342	813
802.596	814
802.85	812
803.105	825
803.359	801
803.613	774
803.867	771
804.121	789
804.375	774
804.63	774
804.884	768
805.138	752
805.392	725
805.646	749.326
805.9	751.034
806.154	748.25
806.408	739.397
806.662	730.673
806.916	732.327
807.17	711.447
807.424	712.751
807.678	691.055
807.931	693.908
808.185	711.379
808.439	702.29
808.693	664.573
808.947	693.767
809.201	669.792
809.454	668.836
809.708	661.778
809.962	661.733
810.216	669.205
810.469	676.227
810.678	644
810.933	675
811.188	633
811.443	626
811.699	649
811.954	625
812.209	619
812.464	618
812.719	627
812.974	601
813.229	591
813.484	572
813.739	598
813.994	589
814.249	583
814.504	567
814.759	595
815.014	575
815.268	584
815.523	563
815.778	551
816.033	560
816.288	572
816.543	551
816.798	549
817.052	544
817.307	541
817.562	538
817.817	531
818.071	538
818.326	526
818.581	542
818.836	509
819.09	524
819.345	518
819.6	506
819.854	523
820.109	513
820.364	509
820.618	496
820.873	479
821.127	493
821.382	471
821.637	474
821.891	486
822.146	472
822.4	471
822.655	451
822.909	474
823.164	466
823.418	466
823.672	454
823.927	438
824.181	460
824.436	460
824.69	438
824.944	444
825.199	448
825.453	443
825.707	430
825.962	416
826.216	427
826.47	428
826.725	415
826.979	425
827.233	413
827.487	417
827.741	429
827.996	400
828.25	412
828.504	411
828.758	413
829.012	400
829.266	395
829.52	416
829.774	410
830.029	379
830.283	381
830.537	384
830.791	376
831.045	388
831.299	367
831.553	388
831.807	382
832.061	350
832.315	369
832.568	380
832.822	371
833.076	376
833.33	359
833.584	357
833.838	348
834.092	345
834.345	348
834.599	347
834.853	340
835.107	337
835.36	365
835.614	340
835.868	346
836.122	356
836.375	338
836.629	334
836.883	338
837.136	331
837.39	339
837.643	327
837.897	341
838.151	329
838.404	338
838.658	319
838.911	321
839.165	324
839.418	314
839.672	322
839.925	329
840.179	322
840.432	298
840.686	321
840.939	309
841.192	307
841.446	308
841.699	292
841.952	293
842.206	287
842.459	292
842.712	289
842.966	309
843.219	293
843.472	295
843.725	295
843.979	283
844.232	283
844.485	279
844.738	293
844.991	277
845.244	273
845.497	271
845.75	267
846.004	278
846.257	281
846.51	259
846.763	270
847.016	272
847.269	277
847.522	272
847.775	262
848.028	253
848.281	258
848.534	265
848.786	261
849.039	274
849.292	274
849.545	257
849.798	242
850.051	250
850.303	250
850.556	230
850.809	251
851.062	241
851.314	242
851.567	239
851.82	249
852.073	245
852.325	244.037
852.578	246.341
852.831	243.693
853.083	232.294
853.336	239.966
853.588	240.518
853.841	223.042
854.093	226.699
854.346	232.269
854.598	227.527
854.851	223.145
855.103	219.901
855.356	225.62
855.608	218.671
855.861	225.773
856.113	214.911
856.366	222.847
856.618	215.373
856.87	215.452
857.123	211.672
857.352	224
857.606	203
857.859	218
858.113	208
858.367	205
858.621	209
858.875	201
859.128	207
859.382	214
859.636	206
859.889	202
860.143	199
860.397	197
860.65	206
860.904	201
861.158	198
861.411	202
861.665	199
861.918	186
862.172	198
862.425	195
862.679	191
862.932	197
863.186	201
863.439	175
863.693	205
863.946	186
864.2	193
864.453	185
864.707	191
864.96	181
865.213	189
865.467	182
865.72	194
865.973	184
866.227	185
866.48	175
866.733	176
866.987	177
867.24	164
867.493	168
867.746	170
867.999	180
868.253	176
868.506	171
868.759	181
869.012	177
869.265	169
869.518	172
869.771	161
870.025	176
870.278	171
870.531	154
870.784	148
871.037	163
871.29	160
871.543	164
871.796	158
872.049	164
872.302	153
872.555	162
872.808	145
873.06	147
873.313	158
873.566	150
873.819	164
874.072	149
874.325	160
874.578	158
874.83	156
875.083	152
875.336	148
875.589	153
875.841	159
876.094	144
876.347	153
876.6	136
876.852	150
877.105	148
877.358	152
877.61	144
877.863	148
878.115	140
878.368	137
878.621	141
878.873	136
879.126	135
879.378	146
879.631	143
879.883	134
880.136	139
880.388	144
880.641	132
880.893	136
881.145	141
881.398	139
881.65	130
881.902	129
882.155	130
882.407	139
882.659	140
882.912	124
883.164	125
883.416	127
883.669	129
883.921	128
884.173	126
884.425	134
884.677	129
884.93	115
885.182	125
885.434	130
885.686	124
885.938	116
886.19	124
886.442	126
886.694	127
886.946	111
887.198	111
887.45	117
887.702	116
887.954	115
888.206	110
888.458	113
888.71	120
888.962	110
889.214	106
889.466	118
889.718	106
889.969	109
890.221	100
890.473	113
890.725	117
890.977	117
891.228	106
891.48	115
891.732	120
891.983	114
892.235	107
892.487	111
892.738	108
892.99	121
893.242	96
893.493	110
893.745	107
893.996	101
894.248	103
894.5	103
894.751	93
895.003	98
895.254	92
895.505	101
895.757	106
896.008	103
896.26	92
896.511	87
896.763	101
897.014	99
897.265	97
897.517	107
897.768	93
898.019	95
898.27	89
898.522	95
898.773	99
899.024	97
899.275	95
899.527	88
899.778	89
899.979	99