File: PL_M6_280424_01.txt
#Acq. time (s)=	3
#Accumulations=	2
#Range (nm)=	520...900
#Windows=	8
#Auto scanning=	Off
#Autofocus=	Off
#AutoExposure=	Off
#Spike filter=	Off
#Delay time (s)=	0
#Binning=	1
#Readout mode=	Signal
#DeNoise=	Off
#ICS correction=	Off
#Dark correction=	Off
#Inst. Process=	Off
#Detector temperature (°C)=	-59.98
#Instrument=	LabRAM HR Evol
#Detector=	Syncerity OE
#Objective=	x50_VIS
#Grating=	600 (500nm)
#ND Filter=	25%
#Laser=	514nm_Edge
#Hole=	199.981
#Range=	Visible
#StageXY=	Marzhauser
#StageZ=	Marzhauser
#X (µm)=	-9058.7
#Y (µm)=	-5026.8
#Z (µm)=	-261.6
#Full time(mm:ss)=	1:32
#Project=
#Sample=
#Site=
#Title=	PL_M6_280424
#Remark=
#Date=	06.05.2024 16:47
#Acquired=	06.05.2024 16:47:03
520.044	47
520.306	44
520.569	53
520.831	46
521.093	50
521.355	47
521.617	43
521.88	55
522.142	41
522.404	47
522.666	55
522.928	49
523.19	49
523.453	55
523.715	52
523.977	46
524.239	48
524.501	47
524.763	49
525.025	38
525.287	44
525.549	47
525.811	52
526.073	43
526.335	41
526.597	49
526.859	49
527.121	47
527.383	48
527.645	48
527.907	52
528.169	50
528.431	43
528.693	47
528.955	48
529.217	48
529.479	46
529.741	53
530.003	49
530.264	52
530.526	44
530.788	51
531.05	55
531.312	51
531.574	54
531.835	47
532.097	56
532.359	54
532.621	55
532.883	53
533.144	52
533.406	60
533.668	57
533.93	57
534.191	61
534.453	68
534.715	66
534.976	77
535.238	88
535.5	92
535.761	90
536.023	74
536.285	74
536.546	70
536.808	62
537.069	59
537.331	64
537.593	69
537.854	64
538.116	58
538.377	68
538.639	65
538.9	63
539.162	62
539.423	66
539.685	69
539.946	65
540.208	64
540.469	66
540.731	72
540.992	67
541.254	68
541.515	68
541.776	75
542.038	72
542.299	72
542.56	60
542.822	74
543.083	79
543.344	71
543.606	79
543.867	80
544.128	82
544.39	79
544.651	82
544.912	89
545.174	88
545.435	83
545.696	89
545.957	89
546.218	87
546.48	92
546.741	84
547.002	94
547.263	106
547.524	94
547.785	99
548.047	104
548.308	115
548.569	103
548.83	100
549.091	106
549.352	114
549.613	119
549.874	120
550.135	115
550.396	127
550.657	133
550.918	137
551.179	149
551.44	172
551.701	173
551.962	226
552.223	370
552.484	2253
552.745	29167
553.006	814
553.267	282
553.528	207
553.788	193
554.049	175
554.31	170
554.571	160
554.832	158
555.093	156
555.353	171
555.614	162
555.875	155
556.136	162
556.396	167
556.657	176
556.918	178
557.179	176
557.439	187
557.7	184
557.961	180
558.221	176
558.482	196
558.743	193
559.003	192
559.264	197
559.525	212
559.785	203
560.046	211
560.306	219
560.567	218
560.827	224
561.088	229
561.348	236
561.609	223
561.869	234
562.13	246
562.39	247
562.651	237
562.911	262
563.172	270
563.432	277
563.692	297
563.953	325
564.213	344
564.474	318
564.734	310
564.994	317
565.255	322
565.515	320
565.775	322
566.035	346
566.296	317
566.556	337
566.816	340
567.076	342
567.337	360
567.597	367
567.857	358
568.117	366.975
568.377	375.346
568.637	390.903
568.898	386.361
569.158	372.914
569.418	382.508
569.678	397.118
569.938	409.446
570.198	429.734
570.458	444.36
570.718	446.691
570.978	455.34
571.238	474.853
571.498	491.658
571.758	515.619
572.018	536.5
572.278	560.985
572.538	580.546
572.798	593.89
573.058	644.369
573.312	674
573.573	754
573.834	801
574.095	856
574.356	910
574.617	976
574.878	1054
575.139	1174
575.4	1224
575.661	1317
575.922	1339
576.183	1381
576.444	1333
576.705	1303
576.965	1232
577.226	1192
577.487	1148
577.748	1077
578.009	1028
578.27	981
578.531	951
578.791	903
579.052	912
579.313	887
579.574	880
579.835	906
580.095	890
580.356	893
580.617	895
580.878	849
581.138	861
581.399	887
581.66	891
581.92	909
582.181	888
582.442	932
582.703	927
582.963	940
583.224	940
583.484	960
583.745	968
584.006	991
584.266	1034
584.527	1053
584.787	1020
585.048	1092
585.308	1098
585.569	1099
585.83	1119
586.09	1127
586.351	1149
586.611	1161
586.872	1186
587.132	1185
587.392	1195
587.653	1229
587.913	1215
588.174	1256
588.434	1220
588.695	1237
588.955	1261
589.215	1301
589.476	1314
589.736	1291
589.996	1286
590.257	1298
590.517	1316
590.777	1275
591.038	1272
591.298	1292
591.558	1243
591.818	1277
592.079	1246
592.339	1225
592.599	1257
592.859	1228
593.12	1224
593.38	1222
593.64	1205
593.9	1257
594.16	1225
594.42	1278
594.68	1239
594.941	1250
595.201	1256
595.461	1284
595.721	1299
595.981	1282
596.241	1328
596.501	1341
596.761	1393
597.021	1365
597.281	1356
597.541	1394
597.801	1410
598.061	1403
598.321	1429
598.581	1415
598.841	1417
599.101	1395
599.361	1426
599.62	1461
599.88	1423
600.14	1424
600.4	1415
600.66	1413
600.92	1418
601.18	1431
601.439	1417
601.699	1400
601.959	1422
602.219	1438
602.478	1409
602.738	1429
602.998	1449
603.258	1466
603.517	1453
603.777	1496
604.037	1463
604.296	1467
604.556	1496
604.816	1491
605.075	1488
605.335	1527
605.594	1482
605.854	1480
606.114	1471
606.373	1532
606.633	1489
606.892	1479
607.152	1496
607.411	1490
607.671	1521
607.93	1526
608.19	1525
608.449	1524
608.709	1573
608.968	1563
609.228	1494
609.487	1543
609.746	1585
610.006	1565
610.265	1572
610.524	1590
610.784	1593
611.043	1616
611.302	1655
611.562	1654
611.821	1674
612.08	1673
612.339	1659
612.599	1681
612.858	1645
613.117	1692
613.376	1696
613.635	1728
613.895	1757
614.154	1749
614.413	1758
614.672	1775
614.931	1783
615.19	1777
615.449	1792
615.709	1785
615.968	1841
616.227	1879.8
616.486	1827.16
616.745	1855.06
617.004	1838.71
617.263	1928.03
617.522	1876.36
617.781	1918.72
618.04	1923.69
618.299	1932.77
618.557	1935.95
618.816	1961.46
619.075	1919.39
619.334	1953.88
619.593	1968.66
619.852	1966.28
620.111	1974.16
620.37	1986.17
620.628	2010.57
620.887	2009.49
621.146	2015.11
621.373	2026
621.633	2054
621.893	2103
622.153	2135
622.413	2154
622.673	2262
622.932	2359
623.192	2305
623.452	2310
623.712	2165
623.972	2209
624.232	2131
624.492	2168
624.751	2155
625.011	2167
625.271	2122
625.531	2115
625.791	2136
626.05	2093
626.31	2143
626.57	2202
626.83	2178
627.089	2165
627.349	2177
627.609	2171
627.868	2212
628.128	2229
628.388	2205
628.647	2171
628.907	2246
629.167	2248
629.426	2238
629.686	2279
629.945	2272
630.205	2286
630.465	2318
630.724	2352
630.984	2365
631.243	2364
631.503	2367
631.762	2403
632.022	2404
632.281	2397
632.541	2480
632.8	2459
633.06	2449
633.319	2519
633.579	2501
633.838	2572
634.097	2554
634.357	2553
634.616	2616
634.876	2632
635.135	2628
635.394	2665
635.654	2736
635.913	2775
636.172	2856
636.431	2887
636.691	2939
636.95	3093
637.209	3130
637.469	3355
637.728	3484
637.987	3627
638.246	3741
638.505	3842
638.765	3949
639.024	3893
639.283	3869
639.542	3730
639.801	3672
640.06	3516
640.319	3424
640.578	3324
640.838	3307
641.097	3304
641.356	3237
641.615	3238
641.874	3194
642.133	3221
642.392	3208
642.651	3219
642.91	3156
643.169	3243
643.428	3172
643.687	3271
643.946	3189
644.205	3289
644.463	3238
644.722	3305
644.981	3285
645.24	3271
645.499	3335
645.758	3259
646.017	3345
646.275	3274
646.534	3332
646.793	3399
647.052	3363
647.31	3426
647.569	3377
647.828	3371
648.087	3405
648.345	3391
648.604	3427
648.863	3438
649.121	3497
649.38	3535
649.639	3582
649.897	3543
650.156	3577
650.415	3624
650.673	3636
650.932	3672
651.19	3651
651.449	3661
651.707	3720
651.966	3803
652.224	3747
652.483	3780
652.741	3775
653	3791
653.258	3911
653.517	3941
653.775	3910
654.034	3852
654.292	3928
654.55	3986
654.809	4046
655.067	4127
655.326	4109
655.584	4189
655.842	4225
656.1	4255
656.359	4354
656.617	4308
656.875	4384
657.134	4351
657.392	4450
657.65	4522
657.908	4536
658.166	4536
658.425	4577
658.683	4575
658.941	4633
659.199	4610
659.457	4712
659.715	4616
659.973	4677
660.231	4709
660.49	4702
660.748	4758
661.006	4696
661.264	4739
661.522	4727
661.78	4689
662.038	4732
662.296	4772
662.554	4744
662.811	4802
663.069	4700
663.327	4749
663.585	4819
663.843	4764.96
664.101	4734.57
664.359	4766.27
664.617	4766.76
664.874	4787.79
665.132	4757.43
665.39	4728.98
665.648	4696.51
665.906	4769.47
666.163	4724.86
666.421	4758.91
666.679	4752.91
666.937	4749.88
667.194	4740.04
667.452	4768.68
667.71	4733.48
667.967	4736.48
668.225	4697.55
668.482	4753.76
668.74	4690.25
668.987	4744
669.245	4742
669.504	4656
669.763	4739
670.022	4679
670.281	4688
670.539	4738
670.798	4713
671.057	4739
671.316	4741
671.575	4751
671.833	4727
672.092	4735
672.351	4736
672.609	4747
672.868	4717
673.127	4788
673.385	4862
673.644	4823
673.903	4796
674.161	4945
674.42	4898
674.678	4884
674.937	4920
675.195	4894
675.454	4951
675.713	4979
675.971	5024
676.23	4945
676.488	4996
676.747	5059
677.005	5049
677.263	5066
677.522	5088
677.78	5064
678.039	5032
678.297	4986
678.556	5026
678.814	5016
679.072	5028
679.331	5044
679.589	5047
679.847	5097
680.106	5126
680.364	5164
680.622	5077
680.881	5179
681.139	5187
681.397	5200
681.656	5184
681.914	5217
682.172	5166
682.43	5209
682.688	5314
682.947	5203
683.205	5218
683.463	5241
683.721	5277
683.979	5214
684.237	5263
684.495	5268
684.754	5229
685.012	5181
685.27	5282
685.528	5231
685.786	5215
686.044	5205
686.302	5157
686.56	5108
686.818	5153
687.076	5207
687.334	5124
687.592	5167
687.85	5138
688.108	5181
688.366	5071
688.623	5171
688.881	5149
689.139	5149
689.397	5076
689.655	5164
689.913	5130
690.171	5099
690.428	5115
690.686	4976
690.944	5057
691.202	5049
691.459	4997
691.717	4973
691.975	5028
692.233	4920
692.49	5010
692.748	4934
693.006	4971
693.263	4956
693.521	4898
693.779	4956
694.036	4896
694.294	4861
694.552	4884
694.809	4918
695.067	4855
695.324	4861
695.582	4841
695.839	4841
696.097	4825
696.354	4794
696.612	4823
696.869	4807
697.127	4757
697.384	4752
697.642	4695
697.899	4669
698.156	4715
698.414	4621
698.671	4674
698.928	4630
699.186	4630
699.443	4611
699.7	4561
699.958	4585
700.215	4593
700.472	4595
700.73	4525
700.987	4505
701.244	4545
701.501	4500
701.758	4520
702.016	4562
702.273	4571
702.53	4591
702.787	4490
703.044	4637
703.301	4583
703.558	4549
703.816	4560
704.073	4575
704.33	4527
704.587	4522
704.844	4470
705.101	4503
705.358	4451
705.615	4403
705.872	4422
706.129	4401
706.386	4388
706.643	4388
706.899	4300
707.156	4339
707.413	4312
707.67	4319
707.927	4332
708.184	4316
708.441	4225
708.697	4267
708.954	4308
709.211	4228
709.468	4172
709.725	4186
709.981	4182
710.238	4194
710.495	4205
710.751	4199
711.008	4156
711.265	4153.62
711.521	4183.78
711.778	4103.38
712.035	4112.96
712.291	4142.48
712.548	4088.92
712.804	4063.71
713.061	4085.47
713.317	4036.5
713.574	4023.39
713.831	4023.92
714.087	3993.87
714.343	3956.57
714.6	3909.83
714.856	3919.5
715.113	3890.89
715.369	3873.38
715.626	3869.22
715.882	3845.76
716.138	3849.35
716.395	3827.44
716.639	3827
716.897	3791
717.155	3742
717.412	3765
717.67	3713
717.927	3715
718.185	3726
718.443	3734
718.7	3661
718.958	3702
719.215	3654
719.473	3607
719.73	3653
719.988	3583
720.245	3572
720.503	3523
720.76	3549
721.018	3533
721.275	3489
721.532	3527
721.79	3474
722.047	3460
722.305	3434
722.562	3387
722.819	3467
723.077	3340
723.334	3357
723.591	3362
723.849	3319
724.106	3308
724.363	3290
724.621	3285
724.878	3248
725.135	3259
725.392	3291
725.65	3251
725.907	3156
726.164	3216
726.421	3209
726.678	3173
726.935	3180
727.193	3170
727.45	3125
727.707	3067
727.964	3132
728.221	3101
728.478	3091
728.735	3012
728.992	3004
729.249	3020
729.506	2991
729.763	2915
730.02	2913
730.277	2904
730.534	2901
730.791	2857
731.048	2897
731.305	2873
731.562	2831
731.819	2821
732.076	2830
732.333	2771
732.589	2791
732.846	2794
733.103	2820
733.36	2762
733.617	2788
733.873	2702
734.13	2739
734.387	2752
734.644	2716
734.901	2745
735.157	2722
735.414	2669
735.671	2699
735.927	2690
736.184	2683
736.441	2691
736.697	2671
736.954	2665
737.211	2673
737.467	2694
737.724	2677
737.98	2667
738.237	2695
738.493	2723
738.75	2718
739.006	2646
739.263	2611
739.519	2659
739.776	2632
740.032	2591
740.289	2575
740.545	2535
740.802	2533
741.058	2532
741.314	2528
741.571	2550
741.827	2520
742.083	2536
742.34	2489
742.596	2462
742.852	2487
743.109	2426
743.365	2389
743.621	2445
743.878	2391
744.134	2373
744.39	2386
744.646	2372
744.902	2350
745.159	2359
745.415	2288
745.671	2345
745.927	2330
746.183	2299
746.439	2302
746.695	2249
746.951	2263
747.207	2256
747.463	2287
747.719	2246
747.975	2269
748.231	2239
748.487	2239
748.743	2220
748.999	2232
749.255	2227
749.511	2175
749.767	2175
750.023	2171
750.279	2166
750.535	2115
750.791	2145
751.046	2113
751.302	2155
751.558	2132
751.814	2124
752.07	2117
752.325	2061
752.581	2108
752.837	2039
753.092	2034
753.348	2032
753.604	2016
753.859	2024
754.115	1971
754.371	1981
754.626	1948
754.882	1985
755.138	1985
755.393	1974
755.649	1884
755.904	1907
756.16	1944
756.415	1892
756.671	1881
756.926	1889
757.182	1881
757.437	1886
757.693	1874
757.948	1798
758.203	1840
758.459	1811
758.714	1840.24
758.97	1826.88
759.225	1814.09
759.48	1790.96
759.736	1796.27
759.991	1773.09
760.246	1765.92
760.501	1736.49
760.757	1736.87
761.012	1736.1
761.267	1711.13
761.522	1724.1
761.777	1724.65
762.033	1699.05
762.288	1686.3
762.543	1649.55
762.798	1657.11
763.053	1635.48
763.308	1636.24
763.563	1664.82
763.78	1662
764.037	1616
764.293	1609
764.55	1611
764.806	1583
765.062	1586
765.319	1560
765.575	1546
765.831	1541
766.088	1548
766.344	1538
766.6	1528
766.857	1514
767.113	1537
767.369	1509
767.625	1504
767.882	1471
768.138	1471
768.394	1463
768.65	1451
768.906	1435
769.163	1415
769.419	1434
769.675	1386
769.931	1402
770.187	1352
770.443	1361
770.699	1425
770.955	1381
771.211	1363
771.467	1340
771.723	1306
771.979	1325
772.235	1320
772.491	1307
772.747	1304
773.003	1282
773.259	1301
773.515	1292
773.771	1283
774.027	1288
774.283	1262
774.539	1220
774.795	1231
775.05	1220
775.306	1229
775.562	1204
775.818	1198
776.074	1187
776.329	1168
776.585	1171
776.841	1166
777.097	1164
777.352	1160
777.608	1160
777.864	1133
778.12	1119
778.375	1100
778.631	1144
778.886	1113
779.142	1100
779.398	1088
779.653	1099
779.909	1071
780.164	1061
780.42	1077
780.675	1060
780.931	1060
781.187	1077
781.442	1033
781.698	1036
781.953	1022
782.208	1027
782.464	1020
782.719	981
782.975	983
783.23	1000
783.485	995
783.741	980
783.996	959
784.252	960
784.507	949
784.762	960
785.017	928
785.273	967
785.528	948
785.783	922
786.038	904
786.294	893
786.549	905
786.804	902
787.059	874
787.314	865
787.57	877
787.825	885
788.08	870
788.335	863
788.59	858
788.845	840
789.1	844
789.355	803
789.61	834
789.865	829
790.12	809
790.375	825
790.63	808
790.885	835
791.14	811
791.395	781
791.65	798
791.905	778
792.16	761
792.414	762
792.669	777
792.924	731
793.179	751
793.434	739
793.689	735
793.943	741
794.198	724
794.453	735
794.708	711
794.962	716
795.217	705
795.472	701
795.726	695
795.981	691
796.236	685
796.49	664
796.745	687
796.999	660
797.254	678
797.508	659
797.763	641
798.018	648
798.272	631
798.526	659
798.781	645
799.035	642
799.29	636
799.544	614
799.799	615
800.053	606
800.307	621
800.562	608
800.816	602
801.07	582
801.325	586
801.579	573
801.833	593
802.088	578
802.342	570
802.596	567
802.85	572
803.105	571
803.359	560
803.613	575
803.867	560
804.121	547
804.375	541
804.63	553
804.884	552
805.138	521
805.392	523
805.646	542.681
805.9	533.963
806.154	531.678
806.408	523.239
806.662	516.93
806.916	517.18
807.17	506.056
807.424	502.607
807.678	487.12
807.931	501.693
808.185	491.257
808.439	487.42
808.693	485.123
808.947	478.855
809.201	477.928
809.454	479.092
809.708	464.121
809.962	458.61
810.216	459.841
810.469	472.671
810.678	472
810.933	453
811.188	464
811.443	448
811.699	436
811.954	452
812.209	435
812.464	421
812.719	450
812.974	431
813.229	444
813.484	429
813.739	428
813.994	427
814.249	412
814.504	411
814.759	431
815.014	408
815.268	406
815.523	397
815.778	395
816.033	411
816.288	388
816.543	397
816.798	384
817.052	388
817.307	392
817.562	366
817.817	379
818.071	377
818.326	392
818.581	369
818.836	377
819.09	367
819.345	370
819.6	375
819.854	353
820.109	372
820.364	356
820.618	339
820.873	348
821.127	352
821.382	350
821.637	345
821.891	333
822.146	333
822.4	355
822.655	338
822.909	335
823.164	345
823.418	333
823.672	320
823.927	334
824.181	325
824.436	315
824.69	312
824.944	295
825.199	311
825.453	312
825.707	320
825.962	302
826.216	314
826.47	303
826.725	300
826.979	304
827.233	309
827.487	295
827.741	299
827.996	292
828.25	292
828.504	294
828.758	282
829.012	285
829.266	278
829.52	287
829.774	269
830.029	275
830.283	282
830.537	288
830.791	269
831.045	265
831.299	278
831.553	289
831.807	276
832.061	261
832.315	271
832.568	265
832.822	263
833.076	253
833.33	257
833.584	261
833.838	252
834.092	248
834.345	266
834.599	251
834.853	253
835.107	251
835.36	246
835.614	259
835.868	249
836.122	247
836.375	243
836.629	231
836.883	246
837.136	241
837.39	244
837.643	255
837.897	242
838.151	241
838.404	221
838.658	229
838.911	243
839.165	240
839.418	234
839.672	224
839.925	237
840.179	220
840.432	227
840.686	234
840.939	239
841.192	210
841.446	218
841.699	220
841.952	232
842.206	203
842.459	214
842.712	227
842.966	220
843.219	212
843.472	204
843.725	216
843.979	216
844.232	200
844.485	213
844.738	191
844.991	204
845.244	215
845.497	199
845.75	207
846.004	197
846.257	208
846.51	186
846.763	198
847.016	194
847.269	192
847.522	199
847.775	199
848.028	191
848.281	178
848.534	177
848.786	187
849.039	183
849.292	188
849.545	206
849.798	189
850.051	180
850.303	171
850.556	177
850.809	184
851.062	182
851.314	170
851.567	173
851.82	189
852.073	182
852.325	183
852.578	174.439
852.831	169.819
853.083	173.855
853.336	175.675
853.588	162.964
853.841	174.398
854.093	169.645
854.346	176.225
854.598	166.987
854.851	175.204
855.103	157.987
855.356	160.753
855.608	163.491
855.861	161.119
856.113	165.771
856.366	163.639
856.618	163.452
856.87	156.427
857.123	161.208
857.352	158
857.606	158
857.859	155
858.113	151
858.367	158
858.621	160
858.875	152
859.128	143
859.382	159
859.636	152
859.889	165
860.143	143
860.397	148
860.65	153
860.904	152
861.158	143
861.411	149
861.665	143
861.918	154
862.172	140
862.425	146
862.679	143
862.932	147
863.186	151
863.439	134
863.693	143
863.946	148
864.2	134
864.453	146
864.707	144
864.96	131
865.213	148
865.467	145
865.72	144
865.973	153
866.227	133
866.48	137
866.733	144
866.987	139
867.24	140
867.493	128
867.746	132
867.999	135
868.253	134
868.506	122
868.759	129
869.012	129
869.265	127
869.518	126
869.771	126
870.025	123
870.278	130
870.531	122
870.784	118
871.037	128
871.29	134
871.543	118
871.796	118
872.049	122
872.302	131
872.555	117
872.808	131
873.06	131
873.313	108
873.566	112
873.819	119
874.072	110
874.325	119
874.578	113
874.83	115
875.083	112
875.336	121
875.589	113
875.841	115
876.094	118
876.347	105
876.6	108
876.852	110
877.105	116
877.358	115
877.61	113
877.863	110
878.115	108
878.368	115
878.621	109
878.873	114
879.126	107
879.378	102
879.631	111
879.883	101
880.136	107
880.388	105
880.641	123
880.893	105
881.145	107
881.398	98
881.65	105
881.902	112
882.155	111
882.407	97
882.659	104
882.912	93
883.164	101
883.416	100
883.669	92
883.921	94
884.173	106
884.425	103
884.677	108
884.93	100
885.182	99
885.434	93
885.686	96
885.938	96
886.19	101
886.442	102
886.694	91
886.946	90
887.198	96
887.45	99
887.702	94
887.954	86
888.206	95
888.458	98
888.71	96
888.962	95
889.214	87
889.466	88
889.718	86
889.969	92
890.221	80
890.473	87
890.725	97
890.977	81
891.228	97
891.48	91
891.732	94
891.983	89
892.235	87
892.487	82
892.738	85
892.99	93
893.242	79
893.493	82
893.745	85
893.996	84
894.248	81
894.5	85
894.751	88
895.003	90
895.254	71
895.505	74
895.757	80
896.008	76
896.26	78
896.511	80
896.763	74
897.014	88
897.265	74
897.517	78
897.768	78
898.019	76
898.27	70
898.522	74
898.773	72
899.024	81
899.275	78
899.527	75
899.778	74
899.979	69