File: PL_M1_180324_01.txt
#Acq. time (s)=	3
#Accumulations=	2
#Range (nm)=	520...900
#Windows=	8
#Auto scanning=	Off
#Autofocus=	Off
#AutoExposure=	Off
#Spike filter=	Multiple accum.
#Delay time (s)=	0
#Binning=	1
#Readout mode=	Signal
#DeNoise=	Off
#ICS correction=	Off
#Dark correction=	Off
#Inst. Process=	Off
#Detector temperature (°C)=	-59.98
#Instrument=	LabRAM HR Evol
#Detector=	Syncerity OE
#Objective=	x50_VIS
#Grating=	600 (500nm)
#ND Filter=	25%
#Laser=	514nm_Edge
#Hole=	199.981
#Range=	Auto
#StageXY=	Marzhauser
#StageZ=	Marzhauser
#X (µm)=	-371.6
#Y (µm)=	4464.7
#Z (µm)=	-6.4
#Full time(mm:ss)=	1:28
#Project=
#Sample=
#Site=
#Title=	PL_M1_180324
#Remark=
#Date=	28.03.2024 09:08
#Acquired=	28.03.2024 09:08:16
520.044	50
520.306	42
520.569	52
520.831	44
521.093	52
521.355	50
521.617	50
521.88	42
522.142	56
522.404	48
522.666	54
522.928	44
523.19	54
523.453	54
523.715	42
523.977	60
524.239	52
524.501	46
524.763	42
525.025	54
525.287	56
525.549	52
525.811	40
526.073	52
526.335	40
526.597	48
526.859	50
527.121	48
527.383	54
527.645	44
527.907	32
528.169	48
528.431	50
528.693	50
528.955	48
529.217	44
529.479	54
529.741	56
530.003	44
530.264	50
530.526	48
530.788	54
531.05	44
531.312	48
531.574	60
531.835	56
532.097	46
532.359	52
532.621	56
532.883	62
533.144	56
533.406	54
533.668	60
533.93	68
534.191	68
534.453	74
534.715	96
534.976	94
535.238	100
535.5	80
535.761	80
536.023	72
536.285	74
536.546	60
536.808	68
537.069	76
537.331	62
537.593	72
537.854	70
538.116	80
538.377	72
538.639	70
538.9	76
539.162	80
539.423	70
539.685	72
539.946	72
540.208	72
540.469	70
540.731	76
540.992	78
541.254	92
541.515	82
541.776	78
542.038	96
542.299	88
542.56	82
542.822	80
543.083	90
543.344	86
543.606	90
543.867	92
544.128	102
544.39	112
544.651	92
544.912	94
545.174	104
545.435	116
545.696	110
545.957	114
546.218	106
546.48	116
546.741	126
547.002	110
547.263	132
547.524	134
547.785	130
548.047	130
548.308	130
548.569	132
548.83	140
549.091	136
549.352	136
549.613	144
549.874	158
550.135	152
550.396	170
550.657	172
550.918	178
551.179	186
551.44	202
551.701	236
551.962	286
552.223	424
552.484	3248
552.745	23948
553.006	710
553.267	348
553.528	266
553.788	244
554.049	222
554.31	214
554.571	228
554.832	198
555.093	226
555.353	214
555.614	228
555.875	226
556.136	226
556.396	234
556.657	254
556.918	262
557.179	270
557.439	266
557.7	274
557.961	270
558.221	262
558.482	278
558.743	306
559.003	280
559.264	294
559.525	262
559.785	294
560.046	318
560.306	306
560.567	292
560.827	316
561.088	332
561.348	330
561.609	330
561.869	364
562.13	376
562.39	356
562.651	376
562.911	398
563.172	386
563.432	430
563.692	442
563.953	464
564.213	480
564.474	480
564.734	470
564.994	444
565.255	472
565.515	460
565.775	456
566.035	458
566.296	492
566.556	490
566.816	512
567.076	496
567.337	522
567.597	548
567.857	552
568.117	553.97
568.377	550.888
568.637	569.376
568.898	561.571
569.158	581.439
569.418	611.76
569.678	609.713
569.938	633.246
570.198	649.073
570.458	679.71
570.718	688.407
570.978	706.762
571.238	746.902
571.498	770.962
571.758	813.133
572.018	843.445
572.278	898.09
572.538	958.811
572.798	996.94
573.058	1039.51
573.312	1080
573.573	1212
573.834	1290
574.095	1368
574.356	1540
574.617	1684
574.878	1788
575.139	1940
575.4	2000
575.661	2092
575.922	2106
576.183	2086
576.444	2024
576.705	1944
576.965	1844
577.226	1706
577.487	1586
577.748	1524
578.009	1468
578.27	1420
578.531	1378
578.791	1380
579.052	1358
579.313	1334
579.574	1312
579.835	1360
580.095	1330
580.356	1322
580.617	1320
580.878	1356
581.138	1350
581.399	1318
581.66	1378
581.92	1402
582.181	1404
582.442	1424
582.703	1394
582.963	1440
583.224	1454
583.484	1498
583.745	1516
584.006	1536
584.266	1538
584.527	1600
584.787	1626
585.048	1662
585.308	1650
585.569	1698
585.83	1710
586.09	1746
586.351	1782
586.611	1798
586.872	1804
587.132	1852
587.392	1844
587.653	1824
587.913	1834
588.174	1838
588.434	1870
588.695	1884
588.955	1924
589.215	1928
589.476	1892
589.736	1950
589.996	1910
590.257	1916
590.517	1974
590.777	1912
591.038	1870
591.298	1908
591.558	1900
591.818	1848
592.079	1870
592.339	1888
592.599	1898
592.859	1854
593.12	1842
593.38	1862
593.64	1820
593.9	1882
594.16	1842
594.42	1898
594.68	1878
594.941	1932
595.201	1914
595.461	1984
595.721	1972
595.981	1990
596.241	1968
596.501	2070
596.761	2134
597.021	2120
597.281	2092
597.541	2136
597.801	2152
598.061	2156
598.321	2122
598.581	2116
598.841	2126
599.101	2154
599.361	2144
599.62	2160
599.88	2168
600.14	2188
600.4	2194
600.66	2174
600.92	2182
601.18	2174
601.439	2182
601.699	2192
601.959	2212
602.219	2228
602.478	2238
602.738	2228
602.998	2262
603.258	2232
603.517	2256
603.777	2276
604.037	2244
604.296	2226
604.556	2286
604.816	2254
605.075	2286
605.335	2288
605.594	2276
605.854	2252
606.114	2266
606.373	2294
606.633	2258
606.892	2260
607.152	2164
607.411	2278
607.671	2292
607.93	2326
608.19	2354
608.449	2378
608.709	2380
608.968	2320
609.228	2396
609.487	2430
609.746	2426
610.006	2412
610.265	2450
610.524	2474
610.784	2470
611.043	2446
611.302	2476
611.562	2498
611.821	2548
612.08	2540
612.339	2610
612.599	2540
612.858	2584
613.117	2584
613.376	2620
613.635	2660
613.895	2654
614.154	2736
614.413	2722
614.672	2692
614.931	2722
615.19	2798
615.449	2802
615.709	2818
615.968	2808
616.227	2866.16
616.486	2893.78
616.745	2901.85
617.004	2907.41
617.263	2922.87
617.522	2921.96
617.781	2950.47
618.04	2934.44
618.299	2968.27
618.557	3036.88
618.816	2989.95
619.075	3004.02
619.334	3055.07
619.593	3045
619.852	3046.86
620.111	3044.67
620.37	3073.16
620.628	3118.32
620.887	3114.17
621.146	3115.37
621.373	3110
621.633	3094
621.893	3040
622.153	3082
622.413	3144
622.673	3158
622.932	3174
623.192	3208
623.452	3190
623.712	3172
623.972	3162
624.232	3220
624.492	3306
624.751	3240
625.011	3260
625.271	3302
625.531	3318
625.791	3268
626.05	3286
626.31	3352
626.57	3372
626.83	3400
627.089	3416
627.349	3416
627.609	3422
627.868	3458
628.128	3472
628.388	3468
628.647	3512
628.907	3510
629.167	3502
629.426	3616
629.686	3622
629.945	3596
630.205	3636
630.465	3654
630.724	3638
630.984	3684
631.243	3724
631.503	3772
631.762	3836
632.022	3826
632.281	3832
632.541	3836
632.8	3924
633.06	3934
633.319	3984
633.579	4000
633.838	4056
634.097	4086
634.357	4130
634.616	4268
634.876	4250
635.135	4304
635.394	4428
635.654	4446
635.913	4552
636.172	4794
636.431	4924
636.691	5118
636.95	5454
637.209	5696
637.469	5946
637.728	6056
637.987	6320
638.246	6270
638.505	6206
638.765	6082
639.024	5940
639.283	5768
639.542	5616
639.801	5476
640.06	5452
640.319	5324
640.578	5182
640.838	5228
641.097	5152
641.356	5074
641.615	5092
641.874	5134
642.133	5082
642.392	5174
642.651	5188
642.91	5160
643.169	5150
643.428	5142
643.687	5234
643.946	5206
644.205	5308
644.463	5206
644.722	5320
644.981	5318
645.24	5330
645.499	5352
645.758	5412
646.017	5324
646.275	5422
646.534	5404
646.793	5482
647.052	5482
647.31	5566
647.569	5520
647.828	5520
648.087	5530
648.345	5538
648.604	5600
648.863	5648
649.121	5732
649.38	5620
649.639	5752
649.897	5864
650.156	5830
650.415	5922
650.673	5950
650.932	5966
651.19	6052
651.449	6094
651.707	6066
651.966	6170
652.224	6212
652.483	6228
652.741	6312
653	6334
653.258	6346
653.517	6412
653.775	6450
654.034	6506
654.292	6568
654.55	6666
654.809	6784
655.067	6838
655.326	6856
655.584	6972
655.842	7016
656.1	7116
656.359	7208
656.617	7158
656.875	7354
657.134	7434
657.392	7422
657.65	7358
657.908	7562
658.166	7524
658.425	7596
658.683	7754
658.941	7682
659.199	7750
659.457	7772
659.715	7762
659.973	7674
660.231	7836
660.49	7720
660.748	7774
661.006	7760
661.264	7738
661.522	7780
661.78	7736
662.038	7770
662.296	7790
662.554	7790
662.811	7800
663.069	7834
663.327	7838
663.585	7754
663.843	7794.56
664.101	7793.75
664.359	7850.15
664.617	7820.56
664.874	7799.84
665.132	7868.27
665.39	7814.55
665.648	7827.04
665.906	7837.21
666.163	7823.61
666.421	7855.04
666.679	7822.88
666.937	7800.51
667.194	7845.24
667.452	7879.01
667.71	7823.93
667.967	7870.1
668.225	7788.91
668.482	7867.57
668.74	7865.15
668.987	7910
669.245	7846
669.504	7784
669.763	7754
670.022	7814
670.281	7832
670.539	7930
670.798	7884
671.057	7882
671.316	7842
671.575	7840
671.833	7982
672.092	7852
672.351	7912
672.609	8010
672.868	7910
673.127	7972
673.385	7986
673.644	8004
673.903	8094
674.161	8170
674.42	8164
674.678	8182
674.937	8232
675.195	8242
675.454	8260
675.713	8228
675.971	8360
676.23	8396
676.488	8334
676.747	8464
677.005	8392
677.263	8462
677.522	8408
677.78	8410
678.039	8470
678.297	8468
678.556	8524
678.814	8404
679.072	8496
679.331	8394
679.589	8456
679.847	8452
680.106	8506
680.364	8536
680.622	8602
680.881	8558
681.139	8630
681.397	8636
681.656	8732
681.914	8658
682.172	8814
682.43	8754
682.688	8716
682.947	8732
683.205	8760
683.463	8726
683.721	8754
683.979	8704
684.237	8678
684.495	8702
684.754	8670
685.012	8708
685.27	8732
685.528	8566
685.786	8566
686.044	8636
686.302	8536
686.56	8622
686.818	8526
687.076	8544
687.334	8498
687.592	8544
687.85	8570
688.108	8504
688.366	8454
688.623	8512
688.881	8528
689.139	8538
689.397	8568
689.655	8442
689.913	8388
690.171	8394
690.428	8432
690.686	8364
690.944	8356
691.202	8372
691.459	8344
691.717	8292
691.975	8150
692.233	8254
692.49	8162
692.748	8222
693.006	8160
693.263	8218
693.521	8156
693.779	8076
694.036	8166
694.294	8046
694.552	8044
694.809	8042
695.067	8028
695.324	8148
695.582	8050
695.839	8000
696.097	8000
696.354	7950
696.612	8072
696.869	7864
697.127	7860
697.384	7822
697.642	7854
697.899	7752
698.156	7772
698.414	7846
698.671	7798
698.928	7722
699.186	7712
699.443	7658
699.7	7624
699.958	7600
700.215	7596
700.472	7582
700.73	7586
700.987	7516
701.244	7600
701.501	7620
701.758	7552
702.016	7552
702.273	7610
702.53	7632
702.787	7624
703.044	7618
703.301	7560
703.558	7594
703.816	7588
704.073	7562
704.33	7540
704.587	7478
704.844	7448
705.101	7504
705.358	7388
705.615	7428
705.872	7382
706.129	7326
706.386	7258
706.643	7296
706.899	7282
707.156	7188
707.413	7124
707.67	7096
707.927	7178
708.184	7078
708.441	7106
708.697	7042
708.954	7134
709.211	6970
709.468	6972
709.725	6944
709.981	7032
710.238	6984
710.495	6990
710.751	6932
711.008	6862
711.265	6845.21
711.521	6861.55
711.778	6804.53
712.035	6835.88
712.291	6875.68
712.548	6767.86
712.804	6779.44
713.061	6762.14
713.317	6693.69
713.574	6608.98
713.831	6653.15
714.087	6535.94
714.343	6513.58
714.6	6548.17
714.856	6462.73
715.113	6481.19
715.369	6403.1
715.626	6401.05
715.882	6360.98
716.138	6291.16
716.395	6342.57
716.639	6330
716.897	6368
717.155	6240
717.412	6250
717.67	6228
717.927	6134
718.185	6170
718.443	6158
718.7	6166
718.958	6130
719.215	6046
719.473	6058
719.73	6020
719.988	5970
720.245	5918
720.503	5908
720.76	5936
721.018	5804
721.275	5772
721.532	5784
721.79	5704
722.047	5718
722.305	5664
722.562	5652
722.819	5562
723.077	5598
723.334	5608
723.591	5508
723.849	5492
724.106	5456
724.363	5494
724.621	5376
724.878	5386
725.135	5346
725.392	5436
725.65	5320
725.907	5394
726.164	5334
726.421	5326
726.678	5242
726.935	5216
727.193	5250
727.45	5054
727.707	5162
727.964	5090
728.221	5136
728.478	5012
728.735	4980
728.992	4902
729.249	4892
729.506	4938
729.763	4832
730.02	4902
730.277	4724
730.534	4754
730.791	4698
731.048	4780
731.305	4692
731.562	4714
731.819	4644
732.076	4630
732.333	4632
732.589	4634
732.846	4594
733.103	4614
733.36	4574
733.617	4542
733.873	4574
734.13	4468
734.387	4530
734.644	4618
734.901	4504
735.157	4468
735.414	4448
735.671	4462
735.927	4462
736.184	4502
736.441	4488
736.697	4488
736.954	4412
737.211	4514
737.467	4454
737.724	4494
737.98	4520
738.237	4500
738.493	4446
738.75	4452
739.006	4442
739.263	4380
739.519	4322
739.776	4364
740.032	4366
740.289	4286
740.545	4262
740.802	4156
741.058	4204
741.314	4208
741.571	4162
741.827	4104
742.083	4046
742.34	4146
742.596	4058
742.852	4034
743.109	3962
743.365	4020
743.621	3984
743.878	3926
744.134	3976
744.39	3860
744.646	3820
744.902	3834
745.159	3778
745.415	3782
745.671	3786
745.927	3804
746.183	3814
746.439	3782
746.695	3780
746.951	3724
747.207	3730
747.463	3628
747.719	3650
747.975	3668
748.231	3636
748.487	3618
748.743	3672
748.999	3584
749.255	3550
749.511	3574
749.767	3598
750.023	3510
750.279	3584
750.535	3496
750.791	3506
751.046	3514
751.302	3474
751.558	3378
751.814	3392
752.07	3410
752.325	3392
752.581	3358
752.837	3350
753.092	3284
753.348	3302
753.604	3296
753.859	3232
754.115	3242
754.371	3258
754.626	3274
754.882	3214
755.138	3208
755.393	3194
755.649	3198
755.904	3138
756.16	3102
756.415	3134
756.671	3118
756.926	3068
757.182	3022
757.437	3036
757.693	3018
757.948	3004
758.203	2982
758.459	2990
758.714	2957.76
758.97	2992.29
759.225	2919.4
759.48	2929.57
759.736	2894.2
759.991	2891.18
760.246	2865.42
760.501	2807.74
760.757	2852.55
761.012	2842.59
761.267	2765.18
761.522	2794.12
761.777	2821.23
762.033	2757.65
762.288	2714.98
762.543	2718.58
762.798	2732.08
763.053	2685.91
763.308	2711.99
763.563	2639.01
763.78	2664
764.037	2654
764.293	2650
764.55	2604
764.806	2570
765.062	2610
765.319	2568
765.575	2582
765.831	2524
766.088	2514
766.344	2452
766.6	2484
766.857	2454
767.113	2470
767.369	2466
767.625	2428
767.882	2396
768.138	2334
768.394	2426
768.65	2348
768.906	2320
769.163	2304
769.419	2290
769.675	2328
769.931	2296
770.187	2272
770.443	2276
770.699	2206
770.955	2218
771.211	2220
771.467	2202
771.723	2128
771.979	2176
772.235	2164
772.491	2158
772.747	2142
773.003	2072
773.259	2088
773.515	2062
773.771	2038
774.027	2054
774.283	2034
774.539	2056
774.795	2002
775.05	2004
775.306	1948
775.562	1968
775.818	1926
776.074	1926
776.329	1940
776.585	1934
776.841	1872
777.097	1870
777.352	1860
777.608	1880
777.864	1864
778.12	1836
778.375	1844
778.631	1744
778.886	1744
779.142	1772
779.398	1742
779.653	1752
779.909	1746
780.164	1700
780.42	1754
780.675	1714
780.931	1700
781.187	1704
781.442	1672
781.698	1664
781.953	1632
782.208	1654
782.464	1610
782.719	1626
782.975	1594
783.23	1616
783.485	1570
783.741	1588
783.996	1520
784.252	1554
784.507	1502
784.762	1522
785.017	1546
785.273	1466
785.528	1480
785.783	1500
786.038	1486
786.294	1476
786.549	1450
786.804	1446
787.059	1396
787.314	1400
787.57	1404
787.825	1384
788.08	1362
788.335	1340
788.59	1348
788.845	1372
789.1	1302
789.355	1320
789.61	1350
789.865	1292
790.12	1266
790.375	1270
790.63	1294
790.885	1284
791.14	1284
791.395	1238
791.65	1252
791.905	1244
792.16	1236
792.414	1220
792.669	1222
792.924	1200
793.179	1218
793.434	1190
793.689	1196
793.943	1180
794.198	1148
794.453	1154
794.708	1146
794.962	1118
795.217	1102
795.472	1092
795.726	1112
795.981	1110
796.236	1078
796.49	1078
796.745	1076
796.999	1086
797.254	1108
797.508	1062
797.763	1034
798.018	1032
798.272	1026
798.526	1034
798.781	1048
799.035	996
799.29	1008
799.544	1010
799.799	1000
800.053	974
800.307	968
800.562	966
800.816	964
801.07	946
801.325	934
801.579	922
801.833	940
802.088	920
802.342	938
802.596	890
802.85	898
803.105	918
803.359	886
803.613	878
803.867	888
804.121	852
804.375	860
804.63	884
804.884	850
805.138	824
805.392	822
805.646	854.768
805.9	808.136
806.154	810.067
806.408	820.831
806.662	820.766
806.916	793.138
807.17	792.777
807.424	791.245
807.678	798.056
807.931	778.462
808.185	765.438
808.439	763.512
808.693	785.091
808.947	754.32
809.201	730.642
809.454	750.907
809.708	755.59
809.962	700.327
810.216	745.559
810.469	726.851
810.678	696
810.933	712
811.188	712
811.443	720
811.699	702
811.954	716
812.209	668
812.464	704
812.719	664
812.974	652
813.229	684
813.484	678
813.739	676
813.994	664
814.249	664
814.504	642
814.759	650
815.014	660
815.268	640
815.523	644
815.778	620
816.033	626
816.288	620
816.543	592
816.798	608
817.052	628
817.307	586
817.562	604
817.817	586
818.071	570
818.326	596
818.581	572
818.836	536
819.09	602
819.345	562
819.6	560
819.854	568
820.109	544
820.364	542
820.618	528
820.873	550
821.127	544
821.382	550
821.637	518
821.891	520
822.146	528
822.4	530
822.655	524
822.909	510
823.164	498
823.418	498
823.672	506
823.927	482
824.181	492
824.436	498
824.69	480
824.944	506
825.199	516
825.453	458
825.707	468
825.962	472
826.216	500
826.47	476
826.725	478
826.979	452
827.233	484
827.487	454
827.741	458
827.996	456
828.25	456
828.504	456
828.758	430
829.012	448
829.266	446
829.52	458
829.774	426
830.029	440
830.283	444
830.537	432
830.791	408
831.045	410
831.299	422
831.553	404
831.807	438
832.061	416
832.315	414
832.568	420
832.822	390
833.076	394
833.33	412
833.584	410
833.838	392
834.092	406
834.345	400
834.599	384
834.853	386
835.107	382
835.36	362
835.614	402
835.868	374
836.122	362
836.375	378
836.629	368
836.883	368
837.136	378
837.39	364
837.643	368
837.897	352
838.151	352
838.404	346
838.658	360
838.911	354
839.165	334
839.418	352
839.672	338
839.925	344
840.179	316
840.432	322
840.686	330
840.939	330
841.192	318
841.446	324
841.699	324
841.952	324
842.206	322
842.459	316
842.712	322
842.966	308
843.219	326
843.472	320
843.725	310
843.979	312
844.232	290
844.485	304
844.738	318
844.991	308
845.244	316
845.497	300
845.75	310
846.004	290
846.257	316
846.51	298
846.763	292
847.016	278
847.269	292
847.522	264
847.775	304
848.028	284
848.281	270
848.534	252
848.786	284
849.039	276
849.292	292
849.545	290
849.798	294
850.051	266
850.303	272
850.556	280
850.809	260
851.062	260
851.314	258
851.567	266
851.82	274
852.073	258
852.325	254.05
852.578	259.994
852.831	254.467
853.083	250.41
853.336	249.402
853.588	244.348
853.841	254.81
854.093	250.566
854.346	235.478
854.598	238.581
854.851	250.302
855.103	238.872
855.356	237.543
855.608	230.174
855.861	231.714
856.113	232.28
856.366	222.847
856.618	229.693
856.87	227.619
857.123	219.165
857.352	216
857.606	224
857.859	234
858.113	240
858.367	222
858.621	220
858.875	232
859.128	212
859.382	226
859.636	220
859.889	216
860.143	220
860.397	212
860.65	206
860.904	216
861.158	216
861.411	216
861.665	210
861.918	216
862.172	204
862.425	206
862.679	214
862.932	204
863.186	202
863.439	206
863.693	210
863.946	208
864.2	202
864.453	194
864.707	188
864.96	200
865.213	196
865.467	212
865.72	186
865.973	196
866.227	188
866.48	190
866.733	186
866.987	186
867.24	198
867.493	190
867.746	166
867.999	172
868.253	194
868.506	180
868.759	176
869.012	178
869.265	178
869.518	176
869.771	176
870.025	182
870.278	184
870.531	168
870.784	156
871.037	170
871.29	176
871.543	180
871.796	164
872.049	180
872.302	178
872.555	168
872.808	156
873.06	180
873.313	174
873.566	168
873.819	164
874.072	164
874.325	166
874.578	172
874.83	172
875.083	160
875.336	154
875.589	158
875.841	164
876.094	166
876.347	166
876.6	158
876.852	152
877.105	154
877.358	150
877.61	144
877.863	144
878.115	148
878.368	162
878.621	146
878.873	138
879.126	148
879.378	146
879.631	148
879.883	144
880.136	156
880.388	150
880.641	150
880.893	138
881.145	146
881.398	140
881.65	152
881.902	128
882.155	140
882.407	134
882.659	140
882.912	126
883.164	138
883.416	136
883.669	126
883.921	128
884.173	128
884.425	136
884.677	120
884.93	136
885.182	136
885.434	116
885.686	126
885.938	132
886.19	118
886.442	126
886.694	128
886.946	124
887.198	130
887.45	116
887.702	124
887.954	120
888.206	124
888.458	112
888.71	114
888.962	120
889.214	114
889.466	116
889.718	114
889.969	108
890.221	108
890.473	116
890.725	112
890.977	116
891.228	106
891.48	116
891.732	116
891.983	116
892.235	104
892.487	112
892.738	110
892.99	114
893.242	106
893.493	116
893.745	96
893.996	108
894.248	88
894.5	118
894.751	108
895.003	102
895.254	96
895.505	112
895.757	100
896.008	98
896.26	96
896.511	104
896.763	100
897.014	100
897.265	102
897.517	98
897.768	96
898.019	100
898.27	92
898.522	96
898.773	98
899.024	92
899.275	86
899.527	100
899.778	88
899.979	90