File: PL_M7_011123_01.txt
#Acq. time (s)=	5
#Accumulations=	2
#Range (nm)=	520...900
#Windows=	8
#Auto scanning=	Off
#Autofocus=	Off
#AutoExposure=	Off
#Spike filter=	Multiple accum.
#Delay time (s)=	0
#Binning=	1
#Readout mode=	Signal
#DeNoise=	Off
#ICS correction=	On
#Dark correction=	Off
#Inst. Process=	Off
#Detector temperature (°C)=	-59.98
#Instrument=	LabRAM HR Evol
#Detector=	Syncerity OE
#Objective=	x50_VIS
#Grating=	600 (500nm)
#ND Filter=	10%
#Laser=	514nm_Edge
#Hole=	199.981
#Range=	Auto
#StageXY=	Marzhauser
#StageZ=	Marzhauser
#X (µm)=	-601.1
#Y (µm)=	-1002.1
#Z (µm)=	-42.7
#Full time(mm:ss)=	2:04
#Project=
#Sample=
#Site=
#Title=	PL_M7_011123
#Remark=
#Date=	11.11.2023 11:51
#Acquired=	11.11.2023 11:51:00
520.044	41.4395
520.306	33.8871
520.569	39.0916
520.831	33.9056
521.093	44.7326
521.355	37.5356
521.617	33.7915
521.88	35.4493
522.142	35.4654
522.404	33.8709
522.666	35.7784
522.928	39.3855
523.19	40.8814
523.453	37.0706
523.715	31.6593
523.977	38.7377
524.239	40.7546
524.501	30.294
524.763	42.8882
525.025	35.6207
525.287	35.5165
525.549	35.516
525.811	37.305
526.073	33.9811
526.335	43.2162
526.597	34.3582
526.859	37.9586
527.121	34.2383
527.383	41.3997
527.645	35.9239
527.907	41.2931
528.169	43.2495
528.431	34.4513
528.693	38.3293
528.955	42.1256
529.217	36.5873
529.479	43.725
529.741	41.6701
530.003	39.7806
530.264	50.5631
530.526	39.8421
530.788	43.766
531.05	34.9131
531.312	40.5484
531.574	44.4401
531.835	38.9639
532.097	39.0839
532.359	44.7458
532.621	46.8179
532.883	39.3876
533.144	41.2423
533.406	46.8323
533.668	56.1926
533.93	52.2826
534.191	37.2067
534.453	48.1254
534.715	46.3093
534.976	46.4201
535.238	44.7172
535.5	52.2088
535.761	59.8658
536.023	48.8416
536.285	46.9523
536.546	56.1419
536.808	48.6089
537.069	50.195
537.331	46.2309
537.593	58.9398
537.854	53.2892
538.116	42.1484
538.377	47.7424
538.639	56.9768
538.9	58.8999
539.162	57.0578
539.423	44.0834
539.685	47.7264
539.946	53.1593
540.208	58.5583
540.469	54.9474
540.731	58.7783
540.992	67.9954
541.254	60.8161
541.515	49.834
541.776	51.6923
542.038	62.9172
542.299	68.2635
542.56	62.4688
542.822	66.0137
543.083	62.2017
543.344	63.985
543.606	58.6777
543.867	64.1007
544.128	69.6475
544.39	60.5921
544.651	68.0173
544.912	68.0208
545.174	64.2859
545.435	78.81
545.696	69.3642
545.957	69.2529
546.218	70.7851
546.48	74.2244
546.741	74.2005
547.002	74.3311
547.263	79.7681
547.524	77.9329
547.785	81.673
548.047	87.1434
548.308	72.6627
548.569	87.0311
548.83	85.1753
549.091	85.0844
549.352	104.529
549.613	97.1522
549.874	91.4292
550.135	102.084
550.396	96.3002
550.657	103.423
550.918	110.429
551.179	115.555
551.44	136.568
551.701	143.756
551.962	179.087
552.223	324.686
552.484	3658.06
552.745	7209.19
553.006	331.655
553.267	186.401
553.528	161.934
553.788	136.727
554.049	135.011
554.31	110.195
554.571	129.593
554.832	131.18
555.093	123.828
555.353	139.372
555.614	135.208
555.875	145.35
556.136	118.956
556.396	136.144
556.657	144.995
556.918	144.83
557.179	145.009
557.439	140.181
557.7	151.073
557.961	149.79
558.221	155.56
558.482	166.182
558.743	158.964
559.003	160.778
559.264	172.438
559.525	162.747
559.785	164.077
560.046	168.263
560.306	174.287
560.567	164.407
560.827	173.749
561.088	171.3
561.348	174.238
561.609	187.607
561.869	184.363
562.13	196.33
562.39	189.596
562.651	203.676
562.911	214.247
563.172	216.387
563.432	218.202
563.692	223.131
563.953	248.062
564.213	232.629
564.474	238.718
564.734	222.308
564.994	232.685
565.255	250.149
565.515	236.899
565.775	252.319
566.035	257.953
566.296	247.013
566.556	231.425
566.816	271.27
567.076	263.151
567.337	266.611
567.597	266.945
567.857	262.469
568.117	292.343
568.377	284.095
568.637	295.05
568.898	292.771
569.158	303.853
569.418	307.722
569.678	313.07
569.938	310.944
570.198	327.132
570.458	329.175
570.718	336.82
570.978	355.656
571.238	358.523
571.498	376.61
571.758	387.372
572.018	397.778
572.278	424.263
572.538	450.961
572.798	470.331
573.058	484.274
573.312	507.136
573.573	552.078
573.834	599.438
574.095	633.503
574.356	685.253
574.617	765.788
574.878	813.05
575.139	863.059
575.4	932.99
575.661	945.599
575.922	967.272
576.183	958.907
576.444	927.036
576.705	890.908
576.965	846.449
577.226	816.607
577.487	739.2
577.748	712.542
578.009	705.271
578.27	666.556
578.531	647.13
578.791	628.206
579.052	588.354
579.313	591.178
579.574	592.027
579.835	582.82
580.095	576.019
580.356	581.326
580.617	581.193
580.878	596.369
581.138	579.994
581.399	584.186
581.66	581.57
581.92	588.658
582.181	575.861
582.442	601.287
582.703	618.766
582.963	643.985
583.224	626.275
583.484	646.624
583.745	645.372
584.006	657.05
584.266	683.268
584.527	680.703
584.787	710.797
585.048	716.154
585.308	695.13
585.569	715.856
585.83	719.954
586.09	750.102
586.351	726.439
586.611	747.392
586.872	740.534
587.132	766.597
587.392	779.791
587.653	781.061
587.913	774.764
588.174	780.136
588.434	778.232
588.695	771.762
588.955	828.113
589.215	830.024
589.476	808.018
589.736	792.206
589.996	790.168
590.257	795.144
590.517	788.916
590.777	771.453
591.038	787.236
591.298	783.06
591.558	782.537
591.818	774.994
592.079	746.214
592.339	768.849
592.599	760.37
592.859	763.263
593.12	750.388
593.38	752.841
593.64	739.263
593.9	746.949
594.16	760.584
594.42	775.315
594.68	775.49
594.941	756.282
595.201	780.595
595.461	773.118
595.721	762.845
595.981	801.019
596.241	813.988
596.501	811.432
596.761	834.706
597.021	784.259
597.281	812.785
597.541	826.038
597.801	832.911
598.061	860.666
598.321	809.126
598.581	811.487
598.841	827.695
599.101	850.971
599.361	844.109
599.62	849.556
599.88	852.322
600.14	854.168
600.4	858.681
600.66	845.851
600.92	827.903
601.18	842.936
601.439	880.891
601.699	847.838
601.959	859.155
602.219	828.583
602.478	870.77
602.738	859.267
602.998	853.406
603.258	847.96
603.517	848.337
603.777	878.876
604.037	860.707
604.296	855.617
604.556	862.749
604.816	858.608
605.075	867.603
605.335	891.036
605.594	872.737
605.854	878.128
606.114	870.17
606.373	867.782
606.633	867.675
606.892	885.811
607.152	855.487
607.411	874.277
607.671	823.2
607.93	896.231
608.19	869.523
608.449	879.837
608.709	904.569
608.968	887.212
609.228	891.682
609.487	904.334
609.746	901.817
610.006	885.094
610.265	921.377
610.524	939.99
610.784	890.158
611.043	939.329
611.302	912.281
611.562	908.797
611.821	923.232
612.08	903.191
612.339	938.975
612.599	949.801
612.858	952.556
613.117	967.081
613.376	957.992
613.635	976.711
613.895	967.255
614.154	970.44
614.413	994.209
614.672	998.312
614.931	1003.86
615.19	1017.61
615.449	995.435
615.709	1015.69
615.968	1021.13
616.227	1020.27
616.486	1042.63
616.745	1028.5
617.004	1025.15
617.263	1022.18
617.522	1037.37
617.781	1031.16
618.04	1027.12
618.299	1050.58
618.557	1056
618.816	1071.84
619.075	1065.06
619.334	1072.64
619.593	1061.09
619.852	1067.12
620.111	1073.93
620.37	1067.09
620.628	1067.3
620.887	1073.61
621.146	1079.28
621.373	1078.04
621.633	1073.78
621.893	1088.43
622.153	1071.2
622.413	1091
622.673	1098.82
622.932	1075.69
623.192	1076.58
623.452	1065.96
623.712	1079
623.972	1113.83
624.232	1081.63
624.492	1107.78
624.751	1105.72
625.011	1106.87
625.271	1096.4
625.531	1132.41
625.791	1123.36
626.05	1130.52
626.31	1141.2
626.57	1127.18
626.83	1128.17
627.089	1153.15
627.349	1147.24
627.609	1162.86
627.868	1168.27
628.128	1169.02
628.388	1183.46
628.647	1156.89
628.907	1165.79
629.167	1191.68
629.426	1198.81
629.686	1176.62
629.945	1192.02
630.205	1214.16
630.465	1215.11
630.724	1223.92
630.984	1211.86
631.243	1230.88
631.503	1241.34
631.762	1249.49
632.022	1244.2
632.281	1258.78
632.541	1262.12
632.8	1305.66
633.06	1277.03
633.319	1322.61
633.579	1316.99
633.838	1336.42
634.097	1360.33
634.357	1346.38
634.616	1356.37
634.876	1394.14
635.135	1414.94
635.394	1417.58
635.654	1451.29
635.913	1500.43
636.172	1504.33
636.431	1585.09
636.691	1620.59
636.95	1664.95
637.209	1764.84
637.469	1839.16
637.728	1988.48
637.987	2009.96
638.246	2074.95
638.505	2110.63
638.765	2082.66
639.024	2031.24
639.283	1931.9
639.542	1900.52
639.801	1861.15
640.06	1822.21
640.319	1786.56
640.578	1757.31
640.838	1712.17
641.097	1710.88
641.356	1688.98
641.615	1701.77
641.874	1675.98
642.133	1686.37
642.392	1678.09
642.651	1695.23
642.91	1658.73
643.169	1667.84
643.428	1679.16
643.687	1694.12
643.946	1667.96
644.205	1683.83
644.463	1726.93
644.722	1693.97
644.981	1690.81
645.24	1724.81
645.499	1728.74
645.758	1738.64
646.017	1751.4
646.275	1730.74
646.534	1755.91
646.793	1766.12
647.052	1759.41
647.31	1774.02
647.569	1771.11
647.828	1764.56
648.087	1781.06
648.345	1779.84
648.604	1817.02
648.863	1818.51
649.121	1833.95
649.38	1802.69
649.639	1851.87
649.897	1843.43
650.156	1871.95
650.415	1911.36
650.673	1909.81
650.932	1904.46
651.19	1913.88
651.449	1934.16
651.707	1957.91
651.966	1970.85
652.224	1966.34
652.483	1985.79
652.741	1997.79
653	2021.18
653.258	2033.93
653.517	2032.25
653.775	2050.83
654.034	2094.1
654.292	2121.9
654.55	2109.54
654.809	2125.53
655.067	2126.44
655.326	2127.19
655.584	2195.18
655.842	2189.7
656.1	2206.7
656.359	2245.83
656.617	2286.18
656.875	2268.19
657.134	2316.15
657.392	2360.94
657.65	2347.68
657.908	2377
658.166	2373.43
658.425	2405.53
658.683	2446.01
658.941	2466.77
659.199	2454
659.457	2494.05
659.715	2512.74
659.973	2467.86
660.231	2458.82
660.49	2468.03
660.748	2460.65
661.006	2518.17
661.264	2507.02
661.522	2484.22
661.78	2434.78
662.038	2489.78
662.296	2413.64
662.554	2439.79
662.811	2447.93
663.069	2412.99
663.327	2442.6
663.585	2413.35
663.843	2391.7
664.101	2432.16
664.359	2428.55
664.617	2424.95
664.874	2421
665.132	2419.47
665.39	2432.36
665.648	2442.02
665.906	2441.37
666.163	2432.59
666.421	2413.31
666.679	2414.32
666.937	2434.97
667.194	2424.29
667.452	2417.33
667.71	2411.24
667.967	2438.6
668.225	2452.26
668.482	2439.05
668.74	2461.99
668.987	2432.87
669.245	2441.21
669.504	2479.19
669.763	2451.42
670.022	2446.47
670.281	2477.96
670.539	2452.64
670.798	2500.79
671.057	2431.54
671.316	2474.8
671.575	2463.08
671.833	2484.44
672.092	2464.21
672.351	2485.57
672.609	2461.64
672.868	2474
673.127	2481.44
673.385	2484.3
673.644	2494.36
673.903	2481.51
674.161	2498.48
674.42	2539.02
674.678	2499.74
674.937	2519.78
675.195	2562.61
675.454	2552.84
675.713	2563.1
675.971	2586.69
676.23	2599.1
676.488	2606.53
676.747	2606.12
677.005	2630.93
677.263	2627.05
677.522	2658.86
677.78	2624.83
678.039	2669.14
678.297	2620.02
678.556	2665.77
678.814	2624.9
679.072	2663.97
679.331	2642
679.589	2668.41
679.847	2638.02
680.106	2648.16
680.364	2673.66
680.622	2671.09
680.881	2699.39
681.139	2685.21
681.397	2677.35
681.656	2672.43
681.914	2707.78
682.172	2717.22
682.43	2706.41
682.688	2710.19
682.947	2704.78
683.205	2693.88
683.463	2686.71
683.721	2674.04
683.979	2716.53
684.237	2691.37
684.495	2678.16
684.754	2702.3
685.012	2707.46
685.27	2701.05
685.528	2647.18
685.786	2712.84
686.044	2691.48
686.302	2708.01
686.56	2679.66
686.818	2674.02
687.076	2634.57
687.334	2665.13
687.592	2681.98
687.85	2657.92
688.108	2627.7
688.366	2659.28
688.623	2643.39
688.881	2623.87
689.139	2630.48
689.397	2629.81
689.655	2658.89
689.913	2600.59
690.171	2635.69
690.428	2617.21
690.686	2614.8
690.944	2608.22
691.202	2598.91
691.459	2619.07
691.717	2628.72
691.975	2584.51
692.233	2616.7
692.49	2575.52
692.748	2590.22
693.006	2613.79
693.263	2571.01
693.521	2590.91
693.779	2560.77
694.036	2556.58
694.294	2594.97
694.552	2572.36
694.809	2584.72
695.067	2537.44
695.324	2526.94
695.582	2581.92
695.839	2526.41
696.097	2566.29
696.354	2552.11
696.612	2529.45
696.869	2542.88
697.127	2561.58
697.384	2535.7
697.642	2525.99
697.899	2539.5
698.156	2545.69
698.414	2522.05
698.671	2537.9
698.928	2510.72
699.186	2457.7
699.443	2473.99
699.7	2496.68
699.958	2463.35
700.215	2504.69
700.472	2477.51
700.73	2488.5
700.987	2469.2
701.244	2449.09
701.501	2486.79
701.758	2465.94
702.016	2456.16
702.273	2473.69
702.53	2455.58
702.787	2467.92
703.044	2469.56
703.301	2475.12
703.558	2486.38
703.816	2458.54
704.073	2485.17
704.33	2451.88
704.587	2492.6
704.844	2456.26
705.101	2471.62
705.358	2495.05
705.615	2471.28
705.872	2444.12
706.129	2432.93
706.386	2418.38
706.643	2455.63
706.899	2459.81
707.156	2430.42
707.413	2403.07
707.67	2423.31
707.927	2415.88
708.184	2398.01
708.441	2459.19
708.697	2352.94
708.954	2360.43
709.211	2347.26
709.468	2382.46
709.725	2412.84
709.981	2370.99
710.238	2393.91
710.495	2395.68
710.751	2376
711.008	2359.47
711.265	2376.97
711.521	2388.57
711.778	2365.71
712.035	2359.82
712.291	2389.62
712.548	2374.67
712.804	2383.19
713.061	2370.63
713.317	2355.42
713.574	2337.96
713.831	2323.97
714.087	2329.42
714.343	2327.87
714.6	2316.77
714.856	2307.11
715.113	2289.42
715.369	2281.26
715.626	2291.07
715.882	2255.69
716.138	2270.23
716.395	2291.03
716.639	2264.1
716.897	2252.41
717.155	2231.24
717.412	2228.59
717.67	2236.95
717.927	2245.71
718.185	2213.88
718.443	2238.65
718.7	2211.8
718.958	2199.09
719.215	2173.55
719.473	2186.3
719.73	2231.77
719.988	2207.47
720.245	2170.09
720.503	2169.36
720.76	2179.02
721.018	2160.08
721.275	2146.28
721.532	2181.33
721.79	2167.5
722.047	2109.74
722.305	2124.09
722.562	2142.29
722.819	2101.9
723.077	2082.19
723.334	2076.22
723.591	2115.49
723.849	2068.06
724.106	2092.52
724.363	2069.32
724.621	2062.25
724.878	2038.29
725.135	2032.23
725.392	2040.33
725.65	2007.34
725.907	2011.77
726.164	2037.79
726.421	2041.04
726.678	1987.6
726.935	1992.5
727.193	2006.91
727.45	1974.26
727.707	1983.64
727.964	1974.21
728.221	1954.7
728.478	1963.11
728.735	1996.21
728.992	1983.42
729.249	1921.23
729.506	1934.69
729.763	1902.38
730.02	1907.75
730.277	1928.32
730.534	1860.65
730.791	1941.71
731.048	1912.99
731.305	1882.94
731.562	1914.62
731.819	1893.14
732.076	1869.71
732.333	1865.44
732.589	1896.51
732.846	1854.87
733.103	1831.28
733.36	1838.3
733.617	1837.52
733.873	1848.26
734.13	1814.07
734.387	1851.57
734.644	1784.39
734.901	1814.29
735.157	1821.77
735.414	1795.83
735.671	1804.9
735.927	1809.95
736.184	1757.38
736.441	1778.24
736.697	1774.46
736.954	1789.51
737.211	1750.05
737.467	1782.93
737.724	1777.12
737.98	1739.19
738.237	1732.7
738.493	1741.63
738.75	1738.07
739.006	1718.35
739.263	1736.71
739.519	1711.99
739.776	1725.85
740.032	1702.94
740.289	1700.95
740.545	1693.38
740.802	1674.93
741.058	1675.05
741.314	1699.49
741.571	1635.99
741.827	1670.65
742.083	1676.94
742.34	1671.47
742.596	1665.92
742.852	1640.94
743.109	1632.82
743.365	1620.87
743.621	1608.74
743.878	1621.35
744.134	1629.1
744.39	1584.11
744.646	1613.61
744.902	1553.34
745.159	1612.82
745.415	1562.25
745.671	1558.6
745.927	1569.21
746.183	1551.95
746.439	1551.39
746.695	1551.44
746.951	1572.82
747.207	1536.34
747.463	1498.76
747.719	1537.06
747.975	1514.92
748.231	1490.07
748.487	1516.06
748.743	1521.31
748.999	1488.2
749.255	1458.68
749.511	1480.87
749.767	1488.08
750.023	1492.82
750.279	1435.23
750.535	1457.8
750.791	1461.43
751.046	1445.31
751.302	1432.84
751.558	1458.48
751.814	1437.13
752.07	1446.72
752.325	1453.51
752.581	1418.59
752.837	1427.32
753.092	1396.77
753.348	1415.24
753.604	1423.26
753.859	1407.6
754.115	1383.22
754.371	1371.17
754.626	1325.23
754.882	1337.41
755.138	1383.88
755.393	1334.42
755.649	1360.05
755.904	1358.84
756.16	1340.31
756.415	1349.34
756.671	1311.04
756.926	1342.61
757.182	1288.37
757.437	1332.74
757.693	1286.01
757.948	1309.68
758.203	1305.18
758.459	1279.48
758.714	1288.99
758.97	1297.9
759.225	1298.28
759.48	1266.99
759.736	1274.9
759.991	1272.09
760.246	1281.03
760.501	1239.52
760.757	1241.61
761.012	1214.89
761.267	1244.41
761.522	1242.92
761.777	1223.54
762.033	1199.9
762.288	1200
762.543	1203.62
762.798	1203.69
763.053	1192.75
763.308	1192.27
763.563	1183.54
763.78	1221.05
764.037	1170.25
764.293	1174.2
764.55	1184.97
764.806	1141.29
765.062	1169.63
765.319	1138.72
765.575	1149.53
765.831	1147.59
766.088	1122.14
766.344	1142.6
766.6	1133.5
766.857	1108.33
767.113	1113.97
767.369	1082.61
767.625	1103.26
767.882	1096.41
768.138	1089.85
768.394	1120.41
768.65	1083.34
768.906	1093.18
769.163	1079.42
769.419	1070.12
769.675	1063.42
769.931	1065.25
770.187	1035.48
770.443	1046.12
770.699	1053.04
770.955	1064.27
771.211	1044.81
771.467	1010.29
771.723	1018.96
771.979	1024.7
772.235	1019.94
772.491	1035.51
772.747	1013.18
773.003	1004.11
773.259	1006.39
773.515	992.397
773.771	989.345
774.027	985.182
774.283	999.154
774.539	994.294
774.795	993.932
775.05	971.897
775.306	997.408
775.562	967.18
775.818	988.066
776.074	919.039
776.329	941.938
776.585	924.963
776.841	924.707
777.097	917.26
777.352	933.371
777.608	902.293
777.864	931.002
778.12	895.374
778.375	913.794
778.631	913.26
778.886	904.946
779.142	901.957
779.398	887.254
779.653	889.081
779.909	878.322
780.164	881.363
780.42	874.877
780.675	881.697
780.931	860.85
781.187	881.178
781.442	848.81
781.698	857.135
781.953	865.73
782.208	853.82
782.464	855.013
782.719	836.385
782.975	839.954
783.23	817.833
783.485	820.321
783.741	813.43
783.996	792.155
784.252	822.291
784.507	793.422
784.762	812.154
785.017	814.614
785.273	784.422
785.528	810.588
785.783	802.653
786.038	786.057
786.294	771.639
786.549	760.519
786.804	794.508
787.059	771.708
787.314	759.636
787.57	771.552
787.825	769.012
788.08	764.467
788.335	729.337
788.59	728.757
788.845	734.169
789.1	739.48
789.355	741.741
789.61	742.481
789.865	726.728
790.12	719.182
790.375	711.449
790.63	716.42
790.885	706.219
791.14	706.42
791.395	685.402
791.65	707.068
791.905	686.587
792.16	665.196
792.414	673.008
792.669	691.844
792.924	671.748
793.179	683.814
793.434	674.41
793.689	643.533
793.943	665.068
794.198	652.346
794.453	643.524
794.708	654.814
794.962	667.157
795.217	680.269
795.472	648.341
795.726	641.126
795.981	628.042
796.236	655.624
796.49	639.138
796.745	628.324
796.999	606.37
797.254	628.576
797.508	609.322
797.763	624.976
798.018	616.499
798.272	624.999
798.526	611.29
798.781	598.901
799.035	604.138
799.29	616.417
799.544	589.662
799.799	603.705
800.053	582.527
800.307	600.857
800.562	576.584
800.816	562.961
801.07	572.56
801.325	591.346
801.579	568.999
801.833	552.403
802.088	551.225
802.342	558.511
802.596	544.081
802.85	560.616
803.105	575.321
803.359	517.006
803.613	531.059
803.867	561.305
804.121	547.05
804.375	547.964
804.63	546.675
804.884	542.739
805.138	523.672
805.392	510.744
805.646	546.274
805.9	511.673
806.154	514.354
806.408	517.978
806.662	496.869
806.916	509.53
807.17	517.114
807.424	492.061
807.678	503.67
807.931	522.692
808.185	506.671
808.439	503.466
808.693	495.039
808.947	468.956
809.201	507.661
809.454	487.172
809.708	486.329
809.962	484.817
810.216	478.932
810.469	485.907
810.678	477.821
810.933	448.718
811.188	481.796
811.443	452.351
811.699	462.623
811.954	452.035
812.209	475.751
812.464	460.026
812.719	444.58
812.974	428.063
813.229	436.481
813.484	441.716
813.739	452.086
813.994	453.466
814.249	451.744
814.504	453.745
814.759	427.034
815.014	432.411
815.268	420.925
815.523	440.664
815.778	426.193
816.033	411.457
816.288	448.989
816.543	432.675
816.798	404.307
817.052	434.465
817.307	415.446
817.562	406.944
817.817	391.004
818.071	408.008
818.326	396.595
818.581	414.348
818.836	386.081
819.09	404.022
819.345	414.38
819.6	395.792
819.854	382.569
820.109	407.915
820.364	373.369
820.618	391.814
820.873	387.341
821.127	370.977
821.382	396.224
821.637	394.283
821.891	357.441
822.146	370.704
822.4	376.102
822.655	375.009
822.909	358.209
823.164	378.627
823.418	340.518
823.672	353.552
823.927	376.258
824.181	379.044
824.436	346.701
824.69	380.212
824.944	357.596
825.199	358.072
825.453	348.461
825.707	351.661
825.962	343.93
826.216	359.349
826.47	328.527
826.725	346.338
826.979	341.653
827.233	334.489
827.487	332.386
827.741	311.522
827.996	320.112
828.25	318.531
828.504	318.271
828.758	336.991
829.012	319.309
829.266	352.86
829.52	304.18
829.774	340.614
830.029	307.778
830.283	336.653
830.537	310.964
830.791	310.814
831.045	298.376
831.299	303.859
831.553	309.346
831.807	301.714
832.061	317.508
832.315	312.509
832.568	323.526
832.822	321.147
833.076	297.89
833.33	303.591
833.584	298.58
833.838	293.578
834.092	272.923
834.345	288.654
834.599	315.425
834.853	318.309
835.107	278.912
835.36	270.929
835.614	271.185
835.868	287.053
836.122	298.295
836.375	308.836
836.629	271.474
836.883	276.76
837.136	263.882
837.39	284.785
837.643	271.826
837.897	287.931
838.151	258.56
838.404	287.414
838.658	273.99
838.911	279.371
839.165	245.291
839.418	256.159
839.672	261.332
839.925	264.243
840.179	259.288
840.432	256.664
840.686	264.687
840.939	262.391
841.192	244.15
841.446	260.29
841.699	249.951
841.952	252.824
842.206	236.464
842.459	265.704
842.712	247.225
842.966	255.177
843.219	247.391
843.472	247.635
843.725	250.712
843.979	245.478
844.232	221.355
844.485	226.911
844.738	237.796
844.991	235.213
845.244	211.275
845.497	259.546
845.75	241.139
846.004	227.87
846.257	233.4
846.51	236.184
846.763	247.252
847.016	225.522
847.269	209.545
847.522	231.059
847.775	231.322
848.028	215.313
848.281	229.035
848.534	239.983
848.786	234.992
849.039	221.691
849.292	213.928
849.545	219.352
849.798	222.532
850.051	219.782
850.303	211.696
850.556	219.99
850.809	212.07
851.062	217.545
851.314	220.363
851.567	210.084
851.82	204.762
852.073	210.391
852.325	210.53
852.578	207.725
852.831	209.213
853.083	205.15
853.336	197.141
853.588	202.325
853.841	198.144
854.093	202.92
854.346	198.378
854.598	206.483
854.851	195.623
855.103	199.086
855.356	195.949
855.608	195.877
855.861	190.729
856.113	193.174
856.366	189.952
856.618	196.588
856.87	182.598
857.123	183.795
857.352	182.932
857.606	194.065
857.859	191.25
858.113	199.763
858.367	194.244
858.621	174.665
858.875	185.676
859.128	185.772
859.382	194.004
859.636	158.048
859.889	191.303
860.143	155.418
860.397	171.948
860.65	166.646
860.904	188.823
861.158	158.304
861.411	175.168
861.665	175.242
861.918	177.847
862.172	169.248
862.425	180.436
862.679	174.755
862.932	174.8
863.186	164.119
863.439	161.041
863.693	172.174
863.946	166.872
864.2	175.242
864.453	167.055
864.707	147.454
864.96	175.111
865.213	169.674
865.467	180.826
865.72	169.844
865.973	170.047
866.227	131.117
866.48	145.032
866.733	153.424
866.987	147.87
867.24	148.151
867.493	173.228
867.746	145.436
867.999	159.537
868.253	131.608
868.506	156.944
868.759	157.219
869.012	151.722
869.265	151.845
869.518	168.759
869.771	160.267
870.025	160.329
870.278	157.554
870.531	149.395
870.784	155.291
871.037	138.415
871.29	144.023
871.543	149.896
871.796	155.739
872.049	138.76
872.302	147.375
872.555	152.988
872.808	144.498
873.06	141.706
873.313	144.69
873.566	147.495
873.819	153.344
874.072	147.336
874.325	150.204
874.578	139.166
874.83	136.313
875.083	133.44
875.336	139.085
875.589	139.204
875.841	116.451
876.094	124.983
876.347	147.856
876.6	136.463
876.852	128.055
877.105	145.231
877.358	139.659
877.61	131.086
877.863	142.508
878.115	131.213
878.368	131.445
878.621	131.661
878.873	140.244
879.126	128.716
879.378	143.385
879.631	134.987
879.883	143.594
880.136	123.548
880.388	123.755
880.641	138.392
880.893	135.676
881.145	135.683
881.398	115.701
881.65	121.631
881.902	139.117
882.155	124.693
882.407	118.877
882.659	118.97
882.912	127.932
883.164	119.311
883.416	131.108
883.669	119.494
883.921	125.486
884.173	140.196
884.425	119.904
884.677	125.764
884.93	120.069
885.182	120.006
885.434	117.008
885.686	122.96
885.938	108.332
886.19	111.383
886.442	111.38
886.694	108.544
886.946	123.256
887.198	108.845
887.45	117.786
887.702	108.988
887.954	97.3416
888.206	118.082
888.458	109.414
888.71	109.374
888.962	112.445
889.214	109.533
889.466	109.631
889.718	112.668
889.969	115.814
890.221	104.051
890.473	110.111
890.725	113.453
890.977	119.507
891.228	95.6722
891.48	110.755
891.732	92.8516
891.983	105.155
892.235	108.242
892.487	108.491
892.738	105.707
892.99	108.965
893.242	108.991
893.493	93.8741
893.745	103.101
893.996	109.323
894.248	94.2652
894.5	109.464
894.751	106.665
895.003	109.964
895.254	107.208
895.505	107.318
895.757	89.0174
896.008	104.475
896.26	116.926
896.511	110.876
896.763	95.4774
897.014	95.7468
897.265	92.7197
897.517	104.986
897.768	92.7572
898.019	99.2129
898.27	92.8248
898.522	96.0407
898.773	93.2927
899.024	102.643
899.275	90.232
899.527	102.562
899.778	93.5184
899.979	93.6681