File: PL_M1_280424_02.txt
#Acq. time (s)=	3
#Accumulations=	2
#Range (nm)=	520...900
#Windows=	8
#Auto scanning=	Off
#Autofocus=	Off
#AutoExposure=	Off
#Spike filter=	Off
#Delay time (s)=	0
#Binning=	1
#Readout mode=	Signal
#DeNoise=	Off
#ICS correction=	Off
#Dark correction=	Off
#Inst. Process=	Off
#Detector temperature (°C)=	-59.98
#Instrument=	LabRAM HR Evol
#Detector=	Syncerity OE
#Objective=	x50_VIS
#Grating=	600 (500nm)
#ND Filter=	25%
#Laser=	514nm_Edge
#Hole=	199.981
#Range=	Visible
#StageXY=	Marzhauser
#StageZ=	Marzhauser
#X (µm)=	54.2
#Y (µm)=	9176.9
#Z (µm)=	-258.6
#Full time(mm:ss)=	1:32
#Project=
#Sample=
#Site=
#Title=	PL_M1_280424
#Remark=
#Date=	06.05.2024 16:38
#Acquired=	06.05.2024 16:38:37
520.044	62
520.306	46
520.569	41
520.831	48
521.093	53
521.355	53
521.617	45
521.88	50
522.142	52
522.404	48
522.666	47
522.928	54
523.19	50
523.453	54
523.715	48
523.977	49
524.239	51
524.501	51
524.763	43
525.025	56
525.287	48
525.549	53
525.811	44
526.073	52
526.335	45
526.597	51
526.859	50
527.121	53
527.383	45
527.645	55
527.907	41
528.169	54
528.431	47
528.693	50
528.955	56
529.217	54
529.479	49
529.741	51
530.003	42
530.264	41
530.526	52
530.788	54
531.05	47
531.312	39
531.574	57
531.835	51
532.097	50
532.359	51
532.621	63
532.883	49
533.144	55
533.406	57
533.668	59
533.93	64
534.191	63
534.453	60
534.715	66
534.976	80
535.238	82
535.5	71
535.761	68
536.023	69
536.285	70
536.546	69
536.808	70
537.069	61
537.331	58
537.593	68
537.854	71
538.116	79
538.377	69
538.639	60
538.9	64
539.162	61
539.423	67
539.685	70
539.946	70
540.208	69
540.469	76
540.731	64
540.992	75
541.254	77
541.515	69
541.776	69
542.038	72
542.299	74
542.56	75
542.822	64
543.083	79
543.344	79
543.606	81
543.867	81
544.128	79
544.39	95
544.651	94
544.912	93
545.174	86
545.435	98
545.696	96
545.957	92
546.218	84
546.48	95
546.741	95
547.002	101
547.263	94
547.524	99
547.785	109
548.047	112
548.308	100
548.569	114
548.83	109
549.091	127
549.352	110
549.613	124
549.874	121
550.135	132
550.396	129
550.657	146
550.918	145
551.179	151
551.44	163
551.701	199
551.962	241
552.223	362
552.484	1494
552.745	28621
553.006	980
553.267	324
553.528	221
553.788	206
554.049	194
554.31	171
554.571	174
554.832	171
555.093	176
555.353	170
555.614	159
555.875	178
556.136	184
556.396	182
556.657	185
556.918	186
557.179	208
557.439	211
557.7	204
557.961	203
558.221	219
558.482	211
558.743	214
559.003	208
559.264	227
559.525	238
559.785	225
560.046	230
560.306	238
560.567	236
560.827	248
561.088	236
561.348	269
561.609	266
561.869	280
562.13	274
562.39	278
562.651	280
562.911	288
563.172	298
563.432	310
563.692	323
563.953	363
564.213	347
564.474	362
564.734	361
564.994	354
565.255	333
565.515	350
565.775	353
566.035	365
566.296	359
566.556	382
566.816	375
567.076	390
567.337	382
567.597	406
567.857	398
568.117	419.905
568.377	426.167
568.637	433.009
568.898	452.087
569.158	451.159
569.418	476.627
569.678	475.068
569.938	481.148
570.198	481.637
570.458	517.6
570.718	510.387
570.978	545.897
571.238	551.334
571.498	582.862
571.758	613.753
572.018	645.826
572.278	679.452
572.538	730.984
572.798	770.951
573.058	813.547
573.312	833
573.573	921
573.834	978
574.095	1074
574.356	1149
574.617	1264
574.878	1319
575.139	1371
575.4	1432
575.661	1475
575.922	1487
576.183	1459
576.444	1408
576.705	1388
576.965	1304
577.226	1258
577.487	1231
577.748	1183
578.009	1120
578.27	1065
578.531	1000
578.791	1016
579.052	1011
579.313	946
579.574	1028
579.835	998
580.095	1006
580.356	997
580.617	991
580.878	1007
581.138	1002
581.399	1015
581.66	1016
581.92	1030
582.181	1040
582.442	1070
582.703	1082
582.963	1080
583.224	1075
583.484	1084
583.745	1128
584.006	1137
584.266	1156
584.527	1200
584.787	1212
585.048	1222
585.308	1223
585.569	1266
585.83	1284
586.09	1302
586.351	1283
586.611	1334
586.872	1360
587.132	1368
587.392	1349
587.653	1385
587.913	1387
588.174	1347
588.434	1389
588.695	1410
588.955	1370
589.215	1427
589.476	1433
589.736	1433
589.996	1428
590.257	1424
590.517	1441
590.777	1423
591.038	1417
591.298	1401
591.558	1401
591.818	1405
592.079	1394
592.339	1373
592.599	1396
592.859	1359
593.12	1398
593.38	1378
593.64	1384
593.9	1378
594.16	1407
594.42	1427
594.68	1457
594.941	1448
595.201	1456
595.461	1456
595.721	1472
595.981	1480
596.241	1547
596.501	1531
596.761	1583
597.021	1571
597.281	1515
597.541	1552
597.801	1558
598.061	1558
598.321	1561
598.581	1571
598.841	1545
599.101	1606
599.361	1576
599.62	1615
599.88	1622
600.14	1597
600.4	1578
600.66	1603
600.92	1581
601.18	1618
601.439	1595
601.699	1622
601.959	1637
602.219	1645
602.478	1633
602.738	1600
602.998	1653
603.258	1663
603.517	1668
603.777	1626
604.037	1638
604.296	1671
604.556	1654
604.816	1689
605.075	1666
605.335	1728
605.594	1666
605.854	1676
606.114	1682
606.373	1682
606.633	1692
606.892	1708
607.152	1691
607.411	1722
607.671	1693
607.93	1714
608.19	1730
608.449	1739
608.709	1789
608.968	1737
609.228	1761
609.487	1754
609.746	1793
610.006	1812
610.265	1838
610.524	1774
610.784	1824
611.043	1850
611.302	1809
611.562	1875
611.821	1881
612.08	1876
612.339	1859
612.599	1895
612.858	1855
613.117	1880
613.376	1936
613.635	1929
613.895	1946
614.154	1972
614.413	1957
614.672	1991
614.931	2043
615.19	2042
615.449	2040
615.709	2048
615.968	2099
616.227	2060.66
616.486	2105.01
616.745	2118.62
617.004	2111.13
617.263	2134.85
617.522	2159.77
617.781	2157
618.04	2152.6
618.299	2194.55
618.557	2183.82
618.816	2206.76
619.075	2194.81
619.334	2206.44
619.593	2212.98
619.852	2233.61
620.111	2226.49
620.37	2260.83
620.628	2254.25
620.887	2265.79
621.146	2234.53
621.373	2291
621.633	2246
621.893	2274
622.153	2291
622.413	2235
622.673	2300
622.932	2264
623.192	2295
623.452	2308
623.712	2327
623.972	2302
624.232	2291
624.492	2347
624.751	2329
625.011	2395
625.271	2337
625.531	2396
625.791	2404
626.05	2387
626.31	2414
626.57	2444
626.83	2471
627.089	2445
627.349	2445
627.609	2471
627.868	2495
628.128	2536
628.388	2509
628.647	2571
628.907	2560
629.167	2545
629.426	2566
629.686	2626
629.945	2615
630.205	2660
630.465	2637
630.724	2725
630.984	2663
631.243	2714
631.503	2761
631.762	2720
632.022	2743
632.281	2804
632.541	2837
632.8	2810
633.06	2872
633.319	2856
633.579	2898
633.838	2960
634.097	2942
634.357	3016
634.616	3000
634.876	3057
635.135	3184
635.394	3241
635.654	3290
635.913	3385
636.172	3525
636.431	3667
636.691	3816
636.95	3908
637.209	4074
637.469	4196
637.728	4269
637.987	4244
638.246	4310
638.505	4235
638.765	4181
639.024	4138
639.283	4096
639.542	3989
639.801	3897
640.06	3883
640.319	3830
640.578	3755
640.838	3730
641.097	3674
641.356	3694
641.615	3634
641.874	3633
642.133	3616
642.392	3565
642.651	3628
642.91	3659
643.169	3640
643.428	3653
643.687	3736
643.946	3665
644.205	3747
644.463	3748
644.722	3746
644.981	3755
645.24	3776
645.499	3780
645.758	3817
646.017	3849
646.275	3848
646.534	3862
646.793	3894
647.052	3896
647.31	3886
647.569	3926
647.828	3887
648.087	3991
648.345	3962
648.604	4018
648.863	4028
649.121	4074
649.38	4027
649.639	4104
649.897	4140
650.156	4154
650.415	4140
650.673	4183
650.932	4266
651.19	4236
651.449	4353
651.707	4338
651.966	4395
652.224	4353
652.483	4403
652.741	4441
653	4476
653.258	4520
653.517	4507
653.775	4619
654.034	4714
654.292	4649
654.55	4697
654.809	4772
655.067	4834
655.326	4819
655.584	4884
655.842	4963
656.1	5009
656.359	4998
656.617	5154
656.875	5138
657.134	5190
657.392	5315
657.65	5301
657.908	5344
658.166	5300
658.425	5364
658.683	5450
658.941	5381
659.199	5432
659.457	5408
659.715	5477
659.973	5459
660.231	5513
660.49	5482
660.748	5477
661.006	5412
661.264	5474
661.522	5435
661.78	5468
662.038	5459
662.296	5473
662.554	5429
662.811	5483
663.069	5359
663.327	5463
663.585	5451
663.843	5410.71
664.101	5510.12
664.359	5490.66
664.617	5470.93
664.874	5472.74
665.132	5458.58
665.39	5475.69
665.648	5460.13
665.906	5464.14
666.163	5484.04
666.421	5452.76
666.679	5480.83
666.937	5476.15
667.194	5492.65
667.452	5478.43
667.71	5471.98
667.967	5485.27
668.225	5452.87
668.482	5455.03
668.74	5449.83
668.987	5476
669.245	5455
669.504	5493
669.763	5476
670.022	5470
670.281	5501
670.539	5481
670.798	5461
671.057	5365
671.316	5501
671.575	5553
671.833	5483
672.092	5484
672.351	5629
672.609	5606
672.868	5559
673.127	5612
673.385	5557
673.644	5590
673.903	5650
674.161	5659
674.42	5713
674.678	5784
674.937	5718
675.195	5790
675.454	5855
675.713	5729
675.971	5848
676.23	5774
676.488	5906
676.747	5910
677.005	5961
677.263	5887
677.522	5933
677.78	5857
678.039	5889
678.297	5884
678.556	5877
678.814	5899
679.072	5889
679.331	5926
679.589	5868
679.847	5821
680.106	5949
680.364	5941
680.622	5938
680.881	5986
681.139	6014
681.397	5980
681.656	6041
681.914	5989
682.172	6027
682.43	6101
682.688	6013
682.947	6026
683.205	6065
683.463	6137
683.721	6074
683.979	6125
684.237	6037
684.495	6081
684.754	6040
685.012	6030
685.27	5990
685.528	6023
685.786	6019
686.044	5986
686.302	5996
686.56	5960
686.818	5905
687.076	5876
687.334	5896
687.592	5846
687.85	5882
688.108	5945
688.366	5956
688.623	5858
688.881	5883
689.139	5878
689.397	5885
689.655	5890
689.913	5884
690.171	5828
690.428	5891
690.686	5836
690.944	5808
691.202	5766
691.459	5773
691.717	5779
691.975	5758
692.233	5730
692.49	5722
692.748	5677
693.006	5698
693.263	5694
693.521	5638
693.779	5732
694.036	5665
694.294	5659
694.552	5654
694.809	5668
695.067	5644
695.324	5674
695.582	5610
695.839	5559
696.097	5537
696.354	5532
696.612	5547
696.869	5529
697.127	5484
697.384	5506
697.642	5467
697.899	5517
698.156	5373
698.414	5390
698.671	5414
698.928	5383
699.186	5328
699.443	5264
699.7	5297
699.958	5303
700.215	5265
700.472	5263
700.73	5336
700.987	5268
701.244	5287
701.501	5318
701.758	5217
702.016	5287
702.273	5310
702.53	5273
702.787	5321
703.044	5288
703.301	5175
703.558	5238
703.816	5227
704.073	5221
704.33	5252
704.587	5230
704.844	5186
705.101	5177
705.358	5181
705.615	5137
705.872	5088
706.129	5058
706.386	5061
706.643	5017
706.899	5008
707.156	5038
707.413	4971
707.67	4912
707.927	4903
708.184	4999
708.441	4877
708.697	4903
708.954	4863
709.211	4899
709.468	4818
709.725	4879
709.981	4880
710.238	4846
710.495	4839
710.751	4769
711.008	4876
711.265	4837.15
711.521	4788.65
711.778	4820.85
712.035	4778.98
712.291	4701.66
712.548	4693.94
712.804	4671.02
713.061	4626.89
713.317	4653.08
713.574	4605.64
713.831	4607.82
714.087	4592.51
714.343	4546.62
714.6	4583.59
714.856	4485.42
715.113	4481.78
715.369	4469.05
715.626	4436.91
715.882	4443.15
716.138	4409.17
716.395	4396.32
716.639	4357
716.897	4413
717.155	4334
717.412	4273
717.67	4295
717.927	4258
718.185	4248
718.443	4289
718.7	4248
718.958	4223
719.215	4207
719.473	4216
719.73	4223
719.988	4132
720.245	4126
720.503	4084
720.76	4062
721.018	4047
721.275	4065
721.532	4038
721.79	3989
722.047	3973
722.305	3940
722.562	3921
722.819	3926
723.077	3862
723.334	3835
723.591	3886
723.849	3864
724.106	3820
724.363	3736
724.621	3775
724.878	3791
725.135	3787
725.392	3693
725.65	3723
725.907	3629
726.164	3703
726.421	3695
726.678	3631
726.935	3564
727.193	3624
727.45	3595
727.707	3601
727.964	3601
728.221	3537
728.478	3488
728.735	3475
728.992	3411
729.249	3438
729.506	3379
729.763	3354
730.02	3332
730.277	3383
730.534	3270
730.791	3291
731.048	3337
731.305	3244
731.562	3280
731.819	3258
732.076	3275
732.333	3209
732.589	3152
732.846	3207
733.103	3171
733.36	3128
733.617	3108
733.873	3127
734.13	3146
734.387	3136
734.644	3085
734.901	3054
735.157	3123
735.414	3100
735.671	3051
735.927	3060
736.184	3105
736.441	3015
736.697	3060
736.954	3047
737.211	3035
737.467	3045
737.724	3011
737.98	3007
738.237	3007
738.493	2994
738.75	3013
739.006	2953
739.263	2931
739.519	2967
739.776	2996
740.032	2891
740.289	2883
740.545	2912
740.802	2871
741.058	2918
741.314	2907
741.571	2845
741.827	2819
742.083	2834
742.34	2832
742.596	2832
742.852	2758
743.109	2794
743.365	2736
743.621	2703
743.878	2727
744.134	2691
744.39	2724
744.646	2672
744.902	2610
745.159	2649
745.415	2634
745.671	2636
745.927	2632
746.183	2579
746.439	2624
746.695	2583
746.951	2557
747.207	2598
747.463	2561
747.719	2602
747.975	2571
748.231	2501
748.487	2506
748.743	2536
748.999	2501
749.255	2529
749.511	2476
749.767	2507
750.023	2457
750.279	2479
750.535	2431
750.791	2447
751.046	2393
751.302	2390
751.558	2400
751.814	2326
752.07	2363
752.325	2360
752.581	2342
752.837	2331
753.092	2263
753.348	2312
753.604	2232
753.859	2289
754.115	2274
754.371	2210
754.626	2259
754.882	2211
755.138	2224
755.393	2176
755.649	2196
755.904	2159
756.16	2176
756.415	2165
756.671	2186
756.926	2131
757.182	2105
757.437	2114
757.693	2093
757.948	2092
758.203	2106
758.459	2083
758.714	2064.31
758.97	2060.43
759.225	2047.03
759.48	2008.74
759.736	2007.06
759.991	2002.84
760.246	1950.87
760.501	2006.6
760.757	1950.99
761.012	1982.33
761.267	1917.07
761.522	1908.91
761.777	1935.35
762.033	1923.32
762.288	1865.53
762.543	1913.74
762.798	1881.95
763.053	1865.63
763.308	1849.24
763.563	1837.76
763.78	1825
764.037	1790
764.293	1813
764.55	1804
764.806	1767
765.062	1813
765.319	1810
765.575	1783
765.831	1743
766.088	1721
766.344	1714
766.6	1698
766.857	1736
767.113	1685
767.369	1681
767.625	1667
767.882	1680
768.138	1668
768.394	1626
768.65	1616
768.906	1616
769.163	1597
769.419	1610
769.675	1562
769.931	1578
770.187	1580
770.443	1554
770.699	1567
770.955	1533
771.211	1504
771.467	1542
771.723	1500
771.979	1491
772.235	1496
772.491	1514
772.747	1452
773.003	1477
773.259	1442
773.515	1440
773.771	1433
774.027	1395
774.283	1415
774.539	1435
774.795	1393
775.05	1386
775.306	1384
775.562	1344
775.818	1355
776.074	1338
776.329	1309
776.585	1318
776.841	1293
777.097	1298
777.352	1303
777.608	1277
777.864	1313
778.12	1283
778.375	1248
778.631	1259
778.886	1239
779.142	1248
779.398	1209
779.653	1199
779.909	1227
780.164	1218
780.42	1215
780.675	1174
780.931	1172
781.187	1189
781.442	1211
781.698	1150
781.953	1161
782.208	1155
782.464	1133
782.719	1115
782.975	1107
783.23	1094
783.485	1110
783.741	1112
783.996	1106
784.252	1063
784.507	1080
784.762	1075
785.017	1058
785.273	1036
785.528	1028
785.783	1040
786.038	1028
786.294	1018
786.549	1012
786.804	1003
787.059	1021
787.314	995
787.57	989
787.825	1021
788.08	974
788.335	962
788.59	946
788.845	947
789.1	940
789.355	941
789.61	911
789.865	918
790.12	904
790.375	900
790.63	932
790.885	902
791.14	897
791.395	881
791.65	871
791.905	874
792.16	864
792.414	863
792.669	856
792.924	863
793.179	846
793.434	834
793.689	831
793.943	832
794.198	818
794.453	799
794.708	824
794.962	770
795.217	784
795.472	763
795.726	764
795.981	775
796.236	760
796.49	761
796.745	761
796.999	734
797.254	714
797.508	706
797.763	742
798.018	719
798.272	714
798.526	700
798.781	709
799.035	707
799.29	729
799.544	695
799.799	703
800.053	684
800.307	697
800.562	672
800.816	673
801.07	679
801.325	666
801.579	641
801.833	655
802.088	666
802.342	636
802.596	644
802.85	643
803.105	633
803.359	653
803.613	634
803.867	624
804.121	623
804.375	621
804.63	577
804.884	610
805.138	593
805.392	584
805.646	592.739
805.9	583.435
806.154	584.416
806.408	584.092
806.662	573.683
806.916	581.629
807.17	580.314
807.424	561.392
807.678	559.013
807.931	555.854
808.185	544.951
808.439	547.775
808.693	541.304
808.947	535.533
809.201	531.61
809.454	524.152
809.708	529.284
809.962	510.188
810.216	525.363
810.469	520.774
810.678	512
810.933	515
811.188	517
811.443	521
811.699	496
811.954	471
812.209	478
812.464	481
812.719	476
812.974	494
813.229	478
813.484	473
813.739	469
813.994	443
814.249	459
814.504	465
814.759	454
815.014	468
815.268	463
815.523	438
815.778	448
816.033	434
816.288	426
816.543	435
816.798	421
817.052	421
817.307	429
817.562	453
817.817	439
818.071	422
818.326	426
818.581	410
818.836	422
819.09	421
819.345	418
819.6	419
819.854	417
820.109	405
820.364	399
820.618	380
820.873	389
821.127	378
821.382	400
821.637	394
821.891	389
822.146	384
822.4	385
822.655	373
822.909	369
823.164	369
823.418	363
823.672	353
823.927	356
824.181	353
824.436	343
824.69	352
824.944	350
825.199	355
825.453	345
825.707	355
825.962	335
826.216	334
826.47	343
826.725	329
826.979	353
827.233	328
827.487	336
827.741	333
827.996	336
828.25	344
828.504	322
828.758	327
829.012	331
829.266	313
829.52	327
829.774	288
830.029	317
830.283	306
830.537	300
830.791	310
831.045	313
831.299	310
831.553	327
831.807	308
832.061	298
832.315	295
832.568	293
832.822	295
833.076	306
833.33	294
833.584	294
833.838	273
834.092	279
834.345	287
834.599	275
834.853	270
835.107	271
835.36	277
835.614	269
835.868	264
836.122	280
836.375	277
836.629	279
836.883	257
837.136	276
837.39	284
837.643	269
837.897	278
838.151	264
838.404	257
838.658	275
838.911	252
839.165	259
839.418	261
839.672	247
839.925	268
840.179	252
840.432	256
840.686	245
840.939	249
841.192	241
841.446	249
841.699	250
841.952	241
842.206	236
842.459	244
842.712	232
842.966	239
843.219	236
843.472	253
843.725	224
843.979	239
844.232	227
844.485	228
844.738	236
844.991	230
845.244	229
845.497	226
845.75	217
846.004	232
846.257	218
846.51	227
846.763	203
847.016	219
847.269	220
847.522	207
847.775	220
848.028	213
848.281	199
848.534	213
848.786	222
849.039	205
849.292	210
849.545	201
849.798	208
850.051	205
850.303	206
850.556	206
850.809	197
851.062	194
851.314	206
851.567	188
851.82	200
852.073	188
852.325	207.982
852.578	183.167
852.831	188.488
853.083	186.793
853.336	190.128
853.588	190.082
853.841	194.915
854.093	183.453
854.346	193.211
854.598	188.308
854.851	188.244
855.103	184.555
855.356	191.193
855.608	178.909
855.861	187.844
856.113	173.261
856.366	180.726
856.618	181.719
856.87	174.615
857.123	175.671
857.352	180
857.606	174
857.859	166
858.113	164
858.367	166
858.621	177
858.875	172
859.128	162
859.382	163
859.636	170
859.889	159
860.143	163
860.397	166
860.65	157
860.904	160
861.158	157
861.411	162
861.665	169
861.918	158
862.172	155
862.425	167
862.679	153
862.932	157
863.186	163
863.439	165
863.693	164
863.946	144
864.2	154
864.453	154
864.707	149
864.96	151
865.213	155
865.467	148
865.72	161
865.973	153
866.227	152
866.48	153
866.733	143
866.987	158
867.24	140
867.493	156
867.746	154
867.999	140
868.253	137
868.506	139
868.759	147
869.012	143
869.265	140
869.518	149
869.771	138
870.025	136
870.278	137
870.531	138
870.784	142
871.037	146
871.29	135
871.543	124
871.796	136
872.049	134
872.302	126
872.555	131
872.808	126
873.06	132
873.313	125
873.566	125
873.819	127
874.072	125
874.325	126
874.578	121
874.83	128
875.083	126
875.336	123
875.589	115
875.841	135
876.094	124
876.347	126
876.6	118
876.852	126
877.105	133
877.358	121
877.61	119
877.863	121
878.115	118
878.368	118
878.621	113
878.873	115
879.126	129
879.378	121
879.631	103
879.883	114
880.136	112
880.388	122
880.641	117
880.893	124
881.145	117
881.398	116
881.65	113
881.902	110
882.155	113
882.407	120
882.659	106
882.912	102
883.164	114
883.416	108
883.669	115
883.921	130
884.173	107
884.425	112
884.677	108
884.93	101
885.182	106
885.434	104
885.686	104
885.938	100
886.19	107
886.442	110
886.694	108
886.946	98
887.198	100
887.45	109
887.702	99
887.954	100
888.206	105
888.458	99
888.71	101
888.962	92
889.214	97
889.466	108
889.718	102
889.969	88
890.221	91
890.473	102
890.725	101
890.977	87
891.228	93
891.48	103
891.732	97
891.983	92
892.235	92
892.487	94
892.738	100
892.99	91
893.242	88
893.493	101
893.745	88
893.996	94
894.248	85
894.5	93
894.751	91
895.003	96
895.254	83
895.505	96
895.757	74
896.008	85
896.26	78
896.511	85
896.763	85
897.014	78
897.265	92
897.517	76
897.768	79
898.019	94
898.27	85
898.522	91
898.773	83
899.024	79
899.275	76
899.527	73
899.778	86
899.979	85