File: PL_M1_011123_01.txt
#Acq. time (s)=	5
#Accumulations=	2
#Range (nm)=	520...900
#Windows=	8
#Auto scanning=	Off
#Autofocus=	Off
#AutoExposure=	Off
#Spike filter=	Multiple accum.
#Delay time (s)=	0
#Binning=	1
#Readout mode=	Signal
#DeNoise=	Off
#ICS correction=	On
#Dark correction=	Off
#Inst. Process=	Off
#Detector temperature (°C)=	-59.98
#Instrument=	LabRAM HR Evol
#Detector=	Syncerity OE
#Objective=	x50_VIS
#Grating=	600 (500nm)
#ND Filter=	10%
#Laser=	514nm_Edge
#Hole=	199.981
#Range=	Auto
#StageXY=	Marzhauser
#StageZ=	Marzhauser
#X (µm)=	3719.7
#Y (µm)=	3064.1
#Z (µm)=	-33.5
#Full time(mm:ss)=	2:04
#Project=
#Sample=
#Site=
#Title=	PL_M1_011123
#Remark=
#Date=	11.11.2023 11:36
#Acquired=	11.11.2023 11:36:51
520.044	37.836
520.306	41.0212
520.569	40.8685
520.831	39.2592
521.093	35.7861
521.355	42.8978
521.617	30.2345
521.88	40.7667
522.142	39.012
522.404	41.0016
522.666	37.5673
522.928	44.7563
523.19	37.3265
523.453	52.958
523.715	33.4182
523.977	38.7377
524.239	35.4387
524.501	40.986
524.763	39.3141
525.025	39.1828
525.287	37.2923
525.549	40.8434
525.811	37.305
526.073	39.3466
526.335	34.2128
526.597	43.3998
526.859	45.1888
527.121	34.2383
527.383	35.9997
527.645	43.1087
527.907	30.521
528.169	43.2495
528.431	39.891
528.693	40.1546
528.955	43.9571
529.217	36.5873
529.479	40.0812
529.741	45.2936
530.003	47.0134
530.264	37.9224
530.526	43.4641
530.788	40.1189
531.05	47.7758
531.312	46.0777
531.574	44.4401
531.835	44.5302
532.097	53.973
532.359	42.8814
532.621	50.5634
532.883	45.0144
533.144	41.2423
533.406	48.7056
533.668	41.2079
533.93	46.6809
534.191	52.0893
534.453	49.9764
534.715	53.7188
534.976	59.4178
535.238	55.8965
535.5	55.938
535.761	54.2534
536.023	50.7201
536.285	56.3428
536.546	48.6563
536.808	59.8264
537.069	55.7723
537.331	53.6278
537.593	57.0979
537.854	55.1267
538.116	54.9762
538.377	56.9236
538.639	58.8147
538.9	60.7405
539.162	49.6955
539.423	55.1043
539.685	56.9045
539.946	60.4916
540.208	56.7284
540.469	58.6106
540.731	58.7783
540.992	58.8068
541.254	70.0307
541.515	53.5255
541.776	62.7692
542.038	75.8707
542.299	75.6433
542.56	67.9808
542.822	69.6811
543.083	67.6901
543.344	65.8132
543.606	71.5135
543.867	69.5951
544.128	67.8147
544.39	77.1172
544.651	77.2088
544.912	69.8592
545.174	80.8166
545.435	86.1412
545.696	87.6179
545.957	74.7202
546.218	85.3051
546.48	88.7072
546.741	86.8689
547.002	83.3959
547.263	94.2714
547.524	97.8693
547.785	88.9328
548.047	74.435
548.308	107.177
548.569	106.976
548.83	103.298
549.091	99.5668
549.352	93.7159
549.613	106.148
549.874	100.393
550.135	94.9198
550.396	110.567
550.657	128.388
550.918	140.708
551.179	127.999
551.44	152.53
551.701	165.053
551.962	216.322
552.223	353.074
552.484	4221.52
552.745	7946.99
553.006	386.636
553.267	211.254
553.528	186.847
553.788	158.035
554.049	154.552
554.31	151.074
554.571	161.548
554.832	164.861
555.093	169.821
555.353	183.478
555.614	158.036
555.875	166.365
556.136	176.685
556.396	162.326
556.657	174.692
556.918	188.453
557.179	186.939
557.439	201.51
557.7	200.259
557.961	204.419
558.221	201.521
558.482	199.772
558.743	204.887
559.003	217.315
559.264	223.465
559.525	197.747
559.785	219.933
560.046	228.977
560.306	217.428
560.567	226.059
560.827	243.589
561.088	228.965
561.348	243.594
561.609	251.832
561.869	257.093
562.13	255.568
562.39	277.622
562.651	280.054
562.911	282.262
563.172	284.541
563.432	301.733
563.692	315.109
563.953	316.024
564.213	326.02
564.474	313.211
564.734	333.462
564.994	323.081
565.255	308.518
565.515	334.641
565.775	338.075
566.035	353.247
566.296	335.349
566.556	342.248
566.816	344.367
567.076	354.117
567.337	359.274
567.597	384.14
567.857	386.368
568.117	395.223
568.377	395.39
568.637	399.91
568.898	418.491
569.158	415.441
569.418	438.217
569.678	438.012
569.938	435.811
570.198	428.083
570.458	460.262
570.718	476.435
570.978	488.21
571.238	502.108
571.498	515.587
571.758	562.46
572.018	562.093
572.278	589.022
572.538	631.225
572.798	645.071
573.058	679.071
573.312	749.881
573.573	793.323
573.834	831.18
574.095	917.807
574.356	1000.81
574.617	1057
574.878	1160.4
575.139	1264.7
575.4	1323.01
575.661	1375.69
575.922	1415.11
576.183	1398.09
576.444	1374.62
576.705	1310.6
576.965	1266.65
577.226	1198.49
577.487	1114.83
577.748	1016.84
578.009	984.974
578.27	953.296
578.531	903.286
578.791	868.447
579.052	845.387
579.313	840.951
579.574	846.173
579.835	815.655
580.095	842.884
580.356	815.309
580.617	829.034
580.878	839.549
581.138	824.43
581.399	848.805
581.66	831.847
581.92	866.354
582.181	855.111
582.442	873.023
582.703	878.995
582.963	886.562
583.224	893.236
583.484	930.332
583.745	916.429
584.006	928.44
584.266	940.916
584.527	959.494
584.787	963.242
585.048	985.765
585.308	1012.62
585.569	1014.48
585.83	1062.52
586.09	1051.26
586.351	1049.92
586.611	1110.61
586.872	1087.05
587.132	1084.15
587.392	1107.39
587.653	1048.41
587.913	1100.61
588.174	1108.69
588.434	1099.01
588.695	1147.21
588.955	1140.22
589.215	1132.48
589.476	1154.31
589.736	1133.49
589.996	1138.17
590.257	1105.58
590.517	1112.09
590.777	1149.03
591.038	1140.88
591.298	1115.76
591.558	1077.17
591.818	1085.53
592.079	1074.12
592.339	1088.53
592.599	1104.15
592.859	1084.21
593.12	1071.02
593.38	1067.42
593.64	1104.2
593.9	1096.96
594.16	1095.35
594.42	1081.43
594.68	1091.83
594.941	1115.78
595.201	1083.28
595.461	1102.56
595.721	1138.3
595.981	1125.94
596.241	1150.95
596.501	1139.43
596.761	1175.7
597.021	1172.44
597.281	1150.79
597.541	1166.17
597.801	1196.82
598.061	1183.42
598.321	1193.99
598.581	1194.91
598.841	1204.76
599.101	1224.5
599.361	1223.96
599.62	1233.44
599.88	1224.97
600.14	1242.91
600.4	1225.18
600.66	1227.08
600.92	1214.08
601.18	1258.45
601.439	1247.27
601.699	1259.23
601.959	1249.32
602.219	1235.01
602.478	1218.03
602.738	1242.75
602.998	1232.12
603.258	1239.62
603.517	1232.54
603.777	1225.02
604.037	1256.97
604.296	1215.34
604.556	1266.48
604.816	1296.28
605.075	1259.51
605.335	1275.86
605.594	1241.23
605.854	1248.55
606.114	1248.84
606.373	1275.77
606.633	1284.68
606.892	1262.12
607.152	1279.35
607.411	1295.94
607.671	1260.53
607.93	1307.11
608.19	1276.75
608.449	1302.52
608.709	1301.35
608.968	1266.54
609.228	1312.72
609.487	1321.52
609.746	1345.73
610.006	1328.91
610.265	1349.07
610.524	1342.84
610.784	1347.27
611.043	1359.62
611.302	1305.79
611.562	1343
611.821	1374.14
612.08	1342.85
612.339	1355.18
612.599	1374.15
612.858	1366.49
613.117	1400.9
613.376	1383.08
613.635	1364.43
613.895	1389.35
614.154	1439.1
614.413	1404.89
614.672	1479.71
614.931	1412.26
615.19	1445.18
615.449	1489.49
615.709	1468.73
615.968	1485.5
616.227	1532.73
616.486	1486.54
616.745	1517.38
617.004	1495.95
617.263	1503.74
617.522	1520.01
617.781	1527.35
618.04	1504.52
618.299	1560.6
618.557	1521.48
618.816	1536.8
619.075	1555.25
619.334	1545.58
619.593	1552.02
619.852	1535.3
620.111	1555.67
620.37	1564.75
620.628	1562.28
620.887	1567.22
621.146	1573.59
621.373	1574.79
621.633	1558.56
621.893	1548.38
622.153	1630.8
622.413	1568.75
622.673	1606.86
622.932	1578.06
623.192	1569
623.452	1623.28
623.712	1608.66
623.972	1595.8
624.232	1579.35
624.492	1614.03
624.751	1605.93
625.011	1620.36
625.271	1612.14
625.531	1636.09
625.791	1609.02
626.05	1624.42
626.31	1632.55
626.57	1640.98
626.83	1634.09
627.089	1653.48
627.349	1693.76
627.609	1680.57
627.868	1695.51
628.128	1696.71
628.388	1706.08
628.647	1744.89
628.907	1752.62
629.167	1729.06
629.426	1786.41
629.686	1759.88
629.945	1756.13
630.205	1759.76
630.465	1783.57
630.724	1794.04
630.984	1794.93
631.243	1787.95
631.503	1777.62
631.762	1845.38
632.022	1862.42
632.281	1853.88
632.541	1820.1
632.8	1919.76
633.06	1900.62
633.319	1877.92
633.579	1977.14
633.838	1945.08
634.097	1980.46
634.357	1980.48
634.616	1999.27
634.876	1990.37
635.135	2089.93
635.394	2092.77
635.654	2112.57
635.913	2217.65
636.172	2185.02
636.431	2303.38
636.691	2385.35
636.95	2482.04
637.209	2592.39
637.469	2685.3
637.728	2874.81
637.987	3019.33
638.246	3140.37
638.505	3105.22
638.765	3068.79
639.024	3051.23
639.283	2910.95
639.542	2840.41
639.801	2745.33
640.06	2738.22
640.319	2634.6
640.578	2590.65
640.838	2549.16
641.097	2536.34
641.356	2528.57
641.615	2543.4
641.874	2515.6
642.133	2504
642.392	2507.9
642.651	2495.04
642.91	2458.78
643.169	2464.37
643.428	2488.45
643.687	2483.34
643.946	2516.54
644.205	2517.65
644.463	2544.05
644.722	2573.84
644.981	2561.02
645.24	2532.23
645.499	2565.09
645.758	2591.24
646.017	2567.05
646.275	2621.55
646.534	2591.7
646.793	2658.38
647.052	2572.61
647.31	2628.06
647.569	2609.72
647.828	2633.36
648.087	2651.1
648.345	2716.15
648.604	2702.9
648.863	2723.46
649.121	2727.8
649.38	2750.23
649.639	2730.03
649.897	2809.09
650.156	2818.11
650.415	2804.33
650.673	2835.19
650.932	2865.27
651.19	2865.99
651.449	2898.56
651.707	2964.28
651.966	2910.01
652.224	2948.43
652.483	2928.07
652.741	3001.54
653	3005.38
653.258	3051.97
653.517	3047.3
653.775	3069.8
654.034	3099.35
654.292	3132.53
654.55	3190.99
654.809	3158.48
655.067	3225.78
655.326	3264.02
655.584	3228.71
655.842	3298.3
656.1	3337.01
656.359	3387.23
656.617	3394.47
656.875	3429.68
657.134	3465.77
657.392	3498.59
657.65	3543.7
657.908	3537.46
658.166	3563.33
658.425	3626.35
658.683	3678.58
658.941	3674.1
659.199	3737.5
659.457	3737.34
659.715	3705.07
659.973	3677.83
660.231	3757.97
660.49	3744.13
660.748	3725.53
661.006	3760.81
661.264	3738.3
661.522	3706.78
661.78	3699.14
662.038	3722.55
662.296	3683.98
662.554	3728.31
662.811	3677.65
663.069	3704.92
663.327	3649.83
663.585	3704.28
663.843	3705.73
664.101	3656.49
664.359	3645.54
664.617	3637.96
664.874	3663.13
665.132	3656.38
665.39	3651.4
665.648	3681.03
665.906	3646.31
666.163	3669.71
666.421	3667.43
666.679	3655.62
666.937	3663.17
667.194	3680.98
667.452	3660.35
667.71	3668.01
667.967	3645.08
668.225	3665.41
668.482	3643.98
668.74	3667.39
668.987	3643.06
669.245	3734.36
669.504	3696.32
669.763	3692.32
670.022	3713.76
670.281	3711.68
670.539	3695.81
670.798	3706.51
671.057	3671.47
671.316	3672.32
671.575	3680.99
671.833	3682.64
672.092	3732.98
672.351	3703.21
672.609	3738.5
672.868	3680.17
673.127	3704.44
673.385	3739.98
673.644	3744.65
673.903	3732.64
674.161	3766.36
674.42	3752.74
674.678	3783.63
674.937	3835.89
675.195	3825.38
675.454	3874.62
675.713	3860.13
675.971	3893.48
676.23	3876.87
676.488	3898.36
676.747	3946.2
677.005	3937.51
677.263	3902.83
677.522	3963.61
677.78	3968.81
678.039	3942.57
678.297	3987.58
678.556	3992.32
678.814	3942.64
679.072	4039.78
679.331	4001.5
679.589	4042.1
679.847	4015.89
680.106	3994.8
680.364	4022.01
680.622	4023.35
680.881	4050.12
681.139	4029.38
681.397	4040.95
681.656	4068.36
681.914	4053.88
682.172	4042.11
682.43	4071.57
682.688	4086.56
682.947	4103.87
683.205	4046.54
683.463	4129.55
683.721	4133.75
683.979	4062.27
684.237	4089.34
684.495	4117.18
684.754	4104.31
685.012	4097.43
685.27	4045.8
685.528	4073.72
685.786	4099.22
686.044	4071.4
686.302	4034.65
686.56	4068.92
686.818	3985.79
687.076	4028.6
687.334	4033.37
687.592	4013
687.85	4048.12
688.108	4013.17
688.366	4034.4
688.623	4028.37
688.881	4010.09
689.139	4016.32
689.397	3964.59
689.655	4055.94
689.913	4016.71
690.171	4016.99
690.428	3964.64
690.686	3996.39
690.944	3968.16
691.202	3964.92
691.459	3970.95
691.717	3996.63
691.975	3947.78
692.233	3967.49
692.49	3923.84
692.748	3894.9
693.006	3897.23
693.263	3917.79
693.521	3858.62
693.779	3902.53
694.036	3925.06
694.294	3872.16
694.552	3883.11
694.809	3897.91
695.067	3881.6
695.324	3848.79
695.582	3841.79
695.839	3835.81
696.097	3865.58
696.354	3874.54
696.612	3894.21
696.869	3879.92
697.127	3899.99
697.384	3861.84
697.642	3855.18
697.899	3869.04
698.156	3835.59
698.414	3844.75
698.671	3808.51
698.928	3834.47
699.186	3782.09
699.443	3814.29
699.7	3812.35
699.958	3733.12
700.215	3786.31
700.472	3770.26
700.73	3722.28
700.987	3742.87
701.244	3741.91
701.501	3767.56
701.758	3701.11
702.016	3739.74
702.273	3740.16
702.53	3738.8
702.787	3709.01
703.044	3768.64
703.301	3764.96
703.558	3725.15
703.816	3731.49
704.073	3760.5
704.33	3810.71
704.587	3752.28
704.844	3702.84
705.101	3738.83
705.358	3731.33
705.615	3678.12
705.872	3675.24
706.129	3703.82
706.386	3699.83
706.643	3684.59
706.899	3713.19
707.156	3707.53
707.413	3695.79
707.67	3679.76
707.927	3674.35
708.184	3656.79
708.441	3636.43
708.697	3605.93
708.954	3668.84
709.211	3647.71
709.468	3626.18
709.725	3611.77
709.981	3620.03
710.238	3631.38
710.495	3629.5
710.751	3612.22
711.008	3641.06
711.265	3673.37
711.521	3639.2
711.778	3605.54
712.035	3589.83
712.291	3588.79
712.548	3586.01
712.804	3596.08
713.061	3588.32
713.317	3557.61
713.574	3548.01
713.831	3535.1
714.087	3529.62
714.343	3525.86
714.6	3527.87
714.856	3498.7
715.113	3491.71
715.369	3467.98
715.626	3480.57
715.882	3434.57
716.138	3408.23
716.395	3422.44
716.639	3418.75
716.897	3439.17
717.155	3346.87
717.412	3344.11
717.67	3356.65
717.927	3389.47
718.185	3361.45
718.443	3304.21
718.7	3368.42
718.958	3341.38
719.215	3316.87
719.473	3297.49
719.73	3290.9
719.988	3343.13
720.245	3267.68
720.503	3257.19
720.76	3239.53
721.018	3261.6
721.275	3254.19
721.532	3249.79
721.79	3211.21
722.047	3175.46
722.305	3217.47
722.562	3144.93
722.819	3181.71
723.077	3175.98
723.334	3118.84
723.591	3172.59
723.849	3082.14
724.106	3146.52
724.363	3118.21
724.621	3114.11
724.878	3100.23
725.135	3083.42
725.392	3074.83
725.65	3080.19
725.907	3063.37
726.164	3023.95
726.421	3057.63
726.678	3040.63
726.935	3078
727.193	3055.49
727.45	3053.43
727.707	3051.65
727.964	3017.56
728.221	3024.33
728.478	2996.68
728.735	2960.41
728.992	2945.82
729.249	2965.2
729.506	2945.16
729.763	2945.04
730.02	2899.5
730.277	2910.46
730.534	2907.44
730.791	2907.69
731.048	2913.38
731.305	2813.26
731.562	2885.22
731.819	2841.81
732.076	2832.59
732.333	2860.62
732.589	2825.07
732.846	2836.52
733.103	2854.14
733.36	2774.39
733.617	2792.3
733.873	2785.1
734.13	2769.21
734.387	2760.36
734.644	2726.9
734.901	2752.66
735.157	2752.55
735.414	2767.63
735.671	2718
735.927	2698.58
736.184	2670.2
736.441	2665.23
736.697	2682.98
736.954	2675.02
737.211	2691.18
737.467	2650.22
737.724	2650.06
737.98	2642.15
738.237	2632.4
738.493	2567.06
738.75	2617.03
739.006	2632.06
739.263	2565.4
739.519	2561.61
739.776	2579.57
740.032	2556.54
740.289	2548.59
740.545	2534.41
740.802	2561.32
741.058	2560.83
741.314	2568.4
741.571	2531.45
741.827	2496.01
742.083	2518.26
742.34	2446.65
742.596	2520.27
742.852	2452.86
743.109	2477.09
743.365	2467.78
743.621	2442.47
743.878	2431.3
744.134	2465.89
744.39	2407.73
744.646	2445.56
744.902	2386.11
745.159	2383.29
745.415	2395.93
745.671	2388.32
745.927	2404.97
746.183	2358.9
746.439	2347.97
746.695	2296.88
746.951	2325.35
747.207	2331.9
747.463	2345.51
747.719	2278.25
747.975	2259.42
748.231	2296.29
748.487	2302.16
748.743	2280.53
748.999	2272.75
749.255	2265.36
749.511	2249.47
749.767	2242.97
750.023	2233.44
750.279	2263.64
750.535	2219.34
750.791	2252.37
751.046	2170.88
751.302	2166.73
751.558	2186.26
751.814	2143.26
752.07	2171.55
752.325	2169.96
752.581	2141.16
752.837	2140.24
753.092	2156.49
753.348	2094.73
753.604	2106.01
753.859	2105.47
754.115	2100.83
754.371	2060.48
754.626	2078.03
754.882	2083.73
755.138	2081.05
755.393	2068.27
755.649	2037.83
755.904	2074.34
756.16	2056.35
756.415	2023.25
756.671	2022.32
756.926	1986.76
757.182	2020.92
757.437	1992.3
757.693	1985.82
757.948	1989.57
758.203	1987.4
758.459	1980.84
758.714	1965.18
758.97	1940.16
759.225	1934.83
759.48	1949.5
759.736	1934.36
759.991	1941.43
760.246	1915.92
760.501	1871.09
760.757	1888.65
761.012	1891.81
761.267	1878.31
761.522	1870.57
761.777	1849.06
762.033	1879.78
762.288	1848.84
762.543	1845.56
762.798	1821.4
763.053	1813.42
763.308	1810.66
763.563	1769.05
763.78	1765.49
764.037	1790.08
764.293	1716.38
764.55	1775.87
764.806	1727.74
765.062	1759.99
765.319	1743.72
765.575	1732.24
765.831	1713.44
766.088	1728.57
766.344	1714.69
766.6	1697.05
766.857	1688.88
767.113	1703.81
767.369	1714.54
767.625	1662.93
767.882	1673.64
768.138	1663.02
768.394	1656.34
768.65	1616.89
768.906	1656.04
769.163	1630.55
769.419	1632.14
769.675	1614.76
769.931	1599.51
770.187	1607.46
770.443	1586.48
770.699	1554.81
770.955	1559.16
771.211	1563.9
771.467	1575.25
771.723	1580.06
771.979	1545.4
772.235	1527.4
772.491	1521.33
772.747	1521.46
773.003	1513.76
773.259	1527.34
773.515	1495.37
773.771	1501.84
774.027	1509.25
774.283	1479.98
774.539	1510.23
774.795	1485.76
775.05	1433.81
775.306	1452.19
775.562	1466.31
775.818	1432.78
776.074	1406.3
776.329	1400.74
776.585	1423.15
776.841	1408
777.097	1395.98
777.352	1416.69
777.608	1399.08
777.864	1411.46
778.12	1401.23
778.375	1396.32
778.631	1378.74
778.886	1375.16
779.142	1359.16
779.398	1321.97
779.653	1349.69
779.909	1291.54
780.164	1306.79
780.42	1328.52
780.675	1350.49
780.931	1343.72
781.187	1307.26
781.442	1303.21
781.698	1286.61
781.953	1284.92
782.208	1307.24
782.464	1279.77
782.719	1260.08
782.975	1240.63
783.23	1261.75
783.485	1236.02
783.741	1204.4
783.996	1224.41
784.252	1231.58
784.507	1211.6
784.762	1240.69
785.017	1213.49
785.273	1197.28
785.528	1203.66
785.783	1194.56
786.038	1188.53
786.294	1179.26
786.549	1192.93
786.804	1165.15
787.059	1143.27
787.314	1164.27
787.57	1158.29
787.825	1133.38
788.08	1133.25
788.335	1139.23
788.59	1137.48
788.845	1112.85
789.1	1122.77
789.355	1130.09
789.61	1125.38
789.865	1126.14
790.12	1070.96
790.375	1074.03
790.63	1103.09
790.885	1054.41
791.14	1073.44
791.395	1092.3
791.65	1051.69
791.905	1037.82
792.16	1059.53
792.414	1010.51
792.669	1027.77
792.924	1038.7
793.179	1053.88
793.434	1039.88
793.689	1038.15
793.943	999.63
794.198	987.664
794.453	999.906
794.708	1024.04
794.962	980.271
795.217	977.375
795.472	987.949
795.726	985.396
795.981	975.117
796.236	961.719
796.49	952.482
796.745	927.922
796.999	971.026
797.254	904.23
797.508	908.748
797.763	929.075
798.018	919.488
798.272	929.052
798.526	905.301
798.781	928.084
799.035	880.68
799.29	870.236
799.544	886.63
799.799	867.023
800.053	899.49
800.307	869.097
800.562	884.24
800.816	888.658
801.07	881.527
801.325	881.604
801.579	851.327
801.833	846.003
802.088	862.787
802.342	846.494
802.596	823.77
802.85	851.874
803.105	856.393
803.359	822.81
803.613	817.522
803.867	808.809
804.121	819.467
804.375	791.997
804.63	800.012
804.884	809.659
805.138	782.165
805.392	791.765
805.646	767.149
805.9	802.521
806.154	793.425
806.408	764.753
806.662	794.089
806.916	765.956
807.17	754.563
807.424	758.514
807.678	742.609
807.931	752.596
808.185	759.488
808.439	744.299
808.693	727.639
808.947	739.015
809.201	733.819
809.454	752.753
809.708	699.358
809.962	717.186
810.216	731.552
810.469	742.401
810.678	705.134
810.933	704.464
811.188	702.91
811.443	669.2
811.699	693.934
811.954	693.276
812.209	693.706
812.464	668.915
812.719	684.512
812.974	686.783
813.229	684.213
813.484	647.22
813.739	679.312
813.994	645.774
814.249	644.329
814.504	653.298
814.759	644.129
815.014	661.756
815.268	631.388
815.523	660.996
815.778	624.923
816.033	624.362
816.288	571.441
816.543	658.627
816.798	642.559
817.052	634.802
817.307	630.415
817.562	624.95
817.817	597.434
818.071	633.869
818.326	603.408
818.581	599.587
818.836	586.453
819.09	597.464
819.345	588.469
819.6	602.292
819.854	584.961
820.109	585.915
820.364	581.071
820.618	587.721
820.873	571.08
821.127	577.629
821.382	560.695
821.637	558.984
821.891	562.407
822.146	538.523
822.4	544.095
822.655	556.221
822.909	560.017
823.164	567.941
823.418	527.172
823.672	507.6
823.927	553.023
824.181	523.08
824.436	531.439
824.69	517.089
824.944	524.981
825.199	535.838
825.453	534.138
825.707	524.943
825.962	509.526
826.216	514.811
826.47	499.157
826.725	504.228
826.979	507.38
827.233	510.67
827.487	498.579
827.741	497.924
827.996	496.814
828.25	500.916
828.504	492.806
828.758	465.613
829.012	489.263
829.266	455.884
829.52	458.848
829.774	467.054
830.029	475.892
830.283	486.853
830.537	474.219
830.791	455.86
831.045	477.402
831.299	475.267
831.553	449.721
831.807	478.582
832.061	473.659
832.315	429.7
832.568	443.543
832.822	441.251
833.076	449.448
833.33	447.535
833.584	447.87
833.838	408.913
834.092	427.754
834.345	438.23
834.599	441.595
834.853	431.427
835.107	423.63
835.36	418.23
835.614	434.423
835.868	413.461
836.122	427.645
836.375	398.583
836.629	411.164
836.883	419.094
837.136	372.073
837.39	379.714
837.643	409.058
837.897	420.01
838.151	401.032
838.404	392.888
838.658	397.813
838.911	382.159
839.165	398.269
839.418	401.404
839.672	388.038
839.925	383.152
840.179	391.578
840.432	386.319
840.686	359.975
840.939	363.106
841.192	395.417
841.446	353.251
841.699	366.949
841.952	375.245
842.206	369.309
842.459	366.672
842.712	334.951
842.966	374.791
843.219	364.436
843.472	362.133
843.725	338.728
843.979	360.212
844.232	357.368
844.485	355.049
844.738	358.031
844.991	334.11
845.244	355.69
845.497	329.115
845.75	337.595
846.004	361.911
846.257	351.441
846.51	332.805
846.763	344.003
847.016	332.914
847.269	325.064
847.522	325.094
847.775	330.844
848.028	328.353
848.281	326.038
848.534	302.001
848.786	324.127
849.039	329.833
849.292	311.414
849.545	314.133
849.798	309.374
850.051	331.029
850.303	303.974
850.556	309.616
850.809	290.917
851.062	304.563
851.314	285.655
851.567	316.491
851.82	303.047
852.073	295.094
852.325	317.158
852.578	276.259
852.831	301.854
853.083	304.651
853.336	293.944
853.588	300.611
853.841	307.522
854.093	283.938
854.346	273.085
854.598	292.438
854.851	283.359
855.103	269.066
855.356	280.612
855.608	271.346
855.861	280.581
856.113	276.371
856.366	282.085
856.618	261.458
856.87	271.783
857.123	260.982
857.352	266.083
857.606	252.285
857.859	243.913
858.113	282.997
858.367	263.616
858.621	249.522
858.875	249.416
859.128	257.863
859.382	263.292
859.636	252.323
859.889	241.208
860.143	269.206
860.397	257.922
860.65	233.305
860.904	258.244
861.158	244.399
861.411	244.679
861.665	250.346
861.918	236.203
862.172	246.936
862.425	247.059
862.679	235.781
862.932	249.714
863.186	250.351
863.439	241.562
863.693	233.268
863.946	241.964
864.2	233.656
864.453	217.171
864.707	233.701
864.96	241.821
865.213	228.086
865.467	233.682
865.72	233.883
865.973	248.101
866.227	220.387
866.48	234.283
866.733	217.583
866.987	228.78
867.24	223.624
867.493	212.344
867.746	198.576
867.999	215.515
868.253	229.614
868.506	224.206
868.759	213.368
869.012	221.963
869.265	219.332
869.518	208.137
869.771	205.254
870.025	241.9
870.278	222.264
870.531	211.408
870.784	203.29
871.037	214.685
871.29	197.678
871.543	214.945
871.796	201.045
872.049	223.715
872.302	181.385
872.555	215.317
872.808	184.164
873.06	204.056
873.313	184.409
873.566	201.388
873.819	181.742
874.072	215.337
874.325	195.549
874.578	181.767
874.83	193.11
875.083	193.062
875.336	212.884
875.589	207.386
875.841	193.138
876.094	195.997
876.347	199.037
876.6	170.579
876.852	193.505
877.105	187.946
877.358	185.262
877.61	179.53
877.863	165.309
878.115	191.115
878.368	162.877
878.621	180.319
878.873	166.003
879.126	185.923
879.378	183.533
879.631	186.684
879.883	189.543
880.136	183.886
880.388	172.682
880.641	175.874
880.893	167.43
881.145	193.421
881.398	196.692
881.65	173.759
881.902	159.404
882.155	168.19
882.407	191.363
882.659	165.398
882.912	168.638
883.164	180.422
883.416	171.898
883.669	180.699
883.921	154.669
884.173	166.483
884.425	169.62
884.677	160.862
884.93	143.497
885.182	169.765
885.434	172.586
885.686	166.874
885.938	155.178
886.19	170.006
886.442	152.415
886.694	158.416
886.946	149.668
887.198	152.972
887.45	156.066
887.702	153.173
887.954	138.638
888.206	150.555
888.458	153.771
888.71	156.67
888.962	133.158
889.214	145.057
889.466	165.928
889.718	151.212
889.969	139.571
890.221	160.535
890.473	139.87
890.725	152.266
890.977	131.458
891.228	164.437
891.48	149.669
891.732	143.77
891.983	141.208
892.235	156.35
892.487	153.695
892.738	147.99
892.99	139.233
893.242	148.349
893.493	139.297
893.745	151.62
893.996	136.654
894.248	152.041
894.5	148.993
894.751	127.997
895.003	143.565
895.254	150.091
895.505	122.65
895.757	125.852
896.008	135.202
896.26	132.311
896.511	144.755
896.763	113.957
897.014	123.544
897.265	145.261
897.517	138.953
897.768	129.86
898.019	117.815
898.27	133.049
898.522	117.727
898.773	130.61
899.024	118.195
899.275	130.681
899.527	139.858
899.778	121.574
899.979	128.013