File: PL_M8_011123_01.txt
#Acq. time (s)=	5
#Accumulations=	2
#Range (nm)=	520...900
#Windows=	8
#Auto scanning=	Off
#Autofocus=	Off
#AutoExposure=	Off
#Spike filter=	Multiple accum.
#Delay time (s)=	0
#Binning=	1
#Readout mode=	Signal
#DeNoise=	Off
#ICS correction=	On
#Dark correction=	Off
#Inst. Process=	Off
#Detector temperature (°C)=	-59.98
#Instrument=	LabRAM HR Evol
#Detector=	Syncerity OE
#Objective=	x50_VIS
#Grating=	600 (500nm)
#ND Filter=	10%
#Laser=	514nm_Edge
#Hole=	199.981
#Range=	Auto
#StageXY=	Marzhauser
#StageZ=	Marzhauser
#X (µm)=	9823.1
#Y (µm)=	55.4
#Z (µm)=	-25.9
#Full time(mm:ss)=	2:05
#Project=
#Sample=
#Site=
#Title=	PL_M8_011123
#Remark=
#Date=	11.11.2023 11:54
#Acquired=	11.11.2023 11:54:49
520.044	30.6292
520.306	33.8871
520.569	30.2072
520.831	35.6901
521.093	28.6289
521.355	33.9608
521.617	32.013
521.88	37.2218
522.142	30.1456
522.404	35.6536
522.666	26.8338
522.928	28.644
523.19	28.4392
523.453	40.6012
523.715	33.4182
523.977	35.2161
524.239	28.351
524.501	37.422
524.763	37.5271
525.025	32.0587
525.287	23.0857
525.549	35.516
525.811	31.9757
526.073	35.7696
526.335	34.2128
526.597	36.1665
526.859	41.5737
527.121	37.8424
527.383	34.1997
527.645	37.7201
527.907	39.4977
528.169	37.8433
528.431	38.0778
528.693	34.6789
528.955	36.631
529.217	34.758
529.479	27.3281
529.741	39.8583
530.003	37.9724
530.264	46.9515
530.526	32.5981
530.788	38.2953
531.05	42.2632
531.312	38.7053
531.574	33.3301
531.835	48.241
532.097	40.945
532.359	39.1526
532.621	37.4544
532.883	39.3876
533.144	35.6184
533.406	39.3391
533.668	33.7156
533.93	50.4154
534.191	39.067
534.453	38.8705
534.715	40.7522
534.976	46.4201
535.238	37.2643
535.5	46.615
535.761	37.4161
536.023	50.7201
536.285	43.1961
536.546	44.9135
536.808	37.3915
537.069	42.7587
537.331	40.6832
537.593	51.5723
537.854	36.7512
538.116	51.3111
538.377	42.2337
538.639	45.949
538.9	44.1749
539.162	51.536
539.423	42.2466
539.685	40.3839
539.946	43.9939
540.208	49.4086
540.469	40.2948
540.731	40.4101
540.992	42.2674
541.254	44.2299
541.515	51.6798
541.776	42.4615
542.038	42.5616
542.299	53.5038
542.56	47.7703
542.822	47.6766
543.083	47.566
543.344	47.5317
543.606	51.343
543.867	45.7862
544.128	43.9879
544.39	58.7559
544.651	51.4726
544.912	58.8288
545.174	55.1022
545.435	58.6493
545.696	60.2373
545.957	60.1407
546.218	61.7101
546.48	65.1727
546.741	56.1028
547.002	63.4534
547.263	70.7036
547.524	72.4958
547.785	70.7832
548.047	70.804
548.308	67.213
548.569	77.9653
548.83	68.8651
549.091	72.4122
549.352	70.2869
549.613	70.1655
549.874	77.0873
550.135	77.0104
550.396	74.9002
550.657	87.3749
550.918	83.7126
551.179	97.7772
551.44	90.4539
551.701	129.558
551.962	157.809
552.223	271.459
552.484	3759.38
552.745	6583.38
553.006	294.411
553.267	163.323
553.528	108.549
553.788	97.6618
554.049	95.9291
554.31	90.6442
554.571	97.6388
554.832	88.6348
555.093	93.7553
555.353	84.682
555.614	93.0656
555.875	89.3117
556.136	87.4676
556.396	99.4898
556.657	92.587
556.918	95.9715
557.179	89.1017
557.439	99.8788
557.7	101.886
557.961	109.258
558.221	111.367
558.482	104.306
558.743	102.443
559.003	98.9402
559.264	103.815
559.525	103.248
559.785	113.458
560.046	107.55
560.306	113.891
560.567	107.892
560.827	102.205
561.088	120.419
561.348	121.797
561.609	120.001
561.869	125.164
562.13	113.398
562.39	132.04
562.651	120.508
562.911	125.828
563.172	136.307
563.432	138.081
563.692	148.186
563.953	142.72
564.213	142.634
564.474	152.373
564.734	148.205
564.994	148.985
565.255	148.422
565.515	152.411
565.775	146.774
566.035	147.871
566.296	147.226
566.556	154.826
566.816	157.564
567.076	157.566
567.337	170.696
567.597	167.654
567.857	177.696
568.117	171.534
568.377	173.21
568.637	172.794
568.898	178.395
569.158	178.758
569.418	180.2
569.678	191.391
569.938	191.045
570.198	186.445
570.458	185.715
570.718	193.677
570.978	205.355
571.238	201.927
571.498	213.676
571.758	227.597
572.018	233.759
572.278	252.909
572.538	261.046
572.798	255.393
573.058	283.691
573.312	310.775
573.573	327.845
573.834	341.433
574.095	349.199
574.356	388.259
574.617	414.481
574.878	427.274
575.139	484.417
575.4	478.731
575.661	495.677
575.922	492.014
576.183	471.095
576.444	465.794
576.705	469.696
576.965	442.874
577.226	424.152
577.487	408.823
577.748	384.14
578.009	341.357
578.27	364.805
578.531	350.529
578.791	359.614
579.052	334.292
579.313	336.971
579.574	329.067
579.835	336.806
580.095	316.446
580.356	331.356
580.617	313.062
580.878	319.897
581.138	352.914
581.399	341.257
581.66	339.972
581.92	335.549
582.181	324.103
582.442	333.888
582.703	336.852
582.963	359.534
583.224	362.201
583.484	344.194
583.745	374.316
584.006	377.09
584.266	390.032
584.527	393.421
584.787	383.605
585.048	403.012
585.308	400.015
585.569	399.093
585.83	403.843
586.09	394.57
586.351	415.507
586.611	410.716
586.872	412.184
587.132	432.26
587.392	426.995
587.653	415.726
587.913	432.134
588.174	437.603
588.434	443.508
588.695	440.808
588.955	463.299
589.215	452.992
589.476	479.589
589.736	464.633
589.996	447.625
590.257	453.395
590.517	450.809
590.777	450.92
591.038	444.429
591.298	434.131
591.558	454.115
591.818	421.251
592.079	407.516
592.339	428.937
592.599	412.541
592.859	408.602
593.12	427.061
593.38	418.096
593.64	417.261
593.9	409.012
594.16	421.803
594.42	431.77
594.68	411.103
594.941	418.085
595.201	427.469
595.461	452.978
595.721	439.133
595.981	448.252
596.241	443.993
596.501	464.993
596.761	451.584
597.021	431.606
597.281	432.696
597.541	443.88
597.801	440.103
598.061	434.269
598.321	453.163
598.581	451.701
598.841	448.006
599.101	460.34
599.361	477.449
599.62	465.673
599.88	470.429
600.14	462.784
600.4	461.756
600.66	451.385
600.92	469.498
601.18	477.708
601.439	462.931
601.699	477.321
601.959	463.733
602.219	454.934
602.478	463.453
602.738	465.382
602.998	455.236
603.258	469.222
603.517	471.871
603.777	478.685
604.037	477.313
604.296	448.364
604.556	473.162
604.816	472.428
605.075	471.832
605.335	471.345
605.594	458.995
605.854	461.082
606.114	469.451
606.373	470.156
606.633	468.803
606.892	477.174
607.152	480.727
607.411	487.429
607.671	477.199
607.93	478.931
608.19	469.978
608.449	485.251
608.709	469.508
608.968	492.613
609.228	490.998
609.487	502.408
609.746	504.967
610.006	479.426
610.265	487.34
610.524	504.199
610.784	506.491
611.043	500.047
611.302	507.385
611.562	489.741
611.821	492.474
612.08	503.727
612.339	505.216
612.599	497.99
612.858	504.954
613.117	533.262
613.376	515.556
613.635	532.19
613.895	519.315
614.154	521.412
614.413	533.269
614.672	525.492
614.931	546.561
615.19	543.622
615.449	535.534
615.709	551.688
615.968	549.466
616.227	545.818
616.486	548.108
616.745	559.226
617.004	562.19
617.263	559.963
617.522	560.737
617.781	574.544
618.04	580.019
618.299	566.078
618.557	573.587
618.816	586.514
619.075	584.784
619.334	575.357
619.593	569.914
619.852	576.49
620.111	582.207
620.37	587.033
620.628	587.39
620.887	577.036
621.146	587.449
621.373	570.729
621.633	612.416
621.893	588.69
622.153	586.527
622.413	584.048
622.673	587.279
622.932	608.199
623.192	592.295
623.452	586.281
623.712	605.996
623.972	601.884
624.232	609.209
624.492	613.009
624.751	582.622
625.011	607.066
625.271	602.277
625.531	612.821
625.791	616.147
626.05	607.174
626.31	621.545
626.57	629.232
626.83	640.312
627.089	624.573
627.349	616.527
627.609	620.344
627.868	642.155
628.128	632.328
628.388	619.268
628.647	648.712
628.907	628.423
629.167	650.927
629.426	641.536
629.686	642.709
629.945	664.845
630.205	665.219
630.465	670.096
630.724	693.963
630.984	684.527
631.243	673.816
631.503	672.854
631.762	673.568
632.022	659.214
632.281	676.955
632.541	720.734
632.8	711.473
633.06	717.571
633.319	734.168
633.579	738.53
633.838	714.52
634.097	709.354
634.357	737.59
634.616	768.611
634.876	764.847
635.135	808.223
635.394	802.965
635.654	808.718
635.913	827.219
636.172	856.633
636.431	896.493
636.691	929.344
636.95	981.835
637.209	1006.44
637.469	1043.43
637.728	1041.9
637.987	1058.68
638.246	1077.48
638.505	1085.4
638.765	1094.36
639.024	1089.96
639.283	1053.27
639.542	1033.77
639.801	1040.28
640.06	1015.25
640.319	999.558
640.578	957.84
640.838	972.304
641.097	945.403
641.356	944.13
641.615	920.021
641.874	932.067
642.133	929.621
642.392	925.507
642.651	939.986
642.91	935.749
643.169	922.241
643.428	926.137
643.687	918.956
643.946	944.784
644.205	951.401
644.463	956.174
644.722	944.569
644.981	957.55
645.24	952.956
645.499	937.66
645.758	968.071
646.017	967.108
646.275	944.927
646.534	978.509
646.793	967.962
647.052	961.351
647.31	975.117
647.569	992.947
647.828	992.904
648.087	990.794
648.345	991.32
648.604	995.804
648.863	1025.47
649.121	1029.38
649.38	1027.04
649.639	1041.34
649.897	1040.68
650.156	1050.09
650.415	1047.33
650.673	1064.94
650.932	1059.58
651.19	1102.38
651.449	1081.46
651.707	1071.96
651.966	1088.7
652.224	1116.55
652.483	1087.66
652.741	1122.34
653	1130.65
653.258	1145.16
653.517	1156.99
653.775	1156.41
654.034	1131.71
654.292	1162.66
654.55	1170.07
654.809	1188.42
655.067	1218.3
655.326	1189.91
655.584	1206.13
655.842	1238.72
656.1	1227.59
656.359	1243.81
656.617	1281.23
656.875	1282.71
657.134	1304.81
657.392	1306.82
657.65	1332.32
657.908	1337.13
658.166	1340.35
658.425	1350.33
658.683	1359.01
658.941	1382.84
659.199	1384.77
659.457	1375.73
659.715	1388.73
659.973	1412.34
660.231	1377.96
660.49	1362.37
660.748	1395.61
661.006	1364.67
661.264	1371.03
661.522	1378.95
661.78	1386.78
662.038	1384.5
662.296	1371.13
662.554	1354.51
662.811	1354.15
663.069	1360.7
663.327	1358.27
663.585	1340.86
663.843	1348.01
664.101	1352.85
664.359	1351.48
664.617	1343.56
664.874	1365.2
665.132	1389.72
665.39	1379.02
665.648	1365.25
665.906	1360.2
666.163	1374.02
666.421	1362.04
666.679	1362.05
666.937	1365.25
667.194	1336.98
667.452	1353.92
667.71	1373.39
667.967	1357.57
668.225	1338.72
668.482	1387.38
668.74	1354.76
668.987	1344.54
669.245	1388.12
669.504	1396.83
669.763	1378.2
670.022	1368.01
670.281	1376.76
670.539	1371.59
670.798	1374.96
671.057	1386
671.316	1404.28
671.575	1397.14
671.833	1396.32
672.092	1378.78
672.351	1394.73
672.609	1397.23
672.868	1391.17
673.127	1386.56
673.385	1396.12
673.644	1394.64
673.903	1392.22
674.161	1404.62
674.42	1423.42
674.678	1422.09
674.937	1418.22
675.195	1453.32
675.454	1417.67
675.713	1441.61
675.971	1458.89
676.23	1444.75
676.488	1455.12
676.747	1470.44
677.005	1482.18
677.263	1449.8
677.522	1469.68
677.78	1490.28
678.039	1491.64
678.297	1502.74
678.556	1475.47
678.814	1505.99
679.072	1488.78
679.331	1499.77
679.589	1533.68
679.847	1482.97
680.106	1528.23
680.364	1464.64
680.622	1496.48
680.881	1501.98
681.139	1500.47
681.397	1488.23
681.656	1491.49
681.914	1518.39
682.172	1526.17
682.43	1514.76
682.688	1500.93
682.947	1509.11
683.205	1523.17
683.463	1528.27
683.721	1525.49
683.979	1514.87
684.237	1520.3
684.495	1520.66
684.754	1535.18
685.012	1504.49
685.27	1508.64
685.528	1509.53
685.786	1492.54
686.044	1507.19
686.302	1528.64
686.56	1513.36
686.818	1507.43
687.076	1509.67
687.334	1491
687.592	1490.45
687.85	1485.46
688.108	1497.36
688.366	1483.88
688.623	1480.17
688.881	1498.16
689.139	1486.25
689.397	1511.57
689.655	1477.75
689.913	1484.25
690.171	1488.28
690.428	1477.56
690.686	1474.18
690.944	1471.6
691.202	1486.45
691.459	1454.57
691.717	1486.67
691.975	1478.83
692.233	1450.54
692.49	1451.38
692.748	1441.97
693.006	1428.42
693.263	1467.17
693.521	1477.93
693.779	1455.98
694.036	1444.28
694.294	1463.15
694.552	1416.51
694.809	1457.44
695.067	1441.55
695.324	1431.11
695.582	1443.22
695.839	1424.33
696.097	1456.46
696.354	1434.62
696.612	1433.97
696.869	1409.7
697.127	1428.66
697.384	1419.86
697.642	1449.52
697.899	1417.3
698.156	1453.89
698.414	1440.54
698.671	1441.41
698.928	1426.34
699.186	1407.24
699.443	1409.92
699.7	1421.63
699.958	1432.08
700.215	1404.26
700.472	1402.97
700.73	1385.93
700.987	1405.78
701.244	1408.45
701.501	1411.6
701.758	1386.82
702.016	1386.88
702.273	1394.88
702.53	1389.7
702.787	1412.28
703.044	1400.19
703.301	1406.49
703.558	1409.9
703.816	1418.94
704.073	1406.3
704.33	1402.19
704.587	1388.99
704.844	1389.68
705.101	1414.12
705.358	1398.26
705.615	1399.9
705.872	1380.48
706.129	1368.38
706.386	1386.16
706.643	1385.29
706.899	1388.44
707.156	1368.83
707.413	1360.4
707.67	1373.59
707.927	1393.96
708.184	1372.59
708.441	1326.84
708.697	1332.37
708.954	1349.8
709.211	1355.79
709.468	1341.79
709.725	1353.4
709.981	1350.72
710.238	1359.02
710.495	1338.28
710.751	1351.24
711.008	1338.62
711.265	1343.27
711.521	1337.96
711.778	1320.02
712.035	1348.11
712.291	1326.71
712.548	1360.15
712.804	1340.61
713.061	1346.93
713.317	1313.87
713.574	1340.08
713.831	1320.54
714.087	1323.73
714.343	1320.89
714.6	1322.1
714.856	1306.72
715.113	1294.35
715.369	1303.15
715.626	1291.76
715.882	1279.26
716.138	1290.57
716.395	1269.07
716.639	1275.62
716.897	1241.82
717.155	1256.45
717.412	1256.49
717.67	1269.49
717.927	1259.37
718.185	1257.16
718.443	1264.57
718.7	1240.74
718.958	1222.82
719.215	1247.71
719.473	1250.56
719.73	1213.82
719.988	1245.85
720.245	1246.86
720.503	1208.55
720.76	1230.75
721.018	1232.89
721.275	1210.36
721.532	1227.08
721.79	1198.8
722.047	1221.43
722.305	1188.01
722.562	1172.95
722.819	1179.84
723.077	1200.47
723.334	1181.63
723.591	1171.69
723.849	1153.07
724.106	1136.57
724.363	1154.94
724.621	1187.87
724.878	1163.07
725.135	1151.25
725.392	1146.55
725.65	1143.32
725.907	1141.74
726.164	1132.83
726.421	1137.42
726.678	1146.49
726.935	1117.23
727.193	1146.8
727.45	1128.53
727.707	1142.87
727.964	1123.72
728.221	1146.42
728.478	1097.07
728.735	1097.1
728.992	1108.26
729.249	1127.32
729.506	1088.52
729.763	1099.06
730.02	1077.15
730.277	1102.49
730.534	1077.29
730.791	1068.84
731.048	1067.26
731.305	1078.16
731.562	1062.9
731.819	1073.39
732.076	1066.6
732.333	1041.5
732.589	1073.47
732.846	1036.58
733.103	1052.49
733.36	1049.04
733.617	1048
733.873	1030.11
734.13	1035.8
734.387	1024.87
734.644	1024.71
734.901	1043.43
735.157	1055.83
735.414	1001.63
735.671	1048.01
735.927	1016.59
736.184	1019.45
736.441	1020.4
736.697	985.178
736.954	967.954
737.211	1013.64
737.467	993.833
737.724	1000.69
737.98	993.821
738.237	979.168
738.493	988.532
738.75	1002.3
739.006	983.128
739.263	993.011
739.519	962.905
739.776	955.657
740.032	957.108
740.289	983.715
740.545	947.219
740.802	961.558
741.058	936.89
741.314	958.358
741.571	916.781
741.827	973.358
742.083	949.509
742.34	911.972
742.596	959.899
742.852	943.187
743.109	899.981
743.365	939.904
743.621	935.446
743.878	914.606
744.134	932.963
744.39	919.76
744.646	898.045
744.902	908.994
745.159	894.095
745.415	894.154
745.671	888.779
745.927	876.107
746.183	913.588
746.439	903.176
746.695	889.627
746.951	901.019
747.207	844.556
747.463	888.582
747.719	869.275
747.975	859.701
748.231	849.413
748.487	869.608
748.743	874.466
748.999	851.017
749.255	868.847
749.511	835.064
749.767	822.857
750.023	817.29
750.279	834.201
750.535	847.122
750.791	818.516
751.046	828.802
751.302	799.419
751.558	834.252
751.814	808.476
752.07	817.265
752.325	838.562
752.581	812.518
752.837	822.147
753.092	799.631
753.348	797.924
753.604	793.825
753.859	767.51
754.115	784.468
754.371	790.547
754.626	775.161
754.882	780.653
755.138	754.025
755.393	774.292
755.649	785.741
755.904	763.597
756.16	776.208
756.415	779.215
756.671	750.458
756.926	758.8
757.182	741.608
757.437	757.892
757.693	751.31
757.948	746.656
758.203	726.281
758.459	734.827
758.714	728.439
758.97	715.548
759.225	724.534
759.48	741.511
759.736	714.772
759.991	726.432
760.246	708.131
760.501	717.669
760.757	717.551
761.012	712.044
761.267	695.509
761.522	700.133
761.777	706.464
762.033	710.119
762.288	679.088
762.543	686.087
762.798	695.586
763.053	696.644
763.308	684.568
763.563	670.582
763.78	684.48
764.037	654.522
764.293	650.934
764.55	663.583
764.806	652.843
765.062	655.247
765.319	650.924
765.575	627.163
765.831	656.449
766.088	660.548
766.344	646.993
766.6	641.783
766.857	639.727
767.113	625.105
767.369	619.093
767.625	644.91
767.882	640.111
768.138	616.772
768.394	623.352
768.65	617.89
768.906	618.168
769.163	593.519
769.419	617.567
769.675	585.698
769.931	603.094
770.187	598.279
770.443	611.198
770.699	597.495
770.955	595.859
771.211	587.085
771.467	586.566
771.723	587.735
771.979	587.451
772.235	577.798
772.491	583.316
772.747	584.011
773.003	577.152
773.259	568.313
773.515	565.633
773.771	578.673
774.027	568.309
774.283	564.369
774.539	541.566
774.795	539.808
775.05	551.199
775.306	554.69
775.562	549.22
775.818	560.654
776.074	537.551
776.329	523.106
776.585	531.288
776.841	516.44
777.097	541.62
777.352	539.359
777.608	526.63
777.864	519.179
778.12	542.865
778.375	530.248
778.631	518.576
778.886	525.223
779.142	523.028
779.398	525.582
779.653	480.247
779.909	500.876
780.164	506.2
780.42	505.845
780.675	468.796
780.931	493.723
781.187	514.927
781.442	494.382
781.698	491.351
781.953	499.389
782.208	488.158
782.464	485.179
782.719	473.218
782.975	481.549
783.23	486.279
783.485	467.435
783.741	453.965
783.996	476.777
784.252	452.074
784.507	470.453
784.762	449.118
785.017	458.805
785.273	457.893
785.528	458.895
785.783	446.546
786.038	461.053
786.294	449.333
786.549	445.691
786.804	435.269
787.059	424.916
787.314	429.443
787.57	438.426
787.825	441.079
788.08	437.936
788.335	446.454
788.59	435.712
788.845	425.045
789.1	406.521
789.355	407.763
789.61	431.494
789.865	393.563
790.12	398.677
790.375	378.264
790.63	414.15
790.885	397.371
791.14	412.407
791.395	410.846
791.65	402.058
791.905	406.793
792.16	418.237
792.414	401.408
792.669	415.906
792.924	378.986
793.179	408.277
793.434	399.8
793.689	372.358
793.943	387.28
794.198	361.737
794.453	378.783
794.708	381.465
794.962	368.369
795.217	379.066
795.472	403.412
795.726	389.623
795.981	347.076
796.236	372.278
796.49	375.598
796.745	378.659
796.999	370.907
797.254	359.186
797.508	360.149
797.763	362.822
798.018	364.008
798.272	377.955
798.526	353.237
798.781	361.04
799.035	378.65
799.29	345.535
799.544	346.106
799.799	342.528
800.053	355.513
800.307	347.639
800.562	342.078
800.816	345.11
801.07	345.697
801.325	363.906
801.579	310.56
801.833	347.971
802.088	322.456
802.342	320.708
802.596	329.945
802.85	332.866
803.105	329.382
803.359	323.404
803.613	323.924
803.867	324.849
804.121	323.357
804.375	332.772
804.63	313.338
804.884	311.407
805.138	309.746
805.392	298.863
805.646	309.907
805.9	309.784
806.154	301.787
806.408	289.281
806.662	289.624
806.916	293.538
807.17	300.834
807.424	294.787
807.678	305.81
807.931	289.727
808.185	290.159
808.439	295.141
808.693	294.458
808.947	302.348
809.201	271.874
809.454	293.396
809.708	268.537
809.962	284.156
810.216	293.556
810.469	277.487
810.678	285.301
810.933	272.021
811.188	283.957
811.443	286.8
811.699	261.686
811.954	288.084
812.209	250.765
812.464	281.648
812.719	265.807
812.974	237.552
813.229	261.889
813.484	283.454
813.739	262.73
813.994	263.533
814.249	280.557
814.504	261.319
814.759	269.58
815.014	272.347
815.268	272.645
815.523	249.071
815.778	234.645
816.033	232.042
816.288	244.903
816.543	254.797
816.798	262.318
817.052	234.129
817.307	251.2
817.562	259.185
817.817	247.717
818.071	250.148
818.326	240.877
818.581	236.422
818.836	239.468
819.09	244.862
819.345	247.647
819.6	216.334
819.854	234.478
820.109	224.971
820.364	212.647
820.618	233.105
820.873	225.949
821.127	241.509
821.382	229.262
821.637	212.115
821.891	227.463
822.146	225.428
822.4	205.603
822.655	231.549
822.909	232.079
823.164	219.604
823.418	224.49
823.672	222.233
823.927	224.745
824.181	217.318
824.436	212.576
824.69	205.315
824.944	213.036
825.199	210.78
825.453	228.916
825.707	206.409
825.962	196.168
826.216	186.046
826.47	213.924
826.725	201.182
826.979	221.82
827.233	201.715
827.487	186.648
827.741	201.723
827.996	207.433
828.25	200.367
828.504	202.769
828.758	190.361
829.012	195.705
829.266	195.747
829.52	213.957
829.774	180.629
830.029	193.978
830.283	163.147
830.537	191.761
830.791	165.767
831.045	189.404
831.299	192.184
831.553	197.565
831.807	195.074
832.061	197.792
832.315	179.693
832.568	193.072
832.822	182.767
833.076	190.754
833.33	185.818
833.584	188.577
833.838	186.108
834.092	183.698
834.345	181.065
834.599	162.969
834.853	173.623
835.107	168.4
835.36	176.235
835.614	181.668
835.868	173.812
836.122	171.586
836.375	168.936
836.629	171.318
836.883	150.241
837.136	176.801
837.39	166.125
837.643	179.458
837.897	171.702
838.151	153.025
838.404	171.394
838.658	150.168
838.911	160.77
839.165	152.977
839.418	161.09
839.672	168.942
839.925	126.836
840.179	153.456
840.432	161.407
840.686	158.812
840.939	156.374
841.192	145.959
841.446	159.361
841.699	162.202
841.952	154.356
842.206	154.1
842.459	154.108
842.712	164.817
842.966	146.195
843.219	162.267
843.472	143.788
843.725	149.36
843.979	157.426
844.232	154.682
844.485	149.494
844.738	146.953
844.991	138.99
845.244	141.741
845.497	155.192
845.75	150.042
846.004	142.084
846.257	166.331
846.51	142.247
846.763	155.876
847.016	153.033
847.269	155.816
847.522	139.71
847.775	147.938
848.028	145.337
848.281	156.283
848.534	151
848.786	148.558
849.039	145.991
849.292	127.274
849.545	146.235
849.798	146.545
850.051	132.954
850.303	143.845
850.556	130.365
850.809	127.786
851.062	138.685
851.314	133.306
851.567	141.875
851.82	120.127
852.073	136.618
852.325	142.157
852.578	123.087
852.831	133.942
853.083	129.117
853.336	135.521
853.588	113.071
853.841	130.978
854.093	124.558
854.346	123.891
854.598	123.207
854.851	123.538
855.103	126.361
855.356	123.198
855.608	124.981
855.861	128.27
856.113	123.579
856.366	127.972
856.618	120.555
856.87	110.834
857.123	114.625
857.352	105.324
857.606	127.529
857.859	113.641
858.113	108.205
858.367	127.646
858.621	121.988
858.875	110.851
859.128	113.681
859.382	124.717
859.636	119.229
859.889	105.355
860.143	116.563
860.397	105.388
860.65	113.875
860.904	113.849
861.158	111.09
861.411	125.12
861.665	111.265
861.918	108.376
862.172	97.1095
862.425	105.486
862.679	102.634
862.932	102.66
863.186	116.831
863.439	113.839
863.693	127.742
863.946	108.467
864.2	114.046
864.453	111.37
864.707	97.3753
864.96	105.623
865.213	114.043
865.467	119.623
865.72	116.942
865.973	103.143
866.227	97.64
866.48	94.8288
866.733	108.792
866.987	92.07
867.24	95.0404
867.493	94.996
867.746	106.28
867.999	125.95
868.253	100.806
868.506	100.893
868.759	106.684
869.012	109.577
869.265	101.23
869.518	92.8176
869.771	89.9743
870.025	95.6348
870.278	98.4713
870.531	95.8385
870.784	107.292
871.037	90.3935
871.29	84.7192
871.543	90.5032
871.796	99.1068
872.049	107.61
872.302	96.3606
872.555	93.493
872.808	107.665
873.06	99.1941
873.313	96.4602
873.566	87.9299
873.819	107.909
874.072	93.5016
874.325	99.1915
874.578	93.7237
874.83	85.1958
875.083	79.4963
875.336	85.1538
875.589	90.909
875.841	110.77
876.094	93.7375
876.347	99.5185
876.6	93.8186
876.852	93.907
877.105	82.5822
877.358	88.3559
877.61	88.3403
877.863	94.0554
878.115	88.4263
878.368	94.2974
878.621	83.0038
878.873	83.0016
879.126	85.8106
879.378	88.899
879.631	94.7778
879.883	97.6436
880.136	97.6893
880.388	89.2189
880.641	89.3784
880.893	86.6015
881.145	66.3981
881.398	89.6686
881.65	78.1916
881.902	89.8461
882.155	81.1954
882.407	110.179
882.659	81.2481
882.912	90.1342
883.164	90.2109
883.416	84.4921
883.669	81.6059
883.921	90.467
884.173	78.8602
884.425	96.5078
884.677	84.8179
884.93	87.855
885.182	76.1015
885.434	93.6061
885.686	93.6838
885.938	99.5484
886.19	76.2097
886.442	85.0009
886.694	79.208
886.946	85.1053
887.198	64.7188
887.45	82.4499
887.702	73.6408
887.954	97.3416
888.206	79.7055
888.458	82.7995
888.71	79.8132
888.962	88.7723
889.214	68.088
889.466	85.9268
889.718	74.1235
889.969	83.1486
890.221	74.3218
890.473	83.3269
890.725	77.626
890.977	83.6552
891.228	71.7542
891.48	77.8279
891.732	80.8707
891.983	78.1152
892.235	78.175
892.487	87.3955
892.738	75.5049
892.99	78.6971
893.242	72.6608
893.493	75.7049
893.745	69.7451
893.996	97.176
894.248	72.9795
894.5	76.0167
894.751	63.9987
895.003	82.4734
895.254	61.2617
895.505	67.4572
895.757	73.6696
896.008	79.8924
896.26	67.6938
896.511	67.7575
896.763	67.7581
897.014	80.3038
897.265	71.0851
897.517	64.8446
897.768	58.7462
898.019	86.8112
898.27	68.0715
898.522	71.256
898.773	68.4146
899.024	74.6494
899.275	65.3404
899.527	62.159
899.778	56.1111
899.979	68.6899