File: PL_SCD2_121223_01.txt
#Acq. time (s)=	3
#Accumulations=	2
#Range (nm)=	520...900
#Windows=	16
#Auto scanning=	On
#Autofocus=	Off
#AutoExposure=	Off
#Spike filter=	Multiple accum.
#Delay time (s)=	0
#Binning=	1
#Readout mode=	Signal
#DeNoise=	Off
#ICS correction=	Off
#Dark correction=	Off
#Inst. Process=	Off
#Detector temperature (°C)=	-59.98
#Instrument=	LabRAM HR Evol
#Detector=	Syncerity OE
#Objective=	x50_VIS
#Grating=	600 (500nm)
#ND Filter=	10%
#Laser=	514nm_Edge
#Hole=	199.981
#Range=	Auto
#StageXY=	Marzhauser
#StageZ=	Marzhauser
#X (µm)=	-15436.1
#Y (µm)=	-8975.3
#Z (µm)=	-26.3
#Full time(mm:ss)=	2:39
#Project=
#Sample=
#Site=
#Title=	PL_SCD2_121223
#Remark=
#Date=	21.12.2023 09:51
#Acquired=	21.12.2023 09:51:12
520.042	32
520.304	32.8976
520.565	29.3562
520.827	32.8605
521.089	29.9209
521.351	36.2837
521.612	33.9022
521.874	29.8917
522.136	33.6442
522.397	30.1281
522.659	32.2747
522.921	35.44
523.182	29.3143
523.444	32.6647
523.705	38.8231
523.967	32.5623
524.229	31.6065
524.49	31.3783
524.752	28.6496
525.013	30.135
525.275	29.5274
525.536	32.5041
525.798	35.2573
526.059	37.7322
526.321	31.7218
526.582	33.1548
526.844	32.5967
527.105	34.234
527.367	36.4033
527.628	37
527.889	35.3403
528.151	33
528.412	32.8347
528.674	34.6282
528.935	34.3823
529.196	30.7855
529.458	34.5804
529.719	39.4138
529.98	36
530.242	34.4359
530.503	38.5524
530.764	28.542
531.025	35.4056
531.287	30.9604
531.548	37.042
531.809	31.9977
532.07	32.0233
532.332	31.4301
532.593	39.1352
532.854	38.0909
533.115	36.6713
533.376	33.8648
533.638	34.03
533.899	38.0286
534.16	37.4613
534.421	32.573
534.682	35.5099
534.943	32.0978
535.204	34.928
535.465	35.1862
535.726	31.978
535.987	39.6296
536.248	37.3557
536.509	39.8096
536.77	38.543
537.031	39.777
537.292	27.2603
537.553	39.6517
537.814	37.998
538.075	36.8521
538.336	30.7734
538.597	40.4987
538.858	40.8775
539.119	38.6694
539.38	35.9086
539.641	39.0204
539.901	36.2533
540.162	36.9824
540.423	34.6502
540.684	43.9936
540.945	45.5467
541.205	35.4943
541.466	35.0125
541.727	36.1786
541.988	42.7185
542.248	38.1012
542.509	38.0944
542.77	42.5106
543.031	42.5499
543.291	33.7154
543.552	36.7104
543.813	41.052
544.073	42.593
544.334	39.895
544.594	46.1744
544.855	42.5655
545.116	40.0461
545.376	37.8004
545.637	50.5049
545.897	45.2947
546.158	48.8926
546.418	47.7033
546.679	48.5506
546.898	54.0601
547.159	57.8989
547.42	67.9626
547.681	73.9022
547.942	61.6034
548.203	53.9267
548.464	46.4638
548.725	46.7278
548.987	53.9765
549.248	55.0363
549.509	50.2814
549.77	52.8371
550.031	63.1061
550.292	52.6853
550.553	59.9089
550.814	58.1165
551.075	72.664
551.336	67.3877
551.597	75.9486
551.858	82.9759
552.119	133.597
552.38	407.369
552.641	8647.88
552.901	747.269
553.162	139.028
553.423	87.6574
553.684	68.4263
553.945	73.8022
554.206	66.6939
554.467	60.0561
554.727	64.7743
554.988	61.1136
555.249	60.2532
555.51	64.8419
555.771	61.3265
556.031	68.4306
556.292	67.2339
556.553	61.1811
556.814	71.1768
557.074	69.1354
557.335	73.1953
557.596	64.1545
557.856	73.2943
558.117	74.5107
558.378	71.545
558.638	67.1334
558.899	71.3412
559.16	76.9704
559.42	78.7364
559.681	68.8952
559.941	77.1268
560.202	77.7326
560.463	77.8271
560.723	77.0885
560.984	74.682
561.244	78.9642
561.505	76.0658
561.765	86.7819
562.026	86.7815
562.286	90.7755
562.547	82.6332
562.807	85.6078
563.067	84.9416
563.328	94.0385
563.588	90.2302
563.849	96.8268
564.109	91.221
564.369	96.5828
564.63	95.0322
564.89	97.3093
565.15	100.595
565.411	107.556
565.671	95.5819
565.931	104.551
566.192	103.483
566.452	103.985
566.712	111.57
566.972	105.811
567.232	106.115
567.493	109.023
567.753	112.293
568.013	114.993
568.273	112.806
568.533	125.038
568.794	117.237
569.054	126.059
569.314	127.666
569.574	127.604
569.834	128.678
570.094	134.033
570.354	144.72
570.614	135.18
570.874	139.086
571.134	140.861
571.394	157.697
571.654	152.604
571.914	163.228
572.174	176.51
572.434	178.894
572.694	188.852
572.954	204.544
573.214	220.194
573.459	229.96
573.719	247.811
573.98	259.758
574.241	284.041
574.501	282.922
574.762	330.666
575.022	337.826
575.283	353.634
575.543	350.167
575.804	355.182
576.064	344.826
576.325	329.769
576.585	306.674
576.846	288.023
577.106	299.445
577.366	258.917
577.627	273.779
577.887	254.007
578.148	240.869
578.408	248.804
578.668	233.905
578.929	237.149
579.189	229.225
579.449	246.493
579.71	236.664
579.97	227.611
580.23	235.894
580.49	230.477
580.751	247.211
581.011	241.145
581.271	243.573
581.531	250.705
581.792	247.664
582.052	260.666
582.312	252.855
582.572	263.893
582.832	258.588
583.092	264.532
583.353	272.711
583.613	270.569
583.873	280.052
584.133	278.711
584.393	295.032
584.653	288.716
584.913	301.439
585.173	299.048
585.433	322.716
585.693	307.061
585.953	319.287
586.213	321.43
586.473	328.66
586.733	324.089
586.993	338.126
587.253	329.057
587.513	346.924
587.773	345.245
588.033	343.197
588.293	345.05
588.552	344.469
588.812	345.416
589.072	354.447
589.332	362.297
589.592	356.113
589.852	367.455
590.112	350.233
590.371	360.726
590.631	352.821
590.891	363.417
591.151	344.305
591.41	345.364
591.67	349.333
591.93	336.85
592.189	344.528
592.449	329.975
592.709	336.552
592.968	328.394
593.228	338.313
593.488	327.909
593.747	344
594.007	338.564
594.266	336.091
594.526	341.817
594.786	354.866
595.045	351.473
595.305	336.2
595.564	336.854
595.824	352.594
596.083	358.632
596.343	368.961
596.602	370.533
596.862	364.953
597.121	365.2
597.38	358.803
597.64	350.502
597.899	360.818
598.159	365.191
598.418	351.565
598.677	357.322
598.937	376.185
599.196	364.872
599.455	367.409
599.715	370.59
599.959	393.756
600.219	391.915
600.479	352.903
600.738	364.438
600.998	377.502
601.258	367.781
601.518	387.188
601.778	392.356
602.038	370.683
602.298	376.943
602.558	386.943
602.818	382.19
603.078	373.23
603.337	388.171
603.597	374.931
603.857	390.625
604.117	384.798
604.377	403.397
604.636	382.081
604.896	393.787
605.156	397.739
605.416	394.867
605.675	406.481
605.935	405.059
606.195	387.93
606.455	376.798
606.714	381.759
606.974	385.955
607.234	396.512
607.493	388.622
607.753	403.323
608.012	401.656
608.272	395.832
608.532	394.786
608.791	400.14
609.051	393.119
609.31	408.896
609.57	397.713
609.829	408.744
610.089	403.114
610.348	411.516
610.608	415.146
610.867	414.532
611.127	434.353
611.386	418.246
611.646	424.711
611.905	430.512
612.164	434.916
612.424	416.593
612.683	435.264
612.943	456.117
613.202	431.529
613.461	441.632
613.721	448.495
613.98	451.424
614.239	454.048
614.498	460.692
614.758	473.392
615.017	483.382
615.276	476.294
615.535	473.454
615.795	464.367
616.054	489.791
616.313	493.975
616.572	497.756
616.831	498.53
617.091	504.511
617.35	514.177
617.609	502.676
617.868	511.988
618.127	520.734
618.386	513.101
618.645	532.964
618.904	522.603
619.163	546.24
619.422	553.967
619.681	534.471
619.94	552.708
620.199	543.791
620.458	537.551
620.717	544.967
620.976	564.644
621.235	564.232
621.494	564.252
621.753	567.392
622.012	577.452
622.271	580.558
622.53	589.688
622.788	560.763
623.047	588.559
623.306	587.553
623.565	584.991
623.824	570.726
624.082	582.85
624.341	589.828
624.6	599.669
624.859	602.985
625.117	606.83
625.376	596.132
625.635	598.552
625.893	602.365
626.152	623.78
626.368	613.903
626.627	623.673
626.887	596.45
627.146	625.681
627.405	641.349
627.665	634.006
627.924	625.479
628.183	641.967
628.443	645.499
628.702	625.589
628.961	644.47
629.22	661.688
629.479	676.178
629.739	688.087
629.998	663.056
630.257	690.038
630.516	694.319
630.776	698.835
631.035	700.359
631.294	700.888
631.553	688.733
631.812	710.267
632.071	721.817
632.33	695.22
632.589	719.313
632.848	739.872
633.107	745.889
633.366	757.68
633.625	745.395
633.885	773.63
634.143	780.707
634.403	805.646
634.661	823.866
634.92	821.647
635.179	836.745
635.438	853.436
635.697	889.745
635.956	926.286
636.215	994.891
636.474	1028.74
636.733	1075.62
636.992	1100.5
637.25	1147.54
637.509	1166.58
637.768	1191.03
638.027	1162.62
638.286	1160.63
638.544	1122.83
638.803	1097.06
639.062	1069.41
639.321	1043.84
639.579	1015.38
639.838	1031.01
640.097	990.075
640.356	985.786
640.614	981.9
640.873	991.362
641.131	974.127
641.39	987.226
641.649	966.401
641.907	977.454
642.166	976.464
642.424	987.664
642.683	983.18
642.942	971.986
643.2	992.759
643.459	994.369
643.717	977.576
643.976	997.216
644.234	994.11
644.493	1026.07
644.751	996.047
645.009	1019.22
645.268	1024.09
645.526	1038.27
645.785	1041.25
646.043	1051.68
646.301	1053.61
646.56	1057.6
646.818	1052.65
647.076	1071.97
647.335	1066.02
647.593	1079.63
647.851	1076.71
648.109	1082.01
648.368	1098.3
648.626	1114.06
648.884	1118.36
649.142	1121.57
649.401	1118.93
649.659	1124.82
649.917	1154.9
650.175	1161.05
650.433	1148.93
650.691	1190.08
650.949	1175.75
651.208	1185.79
651.466	1210.39
651.724	1188.25
651.982	1214.68
652.24	1219.41
652.498	1224.86
652.756	1257.62
652.979	1291.84
653.238	1264.5
653.497	1261.07
653.755	1285.99
654.014	1280.11
654.273	1316.44
654.531	1339.02
654.79	1357.29
655.049	1386.14
655.307	1359.96
655.566	1369.94
655.824	1421.29
656.083	1411.89
656.342	1422.73
656.6	1454.38
656.859	1455.91
657.117	1482.25
657.376	1467.4
657.634	1509.53
657.893	1551.03
658.151	1526.09
658.41	1560.9
658.668	1559.15
658.927	1565.35
659.185	1549.23
659.443	1541.79
659.702	1549.07
659.96	1557.08
660.219	1559.14
660.477	1534.88
660.735	1582.26
660.994	1566.7
661.252	1539.49
661.51	1572.3
661.768	1545.88
662.027	1544.89
662.285	1548.46
662.543	1557.54
662.802	1539.81
663.06	1548.57
663.318	1569.13
663.576	1535.2
663.834	1578.78
664.093	1558.8
664.351	1537.32
664.609	1586.02
664.867	1578.53
665.125	1590.24
665.383	1567.73
665.641	1549.73
665.899	1570.18
666.157	1579.02
666.415	1564.61
666.673	1567.82
666.931	1569.55
667.189	1570.83
667.447	1564.94
667.705	1555.39
667.963	1556.16
668.221	1566.03
668.479	1551.24
668.737	1560.02
668.995	1594.01
669.253	1559.98
669.511	1597.23
669.769	1600.05
670.027	1599.85
670.284	1574.49
670.542	1550.94
670.8	1573.76
671.058	1576.29
671.316	1586.91
671.573	1580.78
671.831	1598.75
672.089	1583.91
672.347	1611.17
672.604	1608.42
672.862	1592.09
673.12	1596.61
673.377	1635.62
673.635	1645.03
673.893	1631.98
674.15	1673.47
674.408	1667.26
674.665	1673.91
674.923	1668.71
675.18	1689.38
675.438	1666.22
675.696	1667.77
675.953	1713.77
676.211	1691.79
676.468	1727.81
676.726	1729.05
676.983	1683.88
677.24	1737.72
677.498	1718.81
677.755	1709.58
678.013	1716.49
678.27	1723.59
678.527	1726.8
678.785	1720.81
679.042	1691.72
679.277	1716.14
679.535	1679.55
679.793	1733.79
680.051	1728.55
680.309	1735.7
680.567	1733.54
680.825	1733.91
681.083	1738.09
681.341	1774.53
681.599	1779.92
681.857	1790.95
682.115	1759.43
682.373	1765.83
682.631	1796.08
682.889	1774.02
683.146	1778.93
683.404	1784.52
683.662	1754.92
683.92	1796.18
684.178	1762.32
684.436	1789.44
684.694	1800.11
684.951	1768.59
685.209	1752.13
685.467	1764.39
685.725	1755.88
685.982	1748.71
686.24	1744.93
686.498	1717.16
686.756	1755.67
687.013	1739.46
687.271	1728
687.529	1778.37
687.786	1727.21
688.044	1714.08
688.302	1735.16
688.559	1751.7
688.817	1740.19
689.074	1709.84
689.332	1703.22
689.589	1738.52
689.847	1700.65
690.104	1715.52
690.362	1714.28
690.619	1713.35
690.877	1701.03
691.134	1691.7
691.392	1736.56
691.649	1732.73
691.907	1708.52
692.164	1698.42
692.421	1691.91
692.679	1671.63
692.936	1684.67
693.194	1682.91
693.451	1687.37
693.708	1663.96
693.966	1651.62
694.223	1662.8
694.48	1656.73
694.737	1661.97
694.995	1670.72
695.252	1660.8
695.509	1659.73
695.766	1665.84
696.023	1643.35
696.281	1635.52
696.538	1633.52
696.795	1619.73
697.052	1649.6
697.309	1617.24
697.566	1609.7
697.823	1584.51
698.08	1609.98
698.338	1598.38
698.595	1578.9
698.852	1584.8
699.109	1579.69
699.366	1575.18
699.623	1595.46
699.88	1565.13
700.137	1579.06
700.393	1555.62
700.65	1571.67
700.907	1557.03
701.164	1571.69
701.421	1565.9
701.678	1578.28
701.935	1564.23
702.192	1563.74
702.448	1566.58
702.705	1577.06
702.962	1555.41
703.219	1552.03
703.476	1556.62
703.732	1538.27
703.989	1552.41
704.246	1563.84
704.503	1555.56
704.759	1538.85
705.016	1542.28
705.273	1531.31
705.511	1482.1
705.768	1550.06
706.026	1527.97
706.283	1496.75
706.541	1512.47
706.798	1489.07
707.055	1489.14
707.313	1492.87
707.57	1483.69
707.827	1448.07
708.084	1470.89
708.342	1472.24
708.599	1482.08
708.856	1459.43
709.114	1469.12
709.371	1437.08
709.628	1467.76
709.885	1424.83
710.142	1440.35
710.4	1437.6
710.657	1443.8
710.914	1437.91
711.171	1417.63
711.428	1428.25
711.685	1371.52
711.942	1415.47
712.199	1378.97
712.456	1398.84
712.713	1396.8
712.97	1346.94
713.227	1371.98
713.484	1355.89
713.741	1372.1
713.998	1345.51
714.255	1354.43
714.512	1318.52
714.769	1306.24
715.026	1326.83
715.283	1320
715.54	1295.46
715.797	1286.69
716.054	1298.05
716.31	1282.35
716.567	1286.46
716.824	1278.27
717.081	1249.53
717.338	1260.64
717.594	1256.77
717.851	1273.41
718.108	1296.68
718.365	1248.18
718.621	1255.44
718.878	1257.6
719.135	1246.47
719.391	1234.36
719.648	1237.06
719.905	1222.65
720.161	1209.22
720.418	1200.7
720.675	1224.52
720.931	1176.06
721.188	1184.23
721.444	1182.77
721.701	1194.62
721.957	1157.58
722.214	1161.25
722.47	1175.76
722.727	1156.51
722.983	1150.58
723.24	1149.57
723.496	1137.19
723.753	1142.66
724.009	1123.09
724.265	1125.24
724.522	1101.56
724.778	1090.01
725.034	1126.66
725.291	1124.47
725.547	1104.39
725.803	1117.81
726.06	1067.76
726.316	1094.38
726.572	1087.83
726.828	1103.96
727.085	1087.02
727.341	1076.46
727.597	1069.13
727.853	1069.79
728.109	1055.92
728.366	1047.21
728.622	1024.24
728.878	1026.35
729.134	1035.45
729.39	1020.12
729.646	988.214
729.902	1003.64
730.158	1002.34
730.414	1016.53
730.67	967.233
730.926	962.889
731.182	959.654
731.438	980.371
731.643	950
731.9	932.284
732.156	944.907
732.413	940.544
732.67	972.479
732.927	921.171
733.183	935.813
733.44	918.533
733.697	946.993
733.953	934.062
734.21	886.128
734.466	911.767
734.723	910.184
734.98	921.628
735.236	892.038
735.493	918.225
735.749	909.779
736.006	883.982
736.262	899.441
736.519	902.14
736.775	868.705
737.032	897.938
737.288	881.765
737.544	891.367
737.801	905.532
738.057	875.365
738.314	885.422
738.57	878.761
738.826	871.742
739.083	887.731
739.339	872.07
739.595	891.993
739.852	858.039
740.108	867.411
740.364	866.651
740.621	869.624
740.877	855.339
741.133	852.647
741.389	852.887
741.645	828.285
741.902	842.894
742.158	825.3
742.414	850.16
742.67	824.835
742.926	828.632
743.182	826.899
743.438	813.106
743.694	816.718
743.951	798.012
744.207	817.336
744.463	799.843
744.719	824.359
744.975	793.806
745.231	788.885
745.487	792.55
745.743	786.516
745.998	774.62
746.254	794.293
746.51	779.623
746.766	782.571
747.022	770.777
747.278	756.678
747.534	763.599
747.79	757.951
748.046	759.642
748.301	757.299
748.557	757.678
748.813	750.4
749.069	741.544
749.324	743.078
749.58	759.478
749.836	735.514
750.092	735.458
750.347	751.675
750.603	724.747
750.859	725.311
751.114	714.676
751.37	709.513
751.625	731.115
751.881	698.176
752.137	718.846
752.392	718.114
752.648	704.574
752.903	703.061
753.159	689.047
753.414	688.366
753.67	681.441
753.925	677.527
754.181	674.802
754.436	700.348
754.692	665.254
754.947	632.243
755.202	660.556
755.458	652.494
755.713	677.729
755.968	640.322
756.224	656.417
756.479	649.603
756.734	649.757
756.99	633.895
757.245	633.823
757.5	659.011
757.755	641.696
757.968	600.037
758.224	612.183
758.48	623.766
758.736	606.47
758.992	615.829
759.248	624.68
759.504	595.378
759.76	600.739
760.016	605.209
760.272	593.23
760.528	596.915
760.784	571.964
761.04	576.737
761.296	570.177
761.552	583.637
761.807	575.634
762.063	577.066
762.319	586.516
762.575	586.102
762.831	578.934
763.086	565.64
763.342	547.161
763.598	555.044
763.853	538.346
764.109	528.022
764.365	565.071
764.621	538.261
764.876	546.357
765.132	516.581
765.387	531.377
765.643	532.334
765.899	537.461
766.154	530.625
766.41	512.09
766.665	523.005
766.921	509.267
767.176	519.793
767.432	503.703
767.687	493.721
767.943	495.164
768.198	502.043
768.454	513.514
768.709	478.082
768.965	469.42
769.22	482.369
769.475	479.043
769.731	460.15
769.986	476.304
770.242	466.874
770.497	466.34
770.752	465.389
771.007	460.081
771.263	464.508
771.518	467.111
771.773	443.885
772.028	473.882
772.284	449.172
772.539	443.077
772.794	433.368
773.049	438.66
773.304	430.685
773.56	436.602
773.815	433.395
774.07	437.956
774.325	433.69
774.58	421.039
774.835	443.24
775.09	427.229
775.345	413.575
775.6	409.545
775.855	419.042
776.11	405.032
776.365	400.201
776.62	408.609
776.875	408.757
777.13	397.507
777.385	400.259
777.64	381.531
777.895	375.71
778.149	399.502
778.404	387.482
778.659	384.189
778.914	369.189
779.169	371.903
779.424	375.072
779.678	369.154
779.933	378.229
780.188	370.683
780.442	373.422
780.697	360.278
780.952	355.509
781.207	342.99
781.461	352.989
781.716	364.401
781.97	353.529
782.225	358.392
782.48	349.033
782.734	332.965
782.989	350.664
783.243	349.571
783.498	339.632
783.752	337.62
784.007	330.055
784.253	333.958
784.509	337.912
784.764	341.518
785.019	315.963
785.274	321.813
785.53	306.335
785.785	307.758
786.04	306.329
786.295	297.67
786.551	303.256
786.806	308.385
787.061	294.918
787.316	300.311
787.571	324.463
787.826	297.703
788.081	300.153
788.336	285.205
788.591	300.595
788.847	288.315
789.102	285.589
789.357	279.785
789.612	286.373
789.867	293.905
790.122	271.326
790.377	276.082
790.632	281.846
790.886	276
791.141	275.238
791.396	280.337
791.651	270.016
791.906	266.349
792.161	273.839
792.416	275.807
792.671	257.713
792.925	262.376
793.18	258.953
793.435	251.939
793.69	244.655
793.945	245.589
794.199	241.433
794.454	240.491
794.709	254.506
794.963	246.954
795.218	244.787
795.473	241.591
795.727	247.062
795.982	239.345
796.237	240.786
796.491	234.112
796.746	239.992
797	221.394
797.255	233.572
797.509	221.794
797.764	227.743
798.018	216.912
798.273	224.911
798.527	215.124
798.782	219.312
799.036	214.11
799.291	217.816
799.545	212.341
799.8	214.665
800.054	221.174
800.308	204.641
800.563	199.304
800.817	203.132
801.071	214.978
801.326	211.154
801.58	201.527
801.834	203.354
802.088	192.446
802.343	197.183
802.597	205.198
802.851	195.822
803.105	195.604
803.359	201.436
803.614	188.404
803.868	202.474
804.122	193.483
804.376	188
804.63	205.433
804.884	188.693
805.138	177.185
805.392	186.673
805.646	185.283
805.9	187.71
806.154	175.32
806.408	193.316
806.662	179.024
806.916	183.247
807.17	182.054
807.424	179.664
807.678	176.27
807.932	170.993
808.186	174.086
808.439	168.199
808.693	178.421
808.947	156.948
809.201	176.005
809.455	175.026
809.708	161.941
809.962	162.126
810.183	166
810.438	165.922
810.693	169.83
810.947	156.128
811.202	144.672
811.456	162.18
811.711	158.475
811.965	163.782
812.22	149.082
812.474	156.348
812.729	152.261
812.983	167.36
813.237	161.735
813.492	160.441
813.746	143.571
814.001	136.363
814.255	150.444
814.509	149.521
814.764	157.949
815.018	140.573
815.272	148.198
815.526	154.37
815.781	127.56
816.035	138.208
816.289	149.127
816.543	141.704
816.798	142.265
817.052	135.04
817.306	144.659
817.56	143.222
817.814	142.327
818.068	134.21
818.323	142.34
818.577	131.561
818.831	137.411
819.085	140.732
819.339	138.296
819.593	128.019
819.847	136.811
820.101	133.869
820.355	130.615
820.609	125.986
820.863	126.311
821.117	131.539
821.371	130.081
821.624	131.002
821.878	131.88
822.132	122.439
822.386	130.169
822.64	120.427
822.894	122.758
823.148	119.949
823.401	116.988
823.655	120.191
823.909	134.371
824.163	115.851
824.416	119.924
824.67	115.223
824.924	113.734
825.177	124.828
825.431	116.139
825.685	116.631
825.938	110.157
826.192	114.667
826.446	121.393
826.699	108
826.953	114.616
827.206	111.313
827.46	113.519
827.713	115.391
827.967	109.514
828.22	108.667
828.474	107.993
828.727	104.351
828.981	109.366
829.234	109.502
829.488	105.382
829.741	105.276
829.994	104.71
830.248	109.72
830.501	105.94
830.754	111.583
831.008	106.858
831.261	104.688
831.514	101.321
831.767	101.056
832.021	101.604
832.274	99.3326
832.527	106
832.78	101.977
833.034	100.317
833.287	101.816
833.54	98.0843
833.793	102.033
834.046	90.9325
834.299	96.1004
834.552	103.774
834.805	102.275
835.058	101.984
835.311	96.4803
835.564	96.6476
835.817	96.7337
836.07	96.7786
836.314	95.9959
836.568	101.976
836.821	107.755
837.075	89.9559
837.329	101.327
837.583	92.2843
837.836	86.5517
838.09	97.6264
838.344	99.4864
838.598	101.581
838.851	91.5403
839.105	94.8227
839.359	90.3974
839.612	97.0305
839.866	85.6517
840.119	85.0486
840.373	90.0594
840.627	86.3024
840.88	86.7815
841.134	96.3922
841.387	97.8015
841.641	83.0033
841.894	88.4708
842.148	83.9814
842.401	88.5734
842.655	82.5361
842.908	84.0562
843.161	87.634
843.415	88.5287
843.668	83.7701
843.922	78.6032
844.175	88.9072
844.428	76.2385
844.682	83.8249
844.935	83.2788
845.188	83.043
845.442	84.7667
845.695	74.4287
845.948	85.9152
846.201	85.8178
846.455	83.3962
846.708	70.3306
846.961	75.3364
847.214	83.4579
847.467	74.7285
847.72	85.4512
847.973	79.6129
848.227	73.6651
848.48	83.2525
848.733	71.7426
848.986	73.8243
849.239	80.73
849.492	72.0521
849.745	81.0754
849.998	74.839
850.251	74.4385
850.504	79.1547
850.757	81.6237
851.01	74.5296
851.263	73.5513
851.515	74.5674
851.768	74.7799
852.021	71.221
852.274	73.9185
852.527	75.1918
852.78	74
853.032	75.1396
853.285	68.2136
853.538	76.2436
853.791	70.1747
854.043	71.7646
854.296	68.0634
854.549	68.9432
854.801	65.8607
855.054	77.6934
855.307	71.8508
855.559	66.966
855.812	73.5127
856.065	69.1573
856.317	70.0243
856.57	69.076
856.822	66.0772
857.075	64.0925
857.327	70.6796
857.58	68.3145
857.832	70.9536
858.085	66.2608
858.337	65.3695
858.589	67.5837
858.842	66.9557
859.094	68.0231
859.347	68.8751
859.599	68.867
859.851	65.879
860.104	71.6769
860.356	70.1295
860.608	60.6876
860.861	70.8969
861.113	67.4068
861.365	65.5148
861.617	63.5436
861.869	67.2578
862.112	77.9844
862.365	69.909
862.618	57.9518
862.871	71.6374
863.124	62.1261
863.377	61.8319
863.63	58.3262
863.883	61.7327
864.136	67.4443
864.389	72.9372
864.642	68.1276
864.894	58.1135
865.147	57.2744
865.4	61.8863
865.653	62.3889
865.906	68.5283
866.159	58.1258
866.412	64.2567
866.664	55.1498
866.917	66.1384
867.17	63.1994
867.423	58.0875
867.675	56.5645
867.928	54.1983
868.181	62.9297
868.433	57.8544
868.686	54.635
868.939	59.4717
869.191	53.8807
869.444	55.9314
869.697	65.0663
869.949	65.3575
870.202	62.3595
870.454	61.754
870.707	58
870.959	54.3183
871.212	60.5468
871.464	50.7836
871.717	59.2118
871.969	57.3205
872.222	50.8733
872.474	51.613
872.727	53.996
872.979	52.9649
873.231	54.2517
873.484	60.3331
873.736	55.9761
873.988	54.7655
874.241	49.9679
874.493	51.4714
874.745	52.5918
874.998	54.0078
875.25	51.6519
875.502	54.5227
875.754	53.1418
876.006	52.8503
876.259	52.5923
876.511	54.0175
876.763	47.3977
877.015	49.5254
877.267	49.5146
877.519	54.8638
877.771	56.3538
878.023	52.8755
878.276	50.9886
878.528	53.8279
878.78	55.3165
879.031	51.384
879.284	44.275
879.535	53.5662
879.787	53.9985
880.039	50.368
880.291	46.0136
880.543	52.5337
880.795	48.8991
881.047	49.1973
881.299	51.9242
881.551	47.3016
881.802	54.7106
882.054	47.5053
882.306	53.1161
882.558	46.5313
882.809	44.0112
883.061	47.5517
883.313	45.1301
883.565	53.414
883.816	44.0934
884.068	47.5249
884.319	47.1108
884.571	48.9389
884.823	45.9166
885.074	50.1253
885.326	52.3415
885.577	52.7526
885.829	46
886.08	43.7289
886.332	49.6975
886.583	41.0418
886.835	49.2793
887.086	44.6789
887.338	42.4947
887.589	47.753
887.841	41.9317
888.044	49.9274
888.296	51.8022
888.548	45.819
888.8	47.7437
889.053	44.1335
889.305	42.5198
889.557	42.7277
889.809	47.102
890.061	49.3699
890.313	55.3926
890.566	33.7552
890.818	40.7897
891.07	44.2215
891.322	45.3911
891.574	40.0285
891.826	44.7481
892.078	44.6141
892.33	41.406
892.582	41.3944
892.834	41.9451
893.086	43.2614
893.338	44.3983
893.59	42.7917
893.842	41.2078
894.094	48
894.346	37.0507
894.597	42.9034
894.849	39.1196
895.101	47.8889
895.353	43.0713
895.605	44.6522
895.857	44.8961
896.108	46.2391
896.36	42.8116
896.612	43.2391
896.864	41
897.115	42.1848
897.367	45.1981
897.619	38.9178
897.87	46.5333
898.122	36.4982
898.374	40.2056
898.625	43.4365
898.877	40.5067
899.128	37.2576
899.38	41.6626
899.631	38.0411
899.883	43.5441
899.984	37.7409