File: PL_SCD3_121223_01.txt
#Acq. time (s)=	3
#Accumulations=	2
#Range (nm)=	520...900
#Windows=	16
#Auto scanning=	On
#Autofocus=	Off
#AutoExposure=	Off
#Spike filter=	Multiple accum.
#Delay time (s)=	0
#Binning=	1
#Readout mode=	Signal
#DeNoise=	Off
#ICS correction=	Off
#Dark correction=	Off
#Inst. Process=	Off
#Detector temperature (°C)=	-59.98
#Instrument=	LabRAM HR Evol
#Detector=	Syncerity OE
#Objective=	x50_VIS
#Grating=	600 (500nm)
#ND Filter=	10%
#Laser=	514nm_Edge
#Hole=	199.981
#Range=	Auto
#StageXY=	Marzhauser
#StageZ=	Marzhauser
#X (µm)=	-4700.1
#Y (µm)=	-8959.1
#Z (µm)=	-21.1
#Full time(mm:ss)=	2:39
#Project=
#Sample=
#Site=
#Title=	PL_SCD3_121223
#Remark=
#Date=	21.12.2023 09:54
#Acquired=	21.12.2023 09:54:48
520.042	37
520.304	32.8976
520.565	32.8813
520.827	34.1395
521.089	35
521.351	40.8209
521.612	29.6088
521.874	33.2165
522.136	34.3558
522.397	34.2561
522.659	34
522.921	40.44
523.182	31.2573
523.444	32.3353
523.705	30.8231
523.967	36.8126
524.229	36.3935
524.49	32
524.752	35.1339
525.013	37.908
525.275	35
525.536	38
525.798	36.5145
526.059	36.8033
526.321	38.5565
526.582	35
526.844	33.8065
527.105	32.851
527.367	33.3193
527.628	32.3403
527.889	37
528.151	36.3508
528.412	32
528.674	32.141
528.935	40.1469
529.196	36.1783
529.458	32.7902
529.719	35.5862
529.98	40.2984
530.242	36.5641
530.503	35.3427
530.764	35.6259
531.025	33.8112
531.287	38.5198
531.548	34.958
531.809	33.9977
532.07	37.5117
532.332	38.4767
532.593	38.331
532.854	40.5455
533.115	33.7855
533.376	35.5676
533.638	36.1606
533.899	39.5744
534.16	39.0587
534.421	38.7652
534.682	35.0197
534.943	35.3522
535.204	44.6063
535.465	38.7908
535.726	33.0819
535.987	41.2807
536.248	43.0992
536.509	39.7897
536.77	39.1013
537.031	42.0666
537.292	40
537.553	39.9435
537.814	40.7013
538.075	41.133
538.336	43.6632
538.597	39.1121
538.858	37.423
539.119	42.5695
539.38	44.9154
539.641	40.328
539.901	45.3692
540.162	38.9824
540.423	40.8287
540.684	42.3479
540.945	49.2797
541.205	46.4129
541.466	37.8996
541.727	41.0237
541.988	47.927
542.248	46.6614
542.509	40.3465
542.77	41.409
543.031	53.1219
543.291	44.0978
543.552	51.8835
543.813	40.9682
544.073	53.2925
544.334	51.4132
544.594	48.9142
544.855	46.8434
545.116	48.2021
545.376	52.3284
545.637	52.6526
545.897	48.9103
546.158	66.4263
546.418	55.7419
546.679	50.7468
546.898	50.0327
547.159	49.9961
547.42	60.0507
547.681	54.1955
547.942	54.0314
548.203	63.6538
548.464	54.2579
548.725	61.9337
548.987	65.2926
549.248	76.1326
549.509	51.4001
549.77	58.3309
550.031	58.5253
550.292	70.9674
550.553	71.2062
550.814	78.5257
551.075	68.2784
551.336	90.163
551.597	88.2187
551.858	101.355
552.119	144.628
552.38	388.237
552.641	10364.2
552.901	676.247
553.162	164.266
553.423	103.339
553.684	90.2
553.945	83.1089
554.206	88.3165
554.467	80.6807
554.727	74.1575
554.988	73.8404
555.249	90.425
555.51	75.1581
555.771	74
556.031	81.1595
556.292	81.3021
556.553	87.8138
556.814	86.0316
557.074	87.7798
557.335	90.4644
557.596	92.3463
557.856	92.0227
558.117	92.995
558.378	82.6722
558.638	91.981
558.899	95.1585
559.16	90.8863
559.42	89.0466
559.681	94.9119
559.941	96.9259
560.202	92.1899
560.463	102.139
560.723	92.9036
560.984	98.1595
561.244	107.865
561.505	103.934
561.765	97.4709
562.026	104.731
562.286	113.752
562.547	106.61
562.807	116.233
563.067	120.548
563.328	115.096
563.588	124.912
563.849	115.409
564.109	125.627
564.369	124.546
564.63	120.635
564.89	117.424
565.15	134.488
565.411	140.06
565.671	126.05
565.931	136.382
566.192	137.89
566.452	134.375
566.712	139.675
566.972	143.148
567.232	141.6
567.493	142.978
567.753	147.342
568.013	144.203
568.273	153.317
568.533	161.477
568.794	149.728
569.054	166.569
569.314	158.809
569.574	163.829
569.834	173.953
570.094	169.706
570.354	186.877
570.614	176.484
570.874	191.525
571.134	193.116
571.394	204.464
571.654	193.41
571.914	213.752
572.174	232.219
572.434	242.043
572.694	256.526
572.954	271.359
573.214	282.62
573.459	298.014
573.719	310.044
573.98	336.06
574.241	352.406
574.501	403.208
574.762	403.042
575.022	450.549
575.283	478.175
575.543	496.343
575.804	507.237
576.064	511.063
576.325	484.135
576.585	471.341
576.846	450.868
577.106	430.18
577.366	403.922
577.627	371.238
577.887	364.253
578.148	335.998
578.408	351.909
578.668	319.516
578.929	329.885
579.189	335.352
579.449	328.964
579.71	314.885
579.97	324.004
580.23	322.507
580.49	341.129
580.751	336.948
581.011	338.465
581.271	332.938
581.531	342.658
581.792	344.457
582.052	361.013
582.312	347.014
582.572	356.359
582.832	363.239
583.092	367.715
583.353	368.896
583.613	371.56
583.873	393.065
584.133	383.698
584.393	388.254
584.653	402.145
584.913	413.099
585.173	420.148
585.433	408.141
585.693	424.727
585.953	440.425
586.213	435.885
586.473	437.887
586.733	456.893
586.993	458.557
587.253	427.557
587.513	448.985
587.773	465.352
588.033	474.545
588.293	463.533
588.552	479.612
588.812	472.689
589.072	467.649
589.332	488.432
589.592	486.958
589.852	489.239
590.112	477.1
590.371	482.951
590.631	488.403
590.891	479.979
591.151	475.829
591.41	484.358
591.67	458.589
591.93	460.367
592.189	464.605
592.449	472.253
592.709	471.9
592.968	446.575
593.228	458.096
593.488	461.209
593.747	466.401
594.007	470.554
594.266	471.528
594.526	474.893
594.786	478.295
595.045	468.434
595.305	483.981
595.564	483.887
595.824	496.988
596.083	496.891
596.343	505.683
596.602	523.574
596.862	511.346
597.121	508.393
597.38	508.103
597.64	521.109
597.899	505.033
598.159	514.549
598.418	515.905
598.677	528.764
598.937	511.263
599.196	521.319
599.455	525.892
599.715	537.184
599.959	535.988
600.219	512.112
600.479	542.89
600.738	524.017
600.998	521.851
601.258	528.281
601.518	543.238
601.778	531.996
602.038	554.471
602.298	536.871
602.558	533.776
602.818	539.104
603.078	547.649
603.337	539.65
603.597	552.77
603.857	540.193
604.117	558.146
604.377	576.049
604.636	560.997
604.896	575.043
605.156	569.853
605.416	566.845
605.675	562.481
605.935	551.173
606.195	567.63
606.455	561.361
606.714	550.817
606.974	555.291
607.234	559.696
607.493	554.219
607.753	555.426
608.012	551.119
608.272	568.805
608.532	563.766
608.791	575.908
609.051	565.762
609.31	578.075
609.57	585.279
609.829	578.464
610.089	579.415
610.348	581.474
610.608	590.166
610.867	576.414
611.127	608.404
611.386	594.476
611.646	596.072
611.905	583.16
612.164	599.05
612.424	609.32
612.683	614.409
612.943	615.005
613.202	621.076
613.461	620.913
613.721	633.867
613.98	623.583
614.239	639.046
614.498	639.582
614.758	650.44
615.017	650.803
615.276	659.086
615.535	658
615.795	662.012
616.054	678.938
616.313	687.236
616.572	683.378
616.831	673.752
617.091	700.462
617.35	706.877
617.609	705.948
617.868	713.658
618.127	700.866
618.386	723.616
618.645	707.278
618.904	732.167
619.163	733.157
619.422	727.842
619.681	755.951
619.94	741.814
620.199	746.559
620.458	750.879
620.717	773.546
620.976	781.433
621.235	766.82
621.494	767.66
621.753	764.189
622.012	781.404
622.271	786.969
622.53	780.03
622.788	777.701
623.047	771.253
623.306	773.745
623.565	761.385
623.824	796.411
624.082	772.686
624.341	795.59
624.6	769.751
624.859	793.548
625.117	809.346
625.376	784.738
625.635	823.562
625.893	808.935
626.152	802.468
626.368	790.159
626.627	821.022
626.887	827.365
627.146	825.996
627.405	842.536
627.665	832.758
627.924	843.423
628.183	853.427
628.443	850.082
628.702	867.66
628.961	881.928
629.22	862.439
629.479	852.342
629.739	879.28
629.998	872.514
630.257	903.392
630.516	902.286
630.776	898.358
631.035	908.548
631.294	916.392
631.553	908.796
631.812	928.967
632.071	920.669
632.33	915.608
632.589	914.294
632.848	948.698
633.107	964.851
633.366	943.461
633.625	973.849
633.885	978.28
634.143	994.39
634.403	987.682
634.661	1013.28
634.92	1031.72
635.179	1065.16
635.438	1066.24
635.697	1070.65
635.956	1101.1
636.215	1163.14
636.474	1192.74
636.733	1237.12
636.992	1266.39
637.25	1354.64
637.509	1428.82
637.768	1441.25
638.027	1532.68
638.286	1512.35
638.544	1488.78
638.803	1471.89
639.062	1411.55
639.321	1371.87
639.579	1368.56
639.838	1316.84
640.097	1285.72
640.356	1277.65
640.614	1266.6
640.873	1238.22
641.131	1252.98
641.39	1247.99
641.649	1247.02
641.907	1231.04
642.166	1227.72
642.424	1225.3
642.683	1202.82
642.942	1244.75
643.2	1246.91
643.459	1234.02
643.717	1222.34
643.976	1236.9
644.234	1232.01
644.493	1255.36
644.751	1254
645.009	1263.64
645.268	1268.54
645.526	1301.86
645.785	1291.13
646.043	1283.48
646.301	1309.62
646.56	1297.12
646.818	1284.87
647.076	1306.63
647.335	1319.68
647.593	1332.71
647.851	1304.3
648.109	1341.84
648.368	1337.84
648.626	1390.24
648.884	1363.75
649.142	1361.1
649.401	1381.34
649.659	1412.96
649.917	1399.35
650.175	1421.61
650.433	1409.07
650.691	1416.46
650.949	1427.07
651.208	1443.2
651.466	1472.98
651.724	1455.45
651.982	1460.36
652.24	1474.74
652.498	1477.94
652.756	1512.85
652.979	1500.11
653.238	1510.17
653.497	1491.49
653.755	1560.43
654.014	1558.5
654.273	1550.25
654.531	1583
654.79	1573.62
655.049	1609.15
655.307	1598.04
655.566	1646.35
655.824	1675.12
656.083	1677.74
656.342	1703.46
656.6	1719.76
656.859	1728.28
657.117	1738.95
657.376	1758.23
657.634	1794.73
657.893	1808.19
658.151	1801.03
658.41	1813.05
658.668	1822.45
658.927	1813.68
659.185	1819.4
659.443	1848.6
659.702	1843.67
659.96	1866.36
660.219	1844.52
660.477	1827.3
660.735	1841.65
660.994	1828
661.252	1833.01
661.51	1859.66
661.768	1842.5
662.027	1810
662.285	1861.51
662.543	1861.99
662.802	1865.2
663.06	1852.84
663.318	1854.15
663.576	1833.19
663.834	1872.64
664.093	1851.76
664.351	1853.5
664.609	1828.35
664.867	1839.58
665.125	1856.57
665.383	1834.7
665.641	1847.44
665.899	1861.53
666.157	1855.84
666.415	1845
666.673	1853.88
666.931	1857.99
667.189	1822.42
667.447	1840.1
667.705	1846.63
667.963	1860.93
668.221	1821.01
668.479	1849.15
668.737	1849.58
668.995	1816.06
669.253	1867.9
669.511	1805.7
669.769	1816.47
670.027	1872.97
670.284	1826
670.542	1857.84
670.8	1842.54
671.058	1867.48
671.316	1836.96
671.573	1825.54
671.831	1858.94
672.089	1803.47
672.347	1852.7
672.604	1868.32
672.862	1879.21
673.12	1867.66
673.377	1889.06
673.635	1877.61
673.893	1911.79
674.15	1903.57
674.408	1886
674.665	1916.96
674.923	1961.61
675.18	1939.24
675.438	1952.96
675.696	1981.15
675.953	1969.97
676.211	1965.34
676.468	1959.67
676.726	1967.15
676.983	1949.14
677.24	1972.29
677.498	1974.01
677.755	1945.49
678.013	1957.52
678.27	1961.25
678.527	1951.27
678.785	1981.82
679.042	1969.61
679.277	1991.72
679.535	1985.93
679.793	1961.1
680.051	2003.44
680.309	2004.97
680.567	1983.15
680.825	1962.45
681.083	2018.61
681.341	2022.22
681.599	2022.98
681.857	2030.23
682.115	2031.51
682.373	2032.16
682.631	2075.35
682.889	2022.58
683.146	1984.26
683.404	1990.66
683.662	2055.59
683.92	2076.72
684.178	2068.65
684.436	2012.84
684.694	1993.15
684.951	2005.3
685.209	2041.65
685.467	2010.99
685.725	2023.59
685.982	2020.69
686.24	2018.03
686.498	1967.35
686.756	2007.84
687.013	1960.04
687.271	1932.5
687.529	1982.92
687.786	1967.59
688.044	1984.07
688.302	1998.22
688.559	1948.79
688.817	1944.32
689.074	1998.25
689.332	2005.8
689.589	1985.92
689.847	1966.88
690.104	1976.12
690.362	1961.09
690.619	1949.65
690.877	1965.07
691.134	1929.25
691.392	1931.96
691.649	1927.92
691.907	1921.73
692.164	1917.32
692.421	1910.13
692.679	1901.45
692.936	1882.13
693.194	1883.62
693.451	1901.14
693.708	1909.69
693.966	1906.99
694.223	1888.12
694.48	1886.08
694.737	1884.41
694.995	1859.49
695.252	1874.39
695.509	1885.91
695.766	1847.94
696.023	1844.85
696.281	1860.31
696.538	1867.01
696.795	1860.42
697.052	1820.64
697.309	1822.09
697.566	1804.44
697.823	1793.15
698.08	1796.42
698.338	1810.81
698.595	1786.8
698.852	1786.22
699.109	1787.25
699.366	1773.63
699.623	1767.18
699.88	1799.54
700.137	1750.39
700.393	1760.22
700.65	1738.01
700.907	1751.87
701.164	1768.63
701.421	1772.28
701.678	1791.01
701.935	1725.5
702.192	1770.31
702.448	1759.11
702.705	1752.31
702.962	1754.32
703.219	1760.96
703.476	1768.97
703.732	1768.04
703.989	1753.49
704.246	1741.52
704.503	1735.44
704.759	1711.26
705.016	1735.01
705.273	1715.99
705.511	1706.02
705.768	1690.28
706.026	1697.54
706.283	1705.53
706.541	1681.09
706.798	1653.12
707.055	1641.01
707.313	1664.42
707.57	1656.6
707.827	1638.2
708.084	1648.3
708.342	1629.12
708.599	1629.11
708.856	1579.92
709.114	1626.15
709.371	1634.06
709.628	1600.33
709.885	1617.07
710.142	1627.67
710.4	1573.24
710.657	1588.21
710.914	1583.08
711.171	1584.56
711.428	1580.57
711.685	1543.56
711.942	1566.62
712.199	1540.61
712.456	1556.32
712.713	1543.17
712.97	1555.84
713.227	1518.47
713.484	1518.26
713.741	1514.47
713.998	1497.53
714.255	1493.75
714.512	1489.51
714.769	1463.59
715.026	1492.91
715.283	1455.36
715.54	1429.21
715.797	1480.48
716.054	1414.08
716.31	1422.15
716.567	1409.98
716.824	1436.24
717.081	1433.87
717.338	1414.98
717.594	1418.59
717.851	1417.17
718.108	1411.59
718.365	1391.5
718.621	1415.77
718.878	1402.34
719.135	1392.46
719.391	1372.42
719.648	1351.37
719.905	1342.53
720.161	1365.64
720.418	1339.39
720.675	1355.81
720.931	1345.61
721.188	1341.76
721.444	1325.94
721.701	1305.1
721.957	1314.74
722.214	1289.66
722.47	1269.18
722.727	1285.63
722.983	1276.03
723.24	1277.71
723.496	1250.46
723.753	1252.64
724.009	1230.59
724.265	1248.26
724.522	1253.12
724.778	1241.29
725.034	1210.12
725.291	1239.91
725.547	1225.62
725.803	1220.41
726.06	1221.16
726.316	1210.5
726.572	1167.47
726.828	1201.42
727.085	1178.03
727.341	1190.51
727.597	1193.49
727.853	1186.63
728.109	1169.45
728.366	1152.02
728.622	1146.23
728.878	1134.11
729.134	1147.98
729.39	1119.42
729.646	1099.42
729.902	1117.36
730.158	1077.35
730.414	1065.67
730.67	1077.43
730.926	1064.83
731.182	1061.28
731.438	1058.06
731.643	1056
731.9	1072.12
732.156	1050.2
732.413	1042.72
732.67	1025.61
732.927	1060.21
733.183	1024.04
733.44	1026.33
733.697	1042.79
733.953	1013.42
734.21	1028.99
734.466	1012.13
734.723	990.251
734.98	1007.71
735.236	1018.08
735.493	991.679
735.749	1001.97
736.006	976.002
736.262	959.845
736.519	981.996
736.775	979.922
737.032	994.42
737.288	997.956
737.544	979.623
737.801	976.724
738.057	944.949
738.314	991.892
738.57	969.276
738.826	980.424
739.083	947.789
739.339	972.558
739.595	956.179
739.852	949.255
740.108	970.609
740.364	928.588
740.621	937.533
740.877	933.214
741.133	949.704
741.389	936.033
741.645	905.33
741.902	910.431
742.158	918.438
742.414	929.137
742.67	903.505
742.926	896.029
743.182	918.38
743.438	871.517
743.694	865.487
743.951	874.61
744.207	877.374
744.463	870.477
744.719	860.115
744.975	878.211
745.231	863.217
745.487	861.842
745.743	846.121
745.998	840.838
746.254	833.494
746.51	836.244
746.766	830.584
747.022	824.594
747.278	835.598
747.534	836.64
747.79	819.849
748.046	817.274
748.301	833.969
748.557	812.309
748.813	811.789
749.069	823.197
749.324	797.615
749.58	815.62
749.836	814.528
750.092	804.63
750.347	781.744
750.603	797.38
750.859	798.32
751.114	780.352
751.37	784.266
751.625	762.369
751.881	759.433
752.137	759.566
752.392	773.36
752.648	747.298
752.903	763.308
753.159	765.521
753.414	758.274
753.67	750.542
753.925	726.834
754.181	750.398
754.436	716.369
754.692	714.327
754.947	716.131
755.202	737.34
755.458	717.136
755.713	679.901
755.968	683.486
756.224	697.267
756.479	695.289
756.734	698.857
756.99	688.19
757.245	687.259
757.5	677.756
757.755	678.957
757.968	675.982
758.224	681.914
758.48	663.351
758.736	654.472
758.992	685.216
759.248	642.762
759.504	654.303
759.76	635.651
760.016	642.133
760.272	645.195
760.528	653.468
760.784	636.124
761.04	618.171
761.296	618.558
761.552	627.149
761.807	611.565
762.063	627.382
762.319	616.412
762.575	618.416
762.831	600.819
763.086	591.375
763.342	593.973
763.598	560.874
763.853	570.752
764.109	578.883
764.365	567.217
764.621	584.659
764.876	574.885
765.132	574.039
765.387	566.076
765.643	554.953
765.899	547.942
766.154	548.053
766.41	554.558
766.665	545.711
766.921	543.75
767.176	556.214
767.432	543.703
767.687	537.582
767.943	553.272
768.198	530.666
768.454	525.853
768.709	511.185
768.965	504.06
769.22	519.387
769.475	501.317
769.731	505.613
769.986	501.643
770.242	507.185
770.497	514.328
770.752	483.314
771.007	499.876
771.263	498.674
771.518	473.341
771.773	492.449
772.028	511.352
772.284	489.502
772.539	479.962
772.794	486.929
773.049	465.855
773.304	474.462
773.56	447.151
773.815	464.624
774.07	462.635
774.325	457.42
774.58	455.249
774.835	461.694
775.09	442.542
775.345	456.565
775.6	451.436
775.855	441.725
776.11	435.223
776.365	423.982
776.62	419.926
776.875	413.696
777.13	417.048
777.385	420.007
777.64	406.174
777.895	408.693
778.149	403.231
778.404	407.219
778.659	414.747
778.914	402.077
779.169	392.599
779.424	397.567
779.678	389.023
779.933	385.583
780.188	380.955
780.442	376.531
780.697	371.534
780.952	380.956
781.207	385.368
781.461	386.404
781.716	381.377
781.97	371.212
782.225	343.911
782.48	369.298
782.734	350.725
782.989	362.252
783.243	353.505
783.498	357.017
783.752	346.507
784.007	358.812
784.253	357.968
784.509	344.235
784.764	347.725
785.019	353.796
785.274	348.867
785.53	345.487
785.785	337.351
786.04	323.745
786.295	323.676
786.551	327.027
786.806	335.104
787.061	313.71
787.316	330.786
787.571	320.783
787.826	321.992
788.081	317.069
788.336	329.175
788.591	308.938
788.847	304.937
789.102	305.293
789.357	308.186
789.612	307.01
789.867	298.721
790.122	302.267
790.377	299.378
790.632	287.252
790.886	286.175
791.141	307.899
791.396	282.775
791.651	278.804
791.906	273.016
792.161	284.457
792.416	268.511
792.671	267.784
792.925	275.178
793.18	282.477
793.435	267.766
793.69	276.601
793.945	277.547
794.199	266.944
794.454	266.52
794.709	256.487
794.963	258.268
795.218	261.931
795.473	257.228
795.727	248.843
795.982	249.271
796.237	261.633
796.491	253.051
796.746	244.429
797	244.984
797.255	243.795
797.509	241.932
797.764	233.082
798.018	239.905
798.273	243.684
798.527	232.419
798.782	230.583
799.036	243.767
799.291	234.393
799.545	226
799.8	232.611
800.054	228.362
800.308	223.787
800.563	214.334
800.817	217.899
801.071	212.669
801.326	212.459
801.58	206.022
801.834	220.475
802.088	221.157
802.343	205.999
802.597	209.958
802.851	213.774
803.105	215.232
803.359	206.169
803.614	205.3
803.868	212.812
804.122	197.87
804.376	195.472
804.63	189.418
804.884	182.843
805.138	205.424
805.392	196.751
805.646	199.831
805.9	191.753
806.154	189.895
806.408	187.34
806.662	181.791
806.916	194.223
807.17	193.313
807.424	181.124
807.678	186.296
807.932	182.838
808.186	172.138
808.439	188.457
808.693	177.643
808.947	196.579
809.201	185.912
809.455	184.252
809.708	178.059
809.962	180.71
810.183	180
810.438	162.147
810.693	175.784
810.947	171.73
811.202	175.649
811.456	171.628
811.711	175.654
811.965	171.617
812.22	171.051
812.474	158.523
812.729	161.207
812.983	153.902
813.237	158.409
813.492	161.891
813.746	161.717
814.001	163.217
814.255	163.511
814.509	161.272
814.764	159.498
815.018	147.276
815.272	138.72
815.526	149.614
815.781	148.366
816.035	142.928
816.289	147.614
816.543	141.301
816.798	138.027
817.052	157.348
817.306	145.092
817.56	149.19
817.814	148.751
818.068	142.047
818.323	141.456
818.577	139.561
818.831	147.484
819.085	129.21
819.339	145.807
819.593	146.038
819.847	132.811
820.101	144.609
820.355	138.973
820.609	138.954
820.863	129.007
821.117	136.04
821.371	133.53
821.624	124.466
821.878	131.211
822.132	121.095
822.386	124.281
822.64	120.543
822.894	129.67
823.148	124.317
823.401	124.031
823.655	123.967
823.909	125.176
824.163	118.277
824.416	128.148
824.67	126.323
824.924	120.456
825.177	125.382
825.431	114.731
825.685	126.063
825.938	120.889
826.192	119.489
826.446	122.152
826.699	121.815
826.953	113.581
827.206	117.171
827.46	115.657
827.713	115.197
827.967	111.765
828.22	120.424
828.474	111.584
828.727	118.83
828.981	111.88
829.234	113.659
829.488	111.397
829.741	116.415
829.994	109.284
830.248	105.659
830.501	114.066
830.754	110.834
831.008	104.053
831.261	110.716
831.514	109.567
831.767	111.641
832.021	109.111
832.274	102.658
832.527	103.9
832.78	100.045
833.034	105.355
833.287	102.359
833.54	109.723
833.793	101.529
834.046	105.302
834.299	105.933
834.552	104.373
834.805	106.897
835.058	104.525
835.311	105.123
835.564	96.473
835.817	97.9828
836.07	99.2354
836.314	88.0273
836.568	92.0266
836.821	93.8569
837.075	95.7621
837.329	90.283
837.583	99.5608
837.836	97.5454
838.09	94.3253
838.344	97.6543
838.598	90.7437
838.851	99.0727
839.105	90.2951
839.359	98.6398
839.612	93.8341
839.866	86.8395
840.119	100.086
840.373	105.708
840.627	98.7523
840.88	89.4143
841.134	96.4289
841.387	87.102
841.641	88.734
841.894	90.2581
842.148	99.431
842.401	81.103
842.655	87.5673
842.908	89.4279
843.161	78.4579
843.415	95.0015
843.668	79.2473
843.922	78.5628
844.175	84.8397
844.428	84.2256
844.682	82.8718
844.935	82.6575
845.188	75.8062
845.442	88.1327
845.695	83.6731
845.948	84.9802
846.201	83.8813
846.455	81.8228
846.708	83.1129
846.961	77.1722
847.214	82.1548
847.467	83.1763
847.72	79.155
847.973	86.1296
848.227	80.3712
848.48	76.0881
848.733	76.5546
848.986	75.68
849.239	78.8959
849.492	75.9318
849.745	79.9104
849.998	73.9016
850.251	74.0156
850.504	77.2523
850.757	81.6483
851.01	77.5919
851.263	78.7118
851.515	69.6493
851.768	71.8539
852.021	70.7318
852.274	73.4087
852.527	80.7744
852.78	67.1115
853.032	75.9798
853.285	74.7009
853.538	76.6734
853.791	78.4692
854.043	72.4971
854.296	80.3718
854.549	73.0517
854.801	70.7342
855.054	70.4642
855.307	67.9689
855.559	68.1084
855.812	75.8341
856.065	74.8157
856.317	76.5956
856.57	68.2333
856.822	69.182
857.075	72.1454
857.327	73.9698
857.58	65.1573
857.832	68.6771
858.085	69.9227
858.337	69.2137
858.589	69.0361
858.842	65.9859
859.094	74.0907
859.347	65.1979
859.599	65.9475
859.851	64.669
860.104	64.4416
860.356	71.3392
860.608	59.832
860.861	65.9857
861.113	71.3305
861.365	67.8865
861.617	59.3064
861.869	62.6741
862.112	71.9941
862.365	62.0295
862.618	62.0409
862.871	65.9372
863.124	71.4743
863.377	65.7831
863.63	56.3031
863.883	76.4036
864.136	60.5617
864.389	60.2683
864.642	61.1201
864.894	70.6911
865.147	62.1465
865.4	65.8863
865.653	66.7441
865.906	65.5558
866.159	68.9327
866.412	60.3085
866.664	61.0723
866.917	69.0157
867.17	65.8581
867.423	51.6556
867.675	69.4448
867.928	61.0994
868.181	54.9396
868.433	55.3058
868.686	62.6
868.939	67.7287
869.191	57.8807
869.444	57.6949
869.697	60.2601
869.949	57.6113
870.202	53.5688
870.454	58.5795
870.707	58.5884
870.959	64.1604
871.212	52.7037
871.464	57.2768
871.717	56.0456
871.969	54.6942
872.222	51.5634
872.474	63.9469
872.727	56.002
872.979	54.2768
873.231	56.1567
873.484	60.3965
873.736	56.4412
873.988	48.667
874.241	54.31
874.493	58.3929
874.745	53.7782
874.998	57.1427
875.25	53.0156
875.502	50.9649
875.754	52.6221
876.006	48.7834
876.259	51.9399
876.511	58.0827
876.763	49.4958
877.015	49.9654
877.267	56.9613
877.519	53.6578
877.771	50.3762
878.023	54.6199
878.276	49.3097
878.528	53.462
878.78	48.9131
879.031	50.2275
879.284	55.6025
879.535	49.9482
879.787	52.0994
880.039	49.8421
880.291	56.1184
880.543	54.5751
880.795	50.3935
881.047	47.7496
881.299	44.8338
881.551	52.1053
881.802	48.2773
882.054	51.7078
882.306	57.1421
882.558	52.2709
882.809	46.0376
883.061	48.7089
883.313	49.1301
883.565	49.8543
883.816	45.6377
884.068	48.7401
884.319	52.8988
884.571	56.0778
884.823	50.7127
885.074	46.0345
885.326	53.7795
885.577	45.1002
885.829	48.7478
886.08	51.0476
886.332	50.5156
886.583	49.1336
886.835	46.6034
887.086	44.5657
887.338	47.717
887.589	42.3057
887.841	44.0887
888.044	49.9383
888.296	51.8335
888.548	49.9224
888.8	40.3083
889.053	47.9385
889.305	48.1655
889.557	52.6485
889.809	38.9102
890.061	44.361
890.313	45.9213
890.566	41.2657
890.818	42.1014
891.07	46.4369
891.322	43.5024
891.574	44.1418
891.826	43.4908
892.078	43.6596
892.33	43.5779
892.582	40.8676
892.834	43.0143
893.086	40.0062
893.338	43.6937
893.59	45.9249
893.842	47.1613
894.094	42.971
894.346	41.0254
894.597	41.9517
894.849	45.1196
895.101	45.8889
895.353	39.2854
895.605	42.913
895.857	41.4155
896.108	46.5217
896.36	36.8647
896.612	45.6957
896.864	41.5042
897.115	42.5543
897.367	44.599
897.619	45.2164
897.87	43.7666
898.122	39.9927
898.374	45.7352
898.625	45.7183
898.877	42.7013
899.128	35.5719
899.38	41.3434
899.631	43.653
899.883	43.364
899.984	40.4068