File: PL_SCD1_121223_01.txt
#Acq. time (s)=	3
#Accumulations=	2
#Range (nm)=	520...900
#Windows=	16
#Auto scanning=	On
#Autofocus=	Off
#AutoExposure=	Off
#Spike filter=	Multiple accum.
#Delay time (s)=	0
#Binning=	1
#Readout mode=	Signal
#DeNoise=	Off
#ICS correction=	Off
#Dark correction=	Off
#Inst. Process=	Off
#Detector temperature (°C)=	-59.98
#Instrument=	LabRAM HR Evol
#Detector=	Syncerity OE
#Objective=	x50_VIS
#Grating=	600 (500nm)
#ND Filter=	10%
#Laser=	514nm_Edge
#Hole=	199.981
#Range=	Auto
#StageXY=	Marzhauser
#StageZ=	Marzhauser
#X (µm)=	-26126.2
#Y (µm)=	-8975.3
#Z (µm)=	0.8
#Full time(mm:ss)=	2:32
#Project=
#Sample=
#Site=
#Title=	PL_SCD1_121223
#Remark=
#Date=	21.12.2023 09:42
#Acquired=	21.12.2023 09:42:55
520.042	36
520.304	41.8976
520.565	37.1781
520.827	39.7209
521.089	45.7628
521.351	42.6419
521.612	41.7066
521.874	42.3248
522.136	41.7116
522.397	35.3842
522.659	37.4121
522.921	42.1467
523.182	43.8428
523.444	41.6647
523.705	41.3539
523.967	41.8126
524.229	49.4098
524.49	38
524.752	42.2165
525.013	40.773
525.275	43.291
525.536	42.248
525.798	40.7718
526.059	43.7322
526.321	45.7218
526.582	42.4435
526.844	43
527.105	42
527.367	43.3193
527.628	40.6492
527.889	45
528.151	41
528.412	40.5565
528.674	41.859
528.935	41.7063
529.196	40.1783
529.458	45.1772
529.719	39.5862
529.98	46.1713
530.242	44.4359
530.503	47.7622
530.764	41.0839
531.025	39.5944
531.287	41.5198
531.548	47
531.809	43.5035
532.07	49.465
532.332	45.5233
532.593	43.7366
532.854	43.5455
533.115	39.5571
533.376	45.4324
533.638	44.859
533.899	48.0811
534.16	45.3439
534.421	42.5489
534.682	42.8815
534.943	50.7569
535.204	47.5343
535.465	45.4035
535.726	45.9639
535.987	54.4129
536.248	50.3695
536.509	45.5795
536.77	44.6267
537.031	50.0333
537.292	49.2818
537.553	48.7103
537.814	46.7033
538.075	50.9925
538.336	46.3368
538.597	48.8329
538.858	44
539.119	48.5316
539.38	48.1269
539.641	49.5507
539.901	48.3005
540.162	55.5915
540.423	54.9782
540.684	54.6082
540.945	49.1528
541.205	51.6462
541.466	42.5437
541.727	42.876
541.988	47.1256
542.248	52.7432
542.509	42.3628
542.77	54.4867
543.031	49.1037
543.291	49.9022
543.552	51.8889
543.813	51.5454
544.073	47.8889
544.334	51.7694
544.594	50.7926
544.855	56.5265
545.116	56.4775
545.376	58.1708
545.637	56.0802
545.897	59.7168
546.158	51.4915
546.418	49.8064
546.679	58.0847
546.898	57.8987
547.159	56.0826
547.42	63.6969
547.681	55.9613
547.942	59.9391
548.203	52.0401
548.464	65.5623
548.725	57.7036
548.987	61.5581
549.248	52.866
549.509	68.939
549.77	58.8652
550.031	74.1477
550.292	59.3094
550.553	66.4068
550.814	76.0597
551.075	73.3102
551.336	71.7996
551.597	88.8101
551.858	110.489
552.119	159.622
552.38	427.221
552.641	10573.6
552.901	795.018
553.162	161.056
553.423	108.478
553.684	97.8286
553.945	89.3386
554.206	73.7218
554.467	78.656
554.727	71.7061
554.988	70.7735
555.249	71.1225
555.51	71.7556
555.771	65.8216
556.031	78.7101
556.292	69.5638
556.553	76.5031
556.814	75.2863
557.074	77.9043
557.335	75.9604
557.596	79.7421
557.856	78.3301
558.117	81.6658
558.378	79.1106
558.638	85.502
558.899	83.4312
559.16	80.4245
559.42	87.0321
559.681	83.7716
559.941	83.1229
560.202	89.6122
560.463	84.1824
560.723	89.8935
560.984	89.1195
561.244	92.8373
561.505	94.0177
561.765	91.7237
562.026	90.3948
562.286	99.3503
562.547	98.0408
562.807	92.4319
563.067	99.746
563.328	103.803
563.588	110.036
563.849	114.356
564.109	125.96
564.369	114
564.63	113.457
564.89	110.859
565.15	109.091
565.411	108.669
565.671	113.964
565.931	105.593
566.192	113.772
566.452	108.527
566.712	115.848
566.972	118.797
567.232	116.569
567.493	116.753
567.753	118.499
568.013	125.963
568.273	127.692
568.533	122.227
568.794	123.01
569.054	130.951
569.314	123.786
569.574	125.392
569.834	125.381
570.094	140.33
570.354	140.925
570.614	138.643
570.874	152.485
571.134	152.115
571.394	149.458
571.654	160.684
571.914	170.395
572.174	168.159
572.434	181.743
572.694	178.756
572.954	185.895
573.214	201.352
573.459	227.719
573.719	231.692
573.98	241.939
574.241	254.247
574.501	284.934
574.762	272.968
575.022	305.647
575.283	348.982
575.543	337.888
575.804	329.041
576.064	331.464
576.325	342.129
576.585	325.131
576.846	316.756
577.106	291.221
577.366	283.909
577.627	264.434
577.887	253.047
578.148	257.751
578.408	244.126
578.668	236.568
578.929	235.088
579.189	246.004
579.449	260.293
579.71	255.223
579.97	255.198
580.23	248.796
580.49	252.75
580.751	255.46
581.011	244
581.271	246.191
581.531	245.978
581.792	258.147
582.052	261.26
582.312	256.357
582.572	258.21
582.832	276.802
583.092	270.737
583.353	271.286
583.613	272.371
583.873	268.935
584.133	277.88
584.393	302.103
584.653	295.718
584.913	300.883
585.173	303.26
585.433	314.427
585.693	316.242
585.953	317.007
586.213	324.973
586.473	309.695
586.733	314.365
586.993	338.194
587.253	328.387
587.513	325.06
587.773	336.116
588.033	329.661
588.293	348.387
588.552	347.383
588.812	343.501
589.072	352.231
589.332	348.361
589.592	361.345
589.852	357.581
590.112	354.743
590.371	358.682
590.631	338.806
590.891	351.259
591.151	345.585
591.41	321.279
591.67	329.36
591.93	327.791
592.189	330.566
592.449	334.605
592.709	325.613
592.968	329.828
593.228	332.82
593.488	335.254
593.747	325.227
594.007	332.118
594.266	332.966
594.526	324.427
594.786	349.856
595.045	341.353
595.305	342.63
595.564	338.266
595.824	350.198
596.083	354.875
596.343	347.852
596.602	366.959
596.862	370.653
597.121	347.791
597.38	342.47
597.64	349.902
597.899	361.833
598.159	347.877
598.418	344.311
598.677	349.223
598.937	348.58
599.196	356.928
599.455	353.359
599.715	365.053
599.959	355.911
600.219	344.105
600.479	365.676
600.738	355.17
600.998	367.756
601.258	341.538
601.518	365.621
601.778	367.553
602.038	376.298
602.298	365.166
602.558	365.57
602.818	366.694
603.078	364.387
603.337	375.876
603.597	377.301
603.857	370.409
604.117	371.046
604.377	388.873
604.636	382.348
604.896	376.734
605.156	378.122
605.416	362.485
605.675	364.429
605.935	368.377
606.195	365.916
606.455	387.492
606.714	359.137
606.974	385.723
607.234	374.195
607.493	388.882
607.753	390.91
608.012	388.373
608.272	385.188
608.532	389.98
608.791	374.11
609.051	381.66
609.31	378.179
609.57	382.434
609.829	398.742
610.089	386.419
610.348	401.634
610.608	394
610.867	392.438
611.127	400.467
611.386	399.454
611.646	405.618
611.905	407.334
612.164	398.598
612.424	410.206
612.683	404.414
612.943	402.295
613.202	423.374
613.461	415.477
613.721	438.162
613.98	410.566
614.239	427.992
614.498	430.042
614.758	432.113
615.017	422.58
615.276	419.492
615.535	444.959
615.795	427.403
616.054	448.089
616.313	449.023
616.572	452.429
616.831	456.808
617.091	459.969
617.35	447.742
617.609	464.07
617.868	481.96
618.127	466.191
618.386	470.272
618.645	476.326
618.904	476.32
619.163	483.954
619.422	488.487
619.681	498.854
619.94	486.345
620.199	506.746
620.458	486.44
620.717	514.772
620.976	508.734
621.235	509.452
621.494	510.121
621.753	485.327
622.012	497.096
622.271	507.54
622.53	503.864
622.788	518.578
623.047	528.613
623.306	502.867
623.565	514.406
623.824	517.531
624.082	515.276
624.341	542.531
624.6	527.782
624.859	509.465
625.117	532.219
625.376	503.879
625.635	521.476
625.893	542.175
626.152	544.888
626.368	520.068
626.627	569.336
626.887	525.544
627.146	554.928
627.405	523.458
627.665	560.439
627.924	556.188
628.183	529.7
628.443	556.62
628.702	551.014
628.961	568.108
629.22	562.442
629.479	577.021
629.739	555.467
629.998	581.276
630.257	575.197
630.516	577.443
630.776	571.095
631.035	574.683
631.294	578.767
631.553	601.839
631.812	602.18
632.071	587.033
632.33	603.828
632.589	590.177
632.848	610.268
633.107	611.816
633.366	620.746
633.625	624.675
633.885	609.177
634.143	641.691
634.403	634.749
634.661	641.466
634.92	654.876
635.179	652.59
635.438	649.4
635.697	711.956
635.956	723.249
636.215	737.068
636.474	775.275
636.733	800.38
636.992	812.014
637.25	860.018
637.509	888.586
637.768	929.907
638.027	928.906
638.286	935.537
638.544	943.231
638.803	903.289
639.062	873.213
639.321	860.833
639.579	842.896
639.838	818.55
640.097	804.251
640.356	800.062
640.614	794.354
640.873	779.309
641.131	773.499
641.39	777.806
641.649	773.168
641.907	783.43
642.166	771.003
642.424	753.65
642.683	789.162
642.942	765.513
643.2	770.214
643.459	767.917
643.717	771.69
643.976	787.363
644.234	783.342
644.493	787.237
644.751	789.975
645.009	795.907
645.268	822.497
645.526	793.788
645.785	810.118
646.043	814.711
646.301	822.81
646.56	786.869
646.818	809.962
647.076	810.747
647.335	831.663
647.593	847.231
647.851	849.6
648.109	819.547
648.368	825.785
648.626	862.779
648.884	848.385
649.142	846.669
649.401	850.752
649.659	864.31
649.917	888.655
650.175	868.436
650.433	890.306
650.691	912.138
650.949	912.626
651.208	909.105
651.466	901.029
651.724	922.015
651.982	913.379
652.24	915.954
652.498	915.974
652.756	918.21
652.979	934.25
653.238	961.779
653.497	938.759
653.755	979.808
654.014	978.69
654.273	975.286
654.531	939.703
654.79	1005.22
655.049	1011.07
655.307	1021.96
655.566	1020.5
655.824	1042
656.083	1050.85
656.342	1067.33
656.6	1055.54
656.859	1046.18
657.117	1076.31
657.376	1084.14
657.634	1115.17
657.893	1121.41
658.151	1092.87
658.41	1088.64
658.668	1124.85
658.927	1156.51
659.185	1124.2
659.443	1126.22
659.702	1152.89
659.96	1137.83
660.219	1147.61
660.477	1145.57
660.735	1153.1
660.994	1139.56
661.252	1162.85
661.51	1159.12
661.768	1138.86
662.027	1160.14
662.285	1129.09
662.543	1151.46
662.802	1148.76
663.06	1135.46
663.318	1117.27
663.576	1131.97
663.834	1133.04
664.093	1152.77
664.351	1124.75
664.609	1139.17
664.867	1157.28
665.125	1122.98
665.383	1126.11
665.641	1146.89
665.899	1136.18
666.157	1150.06
666.415	1153.94
666.673	1128.31
666.931	1129.92
667.189	1118.51
667.447	1124.83
667.705	1151.98
667.963	1128.64
668.221	1146.11
668.479	1112.02
668.737	1157.85
668.995	1140.73
669.253	1118.53
669.511	1126.45
669.769	1133.29
670.027	1148.82
670.284	1156.23
670.542	1133.61
670.8	1163.39
671.058	1117.08
671.316	1149.31
671.573	1135.49
671.831	1132.79
672.089	1137.18
672.347	1124.99
672.604	1127.28
672.862	1155.3
673.12	1140.9
673.377	1171.46
673.635	1183.94
673.893	1158.74
674.15	1173.5
674.408	1182.32
674.665	1214.47
674.923	1181.68
675.18	1193.31
675.438	1188.53
675.696	1209.48
675.953	1204.05
676.211	1201.49
676.468	1207.14
676.726	1212.27
676.983	1225.51
677.24	1214.79
677.498	1220.04
677.755	1221.45
678.013	1215.36
678.27	1227.91
678.527	1227.69
678.785	1222.09
679.042	1236.27
679.277	1202.45
679.535	1179.57
679.793	1232.82
680.051	1224.91
680.309	1216.57
680.567	1214.43
680.825	1211.49
681.083	1259.03
681.341	1274.29
681.599	1256.08
681.857	1246.46
682.115	1235.17
682.373	1252.31
682.631	1255.58
682.889	1270.22
683.146	1243.66
683.404	1275.43
683.662	1268.2
683.92	1268.97
684.178	1282.21
684.436	1243.22
684.694	1269.39
684.951	1239.87
685.209	1249.57
685.467	1243.61
685.725	1283.62
685.982	1254.42
686.24	1229.25
686.498	1242.8
686.756	1261.81
687.013	1224.11
687.271	1209.65
687.529	1243.35
687.786	1220.17
688.044	1196.56
688.302	1208.65
688.559	1248.58
688.817	1215.25
689.074	1221.24
689.332	1235.87
689.589	1216.73
689.847	1229.27
690.104	1214.26
690.362	1236.79
690.619	1220.52
690.877	1246.11
691.134	1199.68
691.392	1192.44
691.649	1200.71
691.907	1187.33
692.164	1197.47
692.421	1177.67
692.679	1187.99
692.936	1193.99
693.194	1178.56
693.451	1215.12
693.708	1172.46
693.966	1156.73
694.223	1196.56
694.48	1159.35
694.737	1148.02
694.995	1157.44
695.252	1176.84
695.509	1157.97
695.766	1169.46
696.023	1151.94
696.281	1150.76
696.538	1143.02
696.795	1138.2
697.052	1150.75
697.309	1144.41
697.566	1140.92
697.823	1136.92
698.08	1102.73
698.338	1124.77
698.595	1123.15
698.852	1127.57
699.109	1128.57
699.366	1102.79
699.623	1104.75
699.88	1102.12
700.137	1103.61
700.393	1102.65
700.65	1093
700.907	1100
701.164	1117.86
701.421	1097.86
701.678	1096.3
701.935	1092.15
702.192	1085.47
702.448	1091.26
702.705	1076.98
702.962	1086.76
703.219	1086.58
703.476	1116.11
703.732	1096.96
703.989	1094.83
704.246	1088.19
704.503	1073.73
704.759	1073.75
705.016	1068.83
705.273	1065.98
705.511	1074.03
705.768	1042.94
706.026	1033.14
706.283	1052.82
706.541	1018.73
706.798	1038.15
707.055	1038.12
707.313	1045.44
707.57	1064.49
707.827	1047.81
708.084	997.038
708.342	1023.9
708.599	1002.68
708.856	1024.96
709.114	1032.14
709.371	1022.28
709.628	1024.68
709.885	1024.8
710.142	1007.57
710.4	1009.3
710.657	1048.32
710.914	975.173
711.171	993.924
711.428	994.504
711.685	997.25
711.942	987.737
712.199	990.87
712.456	979.762
712.713	978.755
712.97	957.525
713.227	936.652
713.484	955.327
713.741	956.47
713.998	943.026
714.255	938.74
714.512	928.042
714.769	943.682
715.026	924.198
715.283	895.759
715.54	913.777
715.797	890.967
716.054	904.525
716.31	924.574
716.567	892.174
716.824	913.173
717.081	902.259
717.338	902.248
717.594	894.128
717.851	885.284
718.108	880.345
718.365	902.307
718.621	877.274
718.878	850.073
719.135	874.695
719.391	878.464
719.648	872.079
719.905	853.619
720.161	858.823
720.418	840.15
720.675	840.012
720.931	818.753
721.188	827.781
721.444	831.511
721.701	832.889
721.957	830.511
722.214	824.626
722.47	824.425
722.727	809.232
722.983	808.654
723.24	811.155
723.496	810.419
723.753	799.62
724.009	796.82
724.265	801.682
724.522	793.177
724.778	780.06
725.034	794.746
725.291	779.067
725.547	790.674
725.803	770.879
726.06	780.593
726.316	759.449
726.572	767.154
726.828	779.922
727.085	749.89
727.341	768.721
727.597	734.69
727.853	749.757
728.109	736.727
728.366	732.02
728.622	718.951
728.878	733.355
729.134	728.33
729.39	708.598
729.646	712.608
729.902	706.57
730.158	718.953
730.414	687.057
730.67	667.176
730.926	724.764
731.182	704.834
731.438	672.115
731.643	668
731.9	674.113
732.156	648.615
732.413	666.582
732.67	662.822
732.927	670.826
733.183	651.188
733.44	649.323
733.697	627.406
733.953	653.306
734.21	665.059
734.466	637.785
734.723	619.56
734.98	636.809
735.236	639.428
735.493	655.2
735.749	648.18
736.006	634.459
736.262	644.936
736.519	614.375
736.775	631.875
737.032	639.314
737.288	667.202
737.544	643.604
737.801	618.634
738.057	643.449
738.314	628.533
738.57	623.114
738.826	613.568
739.083	654.344
739.339	624.208
739.595	618.387
739.852	610.267
740.108	626.542
740.364	608.162
740.621	613.67
740.877	594.966
741.133	593.71
741.389	591.377
741.645	590.523
741.902	588.966
742.158	583.065
742.414	600.553
742.67	574.713
742.926	592.368
743.182	572.733
743.438	586.627
743.694	580.593
743.951	576.213
744.207	562.046
744.463	560.299
744.719	576.693
744.975	562.055
745.231	563.928
745.487	555.578
745.743	539.843
745.998	559.305
746.254	539.972
746.51	543.432
746.766	550.014
747.022	541.231
747.278	541.745
747.534	547.92
747.79	527.557
748.046	521.201
748.301	525.136
748.557	540.06
748.813	536.304
749.069	521.001
749.324	520.709
749.58	515.097
749.836	521.009
750.092	530.988
750.347	525.47
750.603	504.175
750.859	504.244
751.114	499.883
751.37	497.193
751.625	508.218
751.881	494.337
752.137	488.434
752.392	490.331
752.648	485.542
752.903	493.071
753.159	503.892
753.414	492.758
753.67	479.292
753.925	481.83
754.181	493.611
754.436	462.239
754.692	472.132
754.947	481.321
755.202	457.784
755.458	458.913
755.713	452.053
755.968	462.172
756.224	450.671
756.479	452.564
756.734	443.794
756.99	440.19
757.245	461.12
757.5	451.217
757.755	422.551
757.968	455.986
758.224	431.949
758.48	408.743
758.736	452.829
758.992	436.202
759.248	453.064
759.504	428.406
759.76	429.932
760.016	418.003
760.272	433.571
760.528	430.134
760.784	424.497
761.04	415.75
761.296	417.228
761.552	401.981
761.807	421.206
762.063	408.217
762.319	413.996
762.575	393.755
762.831	412.138
763.086	397.354
763.342	397.515
763.598	396.35
763.853	381.669
764.109	380.498
764.365	388.495
764.621	373.579
764.876	377.435
765.132	370.457
765.387	370.05
765.643	376.645
765.899	380.296
766.154	382.788
766.41	359.533
766.665	369.472
766.921	366.742
767.176	364.07
767.432	355.449
767.687	370.606
767.943	353.309
768.198	357.23
768.454	350.358
768.709	348.326
768.965	345.322
769.22	349.139
769.475	341.663
769.731	357.226
769.986	342.826
770.242	330.722
770.497	338.164
770.752	343.275
771.007	329.303
771.263	334.663
771.518	336.548
771.773	330.508
772.028	322.174
772.284	306.092
772.539	311.731
772.794	311.178
773.049	321.663
773.304	319.031
773.56	311.268
773.815	321.926
774.07	310.303
774.325	299.993
774.58	305.547
774.835	302.481
775.09	298.63
775.345	302.66
775.6	304.901
775.855	295.696
776.11	295.856
776.365	281.514
776.62	287.265
776.875	282.626
777.13	287.646
777.385	272.74
777.64	275.982
777.895	275.645
778.149	274.336
778.404	273.576
778.659	274.033
778.914	259.278
779.169	272.247
779.424	266.975
779.678	263.111
779.933	263.094
780.188	265.133
780.442	269.247
780.697	256.045
780.952	262.737
781.207	264.251
781.461	243.389
781.716	255.671
781.97	250.244
782.225	252.224
782.48	246.084
782.734	252.897
782.989	244.711
783.243	248.366
783.498	235.25
783.752	248.464
784.007	234.781
784.253	243.915
784.509	246.015
784.764	239.706
785.019	241.57
785.274	244.758
785.53	226.397
785.785	222.013
786.04	216.089
786.295	215.318
786.551	249.866
786.806	219.775
787.061	223.361
787.316	231.506
787.571	215.73
787.826	216.851
788.081	217.53
788.336	210.622
788.591	223.908
788.847	202.724
789.102	212.858
789.357	210.796
789.612	208.677
789.867	207.411
790.122	221.217
790.377	192.326
790.632	209.26
790.886	195.072
791.141	188.821
791.396	203.306
791.651	204.524
791.906	199.93
792.161	200.77
792.416	200.912
792.671	185.129
792.925	194.911
793.18	175.27
793.435	187.745
793.69	176.946
793.945	186.418
794.199	184.133
794.454	188.262
794.709	180.283
794.963	183.1
795.218	183.804
795.473	177.678
795.727	174.885
795.982	180.246
796.237	165.351
796.491	181.366
796.746	170.106
797	168.618
797.255	174.517
797.509	168.656
797.764	171.234
798.018	167.979
798.273	166.973
798.527	160.007
798.782	157.084
799.036	164.745
799.291	163.849
799.545	163.965
799.8	155.272
800.054	163.032
800.308	160.065
800.563	156.586
800.817	162.151
801.071	141.839
801.326	157.798
801.58	148.895
801.834	146.243
802.088	159.128
802.343	144.606
802.597	150.471
802.851	143.979
803.105	140.168
803.359	159.36
803.614	142.699
803.868	148.993
804.122	137.392
804.376	133.666
804.63	131.293
804.884	141.934
805.138	136.235
805.392	142.196
805.646	135.376
805.9	132.595
806.154	141.96
806.408	140.947
806.662	129.602
806.916	132.482
807.17	130.744
807.424	122.711
807.678	132.755
807.932	128.897
808.186	120.661
808.439	129.869
808.693	132.742
808.947	128.594
809.201	124.988
809.455	123.015
809.708	124.033
809.962	130.532
810.183	124
810.438	127.981
810.693	120.057
810.947	119.661
811.202	116.295
811.456	119.958
811.711	116.441
811.965	121.295
812.22	121.806
812.474	121.593
812.729	127.36
812.983	117.398
813.237	108.442
813.492	111.386
813.746	111.678
814.001	108.353
814.255	127.471
814.509	113.239
814.764	111.35
815.018	103.688
815.272	115.024
815.526	108.341
815.781	116.975
816.035	108.143
816.289	113.824
816.543	114.072
816.798	105.971
817.052	106.421
817.306	106.427
817.56	103.642
817.814	106.618
818.068	109.232
818.323	111.5
818.577	96.9532
818.831	101.462
819.085	104.295
819.339	103.831
819.593	96.9083
819.847	107.418
820.101	102.713
820.355	114.618
820.609	101.214
820.863	93.9868
821.117	99.9192
821.371	101.95
821.624	103.401
821.878	102.407
822.132	98.9594
822.386	96.9374
822.64	81.6983
822.894	92.5524
823.148	97.656
823.401	91.9259
823.655	91.9628
823.909	93.7846
824.163	87.2231
824.416	86.8323
824.67	86.7743
824.924	82.0837
825.177	93.0765
825.431	89.1747
825.685	88.9369
825.938	94.5839
826.192	94.1272
826.446	83.7014
826.699	90.5523
826.953	87.7866
827.206	86.5482
827.46	78.8481
827.713	85.1301
827.967	87.5729
828.22	82.5434
828.474	86.8072
828.727	81.2917
828.981	79.0174
829.234	78.9597
829.488	83.103
829.741	89.0552
829.994	80.4755
830.248	79.7146
830.501	84.0423
830.754	83.3583
831.008	85.3989
831.261	81.698
831.514	78
831.767	81.9601
832.021	78.9451
832.274	75.8651
832.527	75.7078
832.78	77.7322
833.034	76.1519
833.287	79.9172
833.54	80
833.793	74.1305
834.046	82.576
834.299	72.7969
834.552	79.588
834.805	76.6565
835.058	72.4526
835.311	73.9825
835.564	74.3776
835.817	72.3734
836.07	79.5233
836.314	70.0048
836.568	73.9431
836.821	83.8281
837.075	77.4251
837.329	71.8962
837.583	81.7145
837.836	69.8443
838.09	76.8967
838.344	74.1152
838.598	61.2583
838.851	74.9197
839.105	66.4431
839.359	73.4961
839.612	69.5738
839.866	68.2114
840.119	66.1064
840.373	67.9518
840.627	75.2867
840.88	75.3368
841.134	70.6964
841.387	71.8015
841.641	63.4822
841.894	68.9072
842.148	76.1475
842.401	72.2997
842.655	63.5263
842.908	64.1712
843.161	67.1605
843.415	66.5121
843.668	59.7845
843.922	67.1726
844.175	72.4212
844.428	70.102
844.682	72.0278
844.935	65.3651
845.188	66.7262
845.442	65.5087
845.695	63.0334
845.948	65.2505
846.201	64.1187
846.455	62.2494
846.708	59.0189
846.961	64.8187
847.214	69.8452
847.467	61.3992
847.72	61.2657
847.973	61.774
848.227	58.9256
848.48	60.8464
848.733	61.6414
848.986	59.8652
849.239	64.946
849.492	63.9061
849.745	61.8888
849.998	62.7137
850.251	61.5597
850.504	65.7254
850.757	56.2427
851.01	60.9854
851.263	61.635
851.515	57.8511
851.768	54.3992
852.021	60.9258
852.274	57.1011
852.527	59.5109
852.78	58.7726
853.032	62.1109
853.285	58.6341
853.538	60.1271
853.791	54.7164
854.043	53.9216
854.296	57.7068
854.549	52.6027
854.801	55.836
855.054	54.9285
855.307	58.2362
855.559	53.0542
855.812	60.6001
856.065	58.2583
856.317	60.9505
856.57	52.9476
856.822	45.7582
857.075	60.6339
857.327	57.1699
857.58	47.8927
857.832	52.7894
858.085	58.4946
858.337	52.3602
858.589	57.5837
858.842	52.7432
859.094	51.6764
859.347	52.0819
859.599	51.041
859.851	52.3483
860.104	59.0905
860.356	44.3332
860.608	53.9371
860.861	41.2971
861.113	56.7963
861.365	51.9456
861.617	56.9128
861.869	46.1433
862.112	50.0059
862.365	50.0238
862.618	53.8026
862.871	51.8434
863.124	57.714
863.377	46.0994
863.63	55.7085
863.883	53.7042
864.136	57.5142
864.389	49.6452
864.642	49.8152
864.894	53.6701
865.147	60.9481
865.4	51.8304
865.653	43.1418
865.906	48.1222
866.159	54.4319
866.412	45.9234
866.664	46.7195
866.917	45.4382
867.17	57.3738
867.423	48.1336
867.675	42.2675
867.928	49.4965
868.181	49.6511
868.433	44.8761
868.686	47.1438
868.939	47.7431
869.191	47.9283
869.444	50.5673
869.697	48.6292
869.949	51.7926
870.202	45.8311
870.454	43.7155
870.707	53.7528
870.959	46.7489
871.212	45.1657
871.464	40.2811
871.717	51.2572
871.969	49.4269
872.222	47.7502
872.474	46.7645
872.727	56.3527
872.979	50.1341
873.231	46.3388
873.484	47.1444
873.736	49.5664
873.988	46
874.241	45.1021
874.493	46.8215
874.745	47.9185
874.998	42.8495
875.25	44.1654
875.502	39.9298
875.754	42.5129
876.006	41.5413
876.259	44.5614
876.511	50.6305
876.763	39.1586
877.015	42.1878
877.267	44.2165
877.519	46.1943
877.771	42.7379
878.023	47.3098
878.276	42.5498
878.528	48.173
878.78	47.1148
879.031	42.0757
879.284	41.8791
879.535	39.9591
879.787	47.3679
880.039	40.7719
880.291	44.0068
880.543	41.1088
880.795	40.0306
881.047	39.0721
881.299	42.8338
881.551	47.2194
881.802	42.2055
882.054	44.2106
882.306	44.9613
882.558	43.9771
882.809	42.9213
883.061	41.9439
883.313	38.6948
883.565	41.6527
883.816	37.723
884.068	45.9966
884.319	43.4683
884.571	41.2524
884.823	38
885.074	41.3176
885.326	41.3541
885.577	41.7655
885.829	36.6368
886.08	39.2266
886.332	40.55
886.583	42.4277
886.835	46.7853
887.086	39.5616
887.338	43.9078
887.589	38.0588
887.841	34.2323
888.044	43.9456
888.296	34.0902
888.548	43.5174
888.8	32.5647
889.053	35.8156
889.305	39.125
889.557	48.7277
889.809	38.38
890.061	42.5625
890.313	44.2938
890.566	37.6556
890.818	44.1378
891.07	38.0118
891.322	41.4621
891.574	37.5887
891.826	38.8196
892.078	40.6141
892.33	41.7422
892.582	44.1991
892.834	40.2393
893.086	38.1618
893.338	35.8405
893.59	42.0411
893.842	43.8646
894.094	35
894.346	36.9831
894.597	37.9517
894.849	36.1196
895.101	38
895.353	40
895.605	40.5652
895.857	35.5193
896.108	43.7609
896.36	32.4058
896.612	37.5435
896.864	37.4958
897.115	32.1087
897.367	32.7995
897.619	41
897.87	37.7001
898.122	34.2418
898.374	38.0592
898.625	34.5635
898.877	37.7013
899.128	36.3712
899.38	35.3374
899.631	42.3059
899.883	36.364
899.984	35