File: PL_SCD4_121223_01.txt
#Acq. time (s)=	3
#Accumulations=	2
#Range (nm)=	520...900
#Windows=	16
#Auto scanning=	On
#Autofocus=	Off
#AutoExposure=	Off
#Spike filter=	Multiple accum.
#Delay time (s)=	0
#Binning=	1
#Readout mode=	Signal
#DeNoise=	Off
#ICS correction=	Off
#Dark correction=	Off
#Inst. Process=	Off
#Detector temperature (°C)=	-59.98
#Instrument=	LabRAM HR Evol
#Detector=	Syncerity OE
#Objective=	x50_VIS
#Grating=	600 (500nm)
#ND Filter=	10%
#Laser=	514nm_Edge
#Hole=	199.981
#Range=	Auto
#StageXY=	Marzhauser
#StageZ=	Marzhauser
#X (µm)=	4132.5
#Y (µm)=	-8959.1
#Z (µm)=	-238.4
#Full time(mm:ss)=	2:23
#Project=
#Sample=
#Site=
#Title=	PL_SCD4_121223
#Remark=
#Date=	21.12.2023 09:58
#Acquired=	21.12.2023 09:58:59
520.042	36
520.304	36
520.565	35.6438
520.827	38.0698
521.089	37
521.351	35.0895
521.612	40.4133
521.874	36.1083
522.136	37.7628
522.397	37.4878
522.659	38.8626
522.921	34.2934
523.182	40.4715
523.444	40.9942
523.705	40.4692
523.967	45.5006
524.229	35.5902
524.49	36.1711
524.752	40.0827
525.013	42.227
525.275	32.6543
525.536	36.7602
525.798	42.7427
526.059	40.2678
526.321	37.2782
526.582	41
526.844	36
527.105	42.3085
527.367	37.958
527.628	41.6702
527.889	39.6597
528.151	39.3508
528.412	38.2782
528.674	37.141
528.935	37.5291
529.196	38.3566
529.458	36
529.719	39.9312
529.98	39.7238
530.242	42.8718
530.503	38.1049
530.764	39.2902
531.025	41.8741
531.287	43.9604
531.548	40.5105
531.809	43.4942
532.07	40.9767
532.332	42.0932
532.593	38.331
532.854	41.2727
533.115	41.4429
533.376	42.2704
533.638	41.2102
533.899	44.585
534.16	41.8528
534.421	42.6232
534.682	43.9056
534.943	44.7167
535.204	48.5651
535.465	47.2253
535.726	43.5897
535.987	46.7513
536.248	47.3924
536.509	41.284
536.77	52.7646
537.031	49.1625
537.292	49.73
537.553	46.0469
537.814	47.3667
538.075	47.6821
538.336	45.7997
538.597	41.7256
538.858	52.3441
539.119	47.1148
539.38	46.7885
539.641	44.7953
539.901	47.9056
540.162	42.1039
540.423	45.1218
540.684	41.6521
540.945	47.2797
541.205	49.9018
541.466	46.5021
541.727	40.3236
541.988	50.5002
542.248	46.2335
542.509	48.4094
542.77	54.5433
543.031	53.9597
543.291	55.8045
543.552	47.2195
543.813	55.6043
544.073	53.9034
544.334	52.2512
544.594	48.938
544.855	59.2584
545.116	58.8334
545.376	46.0415
545.637	61.7338
545.897	46.8697
546.158	61.6477
546.418	51.4452
546.679	50.0117
546.898	50.1013
547.159	54.2432
547.42	67.765
547.681	52.2036
547.942	64.1364
548.203	54.7055
548.464	65.3903
548.725	59.9025
548.987	69.1078
549.248	66.9498
549.509	66.5422
549.77	67.5136
550.031	69.8157
550.292	85.8284
550.553	75.0925
550.814	72.7585
551.075	80.2356
551.336	87.21
551.597	87.672
551.858	97.3973
552.119	147.539
552.38	357.029
552.641	7698.89
552.901	706.17
553.162	146.857
553.423	102.256
553.684	89.0788
553.945	83.6593
554.206	89.9504
554.467	84.2511
554.727	85.1527
554.988	82.83
555.249	89.1215
555.51	72.9118
555.771	81.1223
556.031	83.1206
556.292	92.2158
556.553	90.7579
556.814	74.9395
557.074	89.0082
557.335	94.6912
557.596	88.9196
557.856	94.9414
558.117	90.2685
558.378	93.1685
558.638	93.2797
558.899	94.0173
559.16	93.3967
559.42	85.6477
559.681	97.5076
559.941	99.9395
560.202	107.484
560.463	97.6165
560.723	99.9217
560.984	104
561.244	109.397
561.505	110.616
561.765	107.694
562.026	108.395
562.286	112.918
562.547	110.804
562.807	112.98
563.067	113.604
563.328	115.764
563.588	120.867
563.849	119.568
564.109	125.827
564.369	119.46
564.63	121.094
564.89	127.644
565.15	131.03
565.411	132.675
565.671	136.263
565.931	132.197
566.192	138.586
566.452	133.969
566.712	143.583
566.972	140.782
567.232	150.925
567.493	149.84
567.753	148.453
568.013	159.894
568.273	153.079
568.533	161.348
568.794	164.926
569.054	163.137
569.314	165.095
569.574	167.064
569.834	179.526
570.094	173.251
570.354	185.412
570.614	180.885
570.874	193.606
571.134	200.369
571.394	204.657
571.654	214.741
571.914	228.97
572.174	234.922
572.434	237.025
572.694	258.173
572.954	264.565
573.214	290.408
573.459	307.928
573.719	316.311
573.98	342.061
574.241	371.845
574.501	411.126
574.762	416.603
575.022	446.52
575.283	446.123
575.543	490.055
575.804	502.851
576.064	490.47
576.325	491.26
576.585	449.629
576.846	447.849
577.106	418.8
577.366	389.546
577.627	363.609
577.887	381.738
578.148	379.145
578.408	355.162
578.668	322.057
578.929	346.832
579.189	329.48
579.449	344.104
579.71	332.71
579.97	319.568
580.23	312.357
580.49	337.538
580.751	339.652
581.011	329.299
581.271	340.365
581.531	337.956
581.792	344.862
582.052	345.765
582.312	350.347
582.572	356.182
582.832	361.245
583.092	371.481
583.353	366.975
583.613	373.116
583.873	390.025
584.133	390.756
584.393	385.905
584.653	406.66
584.913	406.188
585.173	405.726
585.433	428.738
585.693	426.939
585.953	438.041
586.213	444.904
586.473	428.298
586.733	441.398
586.993	444.111
587.253	452.143
587.513	456.084
587.773	463.053
588.033	470.981
588.293	472.096
588.552	479.92
588.812	460.006
589.072	467.013
589.332	485.355
589.592	492.803
589.852	484.722
590.112	469.609
590.371	475.555
590.631	485.883
590.891	472.273
591.151	476.107
591.41	469.849
591.67	466.787
591.93	470.482
592.189	445.164
592.449	469.437
592.709	463.284
592.968	460.52
593.228	463.807
593.488	465.307
593.747	460.602
594.007	455.935
594.266	454.45
594.526	473.072
594.786	471.466
595.045	470.067
595.305	470.411
595.564	493.544
595.824	474.698
596.083	487.51
596.343	501.765
596.602	516.076
596.862	494.75
597.121	511.016
597.38	486.685
597.64	514.049
597.899	512.669
598.159	499.082
598.418	512.088
598.677	540.818
598.937	519.683
599.196	519.865
599.455	510.856
599.715	506.613
599.959	526.078
600.219	515.924
600.479	527.886
600.738	525.94
600.998	542.514
601.258	528.095
601.518	530.322
601.778	543.301
602.038	528.334
602.298	531.622
602.558	545.906
602.818	540.425
603.078	532.144
603.337	525.385
603.597	535.585
603.857	544.818
604.117	537.486
604.377	557.135
604.636	534.365
604.896	544.638
605.156	533.434
605.416	566.01
605.675	532.459
605.935	550.936
606.195	542.679
606.455	564.477
606.714	545.526
606.974	552.281
607.234	544.679
607.493	537.74
607.753	535.669
608.012	551.857
608.272	566.206
608.532	559.627
608.791	571.803
609.051	581.395
609.31	548.457
609.57	573.295
609.829	576.735
610.089	585.026
610.348	590.908
610.608	581.79
610.867	580.664
611.127	571.244
611.386	604.338
611.646	600.281
611.905	596.984
612.164	592.421
612.424	592.018
612.683	611.784
612.943	595.516
613.202	595.932
613.461	623.96
613.721	616.703
613.98	626.532
614.239	631.312
614.498	625.602
614.758	637.954
615.017	637.146
615.276	658.556
615.535	644.949
615.795	661.234
616.054	656.2
616.313	664.433
616.572	659.509
616.831	670.278
617.091	677.975
617.35	680.346
617.609	694.464
617.868	690.761
618.127	699.295
618.386	693.18
618.645	698.635
618.904	712.486
619.163	743.655
619.422	735.191
619.681	738.557
619.94	704.187
620.199	742.816
620.458	754.435
620.717	722
620.976	740.099
621.235	745.163
621.494	730.906
621.753	740.96
622.012	763.23
622.271	743.951
622.53	746.7
622.788	773.715
623.047	755.179
623.306	766.619
623.565	752.986
623.824	742.482
624.082	778.344
624.341	795.349
624.6	764.443
624.859	781.049
625.117	770.332
625.376	777.275
625.635	783.377
625.893	786.869
626.152	809.54
626.368	791.89
626.627	787.959
626.887	817.626
627.146	822.553
627.405	811.874
627.665	812.893
627.924	816.336
628.183	819.971
628.443	826.605
628.702	827.069
628.961	827.032
629.22	847.249
629.479	822.627
629.739	854.88
629.998	805.307
630.257	856.812
630.516	874.429
630.776	855.259
631.035	885.057
631.294	893.495
631.553	864.846
631.812	893.586
632.071	909.052
632.33	913.674
632.589	919.449
632.848	911.5
633.107	917.98
633.366	935.536
633.625	936.1
633.885	940.593
634.143	958.47
634.403	983.236
634.661	982.135
634.92	987.975
635.179	1004.79
635.438	1054.44
635.697	1028.91
635.956	1091.3
636.215	1131.28
636.474	1156.04
636.733	1207.6
636.992	1218.41
637.25	1296.54
637.509	1315.28
637.768	1351.09
638.027	1383.24
638.286	1363.33
638.544	1365.13
638.803	1363.71
639.062	1337.01
639.321	1289.68
639.579	1282.89
639.838	1258.18
640.097	1213.18
640.356	1218
640.614	1195.83
640.873	1180.59
641.131	1178.21
641.39	1184.78
641.649	1169.53
641.907	1161.85
642.166	1154.42
642.424	1173.54
642.683	1166.66
642.942	1186.26
643.2	1180.52
643.459	1177.88
643.717	1183.96
643.976	1189.53
644.234	1171.61
644.493	1192.66
644.751	1208.02
645.009	1209.66
645.268	1221.8
645.526	1219.88
645.785	1226.59
646.043	1228.09
646.301	1242.48
646.56	1242.36
646.818	1239.17
647.076	1208.9
647.335	1227.96
647.593	1263.86
647.851	1244.99
648.109	1252.82
648.368	1288.05
648.626	1285.73
648.884	1304.31
649.142	1293.11
649.401	1306.09
649.659	1346.54
649.917	1307.18
650.175	1335.49
650.433	1336.09
650.691	1340.36
650.949	1354.64
651.208	1366.14
651.466	1357.1
651.724	1391.75
651.982	1398.17
652.24	1411.16
652.498	1418.17
652.756	1428.68
652.979	1432
653.238	1422.57
653.497	1453.56
653.755	1468.42
654.014	1494.8
654.273	1494.25
654.531	1524.13
654.79	1510.37
655.049	1542.21
655.307	1515.06
655.566	1562.2
655.824	1571.56
656.083	1588.48
656.342	1596.02
656.6	1636.28
656.859	1645.1
657.117	1676.99
657.376	1646.19
657.634	1689.3
657.893	1667.1
658.151	1661.41
658.41	1685.36
658.668	1718.45
658.927	1719.31
659.185	1717.22
659.443	1746.45
659.702	1708.95
659.96	1720.94
660.219	1702.81
660.477	1721.69
660.735	1726.14
660.994	1752
661.252	1723.75
661.51	1716.42
661.768	1720.91
662.027	1715.65
662.285	1704.99
662.543	1749.01
662.802	1720.86
663.06	1743.46
663.318	1723.9
663.576	1735.98
663.834	1731.43
664.093	1739.95
664.351	1733.83
664.609	1744.34
664.867	1740.82
665.125	1727.07
665.383	1728.02
665.641	1718.65
665.899	1743.38
666.157	1719.29
666.415	1713.72
666.673	1725.17
666.931	1740.97
667.189	1711.01
667.447	1725.32
667.705	1733.58
667.963	1728.94
668.221	1731.82
668.479	1714.03
668.737	1709.58
668.995	1707.71
669.253	1729.15
669.511	1729.81
669.769	1710.88
670.027	1700.86
670.284	1741.81
670.542	1736.84
670.8	1721.15
671.058	1751.53
671.316	1710.87
671.573	1744.81
671.831	1736.18
672.089	1721.22
672.347	1741.89
672.604	1736.94
672.862	1735.88
673.12	1771.81
673.377	1747.92
673.635	1756.82
673.893	1783.3
674.15	1786.58
674.408	1787.03
674.665	1792.47
674.923	1796.46
675.18	1799.03
675.438	1803.25
675.696	1851.09
675.953	1826.49
676.211	1836.78
676.468	1854.82
676.726	1854.52
676.983	1841.26
677.24	1835.16
677.498	1840.12
677.755	1832.22
678.013	1855.84
678.27	1835.39
678.527	1849.38
678.785	1858.37
679.042	1842.04
679.277	1862.35
679.535	1819.89
679.793	1870.48
680.051	1885.28
680.309	1903.25
680.567	1853.22
680.825	1879.74
681.083	1869.15
681.341	1903.39
681.599	1878.45
681.857	1907.32
682.115	1902.66
682.373	1921.05
682.631	1924.32
682.889	1943.16
683.146	1932.93
683.404	1926.77
683.662	1912.48
683.92	1914.75
684.178	1917.39
684.436	1908.7
684.694	1879.88
684.951	1933.55
685.209	1883.26
685.467	1868.63
685.725	1907.54
685.982	1891.82
686.24	1868.72
686.498	1874.11
686.756	1897.54
687.013	1877.42
687.271	1858.02
687.529	1837.36
687.786	1870.07
688.044	1870.51
688.302	1877.19
688.559	1888.91
688.817	1844.62
689.074	1855.87
689.332	1879.51
689.589	1879.41
689.847	1846.39
690.104	1869.33
690.362	1852.94
690.619	1863.2
690.877	1840.57
691.134	1826.6
691.392	1793.74
691.649	1850.69
691.907	1835.64
692.164	1789.25
692.421	1792.52
692.679	1803.36
692.936	1790.19
693.194	1788.85
693.451	1794.25
693.708	1794.88
693.966	1781.27
694.223	1783.94
694.48	1797.07
694.737	1785.37
694.995	1752.72
695.252	1760.1
695.509	1770.32
695.766	1742.14
696.023	1760.26
696.281	1741.56
696.538	1709.63
696.795	1757.31
697.052	1748.56
697.309	1735.12
697.566	1726.67
697.823	1708.77
698.08	1694.14
698.338	1703.62
698.595	1707.19
698.852	1691.44
699.109	1660.49
699.366	1678.59
699.623	1690.21
699.88	1676.03
700.137	1671.05
700.393	1683.14
700.65	1684.66
700.907	1674.96
701.164	1665.25
701.421	1661.9
701.678	1685.16
701.935	1682.26
702.192	1694.09
702.448	1674.63
702.705	1657.26
702.962	1716.78
703.219	1666.94
703.476	1662.72
703.732	1667.63
703.989	1668.54
704.246	1649.8
704.503	1656.61
704.759	1648.45
705.016	1649.36
705.273	1621.92
705.511	1640.03
705.768	1591.02
706.026	1616.99
706.283	1610.67
706.541	1581.54
706.798	1593.83
707.055	1556.53
707.313	1547.94
707.57	1562.82
707.827	1549.52
708.084	1514.31
708.342	1581.17
708.599	1533.03
708.856	1558.7
709.114	1570.93
709.371	1533.51
709.628	1549.56
709.885	1527.99
710.142	1519.41
710.4	1523.79
710.657	1512.53
710.914	1536.85
711.171	1497.14
711.428	1498.57
711.685	1470.27
711.942	1476.84
712.199	1501.38
712.456	1464.3
712.713	1439.67
712.97	1475.93
713.227	1444.36
713.484	1427.75
713.741	1426.86
713.998	1463.52
714.255	1426.74
714.512	1424.64
714.769	1410.59
715.026	1404.77
715.283	1413.9
715.54	1407.32
715.797	1409.26
716.054	1404.29
716.31	1396.14
716.567	1374.34
716.824	1379.89
717.081	1388.63
717.338	1363.89
717.594	1381.22
717.851	1364.18
718.108	1362.54
718.365	1346.66
718.621	1350.47
718.878	1332.64
719.135	1319.47
719.391	1346.67
719.648	1322.42
719.905	1317.9
720.161	1300.8
720.418	1298.42
720.675	1283.24
720.931	1306.28
721.188	1291.92
721.444	1283.79
721.701	1274.74
721.957	1268.8
722.214	1251.7
722.47	1242.96
722.727	1234.64
722.983	1262.02
723.24	1225.4
723.496	1215.16
723.753	1221.78
724.009	1213.27
724.265	1196.63
724.522	1223.22
724.778	1218.22
725.034	1203.59
725.291	1198.76
725.547	1193.03
725.803	1187.05
726.06	1175.19
726.316	1159.6
726.572	1140.66
726.828	1154.19
727.085	1140.16
727.341	1122.83
727.597	1137.23
727.853	1120.75
728.109	1134.81
728.366	1115.71
728.622	1100.68
728.878	1116.14
729.134	1109.87
729.39	1073.88
729.646	1089.21
729.902	1116.23
730.158	1054.4
730.414	1076.82
730.67	1059.75
730.926	1045.73
731.182	1013.52
731.438	1053.73
731.643	1040
731.9	1038.08
732.156	1018.71
732.413	1001.26
732.67	980.842
732.927	1020.71
733.183	1009.29
733.44	983.246
733.697	992.962
733.953	982.404
734.21	1004.46
734.466	991.389
734.723	996.609
734.98	1000.42
735.236	973.171
735.493	1009.27
735.749	965.438
736.006	990.064
736.262	983.727
736.519	981.261
736.775	976.715
737.032	983.222
737.288	968.791
737.544	955.78
737.801	976.946
738.057	964.8
738.314	934.813
738.57	953.392
738.826	907.878
739.083	951.22
739.339	942.751
739.595	945.457
739.852	951.935
740.108	925.782
740.364	921.867
740.621	938.126
740.877	902.199
741.133	918.561
741.389	893.023
741.645	909.99
741.902	911.667
742.158	889.833
742.414	886.376
742.67	887.358
742.926	904.899
743.182	904.684
743.438	877.706
743.694	860.229
743.951	871.07
744.207	870.314
744.463	861.692
744.719	864.296
744.975	841.325
745.231	841.448
745.487	860.781
745.743	842.104
745.998	833.669
746.254	829.493
746.51	829.415
746.766	820.595
747.022	834.298
747.278	825.744
747.534	841.529
747.79	814.424
748.046	821.834
748.301	816.459
748.557	818.412
748.813	812.492
749.069	792.938
749.324	788.919
749.58	816.315
749.836	800.669
750.092	793.042
750.347	786.768
750.603	782.979
750.859	784.432
751.114	755.099
751.37	785.258
751.625	772.584
751.881	764.93
752.137	756.192
752.392	760.841
752.648	734.565
752.903	753.153
753.159	741.361
753.414	745.628
753.67	757.912
753.925	718.449
754.181	735.366
754.436	734.713
754.692	738.109
754.947	715.949
755.202	729.748
755.458	729.591
755.713	719.841
755.968	680.82
756.224	694.224
756.479	705.714
756.734	682.214
756.99	713.749
757.245	681.154
757.5	668.477
757.755	677.566
757.968	668.016
758.224	681.955
758.48	670.193
758.736	652.351
758.992	667.58
759.248	684.56
759.504	661.836
759.76	664.439
760.016	647.669
760.272	629.244
760.528	645.088
760.784	650.878
761.04	634.495
761.296	624.389
761.552	626.861
761.807	631.931
762.063	589.073
762.319	595.833
762.575	600.324
762.831	621.582
763.086	605.533
763.342	620.878
763.598	584.808
763.853	577.97
764.109	562.793
764.365	581.352
764.621	577.706
764.876	589.633
765.132	584.314
765.387	547.115
765.643	560.167
765.899	587.783
766.154	568.671
766.41	554.872
766.665	553.61
766.921	555.13
767.176	546.49
767.432	552.557
767.687	536.232
767.943	541.636
768.198	538.236
768.454	531.252
768.709	542.032
768.965	507.98
769.22	519.07
769.475	513.614
769.731	497.63
769.986	528.565
770.242	505.719
770.497	529.985
770.752	515.124
771.007	488.294
771.263	491.182
771.518	502.011
771.773	501.087
772.028	490.067
772.284	495.961
772.539	486.654
772.794	467.504
773.049	479.579
773.304	473.405
773.56	472.786
773.815	467.089
774.07	462.956
774.325	459.316
774.58	462.44
774.835	451.488
775.09	448.396
775.345	450.171
775.6	443.136
775.855	440.631
776.11	434.293
776.365	436.209
776.62	432.57
776.875	439.444
777.13	426.961
777.385	426.197
777.64	413.558
777.895	416.773
778.149	411.176
778.404	413.752
778.659	418.071
778.914	411.931
779.169	398.527
779.424	406.232
779.678	400.203
779.933	397.601
780.188	401.306
780.442	404.188
780.697	387.116
780.952	398.042
781.207	388.637
781.461	383.008
781.716	386.402
781.97	391.891
782.225	378.11
782.48	378.017
782.734	371.311
782.989	372.711
783.243	351.419
783.498	367.136
783.752	368.261
784.007	361.68
784.253	360.021
784.509	367.756
784.764	342.166
785.019	349.725
785.274	344.395
785.53	336.618
785.785	343.403
786.04	340.644
786.295	352.161
786.551	331.127
786.806	344.218
787.061	341.474
787.316	333.233
787.571	324.163
787.826	333.146
788.081	331.001
788.336	318.732
788.591	336.988
788.847	313.122
789.102	311.707
789.357	307.086
789.612	316.301
789.867	315.013
790.122	307.294
790.377	308.074
790.632	302.907
790.886	294.977
791.141	295.462
791.396	306.982
791.651	290.887
791.906	300.768
792.161	286.776
792.416	283.252
792.671	283.169
792.925	292.65
793.18	277.35
793.435	285.301
793.69	285.507
793.945	273.352
794.199	274.809
794.454	268.08
794.709	267.749
794.963	270.337
795.218	263.213
795.473	263.376
795.727	260.924
795.982	260.64
796.237	263.273
796.491	248.374
796.746	259.645
797	253.535
797.255	249.07
797.509	249.438
797.764	249.654
798.018	246
798.273	240.569
798.527	249.158
798.782	242.493
799.036	238.401
799.291	235.485
799.545	234.099
799.8	237.5
800.054	232.928
800.308	231.177
800.563	228.897
800.817	239.692
801.071	224.681
801.326	236.531
801.58	221.01
801.834	220.475
802.088	211.672
802.343	217.009
802.597	223.738
802.851	221.685
803.105	225.546
803.359	210.503
803.614	202.197
803.868	206.493
804.122	217.848
804.376	218.528
804.63	222.286
804.884	212.553
805.138	212.072
805.392	202.577
805.646	197.146
805.9	192.483
806.154	210.876
806.408	194.86
806.662	194.709
806.916	198.984
807.17	186.062
807.424	196.231
807.678	198.376
807.932	195.101
808.186	192.718
808.439	191.712
808.693	181.382
808.947	190.609
809.201	180.41
809.455	187.02
809.708	176.978
809.962	184.099
810.183	192
810.438	179.978
810.693	179.936
810.947	172.284
811.202	162.27
811.456	179.747
811.711	168.523
811.965	164.447
812.22	158.304
812.474	168.871
812.729	158.833
812.983	164.386
813.237	160.177
813.492	157.416
813.746	160.816
814.001	168.506
814.255	171.5
814.509	157.818
814.764	150.513
815.018	160.777
815.272	160.768
815.526	164.331
815.781	159.385
816.035	153.872
816.289	146.515
816.543	142.14
816.798	150.507
817.052	153.047
817.306	145.205
817.56	147.86
817.814	159.431
818.068	150.023
818.323	138.077
818.577	142.855
818.831	138.306
819.085	141.014
819.339	143.488
819.593	144.853
819.847	148.07
820.101	142.111
820.355	139.846
820.609	145.115
820.863	147.489
821.117	137.06
821.371	141.034
821.624	144.032
821.878	141.941
822.132	130.054
822.386	135.709
822.64	131.914
822.894	140.909
823.148	136.152
823.401	132.988
823.655	139.023
823.909	128.038
824.163	128.926
824.416	126.794
824.67	129.172
824.924	129.772
825.177	123.343
825.431	123.309
825.685	133.793
825.938	126.946
826.192	129.587
826.446	135.286
826.699	129.81
826.953	118.251
827.206	116.752
827.46	123.248
827.713	119.502
827.967	124.059
828.22	124.381
828.474	127.738
828.727	120.192
828.981	124.293
829.234	112
829.488	114.515
829.741	114.275
829.994	117.98
830.248	113.373
830.501	122.308
830.754	117.166
831.008	113.782
831.261	111.722
831.514	116.519
831.767	114.279
832.021	110.549
832.274	120.378
832.527	99.9877
832.78	104.283
833.034	111.507
833.287	108.765
833.54	112.042
833.793	106.91
834.046	103.772
834.299	112.295
834.552	107.444
834.805	112.689
835.058	99.6592
835.311	104.304
835.564	106.462
835.817	106.541
836.07	107.291
836.314	108.003
836.568	107.887
836.821	103.893
837.075	104.087
837.329	109.45
837.583	103.74
837.836	107.494
838.09	101.541
838.344	100.597
838.598	101.13
838.851	114.049
839.105	103.558
839.359	101.58
839.612	98.8614
839.866	87.816
840.119	99.2082
840.373	92.0705
840.627	105.115
840.88	100.522
841.134	98.2308
841.387	96.5551
841.641	94.0855
841.894	94.2274
842.148	103.06
842.401	86.8231
842.655	98.8237
842.908	84.7433
843.161	94.6869
843.415	91.5579
843.668	90.8532
843.922	92.3652
844.175	93.4508
844.428	104.008
844.682	79.5406
844.935	96.0678
845.188	83.7017
845.442	91.3776
845.695	86.4793
845.948	89.9782
846.201	82.1674
846.455	80.5393
846.708	85.0752
846.961	87.6395
847.214	86.5378
847.467	89.1331
847.72	88.8035
847.973	87.0291
848.227	88.7781
848.48	84.9452
848.733	90.2113
848.986	88.9435
849.239	87.6948
849.492	76.157
849.745	85.9139
849.998	78.1431
850.251	75.859
850.504	79.1594
850.757	85.2749
851.01	81.4704
851.263	74.8231
851.515	78.4053
851.768	73.5988
852.021	90.4348
852.274	76.6712
852.527	77.6154
852.78	75.7832
853.032	84.0235
853.285	74.4489
853.538	80
853.791	75.0281
854.043	78.3477
854.296	69.8141
854.549	76.8979
854.801	77.8701
855.054	68.5051
855.307	69.7222
855.559	73.9726
855.812	76
856.065	76.5937
856.317	73.6993
856.57	71.9476
856.822	80.6508
857.075	71.3661
857.327	69.3204
857.58	73.7919
857.832	72.4768
858.085	71.3489
858.337	67.7084
858.589	78.6955
858.842	75.7389
859.094	70.4658
859.347	67.9765
859.599	76.8472
859.851	76.3538
860.104	67.5321
860.356	68.7239
860.608	77.7062
860.861	72.7195
861.113	66.5253
861.365	71.1743
861.617	66.7269
861.869	83.9272
862.112	69.998
862.365	69.9252
862.618	67.943
862.871	71.9308
863.124	66.025
863.377	71.4649
863.63	71.9348
863.883	62.2768
864.136	67.2045
864.389	75.0176
864.642	71.8955
864.894	69.2587
865.147	66.5098
865.4	72.2404
865.653	63.8393
865.906	68.5506
866.159	62.1246
866.412	70.1801
866.664	64.902
866.917	62.556
867.17	62.1165
867.423	66.6324
867.675	69.9456
867.928	56.5162
868.181	69.5104
868.433	64.9354
868.686	64.1263
868.939	62.5735
869.191	68.0476
869.444	69.0489
869.697	59.978
869.949	62.4663
870.202	61.3026
870.454	60.13
870.707	52.0709
870.959	63.2942
871.212	63.1852
871.464	55.4464
871.717	55.7135
871.969	66
872.222	58.8269
872.474	58.0319
872.727	61.9921
872.979	61.2206
873.231	63.1694
873.484	56.9226
873.736	62.7956
873.988	57.3983
874.241	55.8469
874.493	55.0928
874.745	57.9185
874.998	59.4593
875.25	55.7004
875.502	54.2562
875.754	58.6577
876.006	61.3932
876.259	60.091
876.511	56.113
876.763	56.8087
877.015	56.0816
877.267	50.4728
877.519	57.9352
877.771	58.3762
878.023	52.3193
878.276	51.1558
878.528	51.7687
878.78	54.4425
879.031	56.0757
879.284	50.4658
879.535	57.5434
879.787	53.7954
880.039	51.0702
880.291	51.2027
880.543	59.0675
880.795	55.9694
881.047	54.3946
881.299	55.452
881.551	57.0476
881.802	51.1009
882.054	55.2001
882.306	53.3742
882.558	55.5709
882.809	55.3597
883.061	52.9719
883.313	51.8243
883.565	52.955
883.816	48.8148
884.068	50.4304
884.319	57.1012
884.571	54.2189
884.823	44.9718
885.074	50.8077
885.326	52.6506
885.577	53.2964
885.829	51.4769
886.08	50.5023
886.332	50.6393
886.583	51.8794
886.835	49.4575
887.086	53.7736
887.338	56.1656
887.589	54.0471
887.841	53.8571
888.044	50.0073
888.296	42.2822
888.548	59.2502
888.8	47.8465
889.053	47.9894
889.305	52.9829
889.557	49.6428
889.809	47.5942
890.061	49.8162
890.313	52.8588
890.566	47.0579
890.818	48.8479
891.07	56.9639
891.322	46
891.574	48.8934
891.826	46.4581
892.078	46.7053
892.33	45.0078
892.582	45.7638
892.834	47.0406
893.086	51.3029
893.338	40.3063
893.59	44.1502
893.842	49.8885
894.094	48
894.346	43.0338
894.597	47.0242
894.849	44.8804
895.101	46
895.353	45.214
895.605	43.3913
895.857	49.8961
896.108	45.8804
896.36	46.1353
896.612	42.6957
896.864	44.3362
897.115	41
897.367	45.0024
897.619	46.2164
897.87	46.8331
898.122	43.4946
898.374	39.7944
898.625	48.0278
898.877	42.5973
899.128	41.2576
899.38	44.3374
899.631	44.9589
899.883	42.4559
899.984	41