File: PL_SCD5_121223_01.txt
#Acq. time (s)=	3
#Accumulations=	2
#Range (nm)=	520...900
#Windows=	16
#Auto scanning=	On
#Autofocus=	Off
#AutoExposure=	Off
#Spike filter=	Multiple accum.
#Delay time (s)=	0
#Binning=	1
#Readout mode=	Signal
#DeNoise=	Off
#ICS correction=	Off
#Dark correction=	Off
#Inst. Process=	Off
#Detector temperature (°C)=	-59.98
#Instrument=	LabRAM HR Evol
#Detector=	Syncerity OE
#Objective=	x50_VIS
#Grating=	600 (500nm)
#ND Filter=	10%
#Laser=	514nm_Edge
#Hole=	199.981
#Range=	Auto
#StageXY=	Marzhauser
#StageZ=	Marzhauser
#X (µm)=	14134.9
#Y (µm)=	-8959.1
#Z (µm)=	-148.3
#Full time(mm:ss)=	2:39
#Project=
#Sample=
#Site=
#Title=	PL_SCD5_121223
#Remark=
#Date=	21.12.2023 10:03
#Acquired=	21.12.2023 10:03:17
520.042	40
520.304	31.7951
520.565	30.0594
520.827	32.8605
521.089	36.0791
521.351	32.1791
521.612	31.2934
521.874	34.4587
522.136	37.1186
522.397	31.5122
522.659	28.6868
522.921	33.56
523.182	36
523.444	32.1676
523.705	28.3539
523.967	32.6251
524.229	37.4098
524.49	30
524.752	31
525.013	36.319
525.275	36
525.536	32.248
525.798	36.2282
526.059	36.929
526.321	37.4435
526.582	31.2887
526.844	35.7016
527.105	33.617
527.367	37
527.628	33
527.889	38.3193
528.151	35.7016
528.412	31.4435
528.674	30.7436
528.935	38.8531
529.196	33
529.458	35.2098
529.719	30.1725
529.98	39.7238
530.242	31
530.503	31.5524
530.764	32.542
531.025	35.4685
531.287	33.8811
531.548	31.4685
531.809	38.4942
532.07	39
532.332	38.5233
532.593	33.8648
532.854	40.4545
533.115	33.6713
533.376	41.7028
533.638	35.8394
533.899	38.7729
534.16	37.549
534.421	37.4059
534.682	35.5674
534.943	40.7508
535.204	40.6746
535.465	36.7085
535.726	35.1871
535.987	43.5556
536.248	40.7664
536.509	41.2217
536.77	35.8126
537.031	41.2407
537.292	45.2407
537.553	40.0276
537.814	37.9679
538.075	40.6059
538.336	41.3019
538.597	40.5726
538.858	40.9114
539.119	46.2916
539.38	41.357
539.641	36.2654
539.901	37.6051
540.162	43.419
540.423	42.8152
540.684	41.8731
540.945	41.299
541.205	45.5521
541.466	45.8913
541.727	40.4464
541.988	45.8647
542.248	47.1051
542.509	45.3069
542.77	44.0358
543.031	46.0201
543.291	50.8116
543.552	47.3452
543.813	46.5927
544.073	40.5009
544.334	53.2146
544.594	53.5007
544.855	43.3991
545.116	54.071
545.376	47.1142
545.637	51.9325
545.897	55.8205
546.158	52.5672
546.418	56.6365
546.679	54.366
546.898	47.9948
547.159	55.9776
547.42	65.6462
547.681	61.4951
547.942	61.572
548.203	65.734
548.464	67.4163
548.725	61.9672
548.987	60.5948
549.248	63.3872
549.509	65.7186
549.77	63.5533
550.031	63.7464
550.292	70.0958
550.553	77.3828
550.814	78.9062
551.075	72.4454
551.336	83.3696
551.597	90.7008
551.858	110.221
552.119	153.904
552.38	394.611
552.641	9587.51
552.901	736.2
553.162	167.278
553.423	109.657
553.684	94.635
553.945	91.2401
554.206	94.7865
554.467	83.9301
554.727	90.4554
554.988	78.2934
555.249	85.819
555.51	88.3279
555.771	90.7713
556.031	86.6543
556.292	91.5432
556.553	93.5601
556.814	94.2507
557.074	90.1408
557.335	97.5382
557.596	96.765
557.856	96.6263
558.117	105.384
558.378	99.3154
558.638	106.479
558.899	97.4275
559.16	108.227
559.42	109.569
559.681	113.631
559.941	95.3804
560.202	117.957
560.463	120.412
560.723	122.528
560.984	118.438
561.244	117.909
561.505	117.974
561.765	127.598
562.026	130.032
562.286	129.064
562.547	135.262
562.807	128.511
563.067	136.296
563.328	142.591
563.588	145.815
563.849	148.313
564.109	154.334
564.369	145.337
564.63	148.968
564.89	156.628
565.15	158.773
565.411	160.814
565.671	161.293
565.931	164.638
566.192	166.905
566.452	181.718
566.712	171.569
566.972	181.054
567.232	173.813
567.493	177.192
567.753	194.533
568.013	175.769
568.273	193.763
568.533	192.939
568.794	202.469
569.054	202.901
569.314	206.607
569.574	216.054
569.834	208.961
570.094	227.874
570.354	218.991
570.614	233.77
570.874	249.79
571.134	263.609
571.394	254.363
571.654	273.245
571.914	286.386
572.174	281.365
572.434	305.853
572.694	333.359
572.954	347.402
573.214	369.257
573.459	378.064
573.719	410.248
573.98	451.969
574.241	488.315
574.501	522.442
574.762	566.325
575.022	603.942
575.283	662.065
575.543	694.934
575.804	695.414
576.064	701.652
576.325	667.142
576.585	663.357
576.846	631.886
577.106	591.1
577.366	579.513
577.627	538.305
577.887	527.527
578.148	502.27
578.408	475.466
578.668	476.706
578.929	467.617
579.189	429.414
579.449	441.705
579.71	458.022
579.97	428.467
580.23	458.033
580.49	448.285
580.751	433.079
581.011	442.146
581.271	446.058
581.531	455.345
581.792	444.482
582.052	479.148
582.312	476.397
582.572	480.189
582.832	485.701
583.092	487.117
583.353	525.572
583.613	521.357
583.873	520.737
584.133	533.596
584.393	538.789
584.653	557.658
584.913	554.45
585.173	551.441
585.433	565.134
585.693	586.727
585.953	579.511
586.213	601.808
586.473	603.605
586.733	610.304
586.993	602.077
587.253	614.936
587.513	630.519
587.773	618.531
588.033	644.387
588.293	647.448
588.552	634.228
588.812	635.81
589.072	651.745
589.332	678.59
589.592	678.739
589.852	646.893
590.112	645.958
590.371	670.493
590.631	654.763
590.891	651.919
591.151	650.388
591.41	637.049
591.67	660.26
591.93	639.953
592.189	638.924
592.449	635.324
592.709	659.579
592.968	627.581
593.228	635.651
593.488	636.711
593.747	647.098
594.007	641.592
594.266	642.056
594.526	662.816
594.786	654.793
595.045	653.787
595.305	666.671
595.564	668.968
595.824	663.934
596.083	700.911
596.343	697.288
596.602	717.602
596.862	697.717
597.121	703.975
597.38	710.271
597.64	736.466
597.899	711.461
598.159	728.48
598.418	728.03
598.677	742.299
598.937	719.813
599.196	731.409
599.455	720.967
599.715	738.079
599.959	718.066
600.219	751.931
600.479	748.357
600.738	732.283
600.998	732.297
601.258	746.219
601.518	762.265
601.778	753.936
602.038	736.578
602.298	747.903
602.558	766.58
602.818	765.81
603.078	747.543
603.337	760.273
603.597	789.763
603.857	791.445
604.117	780.385
604.377	761.635
604.636	802.359
604.896	773.928
605.156	814.301
605.416	793.162
605.675	793.647
605.935	792.762
606.195	770.496
606.455	767.102
606.714	794.499
606.974	795.22
607.234	795.511
607.493	786.145
607.753	795.636
608.012	784.821
608.272	795.061
608.532	818.209
608.791	813.641
609.051	834.64
609.31	825.89
609.57	827.551
609.829	831.484
610.089	835.78
610.348	839.335
610.608	850.921
610.867	828.319
611.127	848.676
611.386	850.449
611.646	859.461
611.905	845.611
612.164	875.241
612.424	881.356
612.683	888.226
612.943	893.045
613.202	858.077
613.461	897.44
613.721	908.96
613.98	915.862
614.239	911.207
614.498	920.767
614.758	943.67
615.017	943.497
615.276	940.981
615.535	946.155
615.795	949.166
616.054	977.758
616.313	957.727
616.572	982.076
616.831	991.667
617.091	1002.49
617.35	991.963
617.609	997.842
617.868	1015.74
618.127	1029.41
618.386	1040.45
618.645	1065.37
618.904	1061.55
619.163	1056.08
619.422	1069.43
619.681	1091.31
619.94	1103.22
620.199	1095.39
620.458	1104.23
620.717	1129.37
620.976	1114.65
621.235	1126.96
621.494	1130.06
621.753	1135.98
622.012	1142.51
622.271	1127.92
622.53	1121.93
622.788	1174.28
623.047	1166.4
623.306	1165.19
623.565	1141.9
623.824	1148.31
624.082	1141.22
624.341	1174.12
624.6	1171.86
624.859	1181.72
625.117	1180.34
625.376	1168.57
625.635	1204.68
625.893	1208.91
626.152	1206.89
626.368	1247.54
626.627	1202.14
626.887	1225.87
627.146	1236.36
627.405	1206.81
627.665	1219.23
627.924	1263.64
628.183	1244.62
628.443	1265.76
628.702	1264.87
628.961	1286.51
629.22	1259.76
629.479	1267.44
629.739	1261.8
629.998	1281.59
630.257	1319.05
630.516	1339.27
630.776	1357.64
631.035	1336.06
631.294	1364.24
631.553	1358.15
631.812	1370.96
632.071	1379.38
632.33	1405.83
632.589	1379.32
632.848	1405.77
633.107	1443.47
633.366	1427.91
633.625	1426.01
633.885	1471.82
634.143	1492.45
634.403	1461.19
634.661	1497.23
634.92	1537.05
635.179	1565.41
635.438	1602.91
635.697	1633.33
635.956	1655.36
636.215	1725.01
636.474	1777.7
636.733	1865.01
636.992	1961.17
637.25	2047.37
637.509	2160.95
637.768	2247.76
638.027	2292.28
638.286	2313.92
638.544	2340.39
638.803	2277.85
639.062	2222.38
639.321	2157.19
639.579	2109.78
639.838	2066.82
640.097	2009.11
640.356	1990.32
640.614	1943.25
640.873	1919.69
641.131	1903.26
641.39	1917.61
641.649	1912.5
641.907	1892.45
642.166	1855.7
642.424	1874.78
642.683	1874.7
642.942	1887.3
643.2	1884.67
643.459	1890.99
643.717	1903.61
643.976	1913.33
644.234	1908.81
644.493	1974
644.751	1942.14
645.009	1932.72
645.268	1961.28
645.526	1987.4
645.785	1972.2
646.043	1975.16
646.301	2007.57
646.56	2019.39
646.818	1997.75
647.076	2009.86
647.335	2018.28
647.593	2033.95
647.851	2039.79
648.109	2076.23
648.368	2061.72
648.626	2085.03
648.884	2109.25
649.142	2104.5
649.401	2078.39
649.659	2124.65
649.917	2191.48
650.175	2182.3
650.433	2176.75
650.691	2223.05
650.949	2185.57
651.208	2230.14
651.466	2209.79
651.724	2251.99
651.982	2255.89
652.24	2234.9
652.498	2302.26
652.756	2343.14
652.979	2363.4
653.238	2358.73
653.497	2362.94
653.755	2391.39
654.014	2423.54
654.273	2464.4
654.531	2446.2
654.79	2501.19
655.049	2508.18
655.307	2548.86
655.566	2580.89
655.824	2611.7
656.083	2598.75
656.342	2673.4
656.6	2701.25
656.859	2720.98
657.117	2707.16
657.376	2778.91
657.634	2812.31
657.893	2811.3
658.151	2816.87
658.41	2882.81
658.668	2868.86
658.927	2885.15
659.185	2903.04
659.443	2909.28
659.702	2914.12
659.96	2944.72
660.219	2920.43
660.477	2890.05
660.735	2889.05
660.994	2937.15
661.252	2931.96
661.51	2875.06
661.768	2914.9
662.027	2913.7
662.285	2914.79
662.543	2912.21
662.802	2911.8
663.06	2937.2
663.318	2913.15
663.576	2906.69
663.834	2917.41
664.093	2936.25
664.351	2901.46
664.609	2921.62
664.867	2940.41
665.125	2905.44
665.383	2938.04
665.641	2947.27
665.899	2904.64
666.157	2885.59
666.415	2913.79
666.673	2927.27
666.931	2915.69
667.189	2911.98
667.447	2885.57
667.705	2897.93
667.963	2951.16
668.221	2896.99
668.479	2892.72
668.737	2915.76
668.995	2897.65
669.253	2863.97
669.511	2899.42
669.769	2917.01
670.027	2922.17
670.284	2876
670.542	2912.49
670.8	2887.87
671.058	2914.41
671.316	2897.63
671.573	2930.41
671.831	2963.12
672.089	2921.32
672.347	2946.54
672.604	2964.85
672.862	2939.08
673.12	2982.81
673.377	2997.96
673.635	2971.88
673.893	3000.75
674.15	3030.49
674.408	3060
674.665	3029.57
674.923	3034.76
675.18	3049.76
675.438	3107.11
675.696	3106.7
675.953	3127.12
676.211	3098.18
676.468	3142.59
676.726	3139.24
676.983	3112.51
677.24	3126.79
677.498	3142.87
677.755	3127.53
678.013	3135.99
678.27	3123.14
678.527	3175.24
678.785	3157.53
679.042	3139.04
679.277	3146.39
679.535	3137.13
679.793	3109.51
680.051	3159.59
680.309	3168.92
680.567	3154.22
680.825	3155.94
681.083	3235.85
681.341	3196.93
681.599	3263.96
681.857	3254.81
682.115	3209.57
682.373	3237.23
682.631	3192.11
682.889	3258.35
683.146	3282.78
683.404	3256.61
683.662	3261.03
683.92	3246.6
684.178	3208.57
684.436	3199.48
684.694	3291.13
684.951	3214.55
685.209	3210.69
685.467	3224.33
685.725	3184.41
685.982	3248.54
686.24	3188.99
686.498	3177.42
686.756	3214.85
687.013	3173.79
687.271	3154.05
687.529	3178.95
687.786	3226.48
688.044	3189.9
688.302	3235.67
688.559	3131.5
688.817	3131.5
689.074	3147.61
689.332	3173.94
689.589	3154.15
689.847	3159.83
690.104	3135.44
690.362	3137.7
690.619	3092.5
690.877	3140.25
691.134	3143.1
691.392	3093.06
691.649	3117.32
691.907	3065.57
692.164	3072.6
692.421	3091.12
692.679	3070.16
692.936	3086.02
693.194	3050.56
693.451	3042.85
693.708	3003.92
693.966	3022.1
694.223	3015.43
694.48	3013.11
694.737	3040.76
694.995	3031.89
695.252	3004.13
695.509	3024.9
695.766	2995.52
696.023	2964.82
696.281	2987.96
696.538	2968.38
696.795	2974.23
697.052	2944.2
697.309	2940.39
697.566	2937
697.823	2875.27
698.08	2904.78
698.338	2917.93
698.595	2863.87
698.852	2892.06
699.109	2868.11
699.366	2833.84
699.623	2803.37
699.88	2839.13
700.137	2812.13
700.393	2789.1
700.65	2817.92
700.907	2811.3
701.164	2831.14
701.421	2829.65
701.678	2834.46
701.935	2811.04
702.192	2813.04
702.448	2785.82
702.705	2825.25
702.962	2800.72
703.219	2831.86
703.476	2815.82
703.732	2819.2
703.989	2791.54
704.246	2808.51
704.503	2789.79
704.759	2793.04
705.016	2789.99
705.273	2720.19
705.511	2762.04
705.768	2761.98
706.026	2698.64
706.283	2670.43
706.541	2668.1
706.798	2664.72
707.055	2702.15
707.313	2675.76
707.57	2668.33
707.827	2640.57
708.084	2653.08
708.342	2631.76
708.599	2662.41
708.856	2610.82
709.114	2579.68
709.371	2574.97
709.628	2588.56
709.885	2578.45
710.142	2586.25
710.4	2570.36
710.657	2576.95
710.914	2569.87
711.171	2533.98
711.428	2570.2
711.685	2520.29
711.942	2515.24
712.199	2499.67
712.456	2489.48
712.713	2454.22
712.97	2462.47
713.227	2458.39
713.484	2436.87
713.741	2423.15
713.998	2408.55
714.255	2403.94
714.512	2368.64
714.769	2390.87
715.026	2336.53
715.283	2333.48
715.54	2316.7
715.797	2333.96
716.054	2335.51
716.31	2326.34
716.567	2258.75
716.824	2304.5
717.081	2290.85
717.338	2295.29
717.594	2260.98
717.851	2288
718.108	2259.22
718.365	2258.99
718.621	2238.93
718.878	2196.69
719.135	2233.38
719.391	2211.04
719.648	2206.89
719.905	2212.82
720.161	2196.36
720.418	2145.48
720.675	2153.71
720.931	2140.97
721.188	2131.82
721.444	2119.06
721.701	2113.02
721.957	2102.96
722.214	2085.88
722.47	2059
722.727	2053.58
722.983	2054.53
723.24	2040.87
723.496	2032.25
723.753	2031.28
724.009	1982.56
724.265	2020.06
724.522	2022.46
724.778	1992.59
725.034	2001.28
725.291	1984.77
725.547	1967.23
725.803	1941.36
726.06	1943.51
726.316	1933.85
726.572	1921.81
726.828	1919.3
727.085	1950.67
727.341	1905.35
727.597	1866.44
727.853	1869.88
728.109	1866.09
728.366	1822.58
728.622	1834.87
728.878	1819.62
729.134	1831.34
729.39	1812.84
729.646	1742.36
729.902	1780.82
730.158	1747.03
730.414	1715.37
730.67	1715.22
730.926	1709.13
731.182	1738.59
731.438	1673.04
731.643	1668
731.9	1700.13
732.156	1673.25
732.413	1694.45
732.67	1664.24
732.927	1674.26
733.183	1624.56
733.44	1630.7
733.697	1657.88
733.953	1618.44
734.21	1630.53
734.466	1619.4
734.723	1624.32
734.98	1627.1
735.236	1612.55
735.493	1622.58
735.749	1580.08
736.006	1603.05
736.262	1585.21
736.519	1604.43
736.775	1584.9
737.032	1569.56
737.288	1597.65
737.544	1544.67
737.801	1568.26
738.057	1558.41
738.314	1556.42
738.57	1549.81
738.826	1540.31
739.083	1530.94
739.339	1525.57
739.595	1515.9
739.852	1506.16
740.108	1509.06
740.364	1484.5
740.621	1501.69
740.877	1509.71
741.133	1525.85
741.389	1491.13
741.645	1512.77
741.902	1492.31
742.158	1466.01
742.414	1453.58
742.67	1435.49
742.926	1481.41
743.182	1443.53
743.438	1449.76
743.694	1431.05
743.951	1429.99
744.207	1430.44
744.463	1406.24
744.719	1402.01
744.975	1405.96
745.231	1396.51
745.487	1386.61
745.743	1373.76
745.998	1364.98
746.254	1364
746.51	1349.98
746.766	1348.66
747.022	1332.44
747.278	1336.73
747.534	1312.32
747.79	1314.04
748.046	1322.15
748.301	1327.14
748.557	1319.75
748.813	1300.82
749.069	1289.49
749.324	1321.4
749.58	1299.26
749.836	1310.43
750.092	1275.54
750.347	1293
750.603	1275.64
750.859	1294.32
751.114	1260.59
751.37	1252.23
751.625	1245.89
751.881	1249.96
752.137	1213.06
752.392	1222.32
752.648	1212.42
752.903	1211.76
753.159	1188.46
753.414	1187.29
753.67	1186.3
753.925	1191.05
754.181	1162.66
754.436	1173.11
754.692	1166.07
754.947	1171.44
755.202	1164.91
755.458	1150.61
755.713	1130.19
755.968	1119.23
756.224	1142.56
756.479	1135.85
756.734	1104.93
756.99	1114.44
757.245	1111.8
757.5	1079.95
757.755	1067.89
757.968	1054.05
758.224	1048.25
758.48	1073.77
758.736	1062.25
758.992	1065.76
759.248	1035.16
759.504	1034.66
759.76	1042.96
760.016	1006.62
760.272	1010.43
760.528	1026.41
760.784	1027.5
761.04	1010.73
761.296	1002.42
761.552	1014.69
761.807	994.235
762.063	985.574
762.319	972.155
762.575	1001.02
762.831	956.964
763.086	968.307
763.342	961.845
763.598	927.284
763.853	915.955
764.109	941.207
764.365	923.834
764.621	914.522
764.876	938.779
765.132	930.671
765.387	915.282
765.643	911.514
765.899	905.07
766.154	876.777
766.41	886.497
766.665	901.004
766.921	872.846
767.176	861.577
767.432	885.022
767.687	860.93
767.943	875.527
768.198	857.509
768.454	847.422
768.709	852.385
768.965	833.844
769.22	832.666
769.475	821.555
769.731	833.604
769.986	820.554
770.242	806.383
770.497	790.096
770.752	808.037
771.007	768.031
771.263	778.569
771.518	777.321
771.773	778.325
772.028	774.678
772.284	749.494
772.539	756.427
772.794	745.042
773.049	748.097
773.304	746.418
773.56	737.935
773.815	733.1
774.07	719.07
774.325	716.09
774.58	702.65
774.835	713.876
775.09	709.144
775.345	713.505
775.6	706.303
775.855	688.654
776.11	676.558
776.365	690.015
776.62	676.371
776.875	670.989
777.13	655.323
777.385	654.918
777.64	662.915
777.895	649.388
778.149	657.932
778.404	632.955
778.659	642.186
778.914	643.578
779.169	632.451
779.424	620.868
779.678	615.647
779.933	623.234
780.188	611.956
780.442	606.987
780.697	613.143
780.952	608.538
781.207	588.002
781.461	586.452
781.716	585.233
781.97	578.251
782.225	588.869
782.48	559.371
782.734	578.931
782.989	570.167
783.243	556.064
783.498	563.663
783.752	550.631
784.007	560.408
784.253	565.86
784.509	553.863
784.764	520.034
785.019	510.723
785.274	515.474
785.53	510.674
785.785	552.092
786.04	528.003
786.295	533.554
786.551	482.319
786.806	511.971
787.061	505.125
787.316	503.52
787.571	515.512
787.826	496.86
788.081	507.001
788.336	484.098
788.591	461.765
788.847	493.874
789.102	484.059
789.357	465.721
789.612	485.088
789.867	477.305
790.122	475.294
790.377	462.265
790.632	458.082
790.886	453.112
791.141	449.309
791.396	441.018
791.651	449.887
791.906	431.118
792.161	433.242
792.416	438.092
792.671	420.762
792.925	451.625
793.18	426.8
793.435	398.398
793.69	418.004
793.945	419.223
794.199	411.021
794.454	419.705
794.709	410.435
794.963	396.272
795.218	402.916
795.473	399.772
795.727	385.157
795.982	406.352
796.237	384.732
796.491	392.519
796.746	375.779
797	380.894
797.255	375.766
797.509	381.192
797.764	379.835
798.018	376.128
798.273	364.111
798.527	356.412
798.782	373.563
799.036	348.854
799.291	357.217
799.545	342.96
799.8	347.771
800.054	344.18
800.308	365.391
800.563	339.635
800.817	333.595
801.071	345.42
801.326	326.626
801.58	340.257
801.834	329.364
802.088	331.186
802.343	325.207
802.597	320.361
802.851	328.446
803.105	304.74
803.359	334.658
803.614	315.619
803.868	315.898
804.122	313.308
804.376	306.279
804.63	302.847
804.884	312.046
805.138	302.592
805.392	289.887
805.646	289.941
805.9	303.288
806.154	296.25
806.408	287.572
806.662	288.145
806.916	284.494
807.17	290.339
807.424	287.791
807.678	277.71
807.932	287.611
808.186	276.567
808.439	279.344
808.693	284.184
808.947	275.273
809.201	271.928
809.455	271.56
809.708	270.039
809.962	272.376
810.183	264
810.438	262.078
810.693	238.508
810.947	265.732
811.202	252.148
811.456	269.221
811.711	253.661
811.965	246.103
812.22	248.044
812.474	244.899
812.729	249.951
812.983	241.124
813.237	235.855
813.492	233.064
813.746	242.701
814.001	238.215
814.255	235.094
814.509	233.025
814.764	219.564
815.018	234.016
815.272	223.196
815.526	230.785
815.781	231.608
816.035	229.519
816.289	227.432
816.543	227.275
816.798	216.742
817.052	223.08
817.306	224.184
817.56	218.597
817.814	212.439
818.068	219.186
818.323	207.994
818.577	210.767
818.831	220.567
819.085	209.084
819.339	204.894
819.593	205.427
819.847	206.793
820.101	202.251
820.355	194.766
820.609	206.66
820.863	204.645
821.117	200.1
821.371	198.321
821.624	207.058
821.878	196.442
822.132	186.533
822.386	191.834
822.64	197.472
822.894	188.657
823.148	191.762
823.401	188.988
823.655	186.182
823.909	182.93
824.163	175.264
824.416	179.512
824.67	176.523
824.924	179.286
825.177	179.133
825.431	176.567
825.685	186.423
825.938	174.209
826.192	174.515
826.446	158.667
826.699	176.314
826.953	176.407
827.206	166.477
827.46	173.889
827.713	174.038
827.967	166.207
828.22	168.952
828.474	170.958
828.727	159.282
828.981	160.552
829.234	160.691
829.488	159.073
829.741	167.76
829.994	159.83
830.248	159.835
830.501	165.316
830.754	159.014
831.008	153.104
831.261	156.855
831.514	157.074
831.767	158.706
832.021	155.439
832.274	144.82
832.527	150.188
832.78	154.483
833.034	151.912
833.287	154.663
833.54	149.181
833.793	152.289
834.046	142.715
834.299	149.656
834.552	139.852
834.805	141.034
835.058	151.375
835.311	144.369
835.564	137.273
835.817	142.195
836.07	134.469
836.314	138.034
836.568	149.821
836.821	145.865
837.075	145.691
837.329	144.039
837.583	130.206
837.836	136.299
838.09	137.015
838.344	126.922
838.598	146.259
838.851	144.38
839.105	125.622
839.359	134.493
839.612	135.17
839.866	138.526
840.119	129.242
840.373	128.497
840.627	141.63
840.88	134.888
841.134	130.244
841.387	124.691
841.641	135.669
841.894	125.113
842.148	118.94
842.401	113.62
842.655	128.701
842.908	120.172
843.161	129.863
843.415	124.434
843.668	117.606
843.922	122.6
844.175	121.999
844.428	115.776
844.682	122.705
844.935	125.72
845.188	115.35
845.442	116.46
845.695	116.427
845.948	119.414
846.201	124.322
846.455	118.668
846.708	111.233
846.961	110.469
847.214	114.379
847.467	115.133
847.72	115.504
847.973	105.172
848.227	119.074
848.48	112.977
848.733	116.723
848.986	113.897
849.239	113.096
849.492	108.877
849.745	102.05
849.998	112.349
850.251	108.016
850.504	104.912
850.757	112.527
851.01	109.296
851.263	105.372
851.515	104.82
851.768	111.897
852.021	106.286
852.274	108.729
852.527	98.2313
852.78	103.034
853.032	99.2942
853.285	97.6991
853.538	103.57
853.791	106.823
854.043	99.9851
854.296	96.9387
854.549	100.267
854.801	100.472
855.054	101.072
855.307	99.4487
855.559	98.6355
855.812	99.4405
856.065	97.6521
856.317	100.921
856.57	98.4521
856.822	97.7029
857.075	97.8543
857.327	94.4
857.58	97.2985
857.832	92.4768
858.085	92.1043
858.337	86.7588
858.589	88.5642
858.842	94.0118
859.094	89.625
859.347	95.3601
859.599	93.8063
859.851	85.0027
860.104	93.6908
860.356	94.5202
860.608	86.3989
860.861	93.7749
861.113	86.3642
861.365	81.1975
861.617	92.3449
861.869	89.2578
862.112	87.9961
862.365	89.9547
862.618	84.0145
862.871	84.0271
863.124	91.6716
863.377	91.8012
863.63	89.6969
863.883	85.6018
864.136	85.8482
864.389	83.3814
864.642	92.8026
864.894	83.4004
865.147	85.2924
865.4	89.8714
865.653	78.3509
865.906	81.4613
866.159	92.3673
866.412	74.8199
866.664	82.4974
866.917	83.7348
867.17	84.1829
867.423	78.5657
867.675	81.2722
867.928	79.6289
868.181	82.8765
868.433	81.7951
868.686	78.1336
868.939	79.4265
869.191	74.3567
869.444	83.5014
869.697	72.2177
869.949	74.3988
870.202	68.3084
870.454	79.7938
870.707	76.8356
870.959	68.9283
871.212	73.4463
871.464	75.3303
871.717	70.1369
871.969	70.1122
872.222	74.9649
872.474	72.3292
872.727	66.8365
872.979	70.1704
873.231	77.0823
873.484	73.0331
873.736	75.7615
873.988	67.2998
874.241	74.9092
874.493	68.3823
874.745	73.1637
874.998	68.2932
875.25	73.4726
875.502	63.8494
875.754	70.2361
876.006	69.0883
876.259	72.5597
876.511	61.3695
876.763	64.4454
877.015	66.1336
877.267	66.6182
877.519	67.99
877.771	64.3986
878.023	70.5308
878.276	69.0582
878.528	70.903
878.78	62.549
879.031	66.0664
879.284	68.38
879.535	70.2374
879.787	64.8367
880.039	65.8943
880.291	62.1116
880.543	64.9667
880.795	65.7778
881.047	64.2694
881.299	61.4227
881.551	62.4545
881.802	65.3306
882.054	69.0105
882.306	61.3289
882.558	67.1137
882.809	64.0974
883.061	64.263
883.313	57.5931
883.565	61.8356
883.816	59.2915
884.068	63.2616
884.319	61.2563
884.571	64.6444
884.823	67.0568
885.074	64.6134
885.326	57.4751
885.577	62.4947
885.829	60.7639
886.08	56.9278
886.332	69.422
886.583	53.3488
886.835	58.3158
887.086	57.9293
887.338	54.1656
887.589	63.8941
887.841	61.8297
888.044	59.7931
888.296	65.4415
888.548	56.1939
888.8	64.8759
889.053	55.9279
889.305	57.929
889.557	55.6408
889.809	61.7635
890.061	55.4683
890.313	54.3062
890.566	61.9707
890.818	59.3697
891.07	54.6227
891.322	58
891.574	49.9717
891.826	48.0967
892.078	50.2613
892.33	55.7107
892.582	52.3694
892.834	52.6754
893.086	48.7386
893.338	50.7991
893.59	51.0581
893.842	46.9621
894.094	54.0145
894.346	47.0169
894.597	52.0725
894.849	50.1594
895.101	54.8333
895.353	57.786
895.605	48.087
895.857	53.3768
896.108	55.0435
896.36	54
896.612	53.7609
896.864	49
897.115	53.8152
897.367	51.7995
897.619	53.9178
897.87	51
898.122	46
898.374	49.4704
898.625	54
898.877	49.104
899.128	53.7424
899.38	47.9879
899.631	43.6941
899.883	47.2721
899.984	50.3705